{"op":"mcm","clk":"990748711","pt":1580499220391,"mc":[{"id":"1.168096552","rc":[{"batb":[[0,2.82,8.48]],"ltp":2.8,"tv":174.59,"id":52106}]}]}
{"op":"mcm","clk":"990753625","pt":1580499255870,"mc":[{"id":"1.168096552","rc":[{"batl":[[0,2.88,41.65]],"ltp":2.8,"tv":174.59,"id":52106}]}]}
{"op":"mcm","clk":"990771660","pt":1580499382253,"mc":[{"id":"1.168096552","rc":[{"batb":[[0,2.84,5.88],[1,2.82,8.48]],"ltp":2.8,"tv":174.59,"id":52106}]}]}
{"op":"mcm","clk":"990774438","pt":1580499402379,"mc":[{"id":"1.168096552","rc":[{"batb":[[1,3.2,3.01],[2,3.15,10]],"ltp":3.3,"tv":349.26,"id":18286408}]}]}
{"op":"mcm","clk":"990811458","pt":1580499588142,"mc":[{"id":"1.168096552","rc":[{"trd":[[3.3,46.41]],"batb":[[0,3.25,9.36]],"batl":[[0,3.35,7.33]],"ltp":3.3,"tv":350.86,"id":18286408}],"tv":1093.78}]}
{"op":"mcm","clk":"990811602","pt":1580499589103,"mc":[{"id":"1.168096552","rc":[{"trd":[[3.35,7.56]],"batl":[[0,3.35,5.65]],"ltp":3.35,"tv":352.46,"id":18286408}],"tv":1095.38}]}
{"op":"mcm","clk":"990812154","pt":1580499593000,"mc":[{"id":"1.168096552","rc":[{"batb":[[0,3.25,13.31]],"ltp":3.35,"tv":352.46,"id":18286408},{"batb":[[1,10,2.37],[2,9.8,4.02]],"ltp":11.0,"tv":4.0,"id":26640937},{"batb":[[0,4.7,2.73],[1,4.6,20.46],[2,4.5,18]],"ltp":4.6,"tv":564.32,"id":21580749},{"batb":[[1,2.82,13.03]],"ltp":2.8,"tv":174.59,"id":52106},{"batb":[[1,12.5,1.03],[2,12,5]],"ltp":0.0,"tv":0.0,"id":24608298}]}]}
{"op":"mcm","clk":"990812364","pt":1580499594407,"mc":[{"id":"1.168096552","rc":[{"batb":[[2,9.8,4.11]],"ltp":11.0,"tv":4.0,"id":26640937}]}]}
{"op":"mcm","clk":"990815518","pt":1580499615448,"mc":[{"id":"1.168096552","rc":[{"batb":[[2,9.8,2.07]],"ltp":11.0,"tv":4.0,"id":26640937}]}]}
{"op":"mcm","clk":"990818537","pt":1580499635084,"mc":[{"id":"1.168096552","rc":[{"batb":[[2,9,10.99]],"ltp":0.0,"tv":0.0,"id":24608298}]}]}
{"op":"mcm","clk":"990821608","pt":1580499653805,"mc":[{"id":"1.168096552","rc":[{"batb":[[1,13,4.5],[2,12.5,1.03]],"ltp":0.0,"tv":0.0,"id":24608298}]}]}
{"op":"mcm","clk":"990831561","pt":1580499716966,"mc":[{"id":"1.168096552","rc":[{"trd":[[2.84,28.2]],"batb":[[0,2.82,13.03],[1,2.76,2.75],[2,2.74,50]],"batl":[[0,2.84,24.12],[1,2.88,41.65],[2,2.9,15.41]],"ltp":2.84,"tv":186.35,"id":52106}],"tv":1107.14}]}
{"op":"mcm","clk":"990832244","pt":1580499721264,"mc":[{"id":"1.168096552","rc":[{"trd":[[2.82,42.05]],"batb":[[0,2.76,2.75],[1,2.74,50],[2,2.6,18.95]],"batl":[[0,2.8,11.08]],"ltp":2.82,"tv":212.42,"id":52106}],"tv":1133.21}]}
{"op":"mcm","clk":"990834563","pt":1580499736376,"mc":[{"id":"1.168096552","rc":[{"trd":[[2.74,16.66],[2.76,37.91]],"batb":[[0,2.74,41.67],[1,2.6,18.95],[2,2.52,18.95]],"batl":[[0,2.88,41.65],[1,2.9,15.41],[2,2.92,6]],"ltp":2.74,"tv":234.58,"id":52106}],"tv":1155.37}]}
{"op":"mcm","clk":"990834779","pt":1580499737888,"mc":[{"id":"1.168096552","rc":[{"batb":[[1,2.6,22.3]],"ltp":2.74,"tv":234.58,"id":52106}]}]}
{"op":"mcm","clk":"990843667","pt":1580499794274,"mc":[{"id":"1.168096552","rc":[{"trd":[[3.25,60.62]],"batb":[[0,3.2,3.01],[1,3.15,10],[2,3.1,5]],"batl":[[0,3.25,16.69],[1,3.35,5.65],[2,3.4,30]],"ltp":3.25,"tv":379.08,"id":18286408}],"tv":1181.99}]}
{"op":"mcm","clk":"990843721","pt":1580499794551,"mc":[{"id":"1.168096552","rc":[{"batb":[[1,2.6,18.95]],"ltp":2.74,"tv":234.58,"id":52106}]}]}
{"op":"mcm","clk":"990845028","pt":1580499803454,"mc":[{"id":"1.168096552","rc":[{"batb":[[2,3.1,2]],"ltp":3.25,"tv":379.08,"id":18286408}]}]}
{"op":"mcm","clk":"990845463","pt":1580499806446,"mc":[{"id":"1.168096552","rc":[{"trd":[[3.2,12.69]],"batb":[[0,3.15,10],[1,3.1,2],[2,3.05,16.17]],"batl":[[0,3.2,13.68]],"ltp":3.2,"tv":385.09,"id":18286408}],"tv":1188.01}]}
{"op":"mcm","clk":"990845531","pt":1580499806876,"mc":[{"id":"1.168096552","rc":[{"trd":[[3.2,21.43]],"batl":[[0,3.2,17.37],[1,3.4,30],[2,3.45,6]],"ltp":3.2,"tv":393.83,"id":18286408}],"tv":1196.75}]}
{"op":"mcm","clk":"990845820","pt":1580499808487,"mc":[{"id":"1.168096552","rc":[{"batb":[[2,4.4,3.68]],"ltp":4.6,"tv":564.32,"id":21580749}]}]}
{"op":"mcm","clk":"990846535","pt":1580499813175,"mc":[{"id":"1.168096552","rc":[{"batb":[[1,4.6,12.06]],"ltp":4.6,"tv":564.32,"id":21580749}]}]}
{"op":"mcm","clk":"990847379","pt":1580499818701,"mc":[{"id":"1.168096552","rc":[{"trd":[[3.15,71.26]],"batb":[[0,3.1,2.69],[1,3.05,16.17],[2,3,49]],"batl":[[0,3.2,8.06]],"ltp":3.15,"tv":412.45,"id":18286408}],"tv":1215.37}]}
{"op":"mcm","clk":"990847597","pt":1580499820098,"mc":[{"id":"1.168096552","rc":[{"batl":[[2,3.45,14.4]],"ltp":3.15,"tv":412.45,"id":18286408}]}]}
{"op":"mcm","clk":"990847796","pt":1580499821495,"mc":[{"id":"1.168096552","rc":[{"batb":[[0,3.1,5.94]],"ltp":3.15,"tv":412.45,"id":18286408},{"batb":[[0,2.74,43.35]],"ltp":2.74,"tv":234.58,"id":52106}]}]}
{"op":"mcm","clk":"990847841","pt":1580499821803,"mc":[{"id":"1.168096552","rc":[{"batb":[[0,10.5,3.14],[2,9.6,2.27]],"ltp":11.0,"tv":4.0,"id":26640937},{"batb":[[0,4.7,4.41],[2,4.4,2]],"ltp":4.6,"tv":564.32,"id":21580749},{"batb":[[0,27,1.98],[1,26,2],[2,20,1.71]],"ltp":0.0,"tv":0.0,"id":27706761}]}]}
{"op":"mcm","clk":"990848835","pt":1580499828405,"mc":[{"id":"1.168096552","rc":[{"batb":[[2,9.6,2.18]],"ltp":11.0,"tv":4.0,"id":26640937}]}]}
{"op":"mcm","clk":"990849023","pt":1580499829465,"mc":[{"id":"1.168096552","rc":[{"batb":[[1,10,2.46]],"ltp":11.0,"tv":4.0,"id":26640937},{"batb":[[1,26,2.03],[2,20,1.68]],"ltp":0.0,"tv":0.0,"id":27706761}]}]}
{"op":"mcm","clk":"990850595","pt":1580499839709,"mc":[{"id":"1.168096552","rc":[{"batl":[[1,12.5,3]],"ltp":11.0,"tv":4.0,"id":26640937}]}]}
{"op":"mcm","clk":"990850797","pt":1580499841102,"mc":[{"id":"1.168096552","rc":[{"trd":[[2.74,56.66]],"batb":[[0,2.74,23.35]],"ltp":2.74,"tv":274.58,"id":52106}],"tv":1255.37}]}
{"op":"mcm","clk":"990853424","pt":1580499858715,"mc":[{"id":"1.168096552","rc":[{"batb":[[0,27,2.86]],"ltp":0.0,"tv":0.0,"id":27706761}]}]}
{"op":"mcm","clk":"990855880","pt":1580499875253,"mc":[{"id":"1.168096552","rc":[{"batb":[[0,2.76,7.56],[1,2.74,23.35],[2,2.6,18.95]],"ltp":2.74,"tv":274.58,"id":52106}]}]}
{"op":"mcm","clk":"990857463","pt":1580499885558,"mc":[{"id":"1.168096552","rc":[{"trd":[[3.15,72.64]],"batb":[[0,3.1,5.25]],"batl":[[0,3.2,8.13]],"ltp":3.15,"tv":413.83,"id":18286408}],"tv":1256.75}]}
{"op":"mcm","clk":"990859538","pt":1580499899171,"mc":[{"id":"1.168096552","rc":[{"batb":[[0,28,2],[1,27,2.86],[2,20,1.71]],"ltp":0.0,"tv":0.0,"id":27706761}]}]}
{"op":"mcm","clk":"990860153","pt":1580499903398,"mc":[{"id":"1.168096552","rc":[{"batb":[[2,20,1.68]],"ltp":0.0,"tv":0.0,"id":27706761}]}]}
{"op":"mcm","clk":"990860267","pt":1580499904070,"mc":[{"id":"1.168096552","rc":[{"batb":[[1,27,2.89]],"ltp":0.0,"tv":0.0,"id":27706761}]}]}
{"op":"mcm","clk":"990861815","pt":1580499914174,"mc":[{"id":"1.168096552","rc":[{"trd":[[3.15,72.78],[3.2,25.29]],"batl":[[0,3.2,6.13]],"ltp":3.2,"tv":417.83,"id":18286408}],"tv":1260.75}]}
{"op":"mcm","clk":"990862276","pt":1580499917307,"mc":[{"id":"1.168096552","rc":[{"batb":[[0,29,1.98],[1,28,2],[2,20,2.59]],"ltp":0.0,"tv":0.0,"id":27706761},{"batb":[[0,2.76,9.24],[1,2.74,21.67]],"ltp":2.74,"tv":274.58,"id":52106}]}]}
{"op":"mcm","clk":"990862448","pt":1580499918433,"mc":[{"id":"1.168096552","rc":[{"batb":[[2,20,2.56]],"ltp":0.0,"tv":0.0,"id":27706761}]}]}
{"op":"mcm","clk":"990862571","pt":1580499919223,"mc":[{"id":"1.168096552","rc":[{"batb":[[1,28,2.03]],"ltp":0.0,"tv":0.0,"id":27706761}]}]}
{"op":"mcm","clk":"990863692","pt":1580499926517,"mc":[{"id":"1.168096552","rc":[{"batb":[[0,4.7,6.41],[2,4.3,3]],"ltp":4.6,"tv":564.32,"id":21580749}]}]}
{"op":"mcm","clk":"990864871","pt":1580499934412,"mc":[{"id":"1.168096552","rc":[{"batb":[[0,3.1,11.97]],"ltp":3.2,"tv":417.83,"id":18286408}]}]}
{"op":"mcm","clk":"990865997","pt":1580499942049,"mc":[{"id":"1.168096552","rc":[{"trd":[[4.8,4]],"batb":[[0,4.7,4.41]],"batl":[[0,4.8,2]],"ltp":4.8,"tv":568.32,"id":21580749}],"tv":1264.75}]}
{"op":"mcm","clk":"990867159","pt":1580499949161,"mc":[{"id":"1.168096552","rc":[{"batb":[[0,4.7,9.45]],"ltp":4.8,"tv":568.32,"id":21580749}]}]}
{"op":"mcm","clk":"990877065","pt":1580500016422,"mc":[{"id":"1.168096552","rc":[{"batl":[[0,3.15,1],[1,3.2,6.13],[2,3.4,30]],"ltp":3.2,"tv":417.83,"id":18286408}]}]}
{"op":"mcm","clk":"990877074","pt":1580500016531,"mc":[{"id":"1.168096552","rc":[{"batl":[[0,3.2,6.13],[1,3.4,30],[2,3.45,14.4]],"ltp":3.2,"tv":417.83,"id":18286408}]}]}
{"op":"mcm","clk":"990879181","pt":1580500031364,"mc":[{"id":"1.168096552","rc":[{"trd":[[3.1,116]],"batb":[[0,3.1,8.97]],"ltp":3.1,"tv":423.83,"id":18286408}],"tv":1270.75}]}
{"op":"mcm","clk":"990879281","pt":1580500032168,"mc":[{"id":"1.168096552","rc":[{"batb":[[2,3,46]],"ltp":3.1,"tv":423.83,"id":18286408}]}]}
{"op":"mcm","clk":"990880253","pt":1580500039971,"mc":[{"id":"1.168096552","rc":[{"trd":[[4.7,4]],"batb":[[0,4.7,7.45]],"ltp":4.7,"tv":572.32,"id":21580749}],"tv":1274.75}]}
{"op":"mcm","clk":"990881391","pt":1580500048795,"mc":[{"id":"1.168096552","rc":[{"trd":[[2.76,43.9]],"batb":[[0,2.76,6.24]],"ltp":2.76,"tv":280.58,"id":52106}],"tv":1280.74}]}
{"op":"mcm","clk":"990892533","pt":1580500136793,"mc":[{"id":"1.168096552","rc":[{"trd":[[2.88,12.53]],"batl":[[0,2.88,39.66]],"ltp":2.88,"tv":284.58,"id":52106}],"tv":1284.74}]}
{"op":"mcm","clk":"990900949","pt":1580500205883,"mc":[{"id":"1.168096552","rc":[{"batl":[[0,2.86,25],[1,2.88,39.66],[2,2.9,15.41]],"ltp":2.88,"tv":284.58,"id":52106}]}]}
{"op":"mcm","clk":"990910195","pt":1580500286388,"mc":[{"id":"1.168096552","rc":[{"trd":[[2.86,31.08]],"batl":[[0,2.86,11.6]],"ltp":2.86,"tv":311.38,"id":52106}],"tv":1311.54}]}
{"op":"mcm","clk":"990914853","pt":1580500330467,"mc":[{"id":"1.168096552","rc":[{"trd":[[3.2,37.56]],"batb":[[0,3.1,9.83]],"batl":[[0,3.4,30],[1,3.45,14.4],[2,3.5,150]],"ltp":3.2,"tv":436.1,"id":18286408}],"tv":1323.81}]}
{"op":"mcm","clk":"990914872","pt":1580500330630,"mc":[{"id":"1.168096552","rc":[{"batl":[[0,3.35,9.83],[1,3.4,30],[2,3.45,14.4]],"ltp":3.2,"tv":436.1,"id":18286408}]}]}
{"op":"mcm","clk":"990915071","pt":1580500332672,"mc":[{"id":"1.168096552","rc":[{"batb":[[0,3.1,8.97]],"ltp":3.2,"tv":436.1,"id":18286408}]}]}
{"op":"mcm","clk":"990915395","pt":1580500335856,"mc":[{"id":"1.168096552","rc":[{"batb":[[2,3,49]],"batl":[[0,3.4,30],[1,3.45,14.4],[2,3.5,150]],"ltp":3.2,"tv":436.1,"id":18286408}]}]}
{"op":"mcm","clk":"990916475","pt":1580500347079,"mc":[{"id":"1.168096552","rc":[{"batb":[[0,3.1,22.83]],"ltp":3.2,"tv":436.1,"id":18286408}]}]}
{"op":"mcm","clk":"990926889","pt":1580500353774,"mc":[{"id":"1.168096552","rc":[{"batb":[[2,3,58.75]],"batl":[[0,3.35,8.73],[1,3.4,30],[2,3.45,14.4]],"ltp":3.2,"tv":436.1,"id":18286408}]}]}
{"op":"mcm","clk":"990933145","pt":1580500413060,"mc":[{"id":"1.168096552","rc":[{"trd":[[2.86,46.4]],"batl":[[0,2.86,3.94]],"ltp":2.86,"tv":326.7,"id":52106}],"tv":1339.13}]}
{"op":"mcm","clk":"990933790","pt":1580500419348,"mc":[{"id":"1.168096552","rc":[{"batb":[[0,29,3.98],[1,20,2.59],[2,18,1.8]],"ltp":0.0,"tv":0.0,"id":27706761}]}]}
{"op":"mcm","clk":"990938222","pt":1580500465497,"mc":[{"id":"1.168096552","rc":[{"batl":[[0,2.84,6.8],[1,2.86,3.94],[2,2.88,39.66]],"ltp":2.86,"tv":326.7,"id":52106}]}]}
{"op":"mcm","clk":"990939213","pt":1580500475639,"mc":[{"id":"1.168096552","rc":[{"batb":[[0,3.15,30],[1,3.1,22.83],[2,3.05,16.17]],"ltp":3.2,"tv":436.1,"id":18286408}]}]}
{"op":"mcm","clk":"990940113","pt":1580500484129,"mc":[{"id":"1.168096552","rc":[{"batb":[[0,3.2,9.24],[1,3.15,30],[2,3.1,16.11]],"ltp":3.2,"tv":436.1,"id":18286408}]}]}
{"op":"mcm","clk":"990943091","pt":1580500512496,"mc":[{"id":"1.168096552","rc":[{"batl":[[0,3.4,30],[1,3.45,14.4],[2,3.5,150]],"ltp":3.2,"tv":436.1,"id":18286408}]}]}
{"op":"mcm","clk":"990946538","pt":1580500544442,"mc":[{"id":"1.168096552","rc":[{"batb":[[0,3.15,30],[1,3.1,16.11],[2,3.05,16.17]],"ltp":3.2,"tv":436.1,"id":18286408},{"batb":[[0,4.7,2.41]],"ltp":4.7,"tv":572.32,"id":21580749},{"batb":[[0,2.76,1.68]],"ltp":2.86,"tv":326.7,"id":52106}]}]}
{"op":"mcm","clk":"990946558","pt":1580500544652,"mc":[{"id":"1.168096552","rc":[{"trd":[[2.76,47.26]],"batb":[[0,2.74,21.67],[1,2.6,18.95],[2,2.52,18.95]],"ltp":2.76,"tv":330.06,"id":52106}],"tv":1342.49}]}
{"op":"mcm","clk":"990947665","pt":1580500553935,"mc":[{"id":"1.168096552","rc":[{"trd":[[2.84,58.81]],"batl":[[0,2.84,8.5]],"ltp":2.84,"tv":360.67,"id":52106}],"tv":1373.1}]}
{"op":"mcm","clk":"990947775","pt":1580500554741,"mc":[{"id":"1.168096552","rc":[{"batl":[[0,2.84,17.01]],"ltp":2.84,"tv":360.67,"id":52106}]}]}
{"op":"mcm","clk":"990950159","pt":1580500575276,"mc":[{"id":"1.168096552","rc":[{"batl":[[0,3.35,10.32],[1,3.4,30],[2,3.45,14.4]],"ltp":3.2,"tv":436.1,"id":18286408},{"batb":[[2,2.54,10.15]],"batl":[[0,2.82,9.15],[1,2.84,17.01],[2,2.86,3.94]],"ltp":2.84,"tv":360.67,"id":52106}]}]}
{"op":"mcm","clk":"990950764","pt":1580500580981,"mc":[{"id":"1.168096552","rc":[{"trd":[[2.74,100]],"batb":[[0,2.6,18.95],[1,2.54,17.64],[2,2.52,18.95]],"ltp":2.74,"tv":404.01,"id":52106}],"tv":1416.44}]}
{"op":"mcm","clk":"990950939","pt":1580500582516,"mc":[{"id":"1.168096552","rc":[{"batb":[[1,2.54,10.15]],"batl":[[0,2.8,2],[1,2.82,9.15],[2,2.84,17.01]],"ltp":2.74,"tv":404.01,"id":52106}]}]}
{"op":"mcm","clk":"990953707","pt":1580500608011,"mc":[{"id":"1.168096552","rc":[{"batb":[[0,2.64,5.58],[1,2.62,7.27],[2,2.6,18.95]],"batl":[[1,2.84,17.01],[2,2.86,3.94]],"ltp":2.74,"tv":404.01,"id":52106}]}]}
{"op":"mcm","clk":"990955404","pt":1580500623831,"mc":[{"id":"1.168096552","rc":[{"batb":[[1,2.62,57.27]],"ltp":2.74,"tv":404.01,"id":52106}]}]}
{"op":"mcm","clk":"990957298","pt":1580500640477,"mc":[{"id":"1.168096552","rc":[{"batb":[[1,2.62,50]],"ltp":2.74,"tv":404.01,"id":52106}]}]}
{"op":"mcm","clk":"990957381","pt":1580500641161,"mc":[{"id":"1.168096552","rc":[{"batb":[[0,2.66,7.16],[1,2.64,5.58],[2,2.62,50]],"ltp":2.74,"tv":404.01,"id":52106}]}]}
{"op":"mcm","clk":"990957935","pt":1580500646162,"mc":[{"id":"1.168096552","rc":[{"batb":[[1,2.62,50],[2,2.6,18.95]],"batl":[[0,2.78,5.43],[1,2.8,77],[2,2.84,17.01]],"ltp":2.74,"tv":404.01,"id":52106}]}]}
{"op":"mcm","clk":"990958113","pt":1580500647900,"mc":[{"id":"1.168096552","rc":[{"batl":[[0,3.3,25],[1,3.35,10.32],[2,3.4,30]],"ltp":3.2,"tv":436.1,"id":18286408}]}]}
{"op":"mcm","clk":"990958666","pt":1580500652673,"mc":[{"id":"1.168096552","rc":[{"batl":[[0,2.78,80.43],[1,2.8,2]],"ltp":2.74,"tv":404.01,"id":52106}]}]}
{"op":"mcm","clk":"990960027","pt":1580500665195,"mc":[{"id":"1.168096552","rc":[{"batb":[[0,3.15,32.25],[1,3.1,13.86]],"ltp":3.2,"tv":436.1,"id":18286408}]}]}
{"op":"mcm","clk":"990960097","pt":1580500665796,"mc":[{"id":"1.168096552","rc":[{"trd":[[3.15,88.65]],"batb":[[0,3.15,24.31]],"ltp":3.15,"tv":451.98,"id":18286408}],"tv":1432.32}]}
{"op":"mcm","clk":"990960763","pt":1580500672492,"mc":[{"id":"1.168096552","rc":[{"batl":[[1,3.4,30],[2,3.45,6]],"ltp":3.15,"tv":451.98,"id":18286408},{"batb":[[0,2.64,7.16]],"ltp":2.74,"tv":404.01,"id":52106}]}]}
{"op":"mcm","clk":"990961659","pt":1580500680624,"mc":[{"id":"1.168096552","rc":[{"batl":[[1,2.84,17.01],[2,2.86,22.23]],"ltp":2.74,"tv":404.01,"id":52106}]}]}
{"op":"mcm","clk":"990963151","pt":1580500695263,"mc":[{"id":"1.168096552","rc":[{"batb":[[0,2.64,26.11],[2,2.52,18.95]],"ltp":2.74,"tv":404.01,"id":52106}]}]}
{"op":"mcm","clk":"990968869","pt":1580500752299,"mc":[{"id":"1.168096552","rc":[{"batl":[[0,2.76,39.66],[1,2.78,80.43],[2,2.84,17.01]],"ltp":2.74,"tv":404.01,"id":52106}]}]}
{"op":"mcm","clk":"990971224","pt":1580500775287,"mc":[{"id":"1.168096552","rc":[{"trd":[[2.64,7.98]],"batb":[[0,2.64,24.11]],"ltp":2.64,"tv":408.01,"id":52106}],"tv":1436.32}]}
{"op":"mcm","clk":"990975447","pt":1580500814500,"mc":[{"id":"1.168096552","rc":[{"trd":[[3.05,37.4],[3.2,37.57],[3.25,60.63],[3.3,46.42]],"ltp":3.15,"tv":451.99,"id":18286408},{"batb":[[1,10,2.47]],"ltp":11.0,"tv":4.0,"id":26640937},{"trd":[[4.1,50.11],[4.7,4]],"batb":[[0,4.7,2.41]],"ltp":4.7,"tv":572.33,"id":21580749},{"batb":[[1,20,2.59]],"ltp":0.0,"tv":0.0,"id":27706761},{"trd":[[2.62,8.97],[2.76,47.25],[2.82,42.06],[2.84,58.8],[3,14.5],[3.05,16.47]],"batb":[[0,2.64,24.1],[2,2.52,18.93]],"batl":[[2,2.84,16.99]],"ltp":2.64,"tv":408.0,"id":52106},{"trd":[[13,5],[34,1.24],[36,1.12],[38,0.64]],"batb":[[0,13,2],[1,12.5,1.03],[2,9,10.99]],"ltp":13.0,"tv":8.0,"id":24608298}],"tv":1444.33}]}
{"op":"mcm","clk":"990976366","pt":1580500822413,"mc":[{"id":"1.168096552","rc":[{"trd":[[2.76,126.57]],"batb":[[0,2.76,11.36],[1,2.64,24.1],[2,2.62,50]],"batl":[[0,2.78,80.43],[1,2.84,16.99],[2,2.86,22.21]],"ltp":2.76,"tv":487.32,"id":52106}],"tv":1523.65}]}
{"op":"mcm","clk":"990976822","pt":1580500826434,"mc":[{"id":"1.168096552","rc":[{"trd":[[2.78,22.72]],"batb":[[0,2.66,11.23]],"batl":[[0,2.78,69.07]],"ltp":2.78,"tv":510.04,"id":52106}],"tv":1546.37}]}
{"op":"mcm","clk":"990977268","pt":1580500830331,"mc":[{"id":"1.168096552","rc":[{"trd":[[2.78,64.46]],"batl":[[0,2.78,48.2]],"ltp":2.78,"tv":551.78,"id":52106}],"tv":1588.11}]}
{"op":"mcm","clk":"990978777","pt":1580500844751,"mc":[{"id":"1.168096552","rc":[{"batl":[[0,2.76,10],[1,2.78,48.2],[2,2.84,16.99]],"ltp":2.78,"tv":551.78,"id":52106}]}]}
{"op":"mcm","clk":"990983572","pt":1580500878802,"mc":[{"id":"1.168096552","rc":[{"batb":[[0,2.68,5.09],[1,2.66,11.23],[2,2.64,18.93]],"ltp":2.78,"tv":551.78,"id":52106}]}]}
{"op":"mcm","clk":"990985334","pt":1580500891884,"mc":[{"id":"1.168096552","rc":[{"batb":[[0,2.7,10.2],[1,2.68,5.09]],"ltp":2.78,"tv":551.78,"id":52106}]}]}
{"op":"mcm","clk":"990989315","pt":1580500921164,"mc":[{"id":"1.168096552","rc":[{"batb":[[0,2.72,10.2],[1,2.7,10.2],[2,2.68,5.09]],"ltp":2.78,"tv":551.78,"id":52106}]}]}
{"op":"mcm","clk":"990990892","pt":1580500934371,"mc":[{"id":"1.168096552","rc":[{"trd":[[2.76,146.57]],"batb":[[0,2.7,10.4],[1,2.68,5.09],[2,2.64,18.93]],"batl":[[0,2.78,48.2],[1,2.84,16.99],[2,2.86,22.21]],"ltp":2.76,"tv":571.78,"id":52106}],"tv":1608.11}]}
{"op":"mcm","clk":"990992282","pt":1580500945400,"mc":[{"id":"1.168096552","rc":[{"trd":[[2.78,75.54]],"batl":[[0,2.78,42.66]],"ltp":2.78,"tv":582.86,"id":52106}],"tv":1619.19}]}
{"op":"mcm","clk":"990992579","pt":1580500947495,"mc":[{"id":"1.168096552","rc":[{"batb":[[0,13.5,1.98],[1,13,2],[2,12.5,1.03]],"ltp":13.0,"tv":8.0,"id":24608298}]}]}
{"op":"mcm","clk":"990992616","pt":1580500947774,"mc":[{"id":"1.168096552","rc":[{"trd":[[2.78,95.94]],"batb":[[0,2.68,5.29],[1,2.64,18.93],[2,2.62,50]],"batl":[[0,2.78,32.46]],"ltp":2.78,"tv":603.26,"id":52106}],"tv":1639.59}]}
{"op":"mcm","clk":"990993683","pt":1580500955493,"mc":[{"id":"1.168096552","rc":[{"batb":[[0,2.76,4.95],[1,2.68,5.09],[2,2.64,18.93]],"ltp":2.78,"tv":603.26,"id":52106}]}]}
{"op":"mcm","clk":"990994504","pt":1580500961503,"mc":[{"id":"1.168096552","rc":[{"trd":[[2.78,96.34]],"batb":[[0,2.76,4.75]],"batl":[[0,2.78,32.26]],"ltp":2.78,"tv":603.66,"id":52106}],"tv":1639.99}]}
{"op":"mcm","clk":"990997929","pt":1580500984195,"mc":[{"id":"1.168096552","rc":[{"batb":[[1,2.64,18.93],[2,2.62,50]],"ltp":2.78,"tv":603.66,"id":52106},{"trd":[[13.5,3.96]],"batb":[[0,13,2],[1,12.5,1.03],[2,9,10.99]],"batl":[[0,290,9.2],[1,290,0]],"ltp":13.5,"tv":11.96,"id":24608298}],"tv":1643.96}]}
{"op":"mcm","clk":"990998115","pt":1580500985535,"mc":[{"id":"1.168096552","rc":[{"batb":[[2,9.2,1.53]],"ltp":13.5,"tv":11.96,"id":24608298}]}]}
{"op":"mcm","clk":"991004951","pt":1580501031281,"mc":[{"id":"1.168096552","rc":[{"trd":[[2.76,156.07]],"batb":[[0,2.66,11.23]],"batl":[[0,2.76,27.51]],"ltp":2.76,"tv":613.16,"id":52106}],"tv":1653.46}]}
{"op":"mcm","clk":"991009222","pt":1580501061127,"mc":[{"id":"1.168096552","rc":[{"batl":[[0,2.74,10],[1,2.76,27.51],[2,2.84,16.99]],"ltp":2.76,"tv":613.16,"id":52106}]}]}
{"op":"mcm","clk":"991011537","pt":1580501075822,"mc":[{"id":"1.168096552","rc":[{"batb":[[2,9.2,6.12]],"ltp":13.5,"tv":11.96,"id":24608298}]}]}
{"op":"mcm","clk":"991012226","pt":1580501080450,"mc":[{"id":"1.168096552","rc":[{"trd":[[4.7,7.63]],"batb":[[0,4.6,12.66],[1,4.3,3],[2,4.2,18]],"ltp":4.7,"tv":575.96,"id":21580749},{"trd":[[2.66,6.38]],"batb":[[0,2.66,8.04]],"ltp":2.66,"tv":619.54,"id":52106}],"tv":1663.46}]}
{"op":"mcm","clk":"991012265","pt":1580501080638,"mc":[{"id":"1.168096552","rc":[{"batl":[[0,2.74,37.51],[1,2.84,16.99],[2,2.86,22.21]],"ltp":2.66,"tv":619.54,"id":52106}]}]}
{"op":"mcm","clk":"991016190","pt":1580501105494,"mc":[{"id":"1.168096552","rc":[{"trd":[[2.74,175.02]],"batb":[[0,2.74,2.49]],"batl":[[0,2.82,3.05]],"ltp":2.74,"tv":694.56,"id":52106}],"tv":1738.48}]}
{"op":"mcm","clk":"991021371","pt":1580501138819,"mc":[{"id":"1.168096552","rc":[{"batb":[[0,2.74,4.17]],"ltp":2.74,"tv":694.56,"id":52106},{"batb":[[0,13.5,1.98],[1,13,2],[2,12.5,1.03]],"ltp":13.5,"tv":11.96,"id":24608298}]}]}
{"op":"mcm","clk":"991023301","pt":1580501152426,"mc":[{"id":"1.168096552","rc":[{"trd":[[2.82,52.98]],"batl":[[0,2.82,22.56]],"ltp":2.82,"tv":705.48,"id":52106}],"tv":1749.4}]}
{"op":"mcm","clk":"991023457","pt":1580501153626,"mc":[{"id":"1.168096552","rc":[{"batl":[[0,2.8,1.89],[1,2.82,22.56],[2,2.84,16.99]],"ltp":2.82,"tv":705.48,"id":52106}]}]}
{"op":"mcm","clk":"991028405","pt":1580501186271,"mc":[{"id":"1.168096552","rc":[{"batl":[[0,2.78,1.9]],"ltp":2.82,"tv":705.48,"id":52106}]}]}
{"op":"mcm","clk":"991032482","pt":1580501213340,"mc":[{"id":"1.168096552","rc":[{"trd":[[2.78,100.14],[2.82,70.46]],"batl":[[0,2.82,13.82],[1,2.84,16.99],[2,2.86,22.21]],"ltp":2.82,"tv":726.75,"id":52106}],"tv":1770.68}]}
{"op":"mcm","clk":"991049901","pt":1580501262600,"mc":[{"id":"1.168096552","rc":[{"batb":[[0,2.76,25],[1,2.74,4.17],[2,2.64,18.93]],"ltp":2.82,"tv":726.75,"id":52106}]}]}
{"op":"mcm","clk":"991051929","pt":1580501276931,"mc":[{"id":"1.168096552","rc":[{"batb":[[0,2.76,26.68],[1,2.74,2.49]],"ltp":2.82,"tv":726.75,"id":52106}]}]}
{"op":"mcm","clk":"991060636","pt":1580501334413,"mc":[{"id":"1.168096552","rc":[{"trd":[[2.8,38.24]],"ltp":2.8,"tv":736.75,"id":52106}],"tv":1780.68}]}
{"op":"mcm","clk":"991071171","pt":1580501404231,"mc":[{"id":"1.168096552","rc":[{"trd":[[3.15,92.65]],"batb":[[0,3.15,22.31]],"ltp":3.15,"tv":455.99,"id":18286408}],"tv":1784.68}]}
{"op":"mcm","clk":"991079235","pt":1580501455379,"mc":[{"id":"1.168096552","rc":[{"trd":[[2.82,81.32]],"batl":[[0,2.82,8.39]],"ltp":2.82,"tv":747.61,"id":52106}],"tv":1795.54}]}
{"op":"mcm","clk":"991085069","pt":1580501492133,"mc":[{"id":"1.168096552","rc":[{"batl":[[0,3.2,12],[1,3.3,25],[2,3.4,30]],"ltp":3.15,"tv":455.99,"id":18286408}]}]}
{"op":"mcm","clk":"991089706","pt":1580501520110,"mc":[{"id":"1.168096552","rc":[{"trd":[[4.6,24.8],[4.7,8.83]],"batb":[[0,4.6,7.66]],"ltp":4.6,"tv":585.95,"id":21580749}],"tv":1805.54}]}
{"op":"mcm","clk":"991102251","pt":1580501596785,"mc":[{"id":"1.168096552","rc":[{"trd":[[3.15,96.01]],"batb":[[0,3.15,20.63]],"ltp":3.15,"tv":459.35,"id":18286408}],"tv":1808.9}]}
{"op":"mcm","clk":"991111108","pt":1580501650269,"mc":[{"id":"1.168096552","rc":[{"batb":[[0,4.6,9.34]],"ltp":4.6,"tv":585.95,"id":21580749}]}]}
{"op":"mcm","clk":"991126320","pt":1580501743432,"mc":[{"id":"1.168096552","rc":[{"batl":[[1,3.3,28]],"ltp":3.15,"tv":459.35,"id":18286408}]}]}
{"op":"mcm","clk":"991146661","pt":1580501867379,"mc":[{"id":"1.168096552","rc":[{"batb":[[1,4.3,8]],"ltp":4.6,"tv":585.95,"id":21580749}]}]}
{"op":"mcm","clk":"991150108","pt":1580501889501,"mc":[{"id":"1.168096552","rc":[{"batb":[[0,2.78,10.91],[1,2.76,26.68],[2,2.74,2.49]],"batl":[[0,2.8,2],[1,2.82,8.39],[2,2.84,16.99]],"ltp":2.82,"tv":747.61,"id":52106}]}]}
{"op":"mcm","clk":"991150203","pt":1580501890090,"mc":[{"id":"1.168096552","rc":[{"batl":[[1,15,2],[2,32,9]],"ltp":11.0,"tv":4.0,"id":26640937}]}]}
{"op":"mcm","clk":"991156341","pt":1580501929457,"mc":[{"id":"1.168096552","rc":[{"batb":[[0,2.76,26.68],[1,2.74,2.49],[2,2.64,18.93]],"batl":[[0,2.8,293.11]],"ltp":2.82,"tv":747.61,"id":52106}]}]}
{"op":"mcm","clk":"991156471","pt":1580501930369,"mc":[{"id":"1.168096552","rc":[{"batl":[[0,2.78,8.4],[1,2.8,293.11],[2,2.82,8.39]],"ltp":2.82,"tv":747.61,"id":52106}]}]}
{"op":"mcm","clk":"991159444","pt":1580501949006,"mc":[{"id":"1.168096552","marketDefinition":{"bspMarket":true,"turnInPlayEnabled":true,"persistenceEnabled":true,"marketBaseRate":5.0,"eventId":"29677422","eventTypeId":"7","numberOfWinners":1,"bettingType":"ODDS","marketType":"WIN","marketTime":"2020-02-01T12:40:00.000Z","suspendTime":"2020-02-01T12:40:00.000Z","bspReconciled":false,"complete":true,"inPlay":false,"crossMatching":false,"runnersVoidable":false,"numberOfActiveRunners":6,"betDelay":0,"status":"SUSPENDED","runners":[{"adjustmentFactor":33.3,"status":"ACTIVE","sortPriority":1,"id":18286408,"name":"Flic Ou Voyou"},{"adjustmentFactor":29.13,"status":"ACTIVE","sortPriority":2,"id":52106,"name":"Palladium"},{"adjustmentFactor":16.07,"status":"ACTIVE","sortPriority":3,"id":21580749,"name":"Golden Taipan"},{"adjustmentFactor":13.18,"status":"ACTIVE","sortPriority":4,"id":26640937,"name":"The Newest One"},{"adjustmentFactor":5.48,"status":"ACTIVE","sortPriority":5,"id":27706761,"name":"Kalakawa Enki"},{"adjustmentFactor":2.81,"status":"ACTIVE","sortPriority":6,"id":24608298,"name":"Vorashann"}],"regulators":["MR_INT"],"venue":"Sandown","countryCode":"GB","discountAllowed":true,"timezone":"Europe/London","openDate":"2020-02-01T12:40:00.000Z","version":3143797484,"name":"2m Nov Hrd","eventName":"Sand  1st Feb"}}]}
{"op":"mcm","clk":"991159548","pt":1580501949616,"mc":[{"id":"1.168096552","marketDefinition":{"bspMarket":true,"turnInPlayEnabled":true,"persistenceEnabled":true,"marketBaseRate":5.0,"eventId":"29677422","eventTypeId":"7","numberOfWinners":1,"bettingType":"ODDS","marketType":"WIN","marketTime":"2020-02-01T12:40:00.000Z","suspendTime":"2020-02-01T12:40:00.000Z","bspReconciled":false,"complete":true,"inPlay":false,"crossMatching":false,"runnersVoidable":false,"numberOfActiveRunners":6,"betDelay":0,"status":"OPEN","runners":[{"adjustmentFactor":29.13,"status":"ACTIVE","sortPriority":1,"id":52106,"name":"Palladium"},{"adjustmentFactor":33.3,"status":"ACTIVE","sortPriority":2,"id":18286408,"name":"Flic Ou Voyou"},{"adjustmentFactor":16.07,"status":"ACTIVE","sortPriority":3,"id":21580749,"name":"Golden Taipan"},{"adjustmentFactor":13.18,"status":"ACTIVE","sortPriority":4,"id":26640937,"name":"The Newest One"},{"adjustmentFactor":2.81,"status":"ACTIVE","sortPriority":5,"id":24608298,"name":"Vorashann"},{"adjustmentFactor":5.48,"status":"ACTIVE","sortPriority":6,"id":27706761,"name":"Kalakawa Enki"}],"regulators":["MR_INT"],"venue":"Sandown","countryCode":"GB","discountAllowed":true,"timezone":"Europe/London","openDate":"2020-02-01T12:40:00.000Z","version":3143797494,"name":"2m Nov Hrd","eventName":"Sand  1st Feb"}}]}
{"op":"mcm","clk":"991174980","pt":1580502047917,"mc":[{"id":"1.168096552","rc":[{"batl":[[1,2.8,2]],"ltp":2.82,"tv":747.61,"id":52106}]}]}
{"op":"mcm","clk":"991175103","pt":1580502048729,"mc":[{"id":"1.168096552","rc":[{"batl":[[0,2.8,2],[1,2.82,8.39],[2,2.84,16.99]],"ltp":2.82,"tv":747.61,"id":52106}]}]}
{"op":"mcm","clk":"991229083","pt":1580502354315,"mc":[{"id":"1.168096552","rc":[{"trd":[[2.8,42.24]],"batb":[[0,2.76,27.17],[1,2.64,18.93],[2,2.62,50]],"batl":[[0,2.82,8.39],[1,2.84,16.99],[2,2.86,22.21]],"ltp":2.8,"tv":751.61,"id":52106}],"tv":1812.9}]}
{"op":"mcm","clk":"991229381","pt":1580502356340,"mc":[{"id":"1.168096552","rc":[{"batb":[[0,2.76,29.17]],"ltp":2.8,"tv":751.61,"id":52106}]}]}
{"op":"mcm","clk":"991246118","pt":1580502470465,"mc":[{"id":"1.168096552","rc":[{"batl":[[2,5.5,20]],"ltp":4.6,"tv":585.95,"id":21580749}]}]}
{"op":"mcm","clk":"991270497","pt":1580502646434,"mc":[{"id":"1.168096552","rc":[{"batl":[[1,3.25,330],[2,3.3,28]],"ltp":3.15,"tv":459.35,"id":18286408}]}]}
{"op":"mcm","clk":"991270621","pt":1580502647126,"mc":[{"id":"1.168096552","rc":[{"batl":[[0,3.2,30.56]],"ltp":3.15,"tv":459.35,"id":18286408}]}]}
{"op":"mcm","clk":"991275117","pt":1580502679670,"mc":[{"id":"1.168096552","rc":[{"trd":[[3.15,100.01]],"batb":[[0,3.15,18.63]],"ltp":3.15,"tv":463.35,"id":18286408}],"tv":1816.9}]}
{"op":"mcm","clk":"991358239","pt":1580503202465,"mc":[{"id":"1.168096552","rc":[{"trd":[[4.6,42.8]],"batb":[[0,4.3,8.34],[1,4.2,18],[2,4,25.06]],"ltp":4.6,"tv":603.96,"id":21580749},{"trd":[[2.76,173.09],[2.8,43.22]],"batb":[[0,2.76,20.17]],"ltp":2.76,"tv":769.61,"id":52106}],"tv":1852.9}]}
{"op":"mcm","clk":"991358293","pt":1580503202890,"mc":[{"id":"1.168096552","rc":[{"trd":[[4.7,15.67]],"batl":[[0,4.7,5.15],[1,4.8,2],[2,5.3,9]],"ltp":4.7,"tv":610.8,"id":21580749},{"trd":[[2.76,179.09]],"batb":[[0,2.76,17.17]],"ltp":2.76,"tv":775.61,"id":52106}],"tv":1865.74}]}
{"op":"mcm","clk":"991365084","pt":1580503259144,"mc":[{"id":"1.168096552","rc":[{"trd":[[4.3,163.32],[4.4,44.68]],"batb":[[0,4.3,1.9],[2,4,33.6]],"batl":[[0,4.8,2],[1,5.3,9],[2,5.5,20]],"ltp":4.3,"tv":630.79,"id":21580749}],"tv":1885.74}]}
{"op":"mcm","clk":"991365281","pt":1580503260744,"mc":[{"id":"1.168096552","rc":[{"batb":[[2,4,28.38]],"ltp":4.3,"tv":630.79,"id":21580749}]}]}
{"op":"mcm","clk":"991365966","pt":1580503266328,"mc":[{"id":"1.168096552","rc":[{"batl":[[0,2.8,6],[1,2.82,8.39],[2,2.84,16.99]],"ltp":2.76,"tv":775.61,"id":52106}]}]}
{"op":"mcm","clk":"991369019","pt":1580503291351,"mc":[{"id":"1.168096552","rc":[{"trd":[[4.2,124],[4.3,167.12]],"batb":[[0,4,28.38],[1,3.35,1.93],[2,2.2,90]],"batl":[[0,4.8,2.1]],"ltp":4.2,"tv":670.59,"id":21580749}],"tv":1925.54}]}
{"op":"mcm","clk":"991370747","pt":1580503306387,"mc":[{"id":"1.168096552","rc":[{"batb":[[0,13.5,9.39]],"ltp":13.5,"tv":11.96,"id":24608298}]}]}
{"op":"mcm","clk":"991370835","pt":1580503307077,"mc":[{"id":"1.168096552","rc":[{"batb":[[0,13.5,9.75]],"ltp":13.5,"tv":11.96,"id":24608298}]}]}
{"op":"mcm","clk":"991371179","pt":1580503310008,"mc":[{"id":"1.168096552","rc":[{"batb":[[2,2.22,7.58]],"batl":[[1,5.2,3.23],[2,5.3,9]],"ltp":4.2,"tv":670.59,"id":21580749}]}]}
{"op":"mcm","clk":"991371770","pt":1580503314801,"mc":[{"id":"1.168096552","rc":[{"batl":[[1,5.1,7.72],[2,5.2,3.23]],"ltp":4.2,"tv":670.59,"id":21580749}]}]}
{"op":"mcm","clk":"991372530","pt":1580503321511,"mc":[{"id":"1.168096552","rc":[{"batb":[[0,4,25.06]],"ltp":4.2,"tv":670.59,"id":21580749}]}]}
{"op":"mcm","clk":"991375071","pt":1580503341818,"mc":[{"id":"1.168096552","rc":[{"batb":[[0,4.1,4.16],[1,4,25],[2,3.35,1.93]],"batl":[[1,5,2.45],[2,5.1,7.72]],"ltp":4.2,"tv":670.59,"id":21580749}]}]}
{"op":"mcm","clk":"991375860","pt":1580503348155,"mc":[{"id":"1.168096552","rc":[{"trd":[[4.2,124.2]],"batb":[[0,4.2,1.88],[1,4.1,4.16],[2,4,25]],"batl":[[0,4.8,2]],"ltp":4.2,"tv":670.79,"id":21580749}],"tv":1925.74}]}
{"op":"mcm","clk":"991376426","pt":1580503352936,"mc":[{"id":"1.168096552","rc":[{"batl":[[2,5.3,9]],"ltp":4.2,"tv":670.79,"id":21580749}]}]}
{"op":"mcm","clk":"991378910","pt":1580503373363,"mc":[{"id":"1.168096552","rc":[{"batb":[[0,4.3,1.68],[1,4.2,1.88],[2,4,25.06]],"batl":[[0,4.7,8.4],[1,4.8,2],[2,5,2.45]],"ltp":4.2,"tv":670.79,"id":21580749}]}]}
{"op":"mcm","clk":"991385295","pt":1580503426790,"mc":[{"id":"1.168096552","rc":[{"batb":[[1,2.7,100],[2,2.64,18.93]],"ltp":2.76,"tv":775.61,"id":52106}]}]}
{"op":"mcm","clk":"991385613","pt":1580503429212,"mc":[{"id":"1.168096552","rc":[{"trd":[[2.8,55.22]],"batb":[[0,2.76,17.32],[1,2.72,6],[2,2.7,100]],"batl":[[0,2.82,8.39],[1,2.84,16.99],[2,2.86,22.21]],"ltp":2.8,"tv":787.61,"id":52106}],"tv":1937.74}]}
{"op":"mcm","clk":"991385808","pt":1580503430903,"mc":[{"id":"1.168096552","rc":[{"batb":[[1,4.2,11.88]],"ltp":4.2,"tv":670.79,"id":21580749}]}]}
{"op":"mcm","clk":"991387039","pt":1580503440937,"mc":[{"id":"1.168096552","rc":[{"batb":[[0,10.5,8.14]],"ltp":11.0,"tv":4.0,"id":26640937}]}]}
{"op":"mcm","clk":"991387209","pt":1580503442214,"mc":[{"id":"1.168096552","rc":[{"batb":[[0,4.3,3.56],[1,4.2,10]],"ltp":4.2,"tv":670.79,"id":21580749}]}]}
{"op":"mcm","clk":"991389727","pt":1580503460751,"mc":[{"id":"1.168096552","rc":[{"batb":[[1,4.2,110]],"batl":[[0,4.8,2],[1,5,2.45],[2,5.3,9]],"ltp":4.2,"tv":670.79,"id":21580749}]}]}
{"op":"mcm","clk":"991390655","pt":1580503467756,"mc":[{"id":"1.168096552","rc":[{"batb":[[0,4.3,18.35]],"batl":[[1,5,14.17]],"ltp":4.2,"tv":670.79,"id":21580749}]}]}
{"op":"mcm","clk":"991395227","pt":1580503505395,"mc":[{"id":"1.168096552","rc":[{"trd":[[2.82,97.32]],"batl":[[0,2.84,17.39],[1,2.86,22.21],[2,2.98,15.35]],"ltp":2.82,"tv":803.61,"id":52106}],"tv":1953.73}]}
{"op":"mcm","clk":"991395349","pt":1580503506022,"mc":[{"id":"1.168096552","rc":[{"trd":[[2.82,98.1]],"batl":[[0,2.84,16.99]],"ltp":2.82,"tv":804.4,"id":52106}],"tv":1954.52}]}
{"op":"mcm","clk":"991395809","pt":1580503510108,"mc":[{"id":"1.168096552","rc":[{"batl":[[0,11.5,3],[1,12,75],[2,15,2]],"ltp":11.0,"tv":4.0,"id":26640937}]}]}
{"op":"mcm","clk":"991397025","pt":1580503520423,"mc":[{"id":"1.168096552","rc":[{"batb":[[0,2.76,17.17]],"ltp":2.82,"tv":804.4,"id":52106}]}]}
{"op":"mcm","clk":"991397038","pt":1580503520528,"mc":[{"id":"1.168096552","rc":[{"batb":[[0,2.76,17.32]],"ltp":2.82,"tv":804.4,"id":52106}]}]}
{"op":"mcm","clk":"991398589","pt":1580503533319,"mc":[{"id":"1.168096552","rc":[{"batb":[[0,2.8,10.15],[1,2.76,17.17],[2,2.72,6]],"ltp":2.82,"tv":804.4,"id":52106}]}]}
{"op":"mcm","clk":"991398868","pt":1580503535417,"mc":[{"id":"1.168096552","rc":[{"batb":[[0,2.8,11.83],[1,2.76,15.49]],"ltp":2.82,"tv":804.4,"id":52106}]}]}
{"op":"mcm","clk":"991417666","pt":1580503696286,"mc":[{"id":"1.168096552","rc":[{"batb":[[0,4.5,1.68],[1,4.3,18.35],[2,4.2,110]],"ltp":4.2,"tv":670.79,"id":21580749}]}]}
{"op":"mcm","clk":"991417786","pt":1580503697390,"mc":[{"id":"1.168096552","rc":[{"batb":[[0,4.3,18.35],[1,4.2,110],[2,4,25.06]],"ltp":4.2,"tv":670.79,"id":21580749}]}]}
{"op":"mcm","clk":"991428394","pt":1580503797700,"mc":[{"id":"1.168096552","rc":[{"batb":[[0,4.4,14.41],[1,4.3,18.35],[2,4.2,110]],"ltp":4.2,"tv":670.79,"id":21580749},{"batb":[[0,29,6.17]],"ltp":0.0,"tv":0.0,"id":27706761},{"batb":[[0,14,4.89],[1,13.5,9.39],[2,13,2]],"ltp":13.5,"tv":11.96,"id":24608298}]}]}
{"op":"mcm","clk":"991432261","pt":1580503833956,"mc":[{"id":"1.168096552","rc":[{"batb":[[0,14.5,1.64],[1,14,4.89],[2,13.5,9.39]],"ltp":13.5,"tv":11.96,"id":24608298}]}]}
{"op":"mcm","clk":"991434371","pt":1580503855511,"mc":[{"id":"1.168096552","rc":[{"batb":[[0,4.4,16.29],[1,4.3,16.47]],"ltp":4.2,"tv":670.79,"id":21580749},{"batb":[[0,14.5,3.62],[2,13.5,7.41]],"ltp":13.5,"tv":11.96,"id":24608298}]}]}
{"op":"mcm","clk":"991434449","pt":1580503856197,"mc":[{"id":"1.168096552","rc":[{"batb":[[0,14.5,3.95],[1,14,4.53]],"ltp":13.5,"tv":11.96,"id":24608298}]}]}
{"op":"mcm","clk":"991436084","pt":1580503871438,"mc":[{"id":"1.168096552","rc":[{"batb":[[1,13.5,7.41],[2,13,2]],"ltp":13.5,"tv":11.96,"id":24608298}]}]}
{"op":"mcm","clk":"991436092","pt":1580503871542,"mc":[{"id":"1.168096552","rc":[{"batb":[[0,14.5,8.32]],"ltp":13.5,"tv":11.96,"id":24608298}]}]}
{"op":"mcm","clk":"991441658","pt":1580503924575,"mc":[{"id":"1.168096552","rc":[{"batl":[[0,4.6,2],[1,4.8,2],[2,5,14.17]],"ltp":4.2,"tv":670.79,"id":21580749}]}]}
{"op":"mcm","clk":"991442726","pt":1580503934394,"mc":[{"id":"1.168096552","rc":[{"batb":[[0,4.4,1.88]],"ltp":4.2,"tv":670.79,"id":21580749}]}]}
{"op":"mcm","clk":"991444010","pt":1580503947128,"mc":[{"id":"1.168096552","rc":[{"batb":[[1,13,2],[2,9.2,4.59]],"ltp":13.5,"tv":11.96,"id":24608298}]}]}
{"op":"mcm","clk":"991454553","pt":1580503954427,"mc":[{"id":"1.168096552","rc":[{"batb":[[0,29,4.17]],"ltp":0.0,"tv":0.0,"id":27706761}]}]}
{"op":"mcm","clk":"991454643","pt":1580503955319,"mc":[{"id":"1.168096552","rc":[{"batl":[[0,11,2],[1,11.5,3],[2,12,75]],"ltp":11.0,"tv":4.0,"id":26640937},{"batb":[[1,4.2,110],[2,4,25.06]],"batl":[[2,5.3,9]],"ltp":4.2,"tv":670.79,"id":21580749},{"batb":[[0,30,2],[1,29,4.17],[2,20,2.59]],"ltp":0.0,"tv":0.0,"id":27706761}]}]}
{"op":"mcm","clk":"991455233","pt":1580503960454,"mc":[{"id":"1.168096552","rc":[{"batb":[[1,4.3,6],[2,4.2,110]],"ltp":4.2,"tv":670.79,"id":21580749},{"batb":[[2,20,2.56]],"ltp":0.0,"tv":0.0,"id":27706761}]}]}
{"op":"mcm","clk":"991455297","pt":1580503961053,"mc":[{"id":"1.168096552","rc":[{"batb":[[1,29,4.2]],"ltp":0.0,"tv":0.0,"id":27706761}]}]}
{"op":"mcm","clk":"991456956","pt":1580503976041,"mc":[{"id":"1.168096552","rc":[{"trd":[[2.84,64.8]],"batl":[[0,2.84,14]],"ltp":2.84,"tv":810.39,"id":52106}],"tv":1960.52}]}
{"op":"mcm","clk":"991457488","pt":1580503981452,"mc":[{"id":"1.168096552","rc":[{"trd":[[2.8,58.92],[2.82,98.4]],"batb":[[0,2.8,9.83]],"ltp":2.8,"tv":814.39,"id":52106}],"tv":1964.52}]}
{"op":"mcm","clk":"991457799","pt":1580503984465,"mc":[{"id":"1.168096552","rc":[{"trd":[[2.84,86.26]],"batb":[[0,2.82,34],[1,2.8,9.83],[2,2.76,15.49]],"batl":[[0,2.84,3.26]],"ltp":2.84,"tv":835.86,"id":52106}],"tv":1985.98}]}
{"op":"mcm","clk":"991457862","pt":1580503985092,"mc":[{"id":"1.168096552","rc":[{"trd":[[2.84,92.79]],"batl":[[0,2.86,22.21],[1,2.98,15.35],[2,3,33.61]],"ltp":2.84,"tv":842.38,"id":52106}],"tv":1992.5}]}
{"op":"mcm","clk":"991457944","pt":1580503985887,"mc":[{"id":"1.168096552","rc":[{"batl":[[1,2.98,19.21]],"ltp":2.84,"tv":842.38,"id":52106}]}]}
{"op":"mcm","clk":"991462267","pt":1580504036432,"mc":[{"id":"1.168096552","rc":[{"batl":[[1,2.9,60],[2,2.98,19.21]],"ltp":2.84,"tv":842.38,"id":52106}]}]}
{"op":"mcm","clk":"991463097","pt":1580504046474,"mc":[{"id":"1.168096552","rc":[{"batb":[[0,32,1.98],[1,30,2],[2,29,2.22]],"ltp":0.0,"tv":0.0,"id":27706761},{"batb":[[0,2.82,35.68],[1,2.8,8.15]],"batl":[[0,2.84,10.75],[1,2.86,22.21],[2,2.9,60]],"ltp":2.84,"tv":842.38,"id":52106}]}]}
{"op":"mcm","clk":"991463254","pt":1580504048262,"mc":[{"id":"1.168096552","rc":[{"batb":[[2,29,2.19]],"ltp":0.0,"tv":0.0,"id":27706761}]}]}
{"op":"mcm","clk":"991463352","pt":1580504049384,"mc":[{"id":"1.168096552","rc":[{"batb":[[1,30,2.03]],"ltp":0.0,"tv":0.0,"id":27706761}]}]}
{"op":"mcm","clk":"991464278","pt":1580504059000,"mc":[{"id":"1.168096552","rc":[{"batl":[[1,2.86,82.21],[2,2.98,15.35]],"ltp":2.84,"tv":842.38,"id":52106}]}]}
{"op":"mcm","clk":"991464575","pt":1580504062402,"mc":[{"id":"1.168096552","rc":[{"batb":[[1,30,4.14],[2,20,2.56]],"ltp":0.0,"tv":0.0,"id":27706761}]}]}
{"op":"mcm","clk":"991465693","pt":1580504076388,"mc":[{"id":"1.168096552","rc":[{"batl":[[0,2.84,70.75],[1,2.86,22.21]],"ltp":2.84,"tv":842.38,"id":52106}]}]}
{"op":"mcm","clk":"991466544","pt":1580504090355,"mc":[{"id":"1.168096552","rc":[{"trd":[[2.82,169.76]],"batb":[[0,2.8,8.15],[1,2.76,15.49],[2,2.72,6]],"batl":[[0,2.82,24.32],[1,2.84,10.75],[2,2.86,22.21]],"ltp":2.82,"tv":913.74,"id":52106}],"tv":2063.86}]}
{"op":"mcm","clk":"991469266","pt":1580504140603,"mc":[{"id":"1.168096552","rc":[{"batb":[[0,2.8,9.83]],"ltp":2.82,"tv":913.74,"id":52106}]}]}
{"op":"mcm","clk":"991471037","pt":1580504171452,"mc":[{"id":"1.168096552","rc":[{"trd":[[3.15,112.01]],"batb":[[0,3.15,12.63]],"ltp":3.15,"tv":475.35,"id":18286408}],"tv":2075.86}]}
{"op":"mcm","clk":"991472726","pt":1580504200488,"mc":[{"id":"1.168096552","rc":[{"trd":[[10.5,16.28]],"batb":[[0,10,2.47],[1,9.6,2.18],[2,7,25.69]],"batl":[[0,10.5,1.86],[1,11,2],[2,11.5,3]],"ltp":10.5,"tv":20.28,"id":26640937}],"tv":2092.15}]}
{"op":"mcm","clk":"991475018","pt":1580504233338,"mc":[{"id":"1.168096552","rc":[{"batb":[[0,10,4.99]],"ltp":10.5,"tv":20.28,"id":26640937}]}]}
{"op":"mcm","clk":"991475076","pt":1580504234125,"mc":[{"id":"1.168096552","rc":[{"batb":[[2,8,2]],"ltp":10.5,"tv":20.28,"id":26640937}]}]}
{"op":"mcm","clk":"991475818","pt":1580504244463,"mc":[{"id":"1.168096552","rc":[{"trd":[[2.8,78.58]],"batb":[[0,2.76,15.49],[1,2.72,6],[2,2.7,100]],"batl":[[0,2.8,90.17],[1,2.82,24.32],[2,2.84,10.75]],"ltp":2.8,"tv":933.4,"id":52106}],"tv":2111.81}]}
{"op":"mcm","clk":"991477712","pt":1580504270386,"mc":[{"id":"1.168096552","rc":[{"trd":[[4.6,46.8]],"batb":[[0,4.6,3],[1,4.4,1.88],[2,4.3,6]],"batl":[[0,4.8,2],[1,5.3,9],[2,5.5,20]],"ltp":4.6,"tv":674.79,"id":21580749}],"tv":2115.81}]}
{"op":"mcm","clk":"991478672","pt":1580504284316,"mc":[{"id":"1.168096552","rc":[{"batb":[[0,3.15,21.03]],"ltp":3.15,"tv":475.35,"id":18286408},{"batb":[[0,2.78,5.04],[1,2.76,15.49],[2,2.72,6]],"ltp":2.8,"tv":933.4,"id":52106}]}]}
{"op":"mcm","clk":"991478746","pt":1580504285435,"mc":[{"id":"1.168096552","rc":[{"batb":[[0,4.4,1.88],[1,4.3,6],[2,4.2,110]],"ltp":4.6,"tv":674.79,"id":21580749},{"batb":[[0,14.5,3.95]],"ltp":13.5,"tv":11.96,"id":24608298}]}]}
{"op":"mcm","clk":"991478793","pt":1580504286122,"mc":[{"id":"1.168096552","rc":[{"trd":[[4.8,8]],"batb":[[0,4.8,1],[1,4.6,13.78],[2,4.4,1.88]],"batl":[[0,5.2,7.84]],"ltp":4.8,"tv":678.79,"id":21580749}],"tv":2119.81}]}
{"op":"mcm","clk":"991479238","pt":1580504292741,"mc":[{"id":"1.168096552","rc":[{"batb":[[1,4.7,4.2],[2,4.6,13.78]],"batl":[[0,5.3,9],[1,5.5,20],[2,6,2.5]],"ltp":4.8,"tv":678.79,"id":21580749}]}]}
{"op":"mcm","clk":"991480106","pt":1580504305755,"mc":[{"id":"1.168096552","rc":[{"batl":[[1,5.4,3.86],[2,5.5,20]],"ltp":4.8,"tv":678.79,"id":21580749}]}]}
{"op":"mcm","clk":"991481895","pt":1580504330267,"mc":[{"id":"1.168096552","rc":[{"batb":[[0,4.8,2.88]],"ltp":4.8,"tv":678.79,"id":21580749}]}]}
{"op":"mcm","clk":"991482050","pt":1580504332481,"mc":[{"id":"1.168096552","rc":[{"batb":[[0,4.8,16.09],[2,4.4,4.75]],"batl":[[0,5.2,7.84],[1,5.3,9],[2,5.4,3.86]],"ltp":4.8,"tv":678.79,"id":21580749},{"batb":[[1,30,2.03]],"ltp":0.0,"tv":0.0,"id":27706761}]}]}
{"op":"mcm","clk":"991483133","pt":1580504348419,"mc":[{"id":"1.168096552","rc":[{"batb":[[0,4.8,2.88]],"ltp":4.8,"tv":678.79,"id":21580749}]}]}
{"op":"mcm","clk":"991483387","pt":1580504351803,"mc":[{"id":"1.168096552","rc":[{"batb":[[1,4.4,4.75],[2,4.3,6]],"ltp":4.8,"tv":678.79,"id":21580749}]}]}
{"op":"mcm","clk":"991486529","pt":1580504396314,"mc":[{"id":"1.168096552","rc":[{"batb":[[1,30,4.14]],"ltp":0.0,"tv":0.0,"id":27706761},{"trd":[[2.78,110.22]],"batb":[[0,2.76,15.49],[1,2.72,6],[2,2.7,100]],"batl":[[0,2.78,4.96],[1,2.8,90.17],[2,2.82,24.32]],"ltp":2.78,"tv":943.48,"id":52106}],"tv":2129.89}]}
{"op":"mcm","clk":"991488517","pt":1580504416046,"mc":[{"id":"1.168096552","rc":[{"batl":[[2,5.4,23.86]],"ltp":4.8,"tv":678.79,"id":21580749}]}]}
{"op":"mcm","clk":"991489015","pt":1580504422163,"mc":[{"id":"1.168096552","rc":[{"batb":[[0,4.8,1],[1,4.5,1.88],[2,4.4,4.75]],"ltp":4.8,"tv":678.79,"id":21580749}]}]}
{"op":"mcm","clk":"991489543","pt":1580504428352,"mc":[{"id":"1.168096552","rc":[{"batb":[[1,4.5,15.97]],"ltp":4.8,"tv":678.79,"id":21580749}]}]}
{"op":"mcm","clk":"991489996","pt":1580504433461,"mc":[{"id":"1.168096552","rc":[{"batl":[[0,5.1,4.09],[1,5.2,7.84],[2,5.3,9]],"ltp":4.8,"tv":678.79,"id":21580749}]}]}
{"op":"mcm","clk":"991490832","pt":1580504444285,"mc":[{"id":"1.168096552","rc":[{"batb":[[0,14.5,8.32]],"ltp":13.5,"tv":11.96,"id":24608298}]}]}
{"op":"mcm","clk":"991490913","pt":1580504445374,"mc":[{"id":"1.168096552","rc":[{"batb":[[1,4.6,5.04],[2,4.5,15.97]],"ltp":4.8,"tv":678.79,"id":21580749}]}]}
{"op":"mcm","clk":"991492018","pt":1580504460418,"mc":[{"id":"1.168096552","rc":[{"batb":[[2,4.5,1.88]],"ltp":4.8,"tv":678.79,"id":21580749},{"batb":[[0,14.5,3.95]],"ltp":13.5,"tv":11.96,"id":24608298}]}]}
{"op":"mcm","clk":"991492666","pt":1580504467712,"mc":[{"id":"1.168096552","rc":[{"batb":[[1,4.5,1.88],[2,4.4,4.75]],"ltp":4.8,"tv":678.79,"id":21580749}]}]}
{"op":"mcm","clk":"991493363","pt":1580504476338,"mc":[{"id":"1.168096552","rc":[{"batb":[[1,4.5,15.97]],"ltp":4.8,"tv":678.79,"id":21580749},{"batb":[[0,14.5,8.32]],"ltp":13.5,"tv":11.96,"id":24608298}]}]}
{"op":"mcm","clk":"991495616","pt":1580504504072,"mc":[{"id":"1.168096552","rc":[{"batb":[[0,2.76,20.53]],"ltp":2.78,"tv":943.48,"id":52106}]}]}
{"op":"mcm","clk":"991497187","pt":1580504524318,"mc":[{"id":"1.168096552","rc":[{"trd":[[2.72,12],[2.76,220.15]],"batb":[[0,2.7,100],[1,2.64,24.72],[2,2.62,50]],"batl":[[0,2.72,44.9],[1,2.78,4.96],[2,2.8,90.17]],"ltp":2.72,"tv":996.54,"id":52106}],"tv":2182.94}]}
{"op":"mcm","clk":"991497485","pt":1580504528318,"mc":[{"id":"1.168096552","rc":[{"batl":[[0,2.72,50.9]],"ltp":2.72,"tv":996.54,"id":52106}]}]}
{"op":"mcm","clk":"991497646","pt":1580504530492,"mc":[{"id":"1.168096552","rc":[{"trd":[[3.15,152.01]],"batb":[[0,3.15,1.03],[2,3.05,19.51]],"ltp":3.15,"tv":515.35,"id":18286408}],"tv":2222.94}]}
{"op":"mcm","clk":"991498759","pt":1580504547460,"mc":[{"id":"1.168096552","rc":[{"batb":[[2,3.05,16.17]],"ltp":3.15,"tv":515.35,"id":18286408},{"batb":[[1,2.64,18.93]],"ltp":2.72,"tv":996.54,"id":52106}]}]}
{"op":"mcm","clk":"991500465","pt":1580504570993,"mc":[{"id":"1.168096552","rc":[{"trd":[[10,4]],"batb":[[0,10,2.98]],"ltp":10.0,"tv":24.28,"id":26640937}],"tv":2226.94}]}
{"op":"mcm","clk":"991500508","pt":1580504571560,"mc":[{"id":"1.168096552","rc":[{"trd":[[2.72,56.44]],"batl":[[0,2.72,28.68]],"ltp":2.72,"tv":1040.98,"id":52106}],"tv":2271.38}]}
{"op":"mcm","clk":"991500894","pt":1580504576881,"mc":[{"id":"1.168096552","rc":[{"batb":[[2,8.4,3]],"ltp":10.0,"tv":24.28,"id":26640937}]}]}
{"op":"mcm","clk":"991500984","pt":1580504578280,"mc":[{"id":"1.168096552","rc":[{"batb":[[1,4.6,5.04],[2,4.5,15.97]],"ltp":4.8,"tv":678.79,"id":21580749}]}]}
{"op":"mcm","clk":"991501126","pt":1580504580414,"mc":[{"id":"1.168096552","rc":[{"batl":[[0,2.72,6],[2,2.82,24.32]],"ltp":2.72,"tv":1040.98,"id":52106}]}]}
{"op":"mcm","clk":"991501462","pt":1580504585484,"mc":[{"id":"1.168096552","rc":[{"batl":[[0,2.76,6]],"ltp":2.72,"tv":1040.98,"id":52106}]}]}
{"op":"mcm","clk":"991501579","pt":1580504587305,"mc":[{"id":"1.168096552","rc":[{"batb":[[2,4.5,1.88]],"ltp":4.8,"tv":678.79,"id":21580749}]}]}
{"op":"mcm","clk":"991501799","pt":1580504590511,"mc":[{"id":"1.168096552","rc":[{"batb":[[1,4.5,1.88],[2,4.4,4.75]],"ltp":4.8,"tv":678.79,"id":21580749}]}]}
{"op":"mcm","clk":"991501860","pt":1580504591394,"mc":[{"id":"1.168096552","rc":[{"batb":[[2,4.4,7.75]],"ltp":4.8,"tv":678.79,"id":21580749}]}]}
{"op":"mcm","clk":"991502056","pt":1580504593999,"mc":[{"id":"1.168096552","rc":[{"batl":[[0,5,2],[1,5.1,4.09],[2,5.2,7.84]],"ltp":4.8,"tv":678.79,"id":21580749}]}]}
{"op":"mcm","clk":"991502494","pt":1580504599520,"mc":[{"id":"1.168096552","rc":[{"batl":[[0,4.9,2],[1,5,2],[2,5.1,4.09]],"ltp":4.8,"tv":678.79,"id":21580749}]}]}
{"op":"mcm","clk":"991502873","pt":1580504604358,"mc":[{"id":"1.168096552","rc":[{"trd":[[2.7,100]],"batb":[[0,2.7,50]],"ltp":2.7,"tv":1140.98,"id":52106}],"tv":2371.38}]}
{"op":"mcm","clk":"991503293","pt":1580504609450,"mc":[{"id":"1.168096552","rc":[{"batb":[[1,3.1,19.75]],"ltp":3.15,"tv":515.35,"id":18286408},{"batb":[[0,9.8,2.98]],"ltp":10.0,"tv":24.28,"id":26640937},{"batb":[[0,2.7,52.03]],"ltp":2.7,"tv":1140.98,"id":52106}]}]}
{"op":"mcm","clk":"991503308","pt":1580504609553,"mc":[{"id":"1.168096552","rc":[{"batb":[[2,8.6,2.61]],"ltp":10.0,"tv":24.28,"id":26640937}]}]}
{"op":"mcm","clk":"991504493","pt":1580504625481,"mc":[{"id":"1.168096552","rc":[{"trd":[[2.76,232.15],[2.78,114.22]],"batb":[[0,2.72,3],[1,2.7,52.03],[2,2.64,18.93]],"batl":[[0,2.78,2.96],[1,2.82,24.32],[2,2.86,22.21]],"ltp":2.78,"tv":1156.98,"id":52106}],"tv":2387.38}]}
{"op":"mcm","clk":"991504594","pt":1580504626481,"mc":[{"id":"1.168096552","rc":[{"batb":[[2,8.4,3]],"ltp":10.0,"tv":24.28,"id":26640937},{"trd":[[2.7,204.06],[2.72,62.44],[2.78,120.14],[2.8,84.32]],"batb":[[0,2.64,18.93],[1,2.62,50],[2,2.52,18.93]],"batl":[[0,2.7,7.82],[1,2.8,8],[2,2.82,24.32]],"ltp":2.7,"tv":1278.7,"id":52106}],"tv":2509.11}]}
{"op":"mcm","clk":"991504624","pt":1580504626746,"mc":[{"id":"1.168096552","rc":[{"batb":[[0,2.66,2.84],[1,2.64,18.93],[2,2.62,50]],"batl":[[1,2.82,24.32],[2,2.86,22.21]],"ltp":2.7,"tv":1278.7,"id":52106}]}]}
{"op":"mcm","clk":"991505333","pt":1580504635390,"mc":[{"id":"1.168096552","rc":[{"batb":[[1,4.5,15.97]],"ltp":4.8,"tv":678.79,"id":21580749}]}]}
{"op":"mcm","clk":"991505420","pt":1580504636484,"mc":[{"id":"1.168096552","rc":[{"batb":[[0,2.66,9.56]],"ltp":2.7,"tv":1278.7,"id":52106}]}]}
{"op":"mcm","clk":"991505838","pt":1580504641774,"mc":[{"id":"1.168096552","rc":[{"batb":[[2,4.4,4.75]],"ltp":4.8,"tv":678.79,"id":21580749}]}]}
{"op":"mcm","clk":"991507341","pt":1580504658235,"mc":[{"id":"1.168096552","rc":[{"batb":[[0,32,2.52]],"ltp":0.0,"tv":0.0,"id":27706761},{"batb":[[0,15,1.48],[1,14.5,7.99],[2,13,2]],"ltp":13.5,"tv":11.96,"id":24608298}]}]}
{"op":"mcm","clk":"991507890","pt":1580504664822,"mc":[{"id":"1.168096552","rc":[{"batl":[[1,11,77]],"ltp":10.0,"tv":24.28,"id":26640937}]}]}
{"op":"mcm","clk":"991508074","pt":1580504667420,"mc":[{"id":"1.168096552","rc":[{"batb":[[1,14.5,3.62]],"ltp":13.5,"tv":11.96,"id":24608298}]}]}
{"op":"mcm","clk":"991508138","pt":1580504668355,"mc":[{"id":"1.168096552","rc":[{"batb":[[0,15,5.71]],"ltp":13.5,"tv":11.96,"id":24608298}]}]}
{"op":"mcm","clk":"991508314","pt":1580504670324,"mc":[{"id":"1.168096552","rc":[{"batb":[[1,3.1,25.49]],"ltp":3.15,"tv":515.35,"id":18286408},{"batb":[[0,10,2.25],[1,9.8,2.52],[2,9.6,2.18]],"ltp":10.0,"tv":24.28,"id":26640937},{"batb":[[1,4.6,3.87],[2,4.5,15.97]],"ltp":4.8,"tv":678.79,"id":21580749},{"batb":[[0,2.68,6.65],[1,2.66,9.56],[2,2.64,18.93]],"ltp":2.7,"tv":1278.7,"id":52106},{"batb":[[0,15.5,1.15],[1,15,5.71],[2,14.5,3.62]],"ltp":13.5,"tv":11.96,"id":24608298}]}]}
{"op":"mcm","clk":"991508918","pt":1580504678063,"mc":[{"id":"1.168096552","rc":[{"trd":[[3.15,154.07]],"batb":[[0,3.1,25.49],[1,3.05,16.17],[2,3,49]],"batl":[[0,3.2,31.53]],"ltp":3.15,"tv":517.41,"id":18286408}],"tv":2511.17}]}
{"op":"mcm","clk":"991509106","pt":1580504680363,"mc":[{"id":"1.168096552","rc":[{"trd":[[3.1,156]],"batb":[[0,3.1,5.49],[2,3,46]],"ltp":3.1,"tv":557.41,"id":18286408},{"batb":[[1,15,9.07]],"ltp":13.5,"tv":11.96,"id":24608298}],"tv":2551.17}]}
{"op":"mcm","clk":"991509398","pt":1580504683439,"mc":[{"id":"1.168096552","rc":[{"batl":[[0,3.15,2.97],[1,3.2,30.56],[2,3.25,330]],"ltp":3.1,"tv":557.41,"id":18286408},{"batb":[[1,4.6,17.65],[2,4.5,1.88]],"ltp":4.8,"tv":678.79,"id":21580749},{"batb":[[0,2.68,30.3]],"ltp":2.7,"tv":1278.7,"id":52106},{"batb":[[0,15.5,5.24],[1,15,4.84]],"ltp":13.5,"tv":11.96,"id":24608298}]}]}
{"op":"mcm","clk":"991509483","pt":1580504684480,"mc":[{"id":"1.168096552","rc":[{"trd":[[4.6,64.81],[4.8,10]],"batb":[[0,4.6,8.65],[1,4.5,1.88],[2,4.4,4.75]],"ltp":4.6,"tv":698.8,"id":21580749},{"batb":[[0,15.5,5.55],[1,15,4.51]],"ltp":13.5,"tv":11.96,"id":24608298}],"tv":2571.17}]}
{"op":"mcm","clk":"991510052","pt":1580504691255,"mc":[{"id":"1.168096552","rc":[{"batb":[[0,4.6,12.01]],"ltp":4.6,"tv":698.8,"id":21580749}]}]}
{"op":"mcm","clk":"991510148","pt":1580504692456,"mc":[{"id":"1.168096552","rc":[{"batb":[[0,10,4.25]],"ltp":10.0,"tv":24.28,"id":26640937}]}]}
{"op":"mcm","clk":"991510645","pt":1580504698495,"mc":[{"id":"1.168096552","rc":[{"batb":[[0,3.1,46.4]],"ltp":3.1,"tv":557.41,"id":18286408},{"batb":[[0,4.6,3.36],[1,4.5,24.81]],"ltp":4.6,"tv":698.8,"id":21580749},{"batb":[[0,2.68,6.65]],"ltp":2.7,"tv":1278.7,"id":52106},{"batb":[[0,15.5,9.64]],"ltp":13.5,"tv":11.96,"id":24608298}]}]}
{"op":"mcm","clk":"991510681","pt":1580504698817,"mc":[{"id":"1.168096552","rc":[{"batb":[[1,30,6.25]],"ltp":0.0,"tv":0.0,"id":27706761}]}]}
{"op":"mcm","clk":"991511003","pt":1580504702400,"mc":[{"id":"1.168096552","rc":[{"batb":[[0,3.1,48.08]],"ltp":3.1,"tv":557.41,"id":18286408},{"batb":[[0,10,6.77],[1,9.6,2.18],[2,8.4,3]],"ltp":10.0,"tv":24.28,"id":26640937},{"batb":[[0,4.6,5.24],[1,4.5,22.93]],"ltp":4.6,"tv":698.8,"id":21580749},{"batb":[[0,2.68,10.15]],"ltp":2.7,"tv":1278.7,"id":52106},{"batb":[[0,16,2.29],[1,15.5,9.33],[2,15,4.51]],"ltp":13.5,"tv":11.96,"id":24608298}]}]}
{"op":"mcm","clk":"991512014","pt":1580504714425,"mc":[{"id":"1.168096552","rc":[{"batb":[[0,3.1,7.17]],"ltp":3.1,"tv":557.41,"id":18286408}]}]}
{"op":"mcm","clk":"991512026","pt":1580504714528,"mc":[{"id":"1.168096552","rc":[{"trd":[[2.7,219.7]],"batb":[[0,2.7,39.14],[1,2.68,10.15],[2,2.66,9.56]],"batl":[[0,2.82,24.32],[1,2.86,22.21],[2,2.98,15.35]],"ltp":2.7,"tv":1294.34,"id":52106}],"tv":2586.81}]}
{"op":"mcm","clk":"991512841","pt":1580504725323,"mc":[{"id":"1.168096552","rc":[{"batl":[[0,2.8,4],[1,2.82,24.32],[2,2.86,22.21]],"ltp":2.7,"tv":1294.34,"id":52106}]}]}
{"op":"mcm","clk":"991513263","pt":1580504730427,"mc":[{"id":"1.168096552","rc":[{"batb":[[1,4.4,4.75],[2,4.3,6]],"ltp":4.6,"tv":698.8,"id":21580749},{"batb":[[0,2.68,10.15],[1,2.66,9.56],[2,2.64,18.93]],"ltp":2.7,"tv":1294.34,"id":52106}]}]}
{"op":"mcm","clk":"991513489","pt":1580504733241,"mc":[{"id":"1.168096552","rc":[{"batb":[[0,4.6,1.88],[1,4.3,6],[2,4.2,110]],"batl":[[2,5.3,9]],"ltp":4.6,"tv":698.8,"id":21580749}]}]}
{"op":"mcm","clk":"991514240","pt":1580504741773,"mc":[{"id":"1.168096552","rc":[{"batb":[[1,4.4,3],[2,4.3,6]],"ltp":4.6,"tv":698.8,"id":21580749}]}]}
{"op":"mcm","clk":"991514387","pt":1580504743461,"mc":[{"id":"1.168096552","rc":[{"batb":[[0,2.7,3.36],[1,2.68,10.15]],"batl":[[0,2.78,8.03],[1,2.8,4],[2,2.82,24.32]],"ltp":2.7,"tv":1294.34,"id":52106}]}]}
{"op":"mcm","clk":"991514619","pt":1580504746370,"mc":[{"id":"1.168096552","rc":[{"batb":[[1,4.4,26.45]],"ltp":4.6,"tv":698.8,"id":21580749}]}]}
{"op":"mcm","clk":"991515189","pt":1580504752795,"mc":[{"id":"1.168096552","rc":[{"batb":[[0,2.7,14.11]],"ltp":2.7,"tv":1294.34,"id":52106}]}]}
{"op":"mcm","clk":"991516733","pt":1580504773403,"mc":[{"id":"1.168096552","rc":[{"batb":[[0,3.1,14.73]],"ltp":3.1,"tv":557.41,"id":18286408}]}]}
{"op":"mcm","clk":"991517488","pt":1580504783444,"mc":[{"id":"1.168096552","rc":[{"batb":[[0,16,5.65],[2,15,1.15]],"ltp":13.5,"tv":11.96,"id":24608298}]}]}
{"op":"mcm","clk":"991518389","pt":1580504794444,"mc":[{"id":"1.168096552","rc":[{"batb":[[0,4.5,1.88]],"ltp":4.6,"tv":698.8,"id":21580749},{"batb":[[0,2.7,17.61],[1,2.68,6.65]],"ltp":2.7,"tv":1294.34,"id":52106},{"batb":[[1,15.5,1.15]],"ltp":13.5,"tv":11.96,"id":24608298}]}]}
{"op":"mcm","clk":"991518477","pt":1580504795433,"mc":[{"id":"1.168096552","rc":[{"batb":[[0,16.5,7.97],[1,16,5.34],[2,15.5,1.15]],"ltp":13.5,"tv":11.96,"id":24608298}]}]}
{"op":"mcm","clk":"991519629","pt":1580504809173,"mc":[{"id":"1.168096552","rc":[{"batb":[[1,4.4,23.45]],"ltp":4.6,"tv":698.8,"id":21580749}]}]}
{"op":"mcm","clk":"991519840","pt":1580504811364,"mc":[{"id":"1.168096552","rc":[{"batb":[[0,2.7,6.86]],"ltp":2.7,"tv":1294.34,"id":52106}]}]}
{"op":"mcm","clk":"991521091","pt":1580504825412,"mc":[{"id":"1.168096552","rc":[{"batb":[[0,4.5,9.44]],"ltp":4.6,"tv":698.8,"id":21580749}]}]}
{"op":"mcm","clk":"991521170","pt":1580504826409,"mc":[{"id":"1.168096552","rc":[{"batb":[[1,4.3,6],[2,4.2,110]],"ltp":4.6,"tv":698.8,"id":21580749}]}]}
{"op":"mcm","clk":"991522072","pt":1580504836503,"mc":[{"id":"1.168096552","rc":[{"batb":[[0,4.5,1.88]],"ltp":4.6,"tv":698.8,"id":21580749}]}]}
{"op":"mcm","clk":"991522523","pt":1580504841324,"mc":[{"id":"1.168096552","rc":[{"trd":[[2.78,136.2]],"batb":[[0,2.78,2.4],[1,2.7,6.86],[2,2.68,6.65]],"batl":[[0,2.8,4],[1,2.82,24.32],[2,2.86,22.21]],"ltp":2.78,"tv":1310.4,"id":52106}],"tv":2602.87}]}
{"op":"mcm","clk":"991522626","pt":1580504842434,"mc":[{"id":"1.168096552","rc":[{"batb":[[1,4.4,26.45],[2,4.3,6]],"ltp":4.6,"tv":698.8,"id":21580749},{"trd":[[2.78,141]],"batb":[[0,2.7,6.86],[1,2.68,6.65],[2,2.64,18.93]],"batl":[[0,2.78,23.14],[1,2.8,4],[2,2.82,24.32]],"ltp":2.78,"tv":1315.2,"id":52106}],"tv":2607.68}]}
{"op":"mcm","clk":"991533352","pt":1580504855861,"mc":[{"id":"1.168096552","rc":[{"batl":[[2,5.1,20]],"ltp":4.6,"tv":698.8,"id":21580749}]}]}
{"op":"mcm","clk":"991533934","pt":1580504863474,"mc":[{"id":"1.168096552","rc":[{"batb":[[1,4.4,23.45]],"ltp":4.6,"tv":698.8,"id":21580749}]}]}
{"op":"mcm","clk":"991535852","pt":1580504888418,"mc":[{"id":"1.168096552","rc":[{"trd":[[3.1,160]],"batb":[[0,3.1,12.73]],"ltp":3.1,"tv":561.42,"id":18286408},{"batb":[[0,17,2.27],[1,16.5,7.68],[2,16,3.36]],"ltp":13.5,"tv":11.96,"id":24608298}],"tv":2611.68}]}
{"op":"mcm","clk":"991535944","pt":1580504889479,"mc":[{"id":"1.168096552","rc":[{"batl":[[0,65,1.68]],"ltp":0.0,"tv":0.0,"id":27706761},{"batl":[[0,290,9]],"ltp":13.5,"tv":11.96,"id":24608298}]}]}
{"op":"mcm","clk":"991536035","pt":1580504890491,"mc":[{"id":"1.168096552","rc":[{"batl":[[0,4.8,2],[1,4.9,2],[2,5,2]],"ltp":4.6,"tv":698.8,"id":21580749}]}]}
{"op":"mcm","clk":"991536518","pt":1580504896507,"mc":[{"id":"1.168096552","rc":[{"batl":[[0,980,9],[1,980,0]],"ltp":0.0,"tv":0.0,"id":27706761}]}]}
{"op":"mcm","clk":"991536543","pt":1580504896821,"mc":[{"id":"1.168096552","rc":[{"batl":[[0,970,1.68],[1,980,9]],"ltp":0.0,"tv":0.0,"id":27706761}]}]}
{"op":"mcm","clk":"991537209","pt":1580504905509,"mc":[{"id":"1.168096552","rc":[{"batb":[[0,2.72,11.04],[1,2.7,46],[2,2.68,6.65]],"ltp":2.78,"tv":1315.2,"id":52106}]}]}
{"op":"mcm","clk":"991537763","pt":1580504912012,"mc":[{"id":"1.168096552","rc":[{"batb":[[0,2.74,3.36],[1,2.72,11.04],[2,2.7,42.65]],"ltp":2.78,"tv":1315.2,"id":52106}]}]}
{"op":"mcm","clk":"991538297","pt":1580504918429,"mc":[{"id":"1.168096552","rc":[{"batl":[[1,2.82,24.32],[2,2.86,22.21]],"ltp":2.78,"tv":1315.2,"id":52106}]}]}
{"op":"mcm","clk":"991538574","pt":1580504921349,"mc":[{"id":"1.168096552","rc":[{"batb":[[2,2.7,3.5]],"ltp":2.78,"tv":1315.2,"id":52106}]}]}
{"op":"mcm","clk":"991539618","pt":1580504933258,"mc":[{"id":"1.168096552","rc":[{"batb":[[0,4.5,9.44]],"ltp":4.6,"tv":698.8,"id":21580749}]}]}
{"op":"mcm","clk":"991540001","pt":1580504937484,"mc":[{"id":"1.168096552","rc":[{"trd":[[3.15,160.01]],"batb":[[0,3.15,37.29],[1,3.1,12.73],[2,3.05,16.17]],"batl":[[0,3.2,30.56],[1,3.25,330],[2,3.3,28]],"ltp":3.15,"tv":567.35,"id":18286408},{"batb":[[0,4.6,22.43],[1,4.5,9.44]],"ltp":4.6,"tv":698.8,"id":21580749}],"tv":2617.62}]}
{"op":"mcm","clk":"991540443","pt":1580504942375,"mc":[{"id":"1.168096552","rc":[{"batb":[[2,3.05,20.17]],"ltp":3.15,"tv":567.35,"id":18286408}]}]}
{"op":"mcm","clk":"991541013","pt":1580504948886,"mc":[{"id":"1.168096552","rc":[{"batl":[[0,10.5,3.86],[1,11,75]],"ltp":10.0,"tv":24.28,"id":26640937}]}]}
{"op":"mcm","clk":"991541451","pt":1580504953471,"mc":[{"id":"1.168096552","rc":[{"batb":[[0,3.1,12.73],[1,3.05,23.38],[2,3,49]],"ltp":3.15,"tv":567.35,"id":18286408}]}]}
{"op":"mcm","clk":"991542035","pt":1580504959488,"mc":[{"id":"1.168096552","rc":[{"batb":[[1,3.05,20.17]],"ltp":3.15,"tv":567.35,"id":18286408},{"trd":[[10,8.01],[10.5,20]],"batb":[[0,10,4.76]],"batl":[[0,11,75],[1,11.5,3],[2,15,2]],"ltp":10.5,"tv":32.01,"id":26640937}],"tv":2625.34}]}
{"op":"mcm","clk":"991542243","pt":1580504961415,"mc":[{"id":"1.168096552","rc":[{"batb":[[2,8.4,3.13]],"batl":[[1,11.5,3.08]],"ltp":10.5,"tv":32.01,"id":26640937}]}]}
{"op":"mcm","clk":"991542329","pt":1580504962193,"mc":[{"id":"1.168096552","rc":[{"batb":[[2,7,25.82]],"ltp":10.5,"tv":32.01,"id":26640937}]}]}
{"op":"mcm","clk":"991542915","pt":1580504968608,"mc":[{"id":"1.168096552","rc":[{"batl":[[0,10.5,3],[1,11,75],[2,15,2.08]],"ltp":10.5,"tv":32.01,"id":26640937}]}]}
{"op":"mcm","clk":"991544033","pt":1580504984811,"mc":[{"id":"1.168096552","rc":[{"batb":[[0,4.6,24.32],[1,4.5,7.56]],"ltp":4.6,"tv":698.8,"id":21580749},{"batb":[[0,2.74,6.86],[2,2.68,6.65]],"ltp":2.78,"tv":1315.2,"id":52106}]}]}
{"op":"mcm","clk":"991545741","pt":1580505008172,"mc":[{"id":"1.168096552","rc":[{"batl":[[0,970,1.88]],"ltp":0.0,"tv":0.0,"id":27706761},{"batl":[[0,290,9.2]],"ltp":13.5,"tv":11.96,"id":24608298}]}]}
{"op":"mcm","clk":"991546994","pt":1580505026512,"mc":[{"id":"1.168096552","rc":[{"trd":[[2.76,242.15],[2.78,147]],"batl":[[0,2.78,20.14]],"ltp":2.78,"tv":1331.2,"id":52106}],"tv":2641.34}]}
{"op":"mcm","clk":"991547012","pt":1580505026718,"mc":[{"id":"1.168096552","rc":[{"trd":[[2.78,151]],"batl":[[0,2.78,18.14]],"ltp":2.78,"tv":1335.2,"id":52106}],"tv":2645.34}]}
{"op":"mcm","clk":"991547466","pt":1580505033316,"mc":[{"id":"1.168096552","rc":[{"batb":[[0,2.76,6.24],[1,2.74,6.86],[2,2.72,11.04]],"ltp":2.78,"tv":1335.2,"id":52106},{"batb":[[0,17,3.29]],"ltp":13.5,"tv":11.96,"id":24608298}]}]}
{"op":"mcm","clk":"991547974","pt":1580505040430,"mc":[{"id":"1.168096552","rc":[{"batb":[[0,4.7,7.56],[1,4.6,24.32],[2,4.5,7.56]],"ltp":4.6,"tv":698.8,"id":21580749},{"batb":[[0,17,6.65]],"ltp":13.5,"tv":11.96,"id":24608298}]}]}
{"op":"mcm","clk":"991548004","pt":1580505040742,"mc":[{"id":"1.168096552","rc":[{"batb":[[2,4.3,6]],"ltp":4.6,"tv":698.8,"id":21580749},{"batb":[[2,15.5,1.15]],"ltp":13.5,"tv":11.96,"id":24608298}]}]}
{"op":"mcm","clk":"991548507","pt":1580505047235,"mc":[{"id":"1.168096552","rc":[{"batl":[[0,2.78,21.08]],"ltp":2.78,"tv":1335.2,"id":52106}]}]}
{"op":"mcm","clk":"991548661","pt":1580505049428,"mc":[{"id":"1.168096552","rc":[{"batb":[[1,4.6,1.88]],"ltp":4.6,"tv":698.8,"id":21580749},{"batb":[[0,17.5,7.25],[1,17,6.65]],"ltp":13.5,"tv":11.96,"id":24608298}]}]}
{"op":"mcm","clk":"991548721","pt":1580505050261,"mc":[{"id":"1.168096552","rc":[{"batb":[[0,17.5,7.53],[1,17,6.36]],"ltp":13.5,"tv":11.96,"id":24608298}]}]}
{"op":"mcm","clk":"991548762","pt":1580505050945,"mc":[{"id":"1.168096552","rc":[{"batb":[[0,4.6,1.88],[1,4.3,6],[2,4.2,110]],"ltp":4.6,"tv":698.8,"id":21580749}]}]}
{"op":"mcm","clk":"991549345","pt":1580505058342,"mc":[{"id":"1.168096552","rc":[{"batb":[[2,13,2]],"ltp":13.5,"tv":11.96,"id":24608298}]}]}
{"op":"mcm","clk":"991549902","pt":1580505065397,"mc":[{"id":"1.168096552","rc":[{"batb":[[0,17,6.64],[1,13,2],[2,9.2,4.59]],"ltp":13.5,"tv":11.96,"id":24608298}]}]}
{"op":"mcm","clk":"991549970","pt":1580505066294,"mc":[{"id":"1.168096552","rc":[{"batb":[[1,4.4,23.45],[2,4.3,6]],"ltp":4.6,"tv":698.8,"id":21580749}]}]}
{"op":"mcm","clk":"991550296","pt":1580505070101,"mc":[{"id":"1.168096552","rc":[{"batb":[[1,4.5,3],[2,4.4,23.45]],"ltp":4.6,"tv":698.8,"id":21580749},{"batb":[[0,17.5,2.65],[1,17,6.36],[2,13,2]],"ltp":13.5,"tv":11.96,"id":24608298}]}]}
{"op":"mcm","clk":"991550480","pt":1580505072298,"mc":[{"id":"1.168096552","rc":[{"batb":[[1,17,3]],"ltp":13.5,"tv":11.96,"id":24608298}]}]}
{"op":"mcm","clk":"991551221","pt":1580505081502,"mc":[{"id":"1.168096552","rc":[{"batb":[[2,4.3,6]],"ltp":4.6,"tv":698.8,"id":21580749}]}]}
{"op":"mcm","clk":"991551285","pt":1580505082490,"mc":[{"id":"1.168096552","rc":[{"batb":[[0,17.5,9.9]],"ltp":13.5,"tv":11.96,"id":24608298}]}]}
{"op":"mcm","clk":"991552037","pt":1580505093215,"mc":[{"id":"1.168096552","rc":[{"batb":[[0,3.15,5.47],[1,3.1,12.73],[2,3.05,20.17]],"ltp":3.15,"tv":567.35,"id":18286408},{"batb":[[1,4.4,3]],"ltp":4.6,"tv":698.8,"id":21580749}]}]}
{"op":"mcm","clk":"991555169","pt":1580505138509,"mc":[{"id":"1.168096552","rc":[{"batb":[[0,2.76,12.24]],"ltp":2.78,"tv":1335.2,"id":52106}]}]}
{"op":"mcm","clk":"991555868","pt":1580505147515,"mc":[{"id":"1.168096552","rc":[{"batl":[[2,5.1,20]],"ltp":4.6,"tv":698.8,"id":21580749}]}]}
{"op":"mcm","clk":"991556211","pt":1580505151610,"mc":[{"id":"1.168096552","rc":[{"batl":[[1,5.1,20],[2,5.3,9]],"ltp":4.6,"tv":698.8,"id":21580749}]}]}
{"op":"mcm","clk":"991556927","pt":1580505160319,"mc":[{"id":"1.168096552","rc":[{"batb":[[1,4.4,26.45]],"ltp":4.6,"tv":698.8,"id":21580749}]}]}
{"op":"mcm","clk":"991557609","pt":1580505169752,"mc":[{"id":"1.168096552","rc":[{"batb":[[0,3.15,7.15],[1,3.1,11.05]],"ltp":3.15,"tv":567.35,"id":18286408},{"batb":[[0,4.5,1.88]],"ltp":4.6,"tv":698.8,"id":21580749},{"batb":[[0,2.76,15.74],[1,2.74,3.36]],"ltp":2.78,"tv":1335.2,"id":52106},{"batb":[[0,18,2.26],[1,17.5,9.62],[2,17,1.02]],"ltp":13.5,"tv":11.96,"id":24608298}]}]}
{"op":"mcm","clk":"991557905","pt":1580505173240,"mc":[{"id":"1.168096552","rc":[{"batb":[[0,4.5,11.12]],"ltp":4.6,"tv":698.8,"id":21580749},{"batb":[[0,18,5.62]],"ltp":13.5,"tv":11.96,"id":24608298}]}]}
{"op":"mcm","clk":"991558123","pt":1580505176442,"mc":[{"id":"1.168096552","rc":[{"batb":[[0,4.6,22.43],[1,4.5,11.12],[2,4.4,3]],"ltp":4.6,"tv":698.8,"id":21580749},{"batb":[[0,18.5,6.85],[1,18,5.62],[2,17.5,2.37]],"ltp":13.5,"tv":11.96,"id":24608298}]}]}
{"op":"mcm","clk":"991558201","pt":1580505177336,"mc":[{"id":"1.168096552","rc":[{"batb":[[0,18.5,7.11],[1,18,5.34]],"ltp":13.5,"tv":11.96,"id":24608298}]}]}
{"op":"mcm","clk":"991558948","pt":1580505187464,"mc":[{"id":"1.168096552","rc":[{"batb":[[2,4.3,6]],"ltp":4.6,"tv":698.8,"id":21580749}]}]}
{"op":"mcm","clk":"991560092","pt":1580505202580,"mc":[{"id":"1.168096552","rc":[{"trd":[[4.6,84.81]],"batb":[[0,4.6,12.43]],"ltp":4.6,"tv":718.8,"id":21580749}],"tv":2665.34}]}
{"op":"mcm","clk":"991560552","pt":1580505208780,"mc":[{"id":"1.168096552","rc":[{"batb":[[1,4.5,1.88]],"ltp":4.6,"tv":718.8,"id":21580749}]}]}
{"op":"mcm","clk":"991561728","pt":1580505224414,"mc":[{"id":"1.168096552","rc":[{"batb":[[0,4.5,1.88],[1,4.3,6],[2,4.2,110]],"ltp":4.6,"tv":718.8,"id":21580749}]}]}
{"op":"mcm","clk":"991561736","pt":1580505224523,"mc":[{"id":"1.168096552","rc":[{"batb":[[1,4.4,13],[2,4.3,6]],"ltp":4.6,"tv":718.8,"id":21580749}]}]}
{"op":"mcm","clk":"991568522","pt":1580505315268,"mc":[{"id":"1.168096552","rc":[{"batb":[[0,19,2.24],[1,18.5,6.85],[2,18,3.36]],"ltp":13.5,"tv":11.96,"id":24608298}]}]}
{"op":"mcm","clk":"991568647","pt":1580505317256,"mc":[{"id":"1.168096552","rc":[{"batb":[[0,4.5,6.08]],"ltp":4.6,"tv":718.8,"id":21580749}]}]}
{"op":"mcm","clk":"991568820","pt":1580505319452,"mc":[{"id":"1.168096552","rc":[{"batb":[[0,4.6,12.43],[1,4.5,6.08]],"ltp":4.6,"tv":718.8,"id":21580749}]}]}
{"op":"mcm","clk":"991569737","pt":1580505332775,"mc":[{"id":"1.168096552","rc":[{"trd":[[4.6,94.81]],"batb":[[0,4.6,7.43]],"ltp":4.6,"tv":728.8,"id":21580749}],"tv":2675.34}]}
{"op":"mcm","clk":"991571797","pt":1580505365121,"mc":[{"id":"1.168096552","rc":[{"trd":[[3.15,174.31]],"batb":[[0,3.1,11.05],[1,3.05,20.17],[2,3,49]],"batl":[[0,3.15,25.85],[1,3.2,30.56],[2,3.25,330]],"ltp":3.15,"tv":581.65,"id":18286408}],"tv":2689.64}]}
{"op":"mcm","clk":"991571872","pt":1580505366211,"mc":[{"id":"1.168096552","rc":[{"batb":[[0,19,3.15]],"ltp":13.5,"tv":11.96,"id":24608298}]}]}
{"op":"mcm","clk":"991571981","pt":1580505367422,"mc":[{"id":"1.168096552","rc":[{"batb":[[1,18,3.36],[2,17.5,2.37]],"ltp":13.5,"tv":11.96,"id":24608298}]}]}
{"op":"mcm","clk":"991571988","pt":1580505367527,"mc":[{"id":"1.168096552","rc":[{"batb":[[0,19,9.82]],"ltp":13.5,"tv":11.96,"id":24608298}]}]}
{"op":"mcm","clk":"991572767","pt":1580505378174,"mc":[{"id":"1.168096552","rc":[{"trd":[[2.78,161.88]],"batl":[[0,2.78,15.63]],"ltp":2.78,"tv":1346.09,"id":52106}],"tv":2700.53}]}
{"op":"mcm","clk":"991577578","pt":1580505444864,"mc":[{"id":"1.168096552","rc":[{"batl":[[0,5,8.06]],"ltp":4.6,"tv":728.8,"id":21580749}]}]}
{"op":"mcm","clk":"991577769","pt":1580505447378,"mc":[{"id":"1.168096552","rc":[{"batb":[[0,4.5,6.08],[1,4.3,6],[2,4.2,110]],"ltp":4.6,"tv":728.8,"id":21580749}]}]}
{"op":"mcm","clk":"991578140","pt":1580505452258,"mc":[{"id":"1.168096552","rc":[{"batb":[[0,4.5,1.88]],"ltp":4.6,"tv":728.8,"id":21580749}]}]}
{"op":"mcm","clk":"991578655","pt":1580505458124,"mc":[{"id":"1.168096552","rc":[{"batb":[[0,4.4,1.88]],"batl":[[0,5.1,20],[1,5.3,9],[2,6,2.5]],"ltp":4.6,"tv":728.8,"id":21580749}]}]}
{"op":"mcm","clk":"991579114","pt":1580505463302,"mc":[{"id":"1.168096552","rc":[{"batb":[[0,4.4,11.7]],"batl":[[1,5.2,1.74],[2,5.3,9]],"ltp":4.6,"tv":728.8,"id":21580749}]}]}
{"op":"mcm","clk":"991579325","pt":1580505465644,"mc":[{"id":"1.168096552","rc":[{"batb":[[0,4.5,3],[1,4.4,11.7],[2,4.3,6]],"ltp":4.6,"tv":728.8,"id":21580749}]}]}
{"op":"mcm","clk":"991580575","pt":1580505479452,"mc":[{"id":"1.168096552","rc":[{"batb":[[0,4.5,10.59],[1,4.4,3.94]],"ltp":4.6,"tv":728.8,"id":21580749}]}]}
{"op":"mcm","clk":"991580860","pt":1580505482445,"mc":[{"id":"1.168096552","rc":[{"batl":[[0,5,2],[1,5.1,20],[2,5.2,1.74]],"ltp":4.6,"tv":728.8,"id":21580749}]}]}
{"op":"mcm","clk":"991581391","pt":1580505488445,"mc":[{"id":"1.168096552","rc":[{"batb":[[0,4.5,7.59]],"ltp":4.6,"tv":728.8,"id":21580749}]}]}
{"op":"mcm","clk":"991581872","pt":1580505494394,"mc":[{"id":"1.168096552","rc":[{"batb":[[0,4.4,3.94],[1,4.3,6],[2,4.2,110]],"ltp":4.6,"tv":728.8,"id":21580749}]}]}
{"op":"mcm","clk":"991581915","pt":1580505494761,"mc":[{"id":"1.168096552","rc":[{"batb":[[0,4.4,17.98]],"batl":[[2,5.2,13.62]],"ltp":4.6,"tv":728.8,"id":21580749}]}]}
{"op":"mcm","clk":"991582168","pt":1580505497575,"mc":[{"id":"1.168096552","rc":[{"batl":[[0,4.9,2],[1,5,2],[2,5.1,20]],"ltp":4.6,"tv":728.8,"id":21580749}]}]}
{"op":"mcm","clk":"991583102","pt":1580505510306,"mc":[{"id":"1.168096552","rc":[{"batb":[[0,4.5,7.59],[1,4.4,17.98],[2,4.3,6]],"ltp":4.6,"tv":728.8,"id":21580749}]}]}
{"op":"mcm","clk":"991583579","pt":1580505515514,"mc":[{"id":"1.168096552","rc":[{"trd":[[3.1,164]],"batb":[[0,3.1,9.05]],"ltp":3.1,"tv":585.65,"id":18286408}],"tv":2704.53}]}
{"op":"mcm","clk":"991584148","pt":1580505522319,"mc":[{"id":"1.168096552","rc":[{"batb":[[2,3,46]],"ltp":3.1,"tv":585.65,"id":18286408},{"trd":[[2.78,193.15],[2.82,211.22]],"batl":[[0,2.82,3.59],[1,2.86,22.21],[2,2.98,15.35]],"ltp":2.82,"tv":1418.81,"id":52106}],"tv":2777.25}]}
{"op":"mcm","clk":"991584174","pt":1580505522628,"mc":[{"id":"1.168096552","rc":[{"trd":[[2.82,218.4]],"batl":[[0,2.86,22.21],[1,2.98,15.35],[2,3,33.61]],"ltp":2.82,"tv":1425.99,"id":52106}],"tv":2784.43}]}
{"op":"mcm","clk":"991584306","pt":1580505524451,"mc":[{"id":"1.168096552","rc":[{"batl":[[1,2.98,19.12]],"ltp":2.82,"tv":1425.99,"id":52106}]}]}
{"op":"mcm","clk":"991584411","pt":1580505526025,"mc":[{"id":"1.168096552","rc":[{"batl":[[2,990,2]],"ltp":0.0,"tv":0.0,"id":27706761},{"batl":[[1,990,2]],"ltp":13.5,"tv":11.96,"id":24608298}]}]}
{"op":"mcm","clk":"991584518","pt":1580505527434,"mc":[{"id":"1.168096552","rc":[{"batb":[[0,2.78,5.04],[1,2.76,15.74]],"ltp":2.82,"tv":1425.99,"id":52106}]}]}
{"op":"mcm","clk":"991585183","pt":1580505536373,"mc":[{"id":"1.168096552","rc":[{"batl":[[1,5.1,20],[2,5.2,13.62]],"ltp":4.6,"tv":728.8,"id":21580749}]}]}
{"op":"mcm","clk":"991585340","pt":1580505538466,"mc":[{"id":"1.168096552","rc":[{"batb":[[0,2.78,10.14]],"ltp":2.82,"tv":1425.99,"id":52106}]}]}
{"op":"mcm","clk":"991586381","pt":1580505552189,"mc":[{"id":"1.168096552","rc":[{"batl":[[0,3.15,55.85]],"ltp":3.1,"tv":585.65,"id":18286408},{"batl":[[2,990,2.33]],"ltp":0.0,"tv":0.0,"id":27706761},{"batl":[[1,990,2.33]],"ltp":13.5,"tv":11.96,"id":24608298}]}]}
{"op":"mcm","clk":"991586544","pt":1580505554288,"mc":[{"id":"1.168096552","rc":[{"batb":[[0,2.8,6.36],[1,2.78,10.14],[2,2.76,15.74]],"ltp":2.82,"tv":1425.99,"id":52106}]}]}
{"op":"mcm","clk":"991587261","pt":1580505564427,"mc":[{"id":"1.168096552","rc":[{"batb":[[0,4.5,15.99]],"ltp":4.6,"tv":728.8,"id":21580749}]}]}
{"op":"mcm","clk":"991587729","pt":1580505570498,"mc":[{"id":"1.168096552","rc":[{"batl":[[2,990,0.33]],"ltp":0.0,"tv":0.0,"id":27706761},{"batl":[[1,990,0.33]],"ltp":13.5,"tv":11.96,"id":24608298}]}]}
{"op":"mcm","clk":"991588069","pt":1580505574423,"mc":[{"id":"1.168096552","rc":[{"batb":[[0,4.5,8.4]],"ltp":4.6,"tv":728.8,"id":21580749}]}]}
{"op":"mcm","clk":"991588078","pt":1580505574526,"mc":[{"id":"1.168096552","rc":[{"batb":[[0,4.6,7.43],[1,4.5,8.4],[2,4.4,17.98]],"ltp":4.6,"tv":728.8,"id":21580749}]}]}
{"op":"mcm","clk":"991589125","pt":1580505590070,"mc":[{"id":"1.168096552","rc":[{"batb":[[2,4.4,1.88]],"batl":[[2,5.3,9]],"ltp":4.6,"tv":728.8,"id":21580749}]}]}
{"op":"mcm","clk":"991589632","pt":1580505598189,"mc":[{"id":"1.168096552","rc":[{"batb":[[0,4.6,9.31],[2,4.3,6]],"ltp":4.6,"tv":728.8,"id":21580749},{"batb":[[0,2.8,9.86],[2,2.76,12.24]],"ltp":2.82,"tv":1425.99,"id":52106}]}]}
{"op":"mcm","clk":"991589844","pt":1580505601301,"mc":[{"id":"1.168096552","rc":[{"batb":[[1,4.3,6],[2,4.2,110]],"ltp":4.6,"tv":728.8,"id":21580749}]}]}
{"op":"mcm","clk":"991590830","pt":1580505612477,"mc":[{"id":"1.168096552","rc":[{"batb":[[0,4.6,1.88],[1,4.4,7.77],[2,4.3,6]],"batl":[[1,5,8.06],[2,5.1,20]],"ltp":4.6,"tv":728.8,"id":21580749}]}]}
{"op":"mcm","clk":"991591447","pt":1580505618194,"mc":[{"id":"1.168096552","rc":[{"batb":[[1,4.5,3],[2,4.4,7.77]],"ltp":4.6,"tv":728.8,"id":21580749}]}]}
{"op":"mcm","clk":"991591905","pt":1580505624501,"mc":[{"id":"1.168096552","rc":[{"batl":[[0,970,2.21],[2,990,0]],"ltp":0.0,"tv":0.0,"id":27706761},{"batl":[[0,290,9.53],[1,990,0]],"ltp":13.5,"tv":11.96,"id":24608298}]}]}
{"op":"mcm","clk":"991592159","pt":1580505627490,"mc":[{"id":"1.168096552","rc":[{"batl":[[0,970,2.01]],"ltp":0.0,"tv":0.0,"id":27706761},{"batl":[[0,290,9.33]],"ltp":13.5,"tv":11.96,"id":24608298}]}]}
{"op":"mcm","clk":"991592169","pt":1580505627594,"mc":[{"id":"1.168096552","rc":[{"batl":[[0,970,2.21]],"ltp":0.0,"tv":0.0,"id":27706761},{"batl":[[0,290,9.53]],"ltp":13.5,"tv":11.96,"id":24608298}]}]}
{"op":"mcm","clk":"991592904","pt":1580505636420,"mc":[{"id":"1.168096552","rc":[{"batl":[[0,950,9.53],[1,970,1.68]],"ltp":0.0,"tv":0.0,"id":27706761}]}]}
{"op":"mcm","clk":"991593231","pt":1580505640342,"mc":[{"id":"1.168096552","rc":[{"trd":[[3.15,193.67]],"batl":[[0,3.15,46.17]],"ltp":3.15,"tv":605.01,"id":18286408}],"tv":2803.79}]}
{"op":"mcm","clk":"991593393","pt":1580505642430,"mc":[{"id":"1.168096552","rc":[{"batb":[[2,3,49]],"ltp":3.15,"tv":605.01,"id":18286408}]}]}
{"op":"mcm","clk":"991593963","pt":1580505648430,"mc":[{"id":"1.168096552","rc":[{"batb":[[0,2.8,14.96],[1,2.78,5.04]],"ltp":2.82,"tv":1425.99,"id":52106}]}]}
{"op":"mcm","clk":"991594332","pt":1580505652346,"mc":[{"id":"1.168096552","rc":[{"batb":[[0,2.82,4.2],[1,2.8,14.96],[2,2.78,5.04]],"ltp":2.82,"tv":1425.99,"id":52106}]}]}
{"op":"mcm","clk":"991594356","pt":1580505652554,"mc":[{"id":"1.168096552","rc":[{"batb":[[2,2.76,12.24]],"ltp":2.82,"tv":1425.99,"id":52106}]}]}
{"op":"mcm","clk":"991594523","pt":1580505654429,"mc":[{"id":"1.168096552","rc":[{"batl":[[0,940,2.21],[1,950,9]],"ltp":0.0,"tv":0.0,"id":27706761}]}]}
{"op":"mcm","clk":"991595720","pt":1580505667263,"mc":[{"id":"1.168096552","rc":[{"batb":[[1,2.8,9.86]],"ltp":2.82,"tv":1425.99,"id":52106}]}]}
{"op":"mcm","clk":"991596154","pt":1580505672380,"mc":[{"id":"1.168096552","rc":[{"trd":[[2.86,56.4]],"batl":[[0,2.86,17.21]],"ltp":2.86,"tv":1435.99,"id":52106}],"tv":2813.79}]}
{"op":"mcm","clk":"991597971","pt":1580505693207,"mc":[{"id":"1.168096552","rc":[{"batb":[[0,2.82,7.7],[1,2.8,6.36]],"ltp":2.86,"tv":1435.99,"id":52106}]}]}
{"op":"mcm","clk":"991599057","pt":1580505705443,"mc":[{"id":"1.168096552","rc":[{"trd":[[4.5,202.22],[4.6,98.57]],"batb":[[0,4.4,7.77],[1,4.3,6],[2,4.2,110]],"batl":[[0,4.5,5.12],[1,4.9,2]],"ltp":4.5,"tv":738.56,"id":21580749},{"batl":[[1,2.98,15.35]],"ltp":2.86,"tv":1435.99,"id":52106}],"tv":2823.56}]}
{"op":"mcm","clk":"991599697","pt":1580505711469,"mc":[{"id":"1.168096552","rc":[{"batb":[[0,4.3,6],[1,4.2,110],[2,4,25.06]],"ltp":4.5,"tv":738.56,"id":21580749}]}]}
{"op":"mcm","clk":"991599798","pt":1580505712456,"mc":[{"id":"1.168096552","rc":[{"trd":[[3.15,268.23]],"batl":[[0,3.15,8.9]],"ltp":3.15,"tv":679.57,"id":18286408}],"tv":2898.11}]}
{"op":"mcm","clk":"991600160","pt":1580505715753,"mc":[{"id":"1.168096552","rc":[{"batb":[[0,4.3,37.92]],"ltp":4.5,"tv":738.56,"id":21580749}]}]}
{"op":"mcm","clk":"991615458","pt":1580505782431,"mc":[{"id":"1.168096552","rc":[{"batb":[[0,2.84,6.06],[1,2.82,7.7],[2,2.8,6.36]],"ltp":2.86,"tv":1435.99,"id":52106}]}]}
{"op":"mcm","clk":"991615779","pt":1580505786246,"mc":[{"id":"1.168096552","rc":[{"batb":[[0,4.3,40.81]],"ltp":4.5,"tv":738.56,"id":21580749},{"batb":[[0,2.84,9.57],[1,2.82,4.2]],"ltp":2.86,"tv":1435.99,"id":52106}]}]}
{"op":"mcm","clk":"991616212","pt":1580505791260,"mc":[{"id":"1.168096552","rc":[{"batl":[[0,920,9.53],[1,940,1.68]],"ltp":0.0,"tv":0.0,"id":27706761},{"trd":[[2.86,90.83]],"batb":[[0,2.86,19.74],[1,2.84,9.57],[2,2.82,4.2]],"batl":[[0,2.98,15.35],[1,3,33.61],[2,3.1,4]],"ltp":2.86,"tv":1470.43,"id":52106}],"tv":2932.55}]}
{"op":"mcm","clk":"991616312","pt":1580505792452,"mc":[{"id":"1.168096552","rc":[{"batl":[[0,2.96,4],[1,2.98,15.35],[2,3,40.89]],"ltp":2.86,"tv":1470.43,"id":52106}]}]}
{"op":"mcm","clk":"991616939","pt":1580505800481,"mc":[{"id":"1.168096552","rc":[{"batb":[[0,2.88,5.88],[1,2.86,19.74],[2,2.84,9.57]],"ltp":2.86,"tv":1470.43,"id":52106}]}]}
{"op":"mcm","clk":"991618137","pt":1580505815207,"mc":[{"id":"1.168096552","rc":[{"batl":[[0,910,2.21],[1,920,9]],"ltp":0.0,"tv":0.0,"id":27706761}]}]}
{"op":"mcm","clk":"991618667","pt":1580505821513,"mc":[{"id":"1.168096552","rc":[{"batl":[[2,3,33.61]],"ltp":2.86,"tv":1470.43,"id":52106}]}]}
{"op":"mcm","clk":"991620429","pt":1580505842457,"mc":[{"id":"1.168096552","rc":[{"batb":[[0,4.4,3.91],[1,4.3,40.81],[2,4.2,110]],"ltp":4.5,"tv":738.56,"id":21580749}]}]}
{"op":"mcm","clk":"991621514","pt":1580505854413,"mc":[{"id":"1.168096552","rc":[{"batb":[[1,2.84,9.57],[2,2.8,6.36]],"ltp":2.86,"tv":1470.43,"id":52106}]}]}
{"op":"mcm","clk":"991622038","pt":1580505860507,"mc":[{"id":"1.168096552","rc":[{"batb":[[0,2.84,9.57],[1,2.8,6.36],[2,2.76,6]],"ltp":2.86,"tv":1470.43,"id":52106}]}]}
{"op":"mcm","clk":"991623514","pt":1580505878492,"mc":[{"id":"1.168096552","rc":[{"batb":[[2,2.78,3.98]],"batl":[[0,2.94,3.76],[1,2.96,4],[2,2.98,15.35]],"ltp":2.86,"tv":1470.43,"id":52106}]}]}
{"op":"mcm","clk":"991623806","pt":1580505882206,"mc":[{"id":"1.168096552","rc":[{"batb":[[0,4.4,6.8],[1,4.3,37.92]],"ltp":4.5,"tv":738.56,"id":21580749}]}]}
{"op":"mcm","clk":"991624144","pt":1580505886425,"mc":[{"id":"1.168096552","rc":[{"trd":[[4.5,212.46]],"batb":[[0,4.5,2.47],[1,4.4,6.8],[2,4.3,37.92]],"batl":[[0,4.9,2],[1,5.1,20],[2,5.3,9]],"ltp":4.5,"tv":748.81,"id":21580749}],"tv":2942.79}]}
{"op":"mcm","clk":"991625090","pt":1580505898461,"mc":[{"id":"1.168096552","rc":[{"batb":[[2,4.3,6]],"batl":[[1,5,8.06],[2,5.1,20]],"ltp":4.5,"tv":748.81,"id":21580749},{"batl":[[0,2.92,4],[1,2.94,3.76]],"ltp":2.86,"tv":1470.43,"id":52106}]}]}
{"op":"mcm","clk":"991625110","pt":1580505898672,"mc":[{"id":"1.168096552","rc":[{"batl":[[1,5,10.76]],"ltp":4.5,"tv":748.81,"id":21580749},{"batb":[[0,2.86,10.64],[1,2.84,9.57],[2,2.8,6.36]],"ltp":2.86,"tv":1470.43,"id":52106}]}]}
{"op":"mcm","clk":"991625407","pt":1580505902444,"mc":[{"id":"1.168096552","rc":[{"batb":[[1,30,2.03]],"ltp":0.0,"tv":0.0,"id":27706761}]}]}
{"op":"mcm","clk":"991625977","pt":1580505910065,"mc":[{"id":"1.168096552","rc":[{"batl":[[1,2.98,15.35],[2,3,33.61]],"ltp":2.86,"tv":1470.43,"id":52106}]}]}
{"op":"mcm","clk":"991626425","pt":1580505916461,"mc":[{"id":"1.168096552","rc":[{"batl":[[1,2.96,4],[2,2.98,15.35]],"ltp":2.86,"tv":1470.43,"id":52106}]}]}
{"op":"mcm","clk":"991626930","pt":1580505924364,"mc":[{"id":"1.168096552","rc":[{"batl":[[0,890,9.53],[1,910,1.68]],"ltp":0.0,"tv":0.0,"id":27706761}]}]}
{"op":"mcm","clk":"991627060","pt":1580505926493,"mc":[{"id":"1.168096552","rc":[{"batl":[[0,2.96,4],[1,2.98,15.35],[2,3,33.61]],"ltp":2.86,"tv":1470.43,"id":52106}]}]}
{"op":"mcm","clk":"991627083","pt":1580505926804,"mc":[{"id":"1.168096552","rc":[{"batl":[[0,2.94,4],[1,2.96,4],[2,2.98,15.35]],"ltp":2.86,"tv":1470.43,"id":52106}]}]}
{"op":"mcm","clk":"991628027","pt":1580505941521,"mc":[{"id":"1.168096552","rc":[{"batl":[[0,880,2.21],[1,890,9]],"ltp":0.0,"tv":0.0,"id":27706761}]}]}
{"op":"mcm","clk":"991628641","pt":1580505949744,"mc":[{"id":"1.168096552","rc":[{"trd":[[3.15,272.31]],"batl":[[0,3.15,6.86]],"ltp":3.15,"tv":683.65,"id":18286408}],"tv":2946.87}]}
{"op":"mcm","clk":"991630375","pt":1580505973362,"mc":[{"id":"1.168096552","rc":[{"batb":[[0,2.88,3.36],[1,2.86,10.64],[2,2.84,9.57]],"ltp":2.86,"tv":1470.43,"id":52106}]}]}
{"op":"mcm","clk":"991630976","pt":1580505983182,"mc":[{"id":"1.168096552","rc":[{"batl":[[0,2.96,4],[1,2.98,15.35],[2,3,33.61]],"ltp":2.86,"tv":1470.43,"id":52106}]}]}
{"op":"mcm","clk":"991631850","pt":1580505998297,"mc":[{"id":"1.168096552","rc":[{"trd":[[4.5,217.4]],"batb":[[0,4.4,6.8],[1,4.3,6],[2,4.2,110]],"batl":[[0,4.5,7.53],[1,4.9,2],[2,5,10.76]],"ltp":4.5,"tv":753.75,"id":21580749},{"batb":[[1,30,6.25]],"ltp":0.0,"tv":0.0,"id":27706761}],"tv":2951.81}]}
{"op":"mcm","clk":"991632620","pt":1580506010935,"mc":[{"id":"1.168096552","rc":[{"batb":[[0,4.4,11]],"batl":[[2,5,2.7]],"ltp":4.5,"tv":753.75,"id":21580749}]}]}
{"op":"mcm","clk":"991633439","pt":1580506023963,"mc":[{"id":"1.168096552","rc":[{"batb":[[0,2.88,6.86],[2,2.84,6.06]],"ltp":2.86,"tv":1470.43,"id":52106}]}]}
{"op":"mcm","clk":"991634876","pt":1580506050605,"mc":[{"id":"1.168096552","rc":[{"batl":[[1,5,2.7],[2,5.1,20]],"ltp":4.5,"tv":753.75,"id":21580749}]}]}
{"op":"mcm","clk":"991636322","pt":1580506079452,"mc":[{"id":"1.168096552","rc":[{"trd":[[3.1,168]],"batb":[[0,3.1,7.05]],"ltp":3.1,"tv":687.65,"id":18286408},{"batl":[[1,890,0]],"ltp":0.0,"tv":0.0,"id":27706761}],"tv":2955.81}]}
{"op":"mcm","clk":"991636333","pt":1580506079556,"mc":[{"id":"1.168096552","rc":[{"batl":[[0,860,9.53],[1,880,1.68]],"ltp":0.0,"tv":0.0,"id":27706761}]}]}
{"op":"mcm","clk":"991636648","pt":1580506084668,"mc":[{"id":"1.168096552","rc":[{"batb":[[2,3,46]],"ltp":3.1,"tv":687.65,"id":18286408}]}]}
{"op":"mcm","clk":"991637720","pt":1580506103297,"mc":[{"id":"1.168096552","rc":[{"batl":[[0,850,2.21],[1,860,9]],"ltp":0.0,"tv":0.0,"id":27706761}]}]}
{"op":"mcm","clk":"991638180","pt":1580506112511,"mc":[{"id":"1.168096552","rc":[{"batb":[[0,2.9,5.94],[1,2.88,6.86],[2,2.86,10.64]],"ltp":2.86,"tv":1470.43,"id":52106}]}]}
{"op":"mcm","clk":"991638299","pt":1580506114425,"mc":[{"id":"1.168096552","rc":[{"trd":[[10.5,26],[11,19.6]],"batb":[[0,10.5,1.64],[1,10,4.76],[2,9.6,2.18]],"batl":[[0,11,67.2],[1,15,2.08],[2,32,9]],"ltp":11.0,"tv":53.61,"id":26640937}],"tv":2977.41}]}
{"op":"mcm","clk":"991638353","pt":1580506115310,"mc":[{"id":"1.168096552","rc":[{"trd":[[4.4,59.74]],"batb":[[0,4.4,3.47]],"batl":[[0,5,2.7],[1,5.1,20],[2,5.3,9]],"ltp":4.4,"tv":768.81,"id":21580749}],"tv":2992.47}]}
{"op":"mcm","clk":"991638919","pt":1580506123998,"mc":[{"id":"1.168096552","rc":[{"batb":[[0,4.3,6],[1,4.2,110],[2,4.1,3.06]],"ltp":4.4,"tv":768.81,"id":21580749}]}]}
{"op":"mcm","clk":"991639018","pt":1580506125403,"mc":[{"id":"1.168096552","rc":[{"batl":[[0,4.9,2],[1,5,2.7],[2,5.1,20]],"ltp":4.4,"tv":768.81,"id":21580749},{"batb":[[1,30,2.03]],"ltp":0.0,"tv":0.0,"id":27706761}]}]}
{"op":"mcm","clk":"991639318","pt":1580506130350,"mc":[{"id":"1.168096552","rc":[{"batl":[[0,2.92,10],[1,2.96,4],[2,2.98,15.35]],"ltp":2.86,"tv":1470.43,"id":52106}]}]}
{"op":"mcm","clk":"991640467","pt":1580506148066,"mc":[{"id":"1.168096552","rc":[{"batb":[[0,2.9,12.08]],"ltp":2.86,"tv":1470.43,"id":52106}]}]}
{"op":"mcm","clk":"991641598","pt":1580506166168,"mc":[{"id":"1.168096552","rc":[{"batb":[[0,3.1,8.73]],"ltp":3.1,"tv":687.65,"id":18286408},{"batb":[[0,4.4,1.98],[1,4.3,6],[2,4.2,110]],"ltp":4.4,"tv":768.81,"id":21580749},{"batb":[[0,2.9,15.58],[1,2.88,3.36]],"ltp":2.86,"tv":1470.43,"id":52106}]}]}
{"op":"mcm","clk":"991645181","pt":1580506228576,"mc":[{"id":"1.168096552","rc":[{"trd":[[10,8.73],[10.5,29.28]],"batb":[[0,10,4.4],[1,9.6,2.18],[2,7,25.82]],"ltp":10.0,"tv":57.6,"id":26640937}],"tv":2996.47}]}
{"op":"mcm","clk":"991645788","pt":1580506237375,"mc":[{"id":"1.168096552","rc":[{"batb":[[2,8.4,3.13]],"ltp":10.0,"tv":57.6,"id":26640937},{"batl":[[0,820,2.21],[1,830,9]],"ltp":0.0,"tv":0.0,"id":27706761}]}]}
{"op":"mcm","clk":"991649684","pt":1580506296322,"mc":[{"id":"1.168096552","rc":[{"trd":[[4.3,182.96],[4.4,63.7]],"batb":[[0,4.2,142.76],[1,4.1,3.06],[2,4,25]],"batl":[[0,4.9,2.1]],"ltp":4.3,"tv":788.61,"id":21580749}],"tv":3016.27}]}
{"op":"mcm","clk":"991649908","pt":1580506299419,"mc":[{"id":"1.168096552","rc":[{"batl":[[0,4.3,6.1],[1,4.9,2],[2,5,2.7]],"ltp":4.3,"tv":788.61,"id":21580749}]}]}
{"op":"mcm","clk":"991649958","pt":1580506300295,"mc":[{"id":"1.168096552","rc":[{"batb":[[1,30,6.25]],"ltp":0.0,"tv":0.0,"id":27706761},{"trd":[[2.92,20]],"batb":[[0,2.92,9.33],[1,2.9,15.58],[2,2.88,3.36]],"batl":[[0,2.96,4],[1,2.98,15.35],[2,3,33.61]],"ltp":2.92,"tv":1490.43,"id":52106}],"tv":3036.27}]}
{"op":"mcm","clk":"991650511","pt":1580506309241,"mc":[{"id":"1.168096552","rc":[{"batb":[[0,2.92,16.89],[2,2.86,10.64]],"ltp":2.92,"tv":1490.43,"id":52106}]}]}
{"op":"mcm","clk":"991651073","pt":1580506316515,"mc":[{"id":"1.168096552","rc":[{"trd":[[3.15,286.03]],"batb":[[0,3.15,33.4],[1,3.1,8.73],[2,3.05,20.17]],"batl":[[0,3.2,30.56],[1,3.25,330],[2,3.3,28]],"ltp":3.15,"tv":701.37,"id":18286408},{"trd":[[4.3,195.16]],"batb":[[0,4.3,23.39],[1,4.2,142.76],[2,4.1,3.06]],"batl":[[0,4.9,2],[1,5,2.7],[2,5.1,20]],"ltp":4.3,"tv":800.81,"id":21580749},{"batb":[[1,30,10.48]],"ltp":0.0,"tv":0.0,"id":27706761},{"batb":[[0,2.92,7.56]],"ltp":2.92,"tv":1490.43,"id":52106},{"batb":[[0,19,16.5]],"ltp":13.5,"tv":11.96,"id":24608298}],"tv":3062.2}]}
{"op":"mcm","clk":"991651234","pt":1580506318847,"mc":[{"id":"1.168096552","rc":[{"trd":[[3.15,316.03]],"batb":[[0,3.15,18.39]],"ltp":3.15,"tv":731.38,"id":18286408}],"tv":3092.2}]}
{"op":"mcm","clk":"991652272","pt":1580506332359,"mc":[{"id":"1.168096552","rc":[{"batb":[[0,3.1,8.73],[1,3.05,20.17],[2,3,49]],"ltp":3.15,"tv":731.38,"id":18286408},{"batb":[[1,30,2.03]],"ltp":0.0,"tv":0.0,"id":27706761}]}]}
{"op":"mcm","clk":"991652289","pt":1580506332667,"mc":[{"id":"1.168096552","rc":[{"batb":[[1,3.05,22.67]],"ltp":3.15,"tv":731.38,"id":18286408}]}]}
{"op":"mcm","clk":"991652498","pt":1580506335884,"mc":[{"id":"1.168096552","rc":[{"batb":[[0,4.3,39.86]],"batl":[[0,4.8,14.76],[1,4.9,2],[2,5,2.7]],"ltp":4.3,"tv":800.81,"id":21580749}]}]}
{"op":"mcm","clk":"991653333","pt":1580506346880,"mc":[{"id":"1.168096552","rc":[{"batb":[[1,3.05,20.17]],"ltp":3.15,"tv":731.38,"id":18286408},{"trd":[[2.92,35.12]],"batb":[[0,2.9,15.58],[1,2.86,10.64],[2,2.76,6]],"batl":[[0,2.92,42.44],[1,2.96,4],[2,2.98,15.35]],"ltp":2.92,"tv":1505.55,"id":52106}],"tv":3107.32}]}
{"op":"mcm","clk":"991653452","pt":1580506348287,"mc":[{"id":"1.168096552","rc":[{"batb":[[0,4.3,16.47]],"ltp":4.3,"tv":800.81,"id":21580749}]}]}
{"op":"mcm","clk":"991653671","pt":1580506351397,"mc":[{"id":"1.168096552","rc":[{"batl":[[2,5.1,20]],"ltp":4.3,"tv":800.81,"id":21580749}]}]}
{"op":"mcm","clk":"991653700","pt":1580506351810,"mc":[{"id":"1.168096552","rc":[{"batl":[[0,4.7,2.87],[1,4.8,14.76],[2,4.9,2]],"ltp":4.3,"tv":800.81,"id":21580749}]}]}
{"op":"mcm","clk":"991656539","pt":1580506393452,"mc":[{"id":"1.168096552","rc":[{"batl":[[0,800,9.53],[1,820,1.68]],"ltp":0.0,"tv":0.0,"id":27706761}]}]}
{"op":"mcm","clk":"991656641","pt":1580506394851,"mc":[{"id":"1.168096552","rc":[{"batl":[[2,5.1,20]],"ltp":4.3,"tv":800.81,"id":21580749}]}]}
{"op":"mcm","clk":"991656897","pt":1580506399362,"mc":[{"id":"1.168096552","rc":[{"batl":[[0,790,2.21],[1,800,9]],"ltp":0.0,"tv":0.0,"id":27706761}]}]}
{"op":"mcm","clk":"991660083","pt":1580506452371,"mc":[{"id":"1.168096552","rc":[{"batb":[[0,4.4,5.04],[1,4.3,16.47],[2,4.2,110]],"ltp":4.3,"tv":800.81,"id":21580749},{"batb":[[0,2.9,20.62]],"ltp":2.92,"tv":1505.55,"id":52106},{"batb":[[0,19.5,5.04],[1,19,16.24]],"ltp":13.5,"tv":11.96,"id":24608298}]}]}
{"op":"mcm","clk":"991660117","pt":1580506452730,"mc":[{"id":"1.168096552","rc":[{"batb":[[0,19.5,5.29]],"ltp":13.5,"tv":11.96,"id":24608298}]}]}
{"op":"mcm","clk":"991660679","pt":1580506461457,"mc":[{"id":"1.168096552","rc":[{"batb":[[0,20,12.93],[1,19.5,5.04],[2,19,2.89]],"ltp":13.5,"tv":11.96,"id":24608298}]}]}
{"op":"mcm","clk":"991660924","pt":1580506465246,"mc":[{"id":"1.168096552","rc":[{"batb":[[1,4.3,6]],"batl":[[1,5.1,20],[2,5.3,9]],"ltp":4.3,"tv":800.81,"id":21580749}]}]}
{"op":"mcm","clk":"991661524","pt":1580506474866,"mc":[{"id":"1.168096552","rc":[{"batb":[[0,4.3,6],[1,4.2,110],[2,4.1,3.06]],"ltp":4.3,"tv":800.81,"id":21580749}]}]}
{"op":"mcm","clk":"991661968","pt":1580506481506,"mc":[{"id":"1.168096552","rc":[{"batl":[[0,5,2.7]],"ltp":4.3,"tv":800.81,"id":21580749}]}]}
{"op":"mcm","clk":"991662805","pt":1580506493486,"mc":[{"id":"1.168096552","rc":[{"batb":[[0,4.4,22.86],[1,4.3,6],[2,4.2,110]],"ltp":4.3,"tv":800.81,"id":21580749}]}]}
{"op":"mcm","clk":"991663015","pt":1580506496485,"mc":[{"id":"1.168096552","rc":[{"batb":[[0,4.4,30.07]],"batl":[[0,4.9,6.48],[1,5,2.7],[2,5.1,20]],"ltp":4.3,"tv":800.81,"id":21580749}]}]}
{"op":"mcm","clk":"991663203","pt":1580506499289,"mc":[{"id":"1.168096552","rc":[{"batb":[[0,21,1.98],[1,20,12.93],[2,19.5,5.04]],"ltp":13.5,"tv":11.96,"id":24608298}]}]}
{"op":"mcm","clk":"991663923","pt":1580506509408,"mc":[{"id":"1.168096552","rc":[{"batb":[[0,4.4,7.21]],"ltp":4.3,"tv":800.81,"id":21580749}]}]}
{"op":"mcm","clk":"991664344","pt":1580506515907,"mc":[{"id":"1.168096552","rc":[{"batl":[[0,4.8,2.81],[1,4.9,6.48]],"ltp":4.3,"tv":800.81,"id":21580749}]}]}
{"op":"mcm","clk":"991664950","pt":1580506525931,"mc":[{"id":"1.168096552","rc":[{"batl":[[0,770,9.53],[1,790,1.68]],"ltp":0.0,"tv":0.0,"id":27706761}]}]}
{"op":"mcm","clk":"991665110","pt":1580506528426,"mc":[{"id":"1.168096552","rc":[{"batl":[[0,760,2.21],[1,770,9]],"ltp":0.0,"tv":0.0,"id":27706761}]}]}
{"op":"mcm","clk":"991666056","pt":1580506543332,"mc":[{"id":"1.168096552","rc":[{"batb":[[0,22,1.98],[1,21,1.98],[2,20,12.93]],"ltp":13.5,"tv":11.96,"id":24608298}]}]}
{"op":"mcm","clk":"991666921","pt":1580506556463,"mc":[{"id":"1.168096552","rc":[{"batb":[[1,21,14.06],[2,19.5,5.29]],"ltp":13.5,"tv":11.96,"id":24608298}]}]}
{"op":"mcm","clk":"991667767","pt":1580506569367,"mc":[{"id":"1.168096552","rc":[{"batb":[[0,22,7.02]],"ltp":13.5,"tv":11.96,"id":24608298}]}]}
{"op":"mcm","clk":"991667801","pt":1580506569779,"mc":[{"id":"1.168096552","rc":[{"batb":[[2,19,1.16]],"ltp":13.5,"tv":11.96,"id":24608298}]}]}
{"op":"mcm","clk":"991668007","pt":1580506572493,"mc":[{"id":"1.168096552","rc":[{"batb":[[0,23,11.03],[1,22,7.02],[2,21,1.98]],"ltp":13.5,"tv":11.96,"id":24608298}]}]}
{"op":"mcm","clk":"991668659","pt":1580506581793,"mc":[{"id":"1.168096552","rc":[{"batb":[[0,4.4,11.41]],"ltp":4.3,"tv":800.81,"id":21580749}]}]}
{"op":"mcm","clk":"991672406","pt":1580506636469,"mc":[{"id":"1.168096552","rc":[{"batb":[[0,23,11.24]],"ltp":13.5,"tv":11.96,"id":24608298}]}]}
{"op":"mcm","clk":"991672516","pt":1580506638388,"mc":[{"id":"1.168096552","rc":[{"batb":[[0,24,2.19],[1,23,11.03],[2,22,5.04]],"ltp":13.5,"tv":11.96,"id":24608298}]}]}
{"op":"mcm","clk":"991683374","pt":1580506657423,"mc":[{"id":"1.168096552","rc":[{"trd":[[11,23.6]],"batl":[[0,11,65.2]],"ltp":11.0,"tv":61.6,"id":26640937}],"tv":3111.32}]}
{"op":"mcm","clk":"991683550","pt":1580506660320,"mc":[{"id":"1.168096552","rc":[{"batb":[[2,7,25.82]],"ltp":11.0,"tv":61.6,"id":26640937}]}]}
{"op":"mcm","clk":"991685007","pt":1580506683258,"mc":[{"id":"1.168096552","rc":[{"batl":[[0,740,9.53],[1,760,1.68]],"ltp":0.0,"tv":0.0,"id":27706761}]}]}
{"op":"mcm","clk":"991685223","pt":1580506686465,"mc":[{"id":"1.168096552","rc":[{"batl":[[1,760,0]],"ltp":0.0,"tv":0.0,"id":27706761}]}]}
{"op":"mcm","clk":"991685232","pt":1580506686558,"mc":[{"id":"1.168096552","rc":[{"batl":[[0,730,2.21],[1,740,9]],"ltp":0.0,"tv":0.0,"id":27706761}]}]}
{"op":"mcm","clk":"991685891","pt":1580506697381,"mc":[{"id":"1.168096552","rc":[{"batb":[[0,24,6.39],[2,21,1.98]],"ltp":13.5,"tv":11.96,"id":24608298}]}]}
{"op":"mcm","clk":"991686081","pt":1580506700465,"mc":[{"id":"1.168096552","rc":[{"batb":[[1,21,1.98],[2,13,2.91]],"ltp":13.5,"tv":11.96,"id":24608298}]}]}
{"op":"mcm","clk":"991686089","pt":1580506700568,"mc":[{"id":"1.168096552","rc":[{"batb":[[0,25,10.14],[1,24,6.39],[2,21,1.98]],"ltp":13.5,"tv":11.96,"id":24608298}]}]}
{"op":"mcm","clk":"991687073","pt":1580506716500,"mc":[{"id":"1.168096552","rc":[{"batb":[[0,24,6.39],[1,21,1.98],[2,13,2.91]],"ltp":13.5,"tv":11.96,"id":24608298}]}]}
{"op":"mcm","clk":"991687521","pt":1580506723203,"mc":[{"id":"1.168096552","rc":[{"batb":[[0,24,2.19]],"ltp":13.5,"tv":11.96,"id":24608298}]}]}
{"op":"mcm","clk":"991688217","pt":1580506732826,"mc":[{"id":"1.168096552","rc":[{"batb":[[0,22,2.19]],"ltp":13.5,"tv":11.96,"id":24608298}]}]}
{"op":"mcm","clk":"991694483","pt":1580506821468,"mc":[{"id":"1.168096552","rc":[{"batl":[[1,740,0]],"ltp":0.0,"tv":0.0,"id":27706761}]}]}
{"op":"mcm","clk":"991694492","pt":1580506821757,"mc":[{"id":"1.168096552","rc":[{"batl":[[0,710,9.53],[1,730,1.68]],"ltp":0.0,"tv":0.0,"id":27706761}]}]}
{"op":"mcm","clk":"991695431","pt":1580506834783,"mc":[{"id":"1.168096552","rc":[{"batl":[[0,2.96,4],[1,2.98,15.35],[2,3,33.61]],"ltp":2.92,"tv":1505.55,"id":52106}]}]}
{"op":"mcm","clk":"991696064","pt":1580506844306,"mc":[{"id":"1.168096552","rc":[{"batl":[[0,700,2.21],[1,710,9]],"ltp":0.0,"tv":0.0,"id":27706761}]}]}
{"op":"mcm","clk":"991696984","pt":1580506858621,"mc":[{"id":"1.168096552","rc":[{"batl":[[1,2.98,19.35]],"ltp":2.92,"tv":1505.55,"id":52106}]}]}
{"op":"mcm","clk":"991698026","pt":1580506873449,"mc":[{"id":"1.168096552","rc":[{"trd":[[2.9,41.23]],"batb":[[0,2.86,10.64],[1,2.76,6],[2,2.7,35]],"batl":[[0,2.9,21.83],[1,2.96,4],[2,2.98,19.35]],"ltp":2.9,"tv":1546.78,"id":52106}],"tv":3152.55}]}
{"op":"mcm","clk":"991698163","pt":1580506875455,"mc":[{"id":"1.168096552","rc":[{"batb":[[0,3.15,5.47],[1,3.1,8.73],[2,3.05,20.17]],"ltp":3.15,"tv":731.38,"id":18286408},{"batb":[[0,4.5,3.83],[1,4.4,11.41],[2,4.3,6]],"ltp":4.3,"tv":800.81,"id":21580749}]}]}
{"op":"mcm","clk":"991698215","pt":1580506876027,"mc":[{"id":"1.168096552","rc":[{"batb":[[0,10.5,1.64],[1,10,4.4],[2,9.6,2.18]],"ltp":11.0,"tv":61.6,"id":26640937},{"batb":[[1,4.4,4.2]],"batl":[[1,5.1,20],[2,5.3,9]],"ltp":4.3,"tv":800.81,"id":21580749}]}]}
{"op":"mcm","clk":"991699837","pt":1580506904172,"mc":[{"id":"1.168096552","rc":[{"batl":[[0,5,10.76]],"ltp":4.3,"tv":800.81,"id":21580749}]}]}
{"op":"mcm","clk":"991700093","pt":1580506908213,"mc":[{"id":"1.168096552","rc":[{"batb":[[1,4.4,6.26]],"batl":[[0,4.9,1.85],[1,5,10.76],[2,5.1,20]],"ltp":4.3,"tv":800.81,"id":21580749}]}]}
{"op":"mcm","clk":"991701004","pt":1580506923438,"mc":[{"id":"1.168096552","rc":[{"trd":[[10,15.45],[10.5,32.56]],"batb":[[0,10,1.04],[1,9.6,2.18],[2,7,25.82]],"ltp":10.0,"tv":71.6,"id":26640937},{"batb":[[0,4.6,1.98],[1,4.5,3.83],[2,4.4,6.26]],"ltp":4.3,"tv":800.81,"id":21580749},{"batb":[[0,2.86,14.76]],"ltp":2.9,"tv":1546.78,"id":52106}],"tv":3162.55}]}
{"op":"mcm","clk":"991701030","pt":1580506923802,"mc":[{"id":"1.168096552","rc":[{"batb":[[0,3.15,7.15],[1,3.1,7.05]],"ltp":3.15,"tv":731.38,"id":18286408}]}]}
{"op":"mcm","clk":"991701618","pt":1580506932413,"mc":[{"id":"1.168096552","rc":[{"batb":[[2,8.4,3.13]],"ltp":10.0,"tv":71.6,"id":26640937},{"batb":[[2,4.4,2.06]],"ltp":4.3,"tv":800.81,"id":21580749},{"batb":[[0,32,3.11]],"ltp":0.0,"tv":0.0,"id":27706761}]}]}
{"op":"mcm","clk":"991702005","pt":1580506938497,"mc":[{"id":"1.168096552","rc":[{"batb":[[0,32,11.03]],"ltp":0.0,"tv":0.0,"id":27706761}]}]}
{"op":"mcm","clk":"991702095","pt":1580506940054,"mc":[{"id":"1.168096552","rc":[{"batb":[[2,4.3,6]],"batl":[[0,5,10.76],[1,5.1,20],[2,5.3,9]],"ltp":4.3,"tv":800.81,"id":21580749}]}]}
{"op":"mcm","clk":"991702523","pt":1580506946870,"mc":[{"id":"1.168096552","rc":[{"batb":[[0,34,3.95],[1,32,10.44],[2,30,2.03]],"ltp":0.0,"tv":0.0,"id":27706761}]}]}
{"op":"mcm","clk":"991703014","pt":1580506954458,"mc":[{"id":"1.168096552","rc":[{"batb":[[1,32,2.52]],"ltp":0.0,"tv":0.0,"id":27706761}]}]}
{"op":"mcm","clk":"991703018","pt":1580506954559,"mc":[{"id":"1.168096552","rc":[{"batb":[[0,34,11.41]],"ltp":0.0,"tv":0.0,"id":27706761}]}]}
{"op":"mcm","clk":"991704375","pt":1580506977475,"mc":[{"id":"1.168096552","rc":[{"batl":[[0,680,9.53],[1,700,1.68]],"ltp":0.0,"tv":0.0,"id":27706761}]}]}
{"op":"mcm","clk":"991704787","pt":1580506984303,"mc":[{"id":"1.168096552","rc":[{"batb":[[0,36,1.15],[1,34,11.41],[2,32,2.52]],"ltp":0.0,"tv":0.0,"id":27706761}]}]}
{"op":"mcm","clk":"991704903","pt":1580506986480,"mc":[{"id":"1.168096552","rc":[{"batb":[[1,34,3.36]],"ltp":0.0,"tv":0.0,"id":27706761}]}]}
{"op":"mcm","clk":"991704938","pt":1580506987150,"mc":[{"id":"1.168096552","rc":[{"batb":[[0,36,8.2]],"ltp":0.0,"tv":0.0,"id":27706761}]}]}
{"op":"mcm","clk":"991705840","pt":1580507003513,"mc":[{"id":"1.168096552","rc":[{"batl":[[0,670,2.21],[1,680,9]],"ltp":0.0,"tv":0.0,"id":27706761}]}]}
{"op":"mcm","clk":"991705846","pt":1580507003720,"mc":[{"id":"1.168096552","rc":[{"batb":[[0,2.88,4.2],[1,2.86,14.76],[2,2.76,6]],"ltp":2.9,"tv":1546.78,"id":52106}]}]}
{"op":"mcm","clk":"991706173","pt":1580507010454,"mc":[{"id":"1.168096552","rc":[{"trd":[[3.15,320.03]],"batb":[[0,3.15,5.15]],"ltp":3.15,"tv":735.38,"id":18286408}],"tv":3166.55}]}
{"op":"mcm","clk":"991706622","pt":1580507018365,"mc":[{"id":"1.168096552","rc":[{"batb":[[0,9.8,1.04]],"ltp":10.0,"tv":71.6,"id":26640937}]}]}
{"op":"mcm","clk":"991711870","pt":1580507113476,"mc":[{"id":"1.168096552","rc":[{"batb":[[0,38,1.98],[1,36,8.2],[2,34,3.36]],"ltp":0.0,"tv":0.0,"id":27706761},{"batb":[[0,2.88,8.32],[1,2.86,10.64]],"ltp":2.9,"tv":1546.78,"id":52106}]}]}
{"op":"mcm","clk":"991712261","pt":1580507120380,"mc":[{"id":"1.168096552","rc":[{"batl":[[0,650,9.2],[1,670,2.01]],"ltp":0.0,"tv":0.0,"id":27706761}]}]}
{"op":"mcm","clk":"991713125","pt":1580507134392,"mc":[{"id":"1.168096552","rc":[{"batl":[[0,640,1.88],[1,650,9],[2,660,0.33]],"ltp":0.0,"tv":0.0,"id":27706761}]}]}
{"op":"mcm","clk":"991713320","pt":1580507137499,"mc":[{"id":"1.168096552","rc":[{"batl":[[0,640,1.68]],"ltp":0.0,"tv":0.0,"id":27706761}]}]}
{"op":"mcm","clk":"991713352","pt":1580507138019,"mc":[{"id":"1.168096552","rc":[{"batl":[[0,640,1.88]],"ltp":0.0,"tv":0.0,"id":27706761}]}]}
{"op":"mcm","clk":"991715897","pt":1580507177861,"mc":[{"id":"1.168096552","rc":[{"trd":[[3.15,330.33]],"batb":[[0,3.1,7.05],[1,3.05,20.17],[2,3,57.62]],"ltp":3.15,"tv":745.67,"id":18286408}],"tv":3176.84}]}
{"op":"mcm","clk":"991717652","pt":1580507206491,"mc":[{"id":"1.168096552","rc":[{"batb":[[1,9.6,22.18]],"ltp":10.0,"tv":71.6,"id":26640937}]}]}
{"op":"mcm","clk":"991717712","pt":1580507207473,"mc":[{"id":"1.168096552","rc":[{"batb":[[0,3.1,10.16]],"ltp":3.15,"tv":745.67,"id":18286408}]}]}
{"op":"mcm","clk":"991717986","pt":1580507212085,"mc":[{"id":"1.168096552","rc":[{"batb":[[0,9.8,8.6]],"ltp":10.0,"tv":71.6,"id":26640937}]}]}
{"op":"mcm","clk":"991720429","pt":1580507251534,"mc":[{"id":"1.168096552","rc":[{"batb":[[0,38,2.44]],"ltp":0.0,"tv":0.0,"id":27706761}]}]}
{"op":"mcm","clk":"991727119","pt":1580507369168,"mc":[{"id":"1.168096552","rc":[{"trd":[[2.88,24.53]],"batb":[[0,2.88,2.32]],"ltp":2.88,"tv":1558.78,"id":52106}],"tv":3188.84}]}
{"op":"mcm","clk":"991729487","pt":1580507404820,"mc":[{"id":"1.168096552","rc":[{"trd":[[4.5,225.06],[4.6,102.54]],"batb":[[0,4.3,6],[1,4.2,110],[2,4.1,3.06]],"batl":[[0,4.5,4.19],[1,5,10.76],[2,5.1,20]],"ltp":4.5,"tv":812.43,"id":21580749}],"tv":3200.46}]}
{"op":"mcm","clk":"991729885","pt":1580507410339,"mc":[{"id":"1.168096552","rc":[{"batb":[[2,3,49]],"ltp":3.15,"tv":745.67,"id":18286408}]}]}
{"op":"mcm","clk":"991730452","pt":1580507419923,"mc":[{"id":"1.168096552","rc":[{"batb":[[0,4.3,42.96]],"batl":[[1,5,2.7]],"ltp":4.5,"tv":812.43,"id":21580749}]}]}
{"op":"mcm","clk":"991736315","pt":1580507517191,"mc":[{"id":"1.168096552","rc":[{"batb":[[0,2.88,5.68]],"ltp":2.88,"tv":1558.78,"id":52106}]}]}
{"op":"mcm","clk":"991749111","pt":1580507565529,"mc":[{"id":"1.168096552","rc":[{"trd":[[11,39.12]],"batl":[[0,11,57.44]],"ltp":11.0,"tv":87.12,"id":26640937}],"tv":3215.98}]}
{"op":"mcm","clk":"991749495","pt":1580507571251,"mc":[{"id":"1.168096552","rc":[{"batb":[[2,7,25.82]],"ltp":11.0,"tv":87.12,"id":26640937}]}]}
{"op":"mcm","clk":"991750275","pt":1580507584160,"mc":[{"id":"1.168096552","rc":[{"trd":[[3.2,56.61]],"batl":[[0,3.2,21.04]],"ltp":3.2,"tv":764.71,"id":18286408}],"tv":3235.02}]}
{"op":"mcm","clk":"991753385","pt":1580507634447,"mc":[{"id":"1.168096552","rc":[{"trd":[[3.1,188]],"batb":[[0,3.05,20.34],[1,3,49],[2,2.88,36]],"ltp":3.1,"tv":784.71,"id":18286408}],"tv":3255.02}]}
{"op":"mcm","clk":"991753876","pt":1580507642467,"mc":[{"id":"1.168096552","rc":[{"batb":[[1,3,46]],"ltp":3.1,"tv":784.71,"id":18286408}]}]}
{"op":"mcm","clk":"991753889","pt":1580507642569,"mc":[{"id":"1.168096552","rc":[{"batb":[[2,2.88,39]],"ltp":3.1,"tv":784.71,"id":18286408}]}]}
{"op":"mcm","clk":"991758463","pt":1580507715451,"mc":[{"id":"1.168096552","rc":[{"trd":[[2.9,84.89]],"batb":[[0,2.92,650.1],[1,2.88,5.68],[2,2.86,10.64]],"batl":[[0,2.96,4],[1,2.98,19.35],[2,3,33.61]],"ltp":2.9,"tv":1602.44,"id":52106}],"tv":3298.68}]}
{"op":"mcm","clk":"991758515","pt":1580507716280,"mc":[{"id":"1.168096552","rc":[{"trd":[[2.92,827.57]],"batb":[[0,2.92,253.9]],"ltp":2.92,"tv":2394.88,"id":52106}],"tv":4091.13}]}
{"op":"mcm","clk":"991758577","pt":1580507717476,"mc":[{"id":"1.168096552","rc":[{"batb":[[0,2.94,10.07],[1,2.92,253.9],[2,2.88,5.68]],"ltp":2.92,"tv":2394.88,"id":52106}]}]}
{"op":"mcm","clk":"991759356","pt":1580507731414,"mc":[{"id":"1.168096552","rc":[{"batb":[[0,2.94,27.71],[2,2.88,2.32]],"ltp":2.92,"tv":2394.88,"id":52106}]}]}
{"op":"mcm","clk":"991759777","pt":1580507738111,"mc":[{"id":"1.168096552","rc":[{"batb":[[1,9.6,2.18]],"ltp":11.0,"tv":87.12,"id":26640937}]}]}
{"op":"mcm","clk":"991760439","pt":1580507747943,"mc":[{"id":"1.168096552","rc":[{"batb":[[0,9.8,1.04]],"ltp":11.0,"tv":87.12,"id":26640937}]}]}
{"op":"mcm","clk":"991760570","pt":1580507749815,"mc":[{"id":"1.168096552","rc":[{"batb":[[0,2.94,30.03],[2,2.86,10.64]],"ltp":2.92,"tv":2394.88,"id":52106}]}]}
{"op":"mcm","clk":"991762877","pt":1580507789206,"mc":[{"id":"1.168096552","rc":[{"batb":[[1,2.76,6],[2,2.7,35]],"ltp":2.92,"tv":2394.88,"id":52106}]}]}
{"op":"mcm","clk":"991762940","pt":1580507790404,"mc":[{"id":"1.168096552","rc":[{"trd":[[2.94,39.92]],"batb":[[0,2.76,6],[1,2.7,35],[2,2.64,18.93]],"ltp":2.94,"tv":2434.8,"id":52106}],"tv":4131.04}]}
{"op":"mcm","clk":"991762950","pt":1580507790598,"mc":[{"id":"1.168096552","rc":[{"batb":[[0,2.78,14.03],[1,2.76,9.27],[2,2.72,14.03]],"ltp":2.94,"tv":2434.8,"id":52106}]}]}
{"op":"mcm","clk":"991763057","pt":1580507792431,"mc":[{"id":"1.168096552","rc":[{"batb":[[0,2.82,10.75],[1,2.8,55.01],[2,2.76,6]],"ltp":2.94,"tv":2434.8,"id":52106}]}]}
{"op":"mcm","clk":"991763170","pt":1580507795290,"mc":[{"id":"1.168096552","rc":[{"batl":[[0,2.94,2],[1,2.96,4],[2,2.98,19.35]],"ltp":2.94,"tv":2434.8,"id":52106}]}]}
{"op":"mcm","clk":"991763211","pt":1580507796413,"mc":[{"id":"1.168096552","rc":[{"batb":[[0,3.1,6.89],[1,3.05,20.17],[2,3,46]],"ltp":3.1,"tv":784.71,"id":18286408}]}]}
{"op":"mcm","clk":"991763667","pt":1580507806937,"mc":[{"id":"1.168096552","rc":[{"batb":[[0,2.84,3],[1,2.82,10.75],[2,2.8,55.01]],"ltp":2.94,"tv":2434.8,"id":52106}]}]}
{"op":"mcm","clk":"991763773","pt":1580507809410,"mc":[{"id":"1.168096552","rc":[{"batb":[[2,2.76,6]],"ltp":2.94,"tv":2434.8,"id":52106}]}]}
{"op":"mcm","clk":"991763785","pt":1580507809616,"mc":[{"id":"1.168096552","rc":[{"batb":[[0,2.84,57.24]],"ltp":2.94,"tv":2434.8,"id":52106}]}]}
{"op":"mcm","clk":"991764693","pt":1580507827480,"mc":[{"id":"1.168096552","rc":[{"batb":[[0,2.84,3]],"ltp":2.94,"tv":2434.8,"id":52106}]}]}
{"op":"mcm","clk":"991764792","pt":1580507829377,"mc":[{"id":"1.168096552","rc":[{"batb":[[0,2.82,10.75],[1,2.76,6],[2,2.7,35]],"ltp":2.94,"tv":2434.8,"id":52106}]}]}
{"op":"mcm","clk":"991765412","pt":1580507843999,"mc":[{"id":"1.168096552","rc":[{"batb":[[0,2.82,13.45]],"ltp":2.94,"tv":2434.8,"id":52106}]}]}
{"op":"mcm","clk":"991766332","pt":1580507863113,"mc":[{"id":"1.168096552","rc":[{"trd":[[2.82,245.31]],"batb":[[0,2.76,6],[1,2.72,4.86]],"batl":[[0,2.82,4.31],[1,2.92,4.53],[2,2.94,2]],"ltp":2.82,"tv":2461.71,"id":52106}],"tv":4157.95}]}
{"op":"mcm","clk":"991767192","pt":1580507879352,"mc":[{"id":"1.168096552","rc":[{"batb":[[1,21,14.06]],"ltp":13.5,"tv":11.96,"id":24608298}]}]}
{"op":"mcm","clk":"991767205","pt":1580507879769,"mc":[{"id":"1.168096552","rc":[{"batb":[[0,22,2.97],[2,13,2]],"ltp":13.5,"tv":11.96,"id":24608298}]}]}
{"op":"mcm","clk":"991767732","pt":1580507893260,"mc":[{"id":"1.168096552","rc":[{"batb":[[1,3.05,26.12]],"ltp":3.1,"tv":784.71,"id":18286408},{"batb":[[0,4.3,47.18]],"ltp":4.5,"tv":812.43,"id":21580749},{"batb":[[0,2.76,12.57]],"ltp":2.82,"tv":2461.71,"id":52106}]}]}
{"op":"mcm","clk":"991767779","pt":1580507894282,"mc":[{"id":"1.168096552","rc":[{"batb":[[1,9.6,4.07]],"ltp":11.0,"tv":87.12,"id":26640937},{"batb":[[0,22,8.01]],"ltp":13.5,"tv":11.96,"id":24608298}]}]}
{"op":"mcm","clk":"991767853","pt":1580507895873,"mc":[{"id":"1.168096552","rc":[{"batb":[[1,2.7,35],[2,2.64,18.93]],"batl":[[1,2.94,2],[2,2.96,4]],"ltp":2.82,"tv":2461.71,"id":52106}]}]}
{"op":"mcm","clk":"991767908","pt":1580507897463,"mc":[{"id":"1.168096552","rc":[{"batb":[[0,23,11.24],[1,22,7.8],[2,21,1.98]],"ltp":13.5,"tv":11.96,"id":24608298}]}]}
{"op":"mcm","clk":"991768444","pt":1580507910284,"mc":[{"id":"1.168096552","rc":[{"trd":[[2.82,413.3]],"batl":[[0,2.8,10.85],[1,2.82,79.69],[2,2.94,2]],"ltp":2.82,"tv":2629.7,"id":52106}],"tv":4325.94}]}
{"op":"mcm","clk":"991768493","pt":1580507911310,"mc":[{"id":"1.168096552","rc":[{"batl":[[0,2.8,19.92],[1,2.82,125.13]],"ltp":2.82,"tv":2629.7,"id":52106}]}]}
{"op":"mcm","clk":"991769012","pt":1580507923622,"mc":[{"id":"1.168096552","rc":[{"batl":[[2,2.96,4]],"ltp":2.82,"tv":2629.7,"id":52106}]}]}
{"op":"mcm","clk":"991770318","pt":1580507949386,"mc":[{"id":"1.168096552","rc":[{"trd":[[3.1,198.06]],"batb":[[0,3.1,1.86]],"ltp":3.1,"tv":794.77,"id":18286408},{"trd":[[9.6,3.92],[9.8,2.08]],"batb":[[0,9.6,2.11],[1,7.2,36.05],[2,7,25]],"ltp":9.6,"tv":93.12,"id":26640937},{"trd":[[4.3,203.16]],"batb":[[0,4.3,43.18]],"ltp":4.3,"tv":820.43,"id":21580749},{"trd":[[38,4]],"batb":[[0,36,8.64],[1,34,3.36],[2,30,2.03]],"ltp":38.0,"tv":3.99,"id":27706761},{"trd":[[23,3.58],[24,0.42]],"batb":[[0,23,9.24]],"ltp":23.0,"tv":15.96,"id":24608298}],"tv":4358.0}]}
{"op":"mcm","clk":"991770386","pt":1580507950465,"mc":[{"id":"1.168096552","rc":[{"batb":[[1,8.4,3.13],[2,7.2,35.91]],"ltp":9.6,"tv":93.12,"id":26640937}]}]}
{"op":"mcm","clk":"991770430","pt":1580507951284,"mc":[{"id":"1.168096552","rc":[{"batb":[[2,7.4,2.7]],"ltp":9.6,"tv":93.12,"id":26640937}]}]}
{"op":"mcm","clk":"991770521","pt":1580507953381,"mc":[{"id":"1.168096552","rc":[{"batl":[[0,4.5,8.19]],"ltp":4.3,"tv":820.43,"id":21580749}]}]}
{"op":"mcm","clk":"991770704","pt":1580507957502,"mc":[{"id":"1.168096552","rc":[{"batb":[[0,2.78,3.36],[1,2.76,12.57],[2,2.7,35]],"ltp":2.82,"tv":2629.7,"id":52106}]}]}
{"op":"mcm","clk":"991771178","pt":1580507966497,"mc":[{"id":"1.168096552","rc":[{"trd":[[3.05,39.68],[3.1,201.78]],"batb":[[0,3.05,24.98],[1,3,46],[2,2.88,39]],"ltp":3.05,"tv":800.77,"id":18286408}],"tv":4364.0}]}
{"op":"mcm","clk":"991771252","pt":1580507968511,"mc":[{"id":"1.168096552","rc":[{"batb":[[1,8.6,29.62],[2,8.4,3]],"ltp":9.6,"tv":93.12,"id":26640937},{"batb":[[0,2.78,58.77]],"ltp":2.82,"tv":2629.7,"id":52106}]}]}
{"op":"mcm","clk":"991771604","pt":1580507976399,"mc":[{"id":"1.168096552","rc":[{"trd":[[3.05,43.68]],"batb":[[0,3.05,22.98]],"ltp":3.05,"tv":804.77,"id":18286408},{"trd":[[9.6,7.92]],"batb":[[0,8.6,29.73],[1,8.4,3],[2,7.4,2.7]],"ltp":9.6,"tv":97.12,"id":26640937},{"trd":[[4.3,207.16]],"batb":[[0,4.3,41.18]],"ltp":4.3,"tv":824.43,"id":21580749}],"tv":4376.0}]}
{"op":"mcm","clk":"991771930","pt":1580507984429,"mc":[{"id":"1.168096552","rc":[{"batb":[[0,8.4,3.24],[1,7.4,2.7],[2,7,25.69]],"ltp":9.6,"tv":97.12,"id":26640937},{"batb":[[0,2.78,3.36]],"ltp":2.82,"tv":2629.7,"id":52106}]}]}
{"op":"mcm","clk":"991771988","pt":1580507985304,"mc":[{"id":"1.168096552","rc":[{"trd":[[3.05,47.68]],"batb":[[0,3.05,20.98]],"ltp":3.05,"tv":808.77,"id":18286408},{"batb":[[0,8.6,11.16],[1,8.4,33.19],[2,7.6,15.48]],"ltp":9.6,"tv":97.12,"id":26640937},{"trd":[[4.3,211.16]],"batb":[[0,4.3,39.18]],"ltp":4.3,"tv":828.43,"id":21580749}],"tv":4384.0}]}
{"op":"mcm","clk":"991772024","pt":1580507986225,"mc":[{"id":"1.168096552","rc":[{"trd":[[23,7.65]],"batb":[[0,23,7.2]],"ltp":23.0,"tv":20.03,"id":24608298}],"tv":4388.07}]}
{"op":"mcm","clk":"991772063","pt":1580507987401,"mc":[{"id":"1.168096552","rc":[{"batb":[[0,3.05,26.75]],"ltp":3.05,"tv":808.77,"id":18286408},{"batb":[[0,8.8,2.22],[1,8.6,10.92],[2,8.4,33.19]],"ltp":9.6,"tv":97.12,"id":26640937},{"batb":[[0,4.3,40.86]],"ltp":4.3,"tv":828.43,"id":21580749},{"batb":[[0,2.78,6.81]],"ltp":2.82,"tv":2629.7,"id":52106},{"trd":[[23,11.71]],"batb":[[0,24,1.98],[1,23,5.17],[2,22,5.82]],"ltp":23.0,"tv":24.09,"id":24608298}],"tv":4392.13}]}
{"op":"mcm","clk":"991772397","pt":1580507995323,"mc":[{"id":"1.168096552","rc":[{"batb":[[0,9,3.53],[1,8.8,1.98],[2,8.6,10.92]],"batl":[[1,14.5,2.12],[2,15,2]],"ltp":9.6,"tv":97.12,"id":26640937}]}]}
{"op":"mcm","clk":"991772499","pt":1580507997424,"mc":[{"id":"1.168096552","rc":[{"batb":[[2,8.4,33.19]],"ltp":9.6,"tv":97.12,"id":26640937},{"trd":[[24,1.84]],"batb":[[0,24,1.27],[2,21,3.52]],"batl":[[1,1000,1.59]],"ltp":24.0,"tv":25.52,"id":24608298}],"tv":4393.56}]}
{"op":"mcm","clk":"991772539","pt":1580507998345,"mc":[{"id":"1.168096552","rc":[{"trd":[[23,12.35],[24,4.38]],"batb":[[0,23,4.85],[1,21,3.52],[2,13,2]],"batl":[[1,1000,0]],"ltp":23.0,"tv":28.69,"id":24608298}],"tv":4396.73}]}
{"op":"mcm","clk":"991772740","pt":1580508002466,"mc":[{"id":"1.168096552","rc":[{"batb":[[2,8.4,3]],"ltp":9.6,"tv":97.12,"id":26640937},{"batb":[[0,21,3.52],[1,13,2],[2,9.2,4.59]],"ltp":23.0,"tv":28.69,"id":24608298}]}]}
{"op":"mcm","clk":"991772770","pt":1580508002835,"mc":[{"id":"1.168096552","rc":[{"batb":[[0,9,31.71]],"ltp":9.6,"tv":97.12,"id":26640937},{"batb":[[0,2.78,62.22]],"ltp":2.82,"tv":2629.7,"id":52106}]}]}
{"op":"mcm","clk":"991773608","pt":1580508019374,"mc":[{"id":"1.168096552","rc":[{"trd":[[3.1,201.77],[3.15,330.25],[3.2,56.61],[3.25,60.62],[3.3,46.41],[3.35,7.56]],"batb":[[0,3.05,26.74]],"batl":[[0,3.2,21.04]],"ltp":3.05,"tv":808.68,"id":18286408},{"trd":[[9.6,7.92],[10,15.44],[10.5,32.56]],"batb":[[0,9,31.67]],"ltp":9.6,"tv":97.12,"id":26640937},{"trd":[[4.1,50.12],[4.3,211.15],[4.4,63.71],[4.5,225.05],[4.6,102.5],[4.7,15.66]],"batb":[[0,4.3,40.86]],"ltp":4.3,"tv":828.38,"id":21580749},{"batb":[[0,36,8.62],[1,34,3.36]],"ltp":38.0,"tv":3.99,"id":27706761},{"trd":[[2.6,10.42],[2.7,219.69],[2.78,193.14],[2.82,413.31],[2.84,92.79],[2.86,90.81],[2.88,24.53],[2.92,827.63],[2.94,39.93],[3,14.49],[3.05,16.47]],"batb":[[0,2.78,6.81],[1,2.76,12.56]],"batl":[[0,2.8,19.92],[1,2.82,125.11]],"ltp":2.82,"tv":2629.75,"id":52106},{"trd":[[13.5,3.97],[23,12.35]],"batb":[[0,21,3.52],[2,9.2,4.59]],"ltp":23.0,"tv":28.69,"id":24608298}],"tv":4396.64}]}
{"op":"mcm","clk":"991773618","pt":1580508019681,"mc":[{"id":"1.168096552","rc":[{"batb":[[2,8.4,6.64]],"ltp":9.6,"tv":97.12,"id":26640937}]}]}
{"op":"mcm","clk":"991774313","pt":1580508033483,"mc":[{"id":"1.168096552","rc":[{"batb":[[0,9.2,2.22],[1,9,31.43]],"ltp":9.6,"tv":97.12,"id":26640937},{"batb":[[0,22,2.76],[1,21,2.74],[2,13,2]],"ltp":23.0,"tv":28.69,"id":24608298}]}]}
{"op":"mcm","clk":"991774492","pt":1580508037491,"mc":[{"id":"1.168096552","rc":[{"batb":[[0,9.2,29.75],[1,9,3.29]],"ltp":9.6,"tv":97.12,"id":26640937},{"batb":[[0,2.78,62.14]],"ltp":2.82,"tv":2629.75,"id":52106},{"batb":[[0,22,7.82]],"ltp":23.0,"tv":28.69,"id":24608298}]}]}
{"op":"mcm","clk":"991775404","pt":1580508054420,"mc":[{"id":"1.168096552","rc":[{"batb":[[0,2.78,6.81]],"ltp":2.82,"tv":2629.75,"id":52106}]}]}
{"op":"mcm","clk":"991776072","pt":1580508064365,"mc":[{"id":"1.168096552","rc":[{"batb":[[0,3.1,8.4],[1,3.05,26.74],[2,3,46]],"ltp":3.05,"tv":808.68,"id":18286408}]}]}
{"op":"mcm","clk":"991776482","pt":1580508072371,"mc":[{"id":"1.168096552","rc":[{"batb":[[0,2.78,62.14]],"ltp":2.82,"tv":2629.75,"id":52106}]}]}
{"op":"mcm","clk":"991776974","pt":1580508079856,"mc":[{"id":"1.168096552","rc":[{"batb":[[0,3.1,14.17],[1,3.05,20.97]],"ltp":3.05,"tv":808.68,"id":18286408}]}]}
{"op":"mcm","clk":"991777279","pt":1580508084295,"mc":[{"id":"1.168096552","rc":[{"batb":[[0,9.4,9.35],[1,9.2,29.65],[2,9,3.29]],"ltp":9.6,"tv":97.12,"id":26640937},{"batb":[[0,22,11.19]],"ltp":23.0,"tv":28.69,"id":24608298}]}]}
{"op":"mcm","clk":"991777683","pt":1580508089494,"mc":[{"id":"1.168096552","rc":[{"batb":[[1,9.2,2.12]],"ltp":9.6,"tv":97.12,"id":26640937},{"batb":[[0,2.78,6.81]],"ltp":2.82,"tv":2629.75,"id":52106},{"batb":[[0,22,6.13]],"ltp":23.0,"tv":28.69,"id":24608298}]}]}
{"op":"mcm","clk":"991777758","pt":1580508090474,"mc":[{"id":"1.168096552","rc":[{"batb":[[0,9.6,26.49],[1,9.4,9.24],[2,9.2,2.12]],"ltp":9.6,"tv":97.12,"id":26640937},{"batb":[[0,23,4.84],[1,22,6.13],[2,21,2.74]],"ltp":23.0,"tv":28.69,"id":24608298}]}]}
{"op":"mcm","clk":"991779072","pt":1580508108307,"mc":[{"id":"1.168096552","rc":[{"batb":[[0,2.78,62.14]],"ltp":2.82,"tv":2629.75,"id":52106}]}]}
{"op":"mcm","clk":"991780113","pt":1580508126350,"mc":[{"id":"1.168096552","rc":[{"batb":[[0,2.78,6.81]],"ltp":2.82,"tv":2629.75,"id":52106}]}]}
{"op":"mcm","clk":"991780154","pt":1580508127240,"mc":[{"id":"1.168096552","rc":[{"batb":[[0,9.8,1.98],[1,9.6,26.49],[2,9.4,9.24]],"ltp":9.6,"tv":97.12,"id":26640937},{"batb":[[0,24,1.98],[1,23,4.84],[2,22,4.14]],"ltp":23.0,"tv":28.69,"id":24608298}]}]}
{"op":"mcm","clk":"991780525","pt":1580508133664,"mc":[{"id":"1.168096552","rc":[{"batb":[[2,21,3.52]],"ltp":23.0,"tv":28.69,"id":24608298}]}]}
{"op":"mcm","clk":"991781132","pt":1580508144377,"mc":[{"id":"1.168096552","rc":[{"batb":[[0,2.78,62.14]],"ltp":2.82,"tv":2629.75,"id":52106}]}]}
{"op":"mcm","clk":"991782076","pt":1580508161480,"mc":[{"id":"1.168096552","rc":[{"batb":[[0,2.78,6.81]],"ltp":2.82,"tv":2629.75,"id":52106}]}]}
{"op":"mcm","clk":"991783056","pt":1580508179439,"mc":[{"id":"1.168096552","rc":[{"batb":[[0,2.78,62.14]],"ltp":2.82,"tv":2629.75,"id":52106}]}]}
{"op":"mcm","clk":"991783448","pt":1580508186456,"mc":[{"id":"1.168096552","rc":[{"batb":[[0,9.8,11.23],[2,9,3.42]],"ltp":9.6,"tv":97.12,"id":26640937}]}]}
{"op":"mcm","clk":"991783801","pt":1580508192133,"mc":[{"id":"1.168096552","rc":[{"batb":[[2,8.4,3.13]],"batl":[[1,15,2.08],[2,32,9]],"ltp":9.6,"tv":97.12,"id":26640937}]}]}
{"op":"mcm","clk":"991784035","pt":1580508196446,"mc":[{"id":"1.168096552","rc":[{"batb":[[1,8.4,3.24],[2,7.6,15.48]],"ltp":9.6,"tv":97.12,"id":26640937},{"batb":[[0,2.78,6.81]],"ltp":2.82,"tv":2629.75,"id":52106}]}]}
{"op":"mcm","clk":"991784049","pt":1580508196649,"mc":[{"id":"1.168096552","rc":[{"batb":[[1,8.6,7.33],[2,8.4,10.09]],"ltp":9.6,"tv":97.12,"id":26640937}]}]}
{"op":"mcm","clk":"991784776","pt":1580508207475,"mc":[{"id":"1.168096552","rc":[{"batb":[[0,9.8,1.98]],"ltp":9.6,"tv":97.12,"id":26640937}]}]}
{"op":"mcm","clk":"991784791","pt":1580508207682,"mc":[{"id":"1.168096552","rc":[{"batb":[[1,8.4,3.24],[2,7.6,15.48]],"ltp":9.6,"tv":97.12,"id":26640937}]}]}
{"op":"mcm","clk":"991785151","pt":1580508214386,"mc":[{"id":"1.168096552","rc":[{"batb":[[1,8.6,29.69],[2,8.4,3]],"ltp":9.6,"tv":97.12,"id":26640937},{"batb":[[0,2.78,62.14]],"ltp":2.82,"tv":2629.75,"id":52106}]}]}
{"op":"mcm","clk":"991785468","pt":1580508220002,"mc":[{"id":"1.168096552","rc":[{"batb":[[0,8.8,2.22],[1,8.6,29.45]],"ltp":9.6,"tv":97.12,"id":26640937}]}]}
{"op":"mcm","clk":"991786066","pt":1580508231394,"mc":[{"id":"1.168096552","rc":[{"batb":[[0,2.78,6.81]],"ltp":2.82,"tv":2629.75,"id":52106}]}]}
{"op":"mcm","clk":"991787175","pt":1580508249403,"mc":[{"id":"1.168096552","rc":[{"batb":[[0,2.78,62.14]],"ltp":2.82,"tv":2629.75,"id":52106}]}]}
{"op":"mcm","clk":"991788153","pt":1580508266341,"mc":[{"id":"1.168096552","rc":[{"batb":[[0,2.78,6.81]],"ltp":2.82,"tv":2629.75,"id":52106}]}]}
{"op":"mcm","clk":"991788623","pt":1580508273466,"mc":[{"id":"1.168096552","rc":[{"batb":[[2,21,2.74]],"ltp":23.0,"tv":28.69,"id":24608298}]}]}
{"op":"mcm","clk":"991788635","pt":1580508273672,"mc":[{"id":"1.168096552","rc":[{"batb":[[0,24,2.7]],"ltp":23.0,"tv":28.69,"id":24608298}]}]}
{"op":"mcm","clk":"991788871","pt":1580508278361,"mc":[{"id":"1.168096552","rc":[{"trd":[[24,8.38]],"batb":[[0,23,5.54],[1,21,2.74],[2,13,2]],"ltp":24.0,"tv":32.69,"id":24608298}],"tv":4400.64}]}
{"op":"mcm","clk":"991788934","pt":1580508279346,"mc":[{"id":"1.168096552","rc":[{"trd":[[3.2,73.91]],"batl":[[0,3.2,12.39]],"ltp":3.2,"tv":825.98,"id":18286408}],"tv":4417.94}]}
{"op":"mcm","clk":"991788965","pt":1580508280068,"mc":[{"id":"1.168096552","rc":[{"batb":[[2,3,49]],"ltp":3.2,"tv":825.98,"id":18286408}]}]}
{"op":"mcm","clk":"991789257","pt":1580508284482,"mc":[{"id":"1.168096552","rc":[{"batb":[[0,9,7.13],[1,8.8,1.98]],"batl":[[1,14.5,4.36],[2,15,2]],"ltp":9.6,"tv":97.12,"id":26640937},{"batb":[[0,21,3.43],[1,13,2],[2,9.2,4.59]],"ltp":24.0,"tv":32.69,"id":24608298}]}]}
{"op":"mcm","clk":"991789295","pt":1580508285063,"mc":[{"id":"1.168096552","rc":[{"batb":[[0,9.2,27.77],[1,9,6.89],[2,8.8,1.98]],"ltp":9.6,"tv":97.12,"id":26640937},{"batb":[[0,2.78,62.14]],"ltp":2.82,"tv":2629.75,"id":52106}]}]}
{"op":"mcm","clk":"991789485","pt":1580508287374,"mc":[{"id":"1.168096552","rc":[{"trd":[[36,3.12],[38,4.88]],"batb":[[0,36,6.63]],"ltp":36.0,"tv":7.99,"id":27706761}],"tv":4421.94}]}
{"op":"mcm","clk":"991790213","pt":1580508297603,"mc":[{"id":"1.168096552","rc":[{"batb":[[1,30,2.03],[2,20,1.68]],"ltp":36.0,"tv":7.99,"id":27706761}]}]}
{"op":"mcm","clk":"991790498","pt":1580508301473,"mc":[{"id":"1.168096552","rc":[{"batb":[[0,30,2.03],[1,20,13.6],[2,18,1.8]],"ltp":36.0,"tv":7.99,"id":27706761},{"batb":[[0,2.78,6.81]],"ltp":2.82,"tv":2629.75,"id":52106}]}]}
{"op":"mcm","clk":"991790936","pt":1580508308534,"mc":[{"id":"1.168096552","rc":[{"batb":[[0,9.4,9.35],[1,9.2,27.66],[2,9,6.89]],"ltp":9.6,"tv":97.12,"id":26640937}]}]}
{"op":"mcm","clk":"991791624","pt":1580508319515,"mc":[{"id":"1.168096552","rc":[{"batb":[[1,9,7.02],[2,8.8,1.98]],"ltp":9.6,"tv":97.12,"id":26640937}]}]}
{"op":"mcm","clk":"991791653","pt":1580508319928,"mc":[{"id":"1.168096552","rc":[{"batb":[[0,9.6,26.49],[1,9.4,9.24],[2,9,7.02]],"ltp":9.6,"tv":97.12,"id":26640937},{"batb":[[0,2.78,62.14]],"ltp":2.82,"tv":2629.75,"id":52106}]}]}
{"op":"mcm","clk":"991792152","pt":1580508328321,"mc":[{"id":"1.168096552","rc":[{"trd":[[2.8,124.17],[2.82,434.85]],"batb":[[0,2.8,232.14],[1,2.78,62.14],[2,2.76,12.56]],"batl":[[0,2.82,114.34],[1,2.96,4],[2,2.98,19.35]],"ltp":2.82,"tv":2691.13,"id":52106}],"tv":4483.32}]}
{"op":"mcm","clk":"991792247","pt":1580508329952,"mc":[{"id":"1.168096552","rc":[{"batb":[[0,2.8,241.21]],"ltp":2.82,"tv":2691.13,"id":52106}]}]}
{"op":"mcm","clk":"991792697","pt":1580508336454,"mc":[{"id":"1.168096552","rc":[{"batb":[[1,2.78,6.81]],"ltp":2.82,"tv":2691.13,"id":52106}]}]}
{"op":"mcm","clk":"991792733","pt":1580508337066,"mc":[{"id":"1.168096552","rc":[{"trd":[[2.82,543.94]],"batl":[[0,2.82,59.8]],"ltp":2.82,"tv":2800.22,"id":52106}],"tv":4592.41}]}
{"op":"mcm","clk":"991792794","pt":1580508338047,"mc":[{"id":"1.168096552","rc":[{"trd":[[2.82,563.28]],"batl":[[0,2.82,50.13]],"ltp":2.82,"tv":2819.56,"id":52106}],"tv":4611.75}]}
{"op":"mcm","clk":"991793858","pt":1580508357297,"mc":[{"id":"1.168096552","rc":[{"batb":[[0,9.8,1.98],[1,9.6,26.49],[2,9.4,9.24]],"ltp":9.6,"tv":97.12,"id":26640937},{"batb":[[0,32,1.98],[1,30,2.03],[2,20,13.6]],"ltp":36.0,"tv":7.99,"id":27706761},{"batb":[[0,2.8,244.66],[1,2.78,3.36]],"ltp":2.82,"tv":2819.56,"id":52106}]}]}
{"op":"mcm","clk":"991794243","pt":1580508364279,"mc":[{"id":"1.168096552","rc":[{"batl":[[1,15,2.08],[2,32,9]],"ltp":9.6,"tv":97.12,"id":26640937}]}]}
{"op":"mcm","clk":"991794676","pt":1580508371508,"mc":[{"id":"1.168096552","rc":[{"batb":[[1,30,9.97],[2,20,1.68]],"ltp":36.0,"tv":7.99,"id":27706761}]}]}
{"op":"mcm","clk":"991795854","pt":1580508390944,"mc":[{"id":"1.168096552","rc":[{"batb":[[0,32,5.34]],"ltp":36.0,"tv":7.99,"id":27706761}]}]}
{"op":"mcm","clk":"991795939","pt":1580508392337,"mc":[{"id":"1.168096552","rc":[{"trd":[[2.82,567.36]],"batl":[[0,2.82,48.09]],"ltp":2.82,"tv":2823.64,"id":52106}],"tv":4615.83}]}
{"op":"mcm","clk":"991796792","pt":1580508406446,"mc":[{"id":"1.168096552","rc":[{"batb":[[1,30,2.03]],"ltp":36.0,"tv":7.99,"id":27706761}]}]}
{"op":"mcm","clk":"991796822","pt":1580508407162,"mc":[{"id":"1.168096552","rc":[{"batb":[[0,34,7.02],[1,32,5.34],[2,30,2.03]],"ltp":36.0,"tv":7.99,"id":27706761}]}]}
{"op":"mcm","clk":"991796993","pt":1580508410258,"mc":[{"id":"1.168096552","rc":[{"trd":[[9.6,23.96],[9.8,6.04]],"batb":[[0,9.6,18.47],[1,9.4,9.24],[2,8.4,3.13]],"ltp":9.6,"tv":117.12,"id":26640937}],"tv":4635.83}]}
{"op":"mcm","clk":"991797098","pt":1580508411952,"mc":[{"id":"1.168096552","rc":[{"batb":[[1,8.4,3.13],[2,7,25.69]],"ltp":9.6,"tv":117.12,"id":26640937}]}]}
{"op":"mcm","clk":"991797862","pt":1580508424508,"mc":[{"id":"1.168096552","rc":[{"batb":[[0,8.6,2.43],[1,8.4,24.11],[2,7.2,8.43]],"ltp":9.6,"tv":117.12,"id":26640937}]}]}
{"op":"mcm","clk":"991798161","pt":1580508429000,"mc":[{"id":"1.168096552","rc":[{"trd":[[10.5,36.56],[11,78.84]],"batl":[[0,11,37.58]],"ltp":11.0,"tv":160.84,"id":26640937}],"tv":4679.55}]}
{"op":"mcm","clk":"991798223","pt":1580508429721,"mc":[{"id":"1.168096552","rc":[{"batb":[[1,8.4,21.11]],"ltp":11.0,"tv":160.84,"id":26640937}]}]}
{"op":"mcm","clk":"991798313","pt":1580508430911,"mc":[{"id":"1.168096552","rc":[{"batl":[[2,21,1.5]],"ltp":11.0,"tv":160.84,"id":26640937}]}]}
{"op":"mcm","clk":"991798389","pt":1580508432097,"mc":[{"id":"1.168096552","rc":[{"batb":[[0,8.8,6.02],[1,8.6,2.29],[2,8.4,21.11]],"batl":[[1,14.5,3.65],[2,15,2]],"ltp":11.0,"tv":160.84,"id":26640937}]}]}
{"op":"mcm","clk":"991798923","pt":1580508441438,"mc":[{"id":"1.168096552","rc":[{"batb":[[2,7.2,8.43]],"ltp":11.0,"tv":160.84,"id":26640937}]}]}
{"op":"mcm","clk":"991798987","pt":1580508442343,"mc":[{"id":"1.168096552","rc":[{"batb":[[0,9,19.83],[1,8.8,5.88],[2,8.6,2.29]],"ltp":11.0,"tv":160.84,"id":26640937}]}]}
{"op":"mcm","clk":"991799494","pt":1580508450264,"mc":[{"id":"1.168096552","rc":[{"batb":[[0,9.2,2.12],[1,9,19.7],[2,8.8,5.88]],"ltp":11.0,"tv":160.84,"id":26640937},{"batb":[[1,32,3.36]],"ltp":36.0,"tv":7.99,"id":27706761}]}]}
{"op":"mcm","clk":"991809755","pt":1580508459473,"mc":[{"id":"1.168096552","rc":[{"batb":[[0,32,10.81],[1,30,2.03],[2,20,1.68]],"ltp":36.0,"tv":7.99,"id":27706761}]}]}
{"op":"mcm","clk":"991810506","pt":1580508471194,"mc":[{"id":"1.168096552","rc":[{"batb":[[0,9.4,5.45],[1,9.2,2.12],[2,9,19.7]],"ltp":11.0,"tv":160.84,"id":26640937}]}]}
{"op":"mcm","clk":"991810829","pt":1580508476488,"mc":[{"id":"1.168096552","rc":[{"batb":[[2,7.2,8.43]],"ltp":11.0,"tv":160.84,"id":26640937}]}]}
{"op":"mcm","clk":"991810842","pt":1580508476586,"mc":[{"id":"1.168096552","rc":[{"batb":[[0,9.6,18.47],[1,9.4,5.45],[2,9.2,2.12]],"ltp":11.0,"tv":160.84,"id":26640937}]}]}
{"op":"mcm","clk":"991811219","pt":1580508482472,"mc":[{"id":"1.168096552","rc":[{"batb":[[0,9.8,2.14],[1,9.6,18.47],[2,9.4,5.45]],"ltp":11.0,"tv":160.84,"id":26640937}]}]}
{"op":"mcm","clk":"991811976","pt":1580508494527,"mc":[{"id":"1.168096552","rc":[{"batb":[[1,9.4,5.45],[2,9.2,2.12]],"ltp":11.0,"tv":160.84,"id":26640937}]}]}
{"op":"mcm","clk":"991812612","pt":1580508504637,"mc":[{"id":"1.168096552","rc":[{"batb":[[1,9.2,2.12],[2,7.2,8.43]],"batl":[[1,15,2.08],[2,21,1.5]],"ltp":11.0,"tv":160.84,"id":26640937}]}]}
{"op":"mcm","clk":"991814829","pt":1580508539279,"mc":[{"id":"1.168096552","rc":[{"batb":[[2,7,25.69]],"ltp":11.0,"tv":160.84,"id":26640937}]}]}
{"op":"mcm","clk":"991815107","pt":1580508543391,"mc":[{"id":"1.168096552","rc":[{"batb":[[0,34,1.75],[1,32,10.81],[2,30,2.03]],"ltp":36.0,"tv":7.99,"id":27706761}]}]}
{"op":"mcm","clk":"991815132","pt":1580508543800,"mc":[{"id":"1.168096552","rc":[{"batb":[[0,10,1.98],[1,9.8,2.14],[2,7,25.82]],"ltp":11.0,"tv":160.84,"id":26640937}]}]}
{"op":"mcm","clk":"991815314","pt":1580508546483,"mc":[{"id":"1.168096552","rc":[{"batb":[[0,34,8.76],[1,32,3.36]],"ltp":36.0,"tv":7.99,"id":27706761}]}]}
{"op":"mcm","clk":"991815811","pt":1580508554390,"mc":[{"id":"1.168096552","rc":[{"trd":[[9.8,6.08],[10,19.4]],"batb":[[0,9.8,2.12],[1,7,25.82],[2,2.64,90.78]],"ltp":9.8,"tv":164.84,"id":26640937},{"trd":[[2.8,127.53]],"batb":[[0,2.8,242.98]],"ltp":2.8,"tv":2827.0,"id":52106}],"tv":4686.91}]}
{"op":"mcm","clk":"991816096","pt":1580508558608,"mc":[{"id":"1.168096552","rc":[{"batb":[[1,8.4,3.13],[2,7,25.69]],"ltp":9.8,"tv":164.84,"id":26640937}]}]}
{"op":"mcm","clk":"991816478","pt":1580508564322,"mc":[{"id":"1.168096552","rc":[{"batb":[[1,8.6,20.75],[2,8.4,3]],"ltp":9.8,"tv":164.84,"id":26640937}]}]}
{"op":"mcm","clk":"991817967","pt":1580508588856,"mc":[{"id":"1.168096552","rc":[{"batb":[[0,8.8,2.49],[1,8.6,20.61]],"ltp":9.8,"tv":164.84,"id":26640937}]}]}
{"op":"mcm","clk":"991818303","pt":1580508593796,"mc":[{"id":"1.168096552","rc":[{"batb":[[0,8.8,9.22]],"ltp":9.8,"tv":164.84,"id":26640937}]}]}
{"op":"mcm","clk":"991818662","pt":1580508599487,"mc":[{"id":"1.168096552","rc":[{"batb":[[0,9,19.83],[1,8.8,9.08]],"ltp":9.8,"tv":164.84,"id":26640937}]}]}
{"op":"mcm","clk":"991819027","pt":1580508604509,"mc":[{"id":"1.168096552","rc":[{"batb":[[0,9.2,6.87],[1,9,19.7],[2,8.8,9.08]],"batl":[[1,14.5,4.36],[2,15,2]],"ltp":9.8,"tv":164.84,"id":26640937}]}]}
{"op":"mcm","clk":"991819901","pt":1580508616432,"mc":[{"id":"1.168096552","rc":[{"batb":[[1,8.8,9.08],[2,8.4,3]],"ltp":9.8,"tv":164.84,"id":26640937}]}]}
{"op":"mcm","clk":"991819922","pt":1580508616791,"mc":[{"id":"1.168096552","rc":[{"batb":[[0,9.4,18.86],[1,9.2,6.87],[2,8.8,9.08]],"ltp":9.8,"tv":164.84,"id":26640937}]}]}
{"op":"mcm","clk":"991821148","pt":1580508636339,"mc":[{"id":"1.168096552","rc":[{"batb":[[0,9.6,1.98],[1,9.4,18.86],[2,9.2,6.87]],"ltp":9.8,"tv":164.84,"id":26640937}]}]}
{"op":"mcm","clk":"991821538","pt":1580508642325,"mc":[{"id":"1.168096552","rc":[{"batb":[[0,9.8,2.12],[1,9.6,4.06],[2,9.4,18.86]],"ltp":9.8,"tv":164.84,"id":26640937},{"batb":[[0,34,9.32]],"ltp":36.0,"tv":7.99,"id":27706761}]}]}
{"op":"mcm","clk":"991821641","pt":1580508643873,"mc":[{"id":"1.168096552","rc":[{"batb":[[0,10,3],[1,9.8,2.12],[2,9.6,4.06]],"ltp":9.8,"tv":164.84,"id":26640937}]}]}
{"op":"mcm","clk":"991821985","pt":1580508650468,"mc":[{"id":"1.168096552","rc":[{"trd":[[3.1,231.78]],"batb":[[0,3.1,5.45]],"batl":[[0,3.2,8.4]],"ltp":3.1,"tv":855.99,"id":18286408}],"tv":4716.92}]}
{"op":"mcm","clk":"991822035","pt":1580508651348,"mc":[{"id":"1.168096552","rc":[{"batb":[[2,3,46]],"ltp":3.1,"tv":855.99,"id":18286408}]}]}
{"op":"mcm","clk":"991823363","pt":1580508672492,"mc":[{"id":"1.168096552","rc":[{"batl":[[1,15,2.08],[2,21,1.5]],"ltp":9.8,"tv":164.84,"id":26640937}]}]}
{"op":"mcm","clk":"991824775","pt":1580508695401,"mc":[{"id":"1.168096552","rc":[{"trd":[[3.2,100.29]],"batb":[[0,3.2,11.81]],"batl":[[0,3.25,330],[1,3.3,28],[2,3.4,30]],"ltp":3.2,"tv":882.37,"id":18286408},{"batb":[[2,9.6,1.98]],"ltp":9.8,"tv":164.84,"id":26640937}],"tv":4743.3}]}
{"op":"mcm","clk":"991824797","pt":1580508695712,"mc":[{"id":"1.168096552","rc":[{"batb":[[0,10,5.08],[1,9.6,1.98],[2,8.4,3.13]],"ltp":9.8,"tv":164.84,"id":26640937}]}]}
{"op":"mcm","clk":"991825258","pt":1580508703142,"mc":[{"id":"1.168096552","rc":[{"batb":[[2,3,49]],"ltp":3.2,"tv":882.37,"id":18286408}]}]}
{"op":"mcm","clk":"991826937","pt":1580508725457,"mc":[{"id":"1.168096552","rc":[{"batb":[[2,8.6,7.14]],"ltp":9.8,"tv":164.84,"id":26640937}]}]}
{"op":"mcm","clk":"991827130","pt":1580508728453,"mc":[{"id":"1.168096552","rc":[{"batb":[[0,3.2,15.28]],"ltp":3.2,"tv":882.37,"id":18286408}]}]}
{"op":"mcm","clk":"991827162","pt":1580508728965,"mc":[{"id":"1.168096552","rc":[{"batb":[[0,10,7.06],[1,8.6,7.14],[2,8.4,3]],"ltp":9.8,"tv":164.84,"id":26640937}]}]}
{"op":"mcm","clk":"991828489","pt":1580508750291,"mc":[{"id":"1.168096552","rc":[{"batb":[[0,3.2,20.32]],"ltp":3.2,"tv":882.37,"id":18286408}]}]}
{"op":"mcm","clk":"991828798","pt":1580508755316,"mc":[{"id":"1.168096552","rc":[{"batb":[[1,8.4,3.13],[2,7,25.69]],"ltp":9.8,"tv":164.84,"id":26640937}]}]}
{"op":"mcm","clk":"991832371","pt":1580508811183,"mc":[{"id":"1.168096552","rc":[{"batb":[[0,36,1.04],[1,34,8.76],[2,32,3.36]],"ltp":36.0,"tv":7.99,"id":27706761}]}]}
{"op":"mcm","clk":"991832928","pt":1580508822473,"mc":[{"id":"1.168096552","rc":[{"trd":[[2.82,663.54]],"batb":[[0,2.82,51.91],[1,2.8,242.98],[2,2.78,3.36]],"batl":[[0,2.96,4],[1,2.98,19.35],[2,3,33.61]],"ltp":2.82,"tv":2923.18,"id":52106}],"tv":4839.48}]}
{"op":"mcm","clk":"991832968","pt":1580508823394,"mc":[{"id":"1.168096552","rc":[{"batb":[[2,3,57.62]],"ltp":3.2,"tv":882.37,"id":18286408}]}]}
{"op":"mcm","clk":"991833016","pt":1580508824477,"mc":[{"id":"1.168096552","rc":[{"trd":[[4.5,241.43]],"batb":[[0,4.5,1.25],[1,4.3,40.86],[2,4.2,110]],"batl":[[0,5,2.7],[1,5.1,20],[2,5.3,9]],"ltp":4.5,"tv":844.76,"id":21580749}],"tv":4855.86}]}
{"op":"mcm","clk":"991833102","pt":1580508826327,"mc":[{"id":"1.168096552","rc":[{"batb":[[1,4.4,22.83],[2,4.3,40.86]],"ltp":4.5,"tv":844.76,"id":21580749}]}]}
{"op":"mcm","clk":"991833119","pt":1580508826584,"mc":[{"id":"1.168096552","rc":[{"batl":[[0,4.9,2],[1,5,2.7],[2,5.1,20]],"ltp":4.5,"tv":844.76,"id":21580749}]}]}
{"op":"mcm","clk":"991833726","pt":1580508839829,"mc":[{"id":"1.168096552","rc":[{"batb":[[0,2.84,29.48],[1,2.82,51.91],[2,2.8,242.98]],"batl":[[0,2.94,28.48],[1,2.96,4],[2,2.98,19.35]],"ltp":2.82,"tv":2923.18,"id":52106}]}]}
{"op":"mcm","clk":"991833906","pt":1580508844511,"mc":[{"id":"1.168096552","rc":[{"batb":[[1,4.3,40.86],[2,4.2,110]],"batl":[[0,4.8,6.72],[1,4.9,2],[2,5,2.7]],"ltp":4.5,"tv":844.76,"id":21580749}]}]}
{"op":"mcm","clk":"991834069","pt":1580508847341,"mc":[{"id":"1.168096552","rc":[{"batb":[[0,10.5,5.1],[1,10,7.06],[2,8.4,3.13]],"ltp":9.8,"tv":164.84,"id":26640937}]}]}
{"op":"mcm","clk":"991834077","pt":1580508847545,"mc":[{"id":"1.168096552","rc":[{"batl":[[2,5.1,20]],"ltp":4.5,"tv":844.76,"id":21580749}]}]}
{"op":"mcm","clk":"991834259","pt":1580508851257,"mc":[{"id":"1.168096552","rc":[{"batl":[[0,4.7,2],[1,4.8,6.72]],"ltp":4.5,"tv":844.76,"id":21580749}]}]}
{"op":"mcm","clk":"991834518","pt":1580508855946,"mc":[{"id":"1.168096552","rc":[{"batb":[[0,2.86,6.99],[1,2.84,29.48],[2,2.82,51.91]],"ltp":2.82,"tv":2923.18,"id":52106}]}]}
{"op":"mcm","clk":"991836084","pt":1580508887021,"mc":[{"id":"1.168096552","rc":[{"batb":[[0,2.88,6.29],[1,2.86,6.99],[2,2.84,29.48]],"batl":[[0,2.92,10.51],[1,2.94,28.48],[2,2.96,4]],"ltp":2.82,"tv":2923.18,"id":52106}]}]}
{"op":"mcm","clk":"991837156","pt":1580508909037,"mc":[{"id":"1.168096552","rc":[{"batb":[[1,2.84,29.48],[2,2.82,51.91]],"ltp":2.82,"tv":2923.18,"id":52106}]}]}
{"op":"mcm","clk":"991837211","pt":1580508910544,"mc":[{"id":"1.168096552","rc":[{"batb":[[1,2.82,51.91],[2,2.8,233.91]],"batl":[[1,2.96,4],[2,2.98,19.35]],"ltp":2.82,"tv":2923.18,"id":52106}]}]}
{"op":"mcm","clk":"991837385","pt":1580508914452,"mc":[{"id":"1.168096552","rc":[{"batb":[[1,2.84,6],[2,2.82,51.91]],"ltp":2.82,"tv":2923.18,"id":52106}]}]}
{"op":"mcm","clk":"991839675","pt":1580508960492,"mc":[{"id":"1.168096552","rc":[{"batb":[[0,10.5,8.46]],"ltp":9.8,"tv":164.84,"id":26640937}]}]}
{"op":"mcm","clk":"991842972","pt":1580509022415,"mc":[{"id":"1.168096552","rc":[{"trd":[[2.92,848.65],[2.94,270.96]],"batb":[[0,2.9,5.94],[1,2.88,6.29],[2,2.84,6]],"batl":[[0,2.96,4],[1,2.98,19.35],[2,3,33.61]],"ltp":2.94,"tv":3175.24,"id":52106}],"tv":5107.92}]}
{"op":"mcm","clk":"991843507","pt":1580509031418,"mc":[{"id":"1.168096552","rc":[{"batb":[[0,2.9,9.3]],"ltp":2.94,"tv":3175.24,"id":52106}]}]}
{"op":"mcm","clk":"991843554","pt":1580509032140,"mc":[{"id":"1.168096552","rc":[{"trd":[[2.96,8],[2.98,85.32]],"batl":[[0,3,33.61],[1,3.1,4],[2,3.15,11.2]],"ltp":2.98,"tv":3259.25,"id":52106}],"tv":5191.94}]}
{"op":"mcm","clk":"991844707","pt":1580509054340,"mc":[{"id":"1.168096552","rc":[{"batb":[[1,34,16.21]],"ltp":36.0,"tv":7.99,"id":27706761}]}]}
{"op":"mcm","clk":"991845452","pt":1580509071461,"mc":[{"id":"1.168096552","rc":[{"batb":[[1,2.88,10.19]],"batl":[[1,3.05,3.68],[2,3.1,4]],"ltp":2.98,"tv":3259.25,"id":52106}]}]}
{"op":"mcm","clk":"991846082","pt":1580509085386,"mc":[{"id":"1.168096552","rc":[{"batb":[[0,2.92,4],[1,2.9,9.3],[2,2.88,10.19]],"ltp":2.98,"tv":3259.25,"id":52106}]}]}
{"op":"mcm","clk":"991850696","pt":1580509183419,"mc":[{"id":"1.168096552","rc":[{"trd":[[11,96.84]],"batl":[[0,11,28.58]],"ltp":11.0,"tv":182.84,"id":26640937}],"tv":5209.94}]}
{"op":"mcm","clk":"991851064","pt":1580509191803,"mc":[{"id":"1.168096552","rc":[{"batb":[[2,7,25.82]],"ltp":11.0,"tv":182.84,"id":26640937}]}]}
{"op":"mcm","clk":"991851586","pt":1580509203457,"mc":[{"id":"1.168096552","rc":[{"batb":[[0,4.5,37.25]],"ltp":4.5,"tv":844.76,"id":21580749}]}]}
{"op":"mcm","clk":"991852331","pt":1580509218353,"mc":[{"id":"1.168096552","rc":[{"batb":[[1,34,1.75]],"ltp":36.0,"tv":7.99,"id":27706761}]}]}
{"op":"mcm","clk":"991852691","pt":1580509226074,"mc":[{"id":"1.168096552","rc":[{"batb":[[2,30,2.03]],"ltp":36.0,"tv":7.99,"id":27706761}]}]}
{"op":"mcm","clk":"991852971","pt":1580509232496,"mc":[{"id":"1.168096552","rc":[{"batb":[[0,2.94,5.86],[1,2.92,4],[2,2.9,3.36]],"ltp":2.98,"tv":3259.25,"id":52106}]}]}
{"op":"mcm","clk":"991853083","pt":1580509235383,"mc":[{"id":"1.168096552","rc":[{"batl":[[0,4.7,4.87]],"ltp":4.5,"tv":844.76,"id":21580749}]}]}
{"op":"mcm","clk":"991854663","pt":1580509267516,"mc":[{"id":"1.168096552","rc":[{"batl":[[1,3.1,4],[2,3.15,11.2]],"ltp":2.98,"tv":3259.25,"id":52106}]}]}
{"op":"mcm","clk":"991856671","pt":1580509308460,"mc":[{"id":"1.168096552","rc":[{"trd":[[3.2,140.93]],"batb":[[0,3.05,20.97],[1,3,57.62],[2,2.88,36]],"ltp":3.2,"tv":923.01,"id":18286408}],"tv":5250.58}]}
{"op":"mcm","clk":"991868460","pt":1580509353906,"mc":[{"id":"1.168096552","rc":[{"batb":[[0,10.5,10.44],[1,10,5.08]],"ltp":11.0,"tv":182.84,"id":26640937},{"batb":[[0,4.5,38.93],[1,4.3,39.18]],"ltp":4.5,"tv":844.76,"id":21580749},{"batb":[[1,32,1.75]],"ltp":36.0,"tv":7.99,"id":27706761},{"batb":[[0,2.94,9.31]],"ltp":2.98,"tv":3259.25,"id":52106}]}]}
{"op":"mcm","clk":"991869743","pt":1580509384264,"mc":[{"id":"1.168096552","rc":[{"batl":[[0,3,83.61]],"ltp":2.98,"tv":3259.25,"id":52106}]}]}
{"op":"mcm","clk":"991870187","pt":1580509392482,"mc":[{"id":"1.168096552","rc":[{"batb":[[0,32,2.23],[1,30,2.03],[2,20,1.68]],"ltp":36.0,"tv":7.99,"id":27706761}]}]}
{"op":"mcm","clk":"991870279","pt":1580509394450,"mc":[{"id":"1.168096552","rc":[{"trd":[[3,44.49]],"batl":[[0,3,68.61]],"ltp":3.0,"tv":3289.25,"id":52106}],"tv":5280.58}]}
{"op":"mcm","clk":"991870831","pt":1580509404395,"mc":[{"id":"1.168096552","rc":[{"trd":[[3.05,89.62]],"batb":[[0,3,57.62],[1,2.9,5.24]],"ltp":3.05,"tv":964.95,"id":18286408}],"tv":5322.51}]}
{"op":"mcm","clk":"991870939","pt":1580509406353,"mc":[{"id":"1.168096552","rc":[{"batb":[[0,3,54.62],[2,2.88,39]],"ltp":3.05,"tv":964.95,"id":18286408}]}]}
{"op":"mcm","clk":"991871044","pt":1580509408260,"mc":[{"id":"1.168096552","rc":[{"trd":[[3.25,80.62]],"batl":[[0,3.25,320]],"ltp":3.25,"tv":984.95,"id":18286408}],"tv":5342.51}]}
{"op":"mcm","clk":"991871326","pt":1580509415095,"mc":[{"id":"1.168096552","rc":[{"batb":[[0,3,57.62],[2,2.88,36]],"batl":[[0,3.2,4],[1,3.25,320],[2,3.3,28]],"ltp":3.25,"tv":984.95,"id":18286408},{"trd":[[4.5,261.43]],"batb":[[0,4.5,28.93]],"ltp":4.5,"tv":864.76,"id":21580749}],"tv":5362.51}]}
{"op":"mcm","clk":"991871408","pt":1580509417460,"mc":[{"id":"1.168096552","rc":[{"batb":[[1,2.88,36],[2,2.86,21.01]],"ltp":3.25,"tv":984.95,"id":18286408},{"trd":[[4.7,25.4]],"batb":[[0,4.7,5.13],[1,4.5,28.93],[2,4.3,39.18]],"batl":[[0,4.8,6.72],[1,5.1,20],[2,5.3,9]],"ltp":4.7,"tv":874.5,"id":21580749}],"tv":5372.25}]}
{"op":"mcm","clk":"991871682","pt":1580509422596,"mc":[{"id":"1.168096552","rc":[{"batb":[[2,4.3,4.21]],"ltp":4.7,"tv":874.5,"id":21580749}]}]}
{"op":"mcm","clk":"991871917","pt":1580509427281,"mc":[{"id":"1.168096552","rc":[{"trd":[[2.88,28.79],[2.9,91.61],[2.92,856.65],[2.94,289.58]],"batb":[[0,2.88,4.16],[1,2.84,6],[2,2.82,51.91]],"ltp":2.88,"tv":3326.85,"id":52106}],"tv":5409.85}]}
{"op":"mcm","clk":"991872060","pt":1580509430478,"mc":[{"id":"1.168096552","rc":[{"batl":[[0,3,70.61]],"ltp":2.88,"tv":3326.85,"id":52106}]}]}
{"op":"mcm","clk":"991872281","pt":1580509434502,"mc":[{"id":"1.168096552","rc":[{"batb":[[1,2.86,2.54],[2,2.84,6]],"batl":[[1,3.05,2.38],[2,3.1,4]],"ltp":2.88,"tv":3326.85,"id":52106}]}]}
{"op":"mcm","clk":"991872654","pt":1580509442188,"mc":[{"id":"1.168096552","rc":[{"batl":[[0,2.98,4],[1,3,70.61],[2,3.05,2.38]],"ltp":2.88,"tv":3326.85,"id":52106}]}]}
{"op":"mcm","clk":"991873621","pt":1580509461022,"mc":[{"id":"1.168096552","rc":[{"batb":[[0,4.5,28.93],[1,4.3,4.21],[2,4.2,110]],"ltp":4.7,"tv":874.5,"id":21580749}]}]}
{"op":"mcm","clk":"991874047","pt":1580509469516,"mc":[{"id":"1.168096552","rc":[{"trd":[[4.8,14]],"batl":[[0,4.8,4.72]],"ltp":4.8,"tv":878.5,"id":21580749}],"tv":5413.85}]}
{"op":"mcm","clk":"991874391","pt":1580509475451,"mc":[{"id":"1.168096552","rc":[{"batb":[[0,4.6,3],[1,4.5,28.93],[2,4.3,4.21]],"ltp":4.8,"tv":878.5,"id":21580749}]}]}
{"op":"mcm","clk":"991875487","pt":1580509496457,"mc":[{"id":"1.168096552","rc":[{"batb":[[0,3,59.35]],"ltp":3.25,"tv":984.95,"id":18286408},{"batb":[[0,4.6,4.68],[1,4.5,27.25]],"ltp":4.8,"tv":878.5,"id":21580749},{"batb":[[0,2.88,13]],"ltp":2.88,"tv":3326.85,"id":52106}]}]}
{"op":"mcm","clk":"991875965","pt":1580509504460,"mc":[{"id":"1.168096552","rc":[{"batl":[[1,990,2]],"ltp":24.0,"tv":32.69,"id":24608298}]}]}
{"op":"mcm","clk":"991876218","pt":1580509509263,"mc":[{"id":"1.168096552","rc":[{"batb":[[0,4.6,1.68]],"ltp":4.8,"tv":878.5,"id":21580749}]}]}
{"op":"mcm","clk":"991876372","pt":1580509512050,"mc":[{"id":"1.168096552","rc":[{"batl":[[1,990,3.3]],"ltp":24.0,"tv":32.69,"id":24608298}]}]}
{"op":"mcm","clk":"991876652","pt":1580509517368,"mc":[{"id":"1.168096552","rc":[{"batl":[[1,990,1.3]],"ltp":24.0,"tv":32.69,"id":24608298}]}]}
{"op":"mcm","clk":"991877498","pt":1580509532609,"mc":[{"id":"1.168096552","rc":[{"batb":[[0,3.05,5.65],[1,3,59.35],[2,2.88,36]],"ltp":3.25,"tv":984.95,"id":18286408}]}]}
{"op":"mcm","clk":"991877963","pt":1580509542430,"mc":[{"id":"1.168096552","rc":[{"batl":[[0,3.25,320],[1,3.3,28],[2,3.4,30]],"ltp":3.25,"tv":984.95,"id":18286408}]}]}
{"op":"mcm","clk":"991878683","pt":1580509556408,"mc":[{"id":"1.168096552","rc":[{"batl":[[1,3,68.61]],"ltp":2.88,"tv":3326.85,"id":52106}]}]}
{"op":"mcm","clk":"991879194","pt":1580509568126,"mc":[{"id":"1.168096552","rc":[{"trd":[[2.88,54.79]],"batb":[[0,2.86,13.31],[1,2.84,6],[2,2.82,51.91]],"batl":[[0,2.98,4.45]],"ltp":2.88,"tv":3352.85,"id":52106}],"tv":5439.85}]}
{"op":"mcm","clk":"991880000","pt":1580509588986,"mc":[{"id":"1.168096552","rc":[{"batb":[[0,3.05,7.38],[1,3,57.62]],"ltp":3.25,"tv":984.95,"id":18286408},{"batb":[[0,22,2.46],[1,21,2.74],[2,13,2]],"ltp":24.0,"tv":32.69,"id":24608298}]}]}
{"op":"mcm","clk":"991880458","pt":1580509599372,"mc":[{"id":"1.168096552","rc":[{"batl":[[0,2.98,4]],"ltp":2.88,"tv":3352.85,"id":52106}]}]}
{"op":"mcm","clk":"991881460","pt":1580509623102,"mc":[{"id":"1.168096552","rc":[{"batb":[[0,4.6,5.43]],"ltp":4.8,"tv":878.5,"id":21580749}]}]}
{"op":"mcm","clk":"991886781","pt":1580509741462,"mc":[{"id":"1.168096552","rc":[{"trd":[[2.86,100.81]],"batb":[[0,2.88,5.98]],"batl":[[0,2.98,6.42]],"ltp":2.86,"tv":3362.85,"id":52106}],"tv":5449.85}]}
{"op":"mcm","clk":"991887795","pt":1580509761300,"mc":[{"id":"1.168096552","rc":[{"batl":[[0,2.96,2.45],[1,2.98,6.42],[2,3,68.61]],"ltp":2.86,"tv":3362.85,"id":52106}]}]}
{"op":"mcm","clk":"991890673","pt":1580509821121,"mc":[{"id":"1.168096552","rc":[{"batb":[[0,34,1.07],[1,32,1.75],[2,30,2.03]],"ltp":36.0,"tv":7.99,"id":27706761}]}]}
{"op":"mcm","clk":"991891806","pt":1580509848020,"mc":[{"id":"1.168096552","rc":[{"batb":[[0,3.15,200],[1,3.05,7.38],[2,3,57.62]],"ltp":3.25,"tv":984.95,"id":18286408}]}]}
{"op":"mcm","clk":"991891862","pt":1580509849258,"mc":[{"id":"1.168096552","rc":[{"batb":[[0,3.2,8.4],[1,3.15,200],[2,3.05,7.38]],"ltp":3.25,"tv":984.95,"id":18286408}]}]}
{"op":"mcm","clk":"991892851","pt":1580509874448,"mc":[{"id":"1.168096552","rc":[{"batb":[[1,2.86,6.99],[2,2.84,6]],"ltp":2.86,"tv":3362.85,"id":52106}]}]}
{"op":"mcm","clk":"991893688","pt":1580509892767,"mc":[{"id":"1.168096552","rc":[{"batl":[[0,55,3],[1,290,9.53],[2,990,1.3]],"ltp":24.0,"tv":32.69,"id":24608298}]}]}
{"op":"mcm","clk":"991893936","pt":1580509897006,"mc":[{"id":"1.168096552","rc":[{"batb":[[1,21,2.78]],"ltp":24.0,"tv":32.69,"id":24608298}]}]}
{"op":"mcm","clk":"991893996","pt":1580509898397,"mc":[{"id":"1.168096552","rc":[{"batl":[[0,55,3.2],[1,290,9.33]],"ltp":24.0,"tv":32.69,"id":24608298}]}]}
{"op":"mcm","clk":"991894476","pt":1580509910004,"mc":[{"id":"1.168096552","rc":[{"batl":[[0,55,3.3]],"ltp":24.0,"tv":32.69,"id":24608298}]}]}
{"op":"mcm","clk":"991894548","pt":1580509911821,"mc":[{"id":"1.168096552","rc":[{"batl":[[0,2.96,4.45]],"ltp":2.86,"tv":3362.85,"id":52106}]}]}
{"op":"mcm","clk":"991895075","pt":1580509923423,"mc":[{"id":"1.168096552","rc":[{"batl":[[1,2.98,2.42]],"ltp":2.86,"tv":3362.85,"id":52106}]}]}
{"op":"mcm","clk":"991896546","pt":1580509960242,"mc":[{"id":"1.168096552","rc":[{"batl":[[2,3,88.61]],"ltp":2.86,"tv":3362.85,"id":52106}]}]}
{"op":"mcm","clk":"991896809","pt":1580509965853,"mc":[{"id":"1.168096552","rc":[{"batl":[[1,140,9],[2,990,1.63]],"ltp":24.0,"tv":32.69,"id":24608298}]}]}
{"op":"mcm","clk":"991898583","pt":1580510002305,"mc":[{"id":"1.168096552","rc":[{"batb":[[0,4.7,10],[1,4.6,5.43],[2,4.5,27.25]],"ltp":4.8,"tv":878.5,"id":21580749}]}]}
{"op":"mcm","clk":"991898600","pt":1580510002599,"mc":[{"id":"1.168096552","rc":[{"trd":[[4.7,45.4]],"batb":[[0,4.6,5.43],[1,4.5,27.25],[2,4.3,4.21]],"ltp":4.7,"tv":898.5,"id":21580749}],"tv":5469.85}]}
{"op":"mcm","clk":"991899707","pt":1580510029114,"mc":[{"id":"1.168096552","rc":[{"trd":[[2.88,58.79]],"batb":[[0,2.88,3.98]],"ltp":2.88,"tv":3366.85,"id":52106}],"tv":5473.85}]}
{"op":"mcm","clk":"991899925","pt":1580510034149,"mc":[{"id":"1.168096552","rc":[{"batl":[[0,2.96,2.45]],"ltp":2.88,"tv":3366.85,"id":52106}]}]}
{"op":"mcm","clk":"991900070","pt":1580510037240,"mc":[{"id":"1.168096552","rc":[{"trd":[[4.7,65.4]],"ltp":4.7,"tv":918.5,"id":21580749}],"tv":5493.85}]}
{"op":"mcm","clk":"991900656","pt":1580510050465,"mc":[{"id":"1.168096552","rc":[{"batb":[[0,3.2,37.81]],"ltp":3.25,"tv":984.95,"id":18286408},{"batb":[[0,4.6,15.51]],"ltp":4.7,"tv":918.5,"id":21580749},{"batb":[[0,2.88,7.34]],"ltp":2.88,"tv":3366.85,"id":52106}]}]}
{"op":"mcm","clk":"991901258","pt":1580510063770,"mc":[{"id":"1.168096552","rc":[{"trd":[[2.88,73.47]],"batb":[[0,2.86,6.99],[1,2.84,6],[2,2.82,51.91]],"batl":[[0,2.88,2.66],[1,2.96,2.45],[2,2.98,2.42]],"ltp":2.88,"tv":3381.53,"id":52106}],"tv":5508.53}]}
{"op":"mcm","clk":"991901475","pt":1580510068441,"mc":[{"id":"1.168096552","rc":[{"batl":[[1,2.98,2.42],[2,3,88.61]],"ltp":2.88,"tv":3381.53,"id":52106}]}]}
{"op":"mcm","clk":"991901604","pt":1580510071369,"mc":[{"id":"1.168096552","rc":[{"trd":[[4.8,23.44]],"batb":[[0,4.8,5.28],[1,4.6,15.51],[2,4.5,27.25]],"batl":[[0,5,8.06]],"ltp":4.8,"tv":927.94,"id":21580749}],"tv":5517.97}]}
{"op":"mcm","clk":"991901631","pt":1580510071993,"mc":[{"id":"1.168096552","rc":[{"trd":[[3.2,154.93]],"batb":[[0,3.2,30.81]],"ltp":3.2,"tv":998.95,"id":18286408},{"trd":[[4.8,34]],"batb":[[0,4.6,15.51],[1,4.5,27.25],[2,4.3,4.21]],"batl":[[0,4.7,4.72],[1,5,8.06],[2,5.1,20]],"ltp":4.8,"tv":938.5,"id":21580749}],"tv":5542.53}]}
{"op":"mcm","clk":"991901896","pt":1580510078462,"mc":[{"id":"1.168096552","rc":[{"trd":[[4.6,112.5]],"batb":[[0,4.6,10.51]],"ltp":4.6,"tv":948.5,"id":21580749}],"tv":5552.53}]}
{"op":"mcm","clk":"991902350","pt":1580510087273,"mc":[{"id":"1.168096552","rc":[{"batl":[[1,2.98,6.42]],"ltp":2.88,"tv":3381.53,"id":52106}]}]}
{"op":"mcm","clk":"991902470","pt":1580510090268,"mc":[{"id":"1.168096552","rc":[{"batb":[[0,2.84,6],[1,2.82,51.91],[2,2.76,6]],"ltp":2.88,"tv":3381.53,"id":52106}]}]}
{"op":"mcm","clk":"991904711","pt":1580510136294,"mc":[{"id":"1.168096552","rc":[{"batl":[[0,4.7,14.72]],"ltp":4.6,"tv":948.5,"id":21580749}]}]}
{"op":"mcm","clk":"991905381","pt":1580510151314,"mc":[{"id":"1.168096552","rc":[{"batb":[[0,4.6,20.51]],"ltp":4.6,"tv":948.5,"id":21580749}]}]}
{"op":"mcm","clk":"991906371","pt":1580510178655,"mc":[{"id":"1.168096552","rc":[{"trd":[[3.2,160.93]],"batb":[[0,3.2,27.81]],"ltp":3.2,"tv":1004.95,"id":18286408}],"tv":5558.53}]}
{"op":"mcm","clk":"991906610","pt":1580510183953,"mc":[{"id":"1.168096552","rc":[{"batb":[[0,2.84,11.88]],"ltp":2.88,"tv":3381.53,"id":52106}]}]}
{"op":"mcm","clk":"991907138","pt":1580510198954,"mc":[{"id":"1.168096552","rc":[{"batb":[[0,2.86,15.3],[1,2.84,11.88],[2,2.82,51.91]],"batl":[[1,2.98,4]],"ltp":2.88,"tv":3381.53,"id":52106}]}]}
{"op":"mcm","clk":"991908276","pt":1580510229294,"mc":[{"id":"1.168096552","rc":[{"batl":[[0,4.7,17.72]],"ltp":4.6,"tv":948.5,"id":21580749}]}]}
{"op":"mcm","clk":"991908781","pt":1580510244006,"mc":[{"id":"1.168096552","rc":[{"batl":[[1,2.98,7.79]],"ltp":2.88,"tv":3381.53,"id":52106}]}]}
{"op":"mcm","clk":"991920938","pt":1580510306703,"mc":[{"id":"1.168096552","rc":[{"trd":[[4.6,122.5]],"batb":[[0,4.6,15.51]],"ltp":4.6,"tv":958.5,"id":21580749}],"tv":5568.53}]}
{"op":"mcm","clk":"991921102","pt":1580510310885,"mc":[{"id":"1.168096552","rc":[{"batl":[[2,3,68.61]],"ltp":2.88,"tv":3381.53,"id":52106}]}]}
{"op":"mcm","clk":"991922240","pt":1580510338039,"mc":[{"id":"1.168096552","rc":[{"trd":[[2.86,131.41]],"batb":[[0,2.84,11.88],[1,2.82,51.91],[2,2.76,6]],"batl":[[0,2.86,4.7],[1,2.88,2.66],[2,2.98,7.79]],"ltp":2.86,"tv":3412.13,"id":52106}],"tv":5599.13}]}
{"op":"mcm","clk":"991922322","pt":1580510339629,"mc":[{"id":"1.168096552","rc":[{"batl":[[2,2.98,3.79]],"ltp":2.86,"tv":3412.13,"id":52106}]}]}
{"op":"mcm","clk":"991922396","pt":1580510341320,"mc":[{"id":"1.168096552","rc":[{"batb":[[0,3.2,41.39]],"ltp":3.2,"tv":1004.95,"id":18286408},{"batb":[[0,10.5,14.58]],"ltp":11.0,"tv":182.84,"id":26640937},{"batb":[[0,4.6,24.96]],"ltp":4.6,"tv":958.5,"id":21580749},{"batb":[[0,34,2.88]],"ltp":36.0,"tv":7.99,"id":27706761},{"trd":[[2.86,140.81]],"batb":[[0,2.86,10.5],[1,2.84,11.88],[2,2.82,51.91]],"batl":[[0,2.88,2.66],[1,2.98,3.79],[2,3,68.61]],"ltp":2.86,"tv":3421.53,"id":52106},{"batb":[[0,22,5.26]],"ltp":24.0,"tv":32.69,"id":24608298}],"tv":5608.53}]}
{"op":"mcm","clk":"991922896","pt":1580510352362,"mc":[{"id":"1.168096552","rc":[{"batb":[[0,34,17.34]],"ltp":36.0,"tv":7.99,"id":27706761},{"batb":[[0,23,16.55],[1,22,4.56],[2,21,2.78]],"ltp":24.0,"tv":32.69,"id":24608298}]}]}
{"op":"mcm","clk":"991923130","pt":1580510357438,"mc":[{"id":"1.168096552","rc":[{"batb":[[2,21,2.74]],"ltp":24.0,"tv":32.69,"id":24608298}]}]}
{"op":"mcm","clk":"991923153","pt":1580510358053,"mc":[{"id":"1.168096552","rc":[{"batb":[[1,22,4.6]],"ltp":24.0,"tv":32.69,"id":24608298}]}]}
{"op":"mcm","clk":"991923302","pt":1580510362266,"mc":[{"id":"1.168096552","rc":[{"batb":[[0,36,5.52],[1,34,16.86],[2,32,1.75]],"ltp":36.0,"tv":7.99,"id":27706761},{"batb":[[0,24,5.74],[1,23,15.85],[2,22,4.6]],"ltp":24.0,"tv":32.69,"id":24608298}]}]}
{"op":"mcm","clk":"991923348","pt":1580510363345,"mc":[{"id":"1.168096552","rc":[{"batb":[[1,34,16.27]],"ltp":36.0,"tv":7.99,"id":27706761}]}]}
{"op":"mcm","clk":"991923403","pt":1580510364476,"mc":[{"id":"1.168096552","rc":[{"trd":[[2.86,144.81]],"batb":[[0,2.86,8.5]],"ltp":2.86,"tv":3425.53,"id":52106}],"tv":5612.53}]}
{"op":"mcm","clk":"991923450","pt":1580510365451,"mc":[{"id":"1.168096552","rc":[{"trd":[[2.84,105.66],[2.86,161.8]],"batb":[[0,2.84,5.44],[1,2.82,51.91],[2,2.76,6]],"ltp":2.84,"tv":3455.4,"id":52106}],"tv":5642.4}]}
{"op":"mcm","clk":"991923506","pt":1580510366475,"mc":[{"id":"1.168096552","rc":[{"trd":[[2.82,670.42],[2.84,116.55]],"batb":[[0,2.82,48.47],[1,2.76,6],[2,2.7,35]],"ltp":2.82,"tv":3473.17,"id":52106},{"batb":[[2,22,4.56]],"ltp":24.0,"tv":32.69,"id":24608298}],"tv":5660.17}]}
{"op":"mcm","clk":"991923572","pt":1580510367452,"mc":[{"id":"1.168096552","rc":[{"batb":[[1,23,15.9]],"ltp":24.0,"tv":32.69,"id":24608298}]}]}
{"op":"mcm","clk":"991923593","pt":1580510367965,"mc":[{"id":"1.168096552","rc":[{"trd":[[2.82,676.42],[2.84,122.55]],"batb":[[0,2.82,45.47]],"ltp":2.82,"tv":3485.17,"id":52106}],"tv":5672.17}]}
{"op":"mcm","clk":"991923643","pt":1580510369449,"mc":[{"id":"1.168096552","rc":[{"batb":[[1,34,1.81]],"ltp":36.0,"tv":7.99,"id":27706761},{"batb":[[1,22,4.6],[2,21,2.74]],"ltp":24.0,"tv":32.69,"id":24608298}]}]}
{"op":"mcm","clk":"991923699","pt":1580510370375,"mc":[{"id":"1.168096552","rc":[{"batb":[[0,38,12.94],[1,36,5.52],[2,34,1.81]],"ltp":36.0,"tv":7.99,"id":27706761},{"batl":[[0,2.86,6],[1,2.88,2.66],[2,2.98,3.79]],"ltp":2.82,"tv":3485.17,"id":52106},{"batb":[[0,25,14.58],[1,24,5.74],[2,22,4.6]],"ltp":24.0,"tv":32.69,"id":24608298}]}]}
{"op":"mcm","clk":"991923788","pt":1580510372481,"mc":[{"id":"1.168096552","rc":[{"batb":[[2,22,4.56]],"ltp":24.0,"tv":32.69,"id":24608298}]}]}
{"op":"mcm","clk":"991923813","pt":1580510373046,"mc":[{"id":"1.168096552","rc":[{"batb":[[1,24,5.77]],"ltp":24.0,"tv":32.69,"id":24608298}]}]}
{"op":"mcm","clk":"991925261","pt":1580510413450,"mc":[{"id":"1.168096552","rc":[{"trd":[[3.2,243.71]],"batb":[[0,3.15,200],[1,3.05,7.38],[2,3,57.62]],"ltp":3.2,"tv":1087.73,"id":18286408},{"trd":[[4.7,100.84]],"batl":[[0,5,8.06],[1,5.1,20],[2,5.3,9]],"ltp":4.7,"tv":993.94,"id":21580749},{"trd":[[2.86,173.8]],"batl":[[0,2.88,2.66],[1,2.98,3.79],[2,3,68.61]],"ltp":2.86,"tv":3497.17,"id":52106}],"tv":5802.38}]}
{"op":"mcm","clk":"991925439","pt":1580510417514,"mc":[{"id":"1.168096552","rc":[{"batl":[[0,2.86,2.98],[1,2.88,2.66],[2,2.98,3.79]],"ltp":2.86,"tv":3497.17,"id":52106}]}]}
{"op":"mcm","clk":"991928026","pt":1580510481900,"mc":[{"id":"1.168096552","rc":[{"batl":[[0,3.2,22],[1,3.25,320],[2,3.3,28]],"ltp":3.2,"tv":1087.73,"id":18286408}]}]}
{"op":"mcm","clk":"991928394","pt":1580510490509,"mc":[{"id":"1.168096552","rc":[{"batb":[[0,40,4.2],[1,38,12.94],[2,34,2.29]],"ltp":36.0,"tv":7.99,"id":27706761},{"batb":[[0,2.84,15.12],[1,2.82,45.47],[2,2.76,6]],"ltp":2.86,"tv":3497.17,"id":52106},{"batb":[[0,26,4.2],[1,25,14.58],[2,22,5.29]],"ltp":24.0,"tv":32.69,"id":24608298}]}]}
{"op":"mcm","clk":"991928490","pt":1580510492514,"mc":[{"id":"1.168096552","rc":[{"batb":[[0,42,11.71],[1,40,4.2]],"ltp":36.0,"tv":7.99,"id":27706761},{"batb":[[0,26,18.23],[1,22,5.29],[2,21,2.74]],"ltp":24.0,"tv":32.69,"id":24608298}]}]}
{"op":"mcm","clk":"991929165","pt":1580510509412,"mc":[{"id":"1.168096552","rc":[{"batb":[[0,40,4.2],[1,34,2.29],[2,32,1.75]],"ltp":36.0,"tv":7.99,"id":27706761},{"batb":[[0,26,4.2]],"ltp":24.0,"tv":32.69,"id":24608298}]}]}
{"op":"mcm","clk":"991929177","pt":1580510509926,"mc":[{"id":"1.168096552","rc":[{"batb":[[1,22,2.5],[2,13,2.76]],"ltp":24.0,"tv":32.69,"id":24608298}]}]}
{"op":"mcm","clk":"991929291","pt":1580510513310,"mc":[{"id":"1.168096552","rc":[{"batl":[[2,2.96,4]],"ltp":2.86,"tv":3497.17,"id":52106}]}]}
{"op":"mcm","clk":"991929380","pt":1580510515410,"mc":[{"id":"1.168096552","rc":[{"batb":[[0,34,2.29],[1,32,1.75],[2,30,2.03]],"ltp":36.0,"tv":7.99,"id":27706761},{"batb":[[0,22,2.5],[1,13,2.76],[2,9.2,4.59]],"ltp":24.0,"tv":32.69,"id":24608298}]}]}
{"op":"mcm","clk":"991929489","pt":1580510518403,"mc":[{"id":"1.168096552","rc":[{"batb":[[0,3.15,201.73],[1,3.05,5.65]],"ltp":3.2,"tv":1087.73,"id":18286408},{"batb":[[0,4.7,1.98],[1,4.6,24.96],[2,4.5,27.25]],"ltp":4.7,"tv":993.94,"id":21580749},{"batb":[[0,36,2.23],[1,34,1.81]],"ltp":36.0,"tv":7.99,"id":27706761},{"batb":[[0,2.84,16.8]],"ltp":2.86,"tv":3497.17,"id":52106},{"batb":[[0,21,1.49],[1,13.5,1.76],[2,13,2]],"ltp":24.0,"tv":32.69,"id":24608298}]}]}
{"op":"mcm","clk":"991929648","pt":1580510522427,"mc":[{"id":"1.168096552","rc":[{"batb":[[1,14,7.36],[2,13.5,1.76]],"ltp":24.0,"tv":32.69,"id":24608298}]}]}
{"op":"mcm","clk":"991929867","pt":1580510527318,"mc":[{"id":"1.168096552","rc":[{"batb":[[1,14.5,25.15],[2,14,7.36]],"ltp":24.0,"tv":32.69,"id":24608298}]}]}
{"op":"mcm","clk":"991929897","pt":1580510528137,"mc":[{"id":"1.168096552","rc":[{"batb":[[0,3.15,208.45]],"ltp":3.2,"tv":1087.73,"id":18286408}]}]}
{"op":"mcm","clk":"991930633","pt":1580510545236,"mc":[{"id":"1.168096552","rc":[{"batb":[[1,15,2.63],[2,14.5,25.15]],"ltp":24.0,"tv":32.69,"id":24608298}]}]}
{"op":"mcm","clk":"991931389","pt":1580510562483,"mc":[{"id":"1.168096552","rc":[{"batb":[[2,14,7.36]],"ltp":24.0,"tv":32.69,"id":24608298}]}]}
{"op":"mcm","clk":"991931397","pt":1580510562586,"mc":[{"id":"1.168096552","rc":[{"batb":[[1,15,26.93]],"ltp":24.0,"tv":32.69,"id":24608298}]}]}
{"op":"mcm","clk":"991934456","pt":1580510634322,"mc":[{"id":"1.168096552","rc":[{"batb":[[1,15.5,9.24],[2,15,26.93]],"ltp":24.0,"tv":32.69,"id":24608298}]}]}
{"op":"mcm","clk":"991934477","pt":1580510634832,"mc":[{"id":"1.168096552","rc":[{"batb":[[1,15.5,9.55]],"ltp":24.0,"tv":32.69,"id":24608298}]}]}
{"op":"mcm","clk":"991934853","pt":1580510643873,"mc":[{"id":"1.168096552","rc":[{"batb":[[1,16,2.77],[2,15.5,9.24]],"ltp":24.0,"tv":32.69,"id":24608298}]}]}
{"op":"mcm","clk":"991935112","pt":1580510649578,"mc":[{"id":"1.168096552","rc":[{"batb":[[1,16,25.56]],"ltp":24.0,"tv":32.69,"id":24608298}]}]}
{"op":"mcm","clk":"991935463","pt":1580510657046,"mc":[{"id":"1.168096552","rc":[{"batb":[[0,4.7,11.98],[1,4.6,14.96]],"ltp":4.7,"tv":993.94,"id":21580749}]}]}
{"op":"mcm","clk":"991935740","pt":1580510662193,"mc":[{"id":"1.168096552","rc":[{"batb":[[0,4.8,3.36],[1,4.7,11.98],[2,4.6,9.45]],"ltp":4.7,"tv":993.94,"id":21580749}]}]}
{"op":"mcm","clk":"991937905","pt":1580510709705,"mc":[{"id":"1.168096552","rc":[{"batl":[[0,2.88,2.66],[1,2.96,6.88],[2,2.98,3.79]],"ltp":2.86,"tv":3497.17,"id":52106}]}]}
{"op":"mcm","clk":"991938316","pt":1580510717429,"mc":[{"id":"1.168096552","rc":[{"batb":[[0,4.9,10],[1,4.8,3.36],[2,4.7,11.98]],"ltp":4.7,"tv":993.94,"id":21580749}]}]}
{"op":"mcm","clk":"991938330","pt":1580510717842,"mc":[{"id":"1.168096552","rc":[{"trd":[[4.9,20]],"batb":[[0,4.8,3.36],[1,4.7,11.98],[2,4.6,9.45]],"ltp":4.9,"tv":1013.94,"id":21580749}],"tv":5822.38}]}
{"op":"mcm","clk":"991940950","pt":1580510776388,"mc":[{"id":"1.168096552","rc":[{"batb":[[1,16.5,8.4],[2,16,25.56]],"ltp":24.0,"tv":32.69,"id":24608298}]}]}
{"op":"mcm","clk":"991941144","pt":1580510780480,"mc":[{"id":"1.168096552","rc":[{"batb":[[1,17,2.32],[2,16.5,8.4]],"ltp":24.0,"tv":32.69,"id":24608298}]}]}
{"op":"mcm","clk":"991941504","pt":1580510789517,"mc":[{"id":"1.168096552","rc":[{"batb":[[1,17,23.76]],"ltp":24.0,"tv":32.69,"id":24608298}]}]}
{"op":"mcm","clk":"991942411","pt":1580510813037,"mc":[{"id":"1.168096552","rc":[{"batl":[[1,15,3.08]],"ltp":11.0,"tv":182.84,"id":26640937},{"batb":[[1,17.5,5.89],[2,17,23.76]],"ltp":24.0,"tv":32.69,"id":24608298}]}]}
{"op":"mcm","clk":"991942739","pt":1580510820223,"mc":[{"id":"1.168096552","rc":[{"batb":[[2,17,21.45]],"ltp":24.0,"tv":32.69,"id":24608298}]}]}
{"op":"mcm","clk":"991942759","pt":1580510820640,"mc":[{"id":"1.168096552","rc":[{"batb":[[1,18,2.19],[2,17.5,5.89]],"ltp":24.0,"tv":32.69,"id":24608298}]}]}
{"op":"mcm","clk":"991942990","pt":1580510825157,"mc":[{"id":"1.168096552","rc":[{"batb":[[1,18,22.44]],"ltp":24.0,"tv":32.69,"id":24608298}]}]}
{"op":"mcm","clk":"991943069","pt":1580510827145,"mc":[{"id":"1.168096552","rc":[{"batl":[[1,15,1.08]],"ltp":11.0,"tv":182.84,"id":26640937}]}]}
{"op":"mcm","clk":"991948671","pt":1580510927345,"mc":[{"id":"1.168096552","rc":[{"batb":[[1,18.5,7.56],[2,18,22.44]],"ltp":24.0,"tv":32.69,"id":24608298}]}]}
{"op":"mcm","clk":"991948844","pt":1580510931463,"mc":[{"id":"1.168096552","rc":[{"batb":[[2,18,2.19]],"ltp":24.0,"tv":32.69,"id":24608298}]}]}
{"op":"mcm","clk":"991948849","pt":1580510931565,"mc":[{"id":"1.168096552","rc":[{"batb":[[1,19,19.19],[2,18.5,7.56]],"ltp":24.0,"tv":32.69,"id":24608298}]}]}
{"op":"mcm","clk":"991949058","pt":1580510937854,"mc":[{"id":"1.168096552","rc":[{"batb":[[1,19.5,2.02],[2,19,19.19]],"ltp":24.0,"tv":32.69,"id":24608298}]}]}
{"op":"mcm","clk":"991949612","pt":1580510949490,"mc":[{"id":"1.168096552","rc":[{"batb":[[1,19.5,20.72],[2,18.5,7.56]],"ltp":24.0,"tv":32.69,"id":24608298}]}]}
{"op":"mcm","clk":"991950044","pt":1580510959380,"mc":[{"id":"1.168096552","rc":[{"trd":[[3.15,340.25]],"batb":[[0,3.15,203.45]],"ltp":3.15,"tv":1097.73,"id":18286408}],"tv":5832.38}]}
{"op":"mcm","clk":"991950916","pt":1580510979532,"mc":[{"id":"1.168096552","rc":[{"trd":[[2.84,126.55]],"batb":[[0,2.84,14.8]],"ltp":2.84,"tv":3501.17,"id":52106}],"tv":5836.38}]}
{"op":"mcm","clk":"991955027","pt":1580511085337,"mc":[{"id":"1.168096552","rc":[{"batb":[[1,20,6.72],[2,19.5,20.72]],"ltp":24.0,"tv":32.69,"id":24608298}]}]}
{"op":"mcm","clk":"991955297","pt":1580511093443,"mc":[{"id":"1.168096552","rc":[{"batb":[[2,19.5,18.7]],"ltp":24.0,"tv":32.69,"id":24608298}]}]}
{"op":"mcm","clk":"991955397","pt":1580511095440,"mc":[{"id":"1.168096552","rc":[{"batb":[[2,17.5,5.89]],"ltp":24.0,"tv":32.69,"id":24608298}]}]}
{"op":"mcm","clk":"991955456","pt":1580511096465,"mc":[{"id":"1.168096552","rc":[{"batb":[[0,21,18.85]],"ltp":24.0,"tv":32.69,"id":24608298}]}]}
{"op":"mcm","clk":"991955797","pt":1580511103965,"mc":[{"id":"1.168096552","rc":[{"batb":[[2,13.5,2.07]],"ltp":24.0,"tv":32.69,"id":24608298}]}]}
{"op":"mcm","clk":"991956386","pt":1580511116362,"mc":[{"id":"1.168096552","rc":[{"batb":[[0,22,5.42],[1,21,18.12],[2,20,6.72]],"ltp":24.0,"tv":32.69,"id":24608298}]}]}
{"op":"mcm","clk":"991956828","pt":1580511125493,"mc":[{"id":"1.168096552","rc":[{"batb":[[0,23,16.58],[1,22,4.68],[2,20,7.48]],"ltp":24.0,"tv":32.69,"id":24608298}]}]}
{"op":"mcm","clk":"991972148","pt":1580511251945,"mc":[{"id":"1.168096552","rc":[{"batb":[[0,24,5.77],[1,23,15.85],[2,22,4.68]],"ltp":24.0,"tv":32.69,"id":24608298}]}]}
{"op":"mcm","clk":"991972681","pt":1580511265452,"mc":[{"id":"1.168096552","rc":[{"batb":[[1,22,4.68],[2,16,1.07]],"ltp":24.0,"tv":32.69,"id":24608298}]}]}
{"op":"mcm","clk":"991972717","pt":1580511266375,"mc":[{"id":"1.168096552","rc":[{"trd":[[3.15,343.61]],"batb":[[0,3.15,201.77]],"ltp":3.15,"tv":1101.09,"id":18286408},{"batb":[[0,25,14.62],[1,24,5.74],[2,22,4.68]],"ltp":24.0,"tv":32.69,"id":24608298}],"tv":5839.74}]}
{"op":"mcm","clk":"991973640","pt":1580511292459,"mc":[{"id":"1.168096552","rc":[{"trd":[[4.8,40.72]],"batb":[[0,4.7,11.98],[1,4.6,9.45],[2,4.5,27.25]],"batl":[[0,5.1,20.84],[1,5.3,9],[2,6,2.5]],"ltp":4.8,"tv":1020.66,"id":21580749}],"tv":5846.47}]}
{"op":"mcm","clk":"991976837","pt":1580511373484,"mc":[{"id":"1.168096552","rc":[{"trd":[[3.15,747.16]],"batb":[[0,3.05,5.65],[1,3,57.62],[2,2.88,36]],"ltp":3.15,"tv":1504.63,"id":18286408},{"trd":[[2.88,78.8]],"batl":[[0,2.96,6.88],[1,2.98,3.79],[2,3,68.61]],"ltp":2.88,"tv":3506.49,"id":52106}],"tv":6255.33}]}
{"op":"mcm","clk":"991976892","pt":1580511374309,"mc":[{"id":"1.168096552","rc":[{"batl":[[0,3.2,32.59]],"ltp":3.15,"tv":1504.63,"id":18286408},{"batl":[[0,2.96,17.33]],"ltp":2.88,"tv":3506.49,"id":52106}]}]}
{"op":"mcm","clk":"991977669","pt":1580511393481,"mc":[{"id":"1.168096552","rc":[{"batl":[[0,2.94,2.47],[1,2.96,17.33],[2,2.98,3.79]],"ltp":2.88,"tv":3506.49,"id":52106},{"batb":[[0,25,15.28],[1,24,5.04]],"ltp":24.0,"tv":32.69,"id":24608298}]}]}
{"op":"mcm","clk":"991978067","pt":1580511402515,"mc":[{"id":"1.168096552","rc":[{"batl":[[0,2.92,2.92],[1,2.94,2.47],[2,2.96,10.45]],"ltp":2.88,"tv":3506.49,"id":52106}]}]}
{"op":"mcm","clk":"991979047","pt":1580511422450,"mc":[{"id":"1.168096552","rc":[{"batb":[[0,26,5.7],[1,25,14.62]],"ltp":24.0,"tv":32.69,"id":24608298}]}]}
{"op":"mcm","clk":"991979102","pt":1580511423436,"mc":[{"id":"1.168096552","rc":[{"batb":[[1,22,4.72],[2,16,1.07]],"ltp":24.0,"tv":32.69,"id":24608298}]}]}
{"op":"mcm","clk":"991979110","pt":1580511423539,"mc":[{"id":"1.168096552","rc":[{"batb":[[0,27,13.5],[1,26,5.7],[2,22,4.72]],"ltp":24.0,"tv":32.69,"id":24608298}]}]}
{"op":"mcm","clk":"991979297","pt":1580511426432,"mc":[{"id":"1.168096552","rc":[{"batb":[[2,22,4.68]],"ltp":24.0,"tv":32.69,"id":24608298}]}]}
{"op":"mcm","clk":"991979351","pt":1580511427458,"mc":[{"id":"1.168096552","rc":[{"batb":[[1,26,5.74]],"ltp":24.0,"tv":32.69,"id":24608298}]}]}
{"op":"mcm","clk":"991979927","pt":1580511441460,"mc":[{"id":"1.168096552","rc":[{"batb":[[0,26,5.74],[1,22,4.68],[2,16,1.07]],"ltp":24.0,"tv":32.69,"id":24608298}]}]}
{"op":"mcm","clk":"991979981","pt":1580511443055,"mc":[{"id":"1.168096552","rc":[{"batb":[[1,16,1.07],[2,13.5,1.76]],"ltp":24.0,"tv":32.69,"id":24608298}]}]}
{"op":"mcm","clk":"991980449","pt":1580511455465,"mc":[{"id":"1.168096552","rc":[{"batb":[[0,21,1.46],[1,14,12.28],[2,13.5,6.32]],"ltp":24.0,"tv":32.69,"id":24608298}]}]}
{"op":"mcm","clk":"991980562","pt":1580511458280,"mc":[{"id":"1.168096552","rc":[{"batb":[[1,14.5,25.46],[2,14,11.97]],"ltp":24.0,"tv":32.69,"id":24608298}]}]}
{"op":"mcm","clk":"991980686","pt":1580511461161,"mc":[{"id":"1.168096552","rc":[{"batb":[[1,15,2.94],[2,14.5,25.15]],"ltp":24.0,"tv":32.69,"id":24608298}]}]}
{"op":"mcm","clk":"991981099","pt":1580511471513,"mc":[{"id":"1.168096552","rc":[{"trd":[[4.8,42.4]],"batb":[[0,4.8,2.52],[1,4.7,11.98],[2,4.6,9.45]],"batl":[[0,5,8.06],[1,5.1,20],[2,5.3,9]],"ltp":4.8,"tv":1022.34,"id":21580749}],"tv":6257.02}]}
{"op":"mcm","clk":"991981301","pt":1580511476508,"mc":[{"id":"1.168096552","rc":[{"batb":[[1,15,27.24],[2,14,7.36]],"ltp":24.0,"tv":32.69,"id":24608298}]}]}
{"op":"mcm","clk":"991981643","pt":1580511485106,"mc":[{"id":"1.168096552","rc":[{"trd":[[2.92,862.49],[2.94,293.75]],"batl":[[0,2.96,10.84],[1,2.98,3.79],[2,3,68.61]],"ltp":2.94,"tv":3516.49,"id":52106}],"tv":6267.02}]}
{"op":"mcm","clk":"991983667","pt":1580511536461,"mc":[{"id":"1.168096552","rc":[{"batb":[[0,3.05,10.65]],"ltp":3.15,"tv":1504.63,"id":18286408},{"batb":[[0,4.8,4.5],[1,4.7,10]],"ltp":4.8,"tv":1022.34,"id":21580749}]}]}
{"op":"mcm","clk":"991989903","pt":1580511665900,"mc":[{"id":"1.168096552","rc":[{"batl":[[1,3,68.61],[2,3.1,4]],"ltp":2.94,"tv":3516.49,"id":52106}]}]}
{"op":"mcm","clk":"991990043","pt":1580511668695,"mc":[{"id":"1.168096552","rc":[{"batb":[[0,2.86,3.79],[1,2.84,14.8],[2,2.82,45.47]],"ltp":2.94,"tv":3516.49,"id":52106}]}]}
{"op":"mcm","clk":"991991399","pt":1580511702243,"mc":[{"id":"1.168096552","rc":[{"batl":[[0,2.94,3.42],[1,2.96,10.45],[2,3,68.61]],"ltp":2.94,"tv":3516.49,"id":52106}]}]}
{"op":"mcm","clk":"991991879","pt":1580511713463,"mc":[{"id":"1.168096552","rc":[{"batl":[[0,3.15,3.03],[1,3.2,32.59],[2,3.25,320]],"ltp":3.15,"tv":1504.63,"id":18286408}]}]}
{"op":"mcm","clk":"991992454","pt":1580511727358,"mc":[{"id":"1.168096552","rc":[{"batb":[[0,2.86,5.47],[1,2.84,13.12]],"ltp":2.94,"tv":3516.49,"id":52106}]}]}
{"op":"mcm","clk":"991992532","pt":1580511729102,"mc":[{"id":"1.168096552","rc":[{"batl":[[1,2.96,12.45]],"ltp":2.94,"tv":3516.49,"id":52106}]}]}
{"op":"mcm","clk":"991996477","pt":1580511816501,"mc":[{"id":"1.168096552","rc":[{"trd":[[3.15,753.22]],"batb":[[0,3.15,1.62],[1,3.05,10.65],[2,3,57.62]],"batl":[[0,3.2,32.59],[1,3.25,320],[2,3.3,28]],"ltp":3.15,"tv":1510.69,"id":18286408}],"tv":6273.08}]}
{"op":"mcm","clk":"991998298","pt":1580511851337,"mc":[{"id":"1.168096552","rc":[{"batl":[[0,3.2,35.62]],"ltp":3.15,"tv":1510.69,"id":18286408}]}]}
{"op":"mcm","clk":"991998498","pt":1580511854020,"mc":[{"id":"1.168096552","rc":[{"batl":[[1,2.96,10.45]],"ltp":2.94,"tv":3516.49,"id":52106}]}]}
{"op":"mcm","clk":"992001704","pt":1580511928420,"mc":[{"id":"1.168096552","rc":[{"batl":[[0,3.2,45.62]],"ltp":3.15,"tv":1510.69,"id":18286408}]}]}
{"op":"mcm","clk":"992001936","pt":1580511934201,"mc":[{"id":"1.168096552","rc":[{"batl":[[0,3.2,35.62]],"ltp":3.15,"tv":1510.69,"id":18286408}]}]}
{"op":"mcm","clk":"992005202","pt":1580512008425,"mc":[{"id":"1.168096552","rc":[{"batb":[[0,10.5,9.48]],"ltp":11.0,"tv":182.84,"id":26640937}]}]}
{"op":"mcm","clk":"992018306","pt":1580512080386,"mc":[{"id":"1.168096552","rc":[{"batl":[[1,3.25,380]],"ltp":3.15,"tv":1510.69,"id":18286408}]}]}
{"op":"mcm","clk":"992021006","pt":1580512143350,"mc":[{"id":"1.168096552","rc":[{"batl":[[0,2.92,2],[1,2.94,3.42],[2,2.96,10.45]],"ltp":2.94,"tv":3516.49,"id":52106}]}]}
{"op":"mcm","clk":"992021951","pt":1580512171088,"mc":[{"id":"1.168096552","rc":[{"trd":[[2.86,184.74]],"batb":[[0,2.84,13.12],[1,2.82,45.47],[2,2.76,6]],"batl":[[0,2.86,14.53],[1,2.92,2],[2,2.94,3.42]],"ltp":2.86,"tv":3527.43,"id":52106}],"tv":6284.01}]}
{"op":"mcm","clk":"992022147","pt":1580512177817,"mc":[{"id":"1.168096552","rc":[{"batl":[[0,2.92,2],[1,2.94,3.42],[2,2.96,10.45]],"ltp":2.86,"tv":3527.43,"id":52106}]}]}
{"op":"mcm","clk":"992022363","pt":1580512183826,"mc":[{"id":"1.168096552","rc":[{"trd":[[2.84,146.54]],"batb":[[0,2.84,3.13]],"ltp":2.84,"tv":3547.43,"id":52106}],"tv":6304.01}]}
{"op":"mcm","clk":"992022754","pt":1580512195434,"mc":[{"id":"1.168096552","rc":[{"trd":[[3.05,106.38],[3.15,756.46]],"batb":[[0,3.1,3.36],[1,3.05,2.27]],"ltp":3.05,"tv":1530.69,"id":18286408}],"tv":6324.01}]}
{"op":"mcm","clk":"992022802","pt":1580512196819,"mc":[{"id":"1.168096552","rc":[{"batl":[[0,3.15,2],[1,3.2,35.62],[2,3.25,380]],"ltp":3.05,"tv":1530.69,"id":18286408}]}]}
{"op":"mcm","clk":"992022897","pt":1580512199454,"mc":[{"id":"1.168096552","rc":[{"batb":[[2,3,54.62]],"ltp":3.05,"tv":1530.69,"id":18286408}]}]}
{"op":"mcm","clk":"992023157","pt":1580512205551,"mc":[{"id":"1.168096552","rc":[{"trd":[[4.8,51.41]],"batb":[[0,4.7,10],[1,4.6,9.45],[2,4.5,27.25]],"batl":[[0,4.8,5.5],[1,5,8.06],[2,5.1,20]],"ltp":4.8,"tv":1031.35,"id":21580749}],"tv":6333.01}]}
{"op":"mcm","clk":"992023386","pt":1580512210145,"mc":[{"id":"1.168096552","rc":[{"batl":[[0,5,8.06],[1,5.1,20],[2,5.3,9]],"ltp":4.8,"tv":1031.35,"id":21580749}]}]}
{"op":"mcm","clk":"992023654","pt":1580512216371,"mc":[{"id":"1.168096552","rc":[{"batb":[[0,3.05,2.27],[1,3,54.62],[2,2.88,39]],"ltp":3.05,"tv":1530.69,"id":18286408}]}]}
{"op":"mcm","clk":"992023805","pt":1580512219468,"mc":[{"id":"1.168096552","rc":[{"trd":[[4.7,110.84]],"batb":[[0,4.7,5]],"ltp":4.7,"tv":1041.35,"id":21580749}],"tv":6343.01}]}
{"op":"mcm","clk":"992023941","pt":1580512223085,"mc":[{"id":"1.168096552","rc":[{"batb":[[0,3.05,12.79]],"batl":[[0,3.1,2],[1,3.15,2],[2,3.2,35.62]],"ltp":3.05,"tv":1530.69,"id":18286408}]}]}
{"op":"mcm","clk":"992024088","pt":1580512225865,"mc":[{"id":"1.168096552","rc":[{"trd":[[3.05,110.38]],"batb":[[0,3.05,10.79]],"ltp":3.05,"tv":1534.69,"id":18286408}],"tv":6347.01}]}
{"op":"mcm","clk":"992024344","pt":1580512232390,"mc":[{"id":"1.168096552","rc":[{"trd":[[3.05,114.37]],"batb":[[0,3.05,8.79]],"ltp":3.05,"tv":1538.69,"id":18286408}],"tv":6351.01}]}
{"op":"mcm","clk":"992024471","pt":1580512235071,"mc":[{"id":"1.168096552","rc":[{"batl":[[2,3.2,32.59]],"ltp":3.05,"tv":1538.69,"id":18286408}]}]}
{"op":"mcm","clk":"992024547","pt":1580512236473,"mc":[{"id":"1.168096552","rc":[{"trd":[[3.1,235.78],[3.15,758.42]],"batl":[[0,3.15,1.02],[1,3.2,32.59],[2,3.25,380]],"ltp":3.15,"tv":1544.65,"id":18286408}],"tv":6356.97}]}
{"op":"mcm","clk":"992024614","pt":1580512238378,"mc":[{"id":"1.168096552","rc":[{"batl":[[0,3.15,4.05]],"ltp":3.15,"tv":1544.65,"id":18286408}]}]}
{"op":"mcm","clk":"992024643","pt":1580512239304,"mc":[{"id":"1.168096552","rc":[{"batb":[[2,2.98,2]],"ltp":3.15,"tv":1544.65,"id":18286408}]}]}
{"op":"mcm","clk":"992024658","pt":1580512239770,"mc":[{"id":"1.168096552","rc":[{"batb":[[0,3.05,10.58]],"ltp":3.15,"tv":1544.65,"id":18286408},{"batb":[[0,4.7,11.77]],"ltp":4.7,"tv":1041.35,"id":21580749},{"batb":[[0,2.84,7.07]],"ltp":2.84,"tv":3547.43,"id":52106}]}]}
{"op":"mcm","clk":"992024751","pt":1580512241677,"mc":[{"id":"1.168096552","rc":[{"batb":[[1,3,57.62]],"ltp":3.15,"tv":1544.65,"id":18286408}]}]}
{"op":"mcm","clk":"992025061","pt":1580512248487,"mc":[{"id":"1.168096552","rc":[{"trd":[[2.84,160.7]],"batb":[[0,2.82,45.47],[1,2.76,6],[2,2.7,35]],"batl":[[0,2.84,2.92],[1,2.92,2],[2,2.94,3.42]],"ltp":2.84,"tv":3561.58,"id":52106}],"tv":6371.13}]}
{"op":"mcm","clk":"992025274","pt":1580512253271,"mc":[{"id":"1.168096552","rc":[{"trd":[[2.82,752.14]],"batb":[[0,2.82,7.61]],"ltp":2.82,"tv":3637.3,"id":52106}],"tv":6446.85}]}
{"op":"mcm","clk":"992025363","pt":1580512255117,"mc":[{"id":"1.168096552","rc":[{"trd":[[2.84,166.54]],"batb":[[0,2.84,50.11],[1,2.82,7.61],[2,2.76,6]],"batl":[[0,2.92,2],[1,2.94,3.42],[2,2.96,10.45]],"ltp":2.84,"tv":3643.14,"id":52106}],"tv":6452.69}]}
{"op":"mcm","clk":"992025444","pt":1580512256712,"mc":[{"id":"1.168096552","rc":[{"trd":[[3.05,118.37]],"batb":[[0,3.05,8.58]],"ltp":3.05,"tv":1548.65,"id":18286408}],"tv":6456.69}]}
{"op":"mcm","clk":"992025693","pt":1580512262227,"mc":[{"id":"1.168096552","rc":[{"batl":[[0,2.92,5.03]],"ltp":2.84,"tv":3643.14,"id":52106}]}]}
{"op":"mcm","clk":"992025725","pt":1580512262690,"mc":[{"id":"1.168096552","rc":[{"batb":[[1,3,54.62]],"ltp":3.05,"tv":1548.65,"id":18286408}]}]}
{"op":"mcm","clk":"992025798","pt":1580512264416,"mc":[{"id":"1.168096552","rc":[{"trd":[[4.7,114.84]],"batb":[[0,4.7,9.77]],"ltp":4.7,"tv":1045.35,"id":21580749},{"batl":[[1,2.96,10.84],[2,2.98,6]],"ltp":2.84,"tv":3643.14,"id":52106}],"tv":6460.69}]}
{"op":"mcm","clk":"992025975","pt":1580512269520,"mc":[{"id":"1.168096552","rc":[{"trd":[[3.05,122.37]],"batb":[[0,3.05,6.58]],"ltp":3.05,"tv":1552.65,"id":18286408}],"tv":6464.69}]}
{"op":"mcm","clk":"992026335","pt":1580512277525,"mc":[{"id":"1.168096552","rc":[{"trd":[[4.7,118.84]],"batb":[[0,4.7,7.77]],"ltp":4.7,"tv":1049.35,"id":21580749}],"tv":6468.69}]}
{"op":"mcm","clk":"992026534","pt":1580512282246,"mc":[{"id":"1.168096552","rc":[{"trd":[[3.05,126.37]],"batb":[[0,3.05,4.58]],"ltp":3.05,"tv":1556.65,"id":18286408}],"tv":6472.69}]}
{"op":"mcm","clk":"992027269","pt":1580512299259,"mc":[{"id":"1.168096552","rc":[{"batb":[[0,2.86,3.79],[1,2.84,50.11],[2,2.82,7.61]],"batl":[[1,2.98,6.39],[2,3,68.61]],"ltp":2.84,"tv":3643.14,"id":52106}]}]}
{"op":"mcm","clk":"992028806","pt":1580512334488,"mc":[{"id":"1.168096552","rc":[{"trd":[[3.05,135.53]],"batb":[[0,3,54.62],[1,2.98,2],[2,2.9,3.65]],"ltp":3.05,"tv":1565.81,"id":18286408},{"trd":[[2.92,872.55]],"batl":[[0,2.98,6.39],[1,3,68.61],[2,3.1,4]],"ltp":2.92,"tv":3653.21,"id":52106}],"tv":6491.91}]}
{"op":"mcm","clk":"992028980","pt":1580512338405,"mc":[{"id":"1.168096552","rc":[{"batb":[[2,2.88,57.3]],"batl":[[0,3.05,1.02],[1,3.15,3.03],[2,3.2,32.59]],"ltp":3.05,"tv":1565.81,"id":18286408},{"batb":[[0,2.88,2],[1,2.86,3.79],[2,2.84,50.11]],"ltp":2.92,"tv":3653.21,"id":52106}]}]}
{"op":"mcm","clk":"992029072","pt":1580512340203,"mc":[{"id":"1.168096552","rc":[{"trd":[[2.94,294.52],[2.98,90.6]],"batl":[[0,2.98,8.5]],"ltp":2.98,"tv":3659.26,"id":52106}],"tv":6497.97}]}
{"op":"mcm","clk":"992029192","pt":1580512343401,"mc":[{"id":"1.168096552","rc":[{"trd":[[2.98,96.66]],"batl":[[0,2.98,5.47]],"ltp":2.98,"tv":3665.32,"id":52106}],"tv":6504.03}]}
{"op":"mcm","clk":"992029438","pt":1580512348591,"mc":[{"id":"1.168096552","rc":[{"batb":[[0,2.88,7.67]],"ltp":2.98,"tv":3665.32,"id":52106}]}]}
{"op":"mcm","clk":"992029627","pt":1580512353023,"mc":[{"id":"1.168096552","rc":[{"trd":[[3.05,137.57]],"batb":[[0,3.05,9.91],[1,3,54.62],[2,2.98,2]],"batl":[[0,3.15,3.03],[1,3.2,32.59],[2,3.25,380]],"ltp":3.05,"tv":1567.85,"id":18286408},{"batb":[[0,4.7,12.81]],"ltp":4.7,"tv":1049.35,"id":21580749}],"tv":6506.06}]}
{"op":"mcm","clk":"992029713","pt":1580512355396,"mc":[{"id":"1.168096552","rc":[{"batb":[[1,2.84,50.11],[2,2.82,7.61]],"ltp":2.98,"tv":3665.32,"id":52106}]}]}
{"op":"mcm","clk":"992029775","pt":1580512357038,"mc":[{"id":"1.168096552","rc":[{"batb":[[2,2.98,4]],"ltp":3.05,"tv":1567.85,"id":18286408}]}]}
{"op":"mcm","clk":"992029809","pt":1580512357914,"mc":[{"id":"1.168096552","rc":[{"trd":[[2.98,107.6],[3,71.41]],"batl":[[0,3,55.15],[1,3.1,4],[2,3.15,11.2]],"ltp":3.0,"tv":3703.18,"id":52106}],"tv":6543.92}]}
{"op":"mcm","clk":"992029949","pt":1580512362494,"mc":[{"id":"1.168096552","rc":[{"trd":[[3,109.27]],"batb":[[1,2.86,33.55],[2,2.84,50.11]],"batl":[[0,3,36.22]],"ltp":3.0,"tv":3741.04,"id":52106}],"tv":6581.78}]}
{"op":"mcm","clk":"992029985","pt":1580512363119,"mc":[{"id":"1.168096552","rc":[{"trd":[[3,181.71],[3.1,3.28]],"batl":[[0,3.1,2.36],[1,3.15,20.42],[2,3.85,10]],"ltp":3.1,"tv":3816.76,"id":52106}],"tv":6657.51}]}
{"op":"mcm","clk":"992030236","pt":1580512369304,"mc":[{"id":"1.168096552","rc":[{"batb":[[0,2.88,95.6]],"ltp":3.1,"tv":3816.76,"id":52106}]}]}
{"op":"mcm","clk":"992030336","pt":1580512372031,"mc":[{"id":"1.168096552","rc":[{"batb":[[1,2.84,50.11],[2,2.82,7.61]],"ltp":3.1,"tv":3816.76,"id":52106}]}]}
{"op":"mcm","clk":"992030379","pt":1580512373011,"mc":[{"id":"1.168096552","rc":[{"batb":[[0,2.9,33.08],[1,2.88,95.6],[2,2.84,50.11]],"ltp":3.1,"tv":3816.76,"id":52106}]}]}
{"op":"mcm","clk":"992030467","pt":1580512375427,"mc":[{"id":"1.168096552","rc":[{"batb":[[0,2.92,6],[1,2.9,33.08],[2,2.88,89.93]],"ltp":3.1,"tv":3816.76,"id":52106}]}]}
{"op":"mcm","clk":"992030530","pt":1580512377437,"mc":[{"id":"1.168096552","rc":[{"batb":[[0,2.92,16.08]],"ltp":3.1,"tv":3816.76,"id":52106}]}]}
{"op":"mcm","clk":"992030951","pt":1580512386446,"mc":[{"id":"1.168096552","rc":[{"batb":[[0,2.94,86.14],[1,2.92,16.08],[2,2.9,33.08]],"ltp":3.1,"tv":3816.76,"id":52106}]}]}
{"op":"mcm","clk":"992030969","pt":1580512386845,"mc":[{"id":"1.168096552","rc":[{"batl":[[1,3.15,11.2]],"ltp":3.1,"tv":3816.76,"id":52106}]}]}
{"op":"mcm","clk":"992031306","pt":1580512394341,"mc":[{"id":"1.168096552","rc":[{"batl":[[0,3.05,24.15],[1,3.1,2.36],[2,3.15,11.2]],"ltp":3.1,"tv":3816.76,"id":52106}]}]}
{"op":"mcm","clk":"992031366","pt":1580512395929,"mc":[{"id":"1.168096552","rc":[{"batb":[[0,2.96,6],[1,2.94,86.14],[2,2.92,10.08]],"ltp":3.1,"tv":3816.76,"id":52106}]}]}
{"op":"mcm","clk":"992031756","pt":1580512404464,"mc":[{"id":"1.168096552","rc":[{"batb":[[1,2.92,10.08],[2,2.9,33.08]],"batl":[[0,3,5.24],[1,3.05,24.15],[2,3.1,2.36]],"ltp":3.1,"tv":3816.76,"id":52106}]}]}
{"op":"mcm","clk":"992031900","pt":1580512407473,"mc":[{"id":"1.168096552","rc":[{"batb":[[0,2.94,6]],"ltp":3.1,"tv":3816.76,"id":52106}]}]}
{"op":"mcm","clk":"992032962","pt":1580512435758,"mc":[{"id":"1.168096552","rc":[{"batl":[[1,3.1,2.36],[2,3.15,11.2]],"ltp":3.1,"tv":3816.76,"id":52106}]}]}
{"op":"mcm","clk":"992033159","pt":1580512440476,"mc":[{"id":"1.168096552","rc":[{"batb":[[2,2.88,2]],"ltp":3.1,"tv":3816.76,"id":52106}]}]}
{"op":"mcm","clk":"992033200","pt":1580512441404,"mc":[{"id":"1.168096552","rc":[{"batb":[[2,2.88,35.32]],"ltp":3.1,"tv":3816.76,"id":52106}]}]}
{"op":"mcm","clk":"992033340","pt":1580512445976,"mc":[{"id":"1.168096552","rc":[{"batb":[[1,2.88,35.32],[2,2.86,6]],"ltp":3.1,"tv":3816.76,"id":52106}]}]}
{"op":"mcm","clk":"992033605","pt":1580512452903,"mc":[{"id":"1.168096552","rc":[{"batb":[[0,2.9,6]],"ltp":3.1,"tv":3816.76,"id":52106}]}]}
{"op":"mcm","clk":"992034176","pt":1580512469322,"mc":[{"id":"1.168096552","rc":[{"batb":[[1,2.88,45.65]],"batl":[[1,3.05,9.75],[2,3.1,2.36]],"ltp":3.1,"tv":3816.76,"id":52106}]}]}
{"op":"mcm","clk":"992035235","pt":1580512494958,"mc":[{"id":"1.168096552","rc":[{"batl":[[0,3.1,18.51],[1,3.15,3.03],[2,3.2,32.59]],"ltp":3.05,"tv":1567.85,"id":18286408},{"batl":[[0,4.9,12.01],[1,5,8.06],[2,5.1,20]],"ltp":4.7,"tv":1049.35,"id":21580749},{"batl":[[0,2.96,19.47],[1,3,5.24],[2,3.05,9.75]],"ltp":3.1,"tv":3816.76,"id":52106}]}]}
{"op":"mcm","clk":"992035530","pt":1580512502463,"mc":[{"id":"1.168096552","rc":[{"batb":[[1,2.88,35.32]],"batl":[[2,3.1,2.36]],"ltp":3.1,"tv":3816.76,"id":52106}]}]}
{"op":"mcm","clk":"992035688","pt":1580512506238,"mc":[{"id":"1.168096552","rc":[{"batl":[[0,3.15,3.03],[1,3.2,32.59],[2,3.25,380]],"ltp":3.05,"tv":1567.85,"id":18286408},{"batl":[[0,5,8.06],[1,5.1,20],[2,5.3,9]],"ltp":4.7,"tv":1049.35,"id":21580749},{"batl":[[0,3,5.24],[1,3.1,2.36],[2,3.15,11.2]],"ltp":3.1,"tv":3816.76,"id":52106}]}]}
{"op":"mcm","clk":"992036397","pt":1580512521584,"mc":[{"id":"1.168096552","rc":[{"batb":[[0,3.05,11.83]],"ltp":3.05,"tv":1567.85,"id":18286408},{"batb":[[0,2.9,7.68]],"ltp":3.1,"tv":3816.76,"id":52106}]}]}
{"op":"mcm","clk":"992036981","pt":1580512534172,"mc":[{"id":"1.168096552","rc":[{"batb":[[1,2.88,46.07]],"batl":[[1,3.05,10.16],[2,3.1,2.36]],"ltp":3.1,"tv":3816.76,"id":52106}]}]}
{"op":"mcm","clk":"992037578","pt":1580512548425,"mc":[{"id":"1.168096552","rc":[{"batl":[[0,3,25.24]],"ltp":3.1,"tv":3816.76,"id":52106}]}]}
{"op":"mcm","clk":"992037919","pt":1580512556097,"mc":[{"id":"1.168096552","rc":[{"batb":[[0,2.9,17.76]],"ltp":3.1,"tv":3816.76,"id":52106}]}]}
{"op":"mcm","clk":"992038725","pt":1580512576950,"mc":[{"id":"1.168096552","rc":[{"batl":[[0,3.1,10.26],[1,3.15,103.03],[2,3.2,32.59]],"ltp":3.05,"tv":1567.85,"id":18286408}]}]}
{"op":"mcm","clk":"992038777","pt":1580512578441,"mc":[{"id":"1.168096552","rc":[{"batl":[[2,3.2,22]],"ltp":3.05,"tv":1567.85,"id":18286408}]}]}
{"op":"mcm","clk":"992040126","pt":1580512609776,"mc":[{"id":"1.168096552","rc":[{"batl":[[0,3,30.24]],"ltp":3.1,"tv":3816.76,"id":52106}]}]}
{"op":"mcm","clk":"992040532","pt":1580512619201,"mc":[{"id":"1.168096552","rc":[{"batl":[[0,5,18.06]],"ltp":4.7,"tv":1049.35,"id":21580749}]}]}
{"op":"mcm","clk":"992042200","pt":1580512659161,"mc":[{"id":"1.168096552","rc":[{"batb":[[1,15.5,6.76],[2,15,26.93]],"ltp":24.0,"tv":32.69,"id":24608298}]}]}
{"op":"mcm","clk":"992042422","pt":1580512664362,"mc":[{"id":"1.168096552","rc":[{"batb":[[1,16,2.77],[2,15.5,6.45]],"ltp":24.0,"tv":32.69,"id":24608298}]}]}
{"op":"mcm","clk":"992042524","pt":1580512666483,"mc":[{"id":"1.168096552","rc":[{"batb":[[1,16,25.56]],"ltp":24.0,"tv":32.69,"id":24608298}]}]}
{"op":"mcm","clk":"992042915","pt":1580512675381,"mc":[{"id":"1.168096552","rc":[{"batb":[[1,16.5,8.4],[2,16,25.56]],"ltp":24.0,"tv":32.69,"id":24608298}]}]}
{"op":"mcm","clk":"992043325","pt":1580512684479,"mc":[{"id":"1.168096552","rc":[{"batb":[[1,17,23.76],[2,16.5,8.4]],"ltp":24.0,"tv":32.69,"id":24608298}]}]}
{"op":"mcm","clk":"992044199","pt":1580512704132,"mc":[{"id":"1.168096552","rc":[{"batb":[[1,17.5,5.89],[2,17,23.76]],"ltp":24.0,"tv":32.69,"id":24608298}]}]}
{"op":"mcm","clk":"992044247","pt":1580512705422,"mc":[{"id":"1.168096552","rc":[{"batb":[[1,18,2.19],[2,17.5,5.89]],"ltp":24.0,"tv":32.69,"id":24608298}]}]}
{"op":"mcm","clk":"992044410","pt":1580512709199,"mc":[{"id":"1.168096552","rc":[{"batb":[[1,18.5,1.76],[2,18,2.19]],"ltp":24.0,"tv":32.69,"id":24608298}]}]}
{"op":"mcm","clk":"992044791","pt":1580512720319,"mc":[{"id":"1.168096552","rc":[{"batb":[[1,18.5,21.47]],"ltp":24.0,"tv":32.69,"id":24608298}]}]}
{"op":"mcm","clk":"992044950","pt":1580512725217,"mc":[{"id":"1.168096552","rc":[{"batb":[[2,17.5,5.89]],"ltp":24.0,"tv":32.69,"id":24608298}]}]}
{"op":"mcm","clk":"992045890","pt":1580512751258,"mc":[{"id":"1.168096552","rc":[{"batb":[[0,2.92,32.86],[1,2.9,17.76],[2,2.88,46.07]],"ltp":3.1,"tv":3816.76,"id":52106}]}]}
{"op":"mcm","clk":"992045908","pt":1580512751871,"mc":[{"id":"1.168096552","rc":[{"batb":[[0,2.94,6],[1,2.92,32.86],[2,2.9,11.76]],"ltp":3.1,"tv":3816.76,"id":52106}]}]}
{"op":"mcm","clk":"992046131","pt":1580512758388,"mc":[{"id":"1.168096552","rc":[{"batl":[[1,3.1,2.36],[2,3.15,11.2]],"ltp":3.1,"tv":3816.76,"id":52106}]}]}
{"op":"mcm","clk":"992046198","pt":1580512760467,"mc":[{"id":"1.168096552","rc":[{"batb":[[0,2.94,16.08]],"ltp":3.1,"tv":3816.76,"id":52106}]}]}
{"op":"mcm","clk":"992046211","pt":1580512760982,"mc":[{"id":"1.168096552","rc":[{"batb":[[2,2.9,1.68]],"ltp":3.1,"tv":3816.76,"id":52106}]}]}
{"op":"mcm","clk":"992046451","pt":1580512768380,"mc":[{"id":"1.168096552","rc":[{"trd":[[2.94,322.32]],"batb":[[0,2.94,2.18]],"ltp":2.94,"tv":3844.56,"id":52106}],"tv":6685.3}]}
{"op":"mcm","clk":"992046754","pt":1580512774388,"mc":[{"id":"1.168096552","rc":[{"trd":[[3,245.68]],"batl":[[0,3,20.97]],"ltp":3.0,"tv":3908.54,"id":52106}],"tv":6749.28}]}
{"op":"mcm","clk":"992046845","pt":1580512776810,"mc":[{"id":"1.168096552","rc":[{"batb":[[1,2.9,1.68],[2,2.88,2]],"ltp":3.0,"tv":3908.54,"id":52106}]}]}
{"op":"mcm","clk":"992047438","pt":1580512790294,"mc":[{"id":"1.168096552","rc":[{"batb":[[0,2.9,1.68],[1,2.88,2],[2,2.86,6]],"ltp":3.0,"tv":3908.54,"id":52106}]}]}
{"op":"mcm","clk":"992048374","pt":1580512808946,"mc":[{"id":"1.168096552","rc":[{"trd":[[11,114.53]],"batl":[[0,11,19.73]],"ltp":11.0,"tv":200.53,"id":26640937}],"tv":6766.97}]}
{"op":"mcm","clk":"992048927","pt":1580512822343,"mc":[{"id":"1.168096552","rc":[{"batb":[[1,2.88,4.06]],"batl":[[1,3.05,1.94],[2,3.1,2.36]],"ltp":3.0,"tv":3908.54,"id":52106}]}]}
{"op":"mcm","clk":"992049864","pt":1580512847254,"mc":[{"id":"1.168096552","rc":[{"batb":[[1,19,7.56],[2,18.5,21.47]],"ltp":24.0,"tv":32.69,"id":24608298}]}]}
{"op":"mcm","clk":"992049910","pt":1580512848455,"mc":[{"id":"1.168096552","rc":[{"batb":[[1,2.88,7.06]],"ltp":3.0,"tv":3908.54,"id":52106},{"batb":[[2,18.5,1.76]],"ltp":24.0,"tv":32.69,"id":24608298}]}]}
{"op":"mcm","clk":"992049979","pt":1580512849488,"mc":[{"id":"1.168096552","rc":[{"batb":[[1,19.5,18.7],[2,19,7.56]],"ltp":24.0,"tv":32.69,"id":24608298}]}]}
{"op":"mcm","clk":"992050011","pt":1580512850569,"mc":[{"id":"1.168096552","rc":[{"batb":[[1,20,1.76],[2,19.5,18.7]],"ltp":24.0,"tv":32.69,"id":24608298}]}]}
{"op":"mcm","clk":"992050242","pt":1580512857365,"mc":[{"id":"1.168096552","rc":[{"batl":[[0,2.98,3.03],[1,3,20.97],[2,3.05,1.94]],"ltp":3.0,"tv":3908.54,"id":52106}]}]}
{"op":"mcm","clk":"992050546","pt":1580512865492,"mc":[{"id":"1.168096552","rc":[{"batb":[[1,20,19.99],[2,19,7.56]],"ltp":24.0,"tv":32.69,"id":24608298}]}]}
{"op":"mcm","clk":"992051302","pt":1580512886223,"mc":[{"id":"1.168096552","rc":[{"batb":[[0,21,6.36]],"ltp":24.0,"tv":32.69,"id":24608298}]}]}
{"op":"mcm","clk":"992051862","pt":1580512900420,"mc":[{"id":"1.168096552","rc":[{"batb":[[1,20,1.76]],"ltp":24.0,"tv":32.69,"id":24608298}]}]}
{"op":"mcm","clk":"992051868","pt":1580512900528,"mc":[{"id":"1.168096552","rc":[{"batb":[[0,22,17.27],[1,21,5.67],[2,20,1.76]],"ltp":24.0,"tv":32.69,"id":24608298}]}]}
{"op":"mcm","clk":"992064609","pt":1580512978298,"mc":[{"id":"1.168096552","rc":[{"trd":[[11,122.53]],"batl":[[0,11,15.73]],"ltp":11.0,"tv":208.53,"id":26640937},{"trd":[[2.88,85.43],[2.9,94.97]],"batb":[[0,2.88,14.54],[1,2.86,6],[2,2.84,50.11]],"ltp":2.88,"tv":3918.54,"id":52106}],"tv":6784.97}]}
{"op":"mcm","clk":"992065043","pt":1580512988413,"mc":[{"id":"1.168096552","rc":[{"batb":[[0,23,2.46],[1,22,16.57],[2,21,5.67]],"ltp":24.0,"tv":32.69,"id":24608298}]}]}
{"op":"mcm","clk":"992065361","pt":1580512996351,"mc":[{"id":"1.168096552","rc":[{"batb":[[0,23,8.34]],"ltp":24.0,"tv":32.69,"id":24608298}]}]}
{"op":"mcm","clk":"992065600","pt":1580513001418,"mc":[{"id":"1.168096552","rc":[{"batb":[[0,24,15.89],[1,23,7.65]],"ltp":24.0,"tv":32.69,"id":24608298}]}]}
{"op":"mcm","clk":"992066433","pt":1580513019460,"mc":[{"id":"1.168096552","rc":[{"trd":[[2.98,111.6]],"batl":[[0,2.98,1.03]],"ltp":2.98,"tv":3922.53,"id":52106}],"tv":6788.97}]}
{"op":"mcm","clk":"992066440","pt":1580513019560,"mc":[{"id":"1.168096552","rc":[{"trd":[[2.98,113.66]],"batl":[[0,3,20.97],[1,3.05,1.94],[2,3.1,2.36]],"ltp":2.98,"tv":3924.59,"id":52106}],"tv":6791.03}]}
{"op":"mcm","clk":"992066937","pt":1580513032389,"mc":[{"id":"1.168096552","rc":[{"batb":[[0,2.88,33.47],[1,2.86,24.93]],"ltp":2.98,"tv":3924.59,"id":52106}]}]}
{"op":"mcm","clk":"992067173","pt":1580513037769,"mc":[{"id":"1.168096552","rc":[{"trd":[[2.88,95.43]],"batb":[[0,2.88,28.47]],"ltp":2.88,"tv":3934.59,"id":52106}],"tv":6801.03}]}
{"op":"mcm","clk":"992067506","pt":1580513046073,"mc":[{"id":"1.168096552","rc":[{"trd":[[3.05,147.57]],"batb":[[0,3.05,6.83]],"ltp":3.05,"tv":1577.85,"id":18286408}],"tv":6811.02}]}
{"op":"mcm","clk":"992067826","pt":1580513053490,"mc":[{"id":"1.168096552","rc":[{"batb":[[0,2.9,5.04],[1,2.88,28.47],[2,2.86,24.93]],"ltp":2.88,"tv":3934.59,"id":52106}]}]}
{"op":"mcm","clk":"992068073","pt":1580513059499,"mc":[{"id":"1.168096552","rc":[{"batl":[[0,2.98,2.9],[1,3,20.97],[2,3.05,1.94]],"ltp":2.88,"tv":3934.59,"id":52106}]}]}
{"op":"mcm","clk":"992070791","pt":1580513134373,"mc":[{"id":"1.168096552","rc":[{"batb":[[0,25,5.74],[1,24,15.19],[2,23,7.65]],"ltp":24.0,"tv":32.69,"id":24608298}]}]}
{"op":"mcm","clk":"992070842","pt":1580513135403,"mc":[{"id":"1.168096552","rc":[{"batb":[[2,23,1.76]],"ltp":24.0,"tv":32.69,"id":24608298}]}]}
{"op":"mcm","clk":"992071042","pt":1580513141485,"mc":[{"id":"1.168096552","rc":[{"batb":[[0,26,14.72],[1,25,5.04]],"ltp":24.0,"tv":32.69,"id":24608298}]}]}
{"op":"mcm","clk":"992071401","pt":1580513152202,"mc":[{"id":"1.168096552","rc":[{"batl":[[0,2.98,5.93]],"ltp":2.88,"tv":3934.59,"id":52106}]}]}
{"op":"mcm","clk":"992071618","pt":1580513158337,"mc":[{"id":"1.168096552","rc":[{"batb":[[0,25,5.74],[1,23,1.76],[2,21,5.67]],"ltp":24.0,"tv":32.69,"id":24608298}]}]}
{"op":"mcm","clk":"992071762","pt":1580513162306,"mc":[{"id":"1.168096552","rc":[{"batb":[[0,23,2.46],[1,21,5.67],[2,13,2.31]],"ltp":24.0,"tv":32.69,"id":24608298}]}]}
{"op":"mcm","clk":"992073918","pt":1580513220870,"mc":[{"id":"1.168096552","rc":[{"batb":[[0,22,2.46]],"ltp":24.0,"tv":32.69,"id":24608298}]}]}
{"op":"mcm","clk":"992076979","pt":1580513294455,"mc":[{"id":"1.168096552","rc":[{"trd":[[3.05,161.23]],"batb":[[0,3,54.62],[1,2.98,4],[2,2.88,39]],"ltp":3.05,"tv":1591.51,"id":18286408},{"trd":[[2.98,125.52]],"batl":[[0,3,20.97],[1,3.05,1.94],[2,3.1,2.36]],"ltp":2.98,"tv":3946.45,"id":52106}],"tv":6836.55}]}
{"op":"mcm","clk":"992077257","pt":1580513301053,"mc":[{"id":"1.168096552","rc":[{"trd":[[3,283.54]],"batl":[[0,3,2.04]],"ltp":3.0,"tv":3984.32,"id":52106}],"tv":6874.41}]}
{"op":"mcm","clk":"992077509","pt":1580513306466,"mc":[{"id":"1.168096552","rc":[{"batb":[[0,2.9,23.97],[2,2.86,6]],"ltp":3.0,"tv":3984.32,"id":52106}]}]}
{"op":"mcm","clk":"992077580","pt":1580513308674,"mc":[{"id":"1.168096552","rc":[{"trd":[[10.5,40.56]],"batb":[[0,10.5,7.48]],"ltp":10.5,"tv":212.53,"id":26640937}],"tv":6878.41}]}
{"op":"mcm","clk":"992077883","pt":1580513315891,"mc":[{"id":"1.168096552","rc":[{"batb":[[0,3,56.3]],"ltp":3.05,"tv":1591.51,"id":18286408}]}]}
{"op":"mcm","clk":"992078816","pt":1580513338314,"mc":[{"id":"1.168096552","rc":[{"batb":[[0,2.92,3],[1,2.9,23.97],[2,2.88,28.47]],"ltp":3.0,"tv":3984.32,"id":52106}]}]}
{"op":"mcm","clk":"992079195","pt":1580513347748,"mc":[{"id":"1.168096552","rc":[{"batb":[[2,2.88,18.93]],"batl":[[1,3.05,169.98]],"ltp":3.0,"tv":3984.32,"id":52106}]}]}
{"op":"mcm","clk":"992079254","pt":1580513349036,"mc":[{"id":"1.168096552","rc":[{"batl":[[0,3,12.13]],"ltp":3.0,"tv":3984.32,"id":52106}]}]}
{"op":"mcm","clk":"992079443","pt":1580513353315,"mc":[{"id":"1.168096552","rc":[{"batb":[[1,2.9,5.04]],"ltp":3.0,"tv":3984.32,"id":52106}]}]}
{"op":"mcm","clk":"992079812","pt":1580513360427,"mc":[{"id":"1.168096552","rc":[{"batl":[[0,2.98,1.99],[1,3,12.13],[2,3.05,168.04]],"ltp":3.0,"tv":3984.32,"id":52106}]}]}
{"op":"mcm","clk":"992080087","pt":1580513366459,"mc":[{"id":"1.168096552","rc":[{"batl":[[0,2.98,5.99]],"ltp":3.0,"tv":3984.32,"id":52106}]}]}
{"op":"mcm","clk":"992080127","pt":1580513367387,"mc":[{"id":"1.168096552","rc":[{"batb":[[0,2.9,5.04],[1,2.88,18.93],[2,2.86,6]],"ltp":3.0,"tv":3984.32,"id":52106}]}]}
{"op":"mcm","clk":"992080956","pt":1580513388484,"mc":[{"id":"1.168096552","rc":[{"trd":[[3.1,256.3]],"batl":[[0,3.15,103.03],[1,3.2,22],[2,3.25,380]],"ltp":3.1,"tv":1612.03,"id":18286408}],"tv":6898.93}]}
{"op":"mcm","clk":"992083160","pt":1580513437225,"mc":[{"id":"1.168096552","rc":[{"batb":[[0,3.05,4.2],[1,3,56.3],[2,2.98,4]],"ltp":3.1,"tv":1612.03,"id":18286408}]}]}
{"op":"mcm","clk":"992083453","pt":1580513443934,"mc":[{"id":"1.168096552","rc":[{"batl":[[1,3,20.57]],"ltp":3.0,"tv":3984.32,"id":52106}]}]}
{"op":"mcm","clk":"992084123","pt":1580513460661,"mc":[{"id":"1.168096552","rc":[{"trd":[[22,2.62],[26,1.39]],"batb":[[0,21,6.12],[1,13,2.31],[2,9.2,4.59]],"ltp":22.0,"tv":36.7,"id":24608298}],"tv":6902.94}]}
{"op":"mcm","clk":"992084322","pt":1580513465500,"mc":[{"id":"1.168096552","rc":[{"batb":[[0,21,6.17]],"batl":[[0,55,3.33]],"ltp":22.0,"tv":36.7,"id":24608298}]}]}
{"op":"mcm","clk":"992085341","pt":1580513491497,"mc":[{"id":"1.168096552","rc":[{"batl":[[0,55,3.13]],"ltp":22.0,"tv":36.7,"id":24608298}]}]}
{"op":"mcm","clk":"992085345","pt":1580513491601,"mc":[{"id":"1.168096552","rc":[{"batl":[[0,55,3.33]],"ltp":22.0,"tv":36.7,"id":24608298}]}]}
{"op":"mcm","clk":"992085455","pt":1580513494478,"mc":[{"id":"1.168096552","rc":[{"batl":[[0,55,3.3]],"ltp":22.0,"tv":36.7,"id":24608298}]}]}
{"op":"mcm","clk":"992085491","pt":1580513495450,"mc":[{"id":"1.168096552","rc":[{"batl":[[0,55,3.33]],"ltp":22.0,"tv":36.7,"id":24608298}]}]}
{"op":"mcm","clk":"992085771","pt":1580513502684,"mc":[{"id":"1.168096552","rc":[{"batb":[[0,3.05,5.88],[1,3,54.62]],"ltp":3.1,"tv":1612.03,"id":18286408}]}]}
{"op":"mcm","clk":"992085955","pt":1580513508296,"mc":[{"id":"1.168096552","rc":[{"trd":[[3.05,164.59]],"batb":[[0,3,54.62],[1,2.98,4],[2,2.88,39]],"ltp":3.05,"tv":1615.39,"id":18286408},{"batb":[[0,10.5,6.12]],"ltp":10.5,"tv":212.53,"id":26640937},{"batb":[[0,4.7,7.77]],"ltp":4.7,"tv":1049.35,"id":21580749},{"batb":[[0,2.88,18.93],[1,2.86,6],[2,2.84,50.11]],"ltp":3.0,"tv":3984.32,"id":52106}],"tv":6906.3}]}
{"op":"mcm","clk":"992086412","pt":1580513519933,"mc":[{"id":"1.168096552","rc":[{"trd":[[4.7,134.38]],"batb":[[0,4.6,9.45],[1,4.5,29.57],[2,4.3,4.21]],"batl":[[0,4.7,12.23],[1,5,18.06],[2,5.1,20]],"ltp":4.7,"tv":1064.89,"id":21580749}],"tv":6921.84}]}
{"op":"mcm","clk":"992086685","pt":1580513526518,"mc":[{"id":"1.168096552","rc":[{"trd":[[11,153.97]],"batb":[[0,11,23.43],[1,10.5,6.12],[2,10,5.08]],"batl":[[0,15,1.08],[1,21,1.5],[2,32,9]],"ltp":11.0,"tv":243.97,"id":26640937},{"batb":[[1,4.5,27.25]],"ltp":4.7,"tv":1064.89,"id":21580749},{"batb":[[0,2.9,87.33],[1,2.88,18.93],[2,2.86,6]],"ltp":3.0,"tv":3984.32,"id":52106}],"tv":6953.28}]}
{"op":"mcm","clk":"992086711","pt":1580513527340,"mc":[{"id":"1.168096552","rc":[{"batl":[[1,5,38.06]],"ltp":4.7,"tv":1064.89,"id":21580749}]}]}
{"op":"mcm","clk":"992087018","pt":1580513535422,"mc":[{"id":"1.168096552","rc":[{"trd":[[4.7,158.85]],"batl":[[0,5,38.06],[1,5.1,20],[2,5.3,9]],"ltp":4.7,"tv":1089.35,"id":21580749}],"tv":6977.74}]}
{"op":"mcm","clk":"992087162","pt":1580513538548,"mc":[{"id":"1.168096552","rc":[{"batl":[[0,4.9,4],[1,5,38.06],[2,5.1,20]],"ltp":4.7,"tv":1089.35,"id":21580749}]}]}
{"op":"mcm","clk":"992087413","pt":1580513544424,"mc":[{"id":"1.168096552","rc":[{"batb":[[0,10.5,6.12],[1,10,5.08],[2,7,25.82]],"ltp":11.0,"tv":243.97,"id":26640937},{"batb":[[0,2.88,18.93],[1,2.86,6],[2,2.84,50.11]],"ltp":3.0,"tv":3984.32,"id":52106}]}]}
{"op":"mcm","clk":"992087563","pt":1580513547864,"mc":[{"id":"1.168096552","rc":[{"batb":[[0,11,2.8],[1,10.5,6.12],[2,10,5.08]],"batl":[[1,20,1.68],[2,21,1.5]],"ltp":11.0,"tv":243.97,"id":26640937}]}]}
{"op":"mcm","clk":"992089845","pt":1580513594083,"mc":[{"id":"1.168096552","rc":[{"batb":[[0,3,57.13]],"ltp":3.05,"tv":1615.39,"id":18286408},{"trd":[[11.5,0.17]],"batb":[[0,11.5,1.9],[1,11,2.8],[2,10.5,4.14]],"batl":[[0,15,1]],"ltp":11.5,"tv":244.14,"id":26640937},{"batb":[[0,4.6,13.81]],"ltp":4.7,"tv":1089.35,"id":21580749},{"batb":[[0,2.88,23.7]],"ltp":3.0,"tv":3984.32,"id":52106}],"tv":6977.91}]}
{"op":"mcm","clk":"992090574","pt":1580513611411,"mc":[{"id":"1.168096552","rc":[{"batl":[[1,21,1.5],[2,30,1.68]],"ltp":11.5,"tv":244.14,"id":26640937}]}]}
{"op":"mcm","clk":"992090590","pt":1580513611909,"mc":[{"id":"1.168096552","rc":[{"batl":[[2,30,1.85]],"ltp":11.5,"tv":244.14,"id":26640937}]}]}
{"op":"mcm","clk":"992091938","pt":1580513643468,"mc":[{"id":"1.168096552","rc":[{"batl":[[1,20,1.68],[2,21,1.5]],"ltp":11.5,"tv":244.14,"id":26640937}]}]}
{"op":"mcm","clk":"992093323","pt":1580513675513,"mc":[{"id":"1.168096552","rc":[{"batl":[[1,21,1.5],[2,30,1.85]],"ltp":11.5,"tv":244.14,"id":26640937}]}]}
{"op":"mcm","clk":"992094621","pt":1580513706341,"mc":[{"id":"1.168096552","rc":[{"batl":[[1,20,1.68],[2,21,1.5]],"ltp":11.5,"tv":244.14,"id":26640937}]}]}
{"op":"mcm","clk":"992095957","pt":1580513734997,"mc":[{"id":"1.168096552","rc":[{"batb":[[1,11,4.36]],"ltp":11.5,"tv":244.14,"id":26640937}]}]}
{"op":"mcm","clk":"992096121","pt":1580513738510,"mc":[{"id":"1.168096552","rc":[{"batl":[[1,21,1.5],[2,30,1.85]],"ltp":11.5,"tv":244.14,"id":26640937}]}]}
{"op":"mcm","clk":"992097104","pt":1580513758507,"mc":[{"id":"1.168096552","rc":[{"trd":[[2.88,105.43]],"batb":[[0,2.88,18.71]],"ltp":2.88,"tv":3994.31,"id":52106}],"tv":6987.91}]}
{"op":"mcm","clk":"992097361","pt":1580513764542,"mc":[{"id":"1.168096552","rc":[{"batb":[[0,22,1.29],[1,21,5.67],[2,13,2.31]],"ltp":22.0,"tv":36.7,"id":24608298}]}]}
{"op":"mcm","clk":"992097592","pt":1580513769931,"mc":[{"id":"1.168096552","rc":[{"batl":[[1,20,1.68],[2,21,1.5]],"ltp":11.5,"tv":244.14,"id":26640937}]}]}
{"op":"mcm","clk":"992097688","pt":1580513772158,"mc":[{"id":"1.168096552","rc":[{"batl":[[0,3.15,100]],"ltp":3.05,"tv":1615.39,"id":18286408}]}]}
{"op":"mcm","clk":"992098034","pt":1580513780850,"mc":[{"id":"1.168096552","rc":[{"batb":[[2,2.84,47.08]],"ltp":2.88,"tv":3994.31,"id":52106}]}]}
{"op":"mcm","clk":"992098098","pt":1580513782252,"mc":[{"id":"1.168096552","rc":[{"batb":[[1,2.84,47.08],[2,2.82,7.61]],"ltp":2.88,"tv":3994.31,"id":52106}]}]}
{"op":"mcm","clk":"992098919","pt":1580513801449,"mc":[{"id":"1.168096552","rc":[{"batl":[[1,21,1.5],[2,32,9.17]],"ltp":11.5,"tv":244.14,"id":26640937}]}]}
{"op":"mcm","clk":"992098924","pt":1580513801549,"mc":[{"id":"1.168096552","rc":[{"batl":[[2,30,1.85]],"ltp":11.5,"tv":244.14,"id":26640937}]}]}
{"op":"mcm","clk":"992100223","pt":1580513833390,"mc":[{"id":"1.168096552","rc":[{"batl":[[1,20,1.68],[2,21,1.5]],"ltp":11.5,"tv":244.14,"id":26640937}]}]}
{"op":"mcm","clk":"992111569","pt":1580513865721,"mc":[{"id":"1.168096552","rc":[{"batl":[[1,21,1.5],[2,30,1.85]],"ltp":11.5,"tv":244.14,"id":26640937}]}]}
{"op":"mcm","clk":"992113087","pt":1580513897480,"mc":[{"id":"1.168096552","rc":[{"batl":[[1,20,1.68],[2,21,1.5]],"ltp":11.5,"tv":244.14,"id":26640937}]}]}
{"op":"mcm","clk":"992114378","pt":1580513929484,"mc":[{"id":"1.168096552","rc":[{"batl":[[1,21,1.5],[2,32,9.17]],"ltp":11.5,"tv":244.14,"id":26640937}]}]}
{"op":"mcm","clk":"992114422","pt":1580513930507,"mc":[{"id":"1.168096552","rc":[{"batl":[[2,30,1.85]],"ltp":11.5,"tv":244.14,"id":26640937},{"batl":[[0,2.98,9.02]],"ltp":2.88,"tv":3994.31,"id":52106}]}]}
{"op":"mcm","clk":"992114510","pt":1580513933020,"mc":[{"id":"1.168096552","rc":[{"batl":[[0,2.98,5.99]],"ltp":2.88,"tv":3994.31,"id":52106}]}]}
{"op":"mcm","clk":"992114646","pt":1580513937220,"mc":[{"id":"1.168096552","rc":[{"batb":[[0,2.88,4.77],[1,2.86,13.93],[2,2.84,47.08]],"batl":[[0,2.98,7.51]],"ltp":2.88,"tv":3994.31,"id":52106}]}]}
{"op":"mcm","clk":"992115506","pt":1580513961917,"mc":[{"id":"1.168096552","rc":[{"batl":[[1,20,1.68],[2,21,1.5]],"ltp":11.5,"tv":244.14,"id":26640937}]}]}
{"op":"mcm","clk":"992116614","pt":1580513993846,"mc":[{"id":"1.168096552","rc":[{"batl":[[1,21,1.5],[2,30,1.85]],"ltp":11.5,"tv":244.14,"id":26640937}]}]}
{"op":"mcm","clk":"992117952","pt":1580514026112,"mc":[{"id":"1.168096552","rc":[{"batl":[[1,20,1.68],[2,21,1.5]],"ltp":11.5,"tv":244.14,"id":26640937}]}]}
{"op":"mcm","clk":"992119283","pt":1580514057448,"mc":[{"id":"1.168096552","rc":[{"batl":[[1,21,1.5],[2,30,1.85]],"ltp":11.5,"tv":244.14,"id":26640937}]}]}
{"op":"mcm","clk":"992120280","pt":1580514089159,"mc":[{"id":"1.168096552","rc":[{"batl":[[1,20,1.68],[2,21,1.5]],"ltp":11.5,"tv":244.14,"id":26640937}]}]}
{"op":"mcm","clk":"992121223","pt":1580514121891,"mc":[{"id":"1.168096552","rc":[{"batl":[[1,21,1.5],[2,30,1.85]],"ltp":11.5,"tv":244.14,"id":26640937}]}]}
{"op":"mcm","clk":"992122260","pt":1580514153429,"mc":[{"id":"1.168096552","rc":[{"batl":[[1,20,1.68],[2,21,1.5]],"ltp":11.5,"tv":244.14,"id":26640937}]}]}
{"op":"mcm","clk":"992123428","pt":1580514185838,"mc":[{"id":"1.168096552","rc":[{"batl":[[1,21,1.5],[2,30,1.85]],"ltp":11.5,"tv":244.14,"id":26640937}]}]}
{"op":"mcm","clk":"992124696","pt":1580514217433,"mc":[{"id":"1.168096552","rc":[{"batl":[[1,20,1.68],[2,21,1.5]],"ltp":11.5,"tv":244.14,"id":26640937}]}]}
{"op":"mcm","clk":"992125725","pt":1580514249320,"mc":[{"id":"1.168096552","rc":[{"batl":[[1,21,1.5],[2,30,1.85]],"ltp":11.5,"tv":244.14,"id":26640937}]}]}
{"op":"mcm","clk":"992125902","pt":1580514255337,"mc":[{"id":"1.168096552","rc":[{"trd":[[3,152.01]],"batb":[[0,2.98,4],[1,2.88,39],[2,2.86,2.08]],"ltp":3.0,"tv":1729.65,"id":18286408},{"trd":[[2.98,140.53]],"batl":[[0,3,20.57],[1,3.05,168.04],[2,3.1,2.36]],"ltp":2.98,"tv":4009.32,"id":52106}],"tv":7117.18}]}
{"op":"mcm","clk":"992126159","pt":1580514262387,"mc":[{"id":"1.168096552","rc":[{"batl":[[0,3.1,8.62],[1,3.15,100],[2,3.2,22]],"ltp":3.0,"tv":1729.65,"id":18286408}]}]}
{"op":"mcm","clk":"992126227","pt":1580514263771,"mc":[{"id":"1.168096552","rc":[{"batb":[[1,2.88,36],[2,2.86,5.08]],"ltp":3.0,"tv":1729.65,"id":18286408}]}]}
{"op":"mcm","clk":"992126683","pt":1580514277489,"mc":[{"id":"1.168096552","rc":[{"batb":[[0,2.9,4.11],[1,2.88,4.77],[2,2.86,13.93]],"ltp":2.98,"tv":4009.32,"id":52106}]}]}
{"op":"mcm","clk":"992126811","pt":1580514280471,"mc":[{"id":"1.168096552","rc":[{"batb":[[1,2.88,6.99]],"batl":[[0,2.98,2.14],[1,3,20.57],[2,3.05,168.04]],"ltp":2.98,"tv":4009.32,"id":52106}]}]}
{"op":"mcm","clk":"992126821","pt":1580514280779,"mc":[{"id":"1.168096552","rc":[{"batl":[[1,20,1.68],[2,21,1.5]],"ltp":11.5,"tv":244.14,"id":26640937}]}]}
{"op":"mcm","clk":"992126871","pt":1580514282472,"mc":[{"id":"1.168096552","rc":[{"batb":[[0,2.9,8.88],[1,2.88,2.22]],"ltp":2.98,"tv":4009.32,"id":52106}]}]}
{"op":"mcm","clk":"992127887","pt":1580514312925,"mc":[{"id":"1.168096552","rc":[{"batl":[[1,21,1.5],[2,30,1.85]],"ltp":11.5,"tv":244.14,"id":26640937}]}]}
{"op":"mcm","clk":"992128796","pt":1580514345478,"mc":[{"id":"1.168096552","rc":[{"batl":[[1,20,1.68],[2,21,1.5]],"ltp":11.5,"tv":244.14,"id":26640937}]}]}
{"op":"mcm","clk":"992129812","pt":1580514376474,"mc":[{"id":"1.168096552","rc":[{"batl":[[1,21,1.5],[2,30,1.85]],"ltp":11.5,"tv":244.14,"id":26640937}]}]}
{"op":"mcm","clk":"992130860","pt":1580514408362,"mc":[{"id":"1.168096552","rc":[{"batl":[[1,20,1.68],[2,21,1.5]],"ltp":11.5,"tv":244.14,"id":26640937}]}]}
{"op":"mcm","clk":"992131848","pt":1580514439475,"mc":[{"id":"1.168096552","rc":[{"batl":[[1,21,1.5],[2,32,9.17]],"ltp":11.5,"tv":244.14,"id":26640937}]}]}
{"op":"mcm","clk":"992131853","pt":1580514439577,"mc":[{"id":"1.168096552","rc":[{"batl":[[2,30,1.85]],"ltp":11.5,"tv":244.14,"id":26640937}]}]}
{"op":"mcm","clk":"992132782","pt":1580514470922,"mc":[{"id":"1.168096552","rc":[{"batl":[[1,20,1.68],[2,21,1.5]],"ltp":11.5,"tv":244.14,"id":26640937}]}]}
{"op":"mcm","clk":"992133291","pt":1580514492165,"mc":[{"id":"1.168096552","rc":[{"batl":[[0,2.96,2],[1,2.98,2.14],[2,3,20.57]],"ltp":2.98,"tv":4009.32,"id":52106}]}]}
{"op":"mcm","clk":"992133310","pt":1580514492731,"mc":[{"id":"1.168096552","rc":[{"batl":[[0,2.98,2.14],[1,3,20.57],[2,3.05,168.04]],"ltp":2.98,"tv":4009.32,"id":52106}]}]}
{"op":"mcm","clk":"992133619","pt":1580514502881,"mc":[{"id":"1.168096552","rc":[{"batl":[[1,21,1.5],[2,30,1.85]],"ltp":11.5,"tv":244.14,"id":26640937}]}]}
{"op":"mcm","clk":"992134491","pt":1580514531922,"mc":[{"id":"1.168096552","rc":[{"batl":[[0,3.1,58.62]],"ltp":3.0,"tv":1729.65,"id":18286408}]}]}
{"op":"mcm","clk":"992134551","pt":1580514535202,"mc":[{"id":"1.168096552","rc":[{"batl":[[1,20,1.68],[2,21,1.5]],"ltp":11.5,"tv":244.14,"id":26640937}]}]}
{"op":"mcm","clk":"992135406","pt":1580514562502,"mc":[{"id":"1.168096552","rc":[{"batb":[[0,2.96,101],[1,2.9,8.88],[2,2.88,2.22]],"ltp":2.98,"tv":4009.32,"id":52106}]}]}
{"op":"mcm","clk":"992135523","pt":1580514567902,"mc":[{"id":"1.168096552","rc":[{"batl":[[1,21,1.5],[2,30,1.85]],"ltp":11.5,"tv":244.14,"id":26640937},{"batb":[[2,2.86,13.93]],"batl":[[0,3,20.57],[1,3.05,168.04],[2,3.1,2.36]],"ltp":2.98,"tv":4009.32,"id":52106}]}]}
{"op":"mcm","clk":"992136134","pt":1580514597442,"mc":[{"id":"1.168096552","rc":[{"batb":[[1,2.9,6.72],[2,2.88,36]],"ltp":3.0,"tv":1729.65,"id":18286408}]}]}
{"op":"mcm","clk":"992136178","pt":1580514599786,"mc":[{"id":"1.168096552","rc":[{"batl":[[1,20,1.68],[2,21,1.5]],"ltp":11.5,"tv":244.14,"id":26640937}]}]}
{"op":"mcm","clk":"992136692","pt":1580514626989,"mc":[{"id":"1.168096552","rc":[{"batb":[[1,2.9,13.44]],"ltp":3.0,"tv":1729.65,"id":18286408}]}]}
{"op":"mcm","clk":"992136794","pt":1580514631312,"mc":[{"id":"1.168096552","rc":[{"batl":[[1,21,1.5],[2,30,1.85]],"ltp":11.5,"tv":244.14,"id":26640937}]}]}
{"op":"mcm","clk":"992137725","pt":1580514663353,"mc":[{"id":"1.168096552","rc":[{"batl":[[1,20,1.68],[2,21,1.5]],"ltp":11.5,"tv":244.14,"id":26640937}]}]}
{"op":"mcm","clk":"992138373","pt":1580514695675,"mc":[{"id":"1.168096552","rc":[{"batl":[[1,21,1.5],[2,30,1.85]],"ltp":11.5,"tv":244.14,"id":26640937}]}]}
{"op":"mcm","clk":"992138967","pt":1580514719887,"mc":[{"id":"1.168096552","rc":[{"trd":[[2.96,83.72]],"batb":[[0,2.96,63.14]],"ltp":2.96,"tv":4085.04,"id":52106}],"tv":7192.91}]}
{"op":"mcm","clk":"992139081","pt":1580514725425,"mc":[{"id":"1.168096552","rc":[{"trd":[[3,313.83]],"batl":[[0,3,5.43]],"ltp":3.0,"tv":4115.33,"id":52106}],"tv":7223.19}]}
