{"op":"mcm","clk":"993096062","pt":1580536380117,"mc":[{"id":"1.168096552","rc":[{"batl":[[0,3.1,2],[1,3.15,100],[2,3.2,22]],"ltp":3.05,"tv":2798.86,"id":18286408}]}]}
{"op":"mcm","clk":"993096190","pt":1580536384434,"mc":[{"id":"1.168096552","rc":[{"batb":[[1,2.94,4.03]],"ltp":3.05,"tv":2798.86,"id":18286408}]}]}
{"op":"mcm","clk":"993096204","pt":1580536384900,"mc":[{"id":"1.168096552","rc":[{"batl":[[0,3.1,29.67]],"ltp":3.05,"tv":2798.86,"id":18286408},{"batb":[[1,38,2.09]],"ltp":48.0,"tv":44.97,"id":27706761},{"batl":[[0,3,10.44],[1,3.05,83.04],[2,3.1,18.9]],"ltp":2.96,"tv":6435.83,"id":52106}]}]}
{"op":"mcm","clk":"993096247","pt":1580536386233,"mc":[{"id":"1.168096552","rc":[{"batl":[[0,2.98,4],[1,3,10.44],[2,3.05,83.04]],"ltp":2.96,"tv":6435.83,"id":52106}]}]}
{"op":"mcm","clk":"993096364","pt":1580536389315,"mc":[{"id":"1.168096552","rc":[{"batl":[[0,3.05,2],[1,3.1,29.67],[2,3.15,100]],"ltp":3.05,"tv":2798.86,"id":18286408}]}]}
{"op":"mcm","clk":"993096454","pt":1580536392448,"mc":[{"id":"1.168096552","rc":[{"batl":[[0,3,2],[1,3.05,2],[2,3.1,29.67]],"ltp":3.05,"tv":2798.86,"id":18286408},{"batb":[[0,18,3.15]],"ltp":21.0,"tv":67.14,"id":24608298}]}]}
{"op":"mcm","clk":"993096577","pt":1580536396519,"mc":[{"id":"1.168096552","rc":[{"batl":[[1,20,1.68],[2,21,1.5]],"ltp":14.5,"tv":341.94,"id":26640937}]}]}
{"op":"mcm","clk":"993096821","pt":1580536401422,"mc":[{"id":"1.168096552","rc":[{"batl":[[2,3.1,2]],"ltp":3.05,"tv":2798.86,"id":18286408},{"batl":[[1,5.3,11]],"ltp":5.0,"tv":1685.85,"id":21580749},{"batl":[[2,3.1,18.9]],"ltp":2.96,"tv":6435.83,"id":52106}]}]}
{"op":"mcm","clk":"993096876","pt":1580536402229,"mc":[{"id":"1.168096552","rc":[{"batb":[[0,2.98,10.62],[1,2.96,3],[2,2.94,4.03]],"ltp":3.05,"tv":2798.86,"id":18286408}]}]}
{"op":"mcm","clk":"993096924","pt":1580536402959,"mc":[{"id":"1.168096552","rc":[{"batl":[[2,3.1,18.99]],"ltp":3.05,"tv":2798.86,"id":18286408}]}]}
{"op":"mcm","clk":"993097207","pt":1580536409471,"mc":[{"id":"1.168096552","rc":[{"batb":[[0,2.9,7]],"batl":[[0,3,10.44],[1,3.1,18.9],[2,3.15,25.63]],"ltp":2.96,"tv":6435.83,"id":52106}]}]}
{"op":"mcm","clk":"993097931","pt":1580536428097,"mc":[{"id":"1.168096552","rc":[{"batb":[[1,2.88,20.68]],"batl":[[1,3.05,5.23],[2,3.1,18.9]],"ltp":2.96,"tv":6435.83,"id":52106}]}]}
{"op":"mcm","clk":"993101773","pt":1580536513174,"mc":[{"id":"1.168096552","rc":[{"trd":[[3,531.42],[3.05,471.73]],"batl":[[0,3.1,18.99],[1,3.15,100],[2,3.2,22]],"ltp":3.05,"tv":2806.86,"id":18286408}],"tv":11382.62}]}
{"op":"mcm","clk":"993101828","pt":1580536514258,"mc":[{"id":"1.168096552","rc":[{"batl":[[0,3.1,2]],"ltp":3.05,"tv":2806.86,"id":18286408}]}]}
{"op":"mcm","clk":"993101987","pt":1580536517904,"mc":[{"id":"1.168096552","rc":[{"batb":[[0,2.98,12.62],[2,2.94,6.03]],"ltp":3.05,"tv":2806.86,"id":18286408}]}]}
{"op":"mcm","clk":"993102263","pt":1580536523568,"mc":[{"id":"1.168096552","rc":[{"batl":[[1,5.3,9]],"ltp":5.0,"tv":1685.85,"id":21580749}]}]}
{"op":"mcm","clk":"993103461","pt":1580536547630,"mc":[{"id":"1.168096552","rc":[{"batb":[[0,3,3],[1,2.98,12.62]],"ltp":3.05,"tv":2806.86,"id":18286408}]}]}
{"op":"mcm","clk":"993106516","pt":1580536621503,"mc":[{"id":"1.168096552","rc":[{"batb":[[0,18,2.27]],"ltp":21.0,"tv":67.14,"id":24608298}]}]}
{"op":"mcm","clk":"993113775","pt":1580536764083,"mc":[{"id":"1.168096552","rc":[{"batl":[[1,50,3],[2,85,1.35]],"ltp":48.0,"tv":44.97,"id":27706761}]}]}
{"op":"mcm","clk":"993114535","pt":1580536784493,"mc":[{"id":"1.168096552","rc":[{"trd":[[18,4.54]],"batb":[[0,17.5,4.64],[1,13.5,3.7],[2,13,2]],"batl":[[0,18,2.73],[1,21,14.78],[2,48,1.08]],"ltp":18.0,"tv":71.68,"id":24608298}],"tv":11387.15}]}
{"op":"mcm","clk":"993114581","pt":1580536785979,"mc":[{"id":"1.168096552","rc":[{"batb":[[0,2.92,5.9],[1,2.9,7],[2,2.88,20.68]],"ltp":2.96,"tv":6435.83,"id":52106}]}]}
{"op":"mcm","clk":"993114703","pt":1580536789405,"mc":[{"id":"1.168096552","rc":[{"batb":[[1,13.5,2.39]],"ltp":18.0,"tv":71.68,"id":24608298}]}]}
{"op":"mcm","clk":"993115521","pt":1580536808436,"mc":[{"id":"1.168096552","rc":[{"trd":[[18,8.2]],"batl":[[0,21,17.29],[1,48,1.08],[2,55,3.1]],"ltp":18.0,"tv":75.34,"id":24608298}],"tv":11390.81}]}
{"op":"mcm","clk":"993115531","pt":1580536808641,"mc":[{"id":"1.168096552","rc":[{"trd":[[18,10]],"batl":[[0,21,16.39]],"ltp":18.0,"tv":77.14,"id":24608298}],"tv":11392.61}]}
{"op":"mcm","clk":"993115619","pt":1580536810342,"mc":[{"id":"1.168096552","rc":[{"batb":[[1,2.9,4]],"ltp":2.96,"tv":6435.83,"id":52106}]}]}
{"op":"mcm","clk":"993115782","pt":1580536814450,"mc":[{"id":"1.168096552","rc":[{"batl":[[0,3.05,2],[1,3.1,2],[2,3.15,100]],"ltp":3.05,"tv":2806.86,"id":18286408},{"batb":[[1,38,2.54],[2,36,3.98]],"ltp":48.0,"tv":44.97,"id":27706761},{"batb":[[1,14,20.4],[2,13.5,1.98]],"ltp":18.0,"tv":77.14,"id":24608298}]}]}
{"op":"mcm","clk":"993116351","pt":1580536825521,"mc":[{"id":"1.168096552","rc":[{"batl":[[0,2.98,2],[1,3,10.44],[2,3.05,5.23]],"ltp":2.96,"tv":6435.83,"id":52106}]}]}
{"op":"mcm","clk":"993116379","pt":1580536826441,"mc":[{"id":"1.168096552","rc":[{"batl":[[1,3.05,5.23],[2,3.1,18.9]],"ltp":2.96,"tv":6435.83,"id":52106}]}]}
{"op":"mcm","clk":"993116506","pt":1580536829529,"mc":[{"id":"1.168096552","rc":[{"batb":[[1,14.5,1.62],[2,14,20]],"ltp":18.0,"tv":77.14,"id":24608298}]}]}
{"op":"mcm","clk":"993116924","pt":1580536839457,"mc":[{"id":"1.168096552","rc":[{"trd":[[3.05,475.73]],"batl":[[0,3.1,2],[1,3.15,100],[2,3.2,22]],"ltp":3.05,"tv":2810.86,"id":18286408}],"tv":11396.61}]}
{"op":"mcm","clk":"993116953","pt":1580536840175,"mc":[{"id":"1.168096552","rc":[{"batb":[[2,2.88,15.14]],"batl":[[1,3.1,18.9],[2,3.15,25.63]],"ltp":2.96,"tv":6435.83,"id":52106}]}]}
{"op":"mcm","clk":"993117653","pt":1580536857491,"mc":[{"id":"1.168096552","rc":[{"batl":[[1,3.05,4],[2,3.1,18.9]],"ltp":2.96,"tv":6435.83,"id":52106}]}]}
{"op":"mcm","clk":"993117862","pt":1580536862395,"mc":[{"id":"1.168096552","rc":[{"batb":[[0,2.94,4],[1,2.92,5.9]],"ltp":2.96,"tv":6435.83,"id":52106}]}]}
{"op":"mcm","clk":"993118098","pt":1580536867504,"mc":[{"id":"1.168096552","rc":[{"batl":[[0,3.05,2],[1,3.1,2],[2,3.15,100]],"ltp":3.05,"tv":2810.86,"id":18286408}]}]}
{"op":"mcm","clk":"993121420","pt":1580536934834,"mc":[{"id":"1.168096552","rc":[{"batl":[[1,3.15,100],[2,3.2,22]],"ltp":3.05,"tv":2810.86,"id":18286408}]}]}
{"op":"mcm","clk":"993123014","pt":1580536974985,"mc":[{"id":"1.168096552","rc":[{"batl":[[0,21,17.19]],"ltp":18.0,"tv":77.14,"id":24608298}]}]}
{"op":"mcm","clk":"993124474","pt":1580537013035,"mc":[{"id":"1.168096552","rc":[{"batb":[[0,2.96,5.82],[1,2.94,4]],"ltp":2.96,"tv":6435.83,"id":52106}]}]}
{"op":"mcm","clk":"993124936","pt":1580537025039,"mc":[{"id":"1.168096552","rc":[{"batl":[[2,140,9.1]],"ltp":18.0,"tv":77.14,"id":24608298}]}]}
{"op":"mcm","clk":"993125266","pt":1580537033755,"mc":[{"id":"1.168096552","rc":[{"batl":[[1,3.1,18.9],[2,3.15,25.63]],"ltp":2.96,"tv":6435.83,"id":52106}]}]}
{"op":"mcm","clk":"993126163","pt":1580537058386,"mc":[{"id":"1.168096552","rc":[{"batl":[[0,21,16.39]],"ltp":18.0,"tv":77.14,"id":24608298}]}]}
{"op":"mcm","clk":"993127836","pt":1580537103444,"mc":[{"id":"1.168096552","rc":[{"batb":[[0,17.5,5.6]],"ltp":18.0,"tv":77.14,"id":24608298}]}]}
{"op":"mcm","clk":"993129343","pt":1580537134465,"mc":[{"id":"1.168096552","rc":[{"trd":[[3.05,479.73]],"batl":[[0,3.15,100],[1,3.2,22],[2,3.25,380]],"ltp":3.05,"tv":2814.86,"id":18286408}],"tv":11400.61}]}
{"op":"mcm","clk":"993129353","pt":1580537134670,"mc":[{"id":"1.168096552","rc":[{"batb":[[1,2.98,2]],"ltp":3.05,"tv":2814.86,"id":18286408}]}]}
{"op":"mcm","clk":"993129560","pt":1580537138479,"mc":[{"id":"1.168096552","rc":[{"batl":[[0,3.05,2],[1,3.1,2],[2,3.15,100]],"ltp":3.05,"tv":2814.86,"id":18286408}]}]}
{"op":"mcm","clk":"993129922","pt":1580537146977,"mc":[{"id":"1.168096552","rc":[{"trd":[[2.98,468.01]],"batl":[[0,3.1,18.9],[1,3.15,25.63],[2,3.3,15.14]],"ltp":2.98,"tv":6439.83,"id":52106}],"tv":11404.61}]}
{"op":"mcm","clk":"993130161","pt":1580537151875,"mc":[{"id":"1.168096552","rc":[{"batb":[[2,2.92,2]],"ltp":2.98,"tv":6439.83,"id":52106}]}]}
{"op":"mcm","clk":"993130742","pt":1580537165232,"mc":[{"id":"1.168096552","rc":[{"batb":[[0,5,2],[1,4.9,3.22],[2,4.8,3]],"ltp":5.0,"tv":1685.85,"id":21580749}]}]}
{"op":"mcm","clk":"993132342","pt":1580537200063,"mc":[{"id":"1.168096552","rc":[{"trd":[[3.05,483.73]],"batl":[[0,3.1,2],[1,3.15,100],[2,3.2,22]],"ltp":3.05,"tv":2818.86,"id":18286408}],"tv":11408.61}]}
{"op":"mcm","clk":"993132376","pt":1580537200914,"mc":[{"id":"1.168096552","rc":[{"batl":[[0,3.05,2],[1,3.1,2],[2,3.15,100]],"ltp":3.05,"tv":2818.86,"id":18286408}]}]}
{"op":"mcm","clk":"993133287","pt":1580537223277,"mc":[{"id":"1.168096552","rc":[{"batl":[[0,5.1,25],[1,5.2,28.52],[2,5.3,9]],"ltp":5.0,"tv":1685.85,"id":21580749}]}]}
{"op":"mcm","clk":"993144214","pt":1580537252320,"mc":[{"id":"1.168096552","rc":[{"batl":[[2,5.3,25]],"ltp":5.0,"tv":1685.85,"id":21580749}]}]}
{"op":"mcm","clk":"993144588","pt":1580537262592,"mc":[{"id":"1.168096552","rc":[{"batb":[[2,4.7,21.12]],"ltp":5.0,"tv":1685.85,"id":21580749}]}]}
{"op":"mcm","clk":"993145420","pt":1580537284226,"mc":[{"id":"1.168096552","rc":[{"batb":[[0,2.98,4],[1,2.96,5.82]],"ltp":2.98,"tv":6439.83,"id":52106}]}]}
{"op":"mcm","clk":"993146428","pt":1580537310073,"mc":[{"id":"1.168096552","rc":[{"batl":[[2,5.3,9]],"ltp":5.0,"tv":1685.85,"id":21580749}]}]}
{"op":"mcm","clk":"993147262","pt":1580537331286,"mc":[{"id":"1.168096552","rc":[{"trd":[[5.1,79.98]],"batl":[[0,5.1,15]],"ltp":5.1,"tv":1705.85,"id":21580749}],"tv":11428.61}]}
{"op":"mcm","clk":"993148464","pt":1580537361224,"mc":[{"id":"1.168096552","rc":[{"batb":[[0,13,1.33],[1,12.5,3.87],[2,12,1.26]],"ltp":14.5,"tv":341.94,"id":26640937}]}]}
{"op":"mcm","clk":"993148871","pt":1580537371231,"mc":[{"id":"1.168096552","rc":[{"batb":[[0,13,3.33],[1,12.5,1.87]],"ltp":14.5,"tv":341.94,"id":26640937}]}]}
{"op":"mcm","clk":"993150500","pt":1580537411690,"mc":[{"id":"1.168096552","rc":[{"batb":[[0,13.5,5.17],[1,13,3.33],[2,12.5,1.87]],"ltp":14.5,"tv":341.94,"id":26640937}]}]}
{"op":"mcm","clk":"993150787","pt":1580537418904,"mc":[{"id":"1.168096552","rc":[{"batb":[[0,18,2.96],[1,17.5,4.64],[2,14.5,1.62]],"ltp":18.0,"tv":77.14,"id":24608298}]}]}
{"op":"mcm","clk":"993151008","pt":1580537424260,"mc":[{"id":"1.168096552","rc":[{"batb":[[0,18,22.96]],"ltp":18.0,"tv":77.14,"id":24608298}]}]}
{"op":"mcm","clk":"993151221","pt":1580537429585,"mc":[{"id":"1.168096552","rc":[{"batb":[[2,13.5,2.39]],"ltp":18.0,"tv":77.14,"id":24608298}]}]}
{"op":"mcm","clk":"993151406","pt":1580537433762,"mc":[{"id":"1.168096552","rc":[{"batb":[[0,3,5.74],[1,2.98,4]],"ltp":2.98,"tv":6439.83,"id":52106}]}]}
{"op":"mcm","clk":"993151567","pt":1580537437372,"mc":[{"id":"1.168096552","rc":[{"batb":[[0,18,23.92]],"ltp":18.0,"tv":77.14,"id":24608298}]}]}
{"op":"mcm","clk":"993152058","pt":1580537449331,"mc":[{"id":"1.168096552","rc":[{"batb":[[0,18.5,2.64],[1,18,22.96],[2,17.5,4.64]],"ltp":18.0,"tv":77.14,"id":24608298}]}]}
{"op":"mcm","clk":"993153450","pt":1580537481370,"mc":[{"id":"1.168096552","rc":[{"batb":[[0,18,23.92],[1,17.5,4.64],[2,14,2.62]],"ltp":18.0,"tv":77.14,"id":24608298}]}]}
{"op":"mcm","clk":"993153468","pt":1580537481632,"mc":[{"id":"1.168096552","rc":[{"batb":[[2,14,2.86]],"ltp":18.0,"tv":77.14,"id":24608298}]}]}
{"op":"mcm","clk":"993154207","pt":1580537499502,"mc":[{"id":"1.168096552","rc":[{"trd":[[2.94,10.56],[2.98,26],[3,537.42]],"batb":[[0,2.9,6.62],[1,2.88,39],[2,2.78,4.24]],"ltp":2.94,"tv":2839.42,"id":18286408}],"tv":11449.17}]}
{"op":"mcm","clk":"993154543","pt":1580537506792,"mc":[{"id":"1.168096552","rc":[{"batb":[[1,2.88,36]],"ltp":2.94,"tv":2839.42,"id":18286408}]}]}
{"op":"mcm","clk":"993155230","pt":1580537522708,"mc":[{"id":"1.168096552","rc":[{"batb":[[0,2.92,5.75],[1,2.9,5.87],[2,2.88,36]],"ltp":2.94,"tv":2839.42,"id":18286408}]}]}
{"op":"mcm","clk":"993155698","pt":1580537534217,"mc":[{"id":"1.168096552","rc":[{"batl":[[1,3.15,12],[2,3.5,1]],"ltp":2.98,"tv":6439.83,"id":52106}]}]}
{"op":"mcm","clk":"993155815","pt":1580537537146,"mc":[{"id":"1.168096552","rc":[{"batb":[[2,2.94,15.14]],"ltp":2.98,"tv":6439.83,"id":52106}]}]}
{"op":"mcm","clk":"993155876","pt":1580537538439,"mc":[{"id":"1.168096552","rc":[{"batb":[[2,2.92,17.14]],"ltp":2.98,"tv":6439.83,"id":52106}]}]}
{"op":"mcm","clk":"993156317","pt":1580537547126,"mc":[{"id":"1.168096552","rc":[{"batb":[[1,2.94,4]],"ltp":2.98,"tv":6439.83,"id":52106}]}]}
{"op":"mcm","clk":"993156637","pt":1580537554457,"mc":[{"id":"1.168096552","rc":[{"batb":[[0,14,1.23],[1,13.5,5.17],[2,13,2]],"ltp":14.5,"tv":341.94,"id":26640937}]}]}
{"op":"mcm","clk":"993158177","pt":1580537589496,"mc":[{"id":"1.168096552","rc":[{"batb":[[0,2.94,11.48],[1,2.92,5],[2,2.9,5.87]],"batl":[[0,3,2],[1,3.05,2],[2,3.1,19.01]],"ltp":2.94,"tv":2839.42,"id":18286408}]}]}
{"op":"mcm","clk":"993158943","pt":1580537604735,"mc":[{"id":"1.168096552","rc":[{"batl":[[0,2.98,2],[1,3,2]],"ltp":2.94,"tv":2839.42,"id":18286408}]}]}
{"op":"mcm","clk":"993162587","pt":1580537694453,"mc":[{"id":"1.168096552","rc":[{"batl":[[2,3.1,17.01]],"ltp":2.94,"tv":2839.42,"id":18286408}]}]}
{"op":"mcm","clk":"993167155","pt":1580537797309,"mc":[{"id":"1.168096552","rc":[{"trd":[[5.1,83.98]],"batl":[[0,5.1,13]],"ltp":5.1,"tv":1709.85,"id":21580749}],"tv":11453.17}]}
{"op":"mcm","clk":"993167980","pt":1580537810122,"mc":[{"id":"1.168096552","rc":[{"batb":[[0,2.96,5],[1,2.94,11.48]],"ltp":2.94,"tv":2839.42,"id":18286408}]}]}
{"op":"mcm","clk":"993169500","pt":1580537842453,"mc":[{"id":"1.168096552","rc":[{"trd":[[2.98,30],[3,541.42]],"batl":[[0,3.1,17.01],[1,3.15,100],[2,3.2,22]],"ltp":3.0,"tv":2847.42,"id":18286408}],"tv":11461.17}]}
{"op":"mcm","clk":"993169536","pt":1580537843381,"mc":[{"id":"1.168096552","rc":[{"batb":[[1,2.9,6.62],[2,2.88,36]],"ltp":3.0,"tv":2847.42,"id":18286408}]}]}
{"op":"mcm","clk":"993169573","pt":1580537844258,"mc":[{"id":"1.168096552","rc":[{"batl":[[0,3.15,100],[1,3.2,22],[2,3.25,380]],"ltp":3.0,"tv":2847.42,"id":18286408}]}]}
{"op":"mcm","clk":"993169652","pt":1580537846061,"mc":[{"id":"1.168096552","rc":[{"batl":[[0,3.1,2],[1,3.15,100],[2,3.2,22]],"ltp":3.0,"tv":2847.42,"id":18286408}]}]}
{"op":"mcm","clk":"993169784","pt":1580537849300,"mc":[{"id":"1.168096552","rc":[{"batb":[[0,2.96,7]],"ltp":3.0,"tv":2847.42,"id":18286408}]}]}
{"op":"mcm","clk":"993170133","pt":1580537856984,"mc":[{"id":"1.168096552","rc":[{"batb":[[0,2.96,2],[1,2.9,11.62]],"ltp":3.0,"tv":2847.42,"id":18286408}]}]}
{"op":"mcm","clk":"993170195","pt":1580537858383,"mc":[{"id":"1.168096552","rc":[{"batl":[[0,3.1,29.67]],"ltp":3.0,"tv":2847.42,"id":18286408}]}]}
{"op":"mcm","clk":"993170445","pt":1580537864112,"mc":[{"id":"1.168096552","rc":[{"batl":[[0,3.05,2],[1,3.1,29.67],[2,3.15,100]],"ltp":3.0,"tv":2847.42,"id":18286408}]}]}
{"op":"mcm","clk":"993170571","pt":1580537866487,"mc":[{"id":"1.168096552","rc":[{"batl":[[0,3,2],[1,3.05,6],[2,3.1,2]],"ltp":3.0,"tv":2847.42,"id":18286408}]}]}
{"op":"mcm","clk":"993170646","pt":1580537867878,"mc":[{"id":"1.168096552","rc":[{"trd":[[3,887.3]],"batb":[[0,2.94,4],[1,2.92,17.14],[2,2.84,46.76]],"batl":[[0,3,4.26],[1,3.1,18.9],[2,3.15,12]],"ltp":3.0,"tv":6451.31,"id":52106}],"tv":11472.65}]}
{"op":"mcm","clk":"993171140","pt":1580537879103,"mc":[{"id":"1.168096552","rc":[{"batl":[[0,2.98,2],[1,3,2],[2,3.05,4]],"ltp":3.0,"tv":2847.42,"id":18286408}]}]}
{"op":"mcm","clk":"993171775","pt":1580537892318,"mc":[{"id":"1.168096552","rc":[{"batl":[[0,3.1,18.9],[1,3.15,12],[2,3.5,1]],"ltp":3.0,"tv":6451.31,"id":52106}]}]}
{"op":"mcm","clk":"993172359","pt":1580537907333,"mc":[{"id":"1.168096552","rc":[{"batl":[[2,3.1,6]],"ltp":3.0,"tv":2847.42,"id":18286408}]}]}
{"op":"mcm","clk":"993172916","pt":1580537920335,"mc":[{"id":"1.168096552","rc":[{"batb":[[2,2.88,5.28]],"batl":[[0,3.05,4.99],[1,3.1,18.9],[2,3.15,12]],"ltp":3.0,"tv":6451.31,"id":52106}]}]}
{"op":"mcm","clk":"993176113","pt":1580537989153,"mc":[{"id":"1.168096552","rc":[{"batl":[[0,2.98,8.5],[1,3.05,4.99],[2,3.1,18.9]],"ltp":3.0,"tv":6451.31,"id":52106}]}]}
{"op":"mcm","clk":"993176752","pt":1580538003453,"mc":[{"id":"1.168096552","rc":[{"trd":[[4.9,102.14],[5,194.25]],"batb":[[0,4.7,21.26],[1,4.6,39.3],[2,4.5,27.25]],"ltp":4.9,"tv":1719.99,"id":21580749}],"tv":11482.79}]}
{"op":"mcm","clk":"993176806","pt":1580538004434,"mc":[{"id":"1.168096552","rc":[{"batb":[[0,4.8,33.97],[1,4.7,21.12],[2,4.6,39.3]],"ltp":4.9,"tv":1719.99,"id":21580749},{"batb":[[0,18.5,20.67],[1,18,22.96],[2,17.5,4.64]],"ltp":18.0,"tv":77.14,"id":24608298}]}]}
{"op":"mcm","clk":"993176833","pt":1580538005158,"mc":[{"id":"1.168096552","rc":[{"batb":[[0,4.9,8.68],[1,4.8,33.82],[2,4.7,21.12]],"ltp":4.9,"tv":1719.99,"id":21580749},{"batb":[[0,18.5,21.57],[1,18,22]],"ltp":18.0,"tv":77.14,"id":24608298}]}]}
{"op":"mcm","clk":"993177270","pt":1580538015363,"mc":[{"id":"1.168096552","rc":[{"trd":[[13.5,7.68],[14,2.45]],"batb":[[0,13.5,1.33],[1,13,2],[2,12.5,1.87]],"ltp":13.5,"tv":352.08,"id":26640937},{"batb":[[2,2.84,46.76]],"batl":[[1,3.1,18.9],[2,3.15,12]],"ltp":3.0,"tv":6451.31,"id":52106}],"tv":11492.93}]}
{"op":"mcm","clk":"993177637","pt":1580538023470,"mc":[{"id":"1.168096552","rc":[{"batb":[[1,4.7,21.12],[2,4.6,39.3]],"ltp":4.9,"tv":1719.99,"id":21580749},{"batb":[[0,18.5,1.87]],"ltp":18.0,"tv":77.14,"id":24608298}]}]}
{"op":"mcm","clk":"993180808","pt":1580538100251,"mc":[{"id":"1.168096552","rc":[{"trd":[[18,14.82],[18.5,1.92],[19,1.82]],"batb":[[0,18,19.59],[1,17.5,4.64],[2,14,2.86]],"ltp":18.0,"tv":85.69,"id":24608298}],"tv":11501.49}]}
{"op":"mcm","clk":"993180892","pt":1580538102066,"mc":[{"id":"1.168096552","rc":[{"batl":[[0,21,17.19]],"ltp":18.0,"tv":85.69,"id":24608298}]}]}
{"op":"mcm","clk":"993181328","pt":1580538113069,"mc":[{"id":"1.168096552","rc":[{"trd":[[2.98,34]],"batb":[[0,2.98,2.01],[1,2.96,2],[2,2.9,11.62]],"batl":[[0,3,2],[1,3.1,14.66],[2,3.15,100]],"ltp":2.98,"tv":2851.42,"id":18286408},{"batb":[[0,13.5,2.19]],"ltp":13.5,"tv":352.08,"id":26640937},{"trd":[[5.1,88.68]],"batl":[[0,5.1,10.65]],"ltp":5.1,"tv":1724.69,"id":21580749},{"batb":[[0,40,1.42]],"ltp":48.0,"tv":44.97,"id":27706761},{"trd":[[2.98,476.03]],"batl":[[0,2.98,4.49]],"ltp":2.98,"tv":6459.33,"id":52106},{"trd":[[20,1.2]],"batl":[[0,21,16.59]],"ltp":20.0,"tv":86.89,"id":24608298}],"tv":11519.4}]}
{"op":"mcm","clk":"993181381","pt":1580538114363,"mc":[{"id":"1.168096552","rc":[{"trd":[[2.98,38.02]],"batb":[[0,2.96,2],[1,2.9,11.62],[2,2.88,36]],"batl":[[0,3,2.99]],"ltp":2.98,"tv":2855.44,"id":18286408},{"batl":[[0,5.1,12.65]],"ltp":5.1,"tv":1724.69,"id":21580749},{"batl":[[0,2.96,3],[1,2.98,4.49],[2,3.1,18.9]],"ltp":2.98,"tv":6459.33,"id":52106}],"tv":11523.42}]}
{"op":"mcm","clk":"993181398","pt":1580538114879,"mc":[{"id":"1.168096552","rc":[{"batl":[[1,3.1,6]],"ltp":2.98,"tv":2855.44,"id":18286408}]}]}
{"op":"mcm","clk":"993181500","pt":1580538117364,"mc":[{"id":"1.168096552","rc":[{"batb":[[0,18.5,19.71],[1,18,19.59],[2,17.5,4.64]],"ltp":20.0,"tv":86.89,"id":24608298}]}]}
{"op":"mcm","clk":"993181716","pt":1580538121961,"mc":[{"id":"1.168096552","rc":[{"batl":[[1,3.05,2],[2,3.1,6]],"ltp":2.98,"tv":2855.44,"id":18286408}]}]}
{"op":"mcm","clk":"993182081","pt":1580538129960,"mc":[{"id":"1.168096552","rc":[{"trd":[[2.96,529.01]],"batl":[[0,2.98,4.49],[1,3.1,18.9],[2,3.15,12]],"ltp":2.96,"tv":6465.33,"id":52106}],"tv":11529.43}]}
{"op":"mcm","clk":"993182153","pt":1580538131353,"mc":[{"id":"1.168096552","rc":[{"batl":[[0,2.98,2.99],[1,3,2]],"ltp":2.98,"tv":2855.44,"id":18286408},{"batb":[[1,2.92,2]],"ltp":2.96,"tv":6465.33,"id":52106}]}]}
{"op":"mcm","clk":"993182326","pt":1580538135752,"mc":[{"id":"1.168096552","rc":[{"batb":[[2,2.9,15.14]],"ltp":2.96,"tv":6465.33,"id":52106}]}]}
{"op":"mcm","clk":"993182432","pt":1580538139300,"mc":[{"id":"1.168096552","rc":[{"trd":[[34,2.12],[36,16.12],[38,9.96],[40,25.78],[42,1.97],[44,0.56]],"batb":[[0,38,4],[1,32,3.31],[2,30,2]],"ltp":34.0,"tv":62.98,"id":27706761}],"tv":11547.43}]}
{"op":"mcm","clk":"993182608","pt":1580538143982,"mc":[{"id":"1.168096552","rc":[{"batl":[[0,48,2.23]],"ltp":34.0,"tv":62.98,"id":27706761}]}]}
{"op":"mcm","clk":"993182735","pt":1580538147284,"mc":[{"id":"1.168096552","rc":[{"batb":[[0,34,4.78],[1,32,2.54]],"ltp":34.0,"tv":62.98,"id":27706761}]}]}
{"op":"mcm","clk":"993182839","pt":1580538150380,"mc":[{"id":"1.168096552","rc":[{"batl":[[0,48,3.05]],"ltp":34.0,"tv":62.98,"id":27706761}]}]}
{"op":"mcm","clk":"993192766","pt":1580538153088,"mc":[{"id":"1.168096552","rc":[{"batb":[[1,2.92,5]],"ltp":2.96,"tv":6465.33,"id":52106}]}]}
{"op":"mcm","clk":"993194285","pt":1580538187512,"mc":[{"id":"1.168096552","rc":[{"batb":[[0,34,5.34]],"ltp":34.0,"tv":62.98,"id":27706761}]}]}
{"op":"mcm","clk":"993194573","pt":1580538195421,"mc":[{"id":"1.168096552","rc":[{"batb":[[1,12.5,1.87],[2,12,1.26]],"ltp":13.5,"tv":352.08,"id":26640937}]}]}
{"op":"mcm","clk":"993194577","pt":1580538195525,"mc":[{"id":"1.168096552","rc":[{"batb":[[2,12,3.26]],"ltp":13.5,"tv":352.08,"id":26640937}]}]}
{"op":"mcm","clk":"993194822","pt":1580538201885,"mc":[{"id":"1.168096552","rc":[{"batb":[[2,12,1.26]],"ltp":13.5,"tv":352.08,"id":26640937}]}]}
{"op":"mcm","clk":"993200235","pt":1580538333501,"mc":[{"id":"1.168096552","rc":[{"batl":[[0,21,16.39]],"ltp":20.0,"tv":86.89,"id":24608298}]}]}
{"op":"mcm","clk":"993202156","pt":1580538375801,"mc":[{"id":"1.168096552","rc":[{"batl":[[0,48,2.71]],"ltp":34.0,"tv":62.98,"id":27706761}]}]}
{"op":"mcm","clk":"993203315","pt":1580538405478,"mc":[{"id":"1.168096552","rc":[{"batl":[[2,3.1,4]],"ltp":2.98,"tv":2855.44,"id":18286408}]}]}
{"op":"mcm","clk":"993203323","pt":1580538405638,"mc":[{"id":"1.168096552","rc":[{"batb":[[0,18.5,20.62]],"ltp":20.0,"tv":86.89,"id":24608298}]}]}
{"op":"mcm","clk":"993203812","pt":1580538417460,"mc":[{"id":"1.168096552","rc":[{"batl":[[1,3.1,4],[2,3.15,100]],"ltp":2.98,"tv":2855.44,"id":18286408}]}]}
{"op":"mcm","clk":"993203835","pt":1580538418079,"mc":[{"id":"1.168096552","rc":[{"batl":[[1,3.1,21.16]],"ltp":2.98,"tv":2855.44,"id":18286408}]}]}
{"op":"mcm","clk":"993204379","pt":1580538430292,"mc":[{"id":"1.168096552","rc":[{"trd":[[2.98,40]],"batb":[[0,2.98,10.62],[1,2.96,2],[2,2.92,6.65]],"batl":[[0,3.05,2]],"ltp":2.98,"tv":2857.42,"id":18286408}],"tv":11549.41}]}
{"op":"mcm","clk":"993204551","pt":1580538434466,"mc":[{"id":"1.168096552","rc":[{"batb":[[0,18,20.5],[1,17.5,4.64],[2,14,2.86]],"ltp":20.0,"tv":86.89,"id":24608298}]}]}
{"op":"mcm","clk":"993204858","pt":1580538441874,"mc":[{"id":"1.168096552","rc":[{"batl":[[1,3.1,17.16]],"ltp":2.98,"tv":2857.42,"id":18286408},{"batb":[[0,36,1.04],[1,34,4.78],[2,32,2.54]],"ltp":34.0,"tv":62.98,"id":27706761}]}]}
{"op":"mcm","clk":"993204939","pt":1580538443468,"mc":[{"id":"1.168096552","rc":[{"batl":[[1,3.15,100],[2,3.2,22]],"ltp":2.98,"tv":2857.42,"id":18286408}]}]}
{"op":"mcm","clk":"993208344","pt":1580538534647,"mc":[{"id":"1.168096552","rc":[{"trd":[[2.98,44]],"batb":[[0,2.98,8.62]],"ltp":2.98,"tv":2861.42,"id":18286408},{"trd":[[2.94,357.54]],"batb":[[0,2.94,2]],"ltp":2.94,"tv":6469.33,"id":52106}],"tv":11557.41}]}
{"op":"mcm","clk":"993208415","pt":1580538536805,"mc":[{"id":"1.168096552","rc":[{"trd":[[2.84,202.9],[2.9,143.02],[2.92,939],[2.94,361.54]],"batb":[[0,2.84,28.9],[1,2.82,7.61],[2,2.76,6]],"ltp":2.84,"tv":6549.33,"id":52106}],"tv":11637.42}]}
{"op":"mcm","clk":"993208526","pt":1580538539787,"mc":[{"id":"1.168096552","rc":[{"batl":[[0,2.96,2.96],[1,2.98,4.49],[2,3.1,18.9]],"ltp":2.84,"tv":6549.33,"id":52106}]}]}
{"op":"mcm","clk":"993208772","pt":1580538547382,"mc":[{"id":"1.168096552","rc":[{"batb":[[0,2.86,4],[1,2.84,28.9],[2,2.82,7.61]],"ltp":2.84,"tv":6549.33,"id":52106}]}]}
{"op":"mcm","clk":"993208844","pt":1580538549492,"mc":[{"id":"1.168096552","rc":[{"trd":[[2.84,234.9],[2.86,218.56]],"batb":[[0,2.84,12.9],[1,2.82,7.61],[2,2.76,6]],"ltp":2.84,"tv":6589.33,"id":52106}],"tv":11677.42}]}
{"op":"mcm","clk":"993209299","pt":1580538561893,"mc":[{"id":"1.168096552","rc":[{"batb":[[0,2.86,4],[1,2.84,12.9],[2,2.82,7.61]],"ltp":2.84,"tv":6589.33,"id":52106}]}]}
{"op":"mcm","clk":"993209867","pt":1580538576117,"mc":[{"id":"1.168096552","rc":[{"batb":[[0,3,5.74],[1,2.98,8.62],[2,2.96,2]],"ltp":2.98,"tv":2861.42,"id":18286408}]}]}
{"op":"mcm","clk":"993217188","pt":1580538741314,"mc":[{"id":"1.168096552","rc":[{"batb":[[2,11.5,2]],"ltp":13.5,"tv":352.08,"id":26640937}]}]}
{"op":"mcm","clk":"993217302","pt":1580538743866,"mc":[{"id":"1.168096552","rc":[{"batl":[[0,2.94,2],[1,2.96,2.96],[2,2.98,4.49]],"ltp":2.84,"tv":6589.33,"id":52106}]}]}
{"op":"mcm","clk":"993225987","pt":1580538954643,"mc":[{"id":"1.168096552","rc":[{"batl":[[0,2.92,2],[1,2.94,2],[2,2.96,2.96]],"ltp":2.84,"tv":6589.33,"id":52106}]}]}
{"op":"mcm","clk":"993240327","pt":1580539067936,"mc":[{"id":"1.168096552","rc":[{"batb":[[2,11,2.06]],"ltp":13.5,"tv":352.08,"id":26640937}]}]}
{"op":"mcm","clk":"993240758","pt":1580539082280,"mc":[{"id":"1.168096552","rc":[{"trd":[[4.9,119.5]],"batb":[[0,4.7,21.12],[1,4.6,39.3],[2,4.5,27.25]],"batl":[[0,4.9,1.32],[1,5.1,12.65],[2,5.2,28.52]],"ltp":4.9,"tv":1742.06,"id":21580749}],"tv":11694.78}]}
{"op":"mcm","clk":"993241612","pt":1580539104499,"mc":[{"id":"1.168096552","rc":[{"trd":[[4.9,122.14],[5.1,91.04]],"batl":[[0,5.1,11.47],[1,5.2,28.52],[2,5.3,9]],"ltp":5.1,"tv":1747.06,"id":21580749}],"tv":11699.78}]}
{"op":"mcm","clk":"993245432","pt":1580539204486,"mc":[{"id":"1.168096552","rc":[{"batl":[[2,2.96,6.96]],"ltp":2.84,"tv":6589.33,"id":52106}]}]}
{"op":"mcm","clk":"993247661","pt":1580539257477,"mc":[{"id":"1.168096552","rc":[{"trd":[[3.05,487.73]],"batb":[[0,3.05,19.01],[1,3,5.74]],"batl":[[0,3.15,100],[1,3.2,22],[2,3.25,380]],"ltp":3.05,"tv":2865.42,"id":18286408}],"tv":11703.78}]}
{"op":"mcm","clk":"993247776","pt":1580539260376,"mc":[{"id":"1.168096552","rc":[{"batl":[[0,3.1,2],[1,3.15,100],[2,3.2,22]],"ltp":3.05,"tv":2865.42,"id":18286408}]}]}
{"op":"mcm","clk":"993248777","pt":1580539281485,"mc":[{"id":"1.168096552","rc":[{"batb":[[0,3,5.74],[1,2.96,2],[2,2.9,11.62]],"ltp":3.05,"tv":2865.42,"id":18286408}]}]}
{"op":"mcm","clk":"993248825","pt":1580539282467,"mc":[{"id":"1.168096552","rc":[{"trd":[[3.1,442.74]],"batb":[[0,3.1,17.01],[1,3,7.74],[2,2.96,2]],"batl":[[0,3.15,100],[1,3.2,22],[2,3.25,380]],"ltp":3.1,"tv":2869.42,"id":18286408}],"tv":11707.78}]}
{"op":"mcm","clk":"993248853","pt":1580539283088,"mc":[{"id":"1.168096552","rc":[{"trd":[[3.1,442.96]],"batb":[[0,3.1,16.9]],"ltp":3.1,"tv":2869.64,"id":18286408}],"tv":11708.0}]}
{"op":"mcm","clk":"993249033","pt":1580539286404,"mc":[{"id":"1.168096552","rc":[{"trd":[[3.1,443.18]],"batb":[[0,3.1,16.79]],"ltp":3.1,"tv":2869.86,"id":18286408}],"tv":11708.22}]}
{"op":"mcm","clk":"993249128","pt":1580539288487,"mc":[{"id":"1.168096552","rc":[{"trd":[[3.1,476.75]],"batb":[[0,3,25.09],[1,2.9,29.85],[2,2.88,39]],"ltp":3.1,"tv":2903.43,"id":18286408}],"tv":11741.79}]}
{"op":"mcm","clk":"993249182","pt":1580539289467,"mc":[{"id":"1.168096552","rc":[{"batb":[[0,3.1,2],[1,3,25.09],[2,2.9,29.85]],"batl":[[0,3.15,102]],"ltp":3.1,"tv":2903.43,"id":18286408}]}]}
{"op":"mcm","clk":"993249227","pt":1580539290398,"mc":[{"id":"1.168096552","rc":[{"batb":[[2,2.9,15.98]],"ltp":3.1,"tv":2903.43,"id":18286408}]}]}
{"op":"mcm","clk":"993249768","pt":1580539303381,"mc":[{"id":"1.168096552","rc":[{"batl":[[1,2.96,6.96],[2,2.98,4.49]],"ltp":2.84,"tv":6589.33,"id":52106}]}]}
{"op":"mcm","clk":"993250249","pt":1580539315802,"mc":[{"id":"1.168096552","rc":[{"batb":[[2,2.9,11.62]],"ltp":3.1,"tv":2903.43,"id":18286408},{"trd":[[2.86,226.55]],"batb":[[0,2.84,12.9],[1,2.82,7.61],[2,2.76,6]],"batl":[[0,2.86,8.67],[1,2.92,2],[2,2.96,6.96]],"ltp":2.86,"tv":6597.33,"id":52106}],"tv":11749.79}]}
{"op":"mcm","clk":"993250294","pt":1580539317289,"mc":[{"id":"1.168096552","rc":[{"batl":[[1,3.2,43]],"ltp":3.1,"tv":2903.43,"id":18286408}]}]}
{"op":"mcm","clk":"993250797","pt":1580539328305,"mc":[{"id":"1.168096552","rc":[{"batb":[[0,4.8,33.82],[1,4.7,21.12],[2,4.6,39.3]],"ltp":5.1,"tv":1747.06,"id":21580749},{"batb":[[0,18.5,20.62],[1,18,19.59],[2,17.5,4.64]],"ltp":20.0,"tv":86.89,"id":24608298}]}]}
{"op":"mcm","clk":"993251365","pt":1580539339830,"mc":[{"id":"1.168096552","rc":[{"batb":[[2,2.9,21.77]],"ltp":3.1,"tv":2903.43,"id":18286408},{"trd":[[2.84,252.25]],"batb":[[0,2.84,4.22]],"batl":[[0,2.92,2],[1,2.96,6.96],[2,2.98,4.49]],"ltp":2.84,"tv":6614.68,"id":52106}],"tv":11767.14}]}
{"op":"mcm","clk":"993251548","pt":1580539343448,"mc":[{"id":"1.168096552","rc":[{"batb":[[0,4.7,21.12],[1,4.6,39.3],[2,4.5,27.25]],"ltp":5.1,"tv":1747.06,"id":21580749},{"batb":[[0,18,20.5],[1,17.5,4.64],[2,14,2.86]],"ltp":20.0,"tv":86.89,"id":24608298}]}]}
{"op":"mcm","clk":"993251559","pt":1580539343708,"mc":[{"id":"1.168096552","rc":[{"batb":[[1,4.6,42.36]],"ltp":5.1,"tv":1747.06,"id":21580749}]}]}
{"op":"mcm","clk":"993251820","pt":1580539349157,"mc":[{"id":"1.168096552","rc":[{"batb":[[0,13.5,9.75]],"ltp":13.5,"tv":352.08,"id":26640937},{"batb":[[1,34,7.78]],"ltp":34.0,"tv":62.98,"id":27706761},{"batb":[[0,18,24.17]],"ltp":20.0,"tv":86.89,"id":24608298}]}]}
{"op":"mcm","clk":"993252045","pt":1580539353225,"mc":[{"id":"1.168096552","rc":[{"batl":[[1,2.96,2.96]],"ltp":2.84,"tv":6614.68,"id":52106}]}]}
{"op":"mcm","clk":"993252262","pt":1580539357340,"mc":[{"id":"1.168096552","rc":[{"batb":[[1,4.6,39.3]],"ltp":5.1,"tv":1747.06,"id":21580749}]}]}
{"op":"mcm","clk":"993257449","pt":1580539475264,"mc":[{"id":"1.168096552","rc":[{"batb":[[0,4.8,3.59],[1,4.7,21.12],[2,4.6,39.3]],"ltp":5.1,"tv":1747.06,"id":21580749}]}]}
{"op":"mcm","clk":"993258708","pt":1580539504912,"mc":[{"id":"1.168096552","rc":[{"batb":[[0,14,2.09],[1,13.5,8.89],[2,12.5,1.87]],"ltp":13.5,"tv":352.08,"id":26640937}]}]}
{"op":"mcm","clk":"993258983","pt":1580539510324,"mc":[{"id":"1.168096552","rc":[{"batl":[[0,2.96,2.96],[1,2.98,4.49],[2,3.1,18.9]],"ltp":2.84,"tv":6614.68,"id":52106}]}]}
{"op":"mcm","clk":"993262484","pt":1580539588396,"mc":[{"id":"1.168096552","rc":[{"batl":[[0,3.15,104]],"ltp":3.1,"tv":2903.43,"id":18286408}]}]}
{"op":"mcm","clk":"993262512","pt":1580539588555,"mc":[{"id":"1.168096552","rc":[{"batl":[[0,5,2],[1,5.1,11.47],[2,5.2,28.52]],"ltp":5.1,"tv":1747.06,"id":21580749}]}]}
{"op":"mcm","clk":"993263158","pt":1580539598291,"mc":[{"id":"1.168096552","rc":[{"batb":[[0,4.8,5.59]],"ltp":5.1,"tv":1747.06,"id":21580749}]}]}
{"op":"mcm","clk":"993264663","pt":1580539623698,"mc":[{"id":"1.168096552","rc":[{"batb":[[2,2.8,2]],"ltp":2.84,"tv":6614.68,"id":52106}]}]}
{"op":"mcm","clk":"993267264","pt":1580539675072,"mc":[{"id":"1.168096552","rc":[{"batl":[[0,2.94,2],[1,2.96,2.96],[2,2.98,4.49]],"ltp":2.84,"tv":6614.68,"id":52106}]}]}
{"op":"mcm","clk":"993267905","pt":1580539687487,"mc":[{"id":"1.168096552","rc":[{"trd":[[2.84,260.69]],"batb":[[0,2.82,7.61],[1,2.8,2],[2,2.76,6]],"batl":[[0,2.94,2.27],[2,3.1,18.9]],"ltp":2.84,"tv":6623.12,"id":52106}],"tv":11775.58}]}
{"op":"mcm","clk":"993268184","pt":1580539692997,"mc":[{"id":"1.168096552","rc":[{"batl":[[1,3.05,6.87]],"ltp":2.84,"tv":6623.12,"id":52106}]}]}
{"op":"mcm","clk":"993268418","pt":1580539697924,"mc":[{"id":"1.168096552","rc":[{"batl":[[0,44,1.88],[1,50,3.83]],"ltp":34.0,"tv":62.98,"id":27706761}]}]}
{"op":"mcm","clk":"993268491","pt":1580539699322,"mc":[{"id":"1.168096552","rc":[{"trd":[[2.82,752.68]],"batb":[[0,2.82,7.34]],"batl":[[0,2.94,2]],"ltp":2.82,"tv":6623.66,"id":52106}],"tv":11776.12}]}
{"op":"mcm","clk":"993269830","pt":1580539728433,"mc":[{"id":"1.168096552","rc":[{"batl":[[1,3.05,2.87]],"ltp":2.82,"tv":6623.66,"id":52106}]}]}
{"op":"mcm","clk":"993269899","pt":1580539730343,"mc":[{"id":"1.168096552","rc":[{"batl":[[1,5.1,13.47]],"ltp":5.1,"tv":1747.06,"id":21580749}]}]}
{"op":"mcm","clk":"993270320","pt":1580539742248,"mc":[{"id":"1.168096552","rc":[{"trd":[[44,4.3]],"batl":[[0,50,3.84],[1,85,1.35],[2,170,2]],"ltp":44.0,"tv":66.72,"id":27706761}],"tv":11779.86}]}
{"op":"mcm","clk":"993270395","pt":1580539743445,"mc":[{"id":"1.168096552","rc":[{"trd":[[13.5,10.24],[14,6.62]],"batb":[[0,13.5,7.61],[1,12.5,1.87],[2,11,2.06]],"ltp":13.5,"tv":358.8,"id":26640937}],"tv":11786.58}]}
{"op":"mcm","clk":"993270860","pt":1580539753376,"mc":[{"id":"1.168096552","rc":[{"trd":[[3.1,480.75]],"batb":[[0,3,25.09],[1,2.9,21.77],[2,2.88,39]],"ltp":3.1,"tv":2907.43,"id":18286408}],"tv":11790.58}]}
{"op":"mcm","clk":"993271004","pt":1580539756512,"mc":[{"id":"1.168096552","rc":[{"batl":[[1,20,2.5]],"ltp":13.5,"tv":358.8,"id":26640937},{"batb":[[0,36,1.48]],"batl":[[0,48,1.18],[1,50,3],[2,85,1.35]],"ltp":44.0,"tv":66.72,"id":27706761}]}]}
{"op":"mcm","clk":"993271145","pt":1580539759087,"mc":[{"id":"1.168096552","rc":[{"trd":[[4.8,99.65]],"batb":[[0,4.8,3.59]],"ltp":4.8,"tv":1751.06,"id":21580749}],"tv":11794.58}]}
{"op":"mcm","clk":"993271256","pt":1580539761508,"mc":[{"id":"1.168096552","rc":[{"batl":[[0,3.1,10.51],[1,3.15,104],[2,3.2,43]],"ltp":3.1,"tv":2907.43,"id":18286408}]}]}
{"op":"mcm","clk":"993271329","pt":1580539763085,"mc":[{"id":"1.168096552","rc":[{"batl":[[1,19,1.68],[2,21,2.32]],"ltp":13.5,"tv":358.8,"id":26640937}]}]}
{"op":"mcm","clk":"993271374","pt":1580539764111,"mc":[{"id":"1.168096552","rc":[{"batl":[[0,3.1,2]],"ltp":3.1,"tv":2907.43,"id":18286408}]}]}
{"op":"mcm","clk":"993271465","pt":1580539765091,"mc":[{"id":"1.168096552","rc":[{"batl":[[0,3.1,10.51]],"ltp":3.1,"tv":2907.43,"id":18286408}]}]}
{"op":"mcm","clk":"993271652","pt":1580539768499,"mc":[{"id":"1.168096552","rc":[{"batl":[[0,3.1,2]],"ltp":3.1,"tv":2907.43,"id":18286408}]}]}
{"op":"mcm","clk":"993271775","pt":1580539771386,"mc":[{"id":"1.168096552","rc":[{"batl":[[0,3.05,2],[1,3.1,2],[2,3.15,102]],"ltp":3.1,"tv":2907.43,"id":18286408}]}]}
{"op":"mcm","clk":"993271906","pt":1580539774932,"mc":[{"id":"1.168096552","rc":[{"batb":[[0,2.84,7.11],[1,2.82,7.34],[2,2.8,2]],"ltp":2.82,"tv":6623.66,"id":52106}]}]}
{"op":"mcm","clk":"993271975","pt":1580539776428,"mc":[{"id":"1.168096552","rc":[{"trd":[[3.05,491.73]],"batb":[[0,3.05,4.61],[1,3,25.09],[2,2.9,21.77]],"batl":[[0,3.1,2],[1,3.15,102],[2,3.2,43]],"ltp":3.05,"tv":2911.43,"id":18286408},{"batb":[[0,14,2.52],[1,13.5,7.61],[2,12.5,1.87]],"ltp":13.5,"tv":358.8,"id":26640937},{"batb":[[0,4.9,4.12],[1,4.8,3.59],[2,4.7,21.12]],"batl":[[0,5,10.37]],"ltp":4.8,"tv":1751.06,"id":21580749},{"batb":[[0,18.5,1.99],[1,18,23.26],[2,17.5,4.64]],"ltp":20.0,"tv":86.89,"id":24608298}],"tv":11798.58}]}
{"op":"mcm","clk":"993272097","pt":1580539779110,"mc":[{"id":"1.168096552","rc":[{"trd":[[3.05,495.73]],"batb":[[0,3.05,2.61]],"ltp":3.05,"tv":2915.43,"id":18286408}],"tv":11802.58}]}
{"op":"mcm","clk":"993272455","pt":1580539787324,"mc":[{"id":"1.168096552","rc":[{"trd":[[3.05,499.73]],"batb":[[0,3,25.7],[1,2.9,21.77],[2,2.88,39]],"ltp":3.05,"tv":2919.43,"id":18286408}],"tv":11806.58}]}
{"op":"mcm","clk":"993272805","pt":1580539793839,"mc":[{"id":"1.168096552","rc":[{"batb":[[0,34,8.69],[1,32,2.54],[2,30,2]],"ltp":44.0,"tv":66.72,"id":27706761}]}]}
{"op":"mcm","clk":"993273266","pt":1580539803348,"mc":[{"id":"1.168096552","rc":[{"trd":[[3.05,500.95]],"batb":[[0,3,25.09]],"batl":[[0,3.05,1.39],[1,3.1,2],[2,3.15,102]],"ltp":3.05,"tv":2920.66,"id":18286408}],"tv":11807.81}]}
{"op":"mcm","clk":"993273323","pt":1580539804746,"mc":[{"id":"1.168096552","rc":[{"batl":[[1,3.1,10.47]],"ltp":3.05,"tv":2920.66,"id":18286408}]}]}
{"op":"mcm","clk":"993273400","pt":1580539806251,"mc":[{"id":"1.168096552","rc":[{"batl":[[1,3.1,2]],"ltp":3.05,"tv":2920.66,"id":18286408}]}]}
{"op":"mcm","clk":"993273621","pt":1580539811142,"mc":[{"id":"1.168096552","rc":[{"batb":[[0,2.84,18.01]],"ltp":2.82,"tv":6623.66,"id":52106}]}]}
{"op":"mcm","clk":"993274304","pt":1580539828001,"mc":[{"id":"1.168096552","rc":[{"batl":[[1,3.1,10.47]],"ltp":3.05,"tv":2920.66,"id":18286408}]}]}
{"op":"mcm","clk":"993274397","pt":1580539830173,"mc":[{"id":"1.168096552","rc":[{"batl":[[1,3.1,2]],"ltp":3.05,"tv":2920.66,"id":18286408}]}]}
{"op":"mcm","clk":"993275272","pt":1580539849122,"mc":[{"id":"1.168096552","rc":[{"batl":[[1,3.1,10.47]],"ltp":3.05,"tv":2920.66,"id":18286408}]}]}
{"op":"mcm","clk":"993275330","pt":1580539850409,"mc":[{"id":"1.168096552","rc":[{"batl":[[1,3.1,2]],"ltp":3.05,"tv":2920.66,"id":18286408}]}]}
{"op":"mcm","clk":"993275446","pt":1580539853242,"mc":[{"id":"1.168096552","rc":[{"batl":[[1,5.1,11.47]],"ltp":4.8,"tv":1751.06,"id":21580749}]}]}
{"op":"mcm","clk":"993276933","pt":1580539890302,"mc":[{"id":"1.168096552","rc":[{"batl":[[1,3.1,10.47]],"ltp":3.05,"tv":2920.66,"id":18286408}]}]}
{"op":"mcm","clk":"993277044","pt":1580539892565,"mc":[{"id":"1.168096552","rc":[{"batl":[[1,3.1,2]],"ltp":3.05,"tv":2920.66,"id":18286408}]}]}
{"op":"mcm","clk":"993277138","pt":1580539894470,"mc":[{"id":"1.168096552","rc":[{"batb":[[1,2.9,16.77]],"batl":[[1,3.1,10.47]],"ltp":3.05,"tv":2920.66,"id":18286408}]}]}
{"op":"mcm","clk":"993277180","pt":1580539895396,"mc":[{"id":"1.168096552","rc":[{"batb":[[1,2.92,5.75],[2,2.9,16.02]],"batl":[[1,3.1,2]],"ltp":3.05,"tv":2920.66,"id":18286408}]}]}
{"op":"mcm","clk":"993277466","pt":1580539902103,"mc":[{"id":"1.168096552","rc":[{"batb":[[1,2.94,5.75]],"ltp":3.05,"tv":2920.66,"id":18286408}]}]}
{"op":"mcm","clk":"993279240","pt":1580539939782,"mc":[{"id":"1.168096552","rc":[{"batl":[[1,3.1,10.47]],"ltp":3.05,"tv":2920.66,"id":18286408}]}]}
{"op":"mcm","clk":"993279298","pt":1580539941176,"mc":[{"id":"1.168096552","rc":[{"batl":[[1,3.1,2]],"ltp":3.05,"tv":2920.66,"id":18286408}]}]}
{"op":"mcm","clk":"993289670","pt":1580539953114,"mc":[{"id":"1.168096552","rc":[{"batl":[[1,3.1,10.47]],"ltp":3.05,"tv":2920.66,"id":18286408}]}]}
{"op":"mcm","clk":"993289775","pt":1580539956007,"mc":[{"id":"1.168096552","rc":[{"batl":[[1,3.1,2]],"ltp":3.05,"tv":2920.66,"id":18286408}]}]}
{"op":"mcm","clk":"993291158","pt":1580539984126,"mc":[{"id":"1.168096552","rc":[{"batl":[[1,3.1,10.47]],"ltp":3.05,"tv":2920.66,"id":18286408}]}]}
{"op":"mcm","clk":"993291290","pt":1580539986240,"mc":[{"id":"1.168096552","rc":[{"batl":[[1,3.1,2]],"ltp":3.05,"tv":2920.66,"id":18286408}]}]}
{"op":"mcm","clk":"993291564","pt":1580539991394,"mc":[{"id":"1.168096552","rc":[{"batl":[[2,21,1.5]],"ltp":13.5,"tv":358.8,"id":26640937},{"batb":[[0,34,8.25]],"batl":[[0,50,3.84],[1,85,1.35],[2,170,2]],"ltp":44.0,"tv":66.72,"id":27706761}]}]}
{"op":"mcm","clk":"993291709","pt":1580539994280,"mc":[{"id":"1.168096552","rc":[{"batl":[[2,3.15,100]],"ltp":3.05,"tv":2920.66,"id":18286408},{"batl":[[0,5,8.37]],"ltp":4.8,"tv":1751.06,"id":21580749}]}]}
{"op":"mcm","clk":"993292529","pt":1580540008409,"mc":[{"id":"1.168096552","rc":[{"batb":[[0,36,1.04],[1,34,7.78],[2,32,2.54]],"ltp":44.0,"tv":66.72,"id":27706761}]}]}
{"op":"mcm","clk":"993292683","pt":1580540011512,"mc":[{"id":"1.168096552","rc":[{"trd":[[4.9,130.38]],"batb":[[0,4.8,3.59],[1,4.7,21.12],[2,4.6,39.3]],"batl":[[0,4.9,15.88],[1,5,8.37],[2,5.1,11.47]],"ltp":4.9,"tv":1759.29,"id":21580749}],"tv":11816.04}]}
{"op":"mcm","clk":"993292711","pt":1580540012086,"mc":[{"id":"1.168096552","rc":[{"batl":[[2,240,9]],"ltp":44.0,"tv":66.72,"id":27706761}]}]}
{"op":"mcm","clk":"993293192","pt":1580540021918,"mc":[{"id":"1.168096552","rc":[{"batl":[[0,5,24.25],[1,5.1,11.47],[2,5.2,28.52]],"ltp":4.9,"tv":1759.29,"id":21580749}]}]}
{"op":"mcm","clk":"993295064","pt":1580540059379,"mc":[{"id":"1.168096552","rc":[{"batl":[[2,20,8]],"ltp":13.5,"tv":358.8,"id":26640937}]}]}
{"op":"mcm","clk":"993296119","pt":1580540082236,"mc":[{"id":"1.168096552","rc":[{"batl":[[2,20,10]],"ltp":13.5,"tv":358.8,"id":26640937}]}]}
{"op":"mcm","clk":"993296273","pt":1580540085118,"mc":[{"id":"1.168096552","rc":[{"batl":[[2,20,11]],"ltp":13.5,"tv":358.8,"id":26640937}]}]}
{"op":"mcm","clk":"993296610","pt":1580540092039,"mc":[{"id":"1.168096552","rc":[{"batl":[[1,17.5,1],[2,19,1.68]],"ltp":13.5,"tv":358.8,"id":26640937}]}]}
{"op":"mcm","clk":"993296818","pt":1580540096457,"mc":[{"id":"1.168096552","rc":[{"trd":[[4.8,110.19]],"batb":[[0,4.7,21.12],[1,4.6,39.3],[2,4.5,27.25]],"batl":[[0,4.8,4.73],[1,5,15.88],[2,5.1,11.47]],"ltp":4.8,"tv":1769.83,"id":21580749}],"tv":11826.58}]}
{"op":"mcm","clk":"993297130","pt":1580540102349,"mc":[{"id":"1.168096552","rc":[{"batl":[[1,16.5,1]],"ltp":13.5,"tv":358.8,"id":26640937}]}]}
{"op":"mcm","clk":"993297388","pt":1580540107162,"mc":[{"id":"1.168096552","rc":[{"batl":[[1,15.5,1]],"ltp":13.5,"tv":358.8,"id":26640937}]}]}
{"op":"mcm","clk":"993297491","pt":1580540109486,"mc":[{"id":"1.168096552","rc":[{"batb":[[0,18.5,21.7]],"ltp":20.0,"tv":86.89,"id":24608298}]}]}
{"op":"mcm","clk":"993297675","pt":1580540113307,"mc":[{"id":"1.168096552","rc":[{"batl":[[0,14.5,1],[1,15,1]],"ltp":13.5,"tv":358.8,"id":26640937}]}]}
{"op":"mcm","clk":"993297773","pt":1580540115429,"mc":[{"id":"1.168096552","rc":[{"batl":[[2,20,8]],"ltp":13.5,"tv":358.8,"id":26640937}]}]}
{"op":"mcm","clk":"993298102","pt":1580540121434,"mc":[{"id":"1.168096552","rc":[{"trd":[[14,8.62]],"batb":[[0,14,1.52]],"batl":[[0,15,1],[1,20,8],[2,21,1.5]],"ltp":14.0,"tv":360.8,"id":26640937}],"tv":11828.58}]}
{"op":"mcm","clk":"993298312","pt":1580540125402,"mc":[{"id":"1.168096552","rc":[{"batb":[[0,18.5,1.99]],"ltp":20.0,"tv":86.89,"id":24608298}]}]}
{"op":"mcm","clk":"993298879","pt":1580540135344,"mc":[{"id":"1.168096552","rc":[{"trd":[[3.05,503.73]],"batb":[[0,3.05,10.31],[1,3,25.09],[2,2.94,5.75]],"batl":[[0,3.1,2],[1,3.15,100],[2,3.2,43]],"ltp":3.05,"tv":2923.43,"id":18286408},{"trd":[[15,2]],"batb":[[0,14.5,2.99],[1,14,7.23],[2,13.5,7.61]],"batl":[[0,20,8],[1,21,1.5],[2,32,17.17]],"ltp":15.0,"tv":362.8,"id":26640937},{"trd":[[4.8,119.65]],"batb":[[0,4.8,1.63],[1,4.7,21.12],[2,4.6,39.3]],"batl":[[0,5,15.88],[1,5.1,11.47],[2,5.2,28.52]],"ltp":4.8,"tv":1779.29,"id":21580749},{"trd":[[2.94,365.54]],"batb":[[0,2.86,10.13],[1,2.84,18.01],[2,2.82,7.34]],"batl":[[0,3.05,13.18],[1,3.1,18.9],[2,3.15,12]],"ltp":2.94,"tv":6627.66,"id":52106},{"trd":[[21,32.53]],"batl":[[0,21,14.06]],"ltp":21.0,"tv":91.55,"id":24608298}],"tv":11851.48}]}
{"op":"mcm","clk":"993298904","pt":1580540135962,"mc":[{"id":"1.168096552","rc":[{"batl":[[0,20,8.19]],"ltp":15.0,"tv":362.8,"id":26640937}]}]}
{"op":"mcm","clk":"993298969","pt":1580540137253,"mc":[{"id":"1.168096552","rc":[{"trd":[[3.05,507.73]],"batb":[[0,3.05,8.31]],"ltp":3.05,"tv":2927.43,"id":18286408}],"tv":11855.47}]}
{"op":"mcm","clk":"993299125","pt":1580540140235,"mc":[{"id":"1.168096552","rc":[{"batb":[[0,18.5,2.85]],"ltp":21.0,"tv":91.55,"id":24608298}]}]}
{"op":"mcm","clk":"993299243","pt":1580540142458,"mc":[{"id":"1.168096552","rc":[{"batb":[[0,2.86,12.13]],"ltp":2.94,"tv":6627.66,"id":52106}]}]}
{"op":"mcm","clk":"993299518","pt":1580540147758,"mc":[{"id":"1.168096552","rc":[{"batl":[[0,19.5,1.87],[1,20,8],[2,21,1.5]],"ltp":15.0,"tv":362.8,"id":26640937},{"batb":[[0,2.88,7.54],[1,2.86,12.13],[2,2.84,18.01]],"batl":[[0,3,7.23],[1,3.05,13.18],[2,3.1,18.9]],"ltp":2.94,"tv":6627.66,"id":52106}]}]}
{"op":"mcm","clk":"993299823","pt":1580540153470,"mc":[{"id":"1.168096552","rc":[{"batl":[[0,19.5,1.68]],"ltp":15.0,"tv":362.8,"id":26640937}]}]}
{"op":"mcm","clk":"993299871","pt":1580540154403,"mc":[{"id":"1.168096552","rc":[{"trd":[[3.05,511.73]],"batb":[[0,3.05,6.31]],"ltp":3.05,"tv":2931.43,"id":18286408},{"batl":[[0,19.5,1.87]],"ltp":15.0,"tv":362.8,"id":26640937}],"tv":11859.47}]}
{"op":"mcm","clk":"993300318","pt":1580540163286,"mc":[{"id":"1.168096552","rc":[{"trd":[[3.05,515.73]],"batb":[[0,3.05,4.31]],"ltp":3.05,"tv":2935.43,"id":18286408}],"tv":11863.47}]}
{"op":"mcm","clk":"993300421","pt":1580540165505,"mc":[{"id":"1.168096552","rc":[{"batl":[[0,2.98,2.94],[1,3,7.23]],"ltp":2.94,"tv":6627.66,"id":52106}]}]}
{"op":"mcm","clk":"993301141","pt":1580540179309,"mc":[{"id":"1.168096552","rc":[{"trd":[[3.05,519.73]],"batb":[[0,3.05,2.31]],"ltp":3.05,"tv":2939.43,"id":18286408}],"tv":11867.47}]}
{"op":"mcm","clk":"993301594","pt":1580540187425,"mc":[{"id":"1.168096552","rc":[{"trd":[[3.05,523.73]],"batb":[[0,3,25.4],[1,2.94,5.75],[2,2.9,16.02]],"ltp":3.05,"tv":2943.43,"id":18286408}],"tv":11871.47}]}
{"op":"mcm","clk":"993301649","pt":1580540188459,"mc":[{"id":"1.168096552","rc":[{"trd":[[3.05,524.35]],"batb":[[0,3,25.09]],"ltp":3.05,"tv":2944.05,"id":18286408}],"tv":11872.09}]}
{"op":"mcm","clk":"993302236","pt":1580540199455,"mc":[{"id":"1.168096552","rc":[{"trd":[[4.7,322.91],[4.8,122.91]],"batb":[[0,4.7,12.75],[1,4.6,39.3],[2,4.5,27.25]],"ltp":4.7,"tv":1799.3,"id":21580749}],"tv":11892.1}]}
{"op":"mcm","clk":"993302379","pt":1580540202395,"mc":[{"id":"1.168096552","rc":[{"batb":[[0,2.9,5],[1,2.88,7.54],[2,2.86,12.13]],"ltp":2.94,"tv":6627.66,"id":52106}]}]}
{"op":"mcm","clk":"993303283","pt":1580540219291,"mc":[{"id":"1.168096552","rc":[{"trd":[[3,561.41]],"batb":[[0,3,15.09]],"ltp":3.0,"tv":2964.05,"id":18286408}],"tv":11912.1}]}
{"op":"mcm","clk":"993303573","pt":1580540224032,"mc":[{"id":"1.168096552","rc":[{"trd":[[3.1,484.75],[3.15,764.02]],"batl":[[0,3.15,97.2],[1,3.2,43],[2,3.25,380]],"ltp":3.15,"tv":2973.65,"id":18286408}],"tv":11921.7}]}
{"op":"mcm","clk":"993303622","pt":1580540225011,"mc":[{"id":"1.168096552","rc":[{"batl":[[0,3.1,2],[1,3.15,97.2],[2,3.2,43]],"ltp":3.15,"tv":2973.65,"id":18286408}]}]}
{"op":"mcm","clk":"993303874","pt":1580540229331,"mc":[{"id":"1.168096552","rc":[{"batb":[[1,2.98,2],[2,2.94,5.75]],"batl":[[0,3.05,2],[1,3.1,2],[2,3.15,97.2]],"ltp":3.15,"tv":2973.65,"id":18286408}]}]}
{"op":"mcm","clk":"993303990","pt":1580540231439,"mc":[{"id":"1.168096552","rc":[{"batb":[[0,3,18.09]],"ltp":3.15,"tv":2973.65,"id":18286408}]}]}
{"op":"mcm","clk":"993304119","pt":1580540233814,"mc":[{"id":"1.168096552","rc":[{"trd":[[3.05,528.35]],"batb":[[0,3.05,12.84],[1,3,3],[2,2.98,2]],"batl":[[0,3.1,2],[1,3.15,97.2],[2,3.2,43]],"ltp":3.05,"tv":2977.65,"id":18286408}],"tv":11925.7}]}
{"op":"mcm","clk":"993304298","pt":1580540237016,"mc":[{"id":"1.168096552","rc":[{"trd":[[3.05,532.35]],"batb":[[0,3.05,10.84]],"ltp":3.05,"tv":2981.65,"id":18286408}],"tv":11929.7}]}
{"op":"mcm","clk":"993304426","pt":1580540239336,"mc":[{"id":"1.168096552","rc":[{"batb":[[1,2.98,2],[2,2.94,5.75]],"ltp":3.05,"tv":2981.65,"id":18286408}]}]}
{"op":"mcm","clk":"993305193","pt":1580540255176,"mc":[{"id":"1.168096552","rc":[{"batb":[[0,4.8,6.5],[1,4.7,12.75],[2,4.6,39.3]],"ltp":4.7,"tv":1799.3,"id":21580749}]}]}
{"op":"mcm","clk":"993305324","pt":1580540258269,"mc":[{"id":"1.168096552","rc":[{"batl":[[0,4.9,2],[1,5,15.88],[2,5.1,11.47]],"ltp":4.7,"tv":1799.3,"id":21580749}]}]}
{"op":"mcm","clk":"993305564","pt":1580540263511,"mc":[{"id":"1.168096552","rc":[{"trd":[[3.05,536.35]],"batb":[[0,3.05,8.84]],"ltp":3.05,"tv":2985.65,"id":18286408}],"tv":11933.7}]}
{"op":"mcm","clk":"993305935","pt":1580540271437,"mc":[{"id":"1.168096552","rc":[{"trd":[[3.05,540.35]],"batb":[[0,3.05,6.84]],"ltp":3.05,"tv":2989.65,"id":18286408}],"tv":11937.7}]}
{"op":"mcm","clk":"993306294","pt":1580540279519,"mc":[{"id":"1.168096552","rc":[{"trd":[[3.05,544.35]],"batb":[[0,3.05,4.84]],"ltp":3.05,"tv":2993.65,"id":18286408}],"tv":11941.7}]}
{"op":"mcm","clk":"993307301","pt":1580540304279,"mc":[{"id":"1.168096552","rc":[{"trd":[[3.05,548.35]],"batb":[[0,3.05,2.84]],"ltp":3.05,"tv":2997.65,"id":18286408}],"tv":11945.7}]}
{"op":"mcm","clk":"993308212","pt":1580540326013,"mc":[{"id":"1.168096552","rc":[{"batl":[[0,3.1,6]],"ltp":3.05,"tv":2997.65,"id":18286408}]}]}
{"op":"mcm","clk":"993308340","pt":1580540329495,"mc":[{"id":"1.168096552","rc":[{"trd":[[3.05,554.03]],"batb":[[0,2.98,2],[1,2.94,5.75],[2,2.9,5.87]],"ltp":3.05,"tv":3003.33,"id":18286408}],"tv":11951.38}]}
{"op":"mcm","clk":"993308443","pt":1580540332518,"mc":[{"id":"1.168096552","rc":[{"batl":[[0,3.1,20]],"ltp":3.05,"tv":3003.33,"id":18286408}]}]}
{"op":"mcm","clk":"993308564","pt":1580540335496,"mc":[{"id":"1.168096552","rc":[{"batl":[[0,3.05,2],[1,3.1,20],[2,3.15,97.2]],"ltp":3.05,"tv":3003.33,"id":18286408}]}]}
{"op":"mcm","clk":"993308642","pt":1580540337091,"mc":[{"id":"1.168096552","rc":[{"batl":[[0,3.05,4]],"ltp":3.05,"tv":3003.33,"id":18286408}]}]}
{"op":"mcm","clk":"993308984","pt":1580540344322,"mc":[{"id":"1.168096552","rc":[{"batb":[[0,2.92,5.9],[1,2.9,5],[2,2.88,7.54]],"ltp":2.94,"tv":6627.66,"id":52106}]}]}
{"op":"mcm","clk":"993309505","pt":1580540355349,"mc":[{"id":"1.168096552","rc":[{"batl":[[1,3.1,16]],"ltp":3.05,"tv":3003.33,"id":18286408}]}]}
{"op":"mcm","clk":"993310022","pt":1580540365278,"mc":[{"id":"1.168096552","rc":[{"batl":[[0,3,2],[1,3.05,4],[2,3.1,16]],"ltp":3.05,"tv":3003.33,"id":18286408}]}]}
{"op":"mcm","clk":"993310144","pt":1580540368255,"mc":[{"id":"1.168096552","rc":[{"batl":[[2,3.1,2]],"ltp":3.05,"tv":3003.33,"id":18286408}]}]}
{"op":"mcm","clk":"993310207","pt":1580540369487,"mc":[{"id":"1.168096552","rc":[{"batl":[[2,3.1,18.94]],"ltp":3.05,"tv":3003.33,"id":18286408},{"batb":[[2,2.86,12.13]],"batl":[[1,3.1,18.9],[2,3.15,12]],"ltp":2.94,"tv":6627.66,"id":52106}]}]}
{"op":"mcm","clk":"993310639","pt":1580540378384,"mc":[{"id":"1.168096552","rc":[{"batl":[[1,3.05,4],[2,3.1,18.9]],"ltp":2.94,"tv":6627.66,"id":52106},{"batb":[[0,18.5,1.99]],"ltp":21.0,"tv":91.55,"id":24608298}]}]}
{"op":"mcm","clk":"993310668","pt":1580540378898,"mc":[{"id":"1.168096552","rc":[{"batl":[[0,3,10.44],[1,3.05,6.87]],"ltp":2.94,"tv":6627.66,"id":52106}]}]}
{"op":"mcm","clk":"993311101","pt":1580540388210,"mc":[{"id":"1.168096552","rc":[{"trd":[[2.98,48]],"batb":[[0,2.94,5.75],[1,2.9,5.87],[2,2.88,39]],"batl":[[1,3.05,2]],"ltp":2.98,"tv":3007.33,"id":18286408}],"tv":11955.38}]}
{"op":"mcm","clk":"993311143","pt":1580540389287,"mc":[{"id":"1.168096552","rc":[{"batb":[[0,2.96,8.66],[1,2.94,5.75],[2,2.9,5.87]],"batl":[[2,3.1,2]],"ltp":2.98,"tv":3007.33,"id":18286408}]}]}
{"op":"mcm","clk":"993311932","pt":1580540402413,"mc":[{"id":"1.168096552","rc":[{"batl":[[1,3.05,2.87]],"ltp":2.94,"tv":6627.66,"id":52106}]}]}
{"op":"mcm","clk":"993313079","pt":1580540413443,"mc":[{"id":"1.168096552","rc":[{"batl":[[0,2.98,2],[1,3,2],[2,3.05,2]],"ltp":2.98,"tv":3007.33,"id":18286408}]}]}
{"op":"mcm","clk":"993313139","pt":1580540414462,"mc":[{"id":"1.168096552","rc":[{"trd":[[2.98,52],[3,565.41]],"batl":[[0,3.05,2],[1,3.1,2],[2,3.15,97.2]],"ltp":3.0,"tv":3015.33,"id":18286408}],"tv":11963.38}]}
{"op":"mcm","clk":"993313191","pt":1580540415468,"mc":[{"id":"1.168096552","rc":[{"batb":[[0,2.96,10.66]],"ltp":3.0,"tv":3015.33,"id":18286408}]}]}
{"op":"mcm","clk":"993313382","pt":1580540419032,"mc":[{"id":"1.168096552","rc":[{"batl":[[1,3.1,6]],"ltp":3.0,"tv":3015.33,"id":18286408}]}]}
{"op":"mcm","clk":"993313459","pt":1580540420472,"mc":[{"id":"1.168096552","rc":[{"batl":[[1,3.1,14.47]],"ltp":3.0,"tv":3015.33,"id":18286408}]}]}
{"op":"mcm","clk":"993313503","pt":1580540421247,"mc":[{"id":"1.168096552","rc":[{"batl":[[1,3.1,6]],"ltp":3.0,"tv":3015.33,"id":18286408}]}]}
{"op":"mcm","clk":"993313984","pt":1580540430265,"mc":[{"id":"1.168096552","rc":[{"batl":[[0,3.05,4]],"ltp":3.0,"tv":3015.33,"id":18286408}]}]}
{"op":"mcm","clk":"993314678","pt":1580540442215,"mc":[{"id":"1.168096552","rc":[{"batl":[[1,3.1,2]],"ltp":3.0,"tv":3015.33,"id":18286408}]}]}
{"op":"mcm","clk":"993316197","pt":1580540470460,"mc":[{"id":"1.168096552","rc":[{"batl":[[1,3.1,15.13],[2,3.15,157.2]],"ltp":3.0,"tv":3015.33,"id":18286408}]}]}
{"op":"mcm","clk":"993316239","pt":1580540471233,"mc":[{"id":"1.168096552","rc":[{"batb":[[0,2.96,2],[2,2.9,11.75]],"batl":[[1,3.1,27.77]],"ltp":3.0,"tv":3015.33,"id":18286408}]}]}
{"op":"mcm","clk":"993316302","pt":1580540472469,"mc":[{"id":"1.168096552","rc":[{"batl":[[0,3,2],[1,3.05,4],[2,3.1,27.77]],"ltp":3.0,"tv":3015.33,"id":18286408}]}]}
{"op":"mcm","clk":"993316586","pt":1580540476758,"mc":[{"id":"1.168096552","rc":[{"batb":[[2,2.9,5.87]],"ltp":3.0,"tv":3015.33,"id":18286408}]}]}
{"op":"mcm","clk":"993316754","pt":1580540480469,"mc":[{"id":"1.168096552","rc":[{"batl":[[1,3.05,2]],"ltp":3.0,"tv":3015.33,"id":18286408}]}]}
{"op":"mcm","clk":"993316793","pt":1580540481243,"mc":[{"id":"1.168096552","rc":[{"trd":[[2.98,56]],"ltp":2.98,"tv":3019.33,"id":18286408}],"tv":11967.38}]}
{"op":"mcm","clk":"993316880","pt":1580540483462,"mc":[{"id":"1.168096552","rc":[{"batl":[[0,17.5,2],[1,19.5,1.87],[2,20,8]],"ltp":15.0,"tv":362.8,"id":26640937}]}]}
{"op":"mcm","clk":"993317006","pt":1580540486192,"mc":[{"id":"1.168096552","rc":[{"batl":[[1,19.5,1.68]],"ltp":15.0,"tv":362.8,"id":26640937}]}]}
{"op":"mcm","clk":"993317141","pt":1580540488980,"mc":[{"id":"1.168096552","rc":[{"batl":[[1,3.05,6]],"ltp":2.98,"tv":3019.33,"id":18286408}]}]}
{"op":"mcm","clk":"993317722","pt":1580540496773,"mc":[{"id":"1.168096552","rc":[{"batl":[[1,19,2.07],[2,19.5,1.68]],"ltp":15.0,"tv":362.8,"id":26640937}]}]}
{"op":"mcm","clk":"993317966","pt":1580540501995,"mc":[{"id":"1.168096552","rc":[{"trd":[[4.8,128.91]],"batb":[[0,4.8,3.5]],"ltp":4.8,"tv":1805.3,"id":21580749}],"tv":11973.38}]}
{"op":"mcm","clk":"993318172","pt":1580540506022,"mc":[{"id":"1.168096552","rc":[{"batl":[[1,18.5,1.68],[2,19,2.07]],"ltp":15.0,"tv":362.8,"id":26640937}]}]}
{"op":"mcm","clk":"993318323","pt":1580540509031,"mc":[{"id":"1.168096552","rc":[{"batb":[[1,2.86,12.13],[2,2.84,18.01]],"ltp":2.94,"tv":6627.66,"id":52106}]}]}
{"op":"mcm","clk":"993318691","pt":1580540514930,"mc":[{"id":"1.168096552","rc":[{"trd":[[2.98,60]],"ltp":2.98,"tv":3023.33,"id":18286408}],"tv":11977.38}]}
{"op":"mcm","clk":"993318759","pt":1580540516326,"mc":[{"id":"1.168096552","rc":[{"trd":[[2.96,194.22]],"batb":[[0,2.94,5.75],[1,2.9,5.87],[2,2.88,36]],"ltp":2.96,"tv":3027.33,"id":18286408},{"batl":[[2,20,8]],"ltp":15.0,"tv":362.8,"id":26640937},{"batb":[[0,18.5,21.7]],"ltp":21.0,"tv":91.55,"id":24608298}],"tv":11981.38}]}
{"op":"mcm","clk":"993318817","pt":1580540517414,"mc":[{"id":"1.168096552","rc":[{"batl":[[0,2.98,2],[1,3,2],[2,3.05,6]],"ltp":2.96,"tv":3027.33,"id":18286408}]}]}
{"op":"mcm","clk":"993319076","pt":1580540523114,"mc":[{"id":"1.168096552","rc":[{"batl":[[2,3.05,2]],"ltp":2.96,"tv":3027.33,"id":18286408}]}]}
{"op":"mcm","clk":"993319368","pt":1580540529251,"mc":[{"id":"1.168096552","rc":[{"batl":[[0,2.96,3],[1,2.98,2],[2,3,2]],"ltp":2.96,"tv":3027.33,"id":18286408}]}]}
{"op":"mcm","clk":"993319506","pt":1580540532444,"mc":[{"id":"1.168096552","rc":[{"batl":[[1,2.98,4]],"ltp":2.96,"tv":3027.33,"id":18286408}]}]}
{"op":"mcm","clk":"993320598","pt":1580540558276,"mc":[{"id":"1.168096552","rc":[{"batl":[[0,2.96,5],[1,2.98,2]],"ltp":2.96,"tv":3027.33,"id":18286408}]}]}
{"op":"mcm","clk":"993321444","pt":1580540577428,"mc":[{"id":"1.168096552","rc":[{"trd":[[2.96,204.22],[2.98,64]],"batb":[[0,2.98,6.62],[1,2.96,25],[2,2.94,5.75]],"batl":[[0,3,2],[1,3.05,2],[2,3.1,2]],"ltp":2.98,"tv":3041.33,"id":18286408}],"tv":11995.38}]}
{"op":"mcm","clk":"993321475","pt":1580540578197,"mc":[{"id":"1.168096552","rc":[{"batl":[[2,3.1,27.64]],"ltp":2.98,"tv":3041.33,"id":18286408}]}]}
{"op":"mcm","clk":"993321575","pt":1580540580418,"mc":[{"id":"1.168096552","rc":[{"batb":[[2,2.94,7.75]],"ltp":2.98,"tv":3041.33,"id":18286408},{"batb":[[0,18.5,1.99]],"ltp":21.0,"tv":91.55,"id":24608298}]}]}
{"op":"mcm","clk":"993321703","pt":1580540583519,"mc":[{"id":"1.168096552","rc":[{"trd":[[2.98,68]],"batb":[[0,2.98,4.62]],"ltp":2.98,"tv":3045.33,"id":18286408}],"tv":11999.38}]}
{"op":"mcm","clk":"993322644","pt":1580540606144,"mc":[{"id":"1.168096552","rc":[{"trd":[[3,569.41]],"batb":[[0,3,58]],"batl":[[0,3.05,7.81],[1,3.1,27.64],[2,3.15,157.2]],"ltp":3.0,"tv":3049.33,"id":18286408}],"tv":12003.38}]}
{"op":"mcm","clk":"993322916","pt":1580540613849,"mc":[{"id":"1.168096552","rc":[{"batb":[[2,2.94,9.75]],"ltp":3.0,"tv":3049.33,"id":18286408}]}]}
{"op":"mcm","clk":"993323294","pt":1580540624466,"mc":[{"id":"1.168096552","rc":[{"batl":[[0,3.05,9.81]],"ltp":3.0,"tv":3049.33,"id":18286408}]}]}
{"op":"mcm","clk":"993325116","pt":1580540667318,"mc":[{"id":"1.168096552","rc":[{"trd":[[14.5,11.98]],"batb":[[0,14,7.23],[1,13.5,7.61],[2,12.5,1.87]],"ltp":14.5,"tv":368.78,"id":26640937}],"tv":12009.36}]}
{"op":"mcm","clk":"993325685","pt":1580540682864,"mc":[{"id":"1.168096552","rc":[{"batl":[[1,18.5,2.57]],"ltp":14.5,"tv":368.78,"id":26640937}]}]}
{"op":"mcm","clk":"993326602","pt":1580540703402,"mc":[{"id":"1.168096552","rc":[{"batb":[[0,3,63.04]],"ltp":3.0,"tv":3049.33,"id":18286408},{"batb":[[0,14,11.43]],"ltp":14.5,"tv":368.78,"id":26640937},{"batb":[[0,4.8,8.54]],"ltp":4.8,"tv":1805.3,"id":21580749},{"batb":[[1,34,11.14]],"ltp":44.0,"tv":66.72,"id":27706761},{"batb":[[0,18.5,9.55]],"ltp":21.0,"tv":91.55,"id":24608298}]}]}
{"op":"mcm","clk":"993329908","pt":1580540778497,"mc":[{"id":"1.168096552","rc":[{"batl":[[1,3.1,25.64]],"ltp":3.0,"tv":3049.33,"id":18286408}]}]}
{"op":"mcm","clk":"993331344","pt":1580540816194,"mc":[{"id":"1.168096552","rc":[{"batl":[[0,5,15.88],[1,5.1,11.47],[2,5.2,28.52]],"ltp":4.8,"tv":1805.3,"id":21580749}]}]}
{"op":"mcm","clk":"993331937","pt":1580540831925,"mc":[{"id":"1.168096552","rc":[{"batl":[[0,3.05,11.81]],"ltp":3.0,"tv":3049.33,"id":18286408}]}]}
{"op":"mcm","clk":"993332006","pt":1580540834028,"mc":[{"id":"1.168096552","rc":[{"batb":[[0,14.5,1],[1,14,11.43],[2,13.5,7.61]],"ltp":14.5,"tv":368.78,"id":26640937}]}]}
{"op":"mcm","clk":"993332046","pt":1580540834801,"mc":[{"id":"1.168096552","rc":[{"batb":[[0,14,11.43],[1,13.5,7.61],[2,12.5,1.87]],"ltp":14.5,"tv":368.78,"id":26640937}]}]}
{"op":"mcm","clk":"993344228","pt":1580540891381,"mc":[{"id":"1.168096552","rc":[{"trd":[[2.92,950.79]],"batb":[[0,2.86,12.13],[1,2.84,18.01],[2,2.82,7.34]],"batl":[[0,2.92,44.1],[1,3,10.44],[2,3.05,2.87]],"ltp":2.92,"tv":6639.45,"id":52106}],"tv":12021.16}]}
{"op":"mcm","clk":"993344272","pt":1580540892463,"mc":[{"id":"1.168096552","rc":[{"batb":[[0,4.9,3.51],[1,4.8,8.54],[2,4.7,12.75]],"ltp":4.8,"tv":1805.3,"id":21580749}]}]}
{"op":"mcm","clk":"993344332","pt":1580540893495,"mc":[{"id":"1.168096552","rc":[{"batl":[[0,3.05,9.81]],"ltp":3.0,"tv":3049.33,"id":18286408},{"trd":[[4.9,137.4]],"batb":[[0,4.8,8.54],[1,4.7,12.75],[2,4.6,39.3]],"batl":[[0,4.9,4.98],[1,5,15.88],[2,5.1,11.47]],"ltp":4.9,"tv":1812.32,"id":21580749}],"tv":12028.18}]}
{"op":"mcm","clk":"993344402","pt":1580540895189,"mc":[{"id":"1.168096552","rc":[{"trd":[[3.05,573.65]],"batb":[[0,3.05,23],[1,3,63.04],[2,2.96,25]],"batl":[[0,3.1,25.64],[1,3.15,157.2],[2,3.2,43]],"ltp":3.05,"tv":3068.95,"id":18286408},{"batb":[[0,14.5,6.9],[1,14,11.43],[2,13.5,7.61]],"ltp":14.5,"tv":368.78,"id":26640937},{"trd":[[4.9,147.36]],"batb":[[0,4.9,15.45],[1,4.8,8.54],[2,4.7,12.75]],"batl":[[0,5,15.88],[1,5.1,11.47],[2,5.2,28.52]],"ltp":4.9,"tv":1822.28,"id":21580749},{"batb":[[0,36,3.82]],"ltp":44.0,"tv":66.72,"id":27706761},{"batb":[[0,2.88,34.75],[1,2.86,12.13],[2,2.84,18.01]],"batl":[[1,3.05,2.87],[2,3.1,18.9]],"ltp":2.92,"tv":6639.45,"id":52106},{"batb":[[0,19,6.18],[1,18.5,8.65],[2,18,23.26]],"ltp":21.0,"tv":91.55,"id":24608298}],"tv":12057.76}]}
{"op":"mcm","clk":"993344527","pt":1580540898177,"mc":[{"id":"1.168096552","rc":[{"trd":[[3.05,577.65]],"batb":[[0,3.05,21],[2,2.98,2]],"ltp":3.05,"tv":3072.96,"id":18286408}],"tv":12061.76}]}
{"op":"mcm","clk":"993344620","pt":1580540900894,"mc":[{"id":"1.168096552","rc":[{"batl":[[1,18.5,1.68]],"ltp":14.5,"tv":368.78,"id":26640937}]}]}
{"op":"mcm","clk":"993344777","pt":1580540904497,"mc":[{"id":"1.168096552","rc":[{"batb":[[0,36,3.26]],"ltp":44.0,"tv":66.72,"id":27706761}]}]}
{"op":"mcm","clk":"993344887","pt":1580540906496,"mc":[{"id":"1.168096552","rc":[{"trd":[[3.05,581.65]],"batb":[[0,3.05,19]],"ltp":3.05,"tv":3076.96,"id":18286408}],"tv":12065.76}]}
{"op":"mcm","clk":"993344919","pt":1580540907117,"mc":[{"id":"1.168096552","rc":[{"batb":[[0,19,25.77],[2,18,3.67]],"ltp":21.0,"tv":91.55,"id":24608298}]}]}
{"op":"mcm","clk":"993345132","pt":1580540911088,"mc":[{"id":"1.168096552","rc":[{"batl":[[0,3.1,45.64]],"ltp":3.05,"tv":3076.96,"id":18286408}]}]}
{"op":"mcm","clk":"993345316","pt":1580540915500,"mc":[{"id":"1.168096552","rc":[{"batb":[[0,19.5,8.4],[1,19,25.77],[2,18.5,1.08]],"ltp":21.0,"tv":91.55,"id":24608298}]}]}
{"op":"mcm","clk":"993345691","pt":1580540924499,"mc":[{"id":"1.168096552","rc":[{"trd":[[3.05,585.65]],"batb":[[0,3.05,17]],"ltp":3.05,"tv":3080.96,"id":18286408}],"tv":12069.77}]}
{"op":"mcm","clk":"993346059","pt":1580540932711,"mc":[{"id":"1.168096552","rc":[{"trd":[[3.05,589.66]],"batb":[[0,3.05,15]],"ltp":3.05,"tv":3084.96,"id":18286408}],"tv":12073.77}]}
{"op":"mcm","clk":"993346479","pt":1580540941653,"mc":[{"id":"1.168096552","rc":[{"trd":[[3.05,593.66]],"batb":[[0,3.05,13]],"ltp":3.05,"tv":3088.96,"id":18286408}],"tv":12077.77}]}
{"op":"mcm","clk":"993346852","pt":1580540950340,"mc":[{"id":"1.168096552","rc":[{"trd":[[3.05,597.66]],"batb":[[0,3.05,11]],"ltp":3.05,"tv":3092.96,"id":18286408}],"tv":12081.77}]}
{"op":"mcm","clk":"993347579","pt":1580540968461,"mc":[{"id":"1.168096552","rc":[{"trd":[[3.05,601.66]],"batb":[[0,3.05,9]],"ltp":3.05,"tv":3096.96,"id":18286408}],"tv":12085.77}]}
{"op":"mcm","clk":"993348658","pt":1580540993024,"mc":[{"id":"1.168096552","rc":[{"trd":[[3.05,605.66]],"batb":[[0,3.05,6.99]],"ltp":3.05,"tv":3100.96,"id":18286408}],"tv":12089.77}]}
{"op":"mcm","clk":"993349043","pt":1580541001107,"mc":[{"id":"1.168096552","rc":[{"trd":[[3.05,609.66]],"batb":[[0,3.05,4.99]],"ltp":3.05,"tv":3104.96,"id":18286408}],"tv":12093.77}]}
{"op":"mcm","clk":"993350249","pt":1580541027075,"mc":[{"id":"1.168096552","rc":[{"trd":[[3.05,613.66]],"batb":[[0,3.05,2.99]],"ltp":3.05,"tv":3108.96,"id":18286408}],"tv":12097.77}]}
{"op":"mcm","clk":"993350652","pt":1580541037273,"mc":[{"id":"1.168096552","rc":[{"batb":[[0,15,1.15],[1,14.5,6.9],[2,14,11.43]],"ltp":14.5,"tv":368.78,"id":26640937},{"batb":[[0,19.5,9.26],[1,19,24.86]],"ltp":21.0,"tv":91.55,"id":24608298}]}]}
{"op":"mcm","clk":"993350999","pt":1580541043975,"mc":[{"id":"1.168096552","rc":[{"trd":[[3.05,619.64]],"batb":[[0,3,63.04],[1,2.98,2],[2,2.96,25]],"ltp":3.05,"tv":3114.95,"id":18286408}],"tv":12103.75}]}
{"op":"mcm","clk":"993351389","pt":1580541052419,"mc":[{"id":"1.168096552","rc":[{"batb":[[0,3,79.92]],"batl":[[0,3.05,2],[1,3.1,45.64],[2,3.15,157.2]],"ltp":3.05,"tv":3114.95,"id":18286408},{"batb":[[0,15,4.53]],"ltp":14.5,"tv":368.78,"id":26640937},{"batb":[[0,4.9,25.78]],"ltp":4.9,"tv":1822.28,"id":21580749},{"batb":[[0,36,4.67]],"ltp":44.0,"tv":66.72,"id":27706761},{"batb":[[0,2.88,52.34]],"ltp":2.92,"tv":6639.45,"id":52106},{"batb":[[0,19.5,11.86]],"ltp":21.0,"tv":91.55,"id":24608298}]}]}
{"op":"mcm","clk":"993351654","pt":1580541057521,"mc":[{"id":"1.168096552","rc":[{"batb":[[0,15,7.89],[2,14,7.23]],"ltp":14.5,"tv":368.78,"id":26640937},{"batl":[[2,3.1,63.9]],"ltp":2.92,"tv":6639.45,"id":52106}]}]}
{"op":"mcm","clk":"993352907","pt":1580541087331,"mc":[{"id":"1.168096552","rc":[{"batb":[[1,2.98,8.42]],"ltp":3.05,"tv":3114.95,"id":18286408}]}]}
{"op":"mcm","clk":"993353993","pt":1580541113492,"mc":[{"id":"1.168096552","rc":[{"batb":[[2,2.84,7.11]],"ltp":2.92,"tv":6639.45,"id":52106}]}]}
{"op":"mcm","clk":"993354073","pt":1580541115294,"mc":[{"id":"1.168096552","rc":[{"batb":[[0,2.9,10.68],[1,2.88,52.34],[2,2.86,12.13]],"ltp":2.92,"tv":6639.45,"id":52106}]}]}
{"op":"mcm","clk":"993355012","pt":1580541135632,"mc":[{"id":"1.168096552","rc":[{"trd":[[3,573.41]],"batb":[[0,3,77.92]],"ltp":3.0,"tv":3118.95,"id":18286408},{"trd":[[4.9,151.36]],"batb":[[0,4.9,23.78]],"ltp":4.9,"tv":1826.28,"id":21580749},{"trd":[[2.92,994.79]],"batl":[[0,2.92,22.1]],"ltp":2.92,"tv":6683.45,"id":52106}],"tv":12155.76}]}
{"op":"mcm","clk":"993355524","pt":1580541147362,"mc":[{"id":"1.168096552","rc":[{"trd":[[19.5,22.01],[20,2.91]],"batb":[[0,19,24.86],[1,18.5,1.08],[2,18,3.67]],"ltp":19.5,"tv":115.27,"id":24608298}],"tv":12179.48}]}
{"op":"mcm","clk":"993355560","pt":1580541148083,"mc":[{"id":"1.168096552","rc":[{"batb":[[0,3,94.81]],"ltp":3.0,"tv":3118.95,"id":18286408},{"batb":[[0,15,11.27]],"ltp":14.5,"tv":368.78,"id":26640937},{"batb":[[0,4.9,34.12]],"ltp":4.9,"tv":1826.28,"id":21580749},{"batb":[[0,36,6.08]],"ltp":44.0,"tv":66.72,"id":27706761},{"batb":[[0,2.9,28.14]],"ltp":2.92,"tv":6683.45,"id":52106},{"batb":[[0,19.5,2.6],[1,19,24.86],[2,18.5,1.08]],"ltp":19.5,"tv":115.27,"id":24608298}]}]}
{"op":"mcm","clk":"993355632","pt":1580541149365,"mc":[{"id":"1.168096552","rc":[{"batb":[[1,2.88,71]],"ltp":2.92,"tv":6683.45,"id":52106}]}]}
{"op":"mcm","clk":"993355702","pt":1580541150452,"mc":[{"id":"1.168096552","rc":[{"batb":[[0,2.9,34.02]],"ltp":2.92,"tv":6683.45,"id":52106}]}]}
{"op":"mcm","clk":"993357327","pt":1580541185207,"mc":[{"id":"1.168096552","rc":[{"trd":[[3,577.41]],"batb":[[0,3,92.81]],"ltp":3.0,"tv":3122.95,"id":18286408}],"tv":12183.48}]}
{"op":"mcm","clk":"993357783","pt":1580541195506,"mc":[{"id":"1.168096552","rc":[{"trd":[[2.92,998.79]],"batl":[[0,2.92,20.1]],"ltp":2.92,"tv":6687.45,"id":52106}],"tv":12187.48}]}
{"op":"mcm","clk":"993358074","pt":1580541202405,"mc":[{"id":"1.168096552","rc":[{"batb":[[0,19.5,11]],"ltp":19.5,"tv":115.27,"id":24608298}]}]}
{"op":"mcm","clk":"993358315","pt":1580541206709,"mc":[{"id":"1.168096552","rc":[{"batb":[[1,2.98,2]],"ltp":3.0,"tv":3122.95,"id":18286408}]}]}
{"op":"mcm","clk":"993358463","pt":1580541210828,"mc":[{"id":"1.168096552","rc":[{"batl":[[0,5,17.88]],"ltp":4.9,"tv":1826.28,"id":21580749}]}]}
{"op":"mcm","clk":"993360059","pt":1580541247370,"mc":[{"id":"1.168096552","rc":[{"trd":[[2.92,1006.79]],"batl":[[0,2.92,16.1]],"ltp":2.92,"tv":6695.45,"id":52106}],"tv":12195.48}]}
{"op":"mcm","clk":"993361274","pt":1580541271513,"mc":[{"id":"1.168096552","rc":[{"trd":[[4.9,219.62]],"batb":[[0,4.8,8.54],[1,4.7,12.75],[2,4.6,39.3]],"batl":[[0,4.9,3.72],[1,5,17.88],[2,5.1,11.47]],"ltp":4.9,"tv":1894.54,"id":21580749}],"tv":12263.74}]}
{"op":"mcm","clk":"993362575","pt":1580541297349,"mc":[{"id":"1.168096552","rc":[{"trd":[[2.92,1022.41]],"batl":[[0,2.92,8.29],[1,3,7.6],[2,3.05,2.87]],"ltp":2.92,"tv":6711.07,"id":52106}],"tv":12279.36}]}
{"op":"mcm","clk":"993362713","pt":1580541300441,"mc":[{"id":"1.168096552","rc":[{"batl":[[1,3.05,2.87],[2,3.1,63.9]],"ltp":2.92,"tv":6711.07,"id":52106}]}]}
{"op":"mcm","clk":"993362937","pt":1580541304380,"mc":[{"id":"1.168096552","rc":[{"trd":[[2.92,1039]],"batb":[[0,2.92,2.31],[1,2.9,23.35],[2,2.88,71]],"batl":[[0,3.05,2.87],[1,3.1,63.9],[2,3.15,12]],"ltp":2.92,"tv":6727.66,"id":52106}],"tv":12295.94}]}
{"op":"mcm","clk":"993363146","pt":1580541308461,"mc":[{"id":"1.168096552","rc":[{"batb":[[0,2.9,23.35],[1,2.88,71],[2,2.86,12.13]],"batl":[[0,3.05,16.87]],"ltp":2.92,"tv":6727.66,"id":52106}]}]}
{"op":"mcm","clk":"993363241","pt":1580541310163,"mc":[{"id":"1.168096552","rc":[{"batl":[[0,2.94,7.76],[1,3.05,16.87],[2,3.1,63.9]],"ltp":2.92,"tv":6727.66,"id":52106}]}]}
{"op":"mcm","clk":"993363313","pt":1580541311294,"mc":[{"id":"1.168096552","rc":[{"batb":[[0,2.92,2.31],[1,2.9,23.35],[2,2.88,71]],"ltp":2.92,"tv":6727.66,"id":52106}]}]}
{"op":"mcm","clk":"993364099","pt":1580541327023,"mc":[{"id":"1.168096552","rc":[{"trd":[[4.8,148.91]],"batb":[[0,4.8,7.15]],"ltp":4.8,"tv":1914.54,"id":21580749}],"tv":12315.94}]}
{"op":"mcm","clk":"993365242","pt":1580541350429,"mc":[{"id":"1.168096552","rc":[{"batl":[[0,3.05,16.87],[1,3.1,63.9],[2,3.15,12]],"ltp":2.92,"tv":6727.66,"id":52106}]}]}
{"op":"mcm","clk":"993365711","pt":1580541358952,"mc":[{"id":"1.168096552","rc":[{"batl":[[0,2.98,7.65],[1,3.05,16.87],[2,3.1,63.9]],"ltp":2.92,"tv":6727.66,"id":52106}]}]}
{"op":"mcm","clk":"993365934","pt":1580541363045,"mc":[{"id":"1.168096552","rc":[{"batl":[[1,3.05,14]],"ltp":2.92,"tv":6727.66,"id":52106}]}]}
{"op":"mcm","clk":"993366039","pt":1580541364956,"mc":[{"id":"1.168096552","rc":[{"trd":[[44,4.32],[48,7.92],[50,4.3]],"batl":[[0,60,1.2],[1,85,1]],"ltp":50.0,"tv":72.72,"id":27706761}],"tv":12321.94}]}
{"op":"mcm","clk":"993366192","pt":1580541367745,"mc":[{"id":"1.168096552","rc":[{"batb":[[0,36,6.09]],"ltp":50.0,"tv":72.72,"id":27706761}]}]}
{"op":"mcm","clk":"993366460","pt":1580541372183,"mc":[{"id":"1.168096552","rc":[{"batb":[[0,38,1.05],[1,36,6.08],[2,34,11.14]],"ltp":50.0,"tv":72.72,"id":27706761}]}]}
{"op":"mcm","clk":"993366628","pt":1580541374773,"mc":[{"id":"1.168096552","rc":[{"batb":[[0,40,4],[1,38,1.05],[2,36,6.08]],"ltp":50.0,"tv":72.72,"id":27706761},{"batb":[[2,2.88,81]],"ltp":2.92,"tv":6727.66,"id":52106}]}]}
{"op":"mcm","clk":"993366721","pt":1580541376474,"mc":[{"id":"1.168096552","rc":[{"batb":[[1,38,1.03]],"ltp":50.0,"tv":72.72,"id":27706761}]}]}
{"op":"mcm","clk":"993366728","pt":1580541376576,"mc":[{"id":"1.168096552","rc":[{"batb":[[0,40,4.02]],"ltp":50.0,"tv":72.72,"id":27706761}]}]}
{"op":"mcm","clk":"993367087","pt":1580541384165,"mc":[{"id":"1.168096552","rc":[{"batb":[[0,4.8,13.03]],"ltp":4.8,"tv":1914.54,"id":21580749}]}]}
{"op":"mcm","clk":"993367690","pt":1580541391482,"mc":[{"id":"1.168096552","rc":[{"batb":[[1,36,6.08],[2,34,11.14]],"ltp":50.0,"tv":72.72,"id":27706761}]}]}
{"op":"mcm","clk":"993367823","pt":1580541394310,"mc":[{"id":"1.168096552","rc":[{"batb":[[1,38,4],[2,36,6.08]],"ltp":50.0,"tv":72.72,"id":27706761}]}]}
{"op":"mcm","clk":"993371042","pt":1580541453471,"mc":[{"id":"1.168096552","rc":[{"batb":[[0,19.5,11.86]],"ltp":19.5,"tv":115.27,"id":24608298}]}]}
{"op":"mcm","clk":"993371402","pt":1580541461081,"mc":[{"id":"1.168096552","rc":[{"trd":[[3.05,623.64]],"batb":[[0,3.05,5.65],[1,3,92.81],[2,2.98,2]],"batl":[[0,3.1,45.64],[1,3.15,157.2],[2,3.2,43]],"ltp":3.05,"tv":3126.95,"id":18286408}],"tv":12325.94}]}
{"op":"mcm","clk":"993371790","pt":1580541469498,"mc":[{"id":"1.168096552","rc":[{"trd":[[3.05,627.64]],"batb":[[0,3.05,3.65]],"ltp":3.05,"tv":3130.95,"id":18286408}],"tv":12329.94}]}
{"op":"mcm","clk":"993372005","pt":1580541473493,"mc":[{"id":"1.168096552","rc":[{"batb":[[0,2.92,8.21]],"ltp":2.92,"tv":6727.66,"id":52106}]}]}
{"op":"mcm","clk":"993372535","pt":1580541485354,"mc":[{"id":"1.168096552","rc":[{"trd":[[3.05,634.94]],"batb":[[0,3,92.81],[1,2.98,2],[2,2.96,25]],"ltp":3.05,"tv":3138.24,"id":18286408}],"tv":12337.23}]}
{"op":"mcm","clk":"993373315","pt":1580541503337,"mc":[{"id":"1.168096552","rc":[{"batl":[[0,3.05,2],[1,3.1,45.64],[2,3.15,157.2]],"ltp":3.05,"tv":3138.24,"id":18286408}]}]}
{"op":"mcm","clk":"993373569","pt":1580541508156,"mc":[{"id":"1.168096552","rc":[{"trd":[[3,587.41]],"batb":[[0,3,87.81]],"ltp":3.0,"tv":3148.24,"id":18286408}],"tv":12347.23}]}
{"op":"mcm","clk":"993373737","pt":1580541511464,"mc":[{"id":"1.168096552","rc":[{"batl":[[1,3.1,25.64]],"ltp":3.0,"tv":3148.24,"id":18286408}]}]}
{"op":"mcm","clk":"993373984","pt":1580541516492,"mc":[{"id":"1.168096552","rc":[{"trd":[[3.05,638.94]],"batl":[[0,3.1,25.64],[1,3.15,157.2],[2,3.2,43]],"ltp":3.05,"tv":3152.24,"id":18286408}],"tv":12351.23}]}
{"op":"mcm","clk":"993374252","pt":1580541522178,"mc":[{"id":"1.168096552","rc":[{"batl":[[0,3.1,45.64]],"ltp":3.05,"tv":3152.24,"id":18286408}]}]}
{"op":"mcm","clk":"993374675","pt":1580541530494,"mc":[{"id":"1.168096552","rc":[{"batl":[[0,3.05,2],[1,3.1,45.64],[2,3.15,157.2]],"ltp":3.05,"tv":3152.24,"id":18286408}]}]}
{"op":"mcm","clk":"993375320","pt":1580541543550,"mc":[{"id":"1.168096552","rc":[{"batb":[[0,40,4.43],[2,36,5.6]],"ltp":50.0,"tv":72.72,"id":27706761}]}]}
{"op":"mcm","clk":"993376535","pt":1580541568458,"mc":[{"id":"1.168096552","rc":[{"batl":[[0,3.05,14],[1,3.1,63.9],[2,3.15,12]],"ltp":2.92,"tv":6727.66,"id":52106}]}]}
{"op":"mcm","clk":"993377137","pt":1580541581220,"mc":[{"id":"1.168096552","rc":[{"trd":[[3.05,642.94]],"batl":[[0,3.1,45.64],[1,3.15,157.2],[2,3.2,43]],"ltp":3.05,"tv":3156.24,"id":18286408}],"tv":12355.23}]}
{"op":"mcm","clk":"993377300","pt":1580541584464,"mc":[{"id":"1.168096552","rc":[{"batl":[[0,3.05,2],[1,3.1,45.64],[2,3.15,157.2]],"ltp":3.05,"tv":3156.24,"id":18286408}]}]}
{"op":"mcm","clk":"993377564","pt":1580541589390,"mc":[{"id":"1.168096552","rc":[{"batl":[[0,3.05,4]],"ltp":3.05,"tv":3156.24,"id":18286408}]}]}
{"op":"mcm","clk":"993377896","pt":1580541596501,"mc":[{"id":"1.168096552","rc":[{"trd":[[2.92,1054.62]],"batb":[[0,2.9,23.74],[1,2.88,81],[2,2.86,12.13]],"ltp":2.92,"tv":6743.28,"id":52106}],"tv":12370.86}]}
{"op":"mcm","clk":"993378128","pt":1580541601087,"mc":[{"id":"1.168096552","rc":[{"batb":[[0,2.92,2.39],[1,2.9,23.35],[2,2.88,81]],"ltp":2.92,"tv":6743.28,"id":52106}]}]}
{"op":"mcm","clk":"993378380","pt":1580541605416,"mc":[{"id":"1.168096552","rc":[{"batl":[[0,3.05,6]],"ltp":3.05,"tv":3156.24,"id":18286408},{"batl":[[0,3,2],[1,3.05,14],[2,3.1,63.9]],"ltp":2.92,"tv":6743.28,"id":52106}]}]}
{"op":"mcm","clk":"993378760","pt":1580541612736,"mc":[{"id":"1.168096552","rc":[{"batl":[[0,4.9,13.72]],"ltp":4.8,"tv":1914.54,"id":21580749}]}]}
{"op":"mcm","clk":"993379523","pt":1580541627849,"mc":[{"id":"1.168096552","rc":[{"trd":[[15,24.54]],"batb":[[0,14.5,6.9],[1,14,7.23],[2,13.5,7.61]],"ltp":15.0,"tv":391.33,"id":26640937}],"tv":12393.4}]}
{"op":"mcm","clk":"993380031","pt":1580541638165,"mc":[{"id":"1.168096552","rc":[{"batl":[[1,18.5,2.57]],"ltp":15.0,"tv":391.33,"id":26640937},{"batb":[[1,4.7,21.96]],"ltp":4.8,"tv":1914.54,"id":21580749}]}]}
{"op":"mcm","clk":"993381139","pt":1580541661901,"mc":[{"id":"1.168096552","rc":[{"batl":[[0,4.9,23.72]],"ltp":4.8,"tv":1914.54,"id":21580749}]}]}
{"op":"mcm","clk":"993381952","pt":1580541681515,"mc":[{"id":"1.168096552","rc":[{"batl":[[0,3,4.92]],"ltp":2.92,"tv":6743.28,"id":52106}]}]}
{"op":"mcm","clk":"993382249","pt":1580541688045,"mc":[{"id":"1.168096552","rc":[{"batb":[[0,14.5,11.1]],"ltp":15.0,"tv":391.33,"id":26640937}]}]}
{"op":"mcm","clk":"993384692","pt":1580541732969,"mc":[{"id":"1.168096552","rc":[{"trd":[[2.92,1059.4]],"batb":[[0,2.9,23.35],[1,2.88,81],[2,2.86,12.13]],"batl":[[0,2.92,2.11],[1,3,4.92],[2,3.05,14]],"ltp":2.92,"tv":6748.06,"id":52106}],"tv":12398.19}]}
{"op":"mcm","clk":"993384759","pt":1580541734500,"mc":[{"id":"1.168096552","rc":[{"batl":[[0,4.9,33.72]],"ltp":4.8,"tv":1914.54,"id":21580749}]}]}
{"op":"mcm","clk":"993384909","pt":1580541737509,"mc":[{"id":"1.168096552","rc":[{"batl":[[0,3.05,8]],"ltp":3.05,"tv":3156.24,"id":18286408}]}]}
{"op":"mcm","clk":"993384992","pt":1580541739174,"mc":[{"id":"1.168096552","rc":[{"batl":[[2,3.1,63.9]],"ltp":2.92,"tv":6748.06,"id":52106}]}]}
{"op":"mcm","clk":"993385092","pt":1580541741305,"mc":[{"id":"1.168096552","rc":[{"batl":[[2,3.05,4]],"ltp":2.92,"tv":6748.06,"id":52106}]}]}
{"op":"mcm","clk":"993385236","pt":1580541744817,"mc":[{"id":"1.168096552","rc":[{"batl":[[0,3,4.92],[1,3.05,4],[2,3.1,63.9]],"ltp":2.92,"tv":6748.06,"id":52106}]}]}
{"op":"mcm","clk":"993395777","pt":1580541759504,"mc":[{"id":"1.168096552","rc":[{"batl":[[0,3,2],[1,3.05,6.87]],"ltp":2.92,"tv":6748.06,"id":52106}]}]}
{"op":"mcm","clk":"993395926","pt":1580541762337,"mc":[{"id":"1.168096552","rc":[{"trd":[[2.9,147.24]],"batb":[[0,2.9,21.24]],"ltp":2.9,"tv":6752.28,"id":52106}],"tv":12402.4}]}
{"op":"mcm","clk":"993396324","pt":1580541770479,"mc":[{"id":"1.168096552","rc":[{"trd":[[14.5,31.98]],"batb":[[0,14.5,1.1]],"ltp":14.5,"tv":411.33,"id":26640937}],"tv":12422.4}]}
{"op":"mcm","clk":"993396761","pt":1580541778721,"mc":[{"id":"1.168096552","rc":[{"trd":[[4.8,154.91]],"batb":[[0,4.8,10.03]],"ltp":4.8,"tv":1920.54,"id":21580749}],"tv":12428.4}]}
{"op":"mcm","clk":"993397030","pt":1580541783739,"mc":[{"id":"1.168096552","rc":[{"trd":[[3,591.41]],"batb":[[0,3,85.81]],"ltp":3.0,"tv":3160.24,"id":18286408}],"tv":12432.4}]}
{"op":"mcm","clk":"993399092","pt":1580541821514,"mc":[{"id":"1.168096552","rc":[{"batb":[[0,2.92,2],[1,2.9,21.24],[2,2.88,81]],"ltp":2.9,"tv":6752.28,"id":52106}]}]}
{"op":"mcm","clk":"993399957","pt":1580541837492,"mc":[{"id":"1.168096552","rc":[{"batl":[[1,5,15.88]],"ltp":4.8,"tv":1920.54,"id":21580749}]}]}
{"op":"mcm","clk":"993400008","pt":1580541838519,"mc":[{"id":"1.168096552","rc":[{"batl":[[0,4.9,35.72]],"ltp":4.8,"tv":1920.54,"id":21580749}]}]}
{"op":"mcm","clk":"993402656","pt":1580541885161,"mc":[{"id":"1.168096552","rc":[{"trd":[[4.8,158.91]],"batb":[[0,4.8,8.03]],"batl":[[0,4.9,33.72]],"ltp":4.8,"tv":1924.54,"id":21580749}],"tv":12436.4}]}
{"op":"mcm","clk":"993405811","pt":1580541934332,"mc":[{"id":"1.168096552","rc":[{"batb":[[0,14.5,2.29]],"ltp":14.5,"tv":411.33,"id":26640937},{"trd":[[40,32.92],[42,2.83]],"batb":[[0,38,4.43],[1,36,5.6],[2,34,7.14]],"ltp":40.0,"tv":80.71,"id":27706761}],"tv":12444.4}]}
{"op":"mcm","clk":"993406220","pt":1580541941460,"mc":[{"id":"1.168096552","rc":[{"batl":[[0,60,1.22]],"ltp":40.0,"tv":80.71,"id":27706761}]}]}
{"op":"mcm","clk":"993410977","pt":1580542009227,"mc":[{"id":"1.168096552","rc":[{"batl":[[0,3.05,6]],"ltp":3.0,"tv":3160.24,"id":18286408},{"batl":[[0,3.05,6.87],[1,3.1,63.9],[2,3.15,12]],"ltp":2.9,"tv":6752.28,"id":52106}]}]}
{"op":"mcm","clk":"993411060","pt":1580542010516,"mc":[{"id":"1.168096552","rc":[{"batl":[[1,18.5,1.68]],"ltp":14.5,"tv":411.33,"id":26640937}]}]}
{"op":"mcm","clk":"993411465","pt":1580542017347,"mc":[{"id":"1.168096552","rc":[{"batl":[[0,3.05,20.87]],"ltp":2.9,"tv":6752.28,"id":52106}]}]}
{"op":"mcm","clk":"993412094","pt":1580542026287,"mc":[{"id":"1.168096552","rc":[{"batl":[[0,3.05,16.87]],"ltp":2.9,"tv":6752.28,"id":52106}]}]}
{"op":"mcm","clk":"993415751","pt":1580542082119,"mc":[{"id":"1.168096552","rc":[{"trd":[[4.8,174.98]],"batb":[[0,4.7,21.96],[1,4.6,42.8],[2,4.5,27.25]],"batl":[[0,4.8,1.97],[1,4.9,33.72],[2,5,15.88]],"ltp":4.8,"tv":1940.61,"id":21580749}],"tv":12460.46}]}
{"op":"mcm","clk":"993417396","pt":1580542108442,"mc":[{"id":"1.168096552","rc":[{"trd":[[19.5,44.01],[20,4.63]],"batb":[[0,19,24.86],[1,18.5,1.08],[2,18,3.67]],"ltp":19.5,"tv":138.99,"id":24608298}],"tv":12484.19}]}
{"op":"mcm","clk":"993417878","pt":1580542116447,"mc":[{"id":"1.168096552","rc":[{"batb":[[0,19,5.27]],"ltp":19.5,"tv":138.99,"id":24608298}]}]}
{"op":"mcm","clk":"993418215","pt":1580542122289,"mc":[{"id":"1.168096552","rc":[{"batl":[[1,3.1,25.64]],"ltp":3.0,"tv":3160.24,"id":18286408}]}]}
{"op":"mcm","clk":"993418857","pt":1580542133020,"mc":[{"id":"1.168096552","rc":[{"batb":[[1,18.5,18.08]],"ltp":19.5,"tv":138.99,"id":24608298}]}]}
{"op":"mcm","clk":"993419190","pt":1580542138801,"mc":[{"id":"1.168096552","rc":[{"batl":[[0,3.05,4]],"ltp":3.0,"tv":3160.24,"id":18286408}]}]}
{"op":"mcm","clk":"993419401","pt":1580542141901,"mc":[{"id":"1.168096552","rc":[{"batl":[[0,3.05,2]],"ltp":3.0,"tv":3160.24,"id":18286408}]}]}
{"op":"mcm","clk":"993420308","pt":1580542156520,"mc":[{"id":"1.168096552","rc":[{"trd":[[3,595.41]],"batb":[[0,3,83.81]],"ltp":3.0,"tv":3164.24,"id":18286408}],"tv":12488.19}]}
{"op":"mcm","clk":"993421036","pt":1580542168320,"mc":[{"id":"1.168096552","rc":[{"batb":[[0,4.7,42.97]],"ltp":4.8,"tv":1940.61,"id":21580749},{"batb":[[0,40,7.15],[1,38,4],[2,36,5.6]],"ltp":40.0,"tv":80.71,"id":27706761}]}]}
{"op":"mcm","clk":"993421767","pt":1580542180155,"mc":[{"id":"1.168096552","rc":[{"batl":[[0,3.05,4]],"ltp":3.0,"tv":3164.24,"id":18286408},{"batl":[[0,3,2],[1,3.05,16.87],[2,3.1,63.9]],"ltp":2.9,"tv":6752.28,"id":52106}]}]}
{"op":"mcm","clk":"993422673","pt":1580542194595,"mc":[{"id":"1.168096552","rc":[{"batl":[[1,65,2],[2,85,1]],"ltp":40.0,"tv":80.71,"id":27706761}]}]}
{"op":"mcm","clk":"993423054","pt":1580542200477,"mc":[{"id":"1.168096552","rc":[{"trd":[[4.7,342.92]],"batb":[[0,4.7,32.97]],"ltp":4.7,"tv":1960.61,"id":21580749}],"tv":12508.19}]}
{"op":"mcm","clk":"993423138","pt":1580542201475,"mc":[{"id":"1.168096552","rc":[{"batb":[[0,2.94,2],[1,2.92,2],[2,2.9,21.24]],"batl":[[0,3,12.44]],"ltp":2.9,"tv":6752.28,"id":52106}]}]}
{"op":"mcm","clk":"993423344","pt":1580542204085,"mc":[{"id":"1.168096552","rc":[{"batl":[[1,4.9,35.72]],"ltp":4.7,"tv":1960.61,"id":21580749}]}]}
{"op":"mcm","clk":"993423581","pt":1580542207467,"mc":[{"id":"1.168096552","rc":[{"trd":[[4.8,178.92],[4.9,219.68]],"batb":[[0,4.8,3.59],[1,4.7,32.97],[2,4.6,42.8]],"batl":[[0,4.9,35.69],[1,5,15.88],[2,5.1,11.47]],"ltp":4.9,"tv":1964.61,"id":21580749}],"tv":12512.19}]}
{"op":"mcm","clk":"993424084","pt":1580542215298,"mc":[{"id":"1.168096552","rc":[{"batb":[[0,2.96,2],[1,2.94,2],[2,2.92,2]],"ltp":2.9,"tv":6752.28,"id":52106}]}]}
{"op":"mcm","clk":"993424403","pt":1580542219400,"mc":[{"id":"1.168096552","rc":[{"batl":[[0,2.98,2.94],[1,3,12.44],[2,3.05,14]],"ltp":2.9,"tv":6752.28,"id":52106}]}]}
{"op":"mcm","clk":"993424909","pt":1580542226466,"mc":[{"id":"1.168096552","rc":[{"batl":[[2,3.1,63.9]],"ltp":2.9,"tv":6752.28,"id":52106}]}]}
{"op":"mcm","clk":"993425190","pt":1580542230510,"mc":[{"id":"1.168096552","rc":[{"trd":[[2.96,533.01]],"batb":[[0,2.94,2],[1,2.92,2],[2,2.9,15.36]],"batl":[[0,2.96,48],[1,2.98,2.94],[2,3,12.44]],"ltp":2.96,"tv":6756.28,"id":52106}],"tv":12516.19}]}
{"op":"mcm","clk":"993425560","pt":1580542235327,"mc":[{"id":"1.168096552","rc":[{"batb":[[0,40,7.56]],"ltp":40.0,"tv":80.71,"id":27706761}]}]}
{"op":"mcm","clk":"993425634","pt":1580542236313,"mc":[{"id":"1.168096552","rc":[{"batl":[[1,3,12.44],[2,3.05,6]],"ltp":2.96,"tv":6756.28,"id":52106}]}]}
{"op":"mcm","clk":"993425726","pt":1580542237444,"mc":[{"id":"1.168096552","rc":[{"trd":[[2.94,371.5]],"batb":[[0,2.92,2],[1,2.9,15.36],[2,2.88,81]],"batl":[[1,3,2]],"ltp":2.94,"tv":6762.24,"id":52106}],"tv":12522.15}]}
{"op":"mcm","clk":"993427538","pt":1580542261452,"mc":[{"id":"1.168096552","rc":[{"batl":[[0,2.94,3.36],[1,2.96,48],[2,3,2]],"ltp":2.94,"tv":6762.24,"id":52106}]}]}
{"op":"mcm","clk":"993427603","pt":1580542262378,"mc":[{"id":"1.168096552","rc":[{"batl":[[0,2.96,48],[1,3,2],[2,3.05,6]],"ltp":2.94,"tv":6762.24,"id":52106}]}]}
{"op":"mcm","clk":"993428073","pt":1580542269187,"mc":[{"id":"1.168096552","rc":[{"batl":[[0,2.94,3.36],[1,2.96,48],[2,3,2]],"ltp":2.94,"tv":6762.24,"id":52106}]}]}
{"op":"mcm","clk":"993428154","pt":1580542270171,"mc":[{"id":"1.168096552","rc":[{"batl":[[0,2.96,48],[1,3,2],[2,3.05,6]],"ltp":2.94,"tv":6762.24,"id":52106}]}]}
{"op":"mcm","clk":"993429673","pt":1580542289481,"mc":[{"id":"1.168096552","rc":[{"batb":[[0,2.92,7.04]],"ltp":2.94,"tv":6762.24,"id":52106}]}]}
{"op":"mcm","clk":"993432837","pt":1580542327239,"mc":[{"id":"1.168096552","rc":[{"batl":[[0,4.9,33.69]],"ltp":4.9,"tv":1964.61,"id":21580749}]}]}
{"op":"mcm","clk":"993434543","pt":1580542352402,"mc":[{"id":"1.168096552","rc":[{"trd":[[2.96,559.89]],"batl":[[0,2.96,34.56]],"ltp":2.96,"tv":6789.12,"id":52106}],"tv":12549.03}]}
{"op":"mcm","clk":"993435741","pt":1580542372509,"mc":[{"id":"1.168096552","rc":[{"trd":[[2.9,160.49],[2.92,1073.49]],"batb":[[0,2.9,8.74],[1,2.88,81],[2,2.86,12.13]],"ltp":2.9,"tv":6816.45,"id":52106}],"tv":12576.36}]}
{"op":"mcm","clk":"993435806","pt":1580542373492,"mc":[{"id":"1.168096552","rc":[{"batb":[[1,2.88,62.34]],"ltp":2.9,"tv":6816.45,"id":52106}]}]}
{"op":"mcm","clk":"993437756","pt":1580542402137,"mc":[{"id":"1.168096552","rc":[{"trd":[[3,605.5]],"batb":[[0,3,78.77]],"ltp":3.0,"tv":3174.32,"id":18286408}],"tv":12586.44}]}
{"op":"mcm","clk":"993438182","pt":1580542408363,"mc":[{"id":"1.168096552","rc":[{"trd":[[4.8,186.09]],"batb":[[0,4.7,32.97],[1,4.6,42.8],[2,4.5,27.25]],"batl":[[0,4.8,1.45],[1,4.9,33.69],[2,5,15.88]],"ltp":4.8,"tv":1971.78,"id":21580749}],"tv":12593.62}]}
{"op":"mcm","clk":"993438288","pt":1580542410073,"mc":[{"id":"1.168096552","rc":[{"trd":[[2.9,174.48]],"batb":[[0,2.9,1.74]],"ltp":2.9,"tv":6830.45,"id":52106}],"tv":12607.61}]}
{"op":"mcm","clk":"993438372","pt":1580542411371,"mc":[{"id":"1.168096552","rc":[{"batb":[[0,19,6.15]],"ltp":19.5,"tv":138.99,"id":24608298}]}]}
{"op":"mcm","clk":"993438565","pt":1580542413967,"mc":[{"id":"1.168096552","rc":[{"trd":[[4.7,345.82]],"batb":[[0,4.7,31.51]],"batl":[[0,4.9,33.69],[1,5,15.88],[2,5.1,11.47]],"ltp":4.7,"tv":1974.69,"id":21580749}],"tv":12610.52}]}
{"op":"mcm","clk":"993438992","pt":1580542420484,"mc":[{"id":"1.168096552","rc":[{"trd":[[14.5,36.55]],"batb":[[0,14,7.23],[1,13.5,7.61],[2,12.5,1.87]],"batl":[[0,14.5,1.08],[1,17.5,2],[2,18.5,1.68]],"ltp":14.5,"tv":415.9,"id":26640937}],"tv":12615.09}]}
{"op":"mcm","clk":"993439300","pt":1580542424383,"mc":[{"id":"1.168096552","rc":[{"trd":[[3.05,650.93]],"batb":[[0,3.05,50.92],[1,3,78.77],[2,2.98,2]],"batl":[[0,3.1,25.64],[1,3.15,157.2],[2,3.2,43]],"ltp":3.05,"tv":3182.31,"id":18286408}],"tv":12623.08}]}
{"op":"mcm","clk":"993439448","pt":1580542426487,"mc":[{"id":"1.168096552","rc":[{"batl":[[2,3.2,45.11]],"ltp":3.05,"tv":3182.31,"id":18286408}]}]}
{"op":"mcm","clk":"993439460","pt":1580542426673,"mc":[{"id":"1.168096552","rc":[{"batl":[[0,17.5,2],[1,18.5,1.68],[2,20,8]],"ltp":14.5,"tv":415.9,"id":26640937}]}]}
{"op":"mcm","clk":"993439570","pt":1580542428277,"mc":[{"id":"1.168096552","rc":[{"batb":[[2,2.98,4]],"ltp":3.05,"tv":3182.31,"id":18286408}]}]}
{"op":"mcm","clk":"993439648","pt":1580542429468,"mc":[{"id":"1.168096552","rc":[{"trd":[[3.05,654.93]],"batb":[[0,3.05,48.93]],"ltp":3.05,"tv":3186.31,"id":18286408}],"tv":12627.08}]}
{"op":"mcm","clk":"993439699","pt":1580542430395,"mc":[{"id":"1.168096552","rc":[{"batl":[[1,18.5,2.57]],"ltp":14.5,"tv":415.9,"id":26640937}]}]}
{"op":"mcm","clk":"993439815","pt":1580542432471,"mc":[{"id":"1.168096552","rc":[{"trd":[[19,6.78],[19.5,45.78]],"batb":[[0,19,2.79]],"ltp":19.0,"tv":145.71,"id":24608298}],"tv":12633.8}]}
{"op":"mcm","clk":"993440225","pt":1580542438304,"mc":[{"id":"1.168096552","rc":[{"trd":[[3.05,658.92]],"batb":[[0,3.05,46.93]],"ltp":3.05,"tv":3190.31,"id":18286408},{"trd":[[40,37.14],[42,3.66]],"batb":[[0,38,4],[1,36,5.6],[2,34,3.78]],"ltp":40.0,"tv":85.76,"id":27706761}],"tv":12642.84}]}
{"op":"mcm","clk":"993440367","pt":1580542440492,"mc":[{"id":"1.168096552","rc":[{"batb":[[0,3,78.77],[1,2.98,4],[2,2.96,25]],"ltp":3.05,"tv":3190.31,"id":18286408}]}]}
{"op":"mcm","clk":"993440702","pt":1580542445085,"mc":[{"id":"1.168096552","rc":[{"batb":[[0,2.9,17.71]],"ltp":2.9,"tv":6830.45,"id":52106}]}]}
{"op":"mcm","clk":"993440797","pt":1580542446425,"mc":[{"id":"1.168096552","rc":[{"batl":[[0,3.05,6.72],[1,3.1,45.64],[2,3.15,157.2]],"ltp":3.05,"tv":3190.31,"id":18286408},{"batb":[[1,2.88,81]],"ltp":2.9,"tv":6830.45,"id":52106}]}]}
{"op":"mcm","clk":"993441149","pt":1580542451498,"mc":[{"id":"1.168096552","rc":[{"batl":[[0,3.1,45.64],[1,3.15,157.2],[2,3.2,45.11]],"ltp":3.05,"tv":3190.31,"id":18286408}]}]}
{"op":"mcm","clk":"993441217","pt":1580542452520,"mc":[{"id":"1.168096552","rc":[{"trd":[[3,618.94]],"batb":[[0,3,72.05]],"ltp":3.0,"tv":3203.75,"id":18286408}],"tv":12656.28}]}
{"op":"mcm","clk":"993441405","pt":1580542455108,"mc":[{"id":"1.168096552","rc":[{"batl":[[0,3.05,2],[1,3.1,45.64],[2,3.15,157.2]],"ltp":3.0,"tv":3203.75,"id":18286408}]}]}
{"op":"mcm","clk":"993441604","pt":1580542458514,"mc":[{"id":"1.168096552","rc":[{"trd":[[4.7,352.55]],"batb":[[0,4.7,28.15]],"ltp":4.7,"tv":1981.42,"id":21580749}],"tv":12663.01}]}
{"op":"mcm","clk":"993443231","pt":1580542482340,"mc":[{"id":"1.168096552","rc":[{"batl":[[0,3.05,4]],"ltp":3.0,"tv":3203.75,"id":18286408}]}]}
{"op":"mcm","clk":"993443273","pt":1580542482955,"mc":[{"id":"1.168096552","rc":[{"batb":[[0,14,11.43]],"ltp":14.5,"tv":415.9,"id":26640937}]}]}
{"op":"mcm","clk":"993443516","pt":1580542487023,"mc":[{"id":"1.168096552","rc":[{"trd":[[3.05,666.92],[3.1,499.64]],"batl":[[0,3.1,38.2],[1,3.15,157.2],[2,3.2,45.11]],"ltp":3.1,"tv":3226.64,"id":18286408},{"trd":[[17.5,3.78]],"batl":[[0,18.5,2.68],[1,20,8],[2,21,1.5]],"ltp":17.5,"tv":419.68,"id":26640937},{"trd":[[4.9,235.94]],"batl":[[0,4.9,25.56]],"ltp":4.9,"tv":1997.67,"id":21580749},{"trd":[[48,7.95],[50,6],[60,0.7],[65,0.68]],"batl":[[0,65,1.66],[1,85,1],[2,170,2]],"ltp":65.0,"tv":88.88,"id":27706761},{"trd":[[21,38.65]],"batl":[[0,21,11]],"ltp":21.0,"tv":151.83,"id":24608298}],"tv":12715.17}]}
{"op":"mcm","clk":"993443783","pt":1580542490938,"mc":[{"id":"1.168096552","rc":[{"batb":[[0,38,4.02]],"ltp":65.0,"tv":88.88,"id":27706761}]}]}
{"op":"mcm","clk":"993443926","pt":1580542492944,"mc":[{"id":"1.168096552","rc":[{"batb":[[0,14.5,2.72],[1,14,11.43],[2,13.5,7.61]],"ltp":17.5,"tv":419.68,"id":26640937},{"batb":[[0,38,4.99]],"ltp":65.0,"tv":88.88,"id":27706761}]}]}
{"op":"mcm","clk":"993444030","pt":1580542494439,"mc":[{"id":"1.168096552","rc":[{"batb":[[2,2.96,27]],"ltp":3.1,"tv":3226.64,"id":18286408}]}]}
{"op":"mcm","clk":"993444277","pt":1580542497845,"mc":[{"id":"1.168096552","rc":[{"trd":[[2.96,583.42]],"batl":[[0,2.96,22.8]],"ltp":2.96,"tv":6853.97,"id":52106}],"tv":12738.69}]}
{"op":"mcm","clk":"993444368","pt":1580542499287,"mc":[{"id":"1.168096552","rc":[{"batl":[[0,3.05,2],[1,3.1,38.2],[2,3.15,157.2]],"ltp":3.1,"tv":3226.64,"id":18286408}]}]}
{"op":"mcm","clk":"993444829","pt":1580542506165,"mc":[{"id":"1.168096552","rc":[{"batb":[[0,2.92,5.9],[1,2.9,17.71],[2,2.88,81]],"ltp":2.96,"tv":6853.97,"id":52106}]}]}
{"op":"mcm","clk":"993444932","pt":1580542507354,"mc":[{"id":"1.168096552","rc":[{"batl":[[2,240,9]],"ltp":65.0,"tv":88.88,"id":27706761}]}]}
{"op":"mcm","clk":"993445061","pt":1580542509254,"mc":[{"id":"1.168096552","rc":[{"trd":[[3.05,670.92]],"batb":[[0,3.05,22.8],[1,3,72.05],[2,2.98,4]],"batl":[[0,3.1,38.2],[1,3.15,157.2],[2,3.2,45.11]],"ltp":3.05,"tv":3230.64,"id":18286408}],"tv":12742.69}]}
{"op":"mcm","clk":"993445619","pt":1580542517203,"mc":[{"id":"1.168096552","rc":[{"trd":[[3.05,674.92]],"batb":[[0,3.05,20.8]],"ltp":3.05,"tv":3234.64,"id":18286408}],"tv":12746.69}]}
{"op":"mcm","clk":"993446948","pt":1580542535334,"mc":[{"id":"1.168096552","rc":[{"trd":[[3.05,678.92]],"batb":[[0,3.05,18.8]],"ltp":3.05,"tv":3238.64,"id":18286408}],"tv":12750.69}]}
{"op":"mcm","clk":"993448214","pt":1580542552138,"mc":[{"id":"1.168096552","rc":[{"trd":[[4.4,67.33],[4.5,315.93],[4.6,277.85],[4.7,408.83]],"batb":[[0,4.4,1.98],[1,4.3,9.79],[2,4.2,113.79]],"ltp":4.4,"tv":2197.68,"id":21580749}],"tv":12950.7}]}
{"op":"mcm","clk":"993448297","pt":1580542553427,"mc":[{"id":"1.168096552","rc":[{"trd":[[3.05,682.92]],"batb":[[0,3.05,16.8]],"ltp":3.05,"tv":3242.64,"id":18286408}],"tv":12954.7}]}
{"op":"mcm","clk":"993448359","pt":1580542554209,"mc":[{"id":"1.168096552","rc":[{"trd":[[4.8,190.09]],"ltp":4.8,"tv":2201.68,"id":21580749}],"tv":12958.7}]}
{"op":"mcm","clk":"993448430","pt":1580542555132,"mc":[{"id":"1.168096552","rc":[{"batb":[[0,4.4,4.98]],"ltp":4.8,"tv":2201.68,"id":21580749}]}]}
{"op":"mcm","clk":"993449498","pt":1580542570836,"mc":[{"id":"1.168096552","rc":[{"batb":[[0,4.5,2],[1,4.4,4.98],[2,4.3,9.79]],"batl":[[0,4.8,8.56],[1,4.9,25.56],[2,5,15.88]],"ltp":4.8,"tv":2201.68,"id":21580749}]}]}
{"op":"mcm","clk":"993450294","pt":1580542582079,"mc":[{"id":"1.168096552","rc":[{"batl":[[0,3.1,40.2]],"ltp":3.05,"tv":3242.64,"id":18286408},{"batb":[[0,4.5,4.44]],"ltp":4.8,"tv":2201.68,"id":21580749},{"batl":[[1,3.05,6],[2,3.1,63.9]],"ltp":2.96,"tv":6853.97,"id":52106}]}]}
{"op":"mcm","clk":"993450721","pt":1580542588467,"mc":[{"id":"1.168096552","rc":[{"batb":[[0,4.5,2]],"ltp":4.8,"tv":2201.68,"id":21580749}]}]}
{"op":"mcm","clk":"993450860","pt":1580542590372,"mc":[{"id":"1.168096552","rc":[{"trd":[[3.05,686.92]],"batb":[[0,3.05,14.8]],"ltp":3.05,"tv":3246.64,"id":18286408}],"tv":12962.7}]}
{"op":"mcm","clk":"993451708","pt":1580542603388,"mc":[{"id":"1.168096552","rc":[{"trd":[[4.7,412.83]],"ltp":4.7,"tv":2205.68,"id":21580749}],"tv":12966.7}]}
{"op":"mcm","clk":"993451786","pt":1580542604473,"mc":[{"id":"1.168096552","rc":[{"trd":[[4.7,416.83]],"ltp":4.7,"tv":2209.68,"id":21580749}],"tv":12970.7}]}
{"op":"mcm","clk":"993452066","pt":1580542608508,"mc":[{"id":"1.168096552","rc":[{"trd":[[3.05,690.92]],"batb":[[0,3.05,12.8]],"ltp":3.05,"tv":3250.64,"id":18286408},{"trd":[[4.7,420.83]],"ltp":4.7,"tv":2213.68,"id":21580749}],"tv":12978.7}]}
{"op":"mcm","clk":"993452081","pt":1580542608714,"mc":[{"id":"1.168096552","rc":[{"trd":[[4.8,194.09]],"batl":[[0,4.8,6.56]],"ltp":4.8,"tv":2217.68,"id":21580749}],"tv":12982.7}]}
{"op":"mcm","clk":"993452599","pt":1580542616493,"mc":[{"id":"1.168096552","rc":[{"trd":[[3.05,694.92]],"batb":[[0,3.05,10.8]],"ltp":3.05,"tv":3254.64,"id":18286408},{"batb":[[0,4.5,4]],"ltp":4.8,"tv":2217.68,"id":21580749}],"tv":12986.7}]}
{"op":"mcm","clk":"993453397","pt":1580542627428,"mc":[{"id":"1.168096552","rc":[{"batb":[[1,4.4,6.98]],"ltp":4.8,"tv":2217.68,"id":21580749}]}]}
{"op":"mcm","clk":"993453461","pt":1580542628309,"mc":[{"id":"1.168096552","rc":[{"trd":[[3.1,509.48]],"batl":[[0,3.1,35.28]],"ltp":3.1,"tv":3264.48,"id":18286408}],"tv":12996.54}]}
{"op":"mcm","clk":"993453540","pt":1580542629509,"mc":[{"id":"1.168096552","rc":[{"trd":[[4.7,430.83]],"batb":[[0,4.5,7.36]],"batl":[[0,4.7,5],[1,4.8,6.56],[2,4.9,25.56]],"ltp":4.7,"tv":2227.68,"id":21580749}],"tv":13006.54}]}
{"op":"mcm","clk":"993453606","pt":1580542630494,"mc":[{"id":"1.168096552","rc":[{"trd":[[4.7,440.83]],"batb":[[0,4.7,2],[1,4.5,7.36],[2,4.4,6.98]],"batl":[[0,4.8,6.56],[1,4.9,25.56],[2,5,15.88]],"ltp":4.7,"tv":2237.68,"id":21580749}],"tv":13016.54}]}
{"op":"mcm","clk":"993453854","pt":1580542633919,"mc":[{"id":"1.168096552","rc":[{"trd":[[3.05,698.92]],"batb":[[0,3.05,8.8]],"ltp":3.05,"tv":3268.48,"id":18286408}],"tv":13020.54}]}
{"op":"mcm","clk":"993453955","pt":1580542635318,"mc":[{"id":"1.168096552","rc":[{"batb":[[1,3,82.05]],"ltp":3.05,"tv":3268.48,"id":18286408}]}]}
{"op":"mcm","clk":"993454383","pt":1580542640609,"mc":[{"id":"1.168096552","rc":[{"batb":[[2,4.4,3.98]],"ltp":4.7,"tv":2237.68,"id":21580749}]}]}
{"op":"mcm","clk":"993454593","pt":1580542643359,"mc":[{"id":"1.168096552","rc":[{"trd":[[3.05,702.92]],"batb":[[0,3.05,6.8]],"ltp":3.05,"tv":3272.48,"id":18286408}],"tv":13024.54}]}
{"op":"mcm","clk":"993465054","pt":1580542652303,"mc":[{"id":"1.168096552","rc":[{"trd":[[3.05,706.92]],"batb":[[0,3.05,4.8]],"ltp":3.05,"tv":3276.48,"id":18286408}],"tv":13028.54}]}
{"op":"mcm","clk":"993465135","pt":1580542653447,"mc":[{"id":"1.168096552","rc":[{"batl":[[0,18.5,1.79]],"ltp":17.5,"tv":419.68,"id":26640937}]}]}
{"op":"mcm","clk":"993467106","pt":1580542683485,"mc":[{"id":"1.168096552","rc":[{"trd":[[4.7,444.83]],"batb":[[0,4.5,7.36],[1,4.4,3.98],[2,4.3,9.79]],"batl":[[0,4.7,8],[1,4.8,6.56],[2,4.9,25.56]],"ltp":4.7,"tv":2241.68,"id":21580749}],"tv":13032.54}]}
{"op":"mcm","clk":"993467212","pt":1580542685397,"mc":[{"id":"1.168096552","rc":[{"trd":[[4.7,452.83]],"batl":[[0,4.7,4]],"ltp":4.7,"tv":2249.68,"id":21580749}],"tv":13040.54}]}
{"op":"mcm","clk":"993467277","pt":1580542686502,"mc":[{"id":"1.168096552","rc":[{"trd":[[4.7,460.83]],"batl":[[0,4.8,6.56],[1,4.9,25.56],[2,5,15.88]],"ltp":4.7,"tv":2257.68,"id":21580749}],"tv":13048.54}]}
{"op":"mcm","clk":"993467314","pt":1580542687117,"mc":[{"id":"1.168096552","rc":[{"trd":[[3.05,716.52]],"batb":[[0,3,82.05],[1,2.98,4],[2,2.96,27]],"batl":[[0,3.05,5.2],[1,3.1,35.28],[2,3.15,157.2]],"ltp":3.05,"tv":3286.08,"id":18286408}],"tv":13058.14}]}
{"op":"mcm","clk":"993467392","pt":1580542688415,"mc":[{"id":"1.168096552","rc":[{"batl":[[0,3.05,7.2]],"ltp":3.05,"tv":3286.08,"id":18286408}]}]}
{"op":"mcm","clk":"993467741","pt":1580542694415,"mc":[{"id":"1.168096552","rc":[{"trd":[[3.05,730.91]],"batb":[[0,3.05,39.74],[1,3,82.05],[2,2.98,4]],"batl":[[0,3.1,35.28],[1,3.15,157.2],[2,3.2,45.11]],"ltp":3.05,"tv":3300.47,"id":18286408}],"tv":13072.53}]}
{"op":"mcm","clk":"993467944","pt":1580542697718,"mc":[{"id":"1.168096552","rc":[{"trd":[[3.05,734.91]],"batb":[[0,3.05,37.75]],"ltp":3.05,"tv":3304.47,"id":18286408}],"tv":13076.53}]}
{"op":"mcm","clk":"993468243","pt":1580542703438,"mc":[{"id":"1.168096552","rc":[{"trd":[[3.1,513.41]],"batl":[[0,3.1,33.31]],"ltp":3.1,"tv":3308.39,"id":18286408}],"tv":13080.46}]}
{"op":"mcm","clk":"993468275","pt":1580542703899,"mc":[{"id":"1.168096552","rc":[{"batb":[[0,3.05,50.94]],"ltp":3.1,"tv":3308.39,"id":18286408}]}]}
{"op":"mcm","clk":"993468401","pt":1580542706425,"mc":[{"id":"1.168096552","rc":[{"trd":[[3.05,738.91]],"batb":[[0,3.05,48.95]],"ltp":3.05,"tv":3312.39,"id":18286408}],"tv":13084.45}]}
{"op":"mcm","clk":"993468611","pt":1580542710403,"mc":[{"id":"1.168096552","rc":[{"batb":[[0,3.05,13.2]],"ltp":3.05,"tv":3312.39,"id":18286408}]}]}
{"op":"mcm","clk":"993468660","pt":1580542711227,"mc":[{"id":"1.168096552","rc":[{"batb":[[0,3,82.05],[1,2.98,7.97],[2,2.96,27]],"ltp":3.05,"tv":3312.39,"id":18286408}]}]}
{"op":"mcm","clk":"993468691","pt":1580542711845,"mc":[{"id":"1.168096552","rc":[{"batl":[[1,4.9,35.56]],"ltp":4.7,"tv":2257.68,"id":21580749}]}]}
{"op":"mcm","clk":"993468988","pt":1580542717317,"mc":[{"id":"1.168096552","rc":[{"batb":[[1,2.98,21.47]],"ltp":3.05,"tv":3312.39,"id":18286408}]}]}
{"op":"mcm","clk":"993469006","pt":1580542717726,"mc":[{"id":"1.168096552","rc":[{"batb":[[1,2.9,20.58]],"ltp":2.96,"tv":6853.97,"id":52106}]}]}
{"op":"mcm","clk":"993469926","pt":1580542734475,"mc":[{"id":"1.168096552","rc":[{"batb":[[1,2.98,17.5]],"ltp":3.05,"tv":3312.39,"id":18286408}]}]}
{"op":"mcm","clk":"993470488","pt":1580542742493,"mc":[{"id":"1.168096552","rc":[{"batl":[[0,3.05,2],[1,3.1,33.31],[2,3.15,157.2]],"ltp":3.05,"tv":3312.39,"id":18286408},{"trd":[[4.7,464.83],[4.8,198.09]],"batl":[[0,4.8,4.56]],"ltp":4.8,"tv":2265.68,"id":21580749},{"batb":[[0,19,3.7]],"ltp":21.0,"tv":151.83,"id":24608298}],"tv":13092.45}]}
{"op":"mcm","clk":"993470526","pt":1580542743055,"mc":[{"id":"1.168096552","rc":[{"batb":[[0,4.7,2],[1,4.5,7.36],[2,4.4,3.98]],"ltp":4.8,"tv":2265.68,"id":21580749}]}]}
{"op":"mcm","clk":"993470742","pt":1580542746486,"mc":[{"id":"1.168096552","rc":[{"batb":[[1,4.5,9.36]],"ltp":4.8,"tv":2265.68,"id":21580749}]}]}
{"op":"mcm","clk":"993472888","pt":1580542783827,"mc":[{"id":"1.168096552","rc":[{"trd":[[3.05,742.91]],"batl":[[0,3.1,33.31],[1,3.15,157.2],[2,3.2,45.11]],"ltp":3.05,"tv":3316.39,"id":18286408}],"tv":13096.45}]}
{"op":"mcm","clk":"993472994","pt":1580542785425,"mc":[{"id":"1.168096552","rc":[{"batl":[[0,3.05,2],[1,3.1,33.31],[2,3.15,157.2]],"ltp":3.05,"tv":3316.39,"id":18286408}]}]}
{"op":"mcm","clk":"993474578","pt":1580542813500,"mc":[{"id":"1.168096552","rc":[{"trd":[[3.05,746.91]],"batb":[[1,2.98,31.28]],"batl":[[0,3.1,33.31],[1,3.15,157.2],[2,3.2,45.11]],"ltp":3.05,"tv":3320.39,"id":18286408},{"batb":[[1,36,8.23]],"ltp":65.0,"tv":88.88,"id":27706761}],"tv":13100.45}]}
{"op":"mcm","clk":"993474641","pt":1580542814484,"mc":[{"id":"1.168096552","rc":[{"trd":[[4.7,472.93]],"batb":[[0,4.5,9.36],[1,4.4,3.98],[2,4.3,9.79]],"batl":[[0,4.7,5.95],[1,4.8,4.56],[2,4.9,35.56]],"ltp":4.7,"tv":2273.78,"id":21580749}],"tv":13108.55}]}
{"op":"mcm","clk":"993474706","pt":1580542815518,"mc":[{"id":"1.168096552","rc":[{"trd":[[4.7,476.93]],"batl":[[0,4.7,3.95]],"ltp":4.7,"tv":2277.78,"id":21580749}],"tv":13112.55}]}
{"op":"mcm","clk":"993474757","pt":1580542816300,"mc":[{"id":"1.168096552","rc":[{"trd":[[4.7,484.83]],"batb":[[0,4.7,2],[1,4.5,9.36],[2,4.4,3.98]],"batl":[[0,4.8,4.56],[1,4.9,35.56],[2,5,15.88]],"ltp":4.7,"tv":2285.68,"id":21580749},{"batb":[[0,38,8.35]],"ltp":65.0,"tv":88.88,"id":27706761}],"tv":13120.45}]}
{"op":"mcm","clk":"993475130","pt":1580542822512,"mc":[{"id":"1.168096552","rc":[{"batl":[[0,3.05,2],[1,3.1,33.31],[2,3.15,157.2]],"ltp":3.05,"tv":3320.39,"id":18286408}]}]}
{"op":"mcm","clk":"993475478","pt":1580542828319,"mc":[{"id":"1.168096552","rc":[{"trd":[[3.05,750.91],[3.1,529.41]],"batl":[[0,3.1,25.31],[1,3.15,157.2],[2,3.2,45.11]],"ltp":3.1,"tv":3340.39,"id":18286408}],"tv":13140.45}]}
{"op":"mcm","clk":"993475690","pt":1580542831516,"mc":[{"id":"1.168096552","rc":[{"batl":[[0,3.05,2],[1,3.1,25.31],[2,3.15,157.2]],"ltp":3.1,"tv":3340.39,"id":18286408}]}]}
{"op":"mcm","clk":"993475972","pt":1580542836426,"mc":[{"id":"1.168096552","rc":[{"trd":[[4.8,207.21]],"batl":[[0,4.9,35.56],[1,5,15.88],[2,5.1,11.47]],"ltp":4.8,"tv":2294.8,"id":21580749}],"tv":13149.57}]}
{"op":"mcm","clk":"993476124","pt":1580542838820,"mc":[{"id":"1.168096552","rc":[{"trd":[[3.05,754.91]],"batb":[[0,3.05,5.86],[1,3,82.05],[2,2.98,31.28]],"batl":[[0,3.1,25.31],[1,3.15,157.2],[2,3.2,45.11]],"ltp":3.05,"tv":3344.39,"id":18286408}],"tv":13153.57}]}
{"op":"mcm","clk":"993476226","pt":1580542840419,"mc":[{"id":"1.168096552","rc":[{"trd":[[3.05,758.91]],"batb":[[0,3.05,17.06],[2,2.98,4]],"ltp":3.05,"tv":3348.39,"id":18286408}],"tv":13157.57}]}
{"op":"mcm","clk":"993476504","pt":1580542845475,"mc":[{"id":"1.168096552","rc":[{"batb":[[1,4.5,10.88]],"ltp":4.8,"tv":2294.8,"id":21580749}]}]}
{"op":"mcm","clk":"993476671","pt":1580542847437,"mc":[{"id":"1.168096552","rc":[{"batl":[[0,4.8,4],[1,4.9,35.56],[2,5,15.88]],"ltp":4.8,"tv":2294.8,"id":21580749}]}]}
{"op":"mcm","clk":"993476785","pt":1580542849443,"mc":[{"id":"1.168096552","rc":[{"trd":[[3.05,762.9]],"batb":[[0,3.05,15.06]],"ltp":3.05,"tv":3352.39,"id":18286408}],"tv":13161.57}]}
{"op":"mcm","clk":"993476865","pt":1580542850471,"mc":[{"id":"1.168096552","rc":[{"batb":[[0,3.05,1.86],[2,2.98,17.5]],"ltp":3.05,"tv":3352.39,"id":18286408},{"batl":[[0,4.8,5.51]],"ltp":4.8,"tv":2294.8,"id":21580749}]}]}
{"op":"mcm","clk":"993476903","pt":1580542851040,"mc":[{"id":"1.168096552","rc":[{"batb":[[2,2.98,23.95]],"ltp":3.05,"tv":3352.39,"id":18286408},{"batl":[[1,4.9,37.07]],"ltp":4.8,"tv":2294.8,"id":21580749}]}]}
{"op":"mcm","clk":"993477271","pt":1580542858269,"mc":[{"id":"1.168096552","rc":[{"trd":[[3.05,766.62]],"batb":[[0,3,82.05],[1,2.98,17.5],[2,2.96,27]],"batl":[[0,3.1,25.45]],"ltp":3.05,"tv":3356.1,"id":18286408}],"tv":13165.29}]}
{"op":"mcm","clk":"993477307","pt":1580542858784,"mc":[{"id":"1.168096552","rc":[{"batb":[[0,14.5,3.9]],"ltp":17.5,"tv":419.68,"id":26640937}]}]}
{"op":"mcm","clk":"993477587","pt":1580542863484,"mc":[{"id":"1.168096552","rc":[{"batb":[[1,2.98,31.28]],"ltp":3.05,"tv":3356.1,"id":18286408}]}]}
{"op":"mcm","clk":"993482310","pt":1580542947362,"mc":[{"id":"1.168096552","rc":[{"trd":[[3.05,766.9],[3.1,577.93]],"batb":[[0,3.05,20.33],[1,3,82.05],[2,2.98,31.28]],"batl":[[0,3.1,1.05],[2,3.2,50.04]],"ltp":3.1,"tv":3404.9,"id":18286408}],"tv":13214.09}]}
{"op":"mcm","clk":"993482363","pt":1580542948185,"mc":[{"id":"1.168096552","rc":[{"batb":[[0,3.05,46.4],[2,2.98,17.78]],"ltp":3.1,"tv":3404.9,"id":18286408}]}]}
{"op":"mcm","clk":"993482446","pt":1580542949477,"mc":[{"id":"1.168096552","rc":[{"trd":[[3.1,580.03]],"batb":[[0,3.1,14.07],[1,3.05,46.4],[2,3,77]],"batl":[[0,3.15,157.2],[1,3.2,45.11],[2,3.25,320]],"ltp":3.1,"tv":3407.0,"id":18286408}],"tv":13216.19}]}
{"op":"mcm","clk":"993482504","pt":1580542950478,"mc":[{"id":"1.168096552","rc":[{"batb":[[2,3,79]],"ltp":3.1,"tv":3407.0,"id":18286408}]}]}
{"op":"mcm","clk":"993483529","pt":1580542966903,"mc":[{"id":"1.168096552","rc":[{"batl":[[0,3.15,159.2]],"ltp":3.1,"tv":3407.0,"id":18286408}]}]}
{"op":"mcm","clk":"993486222","pt":1580543008976,"mc":[{"id":"1.168096552","rc":[{"batl":[[0,4.8,7.51]],"ltp":4.8,"tv":2294.8,"id":21580749}]}]}
{"op":"mcm","clk":"993486452","pt":1580543014310,"mc":[{"id":"1.168096552","rc":[{"batb":[[0,40,1.42],[1,38,7.36],[2,36,8.23]],"ltp":65.0,"tv":88.88,"id":27706761}]}]}
{"op":"mcm","clk":"993488052","pt":1580543041436,"mc":[{"id":"1.168096552","rc":[{"batb":[[2,36,10.5]],"ltp":65.0,"tv":88.88,"id":27706761}]}]}
{"op":"mcm","clk":"993488225","pt":1580543044217,"mc":[{"id":"1.168096552","rc":[{"batl":[[0,4.8,3.51]],"ltp":4.8,"tv":2294.8,"id":21580749}]}]}
{"op":"mcm","clk":"993488578","pt":1580543051030,"mc":[{"id":"1.168096552","rc":[{"trd":[[4.7,488.83]],"batb":[[0,4.5,10.88],[1,4.4,3.98],[2,4.3,9.79]],"batl":[[0,4.7,8],[1,4.8,3.51],[2,4.9,37.07]],"ltp":4.7,"tv":2298.8,"id":21580749}],"tv":13220.19}]}
{"op":"mcm","clk":"993488663","pt":1580543052319,"mc":[{"id":"1.168096552","rc":[{"trd":[[4.7,492.83]],"batl":[[0,4.7,6]],"ltp":4.7,"tv":2302.8,"id":21580749}],"tv":13224.19}]}
{"op":"mcm","clk":"993488717","pt":1580543053450,"mc":[{"id":"1.168096552","rc":[{"trd":[[4.7,496.83]],"batl":[[0,4.7,4]],"ltp":4.7,"tv":2306.8,"id":21580749}],"tv":13228.19}]}
{"op":"mcm","clk":"993488743","pt":1580543054015,"mc":[{"id":"1.168096552","rc":[{"trd":[[4.7,504.83]],"batl":[[0,4.8,3.51],[1,4.9,37.07],[2,5,15.88]],"ltp":4.7,"tv":2314.8,"id":21580749}],"tv":13236.19}]}
{"op":"mcm","clk":"993489601","pt":1580543069491,"mc":[{"id":"1.168096552","rc":[{"batl":[[0,2.94,25],[1,2.96,22.8],[2,3.05,6]],"ltp":2.96,"tv":6853.97,"id":52106}]}]}
{"op":"mcm","clk":"993490192","pt":1580543078371,"mc":[{"id":"1.168096552","rc":[{"batb":[[1,3.05,71.4]],"ltp":3.1,"tv":3407.0,"id":18286408}]}]}
{"op":"mcm","clk":"993490639","pt":1580543084486,"mc":[{"id":"1.168096552","rc":[{"batb":[[2,3,104]],"ltp":3.1,"tv":3407.0,"id":18286408}]}]}
{"op":"mcm","clk":"993490872","pt":1580543088382,"mc":[{"id":"1.168096552","rc":[{"batb":[[0,3.1,39.07]],"ltp":3.1,"tv":3407.0,"id":18286408}]}]}
{"op":"mcm","clk":"993490930","pt":1580543089403,"mc":[{"id":"1.168096552","rc":[{"trd":[[2.92,1085.28]],"batb":[[0,2.9,20.58],[1,2.88,81],[2,2.86,12.13]],"batl":[[0,2.92,8.28],[1,2.94,25],[2,2.96,22.8]],"ltp":2.92,"tv":6865.77,"id":52106}],"tv":13247.98}]}
{"op":"mcm","clk":"993491010","pt":1580543090587,"mc":[{"id":"1.168096552","rc":[{"batb":[[1,2.88,87.91]],"ltp":2.92,"tv":6865.77,"id":52106}]}]}
{"op":"mcm","clk":"993491369","pt":1580543096812,"mc":[{"id":"1.168096552","rc":[{"trd":[[4.8,210.23]],"batl":[[0,4.7,2]],"ltp":4.8,"tv":2317.82,"id":21580749}],"tv":13251.01}]}
{"op":"mcm","clk":"993491484","pt":1580543098508,"mc":[{"id":"1.168096552","rc":[{"trd":[[4.7,508.83]],"batl":[[0,4.9,37.07],[1,5,15.88],[2,5.1,11.47]],"ltp":4.7,"tv":2321.82,"id":21580749}],"tv":13255.01}]}
{"op":"mcm","clk":"993492867","pt":1580543118475,"mc":[{"id":"1.168096552","rc":[{"batl":[[0,4.8,4],[1,4.9,37.07],[2,5,15.88]],"ltp":4.7,"tv":2321.82,"id":21580749}]}]}
{"op":"mcm","clk":"993494411","pt":1580543141462,"mc":[{"id":"1.168096552","rc":[{"batb":[[0,3.1,48.38]],"ltp":3.1,"tv":3407.0,"id":18286408},{"batb":[[0,14.5,5.89]],"ltp":17.5,"tv":419.68,"id":26640937},{"batb":[[0,4.5,17.3]],"ltp":4.7,"tv":2321.82,"id":21580749},{"batb":[[1,38,8.12]],"ltp":65.0,"tv":88.88,"id":27706761},{"batb":[[0,2.9,30.54]],"ltp":2.92,"tv":6865.77,"id":52106},{"batb":[[0,19,5.22]],"ltp":21.0,"tv":151.83,"id":24608298}]}]}
{"op":"mcm","clk":"993495370","pt":1580543158243,"mc":[{"id":"1.168096552","rc":[{"batb":[[1,2.88,91.13]],"ltp":2.92,"tv":6865.77,"id":52106}]}]}
{"op":"mcm","clk":"993497879","pt":1580543194330,"mc":[{"id":"1.168096552","rc":[{"batb":[[0,4.6,3.75],[1,4.5,17.3],[2,4.4,3.98]],"ltp":4.7,"tv":2321.82,"id":21580749}]}]}
{"op":"mcm","clk":"993498961","pt":1580543206445,"mc":[{"id":"1.168096552","rc":[{"trd":[[2.9,235.55]],"batb":[[0,2.88,91.13],[1,2.86,25.75],[2,2.84,7.11]],"batl":[[0,2.9,2.47],[1,2.92,8.28],[2,2.94,25]],"ltp":2.9,"tv":6926.83,"id":52106}],"tv":13316.07}]}
{"op":"mcm","clk":"993499080","pt":1580543208249,"mc":[{"id":"1.168096552","rc":[{"batb":[[0,2.88,81]],"ltp":2.9,"tv":6926.83,"id":52106},{"batb":[[0,19,8.58]],"ltp":21.0,"tv":151.83,"id":24608298}]}]}
{"op":"mcm","clk":"993499399","pt":1580543213420,"mc":[{"id":"1.168096552","rc":[{"batl":[[0,4.7,10],[1,4.8,4],[2,4.9,37.07]],"ltp":4.7,"tv":2321.82,"id":21580749}]}]}
{"op":"mcm","clk":"993499518","pt":1580543215225,"mc":[{"id":"1.168096552","rc":[{"trd":[[4.7,516.83]],"batl":[[0,4.7,6]],"ltp":4.7,"tv":2329.82,"id":21580749}],"tv":13324.07}]}
{"op":"mcm","clk":"993499630","pt":1580543216463,"mc":[{"id":"1.168096552","rc":[{"trd":[[4.7,524.83]],"batl":[[0,4.7,2]],"ltp":4.7,"tv":2337.82,"id":21580749}],"tv":13332.07}]}
{"op":"mcm","clk":"993499827","pt":1580543218446,"mc":[{"id":"1.168096552","rc":[{"trd":[[4.7,528.83]],"batl":[[0,4.8,4],[1,4.9,37.07],[2,5,15.88]],"ltp":4.7,"tv":2341.82,"id":21580749}],"tv":13336.07}]}
{"op":"mcm","clk":"993501604","pt":1580543244482,"mc":[{"id":"1.168096552","rc":[{"batb":[[2,4.4,8.98]],"ltp":4.7,"tv":2341.82,"id":21580749}]}]}
{"op":"mcm","clk":"993501642","pt":1580543244946,"mc":[{"id":"1.168096552","rc":[{"batb":[[0,4.6,8.35]],"ltp":4.7,"tv":2341.82,"id":21580749}]}]}
{"op":"mcm","clk":"993501727","pt":1580543246485,"mc":[{"id":"1.168096552","rc":[{"batb":[[1,4.5,22.3]],"ltp":4.7,"tv":2341.82,"id":21580749}]}]}
{"op":"mcm","clk":"993502040","pt":1580543251375,"mc":[{"id":"1.168096552","rc":[{"trd":[[4.6,278.19]],"batb":[[0,4.6,8.19]],"ltp":4.6,"tv":2342.16,"id":21580749},{"batb":[[0,2.88,91.92]],"ltp":2.9,"tv":6926.83,"id":52106}],"tv":13336.41}]}
{"op":"mcm","clk":"993504224","pt":1580543280224,"mc":[{"id":"1.168096552","rc":[{"batb":[[2,2.82,7.34]],"ltp":2.9,"tv":6926.83,"id":52106}]}]}
{"op":"mcm","clk":"993504297","pt":1580543281206,"mc":[{"id":"1.168096552","rc":[{"batb":[[1,14,9.91]],"ltp":17.5,"tv":419.68,"id":26640937},{"trd":[[2.9,240.23]],"batl":[[0,2.92,8.41],[1,2.94,25],[2,2.96,22.8]],"ltp":2.9,"tv":6931.52,"id":52106}],"tv":13341.09}]}
{"op":"mcm","clk":"993504363","pt":1580543282338,"mc":[{"id":"1.168096552","rc":[{"batb":[[1,18.5,17]],"ltp":21.0,"tv":151.83,"id":24608298}]}]}
{"op":"mcm","clk":"993504585","pt":1580543285503,"mc":[{"id":"1.168096552","rc":[{"batl":[[0,4.9,37.07],[1,5,15.88],[2,5.1,11.47]],"ltp":4.6,"tv":2342.16,"id":21580749}]}]}
{"op":"mcm","clk":"993505744","pt":1580543301762,"mc":[{"id":"1.168096552","rc":[{"trd":[[4.9,236.26]],"batl":[[0,4.9,36.91]],"ltp":4.9,"tv":2342.48,"id":21580749}],"tv":13341.41}]}
{"op":"mcm","clk":"993505910","pt":1580543304443,"mc":[{"id":"1.168096552","rc":[{"batb":[[2,12.5,1.92]],"ltp":17.5,"tv":419.68,"id":26640937}]}]}
{"op":"mcm","clk":"993506453","pt":1580543313421,"mc":[{"id":"1.168096552","rc":[{"batb":[[0,15,6.79],[1,14.5,5.89],[2,14,9.91]],"ltp":17.5,"tv":419.68,"id":26640937}]}]}
{"op":"mcm","clk":"993506575","pt":1580543315433,"mc":[{"id":"1.168096552","rc":[{"batb":[[0,15,10.99],[2,14,5.7]],"ltp":17.5,"tv":419.68,"id":26640937}]}]}
{"op":"mcm","clk":"993507760","pt":1580543333261,"mc":[{"id":"1.168096552","rc":[{"batb":[[1,14.5,3.17]],"ltp":17.5,"tv":419.68,"id":26640937}]}]}
{"op":"mcm","clk":"993508713","pt":1580543348318,"mc":[{"id":"1.168096552","rc":[{"trd":[[2.9,240.49]],"batb":[[0,2.9,2.89],[1,2.88,91.92],[2,2.86,25.75]],"batl":[[0,2.92,11.28]],"ltp":2.9,"tv":6931.78,"id":52106}],"tv":13341.67}]}
{"op":"mcm","clk":"993508901","pt":1580543350479,"mc":[{"id":"1.168096552","rc":[{"batb":[[2,2.86,12.13]],"ltp":2.9,"tv":6931.78,"id":52106}]}]}
{"op":"mcm","clk":"993509258","pt":1580543355306,"mc":[{"id":"1.168096552","rc":[{"batb":[[0,4.6,5.09],[1,4.5,25.45]],"batl":[[0,4.7,10],[1,4.9,36.91],[2,5,15.88]],"ltp":4.9,"tv":2342.48,"id":21580749}]}]}
{"op":"mcm","clk":"993509315","pt":1580543356128,"mc":[{"id":"1.168096552","rc":[{"trd":[[4.7,532.83]],"batl":[[0,4.7,8]],"ltp":4.7,"tv":2346.48,"id":21580749}],"tv":13345.67}]}
{"op":"mcm","clk":"993509391","pt":1580543357410,"mc":[{"id":"1.168096552","rc":[{"trd":[[4.7,536.83]],"batl":[[0,4.7,6]],"ltp":4.7,"tv":2350.48,"id":21580749}],"tv":13349.67}]}
{"op":"mcm","clk":"993509511","pt":1580543359112,"mc":[{"id":"1.168096552","rc":[{"trd":[[4.7,538.77]],"batl":[[0,4.7,5.03]],"ltp":4.7,"tv":2352.42,"id":21580749}],"tv":13351.61}]}
{"op":"mcm","clk":"993509595","pt":1580543360296,"mc":[{"id":"1.168096552","rc":[{"trd":[[4.7,548.83]],"batb":[[0,4.7,8.68],[1,4.6,5.09],[2,4.5,25.45]],"batl":[[0,4.9,36.91],[1,5,15.88],[2,5.1,11.47]],"ltp":4.7,"tv":2362.48,"id":21580749}],"tv":13361.67}]}
{"op":"mcm","clk":"993509648","pt":1580543361216,"mc":[{"id":"1.168096552","rc":[{"batb":[[0,4.7,9.65]],"ltp":4.7,"tv":2362.48,"id":21580749}]}]}
{"op":"mcm","clk":"993509685","pt":1580543361835,"mc":[{"id":"1.168096552","rc":[{"batb":[[1,4.6,7.25]],"ltp":4.7,"tv":2362.48,"id":21580749}]}]}
{"op":"mcm","clk":"993509977","pt":1580543367222,"mc":[{"id":"1.168096552","rc":[{"trd":[[2.9,246.27]],"batb":[[0,2.88,91.92],[1,2.86,12.13],[2,2.82,7.34]],"batl":[[0,2.9,5.51],[1,2.92,11.28],[2,2.94,25]],"ltp":2.9,"tv":6937.56,"id":52106}],"tv":13367.45}]}
{"op":"mcm","clk":"993510080","pt":1580543369106,"mc":[{"id":"1.168096552","rc":[{"batb":[[1,2.86,25.99]],"ltp":2.9,"tv":6937.56,"id":52106}]}]}
{"op":"mcm","clk":"993510531","pt":1580543376653,"mc":[{"id":"1.168096552","rc":[{"batl":[[1,3.2,24.11]],"ltp":3.1,"tv":3407.0,"id":18286408}]}]}
{"op":"mcm","clk":"993511182","pt":1580543387368,"mc":[{"id":"1.168096552","rc":[{"trd":[[4.7,568.13]],"batb":[[0,4.6,13.44],[1,4.5,25.45],[2,4.4,8.98]],"batl":[[0,4.9,37.26]],"ltp":4.7,"tv":2381.78,"id":21580749}],"tv":13386.75}]}
{"op":"mcm","clk":"993512555","pt":1580543407072,"mc":[{"id":"1.168096552","rc":[{"trd":[[2.88,449.99]],"batb":[[0,2.88,81.78]],"ltp":2.88,"tv":6957.83,"id":52106}],"tv":13407.03}]}
{"op":"mcm","clk":"993513386","pt":1580543418971,"mc":[{"id":"1.168096552","rc":[{"trd":[[4.7,568.84]],"batb":[[0,4.7,3.85],[1,4.6,13.44],[2,4.5,22.09]],"batl":[[0,4.9,36.91]],"ltp":4.7,"tv":2382.48,"id":21580749}],"tv":13407.73}]}
{"op":"mcm","clk":"993513524","pt":1580543420776,"mc":[{"id":"1.168096552","rc":[{"batl":[[0,3.15,180.2]],"ltp":3.1,"tv":3407.0,"id":18286408}]}]}
{"op":"mcm","clk":"993514476","pt":1580543435395,"mc":[{"id":"1.168096552","rc":[{"batb":[[0,15.5,1.11],[1,15,10.99],[2,14.5,1.99]],"ltp":17.5,"tv":419.68,"id":26640937}]}]}
{"op":"mcm","clk":"993516912","pt":1580543469826,"mc":[{"id":"1.168096552","rc":[{"batl":[[1,3.2,22]],"ltp":3.1,"tv":3407.0,"id":18286408}]}]}
{"op":"mcm","clk":"993517344","pt":1580543476229,"mc":[{"id":"1.168096552","rc":[{"trd":[[15,46.52],[15.5,2.22]],"batb":[[0,14.5,1.99],[1,14,13.88],[2,12.5,7.6]],"batl":[[0,15,12.9],[1,18.5,1.79],[2,20,8]],"ltp":15.0,"tv":443.88,"id":26640937}],"tv":13431.93}]}
{"op":"mcm","clk":"993517479","pt":1580543478224,"mc":[{"id":"1.168096552","rc":[{"trd":[[14.5,40.53]],"batb":[[0,14,5.7],[1,12.5,4.22],[2,12,23.55]],"batl":[[0,14.5,1],[1,15,12.9],[2,18.5,1.79]],"ltp":14.5,"tv":447.86,"id":26640937}],"tv":13435.91}]}
{"op":"mcm","clk":"993517573","pt":1580543479520,"mc":[{"id":"1.168096552","rc":[{"trd":[[14.5,42.53]],"batb":[[0,14,6.18]],"batl":[[0,15,12.9],[1,18.5,1.79],[2,20,8]],"ltp":14.5,"tv":449.86,"id":26640937},{"trd":[[2.9,257.3]],"batb":[[0,2.9,1.45],[1,2.88,81.78],[2,2.86,25.99]],"batl":[[0,2.92,11.28],[1,2.94,25],[2,2.96,22.8]],"ltp":2.9,"tv":6968.86,"id":52106}],"tv":13448.93}]}
{"op":"mcm","clk":"993517615","pt":1580543480242,"mc":[{"id":"1.168096552","rc":[{"batb":[[1,12.5,6.43]],"ltp":14.5,"tv":449.86,"id":26640937}]}]}
{"op":"mcm","clk":"993518141","pt":1580543488480,"mc":[{"id":"1.168096552","rc":[{"batb":[[0,13,6.23],[1,12.5,6.38]],"ltp":14.5,"tv":449.86,"id":26640937}]}]}
{"op":"mcm","clk":"993518213","pt":1580543489351,"mc":[{"id":"1.168096552","rc":[{"batb":[[2,12,26.41]],"ltp":14.5,"tv":449.86,"id":26640937},{"batl":[[0,4.8,8.5],[1,4.9,46.91],[2,5,15.88]],"ltp":4.7,"tv":2382.48,"id":21580749}]}]}
{"op":"mcm","clk":"993518282","pt":1580543490482,"mc":[{"id":"1.168096552","rc":[{"batb":[[1,12.5,1.87]],"ltp":14.5,"tv":449.86,"id":26640937},{"batb":[[0,4.7,38.39]],"ltp":4.7,"tv":2382.48,"id":21580749}]}]}
{"op":"mcm","clk":"993518599","pt":1580543495463,"mc":[{"id":"1.168096552","rc":[{"batb":[[0,13.5,1.7],[1,13,5.7],[2,12.5,1.87]],"ltp":14.5,"tv":449.86,"id":26640937}]}]}
{"op":"mcm","clk":"993519293","pt":1580543506496,"mc":[{"id":"1.168096552","rc":[{"batb":[[0,4.7,3.85]],"ltp":4.7,"tv":2382.48,"id":21580749}]}]}
{"op":"mcm","clk":"993519367","pt":1580543507477,"mc":[{"id":"1.168096552","rc":[{"batb":[[0,3.1,61.67]],"ltp":3.1,"tv":3407.0,"id":18286408},{"batb":[[0,2.9,15.64]],"ltp":2.9,"tv":6968.86,"id":52106}]}]}
{"op":"mcm","clk":"993519443","pt":1580543508456,"mc":[{"id":"1.168096552","rc":[{"batb":[[0,14,3.41],[1,13.5,1.23],[2,13,5.7]],"ltp":14.5,"tv":449.86,"id":26640937},{"batb":[[0,4.7,12.6]],"ltp":4.7,"tv":2382.48,"id":21580749},{"batb":[[0,40,2.95]],"ltp":65.0,"tv":88.88,"id":27706761},{"batb":[[1,2.88,86.63],[2,2.86,12.13]],"ltp":2.9,"tv":6968.86,"id":52106},{"batb":[[0,19.5,3.14],[1,19,8.58],[2,18.5,17]],"ltp":21.0,"tv":151.83,"id":24608298}]}]}
{"op":"mcm","clk":"993520669","pt":1580543525987,"mc":[{"id":"1.168096552","rc":[{"batb":[[0,19.5,20.14],[2,18,3.67]],"ltp":21.0,"tv":151.83,"id":24608298}]}]}
{"op":"mcm","clk":"993520840","pt":1580543528512,"mc":[{"id":"1.168096552","rc":[{"batb":[[0,20,3.36],[1,19.5,20.14],[2,19,8.58]],"ltp":21.0,"tv":151.83,"id":24608298}]}]}
{"op":"mcm","clk":"993520928","pt":1580543529494,"mc":[{"id":"1.168096552","rc":[{"batb":[[2,19,5.22]],"ltp":21.0,"tv":151.83,"id":24608298}]}]}
{"op":"mcm","clk":"993521578","pt":1580543538412,"mc":[{"id":"1.168096552","rc":[{"trd":[[2.92,1107.85]],"batl":[[0,2.94,25],[1,2.96,22.8],[2,3.05,6]],"ltp":2.92,"tv":6991.42,"id":52106},{"batb":[[0,20,21.59]],"ltp":21.0,"tv":151.83,"id":24608298}],"tv":13471.5}]}
{"op":"mcm","clk":"993521664","pt":1580543539493,"mc":[{"id":"1.168096552","rc":[{"batb":[[0,2.92,5.04],[1,2.9,15.64],[2,2.88,75.7]],"ltp":2.92,"tv":6991.42,"id":52106}]}]}
{"op":"mcm","clk":"993521803","pt":1580543541501,"mc":[{"id":"1.168096552","rc":[{"batb":[[2,2.88,70.86]],"ltp":2.92,"tv":6991.42,"id":52106}]}]}
{"op":"mcm","clk":"993532550","pt":1580543554414,"mc":[{"id":"1.168096552","rc":[{"trd":[[4.7,588.84]],"batb":[[0,4.7,2.6]],"ltp":4.7,"tv":2402.48,"id":21580749},{"batb":[[0,20,3.36]],"ltp":21.0,"tv":151.83,"id":24608298}],"tv":13491.5}]}
{"op":"mcm","clk":"993534952","pt":1580543587871,"mc":[{"id":"1.168096552","rc":[{"batb":[[2,4.5,24.09]],"ltp":4.7,"tv":2402.48,"id":21580749}]}]}
{"op":"mcm","clk":"993535928","pt":1580543602395,"mc":[{"id":"1.168096552","rc":[{"trd":[[2.92,1115.85]],"batb":[[0,2.92,1.04]],"ltp":2.92,"tv":6999.42,"id":52106},{"batb":[[0,20,21.59]],"ltp":21.0,"tv":151.83,"id":24608298}],"tv":13499.5}]}
{"op":"mcm","clk":"993535952","pt":1580543602702,"mc":[{"id":"1.168096552","rc":[{"batb":[[2,2.88,52.2]],"ltp":2.92,"tv":6999.42,"id":52106}]}]}
{"op":"mcm","clk":"993536046","pt":1580543603888,"mc":[{"id":"1.168096552","rc":[{"batb":[[0,4.7,7.65]],"ltp":4.7,"tv":2402.48,"id":21580749}]}]}
{"op":"mcm","clk":"993537653","pt":1580543626498,"mc":[{"id":"1.168096552","rc":[{"trd":[[3.1,624.03]],"batb":[[0,3.1,39.66]],"ltp":3.1,"tv":3451.01,"id":18286408},{"trd":[[2.92,1117.94]],"batb":[[0,2.9,15.64],[1,2.88,57.86],[2,2.86,12.13]],"batl":[[0,2.92,10.59],[1,2.94,25],[2,2.96,22.8]],"ltp":2.92,"tv":7001.51,"id":52106}],"tv":13545.59}]}
{"op":"mcm","clk":"993537800","pt":1580543628514,"mc":[{"id":"1.168096552","rc":[{"batb":[[1,2.88,76.52]],"ltp":2.92,"tv":7001.51,"id":52106}]}]}
{"op":"mcm","clk":"993538065","pt":1580543631509,"mc":[{"id":"1.168096552","rc":[{"batb":[[0,42,4.2],[1,40,2.95],[2,38,4.76]],"ltp":65.0,"tv":88.88,"id":27706761}]}]}
{"op":"mcm","clk":"993538384","pt":1580543635323,"mc":[{"id":"1.168096552","rc":[{"batl":[[1,3.2,27]],"ltp":3.1,"tv":3451.01,"id":18286408}]}]}
{"op":"mcm","clk":"993539578","pt":1580543650232,"mc":[{"id":"1.168096552","rc":[{"batb":[[1,40,1.97]],"ltp":65.0,"tv":88.88,"id":27706761}]}]}
{"op":"mcm","clk":"993540151","pt":1580543657918,"mc":[{"id":"1.168096552","rc":[{"batb":[[1,40,4.17]],"ltp":65.0,"tv":88.88,"id":27706761}]}]}
{"op":"mcm","clk":"993541040","pt":1580543670065,"mc":[{"id":"1.168096552","rc":[{"batb":[[0,42,9.09],[2,36,11.26]],"ltp":65.0,"tv":88.88,"id":27706761}]}]}
{"op":"mcm","clk":"993541285","pt":1580543673481,"mc":[{"id":"1.168096552","rc":[{"batl":[[1,4.9,56.91]],"ltp":4.7,"tv":2402.48,"id":21580749}]}]}
{"op":"mcm","clk":"993541837","pt":1580543679994,"mc":[{"id":"1.168096552","rc":[{"batb":[[0,3.1,73.27]],"ltp":3.1,"tv":3451.01,"id":18286408},{"batb":[[0,2.9,33.29]],"ltp":2.92,"tv":7001.51,"id":52106}]}]}
{"op":"mcm","clk":"993542441","pt":1580543687353,"mc":[{"id":"1.168096552","rc":[{"batb":[[2,38,3.87]],"ltp":65.0,"tv":88.88,"id":27706761},{"batb":[[1,2.88,81.88]],"ltp":2.92,"tv":7001.51,"id":52106}]}]}
{"op":"mcm","clk":"993542459","pt":1580543687561,"mc":[{"id":"1.168096552","rc":[{"batb":[[1,40,1.97]],"ltp":65.0,"tv":88.88,"id":27706761}]}]}
{"op":"mcm","clk":"993544231","pt":1580543709004,"mc":[{"id":"1.168096552","rc":[{"batb":[[0,42,5.09]],"ltp":65.0,"tv":88.88,"id":27706761}]}]}
{"op":"mcm","clk":"993544343","pt":1580543710406,"mc":[{"id":"1.168096552","rc":[{"batl":[[1,4.9,66.91]],"ltp":4.7,"tv":2402.48,"id":21580749}]}]}
{"op":"mcm","clk":"993544788","pt":1580543716503,"mc":[{"id":"1.168096552","rc":[{"trd":[[4.7,604.12]],"batb":[[0,4.6,13.44],[1,4.5,24.09],[2,4.4,8.98]],"batl":[[0,4.7,2.36],[1,4.8,8.5],[2,4.9,66.91]],"ltp":4.7,"tv":2417.77,"id":21580749}],"tv":13560.87}]}
{"op":"mcm","clk":"993544816","pt":1580543716914,"mc":[{"id":"1.168096552","rc":[{"trd":[[3.15,771.06]],"batl":[[0,3.15,176.68]],"ltp":3.15,"tv":3458.05,"id":18286408},{"trd":[[15,48]],"batl":[[0,15,12.16]],"ltp":15.0,"tv":451.34,"id":26640937},{"trd":[[4.7,608.84]],"batl":[[0,4.8,8.5],[1,4.9,66.91],[2,5,15.88]],"ltp":4.7,"tv":2422.49,"id":21580749},{"trd":[[65,1.02]],"batl":[[0,65,1.49]],"ltp":65.0,"tv":89.22,"id":27706761},{"trd":[[2.92,1125.54]],"batl":[[0,2.92,6.79]],"ltp":2.92,"tv":7009.11,"id":52106},{"trd":[[21,39.71]],"batl":[[0,21,10.47]],"ltp":21.0,"tv":152.89,"id":24608298}],"tv":13583.12}]}
{"op":"mcm","clk":"993544954","pt":1580543718515,"mc":[{"id":"1.168096552","rc":[{"batb":[[2,3,107]],"ltp":3.15,"tv":3458.05,"id":18286408},{"batb":[[0,4.7,2],[1,4.6,13.44],[2,4.5,24.09]],"ltp":4.7,"tv":2422.49,"id":21580749}]}]}
{"op":"mcm","clk":"993545003","pt":1580543719030,"mc":[{"id":"1.168096552","rc":[{"batb":[[1,13,5.76],[2,12.5,1.87]],"ltp":15.0,"tv":451.34,"id":26640937},{"batb":[[1,40,3.97]],"ltp":65.0,"tv":89.22,"id":27706761}]}]}
{"op":"mcm","clk":"993545812","pt":1580543729423,"mc":[{"id":"1.168096552","rc":[{"batb":[[0,20,3.36]],"ltp":21.0,"tv":152.89,"id":24608298}]}]}
{"op":"mcm","clk":"993545889","pt":1580543730507,"mc":[{"id":"1.168096552","rc":[{"trd":[[2.92,1139.12],[2.94,421.5],[2.96,592.9]],"batl":[[0,2.96,18.06],[1,3.05,6],[2,3.1,63.9]],"ltp":2.96,"tv":7082.17,"id":52106}],"tv":13656.18}]}
{"op":"mcm","clk":"993545957","pt":1580543731412,"mc":[{"id":"1.168096552","rc":[{"batl":[[1,3,2.66],[2,3.05,9.39]],"ltp":2.96,"tv":7082.17,"id":52106}]}]}
{"op":"mcm","clk":"993546264","pt":1580543735129,"mc":[{"id":"1.168096552","rc":[{"batl":[[1,20,8.11],[2,21,1.5]],"ltp":15.0,"tv":451.34,"id":26640937}]}]}
{"op":"mcm","clk":"993548244","pt":1580543759753,"mc":[{"id":"1.168096552","rc":[{"trd":[[2.9,292.58]],"batb":[[0,2.9,15.64]],"ltp":2.9,"tv":7117.46,"id":52106}],"tv":13691.47}]}
{"op":"mcm","clk":"993548371","pt":1580543761253,"mc":[{"id":"1.168096552","rc":[{"batl":[[1,3.05,6],[2,3.1,63.9]],"ltp":2.9,"tv":7117.46,"id":52106}]}]}
{"op":"mcm","clk":"993548897","pt":1580543767486,"mc":[{"id":"1.168096552","rc":[{"batb":[[0,4.7,6.2]],"ltp":4.7,"tv":2422.49,"id":21580749}]}]}
{"op":"mcm","clk":"993549354","pt":1580543773086,"mc":[{"id":"1.168096552","rc":[{"trd":[[21,43.07]],"batl":[[0,21,8.79]],"ltp":21.0,"tv":156.25,"id":24608298}],"tv":13694.83}]}
{"op":"mcm","clk":"993549508","pt":1580543775088,"mc":[{"id":"1.168096552","rc":[{"trd":[[3.1,630.03]],"batb":[[0,3.1,70.27]],"ltp":3.1,"tv":3464.05,"id":18286408}],"tv":13700.83}]}
{"op":"mcm","clk":"993549777","pt":1580543778485,"mc":[{"id":"1.168096552","rc":[{"batb":[[2,3,104]],"ltp":3.1,"tv":3464.05,"id":18286408}]}]}
{"op":"mcm","clk":"993549862","pt":1580543779461,"mc":[{"id":"1.168096552","rc":[{"batb":[[0,3.1,80.27]],"ltp":3.1,"tv":3464.05,"id":18286408}]}]}
{"op":"mcm","clk":"993550719","pt":1580543790196,"mc":[{"id":"1.168096552","rc":[{"batb":[[1,2.88,76.52]],"ltp":2.9,"tv":7117.46,"id":52106}]}]}
{"op":"mcm","clk":"993550987","pt":1580543793482,"mc":[{"id":"1.168096552","rc":[{"batl":[[0,2.96,20.06]],"ltp":2.9,"tv":7117.46,"id":52106}]}]}
{"op":"mcm","clk":"993552054","pt":1580543807433,"mc":[{"id":"1.168096552","rc":[{"trd":[[20,5.48]],"batb":[[0,20,2.93]],"ltp":20.0,"tv":157.11,"id":24608298}],"tv":13701.68}]}
{"op":"mcm","clk":"993552383","pt":1580543811229,"mc":[{"id":"1.168096552","rc":[{"batl":[[0,4.8,18.5]],"ltp":4.7,"tv":2422.49,"id":21580749}]}]}
{"op":"mcm","clk":"993553072","pt":1580543819427,"mc":[{"id":"1.168096552","rc":[{"trd":[[4.7,621.24]],"batb":[[0,4.6,13.44],[1,4.5,24.09],[2,4.4,8.98]],"batl":[[0,4.7,13.8],[1,4.8,18.5],[2,4.9,66.91]],"ltp":4.7,"tv":2434.89,"id":21580749}],"tv":13714.08}]}
{"op":"mcm","clk":"993553145","pt":1580543820349,"mc":[{"id":"1.168096552","rc":[{"batl":[[0,4.7,23.8]],"ltp":4.7,"tv":2434.89,"id":21580749}]}]}
{"op":"mcm","clk":"993553244","pt":1580543821433,"mc":[{"id":"1.168096552","rc":[{"trd":[[4.7,625.24]],"batb":[[0,4.6,7.25],[1,4.5,27.42]],"batl":[[0,4.7,31.8]],"ltp":4.7,"tv":2438.89,"id":21580749}],"tv":13718.08}]}
{"op":"mcm","clk":"993553345","pt":1580543822465,"mc":[{"id":"1.168096552","rc":[{"trd":[[4.7,688.84]],"batb":[[0,4.7,10],[1,4.6,7.25],[2,4.5,27.42]],"batl":[[0,4.8,18.5],[1,4.9,66.91],[2,5,15.88]],"ltp":4.7,"tv":2502.49,"id":21580749}],"tv":13781.68}]}
{"op":"mcm","clk":"993553422","pt":1580543823338,"mc":[{"id":"1.168096552","rc":[{"batb":[[0,4.7,12],[1,4.6,12.19]],"ltp":4.7,"tv":2502.49,"id":21580749}]}]}
{"op":"mcm","clk":"993554959","pt":1580543843303,"mc":[{"id":"1.168096552","rc":[{"batl":[[0,4.8,28.5]],"ltp":4.7,"tv":2502.49,"id":21580749}]}]}
{"op":"mcm","clk":"993555692","pt":1580543853304,"mc":[{"id":"1.168096552","rc":[{"trd":[[4.7,712.84]],"batb":[[0,4.6,12.19],[1,4.5,27.42],[2,4.4,8.98]],"ltp":4.7,"tv":2526.49,"id":21580749},{"trd":[[2.9,296.58]],"batb":[[0,2.9,13.64]],"ltp":2.9,"tv":7121.46,"id":52106}],"tv":13809.68}]}
{"op":"mcm","clk":"993555784","pt":1580543854234,"mc":[{"id":"1.168096552","rc":[{"trd":[[2.9,300.58]],"batb":[[0,2.9,11.65],[1,2.88,57.86]],"ltp":2.9,"tv":7125.46,"id":52106}],"tv":13813.68}]}
{"op":"mcm","clk":"993555859","pt":1580543855216,"mc":[{"id":"1.168096552","rc":[{"batb":[[0,3.1,69.34]],"ltp":3.1,"tv":3464.05,"id":18286408}]}]}
{"op":"mcm","clk":"993556106","pt":1580543858457,"mc":[{"id":"1.168096552","rc":[{"batb":[[0,3.1,66.2]],"ltp":3.1,"tv":3464.05,"id":18286408}]}]}
{"op":"mcm","clk":"993556229","pt":1580543860355,"mc":[{"id":"1.168096552","rc":[{"trd":[[3.1,651.89]],"batb":[[0,3.1,55.27]],"ltp":3.1,"tv":3485.91,"id":18286408}],"tv":13835.54}]}
{"op":"mcm","clk":"993556411","pt":1580543862471,"mc":[{"id":"1.168096552","rc":[{"batb":[[1,3.05,46.4]],"ltp":3.1,"tv":3485.91,"id":18286408}]}]}
{"op":"mcm","clk":"993556548","pt":1580543864427,"mc":[{"id":"1.168096552","rc":[{"batb":[[2,3,79]],"ltp":3.1,"tv":3485.91,"id":18286408},{"batb":[[0,4.7,3.36],[1,4.6,12.19],[2,4.5,27.42]],"ltp":4.7,"tv":2526.49,"id":21580749}]}]}
{"op":"mcm","clk":"993556625","pt":1580543865450,"mc":[{"id":"1.168096552","rc":[{"batl":[[1,3.2,22]],"ltp":3.1,"tv":3485.91,"id":18286408},{"batl":[[0,4.8,38.5]],"ltp":4.7,"tv":2526.49,"id":21580749}]}]}
{"op":"mcm","clk":"993557350","pt":1580543874493,"mc":[{"id":"1.168096552","rc":[{"batb":[[0,44,1.29],[1,42,4.2],[2,40,3.55]],"ltp":65.0,"tv":89.22,"id":27706761}]}]}
{"op":"mcm","clk":"993557583","pt":1580543877275,"mc":[{"id":"1.168096552","rc":[{"batl":[[0,4.8,48.5]],"ltp":4.7,"tv":2526.49,"id":21580749}]}]}
{"op":"mcm","clk":"993558593","pt":1580543888207,"mc":[{"id":"1.168096552","rc":[{"batb":[[2,4.5,22.42]],"ltp":4.7,"tv":2526.49,"id":21580749}]}]}
{"op":"mcm","clk":"993558928","pt":1580543891512,"mc":[{"id":"1.168096552","rc":[{"batl":[[0,4.8,58.5]],"ltp":4.7,"tv":2526.49,"id":21580749}]}]}
{"op":"mcm","clk":"993559717","pt":1580543901400,"mc":[{"id":"1.168096552","rc":[{"trd":[[4.7,719.56]],"batb":[[0,4.6,12.19],[1,4.5,22.42],[2,4.4,3.98]],"batl":[[0,4.7,6.64],[1,4.8,58.5],[2,4.9,66.91]],"ltp":4.7,"tv":2533.21,"id":21580749}],"tv":13842.27}]}
{"op":"mcm","clk":"993559890","pt":1580543903516,"mc":[{"id":"1.168096552","rc":[{"trd":[[4.7,721.82]],"batl":[[0,4.7,5.51]],"ltp":4.7,"tv":2535.47,"id":21580749}],"tv":13844.53}]}
{"op":"mcm","clk":"993560026","pt":1580543905220,"mc":[{"id":"1.168096552","rc":[{"trd":[[4.7,724.08]],"batl":[[0,4.7,4.38]],"ltp":4.7,"tv":2537.73,"id":21580749}],"tv":13846.79}]}
{"op":"mcm","clk":"993560499","pt":1580543910335,"mc":[{"id":"1.168096552","rc":[{"batl":[[1,4.8,68.5]],"ltp":4.7,"tv":2537.73,"id":21580749}]}]}
{"op":"mcm","clk":"993560807","pt":1580543913336,"mc":[{"id":"1.168096552","rc":[{"batl":[[0,4.7,12.78]],"ltp":4.7,"tv":2537.73,"id":21580749}]}]}
{"op":"mcm","clk":"993560983","pt":1580543915354,"mc":[{"id":"1.168096552","rc":[{"batl":[[0,4.7,22.78]],"ltp":4.7,"tv":2537.73,"id":21580749}]}]}
{"op":"mcm","clk":"993561256","pt":1580543918443,"mc":[{"id":"1.168096552","rc":[{"batl":[[0,2.96,18.06]],"ltp":2.9,"tv":7125.46,"id":52106}]}]}
{"op":"mcm","clk":"993561347","pt":1580543919475,"mc":[{"id":"1.168096552","rc":[{"batl":[[0,4.7,32.78]],"ltp":4.7,"tv":2537.73,"id":21580749}]}]}
{"op":"mcm","clk":"993561972","pt":1580543926488,"mc":[{"id":"1.168096552","rc":[{"trd":[[4.6,298.19]],"batb":[[0,4.5,15.93],[1,4.4,3.98],[2,4.3,9.79]],"batl":[[0,4.7,22.78]],"ltp":4.6,"tv":2557.73,"id":21580749}],"tv":13866.79}]}
{"op":"mcm","clk":"993562110","pt":1580543927881,"mc":[{"id":"1.168096552","rc":[{"batb":[[1,4.4,9.18]],"ltp":4.6,"tv":2557.73,"id":21580749}]}]}
{"op":"mcm","clk":"993562260","pt":1580543929477,"mc":[{"id":"1.168096552","rc":[{"batb":[[1,4.4,3.98]],"ltp":4.6,"tv":2557.73,"id":21580749}]}]}
{"op":"mcm","clk":"993562360","pt":1580543930459,"mc":[{"id":"1.168096552","rc":[{"batb":[[0,4.6,9],[1,4.5,15.93],[2,4.4,3.98]],"ltp":4.6,"tv":2557.73,"id":21580749},{"batb":[[0,2.92,5.9],[1,2.9,11.65],[2,2.88,57.86]],"ltp":2.9,"tv":7125.46,"id":52106}]}]}
{"op":"mcm","clk":"993562425","pt":1580543931186,"mc":[{"id":"1.168096552","rc":[{"batb":[[2,2.88,70.86]],"ltp":2.9,"tv":7125.46,"id":52106}]}]}
{"op":"mcm","clk":"993562613","pt":1580543932990,"mc":[{"id":"1.168096552","rc":[{"batb":[[2,2.88,52.2]],"ltp":2.9,"tv":7125.46,"id":52106}]}]}
{"op":"mcm","clk":"993563738","pt":1580543944409,"mc":[{"id":"1.168096552","rc":[{"batl":[[0,4.7,14.38]],"ltp":4.6,"tv":2557.73,"id":21580749}]}]}
{"op":"mcm","clk":"993563824","pt":1580543945183,"mc":[{"id":"1.168096552","rc":[{"batb":[[0,4.6,16.56]],"ltp":4.6,"tv":2557.73,"id":21580749}]}]}
{"op":"mcm","clk":"993564803","pt":1580543955342,"mc":[{"id":"1.168096552","rc":[{"batb":[[0,4.6,7.56],[1,4.5,24.93]],"ltp":4.6,"tv":2557.73,"id":21580749}]}]}
{"op":"mcm","clk":"993565913","pt":1580543967455,"mc":[{"id":"1.168096552","rc":[{"trd":[[4.6,313.31],[4.7,742.16]],"batb":[[0,4.5,24.93],[1,4.4,3.98],[2,4.3,9.79]],"batl":[[0,4.6,5.89],[1,4.7,5.34],[2,4.8,68.5]],"ltp":4.6,"tv":2590.93,"id":21580749}],"tv":13899.99}]}
{"op":"mcm","clk":"993565998","pt":1580543968434,"mc":[{"id":"1.168096552","rc":[{"trd":[[4.6,325.1],[4.7,747.54]],"batb":[[1,4.4,8.85]],"batl":[[0,4.7,2.65],[1,4.8,68.5],[2,4.9,66.91]],"ltp":4.7,"tv":2608.1,"id":21580749}],"tv":13917.15}]}
{"op":"mcm","clk":"993566069","pt":1580543969257,"mc":[{"id":"1.168096552","rc":[{"batb":[[0,4.6,2],[1,4.5,24.93],[2,4.4,3.98]],"ltp":4.7,"tv":2608.1,"id":21580749}]}]}
{"op":"mcm","clk":"993567178","pt":1580543983489,"mc":[{"id":"1.168096552","rc":[{"trd":[[4.6,329.1]],"batb":[[0,4.5,24.93],[1,4.4,3.98],[2,4.3,9.79]],"batl":[[0,4.6,6.4],[1,4.7,2.65],[2,4.8,68.5]],"ltp":4.6,"tv":2612.1,"id":21580749}],"tv":13921.15}]}
{"op":"mcm","clk":"993567312","pt":1580543985386,"mc":[{"id":"1.168096552","rc":[{"trd":[[4.6,337.1]],"batl":[[0,4.6,2.4]],"ltp":4.6,"tv":2620.1,"id":21580749}],"tv":13929.15}]}
{"op":"mcm","clk":"993567393","pt":1580543986512,"mc":[{"id":"1.168096552","rc":[{"trd":[[3.15,778.06]],"batl":[[0,3.15,173.18]],"ltp":3.15,"tv":3492.91,"id":18286408},{"trd":[[15,49.48]],"batl":[[0,15,11.42]],"ltp":15.0,"tv":452.82,"id":26640937},{"trd":[[4.6,341.9]],"batb":[[0,4.6,2.4],[1,4.5,24.93],[2,4.4,3.98]],"batl":[[0,4.7,2.65],[1,4.8,68.5],[2,4.9,66.91]],"ltp":4.6,"tv":2624.9,"id":21580749},{"trd":[[65,1.36]],"batl":[[0,65,1.32]],"ltp":65.0,"tv":89.56,"id":27706761},{"trd":[[2.96,600.36]],"batl":[[0,2.96,14.33]],"ltp":2.96,"tv":7132.92,"id":52106},{"trd":[[21,44.13]],"batl":[[0,21,8.26]],"ltp":21.0,"tv":158.17,"id":24608298}],"tv":13951.3}]}
{"op":"mcm","clk":"993567467","pt":1580543987487,"mc":[{"id":"1.168096552","rc":[{"batb":[[0,4.6,2.8]],"ltp":4.6,"tv":2624.9,"id":21580749}]}]}
{"op":"mcm","clk":"993567536","pt":1580543988306,"mc":[{"id":"1.168096552","rc":[{"batb":[[0,3.1,64.68]],"ltp":3.15,"tv":3492.91,"id":18286408},{"batb":[[0,14,5.49]],"ltp":15.0,"tv":452.82,"id":26640937},{"batb":[[0,4.6,9.14]],"ltp":4.6,"tv":2624.9,"id":21580749},{"batb":[[1,42,4.89]],"ltp":65.0,"tv":89.56,"id":27706761},{"batb":[[0,2.92,15.89]],"ltp":2.96,"tv":7132.92,"id":52106},{"batb":[[0,20,4.39]],"ltp":21.0,"tv":158.17,"id":24608298}]}]}
{"op":"mcm","clk":"993567714","pt":1580543990514,"mc":[{"id":"1.168096552","rc":[{"batb":[[1,13,8.24]],"ltp":15.0,"tv":452.82,"id":26640937},{"batb":[[0,2.94,5.04],[1,2.92,15.89]],"ltp":2.96,"tv":7132.92,"id":52106}]}]}
{"op":"mcm","clk":"993567814","pt":1580543991496,"mc":[{"id":"1.168096552","rc":[{"batb":[[2,3,82]],"ltp":3.15,"tv":3492.91,"id":18286408}]}]}
{"op":"mcm","clk":"993568214","pt":1580543996422,"mc":[{"id":"1.168096552","rc":[{"trd":[[3.1,671.89]],"batb":[[0,3.1,54.68]],"ltp":3.1,"tv":3512.91,"id":18286408}],"tv":13971.29}]}
{"op":"mcm","clk":"993568271","pt":1580543997091,"mc":[{"id":"1.168096552","rc":[{"batl":[[1,4.8,70.01]],"ltp":4.6,"tv":2624.9,"id":21580749}]}]}
{"op":"mcm","clk":"993568654","pt":1580544001485,"mc":[{"id":"1.168096552","rc":[{"batb":[[2,3,79]],"ltp":3.1,"tv":3512.91,"id":18286408}]}]}
{"op":"mcm","clk":"993569007","pt":1580544004409,"mc":[{"id":"1.168096552","rc":[{"batb":[[2,2.88,70.86]],"ltp":2.96,"tv":7132.92,"id":52106}]}]}
{"op":"mcm","clk":"993569184","pt":1580544006428,"mc":[{"id":"1.168096552","rc":[{"trd":[[4.7,752.84]],"batb":[[0,4.7,6.35],[1,4.6,9.14],[2,4.5,15.93]],"batl":[[0,4.8,70.01],[1,4.9,66.91],[2,5,15.88]],"ltp":4.7,"tv":2630.2,"id":21580749}],"tv":13976.59}]}
{"op":"mcm","clk":"993569454","pt":1580544009518,"mc":[{"id":"1.168096552","rc":[{"batb":[[0,4.7,10.55]],"ltp":4.7,"tv":2630.2,"id":21580749},{"batb":[[2,2.9,6]],"ltp":2.96,"tv":7132.92,"id":52106}]}]}
{"op":"mcm","clk":"993572758","pt":1580544052513,"mc":[{"id":"1.168096552","rc":[{"batl":[[0,3.15,175.18]],"ltp":3.1,"tv":3512.91,"id":18286408}]}]}
{"op":"mcm","clk":"993576374","pt":1580544092402,"mc":[{"id":"1.168096552","rc":[{"trd":[[4.7,773.94]],"batb":[[0,4.6,9.14],[1,4.5,22.27],[2,4.4,3.98]],"ltp":4.7,"tv":2651.3,"id":21580749}],"tv":13997.7}]}
{"op":"mcm","clk":"993576623","pt":1580544095201,"mc":[{"id":"1.168096552","rc":[{"batb":[[1,4.5,15.93]],"batl":[[0,4.7,10],[1,4.8,70.01],[2,4.9,66.91]],"ltp":4.7,"tv":2651.3,"id":21580749}]}]}
{"op":"mcm","clk":"993577852","pt":1580544111464,"mc":[{"id":"1.168096552","rc":[{"batl":[[0,4.8,70.01],[1,4.9,66.91],[2,5,15.88]],"ltp":4.7,"tv":2651.3,"id":21580749}]}]}
{"op":"mcm","clk":"993578682","pt":1580544117030,"mc":[{"id":"1.168096552","rc":[{"batl":[[1,4.9,65.4]],"ltp":4.7,"tv":2651.3,"id":21580749}]}]}
{"op":"mcm","clk":"993578835","pt":1580544118944,"mc":[{"id":"1.168096552","rc":[{"batl":[[0,4.7,1.51],[1,4.8,70.01],[2,4.9,65.4]],"ltp":4.7,"tv":2651.3,"id":21580749}]}]}
{"op":"mcm","clk":"993579177","pt":1580544124366,"mc":[{"id":"1.168096552","rc":[{"batb":[[0,4.6,10.65]],"ltp":4.7,"tv":2651.3,"id":21580749}]}]}
{"op":"mcm","clk":"993579988","pt":1580544134521,"mc":[{"id":"1.168096552","rc":[{"trd":[[4.7,776.97]],"batb":[[0,4.7,1.85],[1,4.6,10.65],[2,4.5,15.93]],"batl":[[0,4.8,70.01],[1,4.9,65.4],[2,5,15.88]],"ltp":4.7,"tv":2654.33,"id":21580749}],"tv":14000.72}]}
{"op":"mcm","clk":"993581679","pt":1580544149992,"mc":[{"id":"1.168096552","rc":[{"batb":[[0,4.7,11.85]],"ltp":4.7,"tv":2654.33,"id":21580749}]}]}
{"op":"mcm","clk":"993581814","pt":1580544151389,"mc":[{"id":"1.168096552","rc":[{"trd":[[4.7,800.67]],"batb":[[0,4.6,10.65],[1,4.5,15.93],[2,4.4,3.98]],"ltp":4.7,"tv":2678.02,"id":21580749}],"tv":14024.42}]}
{"op":"mcm","clk":"993581934","pt":1580544152488,"mc":[{"id":"1.168096552","rc":[{"batb":[[1,4.5,21.71]],"ltp":4.7,"tv":2678.02,"id":21580749}]}]}
{"op":"mcm","clk":"993582816","pt":1580544161128,"mc":[{"id":"1.168096552","rc":[{"batb":[[1,19.5,20.69]],"ltp":21.0,"tv":158.17,"id":24608298}]}]}
{"op":"mcm","clk":"993583146","pt":1580544164435,"mc":[{"id":"1.168096552","rc":[{"trd":[[21,50.41]],"batl":[[0,21,5.12]],"ltp":21.0,"tv":164.45,"id":24608298}],"tv":14030.7}]}
{"op":"mcm","clk":"993584177","pt":1580544176953,"mc":[{"id":"1.168096552","rc":[{"batb":[[1,4.5,15.93]],"batl":[[0,4.7,10],[1,4.8,70.01],[2,4.9,65.4]],"ltp":4.7,"tv":2678.02,"id":21580749}]}]}
{"op":"mcm","clk":"993584435","pt":1580544180247,"mc":[{"id":"1.168096552","rc":[{"batl":[[0,4.7,20]],"ltp":4.7,"tv":2678.02,"id":21580749}]}]}
{"op":"mcm","clk":"993584720","pt":1580544184136,"mc":[{"id":"1.168096552","rc":[{"batl":[[0,3.15,173.18],[1,3.2,24]],"ltp":3.1,"tv":3512.91,"id":18286408},{"trd":[[4.6,361.9]],"batb":[[0,4.5,16.59],[1,4.4,10.98],[2,4.3,9.79]],"batl":[[0,4.7,10]],"ltp":4.6,"tv":2698.03,"id":21580749}],"tv":14050.7}]}
{"op":"mcm","clk":"993585194","pt":1580544191485,"mc":[{"id":"1.168096552","rc":[{"batb":[[0,4.6,5.69],[1,4.5,15.93],[2,4.4,10.98]],"ltp":4.6,"tv":2698.03,"id":21580749}]}]}
{"op":"mcm","clk":"993585270","pt":1580544192467,"mc":[{"id":"1.168096552","rc":[{"batl":[[0,3.15,175.18]],"ltp":3.1,"tv":3512.91,"id":18286408},{"batb":[[2,4.4,3.98]],"ltp":4.6,"tv":2698.03,"id":21580749}]}]}
{"op":"mcm","clk":"993585610","pt":1580544197477,"mc":[{"id":"1.168096552","rc":[{"batb":[[0,46,2.22],[1,44,1.29],[2,42,4.89]],"ltp":65.0,"tv":89.56,"id":27706761}]}]}
{"op":"mcm","clk":"993585861","pt":1580544201396,"mc":[{"id":"1.168096552","rc":[{"batl":[[0,4.8,70.01],[1,4.9,65.4],[2,5,15.88]],"ltp":4.6,"tv":2698.03,"id":21580749}]}]}
{"op":"mcm","clk":"993586341","pt":1580544208886,"mc":[{"id":"1.168096552","rc":[{"batb":[[1,44,3.29]],"ltp":65.0,"tv":89.56,"id":27706761}]}]}
{"op":"mcm","clk":"993586705","pt":1580544213482,"mc":[{"id":"1.168096552","rc":[{"batb":[[0,46,8.94]],"ltp":65.0,"tv":89.56,"id":27706761}]}]}
{"op":"mcm","clk":"993586764","pt":1580544214408,"mc":[{"id":"1.168096552","rc":[{"batb":[[2,40,2.24]],"ltp":65.0,"tv":89.56,"id":27706761}]}]}
{"op":"mcm","clk":"993587657","pt":1580544227416,"mc":[{"id":"1.168096552","rc":[{"batb":[[1,44,2.39]],"ltp":65.0,"tv":89.56,"id":27706761}]}]}
{"op":"mcm","clk":"993587999","pt":1580544232816,"mc":[{"id":"1.168096552","rc":[{"batb":[[1,44,5.34]],"ltp":65.0,"tv":89.56,"id":27706761}]}]}
{"op":"mcm","clk":"993589101","pt":1580544248726,"mc":[{"id":"1.168096552","rc":[{"batb":[[0,3.1,57.68],[1,3.05,49.4]],"batl":[[1,3.2,26]],"ltp":3.1,"tv":3512.91,"id":18286408},{"batb":[[0,14.5,2.48],[1,14,5.02],[2,13,8.24]],"batl":[[1,15.5,2.01],[2,19.5,11.26]],"ltp":15.0,"tv":452.82,"id":26640937},{"batb":[[0,4.6,7.69],[1,4.5,17.93]],"batl":[[0,4.8,72.01]],"ltp":4.6,"tv":2698.03,"id":21580749},{"batb":[[0,2.94,8.04],[1,2.92,18.89]],"batl":[[1,3,2.01],[2,3.05,8]],"ltp":2.96,"tv":7132.92,"id":52106},{"batb":[[0,20,6.39]],"batl":[[1,22,2.01],[2,48,1.08]],"ltp":21.0,"tv":164.45,"id":24608298}]}]}
{"op":"mcm","clk":"993589184","pt":1580544250270,"mc":[{"id":"1.168096552","rc":[{"batb":[[2,3,83]],"ltp":3.1,"tv":3512.91,"id":18286408},{"batl":[[2,19.5,16.83]],"ltp":15.0,"tv":452.82,"id":26640937},{"batb":[[2,2.9,10]],"ltp":2.96,"tv":7132.92,"id":52106}]}]}
{"op":"mcm","clk":"993589246","pt":1580544251346,"mc":[{"id":"1.168096552","rc":[{"batl":[[1,2.98,2],[2,3,2.01]],"ltp":2.96,"tv":7132.92,"id":52106}]}]}
{"op":"mcm","clk":"993590425","pt":1580544269203,"mc":[{"id":"1.168096552","rc":[{"trd":[[14.5,47.58]],"batb":[[0,14.5,1.96]],"ltp":14.5,"tv":457.86,"id":26640937},{"batb":[[0,48,2.05],[1,46,8.94],[2,44,5.34]],"ltp":65.0,"tv":89.56,"id":27706761}],"tv":14055.74}]}
{"op":"mcm","clk":"993592314","pt":1580544297325,"mc":[{"id":"1.168096552","rc":[{"batb":[[0,48,4.05],[2,44,3.34]],"ltp":65.0,"tv":89.56,"id":27706761}]}]}
{"op":"mcm","clk":"993592479","pt":1580544300006,"mc":[{"id":"1.168096552","rc":[{"batb":[[0,50,5.04],[1,48,4.05],[2,46,2.22]],"ltp":65.0,"tv":89.56,"id":27706761}]}]}
{"op":"mcm","clk":"993593686","pt":1580544317458,"mc":[{"id":"1.168096552","rc":[{"batl":[[0,3.15,173.18],[1,3.2,24]],"ltp":3.1,"tv":3512.91,"id":18286408},{"batb":[[1,48,6.86]],"ltp":65.0,"tv":89.56,"id":27706761},{"batb":[[1,19.5,20.14]],"ltp":21.0,"tv":164.45,"id":24608298}]}]}
{"op":"mcm","clk":"993598040","pt":1580544377038,"mc":[{"id":"1.168096552","rc":[{"batl":[[1,3,2.01],[2,3.05,8]],"ltp":2.96,"tv":7132.92,"id":52106}]}]}
{"op":"mcm","clk":"993598709","pt":1580544386328,"mc":[{"id":"1.168096552","rc":[{"trd":[[4.8,238.23]],"batl":[[0,4.8,58.01]],"ltp":4.8,"tv":2726.03,"id":21580749}],"tv":14083.74}]}
{"op":"mcm","clk":"993599600","pt":1580544399335,"mc":[{"id":"1.168096552","rc":[{"trd":[[14.5,50.94]],"batb":[[0,14,5.3],[1,13,8.24],[2,12.5,1.87]],"ltp":14.5,"tv":461.22,"id":26640937}],"tv":14087.11}]}
{"op":"mcm","clk":"993602433","pt":1580544444498,"mc":[{"id":"1.168096552","rc":[{"trd":[[3.15,798.26]],"batl":[[0,3.15,163.08]],"ltp":3.15,"tv":3533.11,"id":18286408}],"tv":14107.31}]}
{"op":"mcm","clk":"993602632","pt":1580544447495,"mc":[{"id":"1.168096552","rc":[{"batb":[[2,3,86]],"ltp":3.15,"tv":3533.11,"id":18286408}]}]}
{"op":"mcm","clk":"993615451","pt":1580544489134,"mc":[{"id":"1.168096552","rc":[{"batl":[[2,17,1.76]],"ltp":14.5,"tv":461.22,"id":26640937}]}]}
{"op":"mcm","clk":"993616257","pt":1580544500467,"mc":[{"id":"1.168096552","rc":[{"batb":[[0,4.7,20.6],[1,4.6,7.69],[2,4.5,17.93]],"ltp":4.8,"tv":2726.03,"id":21580749}]}]}
{"op":"mcm","clk":"993616278","pt":1580544500672,"mc":[{"id":"1.168096552","rc":[{"batb":[[0,3.1,54.68]],"ltp":3.15,"tv":3533.11,"id":18286408},{"batb":[[0,14.5,2.28],[1,14,5.02],[2,13,8.24]],"ltp":14.5,"tv":461.22,"id":26640937},{"batb":[[0,4.7,23.6]],"batl":[[1,4.9,67.4]],"ltp":4.8,"tv":2726.03,"id":21580749},{"batb":[[0,2.94,5.04]],"batl":[[1,2.98,3.11],[2,3,2.01]],"ltp":2.96,"tv":7132.92,"id":52106}]}]}
{"op":"mcm","clk":"993616935","pt":1580544509185,"mc":[{"id":"1.168096552","rc":[{"trd":[[50,9.36]],"batb":[[0,50,3.71]],"ltp":50.0,"tv":92.92,"id":27706761}],"tv":14110.67}]}
{"op":"mcm","clk":"993617719","pt":1580544519473,"mc":[{"id":"1.168096552","rc":[{"batb":[[0,3.1,58.68]],"ltp":3.15,"tv":3533.11,"id":18286408},{"batb":[[0,4.6,7.69],[1,4.5,17.93],[2,4.4,3.98]],"ltp":4.8,"tv":2726.03,"id":21580749}]}]}
{"op":"mcm","clk":"993618322","pt":1580544528486,"mc":[{"id":"1.168096552","rc":[{"trd":[[4.7,820.67],[4.8,258.23]],"batl":[[0,4.8,48.01]],"ltp":4.8,"tv":2766.03,"id":21580749},{"batb":[[0,2.94,9.04]],"batl":[[1,3,2.01],[2,3.05,8]],"ltp":2.96,"tv":7132.92,"id":52106}],"tv":14150.67}]}
{"op":"mcm","clk":"993618374","pt":1580544529315,"mc":[{"id":"1.168096552","rc":[{"batb":[[1,2.92,22.07]],"ltp":2.96,"tv":7132.92,"id":52106}]}]}
{"op":"mcm","clk":"993618645","pt":1580544533486,"mc":[{"id":"1.168096552","rc":[{"batl":[[0,4.7,10],[1,4.8,48.01],[2,4.9,67.4]],"ltp":4.8,"tv":2766.03,"id":21580749}]}]}
{"op":"mcm","clk":"993618751","pt":1580544535341,"mc":[{"id":"1.168096552","rc":[{"batb":[[0,3.1,73.59]],"ltp":3.15,"tv":3533.11,"id":18286408},{"batb":[[0,14.5,5.46]],"ltp":14.5,"tv":461.22,"id":26640937},{"batb":[[0,2.94,24.75]],"ltp":2.96,"tv":7132.92,"id":52106}]}]}
{"op":"mcm","clk":"993618823","pt":1580544536424,"mc":[{"id":"1.168096552","rc":[{"batb":[[0,4.6,17.74]],"ltp":4.8,"tv":2766.03,"id":21580749},{"trd":[[21,54.81]],"batl":[[0,21,2.92]],"ltp":21.0,"tv":168.85,"id":24608298}],"tv":14155.07}]}
{"op":"mcm","clk":"993619085","pt":1580544539930,"mc":[{"id":"1.168096552","rc":[{"batb":[[0,3.1,69.59]],"ltp":3.15,"tv":3533.11,"id":18286408},{"trd":[[4.7,840.67]],"batb":[[0,4.7,10],[1,4.6,17.74],[2,4.5,17.93]],"batl":[[0,4.8,48.01],[1,4.9,67.4],[2,5,15.88]],"ltp":4.7,"tv":2786.03,"id":21580749},{"batb":[[1,2.92,18.89]],"ltp":2.96,"tv":7132.92,"id":52106}],"tv":14175.07}]}
{"op":"mcm","clk":"993620002","pt":1580544552510,"mc":[{"id":"1.168096552","rc":[{"batb":[[0,3.1,73.59]],"ltp":3.15,"tv":3533.11,"id":18286408},{"trd":[[4.7,860.67]],"batb":[[0,4.6,17.74],[1,4.5,23.84],[2,4.4,3.98]],"ltp":4.7,"tv":2806.03,"id":21580749},{"batb":[[1,2.92,27.14]],"ltp":2.96,"tv":7132.92,"id":52106}],"tv":14195.07}]}
{"op":"mcm","clk":"993620068","pt":1580544553543,"mc":[{"id":"1.168096552","rc":[{"trd":[[4.8,263.03]],"batl":[[0,4.8,45.61]],"ltp":4.8,"tv":2810.83,"id":21580749}],"tv":14199.87}]}
{"op":"mcm","clk":"993620306","pt":1580544556426,"mc":[{"id":"1.168096552","rc":[{"batb":[[1,4.5,17.93]],"batl":[[0,4.7,10],[1,4.8,45.61],[2,4.9,67.4]],"ltp":4.8,"tv":2810.83,"id":21580749}]}]}
{"op":"mcm","clk":"993620336","pt":1580544556943,"mc":[{"id":"1.168096552","rc":[{"batl":[[0,4.7,20]],"ltp":4.8,"tv":2810.83,"id":21580749}]}]}
{"op":"mcm","clk":"993620658","pt":1580544561323,"mc":[{"id":"1.168096552","rc":[{"batl":[[0,4.7,10]],"ltp":4.8,"tv":2810.83,"id":21580749}]}]}
{"op":"mcm","clk":"993620788","pt":1580544563438,"mc":[{"id":"1.168096552","rc":[{"batb":[[0,3.1,69.59]],"ltp":3.15,"tv":3533.11,"id":18286408},{"trd":[[4.7,880.67]],"batb":[[0,4.7,10],[1,4.6,17.74],[2,4.5,17.93]],"batl":[[0,4.8,45.61],[1,4.9,67.4],[2,5,15.88]],"ltp":4.7,"tv":2830.83,"id":21580749},{"batb":[[1,2.92,18.89]],"ltp":2.96,"tv":7132.92,"id":52106}],"tv":14219.87}]}
{"op":"mcm","clk":"993621001","pt":1580544567038,"mc":[{"id":"1.168096552","rc":[{"batl":[[2,360,2]],"ltp":50.0,"tv":92.92,"id":27706761}]}]}
{"op":"mcm","clk":"993621151","pt":1580544569367,"mc":[{"id":"1.168096552","rc":[{"batb":[[0,3.1,73.59]],"ltp":3.15,"tv":3533.11,"id":18286408},{"trd":[[4.7,900.67]],"batb":[[0,4.6,17.74],[1,4.5,23.84],[2,4.4,3.98]],"ltp":4.7,"tv":2850.83,"id":21580749},{"batb":[[1,2.92,27.14]],"ltp":2.96,"tv":7132.92,"id":52106}],"tv":14239.87}]}
{"op":"mcm","clk":"993621293","pt":1580544571382,"mc":[{"id":"1.168096552","rc":[{"batb":[[1,4.5,17.93]],"batl":[[0,4.7,10],[1,4.8,45.61],[2,4.9,67.4]],"ltp":4.7,"tv":2850.83,"id":21580749}]}]}
{"op":"mcm","clk":"993621329","pt":1580544571849,"mc":[{"id":"1.168096552","rc":[{"batb":[[1,4.5,27.93]],"ltp":4.7,"tv":2850.83,"id":21580749}]}]}
{"op":"mcm","clk":"993621514","pt":1580544574379,"mc":[{"id":"1.168096552","rc":[{"batl":[[0,4.7,20]],"ltp":4.7,"tv":2850.83,"id":21580749}]}]}
{"op":"mcm","clk":"993621920","pt":1580544580479,"mc":[{"id":"1.168096552","rc":[{"trd":[[4.7,940.67]],"batl":[[0,4.8,45.61],[1,4.9,67.4],[2,5,15.88]],"ltp":4.7,"tv":2890.83,"id":21580749}],"tv":14279.87}]}
{"op":"mcm","clk":"993621973","pt":1580544581053,"mc":[{"id":"1.168096552","rc":[{"batl":[[2,440,9]],"ltp":50.0,"tv":92.92,"id":27706761}]}]}
{"op":"mcm","clk":"993622072","pt":1580544582501,"mc":[{"id":"1.168096552","rc":[{"batl":[[0,4.7,10],[1,4.8,45.61],[2,4.9,67.4]],"ltp":4.7,"tv":2890.83,"id":21580749}]}]}
{"op":"mcm","clk":"993622166","pt":1580544583594,"mc":[{"id":"1.168096552","rc":[{"batl":[[2,4.9,69.4]],"ltp":4.7,"tv":2890.83,"id":21580749}]}]}
{"op":"mcm","clk":"993622967","pt":1580544595172,"mc":[{"id":"1.168096552","rc":[{"batl":[[0,4.7,20]],"ltp":4.7,"tv":2890.83,"id":21580749}]}]}
{"op":"mcm","clk":"993623115","pt":1580544597507,"mc":[{"id":"1.168096552","rc":[{"trd":[[3.1,675.89]],"batb":[[0,3.1,71.59]],"ltp":3.1,"tv":3537.11,"id":18286408}],"tv":14283.87}]}
{"op":"mcm","clk":"993623709","pt":1580544605423,"mc":[{"id":"1.168096552","rc":[{"trd":[[4.7,953.67]],"batl":[[0,4.7,23.5]],"ltp":4.7,"tv":2903.83,"id":21580749}],"tv":14296.87}]}
{"op":"mcm","clk":"993623778","pt":1580544606408,"mc":[{"id":"1.168096552","rc":[{"batb":[[2,3,83]],"ltp":3.1,"tv":3537.11,"id":18286408}]}]}
{"op":"mcm","clk":"993624603","pt":1580544617252,"mc":[{"id":"1.168096552","rc":[{"batb":[[0,55,2.06],[1,50,3.71],[2,48,6.86]],"ltp":50.0,"tv":92.92,"id":27706761},{"trd":[[2.94,439.5]],"batb":[[0,2.94,19.71]],"ltp":2.94,"tv":7150.92,"id":52106}],"tv":14314.87}]}
{"op":"mcm","clk":"993624680","pt":1580544618343,"mc":[{"id":"1.168096552","rc":[{"batl":[[0,4.7,33.5]],"ltp":4.7,"tv":2903.83,"id":21580749}]}]}
{"op":"mcm","clk":"993625023","pt":1580544623776,"mc":[{"id":"1.168096552","rc":[{"trd":[[4.6,381.9]],"batb":[[0,4.6,10.74]],"ltp":4.6,"tv":2923.83,"id":21580749}],"tv":14334.87}]}
{"op":"mcm","clk":"993625161","pt":1580544626163,"mc":[{"id":"1.168096552","rc":[{"batb":[[1,4.5,36.64]],"ltp":4.6,"tv":2923.83,"id":21580749},{"batb":[[1,2.92,18.89]],"ltp":2.94,"tv":7150.92,"id":52106}]}]}
{"op":"mcm","clk":"993625255","pt":1580544627465,"mc":[{"id":"1.168096552","rc":[{"trd":[[4.6,401.9]],"batb":[[0,4.5,37.38],[1,4.4,15],[2,4.3,27.43]],"ltp":4.6,"tv":2943.83,"id":21580749},{"batb":[[1,2.92,25.52]],"ltp":2.94,"tv":7150.92,"id":52106}],"tv":14354.87}]}
{"op":"mcm","clk":"993627377","pt":1580544655482,"mc":[{"id":"1.168096552","rc":[{"batb":[[2,48,4.86]],"ltp":50.0,"tv":92.92,"id":27706761}]}]}
{"op":"mcm","clk":"993627385","pt":1580544655586,"mc":[{"id":"1.168096552","rc":[{"batb":[[0,55,4.06]],"ltp":50.0,"tv":92.92,"id":27706761}]}]}
{"op":"mcm","clk":"993627498","pt":1580544657397,"mc":[{"id":"1.168096552","rc":[{"batb":[[0,4.5,46.98]],"ltp":4.6,"tv":2943.83,"id":21580749},{"trd":[[2.94,452.38]],"batb":[[0,2.94,13.27]],"ltp":2.94,"tv":7163.8,"id":52106}],"tv":14367.75}]}
{"op":"mcm","clk":"993627732","pt":1580544660508,"mc":[{"id":"1.168096552","rc":[{"batb":[[0,2.94,25.87]],"ltp":2.94,"tv":7163.8,"id":52106}]}]}
{"op":"mcm","clk":"993627785","pt":1580544661484,"mc":[{"id":"1.168096552","rc":[{"trd":[[4.5,334.46],[4.6,403.38]],"batb":[[0,4.5,36.98]],"ltp":4.5,"tv":2963.83,"id":21580749}],"tv":14387.76}]}
{"op":"mcm","clk":"993627818","pt":1580544662001,"mc":[{"id":"1.168096552","rc":[{"batb":[[1,3.05,51.4]],"ltp":3.1,"tv":3537.11,"id":18286408},{"batb":[[0,4.6,7.98],[1,4.5,36.98],[2,4.4,15]],"ltp":4.5,"tv":2963.83,"id":21580749},{"batb":[[1,2.92,18.89]],"ltp":2.94,"tv":7163.8,"id":52106}]}]}
{"op":"mcm","clk":"993628089","pt":1580544665514,"mc":[{"id":"1.168096552","rc":[{"trd":[[4.7,972.91]],"batl":[[0,4.7,23.88]],"ltp":4.7,"tv":2983.07,"id":21580749}],"tv":14407.0}]}
{"op":"mcm","clk":"993628413","pt":1580544670010,"mc":[{"id":"1.168096552","rc":[{"batb":[[0,4.6,16.38]],"ltp":4.7,"tv":2983.07,"id":21580749}]}]}
{"op":"mcm","clk":"993628930","pt":1580544677518,"mc":[{"id":"1.168096552","rc":[{"batb":[[1,4.5,38.98]],"ltp":4.7,"tv":2983.07,"id":21580749}]}]}
{"op":"mcm","clk":"993630359","pt":1580544696463,"mc":[{"id":"1.168096552","rc":[{"trd":[[4.7,992.91]],"batl":[[0,4.7,13.88]],"ltp":4.7,"tv":3003.07,"id":21580749}],"tv":14427.0}]}
{"op":"mcm","clk":"993631188","pt":1580544708468,"mc":[{"id":"1.168096552","rc":[{"batl":[[2,4.9,67.4]],"ltp":4.7,"tv":3003.07,"id":21580749}]}]}
{"op":"mcm","clk":"993633152","pt":1580544735481,"mc":[{"id":"1.168096552","rc":[{"batl":[[0,4.7,23.88]],"ltp":4.7,"tv":3003.07,"id":21580749}]}]}
{"op":"mcm","clk":"993633755","pt":1580544743192,"mc":[{"id":"1.168096552","rc":[{"trd":[[2.96,620.84]],"batl":[[0,2.96,4.09]],"ltp":2.96,"tv":7184.28,"id":52106}],"tv":14447.48}]}
{"op":"mcm","clk":"993634246","pt":1580544749334,"mc":[{"id":"1.168096552","rc":[{"trd":[[4.7,1003.17]],"batl":[[0,4.7,18.75]],"ltp":4.7,"tv":3013.33,"id":21580749}],"tv":14457.74}]}
{"op":"mcm","clk":"993634440","pt":1580544751504,"mc":[{"id":"1.168096552","rc":[{"batb":[[0,4.6,11.4],[1,4.5,20.67]],"ltp":4.7,"tv":3013.33,"id":21580749}]}]}
{"op":"mcm","clk":"993636971","pt":1580544781351,"mc":[{"id":"1.168096552","rc":[{"trd":[[4.6,423.38]],"batb":[[0,4.6,3.4]],"ltp":4.6,"tv":3033.33,"id":21580749}],"tv":14477.73}]}
{"op":"mcm","clk":"993637057","pt":1580544782346,"mc":[{"id":"1.168096552","rc":[{"batb":[[2,4.4,3.98]],"ltp":4.6,"tv":3033.33,"id":21580749}]}]}
{"op":"mcm","clk":"993637304","pt":1580544785454,"mc":[{"id":"1.168096552","rc":[{"batl":[[2,17,2.41]],"ltp":14.5,"tv":461.22,"id":26640937}]}]}
{"op":"mcm","clk":"993637482","pt":1580544787763,"mc":[{"id":"1.168096552","rc":[{"batl":[[0,4.7,21.75]],"ltp":4.6,"tv":3033.33,"id":21580749},{"trd":[[65,3.44]],"batl":[[0,85,1.28],[1,440,9],[2,690,2.33]],"ltp":65.0,"tv":95.0,"id":27706761}],"tv":14479.81}]}
{"op":"mcm","clk":"993637722","pt":1580544790943,"mc":[{"id":"1.168096552","rc":[{"batl":[[2,940,2.33]],"ltp":65.0,"tv":95.0,"id":27706761}]}]}
{"op":"mcm","clk":"993638851","pt":1580544804254,"mc":[{"id":"1.168096552","rc":[{"trd":[[4.7,1022.07]],"batl":[[0,4.7,12.3]],"ltp":4.7,"tv":3052.23,"id":21580749}],"tv":14498.71}]}
{"op":"mcm","clk":"993639189","pt":1580544808258,"mc":[{"id":"1.168096552","rc":[{"batl":[[2,17,1.76]],"ltp":14.5,"tv":461.22,"id":26640937},{"trd":[[4.6,435.38]],"batb":[[0,4.5,20.67],[1,4.4,3.98],[2,4.3,27.43]],"ltp":4.6,"tv":3064.24,"id":21580749},{"batb":[[1,2.92,27.5]],"ltp":2.96,"tv":7184.28,"id":52106}],"tv":14510.72}]}
{"op":"mcm","clk":"993639247","pt":1580544808991,"mc":[{"id":"1.168096552","rc":[{"batl":[[0,4.6,10],[1,4.7,12.3],[2,4.8,45.61]],"ltp":4.6,"tv":3064.24,"id":21580749}]}]}
{"op":"mcm","clk":"993639377","pt":1580544810506,"mc":[{"id":"1.168096552","rc":[{"trd":[[3.15,805.94]],"batb":[[0,3.1,67.59]],"batl":[[0,3.15,159.24]],"ltp":3.15,"tv":3544.79,"id":18286408},{"trd":[[15,51.1]],"batl":[[0,15,10.61],[2,17,2.41]],"ltp":15.0,"tv":462.84,"id":26640937},{"trd":[[4.6,440.64]],"batb":[[1,4.4,5.98]],"batl":[[0,4.6,7.37],[2,4.8,47.61]],"ltp":4.6,"tv":3069.5,"id":21580749},{"trd":[[65,3.82]],"batl":[[0,85,1.09]],"ltp":65.0,"tv":95.38,"id":27706761},{"trd":[[2.96,629.02]],"batb":[[0,2.96,5.82],[1,2.94,25.87],[2,2.92,23.6]],"batl":[[0,3,10.44],[1,3.05,8],[2,3.1,63.9]],"ltp":2.96,"tv":7192.46,"id":52106},{"trd":[[21,55.97]],"batl":[[0,21,2.34]],"ltp":21.0,"tv":170.01,"id":24608298}],"tv":14535.0}]}
{"op":"mcm","clk":"993639471","pt":1580544811500,"mc":[{"id":"1.168096552","rc":[{"batb":[[0,2.96,9.82],[2,2.92,14.99]],"ltp":2.96,"tv":7192.46,"id":52106}]}]}
{"op":"mcm","clk":"993639627","pt":1580544813383,"mc":[{"id":"1.168096552","rc":[{"batb":[[2,3,86]],"ltp":3.15,"tv":3544.79,"id":18286408},{"batb":[[1,2.94,29.31]],"ltp":2.96,"tv":7192.46,"id":52106}]}]}
{"op":"mcm","clk":"993639986","pt":1580544817434,"mc":[{"id":"1.168096552","rc":[{"trd":[[4.6,455.38],[4.7,1046.67]],"batb":[[0,4.5,21.4]],"batl":[[0,4.8,47.61],[1,4.9,69.4],[2,5,15.88]],"ltp":4.7,"tv":3108.84,"id":21580749}],"tv":14574.34}]}
{"op":"mcm","clk":"993640072","pt":1580544818423,"mc":[{"id":"1.168096552","rc":[{"trd":[[4.7,1048.13]],"batb":[[0,4.5,20.67]],"batl":[[0,4.7,2.27],[1,4.8,47.61],[2,4.9,69.4]],"ltp":4.7,"tv":3110.3,"id":21580749}],"tv":14575.8}]}
{"op":"mcm","clk":"993640184","pt":1580544819425,"mc":[{"id":"1.168096552","rc":[{"trd":[[4.6,459.38]],"batb":[[0,4.6,6.82],[1,4.5,20.67],[2,4.4,5.98]],"ltp":4.6,"tv":3114.3,"id":21580749}],"tv":14579.8}]}
{"op":"mcm","clk":"993640326","pt":1580544821028,"mc":[{"id":"1.168096552","rc":[{"batl":[[2,660,0.33]],"ltp":65.0,"tv":95.38,"id":27706761},{"batb":[[1,2.94,25.87]],"ltp":2.96,"tv":7192.46,"id":52106}]}]}
{"op":"mcm","clk":"993640736","pt":1580544825942,"mc":[{"id":"1.168096552","rc":[{"trd":[[3.1,693.79]],"batb":[[0,3.1,58.64]],"ltp":3.1,"tv":3562.68,"id":18286408}],"tv":14597.7}]}
{"op":"mcm","clk":"993640967","pt":1580544828637,"mc":[{"id":"1.168096552","rc":[{"batb":[[2,4.4,7.98]],"ltp":4.6,"tv":3114.3,"id":21580749}]}]}
{"op":"mcm","clk":"993641338","pt":1580544833044,"mc":[{"id":"1.168096552","rc":[{"batb":[[2,3,83]],"ltp":3.1,"tv":3562.68,"id":18286408}]}]}
{"op":"mcm","clk":"993641795","pt":1580544838437,"mc":[{"id":"1.168096552","rc":[{"trd":[[3.1,741.79]],"batb":[[0,3.1,34.64]],"ltp":3.1,"tv":3610.68,"id":18286408},{"trd":[[2.94,484.74],[2.96,648.66]],"batb":[[0,2.94,9.7],[1,2.92,14.99],[2,2.9,10]],"ltp":2.94,"tv":7244.46,"id":52106}],"tv":14697.69}]}
{"op":"mcm","clk":"993641884","pt":1580544839467,"mc":[{"id":"1.168096552","rc":[{"batb":[[0,4.6,8.82]],"ltp":4.6,"tv":3114.3,"id":21580749},{"batb":[[0,2.96,4],[1,2.94,13.7],[2,2.92,18.71]],"batl":[[1,3.05,10]],"ltp":2.94,"tv":7244.46,"id":52106}]}]}
{"op":"mcm","clk":"993641954","pt":1580544840348,"mc":[{"id":"1.168096552","rc":[{"trd":[[2.96,656.66]],"batb":[[0,2.94,13.7],[1,2.92,18.71],[2,2.9,10]],"batl":[[0,2.96,8],[1,3,10.44],[2,3.05,10]],"ltp":2.96,"tv":7252.46,"id":52106}],"tv":14705.69}]}
{"op":"mcm","clk":"993642124","pt":1580544842367,"mc":[{"id":"1.168096552","rc":[{"batb":[[1,2.92,14.99]],"ltp":2.96,"tv":7252.46,"id":52106}]}]}
{"op":"mcm","clk":"993642220","pt":1580544843354,"mc":[{"id":"1.168096552","rc":[{"batb":[[0,2.94,4]],"ltp":2.96,"tv":7252.46,"id":52106}]}]}
{"op":"mcm","clk":"993642300","pt":1580544844075,"mc":[{"id":"1.168096552","rc":[{"batl":[[1,4.8,45.61],[2,4.9,67.4]],"ltp":4.6,"tv":3114.3,"id":21580749},{"trd":[[55,4]],"batb":[[0,55,2],[2,48,2.81]],"ltp":55.0,"tv":99.38,"id":27706761}],"tv":14709.69}]}
{"op":"mcm","clk":"993642428","pt":1580544845475,"mc":[{"id":"1.168096552","rc":[{"batb":[[2,3,86]],"ltp":3.1,"tv":3610.68,"id":18286408},{"batb":[[0,4.6,6.82]],"batl":[[0,4.8,45.61],[1,4.9,67.4],[2,5,15.88]],"ltp":4.6,"tv":3114.3,"id":21580749},{"trd":[[2.94,500.74]],"batb":[[0,2.96,2],[1,2.94,3],[2,2.92,12.99]],"batl":[[0,3.05,10],[1,3.1,63.9],[2,3.15,8.96]],"ltp":2.94,"tv":7268.46,"id":52106}],"tv":14725.69}]}
{"op":"mcm","clk":"993642507","pt":1580544846153,"mc":[{"id":"1.168096552","rc":[{"batl":[[0,4.7,2.02],[1,4.8,45.61],[2,4.9,67.4]],"ltp":4.6,"tv":3114.3,"id":21580749},{"batb":[[0,2.94,3],[1,2.92,12.99],[2,2.9,10]],"batl":[[0,3,10.44],[1,3.05,10],[2,3.1,63.9]],"ltp":2.94,"tv":7268.46,"id":52106}]}]}
{"op":"mcm","clk":"993642685","pt":1580544848065,"mc":[{"id":"1.168096552","rc":[{"batb":[[2,13,5.76]],"ltp":15.0,"tv":462.84,"id":26640937},{"batb":[[2,46,2.22]],"ltp":55.0,"tv":99.38,"id":27706761}]}]}
{"op":"mcm","clk":"993642930","pt":1580544850488,"mc":[{"id":"1.168096552","rc":[{"batl":[[0,3,19.64]],"ltp":2.94,"tv":7268.46,"id":52106}]}]}
{"op":"mcm","clk":"993643010","pt":1580544851469,"mc":[{"id":"1.168096552","rc":[{"batl":[[2,17,1.76]],"ltp":15.0,"tv":462.84,"id":26640937},{"trd":[[4.6,473.02]],"batb":[[0,4.5,20.67],[1,4.4,12.26],[2,4.3,27.43]],"batl":[[0,4.6,3.18],[1,4.7,2.02],[2,4.8,45.61]],"ltp":4.6,"tv":3127.94,"id":21580749},{"batb":[[2,48,2.18]],"batl":[[2,910,2.33]],"ltp":55.0,"tv":99.38,"id":27706761}],"tv":14739.33}]}
{"op":"mcm","clk":"993643184","pt":1580544853491,"mc":[{"id":"1.168096552","rc":[{"batb":[[1,4.4,7.98]],"ltp":4.6,"tv":3127.94,"id":21580749},{"batb":[[2,48,4.37]],"ltp":55.0,"tv":99.38,"id":27706761}]}]}
{"op":"mcm","clk":"993643271","pt":1580544854478,"mc":[{"id":"1.168096552","rc":[{"batl":[[0,4.6,9.18]],"ltp":4.6,"tv":3127.94,"id":21580749}]}]}
{"op":"mcm","clk":"993643402","pt":1580544856075,"mc":[{"id":"1.168096552","rc":[{"batb":[[0,55,2.29]],"ltp":55.0,"tv":99.38,"id":27706761}]}]}
{"op":"mcm","clk":"993643678","pt":1580544859384,"mc":[{"id":"1.168096552","rc":[{"trd":[[4.5,354.46]],"batb":[[0,4.5,13.67]],"ltp":4.5,"tv":3147.94,"id":21580749}],"tv":14759.33}]}
{"op":"mcm","clk":"993644376","pt":1580544868383,"mc":[{"id":"1.168096552","rc":[{"batb":[[0,3.1,41.64]],"ltp":3.1,"tv":3610.68,"id":18286408},{"trd":[[2.94,506.74]],"batb":[[0,2.92,12.99],[1,2.9,10],[2,2.88,73.86]],"batl":[[0,2.94,81.01],[1,2.98,6.15],[2,3,25.64]],"ltp":2.94,"tv":7274.46,"id":52106}],"tv":14765.33}]}
{"op":"mcm","clk":"993644548","pt":1580544870392,"mc":[{"id":"1.168096552","rc":[{"batb":[[1,2.9,14.46]],"batl":[[2,3,15.2]],"ltp":2.94,"tv":7274.46,"id":52106}]}]}
{"op":"mcm","clk":"993644625","pt":1580544871216,"mc":[{"id":"1.168096552","rc":[{"trd":[[3.15,809.66]],"batl":[[0,3.15,157.38]],"ltp":3.15,"tv":3614.4,"id":18286408},{"trd":[[15,51.88]],"batl":[[0,15,10.22]],"ltp":15.0,"tv":463.62,"id":26640937},{"trd":[[4.6,475.56]],"batl":[[0,4.6,7.91]],"ltp":4.6,"tv":3150.48,"id":21580749},{"trd":[[65,4]],"batl":[[0,85,1]],"ltp":65.0,"tv":99.56,"id":27706761},{"trd":[[2.94,510.72]],"batl":[[0,2.94,79.02]],"ltp":2.94,"tv":7278.44,"id":52106},{"trd":[[21,56.53]],"batl":[[0,21,2.06]],"ltp":21.0,"tv":170.57,"id":24608298}],"tv":14777.09}]}
{"op":"mcm","clk":"993644926","pt":1580544874480,"mc":[{"id":"1.168096552","rc":[{"trd":[[3.15,832.78]],"batl":[[0,3.15,145.82]],"ltp":3.15,"tv":3637.52,"id":18286408},{"trd":[[15,56.72]],"batl":[[0,15,7.8]],"ltp":15.0,"tv":468.46,"id":26640937},{"trd":[[4.6,491.38]],"batl":[[0,4.7,2.02],[1,4.8,45.61],[2,4.9,67.4]],"ltp":4.6,"tv":3166.3,"id":21580749},{"batb":[[0,55,2.89]],"ltp":65.0,"tv":99.56,"id":27706761},{"trd":[[2.94,535.46]],"batl":[[0,2.94,66.65]],"ltp":2.94,"tv":7303.18,"id":52106},{"trd":[[21,60.65]],"batl":[[0,22,2.01],[1,48,1.08],[2,95,3.1]],"ltp":21.0,"tv":174.69,"id":24608298}],"tv":14849.73}]}
{"op":"mcm","clk":"993645016","pt":1580544875515,"mc":[{"id":"1.168096552","rc":[{"batb":[[0,3.1,34.64]],"batl":[[0,3.15,147.82]],"ltp":3.15,"tv":3637.52,"id":18286408},{"batb":[[0,2.92,9.99]],"batl":[[1,2.96,6.18],[2,2.98,6.15]],"ltp":2.94,"tv":7303.18,"id":52106},{"batb":[[0,20,7.22],[2,19,4.31]],"batl":[[0,48,1.08],[1,95,3.1],[2,140,9]],"ltp":21.0,"tv":174.69,"id":24608298}]}]}
{"op":"mcm","clk":"993645133","pt":1580544876501,"mc":[{"id":"1.168096552","rc":[{"batb":[[2,3,89]],"ltp":3.15,"tv":3637.52,"id":18286408}]}]}
{"op":"mcm","clk":"993645203","pt":1580544877290,"mc":[{"id":"1.168096552","rc":[{"batb":[[0,4.5,10.67]],"batl":[[0,4.6,12],[1,4.7,12.02],[2,4.8,35.61]],"ltp":4.6,"tv":3166.3,"id":21580749},{"batb":[[0,21,3.02],[1,20,6.39],[2,19.5,20.14]],"ltp":21.0,"tv":174.69,"id":24608298}]}]}
{"op":"mcm","clk":"993645577","pt":1580544881291,"mc":[{"id":"1.168096552","rc":[{"batb":[[0,4.5,13.67]],"ltp":4.6,"tv":3166.3,"id":21580749},{"batl":[[2,660,0.33]],"ltp":65.0,"tv":99.56,"id":27706761},{"batl":[[1,140,9.1],[2,260,2.33]],"ltp":21.0,"tv":174.69,"id":24608298}]}]}
{"op":"mcm","clk":"993647023","pt":1580544897210,"mc":[{"id":"1.168096552","rc":[{"batl":[[1,65,1.78],[2,140,9]],"ltp":21.0,"tv":174.69,"id":24608298}]}]}
{"op":"mcm","clk":"993647130","pt":1580544898347,"mc":[{"id":"1.168096552","rc":[{"batb":[[0,21,20.02],[2,19.5,3.14]],"ltp":21.0,"tv":174.69,"id":24608298}]}]}
{"op":"mcm","clk":"993647630","pt":1580544903327,"mc":[{"id":"1.168096552","rc":[{"batl":[[0,4.6,22],[2,4.8,25.61]],"ltp":4.6,"tv":3166.3,"id":21580749}]}]}
{"op":"mcm","clk":"993647897","pt":1580544906448,"mc":[{"id":"1.168096552","rc":[{"trd":[[4.6,509.38]],"batl":[[0,4.6,13]],"ltp":4.6,"tv":3184.3,"id":21580749}],"tv":14867.73}]}
{"op":"mcm","clk":"993648345","pt":1580544911342,"mc":[{"id":"1.168096552","rc":[{"batl":[[2,910,2.33]],"ltp":65.0,"tv":99.56,"id":27706761}]}]}
{"op":"mcm","clk":"993648628","pt":1580544914489,"mc":[{"id":"1.168096552","rc":[{"trd":[[4.6,519.68]],"batl":[[0,4.6,9.85]],"ltp":4.6,"tv":3194.6,"id":21580749}],"tv":14878.03}]}
{"op":"mcm","clk":"993649124","pt":1580544919986,"mc":[{"id":"1.168096552","rc":[{"batl":[[0,4.6,19.85],[2,4.8,15.61]],"ltp":4.6,"tv":3194.6,"id":21580749}]}]}
{"op":"mcm","clk":"993650359","pt":1580544933270,"mc":[{"id":"1.168096552","rc":[{"trd":[[4.5,375.8]],"batb":[[0,4.4,7.98],[1,4.3,27.43],[2,4.2,113.79]],"ltp":4.5,"tv":3215.94,"id":21580749}],"tv":14899.37}]}
{"op":"mcm","clk":"993650672","pt":1580544936287,"mc":[{"id":"1.168096552","rc":[{"batl":[[0,3.15,145.82]],"ltp":3.15,"tv":3637.52,"id":18286408},{"batb":[[1,4.3,30.43]],"batl":[[0,4.5,2],[1,4.6,19.85],[2,4.7,12.02]],"ltp":4.5,"tv":3215.94,"id":21580749}]}]}
{"op":"mcm","clk":"993650783","pt":1580544937477,"mc":[{"id":"1.168096552","rc":[{"batb":[[1,14,7.02]],"ltp":15.0,"tv":468.46,"id":26640937},{"trd":[[4.5,379.8]],"batb":[[0,4.5,3.2],[1,4.4,7.98],[2,4.3,30.43]],"batl":[[0,4.6,29.85],[1,4.7,12.02],[2,4.8,5.61]],"ltp":4.5,"tv":3219.94,"id":21580749},{"batl":[[0,46,8.17],[1,65,2.28]],"ltp":21.0,"tv":174.69,"id":24608298}],"tv":14903.37}]}
{"op":"mcm","clk":"993651186","pt":1580544941274,"mc":[{"id":"1.168096552","rc":[{"batl":[[2,660,0.33]],"ltp":65.0,"tv":99.56,"id":27706761}]}]}
{"op":"mcm","clk":"993651313","pt":1580544942517,"mc":[{"id":"1.168096552","rc":[{"trd":[[21,64.66]],"batb":[[0,21,18.02]],"ltp":21.0,"tv":178.69,"id":24608298}],"tv":14907.37}]}
{"op":"mcm","clk":"993651954","pt":1580544949512,"mc":[{"id":"1.168096552","rc":[{"batb":[[2,4.3,32.43]],"ltp":4.5,"tv":3219.94,"id":21580749}]}]}
{"op":"mcm","clk":"993652850","pt":1580544958513,"mc":[{"id":"1.168096552","rc":[{"batb":[[1,2.9,10.46]],"ltp":2.94,"tv":7303.18,"id":52106}]}]}
{"op":"mcm","clk":"993653173","pt":1580544961435,"mc":[{"id":"1.168096552","rc":[{"batl":[[0,44,2.26],[1,46,7.6],[2,140,9.6]],"ltp":21.0,"tv":178.69,"id":24608298}]}]}
{"op":"mcm","clk":"993654138","pt":1580544971444,"mc":[{"id":"1.168096552","rc":[{"batl":[[2,910,2.33]],"ltp":65.0,"tv":99.56,"id":27706761}]}]}
{"op":"mcm","clk":"993655956","pt":1580544989457,"mc":[{"id":"1.168096552","rc":[{"trd":[[14.5,54.94]],"batb":[[0,14.5,3.18]],"batl":[[0,15,9.8]],"ltp":14.5,"tv":472.46,"id":26640937}],"tv":14911.37}]}
{"op":"mcm","clk":"993656038","pt":1580544990488,"mc":[{"id":"1.168096552","rc":[{"batl":[[0,15,7.8]],"ltp":14.5,"tv":472.46,"id":26640937}]}]}
{"op":"mcm","clk":"993656325","pt":1580544993470,"mc":[{"id":"1.168096552","rc":[{"trd":[[4.5,386.2]],"batb":[[0,4.4,7.98],[1,4.3,32.43],[2,4.2,113.79]],"batl":[[0,4.5,6.8],[1,4.6,29.85],[2,4.7,12.02]],"ltp":4.5,"tv":3226.34,"id":21580749},{"batb":[[1,2.9,13.46]],"ltp":2.94,"tv":7303.18,"id":52106}],"tv":14917.77}]}
{"op":"mcm","clk":"993656708","pt":1580544995463,"mc":[{"id":"1.168096552","rc":[{"trd":[[4.5,394.2]],"batl":[[0,4.5,2.8]],"ltp":4.5,"tv":3234.34,"id":21580749}],"tv":14925.77}]}
{"op":"mcm","clk":"993656876","pt":1580544996398,"mc":[{"id":"1.168096552","rc":[{"trd":[[4.5,399.8]],"batb":[[0,4.5,3.19],[1,4.4,7.98],[2,4.3,32.43]],"batl":[[0,4.6,29.85],[1,4.7,12.02],[2,4.8,5.61]],"ltp":4.5,"tv":3239.94,"id":21580749}],"tv":14931.37}]}
{"op":"mcm","clk":"993656983","pt":1580544997385,"mc":[{"id":"1.168096552","rc":[{"batb":[[0,4.5,3.99]],"ltp":4.5,"tv":3239.94,"id":21580749}]}]}
{"op":"mcm","clk":"993657017","pt":1580544997695,"mc":[{"id":"1.168096552","rc":[{"trd":[[4.5,401.4]],"batb":[[0,4.4,7.98],[1,4.3,32.43],[2,4.2,113.79]],"ltp":4.5,"tv":3241.54,"id":21580749}],"tv":14932.97}]}
{"op":"mcm","clk":"993657391","pt":1580545001476,"mc":[{"id":"1.168096552","rc":[{"batl":[[2,660,0.33]],"ltp":65.0,"tv":99.56,"id":27706761}]}]}
{"op":"mcm","clk":"993657434","pt":1580545001889,"mc":[{"id":"1.168096552","rc":[{"batb":[[0,4.5,3.22],[1,4.4,7.98],[2,4.3,32.43]],"ltp":4.5,"tv":3241.54,"id":21580749}]}]}
{"op":"mcm","clk":"993659598","pt":1580545022214,"mc":[{"id":"1.168096552","rc":[{"batb":[[1,2.9,10.46]],"ltp":2.94,"tv":7303.18,"id":52106}]}]}
{"op":"mcm","clk":"993660574","pt":1580545031405,"mc":[{"id":"1.168096552","rc":[{"batl":[[2,910,2.33]],"ltp":65.0,"tv":99.56,"id":27706761}]}]}
{"op":"mcm","clk":"993661142","pt":1580545038434,"mc":[{"id":"1.168096552","rc":[{"batb":[[0,55,2.6]],"ltp":65.0,"tv":99.56,"id":27706761}]}]}
{"op":"mcm","clk":"993661231","pt":1580545039314,"mc":[{"id":"1.168096552","rc":[{"batb":[[0,55,4.6]],"ltp":65.0,"tv":99.56,"id":27706761}]}]}
{"op":"mcm","clk":"993661847","pt":1580545046244,"mc":[{"id":"1.168096552","rc":[{"batb":[[0,4.5,43.22]],"ltp":4.5,"tv":3241.54,"id":21580749}]}]}
{"op":"mcm","clk":"993661948","pt":1580545047427,"mc":[{"id":"1.168096552","rc":[{"batl":[[1,110,2],[2,440,9]],"ltp":65.0,"tv":99.56,"id":27706761}]}]}
{"op":"mcm","clk":"993662842","pt":1580545056264,"mc":[{"id":"1.168096552","rc":[{"batl":[[0,4.6,27.85]],"ltp":4.5,"tv":3241.54,"id":21580749},{"batl":[[0,40,2.08],[1,44,2.18],[2,46,7.6]],"ltp":21.0,"tv":178.69,"id":24608298}]}]}
{"op":"mcm","clk":"993662923","pt":1580545056989,"mc":[{"id":"1.168096552","rc":[{"batb":[[0,4.5,53.22]],"ltp":4.5,"tv":3241.54,"id":21580749}]}]}
{"op":"mcm","clk":"993663069","pt":1580545058490,"mc":[{"id":"1.168096552","rc":[{"trd":[[4.5,421.4]],"batb":[[0,4.5,43.22]],"ltp":4.5,"tv":3261.54,"id":21580749}],"tv":14952.97}]}
{"op":"mcm","clk":"993663178","pt":1580545059475,"mc":[{"id":"1.168096552","rc":[{"batb":[[1,3.05,54.4]],"ltp":3.15,"tv":3637.52,"id":18286408},{"batb":[[0,4.5,45.22]],"ltp":4.5,"tv":3261.54,"id":21580749}]}]}
{"op":"mcm","clk":"993663390","pt":1580545061420,"mc":[{"id":"1.168096552","rc":[{"trd":[[4.6,557.68]],"batl":[[0,4.6,8.85]],"ltp":4.6,"tv":3299.54,"id":21580749}],"tv":14990.97}]}
{"op":"mcm","clk":"993663509","pt":1580545062411,"mc":[{"id":"1.168096552","rc":[{"batl":[[0,40,2.48]],"ltp":21.0,"tv":178.69,"id":24608298}]}]}
{"op":"mcm","clk":"993664589","pt":1580545073420,"mc":[{"id":"1.168096552","rc":[{"batl":[[1,46,8.1],[2,90,3.6]],"ltp":21.0,"tv":178.69,"id":24608298}]}]}
{"op":"mcm","clk":"993664684","pt":1580545074454,"mc":[{"id":"1.168096552","rc":[{"batl":[[0,38,1.76],[1,40,2.4],[2,46,8.1]],"ltp":21.0,"tv":178.69,"id":24608298}]}]}
{"op":"mcm","clk":"993666543","pt":1580545092449,"mc":[{"id":"1.168096552","rc":[{"batl":[[0,4.6,18.85]],"ltp":4.6,"tv":3299.54,"id":21580749},{"batb":[[1,50,6.37]],"ltp":65.0,"tv":99.56,"id":27706761}]}]}
{"op":"mcm","clk":"993668353","pt":1580545113890,"mc":[{"id":"1.168096552","rc":[{"trd":[[4.6,577.34]],"batl":[[0,4.6,9.02]],"ltp":4.6,"tv":3319.2,"id":21580749}],"tv":15010.63}]}
{"op":"mcm","clk":"993669355","pt":1580545127406,"mc":[{"id":"1.168096552","rc":[{"batl":[[1,4.7,13.53]],"ltp":4.6,"tv":3319.2,"id":21580749}]}]}
{"op":"mcm","clk":"993669668","pt":1580545131514,"mc":[{"id":"1.168096552","rc":[{"trd":[[4.6,595.38]],"batb":[[0,4.6,1.42],[1,4.5,45.22],[2,4.4,7.98]],"batl":[[0,4.7,13.53],[1,4.8,5.61],[2,4.9,65.4]],"ltp":4.6,"tv":3337.24,"id":21580749}],"tv":15028.67}]}
{"op":"mcm","clk":"993669731","pt":1580545132495,"mc":[{"id":"1.168096552","rc":[{"trd":[[4.6,598.22]],"batb":[[0,4.5,45.22],[1,4.4,7.98],[2,4.3,32.43]],"batl":[[0,4.6,7.28],[1,4.7,13.53],[2,4.8,5.61]],"ltp":4.6,"tv":3340.08,"id":21580749},{"batb":[[1,2.9,6]],"ltp":2.94,"tv":7303.18,"id":52106}],"tv":15031.51}]}
{"op":"mcm","clk":"993669788","pt":1580545133319,"mc":[{"id":"1.168096552","rc":[{"trd":[[4.5,441.4]],"batb":[[0,4.5,35.22]],"ltp":4.5,"tv":3360.08,"id":21580749},{"batb":[[1,2.9,9.5],[2,2.88,55.2]],"ltp":2.94,"tv":7303.18,"id":52106}],"tv":15051.51}]}
{"op":"mcm","clk":"993669889","pt":1580545134512,"mc":[{"id":"1.168096552","rc":[{"batb":[[2,2.88,73.86]],"ltp":2.94,"tv":7303.18,"id":52106}]}]}
{"op":"mcm","clk":"993672048","pt":1580545162502,"mc":[{"id":"1.168096552","rc":[{"batl":[[2,48,1]],"ltp":21.0,"tv":178.69,"id":24608298}]}]}
{"op":"mcm","clk":"993672559","pt":1580545168448,"mc":[{"id":"1.168096552","rc":[{"batl":[[1,4.7,3.53]],"ltp":4.5,"tv":3360.08,"id":21580749}]}]}
{"op":"mcm","clk":"993673349","pt":1580545178468,"mc":[{"id":"1.168096552","rc":[{"batl":[[1,40,2]],"ltp":21.0,"tv":178.69,"id":24608298}]}]}
{"op":"mcm","clk":"993673403","pt":1580545179391,"mc":[{"id":"1.168096552","rc":[{"batl":[[0,34,2.29],[1,36,7.6],[2,38,1.68]],"ltp":21.0,"tv":178.69,"id":24608298}]}]}
{"op":"mcm","clk":"993673734","pt":1580545183375,"mc":[{"id":"1.168096552","rc":[{"batl":[[0,32,1.3],[1,34,2.21],[2,36,7.6]],"ltp":21.0,"tv":178.69,"id":24608298}]}]}
{"op":"mcm","clk":"993674496","pt":1580545193495,"mc":[{"id":"1.168096552","rc":[{"batb":[[0,4.5,40.59]],"ltp":4.5,"tv":3360.08,"id":21580749}]}]}
{"op":"mcm","clk":"993674796","pt":1580545197203,"mc":[{"id":"1.168096552","rc":[{"trd":[[2.92,1143.12]],"batb":[[0,2.92,7.99]],"ltp":2.92,"tv":7307.18,"id":52106}],"tv":15055.51}]}
{"op":"mcm","clk":"993675132","pt":1580545201493,"mc":[{"id":"1.168096552","rc":[{"batl":[[0,32,2.98]],"ltp":21.0,"tv":178.69,"id":24608298}]}]}
{"op":"mcm","clk":"993676327","pt":1580545216512,"mc":[{"id":"1.168096552","rc":[{"trd":[[4.6,612.78]],"batb":[[0,4.6,3.16],[1,4.5,40.59],[2,4.4,7.98]],"batl":[[0,4.7,3.53],[1,4.8,5.61],[2,4.9,65.4]],"ltp":4.6,"tv":3374.64,"id":21580749},{"batb":[[1,2.9,6]],"ltp":2.92,"tv":7307.18,"id":52106}],"tv":15070.07}]}
{"op":"mcm","clk":"993676461","pt":1580545218426,"mc":[{"id":"1.168096552","rc":[{"batb":[[2,2.88,55.2]],"ltp":2.92,"tv":7307.18,"id":52106}]}]}
{"op":"mcm","clk":"993677307","pt":1580545229427,"mc":[{"id":"1.168096552","rc":[{"trd":[[14.5,61.3]],"batb":[[0,14,7.02],[1,13,5.76],[2,12.5,1.87]],"batl":[[0,15,9.8]],"ltp":14.5,"tv":478.83,"id":26640937},{"batb":[[0,4.6,5.16]],"ltp":4.6,"tv":3374.64,"id":21580749}],"tv":15076.44}]}
{"op":"mcm","clk":"993677470","pt":1580545231443,"mc":[{"id":"1.168096552","rc":[{"batb":[[0,14.5,2.99],[1,14,7.02],[2,13.5,2.25]],"ltp":14.5,"tv":478.83,"id":26640937}]}]}
{"op":"mcm","clk":"993677951","pt":1580545237352,"mc":[{"id":"1.168096552","rc":[{"trd":[[2.92,1148.52]],"batb":[[0,2.92,5.29]],"ltp":2.92,"tv":7312.58,"id":52106}],"tv":15081.84}]}
{"op":"mcm","clk":"993678406","pt":1580545242485,"mc":[{"id":"1.168096552","rc":[{"batb":[[0,21,18.8]],"ltp":21.0,"tv":178.69,"id":24608298}]}]}
{"op":"mcm","clk":"993679548","pt":1580545258490,"mc":[{"id":"1.168096552","rc":[{"batb":[[0,14.5,4.99]],"batl":[[0,15,7.8]],"ltp":14.5,"tv":478.83,"id":26640937},{"trd":[[4.6,632.78]],"batb":[[0,4.6,3.86],[2,4.4,11.3]],"ltp":4.6,"tv":3394.64,"id":21580749}],"tv":15101.84}]}
{"op":"mcm","clk":"993679691","pt":1580545260509,"mc":[{"id":"1.168096552","rc":[{"batb":[[2,4.4,7.98]],"ltp":4.6,"tv":3394.64,"id":21580749}]}]}
{"op":"mcm","clk":"993683343","pt":1580545308501,"mc":[{"id":"1.168096552","rc":[{"trd":[[4.7,1055.19]],"batb":[[0,4.7,15.47],[1,4.6,3.86],[2,4.5,40.59]],"batl":[[0,4.8,5.61],[1,4.9,65.4],[2,5,15.88]],"ltp":4.7,"tv":3401.7,"id":21580749}],"tv":15108.91}]}
{"op":"mcm","clk":"993683422","pt":1580545309382,"mc":[{"id":"1.168096552","rc":[{"batl":[[0,3.15,147.82]],"ltp":3.15,"tv":3637.52,"id":18286408},{"batb":[[0,14.5,2.99]],"batl":[[0,15,9.8]],"ltp":14.5,"tv":478.83,"id":26640937},{"trd":[[4.7,1061.19]],"batb":[[0,4.7,12.47],[1,4.6,2]],"batl":[[0,4.8,10.36]],"ltp":4.7,"tv":3407.7,"id":21580749},{"batl":[[0,2.94,71.65]],"ltp":2.92,"tv":7312.58,"id":52106}],"tv":15114.91}]}
{"op":"mcm","clk":"993683976","pt":1580545316463,"mc":[{"id":"1.168096552","rc":[{"trd":[[4.7,1081.19]],"batb":[[0,4.7,2.47]],"ltp":4.7,"tv":3427.7,"id":21580749}],"tv":15134.91}]}
{"op":"mcm","clk":"993684050","pt":1580545317491,"mc":[{"id":"1.168096552","rc":[{"batl":[[1,4.9,67.4]],"ltp":4.7,"tv":3427.7,"id":21580749}]}]}
{"op":"mcm","clk":"993684361","pt":1580545321513,"mc":[{"id":"1.168096552","rc":[{"trd":[[3.1,791.78]],"batb":[[0,3.1,9.65]],"ltp":3.1,"tv":3687.52,"id":18286408}],"tv":15184.9}]}
{"op":"mcm","clk":"993685049","pt":1580545329292,"mc":[{"id":"1.168096552","rc":[{"batb":[[2,3,86]],"ltp":3.1,"tv":3687.52,"id":18286408}]}]}
{"op":"mcm","clk":"993686151","pt":1580545341317,"mc":[{"id":"1.168096552","rc":[{"trd":[[21,83.1],[22,6.75]],"batb":[[0,22,2.04],[1,21,8.8],[2,20,6.39]],"ltp":21.0,"tv":198.69,"id":24608298}],"tv":15204.91}]}
{"op":"mcm","clk":"993686261","pt":1580545342521,"mc":[{"id":"1.168096552","rc":[{"batb":[[0,4.7,22.47]],"ltp":4.7,"tv":3427.7,"id":21580749}]}]}
{"op":"mcm","clk":"993697162","pt":1580545354447,"mc":[{"id":"1.168096552","rc":[{"batb":[[0,4.7,24.47]],"ltp":4.7,"tv":3427.7,"id":21580749}]}]}
{"op":"mcm","clk":"993698137","pt":1580545365370,"mc":[{"id":"1.168096552","rc":[{"batl":[[0,32,3.51]],"ltp":21.0,"tv":198.69,"id":24608298}]}]}
{"op":"mcm","clk":"993699533","pt":1580545381500,"mc":[{"id":"1.168096552","rc":[{"trd":[[4.7,1101.19]],"batb":[[0,4.7,14.47]],"ltp":4.7,"tv":3447.7,"id":21580749}],"tv":15224.91}]}
{"op":"mcm","clk":"993700362","pt":1580545391209,"mc":[{"id":"1.168096552","rc":[{"batb":[[2,4.5,42.1]],"ltp":4.7,"tv":3447.7,"id":21580749}]}]}
{"op":"mcm","clk":"993700862","pt":1580545397385,"mc":[{"id":"1.168096552","rc":[{"batl":[[1,4.9,68.91],[2,5,17.39]],"ltp":4.7,"tv":3447.7,"id":21580749}]}]}
{"op":"mcm","clk":"993701379","pt":1580545404432,"mc":[{"id":"1.168096552","rc":[{"batl":[[2,40,2]],"ltp":21.0,"tv":198.69,"id":24608298}]}]}
{"op":"mcm","clk":"993701551","pt":1580545406509,"mc":[{"id":"1.168096552","rc":[{"batb":[[2,13,5.76]],"ltp":14.5,"tv":478.83,"id":26640937},{"batb":[[1,50,3.71]],"ltp":65.0,"tv":99.56,"id":27706761},{"trd":[[2.94,688.76]],"batb":[[0,2.94,34.22],[1,2.92,173.69],[2,2.9,10]],"batl":[[0,2.98,6.15],[1,3,15.2],[2,3.05,6]],"ltp":2.94,"tv":7465.88,"id":52106}],"tv":15378.21}]}
{"op":"mcm","clk":"993701691","pt":1580545408114,"mc":[{"id":"1.168096552","rc":[{"batb":[[0,2.94,44.31]],"batl":[[1,3,28.98]],"ltp":2.94,"tv":7465.88,"id":52106}]}]}
{"op":"mcm","clk":"993701782","pt":1580545409307,"mc":[{"id":"1.168096552","rc":[{"batl":[[1,3,15.2]],"ltp":2.94,"tv":7465.88,"id":52106}]}]}
{"op":"mcm","clk":"993702032","pt":1580545412424,"mc":[{"id":"1.168096552","rc":[{"trd":[[3.1,811.06]],"batb":[[0,3.05,54.4],[1,3,86],[2,2.98,34]],"batl":[[0,3.1,36.89],[1,3.15,147.82],[2,3.2,24]],"ltp":3.1,"tv":3706.8,"id":18286408}],"tv":15397.49}]}
{"op":"mcm","clk":"993702130","pt":1580545413417,"mc":[{"id":"1.168096552","rc":[{"batb":[[0,3.05,46.4],[2,2.98,41]],"batl":[[0,3.1,39.89]],"ltp":3.1,"tv":3706.8,"id":18286408},{"batb":[[1,2.92,177.69]],"ltp":2.94,"tv":7465.88,"id":52106}]}]}
{"op":"mcm","clk":"993702197","pt":1580545414411,"mc":[{"id":"1.168096552","rc":[{"batb":[[2,4.5,51.55]],"ltp":4.7,"tv":3447.7,"id":21580749},{"batb":[[1,50,6.37]],"ltp":65.0,"tv":99.56,"id":27706761}]}]}
{"op":"mcm","clk":"993702788","pt":1580545421156,"mc":[{"id":"1.168096552","rc":[{"trd":[[3.05,770.9]],"batb":[[0,3.05,44.4]],"batl":[[1,3.15,145.82]],"ltp":3.05,"tv":3710.8,"id":18286408}],"tv":15401.49}]}
{"op":"mcm","clk":"993703383","pt":1580545428527,"mc":[{"id":"1.168096552","rc":[{"batl":[[0,3.1,3]],"ltp":3.05,"tv":3710.8,"id":18286408}]}]}
{"op":"mcm","clk":"993703503","pt":1580545430335,"mc":[{"id":"1.168096552","rc":[{"trd":[[4.8,283.16]],"batl":[[0,4.9,69.21],[1,5,17.39],[2,5.1,11.47]],"ltp":4.8,"tv":3467.82,"id":21580749}],"tv":15421.61}]}
{"op":"mcm","clk":"993703556","pt":1580545431074,"mc":[{"id":"1.168096552","rc":[{"batl":[[0,4.8,3.3],[1,4.9,68.91],[2,5,17.39]],"ltp":4.8,"tv":3467.82,"id":21580749}]}]}
{"op":"mcm","clk":"993704310","pt":1580545440161,"mc":[{"id":"1.168096552","rc":[{"trd":[[3.05,774.9]],"batb":[[0,3.05,42.4]],"ltp":3.05,"tv":3714.8,"id":18286408}],"tv":15425.61}]}
{"op":"mcm","clk":"993705296","pt":1580545450453,"mc":[{"id":"1.168096552","rc":[{"trd":[[3.05,778.9]],"batb":[[0,3.05,40.4]],"ltp":3.05,"tv":3718.8,"id":18286408}],"tv":15429.61}]}
{"op":"mcm","clk":"993705602","pt":1580545453474,"mc":[{"id":"1.168096552","rc":[{"trd":[[4.7,1121.19]],"batb":[[0,4.7,4.47]],"ltp":4.7,"tv":3487.82,"id":21580749}],"tv":15449.61}]}
{"op":"mcm","clk":"993705933","pt":1580545457398,"mc":[{"id":"1.168096552","rc":[{"trd":[[3.05,784.9]],"batb":[[0,3.05,37.4]],"ltp":3.05,"tv":3724.8,"id":18286408}],"tv":15455.61}]}
{"op":"mcm","clk":"993707016","pt":1580545469492,"mc":[{"id":"1.168096552","rc":[{"trd":[[3.05,788.9]],"batb":[[0,3.05,35.4]],"ltp":3.05,"tv":3728.8,"id":18286408},{"batb":[[0,4.7,13.97]],"ltp":4.7,"tv":3487.82,"id":21580749}],"tv":15459.61}]}
{"op":"mcm","clk":"993707095","pt":1580545470324,"mc":[{"id":"1.168096552","rc":[{"batb":[[2,4.5,45]],"ltp":4.7,"tv":3487.82,"id":21580749}]}]}
{"op":"mcm","clk":"993707908","pt":1580545478392,"mc":[{"id":"1.168096552","rc":[{"trd":[[3.05,792.9]],"batb":[[0,3.05,33.4]],"ltp":3.05,"tv":3732.8,"id":18286408}],"tv":15463.61}]}
{"op":"mcm","clk":"993709497","pt":1580545497326,"mc":[{"id":"1.168096552","rc":[{"trd":[[4.8,289.16]],"batl":[[0,4.9,69.21],[1,5,17.39],[2,5.1,11.47]],"ltp":4.8,"tv":3493.82,"id":21580749}],"tv":15469.61}]}
{"op":"mcm","clk":"993709534","pt":1580545497849,"mc":[{"id":"1.168096552","rc":[{"trd":[[4.8,296.33]],"batb":[[2,4.5,51.32]],"batl":[[0,4.9,68.91]],"ltp":4.8,"tv":3500.99,"id":21580749}],"tv":15476.78}]}
{"op":"mcm","clk":"993710402","pt":1580545508351,"mc":[{"id":"1.168096552","rc":[{"trd":[[3.05,796.9]],"batb":[[0,3.05,31.4]],"ltp":3.05,"tv":3736.8,"id":18286408}],"tv":15480.78}]}
{"op":"mcm","clk":"993710517","pt":1580545509494,"mc":[{"id":"1.168096552","rc":[{"batl":[[0,4.8,2.04],[1,4.9,68.91],[2,5,17.39]],"ltp":4.8,"tv":3500.99,"id":21580749}]}]}
{"op":"mcm","clk":"993710925","pt":1580545513859,"mc":[{"id":"1.168096552","rc":[{"batl":[[0,4.8,3.55]],"ltp":4.8,"tv":3500.99,"id":21580749}]}]}
{"op":"mcm","clk":"993711290","pt":1580545518481,"mc":[{"id":"1.168096552","rc":[{"trd":[[3.05,800.9]],"batb":[[0,3.05,29.4]],"ltp":3.05,"tv":3740.8,"id":18286408}],"tv":15484.78}]}
{"op":"mcm","clk":"993711415","pt":1580545520066,"mc":[{"id":"1.168096552","rc":[{"trd":[[4.8,300.33]],"batl":[[0,4.8,1.55]],"ltp":4.8,"tv":3504.99,"id":21580749}],"tv":15488.78}]}
{"op":"mcm","clk":"993711528","pt":1580545521473,"mc":[{"id":"1.168096552","rc":[{"trd":[[3.05,840.9]],"batb":[[0,3.05,9.4]],"batl":[[1,3.15,147.82]],"ltp":3.05,"tv":3780.8,"id":18286408}],"tv":15528.78}]}
{"op":"mcm","clk":"993711602","pt":1580545522258,"mc":[{"id":"1.168096552","rc":[{"batl":[[0,3.1,14.71]],"ltp":3.05,"tv":3780.8,"id":18286408}]}]}
{"op":"mcm","clk":"993711696","pt":1580545523253,"mc":[{"id":"1.168096552","rc":[{"batl":[[0,3.1,34.71]],"ltp":3.05,"tv":3780.8,"id":18286408}]}]}
{"op":"mcm","clk":"993712229","pt":1580545529279,"mc":[{"id":"1.168096552","rc":[{"batl":[[0,15,18.8]],"ltp":14.5,"tv":478.83,"id":26640937}]}]}
{"op":"mcm","clk":"993713155","pt":1580545539521,"mc":[{"id":"1.168096552","rc":[{"trd":[[14.5,67.28]],"batb":[[0,14,5.02],[1,13.5,4.98],[2,13,7.7]],"batl":[[0,14.5,8.01],[1,15,9.8],[2,15.5,2.01]],"ltp":14.5,"tv":484.81,"id":26640937},{"batb":[[1,4.6,4],[2,4.5,53.32]],"batl":[[0,4.8,3.55]],"ltp":4.8,"tv":3504.99,"id":21580749},{"batb":[[0,2.94,48.31]],"batl":[[0,3,15.2],[1,3.05,6],[2,3.1,63.9]],"ltp":2.94,"tv":7465.88,"id":52106}],"tv":15534.76}]}
{"op":"mcm","clk":"993713308","pt":1580545541393,"mc":[{"id":"1.168096552","rc":[{"batb":[[1,13.5,2.26]],"ltp":14.5,"tv":484.81,"id":26640937}]}]}
{"op":"mcm","clk":"993714006","pt":1580545549396,"mc":[{"id":"1.168096552","rc":[{"trd":[[4.8,306.33]],"batl":[[0,4.9,69.46],[1,5,17.39],[2,5.1,11.47]],"ltp":4.8,"tv":3511.0,"id":21580749}],"tv":15540.76}]}
{"op":"mcm","clk":"993715060","pt":1580545561443,"mc":[{"id":"1.168096552","rc":[{"trd":[[4.7,1141.19]],"batb":[[0,4.7,3.97]],"ltp":4.7,"tv":3531.0,"id":21580749}],"tv":15560.76}]}
{"op":"mcm","clk":"993715123","pt":1580545562014,"mc":[{"id":"1.168096552","rc":[{"batl":[[0,4.9,79.46]],"ltp":4.7,"tv":3531.0,"id":21580749}]}]}
{"op":"mcm","clk":"993715384","pt":1580545565024,"mc":[{"id":"1.168096552","rc":[{"trd":[[3.1,821.26]],"batl":[[0,3.1,32.61]],"ltp":3.1,"tv":3791.0,"id":18286408},{"batl":[[0,4.8,2.55],[1,4.9,78.91],[2,5,17.39]],"ltp":4.7,"tv":3531.0,"id":21580749}],"tv":15570.96}]}
{"op":"mcm","clk":"993715449","pt":1580545565847,"mc":[{"id":"1.168096552","rc":[{"trd":[[14.5,77.28]],"batl":[[0,14.5,3.01]],"ltp":14.5,"tv":494.81,"id":26640937},{"batb":[[2,4.5,47]],"ltp":4.7,"tv":3531.0,"id":21580749}],"tv":15580.96}]}
{"op":"mcm","clk":"993715587","pt":1580545567512,"mc":[{"id":"1.168096552","rc":[{"batl":[[0,2.98,2],[1,3,15.2],[2,3.05,6]],"ltp":2.94,"tv":7465.88,"id":52106}]}]}
{"op":"mcm","clk":"993715969","pt":1580545572438,"mc":[{"id":"1.168096552","rc":[{"batl":[[0,4.8,16.55]],"ltp":4.7,"tv":3531.0,"id":21580749}]}]}
{"op":"mcm","clk":"993716217","pt":1580545575451,"mc":[{"id":"1.168096552","rc":[{"trd":[[4.8,310.33]],"batl":[[0,4.8,14.55]],"ltp":4.8,"tv":3535.0,"id":21580749}],"tv":15584.96}]}
{"op":"mcm","clk":"993716379","pt":1580545577367,"mc":[{"id":"1.168096552","rc":[{"trd":[[3.05,844.9]],"batb":[[0,3.05,7.4]],"ltp":3.05,"tv":3795.0,"id":18286408}],"tv":15588.96}]}
{"op":"mcm","clk":"993716666","pt":1580545580385,"mc":[{"id":"1.168096552","rc":[{"batl":[[1,3.15,145.82]],"ltp":3.05,"tv":3795.0,"id":18286408},{"batb":[[2,4.5,44.1]],"ltp":4.8,"tv":3535.0,"id":21580749}]}]}
{"op":"mcm","clk":"993717411","pt":1580545588788,"mc":[{"id":"1.168096552","rc":[{"trd":[[2.94,708.76]],"batb":[[0,2.94,38.31]],"ltp":2.94,"tv":7485.88,"id":52106}],"tv":15608.96}]}
{"op":"mcm","clk":"993717952","pt":1580545594479,"mc":[{"id":"1.168096552","rc":[{"trd":[[3.1,831.58]],"batl":[[0,3.1,27.45]],"ltp":3.1,"tv":3805.32,"id":18286408}],"tv":15619.28}]}
{"op":"mcm","clk":"993718127","pt":1580545596496,"mc":[{"id":"1.168096552","rc":[{"trd":[[3.05,848.9]],"batb":[[0,3.05,5.4]],"ltp":3.05,"tv":3809.32,"id":18286408}],"tv":15623.28}]}
{"op":"mcm","clk":"993718166","pt":1580545597168,"mc":[{"id":"1.168096552","rc":[{"batl":[[0,32,2.98]],"ltp":21.0,"tv":198.69,"id":24608298}]}]}
{"op":"mcm","clk":"993718263","pt":1580545598404,"mc":[{"id":"1.168096552","rc":[{"trd":[[4.7,1149.13]],"batb":[[0,4.6,4],[1,4.5,44.1],[2,4.4,9.98]],"batl":[[0,4.7,6.03],[1,4.8,14.55],[2,4.9,78.91]],"ltp":4.7,"tv":3542.94,"id":21580749}],"tv":15631.22}]}
{"op":"mcm","clk":"993718286","pt":1580545598664,"mc":[{"id":"1.168096552","rc":[{"batb":[[0,4.5,44.1],[1,4.4,9.98],[2,4.3,27.43]],"batl":[[0,4.7,8.03],[1,4.8,16.55]],"ltp":4.7,"tv":3542.94,"id":21580749},{"batb":[[1,2.92,190.31]],"ltp":2.94,"tv":7485.88,"id":52106}]}]}
{"op":"mcm","clk":"993718416","pt":1580545600378,"mc":[{"id":"1.168096552","rc":[{"batb":[[1,4.4,12.27]],"ltp":4.7,"tv":3542.94,"id":21580749}]}]}
{"op":"mcm","clk":"993718503","pt":1580545601465,"mc":[{"id":"1.168096552","rc":[{"batb":[[1,4.4,9.98]],"ltp":4.7,"tv":3542.94,"id":21580749}]}]}
{"op":"mcm","clk":"993718899","pt":1580545606260,"mc":[{"id":"1.168096552","rc":[{"trd":[[3.05,852.9]],"batb":[[0,3.05,3.4]],"ltp":3.05,"tv":3813.32,"id":18286408}],"tv":15635.22}]}
{"op":"mcm","clk":"993719413","pt":1580545612489,"mc":[{"id":"1.168096552","rc":[{"batl":[[2,4.9,68.91]],"ltp":4.7,"tv":3542.94,"id":21580749}]}]}
{"op":"mcm","clk":"993719636","pt":1580545615495,"mc":[{"id":"1.168096552","rc":[{"trd":[[3.05,856.9]],"batb":[[0,3.05,1.4]],"ltp":3.05,"tv":3817.31,"id":18286408}],"tv":15639.22}]}
{"op":"mcm","clk":"993719718","pt":1580545616422,"mc":[{"id":"1.168096552","rc":[{"batb":[[2,2.98,44.37]],"ltp":3.05,"tv":3817.31,"id":18286408}]}]}
{"op":"mcm","clk":"993719796","pt":1580545617405,"mc":[{"id":"1.168096552","rc":[{"batb":[[2,2.98,54.78]],"ltp":3.05,"tv":3817.31,"id":18286408}]}]}
{"op":"mcm","clk":"993720712","pt":1580545626840,"mc":[{"id":"1.168096552","rc":[{"batl":[[2,15.5,7.01]],"ltp":14.5,"tv":494.81,"id":26640937}]}]}
{"op":"mcm","clk":"993720874","pt":1580545628506,"mc":[{"id":"1.168096552","rc":[{"batb":[[0,22,18.61]],"ltp":21.0,"tv":198.69,"id":24608298}]}]}
{"op":"mcm","clk":"993720932","pt":1580545629121,"mc":[{"id":"1.168096552","rc":[{"batb":[[0,22,16.57],[1,21,10.8]],"ltp":21.0,"tv":198.69,"id":24608298}]}]}
{"op":"mcm","clk":"993721056","pt":1580545630520,"mc":[{"id":"1.168096552","rc":[{"trd":[[3,630.14],[3.05,859.7]],"batb":[[0,3,80.4],[1,2.98,54.78],[2,2.96,27]],"batl":[[0,3.1,38]],"ltp":3.0,"tv":3831.32,"id":18286408},{"batl":[[1,3,9.2],[2,3.05,11]],"ltp":2.94,"tv":7485.88,"id":52106}],"tv":15653.22}]}
{"op":"mcm","clk":"993721332","pt":1580545633936,"mc":[{"id":"1.168096552","rc":[{"batl":[[1,100,2],[2,110,2]],"ltp":65.0,"tv":99.56,"id":27706761}]}]}
{"op":"mcm","clk":"993721972","pt":1580545641517,"mc":[{"id":"1.168096552","rc":[{"batb":[[0,3.05,26.05],[1,3,80.4],[2,2.98,41]],"ltp":3.0,"tv":3831.32,"id":18286408},{"batb":[[0,4.6,10.08],[1,4.5,44.1],[2,4.4,9.98]],"ltp":4.7,"tv":3542.94,"id":21580749},{"batb":[[0,60,6.48],[1,55,4],[2,50,3.01]],"ltp":65.0,"tv":99.56,"id":27706761},{"batb":[[0,2.96,12.6],[1,2.94,38.31],[2,2.92,177.69]],"ltp":2.94,"tv":7485.88,"id":52106},{"batb":[[0,23,5.04],[1,22,16.57],[2,21,10.8]],"ltp":21.0,"tv":198.69,"id":24608298}]}]}
{"op":"mcm","clk":"993722048","pt":1580545642445,"mc":[{"id":"1.168096552","rc":[{"batb":[[1,55,6.54]],"ltp":65.0,"tv":99.56,"id":27706761}]}]}
{"op":"mcm","clk":"993722176","pt":1580545644054,"mc":[{"id":"1.168096552","rc":[{"trd":[[3.05,863.7]],"batb":[[0,3.05,24.05]],"ltp":3.05,"tv":3835.32,"id":18286408}],"tv":15657.22}]}
{"op":"mcm","clk":"993722435","pt":1580545647449,"mc":[{"id":"1.168096552","rc":[{"batb":[[1,21,10.8],[2,20,3.46]],"ltp":21.0,"tv":198.69,"id":24608298}]}]}
{"op":"mcm","clk":"993722522","pt":1580545648227,"mc":[{"id":"1.168096552","rc":[{"batb":[[1,2.94,42.64]],"ltp":2.94,"tv":7485.88,"id":52106},{"batb":[[0,22,2.15],[2,20,8.06]],"ltp":21.0,"tv":198.69,"id":24608298}]}]}
{"op":"mcm","clk":"993722622","pt":1580545649463,"mc":[{"id":"1.168096552","rc":[{"batb":[[0,2.96,14.6]],"ltp":2.94,"tv":7485.88,"id":52106}]}]}
{"op":"mcm","clk":"993723718","pt":1580545664040,"mc":[{"id":"1.168096552","rc":[{"trd":[[3.05,867.7]],"batb":[[0,3.05,22.05]],"ltp":3.05,"tv":3839.32,"id":18286408}],"tv":15661.22}]}
{"op":"mcm","clk":"993723972","pt":1580545667449,"mc":[{"id":"1.168096552","rc":[{"trd":[[3.05,871.7]],"batb":[[0,3.05,20.05]],"ltp":3.05,"tv":3843.32,"id":18286408}],"tv":15665.22}]}
{"op":"mcm","clk":"993724756","pt":1580545678452,"mc":[{"id":"1.168096552","rc":[{"trd":[[3.05,911.8]],"batb":[[0,3,80.4],[1,2.98,41],[2,2.96,33]],"batl":[[0,3.05,4.95],[1,3.1,38],[2,3.15,145.82]],"ltp":3.05,"tv":3883.41,"id":18286408},{"batb":[[0,4.6,14.08]],"ltp":4.7,"tv":3542.94,"id":21580749},{"batb":[[1,2.94,38.31]],"ltp":2.94,"tv":7485.88,"id":52106},{"batb":[[2,20,3.46]],"ltp":21.0,"tv":198.69,"id":24608298}],"tv":15705.32}]}
{"op":"mcm","clk":"993724844","pt":1580545679477,"mc":[{"id":"1.168096552","rc":[{"batb":[[1,2.98,54.87]],"ltp":3.05,"tv":3883.41,"id":18286408},{"batb":[[1,2.94,43.29]],"ltp":2.94,"tv":7485.88,"id":52106}]}]}
{"op":"mcm","clk":"993725576","pt":1580545689467,"mc":[{"id":"1.168096552","rc":[{"trd":[[3.05,921.7]],"batb":[[0,3.05,5.44],[1,3,80.4],[2,2.98,54.87]],"batl":[[0,3.1,98],[1,3.15,85.82],[2,3.2,24]],"ltp":3.05,"tv":3893.31,"id":18286408}],"tv":15715.22}]}
{"op":"mcm","clk":"993725650","pt":1580545690390,"mc":[{"id":"1.168096552","rc":[{"batb":[[2,2.98,41]],"batl":[[0,3.1,123]],"ltp":3.05,"tv":3893.31,"id":18286408},{"batb":[[1,2.94,38.31]],"ltp":2.94,"tv":7485.88,"id":52106}]}]}
{"op":"mcm","clk":"993726124","pt":1580545696220,"mc":[{"id":"1.168096552","rc":[{"trd":[[14,18.66]],"batb":[[0,13,11.43],[1,12.5,1.87],[2,10.5,24.86]],"batl":[[0,14,8.98],[1,14.5,3.01],[2,15,9.8]],"ltp":14.0,"tv":504.85,"id":26640937},{"batb":[[1,2.94,43.29]],"ltp":2.94,"tv":7485.88,"id":52106}],"tv":15725.26}]}
{"op":"mcm","clk":"993726322","pt":1580545698491,"mc":[{"id":"1.168096552","rc":[{"trd":[[13.5,10.34]],"batb":[[0,13,7.7],[1,12.5,5.87],[2,11,6.9]],"batl":[[0,13.5,8.21],[1,14,4.98],[2,14.5,3.01]],"ltp":13.5,"tv":504.95,"id":26640937},{"trd":[[4.6,652.78]],"batb":[[0,4.6,4.08]],"batl":[[0,4.7,6.03]],"ltp":4.6,"tv":3562.93,"id":21580749}],"tv":15745.36}]}
{"op":"mcm","clk":"993726392","pt":1580545699515,"mc":[{"id":"1.168096552","rc":[{"batb":[[0,13,5.7],[1,12.5,3.87]],"batl":[[1,14,14.98]],"ltp":13.5,"tv":504.95,"id":26640937}]}]}
{"op":"mcm","clk":"993726448","pt":1580545700087,"mc":[{"id":"1.168096552","rc":[{"batb":[[1,12.5,1.87]],"ltp":13.5,"tv":504.95,"id":26640937}]}]}
{"op":"mcm","clk":"993727041","pt":1580545707512,"mc":[{"id":"1.168096552","rc":[{"batb":[[1,12.5,3.87]],"ltp":13.5,"tv":504.95,"id":26640937},{"trd":[[4.7,1161.19]],"batb":[[0,4.7,4.18],[1,4.6,4.08],[2,4.5,44.1]],"batl":[[0,4.8,16.55],[1,4.9,68.91],[2,5,17.39]],"ltp":4.7,"tv":3574.99,"id":21580749},{"batb":[[1,2.94,38.31]],"ltp":2.94,"tv":7485.88,"id":52106}],"tv":15757.42}]}
{"op":"mcm","clk":"993727335","pt":1580545711429,"mc":[{"id":"1.168096552","rc":[{"trd":[[13.5,26.76],[14,42.24]],"batb":[[0,13,7.7]],"batl":[[0,14,5.19],[1,14.5,3.01],[2,15,7.8]],"ltp":14.0,"tv":544.95,"id":26640937}],"tv":15797.42}]}
{"op":"mcm","clk":"993727404","pt":1580545712306,"mc":[{"id":"1.168096552","rc":[{"batb":[[0,13,8.93]],"ltp":14.0,"tv":544.95,"id":26640937}]}]}
{"op":"mcm","clk":"993727474","pt":1580545713126,"mc":[{"id":"1.168096552","rc":[{"trd":[[3.05,925.7]],"batb":[[0,3.05,3.44]],"ltp":3.05,"tv":3897.31,"id":18286408}],"tv":15801.42}]}
{"op":"mcm","clk":"993727865","pt":1580545716337,"mc":[{"id":"1.168096552","rc":[{"trd":[[3.1,850.81]],"batb":[[0,3.05,8.68],[1,3,92.5]],"batl":[[0,3.1,113.38]],"ltp":3.1,"tv":3916.54,"id":18286408}],"tv":15820.64}]}
{"op":"mcm","clk":"993728424","pt":1580545723519,"mc":[{"id":"1.168096552","rc":[{"trd":[[4.7,1169.55]],"batb":[[0,4.6,4.08],[1,4.5,44.1],[2,4.4,9.98]],"batl":[[0,4.7,5.82],[1,4.8,16.55],[2,4.9,68.91]],"ltp":4.7,"tv":3583.35,"id":21580749},{"batb":[[1,2.94,43.29]],"ltp":2.94,"tv":7485.88,"id":52106}],"tv":15829.0}]}
{"op":"mcm","clk":"993728453","pt":1580545723929,"mc":[{"id":"1.168096552","rc":[{"trd":[[3.05,929.7]],"batb":[[0,3.05,6.68]],"ltp":3.05,"tv":3920.54,"id":18286408}],"tv":15833.0}]}
{"op":"mcm","clk":"993729140","pt":1580545733452,"mc":[{"id":"1.168096552","rc":[{"trd":[[3.05,943.06]],"batb":[[0,3,92.5],[1,2.98,41],[2,2.96,33]],"batl":[[0,3.05,18.32],[1,3.1,113.38],[2,3.15,85.82]],"ltp":3.05,"tv":3933.9,"id":18286408}],"tv":15846.36}]}
{"op":"mcm","clk":"993729222","pt":1580545734450,"mc":[{"id":"1.168096552","rc":[{"batb":[[1,2.98,44.43]],"batl":[[0,3.05,20.32]],"ltp":3.05,"tv":3933.9,"id":18286408}]}]}
{"op":"mcm","clk":"993729304","pt":1580545735480,"mc":[{"id":"1.168096552","rc":[{"batb":[[1,2.98,54.78]],"ltp":3.05,"tv":3933.9,"id":18286408},{"batb":[[0,13,7.7]],"ltp":14.0,"tv":544.95,"id":26640937}]}]}
{"op":"mcm","clk":"993729373","pt":1580545736457,"mc":[{"id":"1.168096552","rc":[{"batb":[[0,2.96,18.6]],"ltp":2.94,"tv":7485.88,"id":52106}]}]}
{"op":"mcm","clk":"993729529","pt":1580545738282,"mc":[{"id":"1.168096552","rc":[{"trd":[[2.98,486.31]],"batl":[[0,2.98,7.35]],"ltp":2.98,"tv":7496.16,"id":52106}],"tv":15856.64}]}
{"op":"mcm","clk":"993729838","pt":1580545742473,"mc":[{"id":"1.168096552","rc":[{"trd":[[4.5,453.24],[4.6,660.95]],"batb":[[0,4.5,38.18],[1,4.4,9.98],[2,4.3,27.43]],"ltp":4.5,"tv":3603.36,"id":21580749},{"batb":[[1,2.94,45.29]],"ltp":2.98,"tv":7496.16,"id":52106}],"tv":15876.65}]}
{"op":"mcm","clk":"993729926","pt":1580545743461,"mc":[{"id":"1.168096552","rc":[{"batb":[[0,4.6,3],[1,4.5,38.18],[2,4.4,9.98]],"ltp":4.5,"tv":3603.36,"id":21580749},{"batb":[[0,22,18.72]],"ltp":21.0,"tv":198.69,"id":24608298}]}]}
{"op":"mcm","clk":"993729999","pt":1580545744486,"mc":[{"id":"1.168096552","rc":[{"batb":[[0,22,16.57]],"ltp":21.0,"tv":198.69,"id":24608298}]}]}
{"op":"mcm","clk":"993730517","pt":1580545751483,"mc":[{"id":"1.168096552","rc":[{"trd":[[4.6,680.95]],"batb":[[0,4.6,1.81]],"ltp":4.6,"tv":3623.36,"id":21580749}],"tv":15896.65}]}
{"op":"mcm","clk":"993730593","pt":1580545752457,"mc":[{"id":"1.168096552","rc":[{"batb":[[0,4.6,4.81]],"ltp":4.6,"tv":3623.36,"id":21580749}]}]}
{"op":"mcm","clk":"993730744","pt":1580545754476,"mc":[{"id":"1.168096552","rc":[{"batb":[[0,3,100.06]],"ltp":3.05,"tv":3933.9,"id":18286408},{"trd":[[14,48.1]],"batb":[[0,13.5,14.6],[1,13,7.7],[2,12.5,3.87]],"batl":[[0,14.5,3.27],[1,15,7.8],[2,15.5,5]],"ltp":14.0,"tv":550.81,"id":26640937},{"batl":[[0,4.7,7.82]],"ltp":4.6,"tv":3623.36,"id":21580749},{"batb":[[0,23,5.04],[1,22,16.57],[2,21,10.8]],"ltp":21.0,"tv":198.69,"id":24608298}],"tv":15902.51}]}
{"op":"mcm","clk":"993730791","pt":1580545755085,"mc":[{"id":"1.168096552","rc":[{"trd":[[14,48.62]],"batl":[[0,14.5,3.01]],"ltp":14.0,"tv":551.33,"id":26640937},{"trd":[[4.6,684.57]],"batb":[[0,4.5,38.18],[1,4.4,9.98],[2,4.3,27.43]],"ltp":4.6,"tv":3626.98,"id":21580749}],"tv":15906.65}]}
{"op":"mcm","clk":"993730896","pt":1580545756485,"mc":[{"id":"1.168096552","rc":[{"batb":[[1,4.4,12.52]],"ltp":4.6,"tv":3626.98,"id":21580749}]}]}
{"op":"mcm","clk":"993731033","pt":1580545758505,"mc":[{"id":"1.168096552","rc":[{"batb":[[1,4.4,9.98]],"ltp":4.6,"tv":3626.98,"id":21580749}]}]}
{"op":"mcm","clk":"993731071","pt":1580545758970,"mc":[{"id":"1.168096552","rc":[{"batl":[[1,4.8,18.06]],"ltp":4.6,"tv":3626.98,"id":21580749},{"batl":[[0,2.98,9.87]],"ltp":2.98,"tv":7496.16,"id":52106}]}]}
{"op":"mcm","clk":"993731351","pt":1580545762493,"mc":[{"id":"1.168096552","rc":[{"batb":[[0,4.6,7.56],[1,4.5,38.18],[2,4.4,9.98]],"ltp":4.6,"tv":3626.98,"id":21580749},{"batb":[[0,24,15.19],[1,23,5.04]],"ltp":21.0,"tv":198.69,"id":24608298}]}]}
{"op":"mcm","clk":"993731427","pt":1580545763370,"mc":[{"id":"1.168096552","rc":[{"batb":[[0,3,93.06]],"batl":[[0,3.05,23.32]],"ltp":3.05,"tv":3933.9,"id":18286408}]}]}
{"op":"mcm","clk":"993732586","pt":1580545772509,"mc":[{"id":"1.168096552","rc":[{"batb":[[2,21,2]],"ltp":21.0,"tv":198.69,"id":24608298}]}]}
{"op":"mcm","clk":"993732673","pt":1580545773484,"mc":[{"id":"1.168096552","rc":[{"batb":[[0,24,23.99]],"ltp":21.0,"tv":198.69,"id":24608298}]}]}
{"op":"mcm","clk":"993733248","pt":1580545781441,"mc":[{"id":"1.168096552","rc":[{"batb":[[0,24,8.8]],"ltp":21.0,"tv":198.69,"id":24608298}]}]}
{"op":"mcm","clk":"993733397","pt":1580545783404,"mc":[{"id":"1.168096552","rc":[{"batb":[[1,21,2],[2,20,3.46]],"ltp":21.0,"tv":198.69,"id":24608298}]}]}
{"op":"mcm","clk":"993734216","pt":1580545792464,"mc":[{"id":"1.168096552","rc":[{"batb":[[0,3,100.06]],"batl":[[0,3.05,20.32]],"ltp":3.05,"tv":3933.9,"id":18286408},{"batb":[[0,14,2.28],[1,13.5,14.6],[2,13,7.7]],"batl":[[0,14.5,1.01],[1,15,9.8]],"ltp":14.0,"tv":551.33,"id":26640937},{"batb":[[0,4.6,10.56]],"batl":[[0,4.7,5.82]],"ltp":4.6,"tv":3626.98,"id":21580749},{"batb":[[0,21,15.4],[1,20,8.06],[2,19.5,6.08]],"ltp":21.0,"tv":198.69,"id":24608298}]}]}
{"op":"mcm","clk":"993734303","pt":1580545793442,"mc":[{"id":"1.168096552","rc":[{"batl":[[0,3.05,23.32]],"ltp":3.05,"tv":3933.9,"id":18286408},{"trd":[[14.5,79.3]],"batl":[[0,15,9.8],[1,15.5,5],[2,17,1.76]],"ltp":14.5,"tv":553.35,"id":26640937},{"batl":[[0,4.7,7.82]],"ltp":4.6,"tv":3626.98,"id":21580749},{"batb":[[0,22,2.28],[1,21,15.4],[2,20,8.06]],"ltp":21.0,"tv":198.69,"id":24608298}],"tv":15908.67}]}
{"op":"mcm","clk":"993734379","pt":1580545794425,"mc":[{"id":"1.168096552","rc":[{"batb":[[1,21,10.8],[2,20,3.46]],"ltp":21.0,"tv":198.69,"id":24608298}]}]}
{"op":"mcm","clk":"993734829","pt":1580545800468,"mc":[{"id":"1.168096552","rc":[{"batb":[[0,22,18.85]],"ltp":21.0,"tv":198.69,"id":24608298}]}]}
{"op":"mcm","clk":"993734884","pt":1580545801034,"mc":[{"id":"1.168096552","rc":[{"batb":[[0,22,16.57]],"ltp":21.0,"tv":198.69,"id":24608298}]}]}
{"op":"mcm","clk":"993737284","pt":1580545826511,"mc":[{"id":"1.168096552","rc":[{"batb":[[0,3,93.06]],"ltp":3.05,"tv":3933.9,"id":18286408},{"trd":[[4.7,1206.33]],"batb":[[0,4.7,2.04],[1,4.6,10.56],[2,4.5,38.18]],"batl":[[0,4.8,18.06],[1,4.9,68.91],[2,5,17.39]],"ltp":4.7,"tv":3663.76,"id":21580749},{"batb":[[0,2.96,14.6]],"ltp":2.98,"tv":7496.16,"id":52106}],"tv":15945.45}]}
{"op":"mcm","clk":"993737367","pt":1580545827499,"mc":[{"id":"1.168096552","rc":[{"batb":[[1,2.98,41]],"ltp":3.05,"tv":3933.9,"id":18286408},{"batb":[[1,2.94,40.31]],"ltp":2.98,"tv":7496.16,"id":52106}]}]}
{"op":"mcm","clk":"993738224","pt":1580545838408,"mc":[{"id":"1.168096552","rc":[{"batb":[[0,21,10.8],[1,20,3.46],[2,19.5,3.14]],"ltp":21.0,"tv":198.69,"id":24608298}]}]}
{"op":"mcm","clk":"993738303","pt":1580545839488,"mc":[{"id":"1.168096552","rc":[{"trd":[[4.8,318.33]],"batl":[[0,4.8,14.06]],"ltp":4.8,"tv":3671.76,"id":21580749},{"batb":[[0,22,2.21],[1,21,10.8],[2,20,3.46]],"ltp":21.0,"tv":198.69,"id":24608298}],"tv":15953.45}]}
{"op":"mcm","clk":"993738377","pt":1580545840493,"mc":[{"id":"1.168096552","rc":[{"trd":[[4.8,322.33]],"batb":[[0,4.7,5.56]],"batl":[[0,4.8,12.06]],"ltp":4.8,"tv":3675.76,"id":21580749}],"tv":15957.45}]}
{"op":"mcm","clk":"993738783","pt":1580545845476,"mc":[{"id":"1.168096552","rc":[{"batb":[[1,2.98,54.78]],"ltp":3.05,"tv":3933.9,"id":18286408},{"trd":[[4.7,1217.45]],"batb":[[0,4.6,10.56],[1,4.5,41.7],[2,4.4,9.98]],"batl":[[0,4.7,4.44],[1,4.8,12.06],[2,4.9,68.91]],"ltp":4.7,"tv":3686.88,"id":21580749},{"batb":[[1,2.94,45.29]],"ltp":2.98,"tv":7496.16,"id":52106}],"tv":15968.57}]}
{"op":"mcm","clk":"993738862","pt":1580545846428,"mc":[{"id":"1.168096552","rc":[{"batl":[[0,4.7,16.44]],"ltp":4.7,"tv":3686.88,"id":21580749},{"batb":[[0,60,7.07]],"ltp":65.0,"tv":99.56,"id":27706761}]}]}
{"op":"mcm","clk":"993738953","pt":1580545847516,"mc":[{"id":"1.168096552","rc":[{"batb":[[1,4.5,38.18]],"ltp":4.7,"tv":3686.88,"id":21580749}]}]}
{"op":"mcm","clk":"993739810","pt":1580545858439,"mc":[{"id":"1.168096552","rc":[{"batb":[[0,22,18.78]],"ltp":21.0,"tv":198.69,"id":24608298}]}]}
{"op":"mcm","clk":"993739880","pt":1580545859321,"mc":[{"id":"1.168096552","rc":[{"batb":[[0,4.6,7.56]],"ltp":4.7,"tv":3686.88,"id":21580749},{"batb":[[0,22,16.57]],"ltp":21.0,"tv":198.69,"id":24608298}]}]}
{"op":"mcm","clk":"993740702","pt":1580545870472,"mc":[{"id":"1.168096552","rc":[{"trd":[[4.6,699.69]],"batb":[[0,4.5,38.18],[1,4.4,9.98],[2,4.3,27.43]],"batl":[[0,4.6,14.37],[1,4.7,16.44],[2,4.8,12.06]],"ltp":4.6,"tv":3702.0,"id":21580749}],"tv":15983.69}]}
{"op":"mcm","clk":"993740749","pt":1580545871042,"mc":[{"id":"1.168096552","rc":[{"batb":[[0,3,99.06]],"batl":[[0,3.05,20.32]],"ltp":3.05,"tv":3933.9,"id":18286408},{"trd":[[4.6,717.21]],"batb":[[1,4.4,15.58]],"batl":[[0,4.6,5.61]],"ltp":4.6,"tv":3719.53,"id":21580749}],"tv":16001.21}]}
{"op":"mcm","clk":"993740838","pt":1580545872179,"mc":[{"id":"1.168096552","rc":[{"batl":[[0,4.6,15.61]],"ltp":4.6,"tv":3719.53,"id":21580749}]}]}
{"op":"mcm","clk":"993740939","pt":1580545873372,"mc":[{"id":"1.168096552","rc":[{"batb":[[1,4.4,9.98]],"ltp":4.6,"tv":3719.53,"id":21580749}]}]}
{"op":"mcm","clk":"993742231","pt":1580545891494,"mc":[{"id":"1.168096552","rc":[{"trd":[[4.6,737.22]],"batl":[[0,4.6,5.61]],"ltp":4.6,"tv":3739.53,"id":21580749}],"tv":16021.22}]}
{"op":"mcm","clk":"993742631","pt":1580545896515,"mc":[{"id":"1.168096552","rc":[{"batb":[[0,23,5.04]],"ltp":21.0,"tv":198.69,"id":24608298}]}]}
