{"op":"mcm","clk":"987610413","pt":1580469009979,"mc":[{"id":"1.168096552","marketDefinition":{"bspMarket":true,"turnInPlayEnabled":true,"persistenceEnabled":true,"marketBaseRate":5.0,"eventId":"29677422","eventTypeId":"7","numberOfWinners":1,"bettingType":"ODDS","marketType":"WIN","marketTime":"2020-02-01T12:40:00.000Z","suspendTime":"2020-02-01T12:40:00.000Z","bspReconciled":false,"complete":true,"inPlay":false,"crossMatching":false,"runnersVoidable":false,"numberOfActiveRunners":6,"betDelay":0,"status":"OPEN","runners":[{"adjustmentFactor":33.3,"status":"ACTIVE","sortPriority":1,"id":18286408,"name":"Flic Ou Voyou"},{"adjustmentFactor":29.13,"status":"ACTIVE","sortPriority":2,"id":52106,"name":"Palladium"},{"adjustmentFactor":16.07,"status":"ACTIVE","sortPriority":3,"id":21580749,"name":"Golden Taipan"},{"adjustmentFactor":13.18,"status":"ACTIVE","sortPriority":4,"id":26640937,"name":"The Newest One"},{"adjustmentFactor":5.48,"status":"ACTIVE","sortPriority":5,"id":27706761,"name":"Kalakawa Enki"},{"adjustmentFactor":2.81,"status":"ACTIVE","sortPriority":6,"id":24608298,"name":"Vorashann"}],"regulators":["MR_INT"],"venue":"Sandown","countryCode":"GB","discountAllowed":false,"timezone":"Europe/London","openDate":"2020-02-01T12:40:00.000Z","version":3142853444,"name":"2m Nov Hrd","eventName":"Sand  1st Feb"}}]}
{"op":"mcm","clk":"987610534","pt":1580469011474,"mc":[{"id":"1.168096552","rc":[{"batb":[[0,1.55,18.18],[1,1.01,2827.2]],"ltp":0.0,"tv":0.0,"id":18286408},{"batb":[[0,1.55,18.18],[1,1.01,2827.2]],"ltp":0.0,"tv":0.0,"id":26640937},{"batb":[[0,1.55,18.18],[1,1.01,2827.2]],"ltp":0.0,"tv":0.0,"id":21580749},{"batb":[[0,1.55,18.18],[1,1.01,2827.2]],"ltp":0.0,"tv":0.0,"id":27706761},{"batb":[[0,1.55,18.18],[1,1.01,2827.2]],"ltp":0.0,"tv":0.0,"id":52106},{"batb":[[0,1.55,18.18],[1,1.01,2827.2]],"ltp":0.0,"tv":0.0,"id":24608298}]}]}
{"op":"mcm","clk":"987610592","pt":1580469012468,"mc":[{"id":"1.168096552","rc":[{"batb":[[1,1.51,3.36],[2,1.01,2830.56]],"ltp":0.0,"tv":0.0,"id":18286408},{"batb":[[1,1.51,3.36],[2,1.01,2830.56]],"ltp":0.0,"tv":0.0,"id":26640937},{"batb":[[1,1.51,3.36],[2,1.01,2830.56]],"ltp":0.0,"tv":0.0,"id":21580749},{"batb":[[1,1.51,3.36],[2,1.01,2830.56]],"ltp":0.0,"tv":0.0,"id":27706761},{"batb":[[1,1.51,3.36],[2,1.01,2830.56]],"ltp":0.0,"tv":0.0,"id":52106},{"batb":[[1,1.51,3.36],[2,1.01,2830.56]],"ltp":0.0,"tv":0.0,"id":24608298}]}]}
{"op":"mcm","clk":"987610672","pt":1580469013466,"mc":[{"id":"1.168096552","marketDefinition":{"bspMarket":true,"turnInPlayEnabled":true,"persistenceEnabled":true,"marketBaseRate":5.0,"eventId":"29677422","eventTypeId":"7","numberOfWinners":1,"bettingType":"ODDS","marketType":"WIN","marketTime":"2020-02-01T12:40:00.000Z","suspendTime":"2020-02-01T12:40:00.000Z","bspReconciled":false,"complete":true,"inPlay":false,"crossMatching":false,"runnersVoidable":false,"numberOfActiveRunners":6,"betDelay":0,"status":"OPEN","runners":[{"adjustmentFactor":33.3,"status":"ACTIVE","sortPriority":1,"id":18286408,"name":"Flic Ou Voyou"},{"adjustmentFactor":29.13,"status":"ACTIVE","sortPriority":2,"id":52106,"name":"Palladium"},{"adjustmentFactor":16.07,"status":"ACTIVE","sortPriority":3,"id":21580749,"name":"Golden Taipan"},{"adjustmentFactor":13.18,"status":"ACTIVE","sortPriority":4,"id":26640937,"name":"The Newest One"},{"adjustmentFactor":5.48,"status":"ACTIVE","sortPriority":5,"id":27706761,"name":"Kalakawa Enki"},{"adjustmentFactor":2.81,"status":"ACTIVE","sortPriority":6,"id":24608298,"name":"Vorashann"}],"regulators":["MR_INT"],"venue":"Sandown","countryCode":"GB","discountAllowed":true,"timezone":"Europe/London","openDate":"2020-02-01T12:40:00.000Z","version":3142853444,"name":"2m Nov Hrd","eventName":"Sand  1st Feb"}}]}
{"op":"mcm","clk":"987611797","pt":1580469030006,"mc":[{"id":"1.168096552","rc":[{"batb":[[2,1.03,5.18]],"ltp":0.0,"tv":0.0,"id":18286408},{"batb":[[2,1.03,5.18]],"ltp":0.0,"tv":0.0,"id":26640937},{"batb":[[2,1.03,5.18]],"ltp":0.0,"tv":0.0,"id":21580749},{"batb":[[2,1.03,5.18]],"ltp":0.0,"tv":0.0,"id":27706761},{"batb":[[2,1.03,5.18]],"ltp":0.0,"tv":0.0,"id":52106},{"batb":[[2,1.03,5.18]],"ltp":0.0,"tv":0.0,"id":24608298}]}]}
{"op":"mcm","clk":"987611954","pt":1580469032110,"mc":[{"id":"1.168096552","rc":[{"batb":[[2,1.03,1696.65]],"ltp":0.0,"tv":0.0,"id":18286408},{"batb":[[2,1.03,1851.33]],"ltp":0.0,"tv":0.0,"id":26640937},{"batb":[[2,1.03,1587.36]],"ltp":0.0,"tv":0.0,"id":21580749},{"batb":[[2,1.03,1522.62]],"ltp":0.0,"tv":0.0,"id":27706761},{"batb":[[2,1.03,1572.22]],"ltp":0.0,"tv":0.0,"id":52106},{"batb":[[2,1.03,1777.35]],"ltp":0.0,"tv":0.0,"id":24608298}]}]}
{"op":"mcm","clk":"987632415","pt":1580469315432,"mc":[{"id":"1.168096552","rc":[{"batb":[[0,1.56,10],[1,1.55,18.18],[2,1.51,3.36]],"ltp":0.0,"tv":0.0,"id":18286408},{"batb":[[0,1.56,10],[1,1.55,18.18],[2,1.51,3.36]],"ltp":0.0,"tv":0.0,"id":26640937},{"batb":[[0,1.56,10],[1,1.55,18.18],[2,1.51,3.36]],"ltp":0.0,"tv":0.0,"id":21580749},{"batb":[[0,1.56,10],[1,1.55,18.18],[2,1.51,3.36]],"ltp":0.0,"tv":0.0,"id":27706761},{"batb":[[0,1.56,10],[1,1.55,18.18],[2,1.51,3.36]],"ltp":0.0,"tv":0.0,"id":52106},{"batb":[[0,1.56,10],[1,1.55,18.18],[2,1.51,3.36]],"ltp":0.0,"tv":0.0,"id":24608298}]}]}
{"op":"mcm","clk":"987634977","pt":1580469351476,"mc":[{"id":"1.168096552","rc":[{"batb":[[0,1.57,1.99],[1,1.56,10],[2,1.55,18.18]],"ltp":0.0,"tv":0.0,"id":18286408},{"batb":[[0,1.57,1.99],[1,1.56,10],[2,1.55,18.18]],"ltp":0.0,"tv":0.0,"id":52106}]}]}
{"op":"mcm","clk":"987635166","pt":1580469352476,"mc":[{"id":"1.168096552","rc":[{"batb":[[0,1.57,1.99],[1,1.56,10],[2,1.55,18.18]],"ltp":0.0,"tv":0.0,"id":26640937},{"batb":[[0,1.57,1.99],[1,1.56,10],[2,1.55,18.18]],"ltp":0.0,"tv":0.0,"id":21580749}]}]}
{"op":"mcm","clk":"987635263","pt":1580469352992,"mc":[{"id":"1.168096552","rc":[{"batb":[[0,1.57,1.99],[1,1.56,10],[2,1.55,18.18]],"ltp":0.0,"tv":0.0,"id":27706761},{"batb":[[0,1.57,1.99],[1,1.56,10],[2,1.55,18.18]],"ltp":0.0,"tv":0.0,"id":24608298}]}]}
{"op":"mcm","clk":"987758822","pt":1580470972688,"mc":[{"id":"1.168096552","rc":[{"batl":[[0,1000,0.2]],"ltp":0.0,"tv":0.0,"id":18286408},{"batl":[[0,1000,0.2]],"ltp":0.0,"tv":0.0,"id":26640937},{"batl":[[0,1000,0.2]],"ltp":0.0,"tv":0.0,"id":21580749},{"batl":[[0,1000,0.2]],"ltp":0.0,"tv":0.0,"id":27706761},{"batl":[[0,1000,0.2]],"ltp":0.0,"tv":0.0,"id":52106},{"batl":[[0,1000,0.2]],"ltp":0.0,"tv":0.0,"id":24608298}]}]}
{"op":"mcm","clk":"988214990","pt":1580475431462,"mc":[{"id":"1.168096552","rc":[{"batb":[[0,1.57,3.04]],"ltp":0.0,"tv":0.0,"id":18286408},{"batb":[[0,1.57,3.04]],"ltp":0.0,"tv":0.0,"id":21580749}]}]}
{"op":"mcm","clk":"988215056","pt":1580475432292,"mc":[{"id":"1.168096552","rc":[{"batb":[[0,1.57,3.04]],"ltp":0.0,"tv":0.0,"id":26640937},{"batb":[[0,1.57,3.04]],"ltp":0.0,"tv":0.0,"id":27706761},{"batb":[[0,1.57,3.04]],"ltp":0.0,"tv":0.0,"id":52106},{"batb":[[0,1.57,3.04]],"ltp":0.0,"tv":0.0,"id":24608298}]}]}
{"op":"mcm","clk":"988689905","pt":1580479652285,"mc":[{"id":"1.168096552","rc":[{"batb":[[0,1.57,3.04]],"ltp":0.0,"tv":0.0,"id":18286408},{"batb":[[0,1.57,3.04]],"ltp":0.0,"tv":0.0,"id":26640937},{"batb":[[0,1.57,3.04]],"ltp":0.0,"tv":0.0,"id":21580749},{"batb":[[0,1.57,3.04]],"ltp":0.0,"tv":0.0,"id":27706761},{"batb":[[0,1.57,3.04]],"ltp":0.0,"tv":0.0,"id":52106},{"batb":[[0,1.57,3.04]],"ltp":0.0,"tv":0.0,"id":24608298}]}]}
{"op":"mcm","clk":"988909811","pt":1580481965078,"mc":[{"id":"1.168096552","rc":[{"batl":[[0,700,2],[1,1000,0.2]],"ltp":0.0,"tv":0.0,"id":24608298}]}]}
{"op":"mcm","clk":"988910626","pt":1580481974190,"mc":[{"id":"1.168096552","rc":[{"batl":[[0,700,2.2],[1,1000,0]],"ltp":0.0,"tv":0.0,"id":24608298}]}]}
{"op":"mcm","clk":"988911200","pt":1580481981337,"mc":[{"id":"1.168096552","rc":[{"batl":[[0,700,3.2]],"ltp":0.0,"tv":0.0,"id":24608298}]}]}
{"op":"mcm","clk":"988912064","pt":1580481992455,"mc":[{"id":"1.168096552","rc":[{"batl":[[0,700,1.2]],"ltp":0.0,"tv":0.0,"id":24608298}]}]}
{"op":"mcm","clk":"988913774","pt":1580482015102,"mc":[{"id":"1.168096552","rc":[{"batl":[[0,5.5,13],[1,1000,0.2]],"ltp":0.0,"tv":0.0,"id":21580749}]}]}
{"op":"mcm","clk":"989109616","pt":1580484359392,"mc":[{"id":"1.168096552","rc":[{"batl":[[0,3.95,9],[1,1000,0.2]],"ltp":0.0,"tv":0.0,"id":52106}]}]}
{"op":"mcm","clk":"989119130","pt":1580484495188,"mc":[{"id":"1.168096552","rc":[{"batl":[[0,5,5],[1,1000,0.2]],"ltp":0.0,"tv":0.0,"id":18286408}]}]}
{"op":"mcm","clk":"989119327","pt":1580484498019,"mc":[{"id":"1.168096552","rc":[{"batl":[[0,1000,0.2],[1,1000,0]],"ltp":0.0,"tv":0.0,"id":18286408}]}]}
{"op":"mcm","clk":"989152294","pt":1580484933973,"mc":[{"id":"1.168096552","rc":[{"batl":[[0,3,10],[1,1000,0.2]],"ltp":0.0,"tv":0.0,"id":18286408}]}]}
{"op":"mcm","clk":"989210493","pt":1580485545802,"mc":[{"id":"1.168096552","rc":[{"trd":[[3,20]],"batb":[[0,3,1],[1,1.57,3.04],[2,1.56,10]],"batl":[[0,1000,0.2],[1,1000,0]],"ltp":3.0,"tv":20.0,"id":18286408}],"tv":20.0}]}
{"op":"mcm","clk":"989211030","pt":1580485552325,"mc":[{"id":"1.168096552","rc":[{"batb":[[1,1.58,3],[2,1.57,1.05]],"ltp":3.0,"tv":20.0,"id":18286408}]}]}
{"op":"mcm","clk":"989212104","pt":1580485566136,"mc":[{"id":"1.168096552","rc":[{"batb":[[1,1.59,3]],"ltp":3.0,"tv":20.0,"id":18286408}]}]}
{"op":"mcm","clk":"989212310","pt":1580485568445,"mc":[{"id":"1.168096552","rc":[{"batb":[[2,1.58,53]],"batl":[[0,4,10],[1,1000,0.2]],"ltp":3.0,"tv":20.0,"id":18286408},{"batb":[[0,2,53],[1,1.57,3.04],[2,1.56,10]],"ltp":0.0,"tv":0.0,"id":26640937},{"batb":[[0,2,53],[1,1.57,3.04],[2,1.56,10]],"ltp":0.0,"tv":0.0,"id":21580749},{"batb":[[0,2,53],[1,1.57,3.04],[2,1.56,10]],"ltp":0.0,"tv":0.0,"id":27706761},{"batb":[[0,2,53],[1,1.57,3.04],[2,1.56,10]],"ltp":0.0,"tv":0.0,"id":52106},{"batb":[[0,2,53],[1,1.57,3.04],[2,1.56,10]],"ltp":0.0,"tv":0.0,"id":24608298}]}]}
{"op":"mcm","clk":"989212466","pt":1580485570237,"mc":[{"id":"1.168096552","rc":[{"batl":[[0,4,10.2],[1,1000,0]],"ltp":3.0,"tv":20.0,"id":18286408}]}]}
{"op":"mcm","clk":"989213106","pt":1580485577953,"mc":[{"id":"1.168096552","rc":[{"batb":[[1,1.59,10.74]],"ltp":3.0,"tv":20.0,"id":18286408},{"batb":[[0,2.02,4.47],[1,2,53],[2,1.57,3.04]],"ltp":0.0,"tv":0.0,"id":26640937},{"batb":[[0,2.02,4.47],[1,2,53],[2,1.57,3.04]],"ltp":0.0,"tv":0.0,"id":21580749},{"batb":[[0,2.02,4.47],[1,2,53],[2,1.57,3.04]],"ltp":0.0,"tv":0.0,"id":27706761},{"batb":[[0,2.02,4.47],[1,2,53],[2,1.57,3.04]],"ltp":0.0,"tv":0.0,"id":52106},{"batb":[[0,2.02,4.47],[1,2,53],[2,1.57,3.04]],"ltp":0.0,"tv":0.0,"id":24608298}]}]}
{"op":"mcm","clk":"989213336","pt":1580485581168,"mc":[{"id":"1.168096552","rc":[{"batb":[[1,1.6,3],[2,1.59,7.74]],"ltp":3.0,"tv":20.0,"id":18286408}]}]}
{"op":"mcm","clk":"989213683","pt":1580485585373,"mc":[{"id":"1.168096552","rc":[{"batb":[[1,1.61,24.57],[2,1.6,3]],"ltp":3.0,"tv":20.0,"id":18286408}]}]}
{"op":"mcm","clk":"989214517","pt":1580485594378,"mc":[{"id":"1.168096552","rc":[{"batb":[[2,1.57,1.99]],"ltp":0.0,"tv":0.0,"id":26640937},{"batb":[[2,1.57,1.99]],"ltp":0.0,"tv":0.0,"id":21580749},{"batb":[[2,1.57,1.99]],"ltp":0.0,"tv":0.0,"id":27706761},{"batb":[[2,1.57,1.99]],"ltp":0.0,"tv":0.0,"id":52106}]}]}
{"op":"mcm","clk":"989214596","pt":1580485595472,"mc":[{"id":"1.168096552","rc":[{"batb":[[1,1.62,3],[2,1.61,24.57]],"ltp":3.0,"tv":20.0,"id":18286408},{"batb":[[2,1.57,1.99]],"ltp":0.0,"tv":0.0,"id":24608298}]}]}
{"op":"mcm","clk":"989215087","pt":1580485601369,"mc":[{"id":"1.168096552","rc":[{"batb":[[2,1.55,18.18]],"ltp":0.0,"tv":0.0,"id":52106}]}]}
{"op":"mcm","clk":"989215190","pt":1580485602467,"mc":[{"id":"1.168096552","rc":[{"batb":[[2,1.55,18.18]],"ltp":0.0,"tv":0.0,"id":26640937},{"batb":[[2,1.55,18.18]],"ltp":0.0,"tv":0.0,"id":21580749},{"batb":[[2,1.55,18.18]],"ltp":0.0,"tv":0.0,"id":27706761}]}]}
{"op":"mcm","clk":"989215234","pt":1580485602995,"mc":[{"id":"1.168096552","rc":[{"batb":[[2,1.55,18.18]],"ltp":0.0,"tv":0.0,"id":24608298}]}]}
{"op":"mcm","clk":"989215397","pt":1580485604993,"mc":[{"id":"1.168096552","rc":[{"batb":[[2,1.59,7.74]],"ltp":3.0,"tv":20.0,"id":18286408}]}]}
{"op":"mcm","clk":"989215881","pt":1580485610077,"mc":[{"id":"1.168096552","rc":[{"batb":[[1,1.63,3]],"ltp":3.0,"tv":20.0,"id":18286408}]}]}
{"op":"mcm","clk":"989216909","pt":1580485623034,"mc":[{"id":"1.168096552","rc":[{"batb":[[1,1.64,3]],"ltp":3.0,"tv":20.0,"id":18286408}]}]}
{"op":"mcm","clk":"989218079","pt":1580485637314,"mc":[{"id":"1.168096552","rc":[{"batb":[[2,1.6,3]],"ltp":3.0,"tv":20.0,"id":18286408},{"batb":[[0,2.02,7.47]],"ltp":0.0,"tv":0.0,"id":26640937},{"batb":[[0,2.02,7.47]],"ltp":0.0,"tv":0.0,"id":21580749},{"batb":[[0,2.02,7.47]],"ltp":0.0,"tv":0.0,"id":27706761},{"batb":[[0,2.02,7.47]],"ltp":0.0,"tv":0.0,"id":52106},{"batb":[[0,2.02,7.47]],"ltp":0.0,"tv":0.0,"id":24608298}]}]}
{"op":"mcm","clk":"989218161","pt":1580485638307,"mc":[{"id":"1.168096552","rc":[{"batb":[[1,1.65,3]],"ltp":3.0,"tv":20.0,"id":18286408}]}]}
{"op":"mcm","clk":"989218566","pt":1580485644106,"mc":[{"id":"1.168096552","rc":[{"batb":[[1,1.65,3.99]],"ltp":3.0,"tv":20.0,"id":18286408},{"batb":[[0,2.02,8.28]],"ltp":0.0,"tv":0.0,"id":26640937},{"batb":[[0,2.02,8.28]],"ltp":0.0,"tv":0.0,"id":21580749},{"batb":[[0,2.02,8.28]],"ltp":0.0,"tv":0.0,"id":27706761},{"batb":[[0,2.02,8.28]],"ltp":0.0,"tv":0.0,"id":52106},{"batb":[[0,2.02,8.28]],"ltp":0.0,"tv":0.0,"id":24608298}]}]}
{"op":"mcm","clk":"989218956","pt":1580485650225,"mc":[{"id":"1.168096552","rc":[{"batb":[[0,2.06,1.99],[1,2.02,8.28],[2,2,53]],"ltp":0.0,"tv":0.0,"id":52106}]}]}
{"op":"mcm","clk":"989219038","pt":1580485651436,"mc":[{"id":"1.168096552","rc":[{"batb":[[0,2.06,1.99],[1,2.02,8.28],[2,2,53]],"ltp":0.0,"tv":0.0,"id":26640937},{"batb":[[0,2.06,1.99],[1,2.02,8.28],[2,2,53]],"ltp":0.0,"tv":0.0,"id":21580749},{"batb":[[0,2.06,1.99],[1,2.02,8.28],[2,2,53]],"ltp":0.0,"tv":0.0,"id":27706761}]}]}
{"op":"mcm","clk":"989219126","pt":1580485652512,"mc":[{"id":"1.168096552","rc":[{"batb":[[1,1.66,3.99]],"ltp":3.0,"tv":20.0,"id":18286408},{"batb":[[0,2.06,1.99],[1,2.02,8.28],[2,2,53]],"ltp":0.0,"tv":0.0,"id":24608298}]}]}
{"op":"mcm","clk":"989220275","pt":1580485667455,"mc":[{"id":"1.168096552","rc":[{"batb":[[1,2.04,5.2],[2,2.02,3]],"ltp":0.0,"tv":0.0,"id":26640937},{"batb":[[1,2.04,5.2],[2,2.02,3]],"ltp":0.0,"tv":0.0,"id":21580749},{"batb":[[1,2.04,5.2],[2,2.02,3]],"ltp":0.0,"tv":0.0,"id":27706761},{"batb":[[1,2.04,5.2],[2,2.02,3]],"ltp":0.0,"tv":0.0,"id":52106},{"batb":[[1,2.04,5.2],[2,2.02,7.47]],"ltp":0.0,"tv":0.0,"id":24608298}]}]}
{"op":"mcm","clk":"989220309","pt":1580485667978,"mc":[{"id":"1.168096552","rc":[{"batb":[[1,1.67,3],[2,1.6,3.99]],"ltp":3.0,"tv":20.0,"id":18286408},{"batb":[[2,2.02,3]],"ltp":0.0,"tv":0.0,"id":24608298}]}]}
{"op":"mcm","clk":"989221767","pt":1580485682959,"mc":[{"id":"1.168096552","rc":[{"batb":[[1,1.68,3]],"ltp":3.0,"tv":20.0,"id":18286408}]}]}
{"op":"mcm","clk":"989222668","pt":1580485693999,"mc":[{"id":"1.168096552","rc":[{"batb":[[1,1.69,3]],"ltp":3.0,"tv":20.0,"id":18286408}]}]}
{"op":"mcm","clk":"989223645","pt":1580485707403,"mc":[{"id":"1.168096552","rc":[{"batb":[[1,1.7,3]],"ltp":3.0,"tv":20.0,"id":18286408}]}]}
{"op":"mcm","clk":"989224546","pt":1580485720339,"mc":[{"id":"1.168096552","rc":[{"batb":[[1,1.71,3]],"ltp":3.0,"tv":20.0,"id":18286408}]}]}
{"op":"mcm","clk":"989225364","pt":1580485732129,"mc":[{"id":"1.168096552","rc":[{"batb":[[1,1.72,3]],"ltp":3.0,"tv":20.0,"id":18286408}]}]}
{"op":"mcm","clk":"989225959","pt":1580485740440,"mc":[{"id":"1.168096552","rc":[{"batb":[[2,1.6,3]],"ltp":3.0,"tv":20.0,"id":18286408}]}]}
{"op":"mcm","clk":"989226374","pt":1580485746065,"mc":[{"id":"1.168096552","rc":[{"batb":[[1,1.73,3]],"ltp":3.0,"tv":20.0,"id":18286408}]}]}
{"op":"mcm","clk":"989227318","pt":1580485759683,"mc":[{"id":"1.168096552","rc":[{"batb":[[1,1.74,3]],"ltp":3.0,"tv":20.0,"id":18286408}]}]}
{"op":"mcm","clk":"989228348","pt":1580485774518,"mc":[{"id":"1.168096552","rc":[{"batb":[[1,1.75,3]],"ltp":3.0,"tv":20.0,"id":18286408}]}]}
{"op":"mcm","clk":"989229340","pt":1580485787432,"mc":[{"id":"1.168096552","rc":[{"batb":[[1,1.76,3]],"ltp":3.0,"tv":20.0,"id":18286408}]}]}
{"op":"mcm","clk":"989230104","pt":1580485798131,"mc":[{"id":"1.168096552","rc":[{"batb":[[1,1.77,3]],"ltp":3.0,"tv":20.0,"id":18286408}]}]}
{"op":"mcm","clk":"989231137","pt":1580485811454,"mc":[{"id":"1.168096552","rc":[{"batb":[[1,1.78,3]],"ltp":3.0,"tv":20.0,"id":18286408}]}]}
{"op":"mcm","clk":"989232476","pt":1580485827479,"mc":[{"id":"1.168096552","rc":[{"batb":[[1,1.6,3],[2,1.59,7.74]],"ltp":3.0,"tv":20.0,"id":18286408}]}]}
{"op":"mcm","clk":"989232486","pt":1580485827585,"mc":[{"id":"1.168096552","rc":[{"batb":[[1,1.79,3],[2,1.6,3]],"ltp":3.0,"tv":20.0,"id":18286408}]}]}
{"op":"mcm","clk":"989233428","pt":1580485841691,"mc":[{"id":"1.168096552","rc":[{"batb":[[1,1.8,3]],"ltp":3.0,"tv":20.0,"id":18286408}]}]}
{"op":"mcm","clk":"989234126","pt":1580485851287,"mc":[{"id":"1.168096552","rc":[{"batb":[[1,1.81,3]],"ltp":3.0,"tv":20.0,"id":18286408}]}]}
{"op":"mcm","clk":"989235538","pt":1580485869200,"mc":[{"id":"1.168096552","rc":[{"batb":[[1,1.82,3]],"ltp":3.0,"tv":20.0,"id":18286408}]}]}
{"op":"mcm","clk":"989236674","pt":1580485884036,"mc":[{"id":"1.168096552","rc":[{"batb":[[1,1.83,3]],"ltp":3.0,"tv":20.0,"id":18286408}]}]}
{"op":"mcm","clk":"989237861","pt":1580485900445,"mc":[{"id":"1.168096552","rc":[{"batb":[[1,1.84,3]],"ltp":3.0,"tv":20.0,"id":18286408}]}]}
{"op":"mcm","clk":"989238773","pt":1580485913461,"mc":[{"id":"1.168096552","rc":[{"batb":[[1,1.6,3],[2,1.59,7.74]],"ltp":3.0,"tv":20.0,"id":18286408}]}]}
{"op":"mcm","clk":"989238779","pt":1580485913564,"mc":[{"id":"1.168096552","rc":[{"batb":[[1,1.85,3],[2,1.6,3]],"ltp":3.0,"tv":20.0,"id":18286408}]}]}
{"op":"mcm","clk":"989239651","pt":1580485925503,"mc":[{"id":"1.168096552","rc":[{"batb":[[1,1.86,3]],"ltp":3.0,"tv":20.0,"id":18286408}]}]}
{"op":"mcm","clk":"989240383","pt":1580485937027,"mc":[{"id":"1.168096552","rc":[{"batb":[[1,1.87,3]],"ltp":3.0,"tv":20.0,"id":18286408}]}]}
{"op":"mcm","clk":"989241217","pt":1580485949251,"mc":[{"id":"1.168096552","rc":[{"batb":[[1,1.88,3]],"ltp":3.0,"tv":20.0,"id":18286408}]}]}
{"op":"mcm","clk":"989251183","pt":1580485961347,"mc":[{"id":"1.168096552","rc":[{"batb":[[1,1.89,3]],"ltp":3.0,"tv":20.0,"id":18286408}]}]}
{"op":"mcm","clk":"989252387","pt":1580485977451,"mc":[{"id":"1.168096552","rc":[{"batb":[[1,1.9,3]],"ltp":3.0,"tv":20.0,"id":18286408}]}]}
{"op":"mcm","clk":"989253261","pt":1580485990383,"mc":[{"id":"1.168096552","rc":[{"batb":[[1,1.91,3]],"ltp":3.0,"tv":20.0,"id":18286408}]}]}
{"op":"mcm","clk":"989254164","pt":1580486003914,"mc":[{"id":"1.168096552","rc":[{"batb":[[1,1.92,3]],"ltp":3.0,"tv":20.0,"id":18286408}]}]}
{"op":"mcm","clk":"989254959","pt":1580486017019,"mc":[{"id":"1.168096552","rc":[{"batb":[[1,1.93,3]],"ltp":3.0,"tv":20.0,"id":18286408}]}]}
{"op":"mcm","clk":"989255687","pt":1580486028508,"mc":[{"id":"1.168096552","rc":[{"batb":[[1,1.94,3]],"ltp":3.0,"tv":20.0,"id":18286408}]}]}
{"op":"mcm","clk":"989255743","pt":1580486029441,"mc":[{"id":"1.168096552","rc":[{"batb":[[1,1.95,10],[2,1.94,3]],"ltp":3.0,"tv":20.0,"id":18286408},{"batb":[[0,2.06,11.7]],"ltp":0.0,"tv":0.0,"id":26640937},{"batb":[[0,2.06,11.7]],"ltp":0.0,"tv":0.0,"id":21580749},{"batb":[[0,2.06,11.7]],"ltp":0.0,"tv":0.0,"id":27706761},{"batb":[[0,2.06,11.7]],"ltp":0.0,"tv":0.0,"id":52106},{"batb":[[0,2.06,11.7]],"ltp":0.0,"tv":0.0,"id":24608298}]}]}
{"op":"mcm","clk":"989256392","pt":1580486040254,"mc":[{"id":"1.168096552","rc":[{"batb":[[1,1.96,3],[2,1.95,10]],"ltp":3.0,"tv":20.0,"id":18286408}]}]}
{"op":"mcm","clk":"989257783","pt":1580486047272,"mc":[{"id":"1.168096552","rc":[{"batb":[[1,1.97,20.09],[2,1.96,3]],"ltp":3.0,"tv":20.0,"id":18286408}]}]}
{"op":"mcm","clk":"989259214","pt":1580486058465,"mc":[{"id":"1.168096552","rc":[{"batb":[[1,1.98,4.66],[2,1.97,20.09]],"ltp":3.0,"tv":20.0,"id":18286408},{"batb":[[0,2.08,4.23],[1,2.06,11.7],[2,2.02,3.81]],"ltp":0.0,"tv":0.0,"id":26640937},{"batb":[[0,2.08,4.23],[1,2.06,11.7],[2,2.02,3.81]],"ltp":0.0,"tv":0.0,"id":21580749},{"batb":[[0,2.08,4.23],[1,2.06,11.7],[2,2.02,3.81]],"ltp":0.0,"tv":0.0,"id":27706761},{"batb":[[0,2.08,4.23],[1,2.06,11.7],[2,2.02,3.81]],"ltp":0.0,"tv":0.0,"id":52106},{"batb":[[0,2.08,4.23],[1,2.06,11.7],[2,2.02,3.81]],"ltp":0.0,"tv":0.0,"id":24608298}]}]}
{"op":"mcm","clk":"989259277","pt":1580486059088,"mc":[{"id":"1.168096552","rc":[{"batb":[[1,1.99,3],[2,1.98,4.66]],"ltp":3.0,"tv":20.0,"id":18286408},{"batb":[[2,2,53.81]],"ltp":0.0,"tv":0.0,"id":26640937},{"batb":[[2,2,53.81]],"ltp":0.0,"tv":0.0,"id":21580749},{"batb":[[2,2,53.81]],"ltp":0.0,"tv":0.0,"id":27706761},{"batb":[[2,2,53.81]],"ltp":0.0,"tv":0.0,"id":52106},{"batb":[[2,2,53.81]],"ltp":0.0,"tv":0.0,"id":24608298}]}]}
{"op":"mcm","clk":"989259984","pt":1580486067368,"mc":[{"id":"1.168096552","rc":[{"batb":[[1,2,19.78],[2,1.99,3]],"ltp":3.0,"tv":20.0,"id":18286408}]}]}
{"op":"mcm","clk":"989260140","pt":1580486069164,"mc":[{"id":"1.168096552","rc":[{"batb":[[2,2.02,6.81]],"ltp":0.0,"tv":0.0,"id":21580749},{"batb":[[2,2.02,6.81]],"ltp":0.0,"tv":0.0,"id":52106}]}]}
{"op":"mcm","clk":"989260251","pt":1580486070378,"mc":[{"id":"1.168096552","rc":[{"batb":[[2,2.02,6.81]],"ltp":0.0,"tv":0.0,"id":26640937},{"batb":[[2,2.02,6.81]],"ltp":0.0,"tv":0.0,"id":27706761},{"batb":[[2,2.02,6.81]],"ltp":0.0,"tv":0.0,"id":24608298}]}]}
{"op":"mcm","clk":"989260504","pt":1580486073896,"mc":[{"id":"1.168096552","rc":[{"batb":[[1,2.02,3],[2,2,19.78]],"ltp":3.0,"tv":20.0,"id":18286408}]}]}
{"op":"mcm","clk":"989261412","pt":1580486084014,"mc":[{"id":"1.168096552","rc":[{"batb":[[1,2.04,3]],"ltp":3.0,"tv":20.0,"id":18286408}]}]}
{"op":"mcm","clk":"989261715","pt":1580486087518,"mc":[{"id":"1.168096552","rc":[{"batb":[[2,2.02,4.47]],"ltp":3.0,"tv":20.0,"id":18286408}]}]}
{"op":"mcm","clk":"989262223","pt":1580486093332,"mc":[{"id":"1.168096552","rc":[{"batb":[[0,2.1,1.99],[1,2.08,4.23],[2,2.06,9.71]],"ltp":0.0,"tv":0.0,"id":21580749},{"batb":[[0,2.1,1.99],[1,2.08,4.23],[2,2.06,9.71]],"ltp":0.0,"tv":0.0,"id":52106}]}]}
{"op":"mcm","clk":"989262357","pt":1580486094491,"mc":[{"id":"1.168096552","rc":[{"batb":[[0,2.1,1.99],[1,2.08,4.23],[2,2.06,9.71]],"ltp":0.0,"tv":0.0,"id":26640937},{"batb":[[0,2.1,1.99],[1,2.08,4.23],[2,2.06,9.71]],"ltp":0.0,"tv":0.0,"id":27706761},{"batb":[[0,2.1,1.99],[1,2.08,4.23],[2,2.06,9.71]],"ltp":0.0,"tv":0.0,"id":24608298}]}]}
{"op":"mcm","clk":"989262673","pt":1580486098235,"mc":[{"id":"1.168096552","rc":[{"batb":[[1,2.06,3]],"ltp":3.0,"tv":20.0,"id":18286408}]}]}
{"op":"mcm","clk":"989262838","pt":1580486099913,"mc":[{"id":"1.168096552","rc":[{"batb":[[2,2.02,6.81]],"ltp":0.0,"tv":0.0,"id":26640937},{"batb":[[2,2.02,6.81]],"ltp":0.0,"tv":0.0,"id":21580749},{"batb":[[2,2.02,6.81]],"ltp":0.0,"tv":0.0,"id":27706761},{"batb":[[2,2.02,6.81]],"ltp":0.0,"tv":0.0,"id":52106},{"batb":[[2,2.02,6.81]],"ltp":0.0,"tv":0.0,"id":24608298}]}]}
{"op":"mcm","clk":"989264170","pt":1580486112241,"mc":[{"id":"1.168096552","rc":[{"batb":[[1,2.08,3]],"ltp":3.0,"tv":20.0,"id":18286408}]}]}
{"op":"mcm","clk":"989265093","pt":1580486124442,"mc":[{"id":"1.168096552","rc":[{"batb":[[1,2.02,4.47],[2,1.58,53]],"ltp":3.0,"tv":20.0,"id":18286408}]}]}
{"op":"mcm","clk":"989265138","pt":1580486125227,"mc":[{"id":"1.168096552","rc":[{"batb":[[1,2.1,3],[2,2.02,4.47]],"ltp":3.0,"tv":20.0,"id":18286408}]}]}
{"op":"mcm","clk":"989265900","pt":1580486137359,"mc":[{"id":"1.168096552","rc":[{"batb":[[1,2.12,3]],"ltp":3.0,"tv":20.0,"id":18286408}]}]}
{"op":"mcm","clk":"989266727","pt":1580486149392,"mc":[{"id":"1.168096552","rc":[{"batb":[[1,2.14,3]],"ltp":3.0,"tv":20.0,"id":18286408}]}]}
{"op":"mcm","clk":"989267549","pt":1580486160791,"mc":[{"id":"1.168096552","rc":[{"batb":[[1,2.16,3]],"ltp":3.0,"tv":20.0,"id":18286408}]}]}
{"op":"mcm","clk":"989268390","pt":1580486172304,"mc":[{"id":"1.168096552","rc":[{"batb":[[2,2.04,3.81]],"ltp":0.0,"tv":0.0,"id":26640937},{"batb":[[2,2.04,3.81]],"ltp":0.0,"tv":0.0,"id":21580749},{"batb":[[2,2.04,3.81]],"ltp":0.0,"tv":0.0,"id":27706761},{"batb":[[2,2.04,3.81]],"ltp":0.0,"tv":0.0,"id":52106},{"batb":[[2,2.04,3.81]],"ltp":0.0,"tv":0.0,"id":24608298}]}]}
{"op":"mcm","clk":"989268548","pt":1580486174803,"mc":[{"id":"1.168096552","rc":[{"batb":[[1,2.18,3]],"ltp":3.0,"tv":20.0,"id":18286408}]}]}
{"op":"mcm","clk":"989269608","pt":1580486189436,"mc":[{"id":"1.168096552","rc":[{"batb":[[1,2.2,3]],"ltp":3.0,"tv":20.0,"id":18286408}]}]}
{"op":"mcm","clk":"989270343","pt":1580486199420,"mc":[{"id":"1.168096552","rc":[{"batb":[[1,2.22,3]],"ltp":3.0,"tv":20.0,"id":18286408}]}]}
{"op":"mcm","clk":"989271543","pt":1580486214337,"mc":[{"id":"1.168096552","rc":[{"batb":[[1,2.02,4.47],[2,1.59,3]],"ltp":3.0,"tv":20.0,"id":18286408}]}]}
{"op":"mcm","clk":"989271558","pt":1580486214549,"mc":[{"id":"1.168096552","rc":[{"batb":[[1,2.24,3],[2,2.02,4.47]],"ltp":3.0,"tv":20.0,"id":18286408}]}]}
{"op":"mcm","clk":"989272744","pt":1580486228371,"mc":[{"id":"1.168096552","rc":[{"batb":[[1,2.26,3]],"ltp":3.0,"tv":20.0,"id":18286408}]}]}
{"op":"mcm","clk":"989273624","pt":1580486239467,"mc":[{"id":"1.168096552","rc":[{"batb":[[1,2.28,3]],"ltp":3.0,"tv":20.0,"id":18286408}]}]}
{"op":"mcm","clk":"989274816","pt":1580486254711,"mc":[{"id":"1.168096552","rc":[{"batb":[[1,2.3,3]],"ltp":3.0,"tv":20.0,"id":18286408}]}]}
{"op":"mcm","clk":"989275934","pt":1580486269138,"mc":[{"id":"1.168096552","rc":[{"batb":[[1,2.32,3]],"ltp":3.0,"tv":20.0,"id":18286408}]}]}
{"op":"mcm","clk":"989277080","pt":1580486284142,"mc":[{"id":"1.168096552","rc":[{"batb":[[1,2.34,3]],"ltp":3.0,"tv":20.0,"id":18286408}]}]}
{"op":"mcm","clk":"989278132","pt":1580486298466,"mc":[{"id":"1.168096552","rc":[{"batb":[[1,2.36,3]],"ltp":3.0,"tv":20.0,"id":18286408}]}]}
{"op":"mcm","clk":"989279319","pt":1580486312894,"mc":[{"id":"1.168096552","rc":[{"batb":[[1,2.38,3]],"ltp":3.0,"tv":20.0,"id":18286408}]}]}
{"op":"mcm","clk":"989280656","pt":1580486327939,"mc":[{"id":"1.168096552","rc":[{"batb":[[1,2.4,3]],"ltp":3.0,"tv":20.0,"id":18286408}]}]}
{"op":"mcm","clk":"989281878","pt":1580486341151,"mc":[{"id":"1.168096552","rc":[{"batb":[[1,2.42,3]],"ltp":3.0,"tv":20.0,"id":18286408}]}]}
{"op":"mcm","clk":"989283511","pt":1580486356449,"mc":[{"id":"1.168096552","rc":[{"batb":[[1,2.02,4.47],[2,1.59,3]],"ltp":3.0,"tv":20.0,"id":18286408}]}]}
{"op":"mcm","clk":"989283521","pt":1580486356558,"mc":[{"id":"1.168096552","rc":[{"batb":[[1,2.44,3],[2,2.02,4.47]],"ltp":3.0,"tv":20.0,"id":18286408}]}]}
{"op":"mcm","clk":"989284659","pt":1580486371287,"mc":[{"id":"1.168096552","rc":[{"batb":[[1,2.46,3]],"ltp":3.0,"tv":20.0,"id":18286408}]}]}
{"op":"mcm","clk":"989285701","pt":1580486383268,"mc":[{"id":"1.168096552","rc":[{"batb":[[1,2.48,3]],"ltp":3.0,"tv":20.0,"id":18286408}]}]}
{"op":"mcm","clk":"989286707","pt":1580486396189,"mc":[{"id":"1.168096552","rc":[{"batb":[[1,2.5,3]],"ltp":3.0,"tv":20.0,"id":18286408}]}]}
{"op":"mcm","clk":"989288236","pt":1580486411231,"mc":[{"id":"1.168096552","rc":[{"batb":[[1,2.52,3],[2,2.02,4.46]],"ltp":3.0,"tv":20.0,"id":18286408},{"batb":[[1,2.08,4.22],[2,2.04,3.81]],"ltp":0.0,"tv":0.0,"id":26640937},{"batb":[[1,2.08,4.22],[2,2.04,3.81]],"ltp":0.0,"tv":0.0,"id":21580749},{"batb":[[1,2.08,4.22],[2,2.04,3.81]],"ltp":0.0,"tv":0.0,"id":27706761},{"batb":[[1,2.08,4.22],[2,2.04,3.81]],"ltp":0.0,"tv":0.0,"id":52106},{"batb":[[1,2.08,4.22],[2,2.04,3.81]],"ltp":0.0,"tv":0.0,"id":24608298}]}]}
{"op":"mcm","clk":"989289740","pt":1580486428392,"mc":[{"id":"1.168096552","rc":[{"batb":[[1,2.02,4.46],[2,1.59,3]],"ltp":3.0,"tv":20.0,"id":18286408}]}]}
{"op":"mcm","clk":"989289750","pt":1580486429151,"mc":[{"id":"1.168096552","rc":[{"batb":[[1,2.54,3],[2,2.02,4.46]],"ltp":3.0,"tv":20.0,"id":18286408}]}]}
{"op":"mcm","clk":"989291661","pt":1580486450383,"mc":[{"id":"1.168096552","rc":[{"batb":[[1,2.56,3]],"ltp":3.0,"tv":20.0,"id":18286408}]}]}
{"op":"mcm","clk":"989294009","pt":1580486469178,"mc":[{"id":"1.168096552","rc":[{"batb":[[1,2.58,3]],"ltp":3.0,"tv":20.0,"id":18286408}]}]}
{"op":"mcm","clk":"989295755","pt":1580486487390,"mc":[{"id":"1.168096552","rc":[{"batb":[[1,2.6,3]],"ltp":3.0,"tv":20.0,"id":18286408}]}]}
{"op":"mcm","clk":"989297772","pt":1580486505717,"mc":[{"id":"1.168096552","rc":[{"batb":[[1,2.62,3]],"ltp":3.0,"tv":20.0,"id":18286408}]}]}
{"op":"mcm","clk":"989299305","pt":1580486521934,"mc":[{"id":"1.168096552","rc":[{"batb":[[1,2.64,3]],"ltp":3.0,"tv":20.0,"id":18286408}]}]}
{"op":"mcm","clk":"989301057","pt":1580486541261,"mc":[{"id":"1.168096552","rc":[{"batb":[[1,2.66,3]],"ltp":3.0,"tv":20.0,"id":18286408}]}]}
{"op":"mcm","clk":"989302438","pt":1580486557455,"mc":[{"id":"1.168096552","rc":[{"batb":[[1,2.02,4.46],[2,1.59,3]],"ltp":3.0,"tv":20.0,"id":18286408}]}]}
{"op":"mcm","clk":"989302446","pt":1580486557566,"mc":[{"id":"1.168096552","rc":[{"batb":[[1,2.68,3],[2,2.02,4.46]],"ltp":3.0,"tv":20.0,"id":18286408}]}]}
{"op":"mcm","clk":"989303899","pt":1580486574972,"mc":[{"id":"1.168096552","rc":[{"batb":[[1,2.7,3]],"ltp":3.0,"tv":20.0,"id":18286408}]}]}
{"op":"mcm","clk":"989305551","pt":1580486592204,"mc":[{"id":"1.168096552","rc":[{"batb":[[1,2.72,3]],"ltp":3.0,"tv":20.0,"id":18286408}]}]}
{"op":"mcm","clk":"989307579","pt":1580486607814,"mc":[{"id":"1.168096552","rc":[{"batb":[[1,2.74,3]],"ltp":3.0,"tv":20.0,"id":18286408}]}]}
{"op":"mcm","clk":"989309341","pt":1580486622145,"mc":[{"id":"1.168096552","rc":[{"batb":[[1,2.76,3]],"ltp":3.0,"tv":20.0,"id":18286408}]}]}
{"op":"mcm","clk":"989310662","pt":1580486635343,"mc":[{"id":"1.168096552","rc":[{"batb":[[1,2.78,3]],"ltp":3.0,"tv":20.0,"id":18286408}]}]}
{"op":"mcm","clk":"989311711","pt":1580486646277,"mc":[{"id":"1.168096552","rc":[{"batb":[[0,2.12,1.68],[1,2.1,1.99],[2,2.08,4.22]],"ltp":0.0,"tv":0.0,"id":52106}]}]}
{"op":"mcm","clk":"989311781","pt":1580486646972,"mc":[{"id":"1.168096552","rc":[{"batb":[[1,2.8,3]],"ltp":3.0,"tv":20.0,"id":18286408},{"batb":[[0,2.1,1.99],[1,2.08,4.22],[2,2.04,3.81]],"ltp":0.0,"tv":0.0,"id":52106}]}]}
{"op":"mcm","clk":"989313468","pt":1580486658693,"mc":[{"id":"1.168096552","rc":[{"batb":[[1,2.82,3]],"ltp":3.0,"tv":20.0,"id":18286408}]}]}
{"op":"mcm","clk":"989314956","pt":1580486670670,"mc":[{"id":"1.168096552","rc":[{"batb":[[1,2.84,3]],"ltp":3.0,"tv":20.0,"id":18286408}]}]}
{"op":"mcm","clk":"989316334","pt":1580486683231,"mc":[{"id":"1.168096552","rc":[{"batb":[[1,2.86,3]],"ltp":3.0,"tv":20.0,"id":18286408}]}]}
{"op":"mcm","clk":"989322261","pt":1580486742279,"mc":[{"id":"1.168096552","rc":[{"batl":[[0,3.95,1.88],[1,4,10]],"ltp":3.0,"tv":20.0,"id":18286408},{"batb":[[0,2.12,2.06],[1,2.1,1.99],[2,2.08,4.22]],"batl":[[0,1000,1.88]],"ltp":0.0,"tv":0.0,"id":26640937},{"batb":[[0,2.12,2.06],[1,2.1,1.99],[2,2.08,4.22]],"batl":[[0,5.4,1.68],[1,5.5,13],[2,1000,0.2]],"ltp":0.0,"tv":0.0,"id":21580749},{"batb":[[0,2.12,2.06],[1,2.1,1.99],[2,2.08,4.22]],"batl":[[0,65,1.68],[1,1000,0.2]],"ltp":0.0,"tv":0.0,"id":27706761},{"batb":[[0,2.12,2.06],[1,2.1,1.99],[2,2.08,4.22]],"batl":[[0,3.9,1.68],[1,3.95,9],[2,1000,0.2]],"ltp":0.0,"tv":0.0,"id":52106},{"batb":[[0,2.12,2.06],[1,2.1,1.99],[2,2.08,4.22]],"batl":[[1,1000,1.68]],"ltp":0.0,"tv":0.0,"id":24608298}]}]}
{"op":"mcm","clk":"989322746","pt":1580486747497,"mc":[{"id":"1.168096552","rc":[{"batb":[[1,2.08,4.22],[2,2.04,3.81]],"ltp":0.0,"tv":0.0,"id":52106}]}]}
{"op":"mcm","clk":"989322811","pt":1580486748189,"mc":[{"id":"1.168096552","rc":[{"batb":[[0,2.14,1.99],[1,2.12,2.06]],"ltp":0.0,"tv":0.0,"id":21580749},{"batb":[[0,2.14,1.99],[1,2.12,2.06],[2,2.08,4.22]],"ltp":0.0,"tv":0.0,"id":52106}]}]}
{"op":"mcm","clk":"989322934","pt":1580486749503,"mc":[{"id":"1.168096552","rc":[{"batb":[[0,2.14,1.99],[1,2.12,2.06]],"ltp":0.0,"tv":0.0,"id":26640937},{"batb":[[0,2.14,1.99],[1,2.12,2.06]],"ltp":0.0,"tv":0.0,"id":27706761},{"batb":[[0,2.14,1.99],[1,2.12,2.06]],"ltp":0.0,"tv":0.0,"id":24608298}]}]}
{"op":"mcm","clk":"989323324","pt":1580486753892,"mc":[{"id":"1.168096552","rc":[{"batl":[[0,65,1.88],[1,1000,0]],"ltp":0.0,"tv":0.0,"id":27706761}]}]}
{"op":"mcm","clk":"989330734","pt":1580486823496,"mc":[{"id":"1.168096552","rc":[{"batb":[[1,2.88,1.68],[2,2.86,3]],"ltp":3.0,"tv":20.0,"id":18286408},{"batb":[[1,2.08,4.22],[2,2.04,3.81]],"ltp":0.0,"tv":0.0,"id":26640937},{"batb":[[0,2.16,1.68],[1,2.14,1.99]],"ltp":0.0,"tv":0.0,"id":21580749},{"batb":[[0,2.16,1.68],[1,2.14,1.99]],"ltp":0.0,"tv":0.0,"id":52106}]}]}
{"op":"mcm","clk":"989330816","pt":1580486824192,"mc":[{"id":"1.168096552","rc":[{"batb":[[0,2.16,1.68],[1,2.14,1.99],[2,2.08,4.22]],"ltp":0.0,"tv":0.0,"id":26640937},{"batb":[[0,2.16,1.68],[1,2.14,1.99]],"ltp":0.0,"tv":0.0,"id":27706761},{"batb":[[0,2.16,1.68],[1,2.14,1.99]],"ltp":0.0,"tv":0.0,"id":24608298}]}]}
{"op":"mcm","clk":"989331998","pt":1580486836212,"mc":[{"id":"1.168096552","rc":[{"batb":[[0,3.05,1.99],[1,3,1],[2,2.88,1.68]],"ltp":3.0,"tv":20.0,"id":18286408}]}]}
{"op":"mcm","clk":"989332098","pt":1580486837430,"mc":[{"id":"1.168096552","rc":[{"batb":[[0,2.18,1.99],[1,2.16,1.68]],"ltp":0.0,"tv":0.0,"id":26640937},{"batb":[[0,2.18,1.99],[1,2.16,1.68]],"ltp":0.0,"tv":0.0,"id":21580749},{"batb":[[0,2.18,1.99],[1,2.16,1.68]],"ltp":0.0,"tv":0.0,"id":52106}]}]}
{"op":"mcm","clk":"989332173","pt":1580486838236,"mc":[{"id":"1.168096552","rc":[{"batb":[[0,2.18,1.99],[1,2.16,1.68]],"ltp":0.0,"tv":0.0,"id":27706761},{"batb":[[0,2.18,1.99],[1,2.16,1.68]],"ltp":0.0,"tv":0.0,"id":24608298}]}]}
{"op":"mcm","clk":"989343565","pt":1580486858136,"mc":[{"id":"1.168096552","rc":[{"batb":[[0,3.05,2.53]],"ltp":3.0,"tv":20.0,"id":18286408},{"batb":[[0,2.18,2.74]],"ltp":0.0,"tv":0.0,"id":26640937},{"batb":[[0,2.18,2.74]],"ltp":0.0,"tv":0.0,"id":21580749},{"batb":[[0,2.18,2.74]],"ltp":0.0,"tv":0.0,"id":27706761},{"batb":[[0,2.18,2.74]],"ltp":0.0,"tv":0.0,"id":52106},{"batb":[[0,2.18,2.74]],"ltp":0.0,"tv":0.0,"id":24608298}]}]}
{"op":"mcm","clk":"989345680","pt":1580486881355,"mc":[{"id":"1.168096552","rc":[{"batb":[[0,3.1,1.68],[1,3.05,2.53],[2,3,1]],"ltp":3.0,"tv":20.0,"id":18286408},{"batb":[[0,2.2,1.68],[1,2.18,2.74]],"ltp":0.0,"tv":0.0,"id":52106}]}]}
{"op":"mcm","clk":"989345814","pt":1580486882491,"mc":[{"id":"1.168096552","rc":[{"batb":[[0,3.15,1.99],[1,3.1,1.68],[2,3,1.54]],"ltp":3.0,"tv":20.0,"id":18286408},{"batb":[[0,2.2,1.68],[1,2.18,2.74]],"ltp":0.0,"tv":0.0,"id":26640937},{"batb":[[0,2.2,1.68],[1,2.18,2.74]],"ltp":0.0,"tv":0.0,"id":21580749},{"batb":[[0,2.2,1.68],[1,2.18,2.74]],"ltp":0.0,"tv":0.0,"id":27706761},{"batb":[[1,2.08,4.22],[2,2.04,3]],"ltp":0.0,"tv":0.0,"id":24608298}]}]}
{"op":"mcm","clk":"989345898","pt":1580486883455,"mc":[{"id":"1.168096552","rc":[{"batb":[[1,2.08,4.97],[2,2.04,3]],"ltp":0.0,"tv":0.0,"id":26640937},{"batb":[[0,2.22,1.99],[1,2.2,1.68],[2,2.08,4.97]],"ltp":0.0,"tv":0.0,"id":21580749},{"batb":[[0,2.22,1.99],[1,2.2,1.68],[2,2.08,4.97]],"ltp":0.0,"tv":0.0,"id":52106},{"batb":[[0,2.2,1.68],[1,2.18,2.74],[2,2.08,4.22]],"ltp":0.0,"tv":0.0,"id":24608298}]}]}
{"op":"mcm","clk":"989345905","pt":1580486883569,"mc":[{"id":"1.168096552","rc":[{"batb":[[0,2.22,1.99],[1,2.2,1.68],[2,2.08,4.97]],"ltp":0.0,"tv":0.0,"id":26640937}]}]}
{"op":"mcm","clk":"989349223","pt":1580486923431,"mc":[{"id":"1.168096552","rc":[{"batb":[[0,2.22,1.99],[1,2.2,1.68],[2,2.08,4.97]],"ltp":0.0,"tv":0.0,"id":27706761}]}]}
{"op":"mcm","clk":"989349252","pt":1580486923695,"mc":[{"id":"1.168096552","rc":[{"batb":[[0,2.22,1.99],[1,2.2,1.68],[2,2.08,4.97]],"ltp":0.0,"tv":0.0,"id":24608298}]}]}
{"op":"mcm","clk":"989350641","pt":1580486939325,"mc":[{"id":"1.168096552","rc":[{"batb":[[0,3.2,1.68],[1,3.15,1.99]],"ltp":3.0,"tv":20.0,"id":18286408},{"batb":[[1,2.08,4.97],[2,2.04,3]],"ltp":0.0,"tv":0.0,"id":21580749},{"batb":[[0,2.24,1.68],[1,2.22,1.99]],"ltp":0.0,"tv":0.0,"id":52106}]}]}
{"op":"mcm","clk":"989350702","pt":1580486940120,"mc":[{"id":"1.168096552","rc":[{"batb":[[0,2.24,1.68],[1,2.22,1.99]],"ltp":0.0,"tv":0.0,"id":26640937},{"batb":[[0,2.24,1.68],[1,2.22,1.99],[2,2.08,4.97]],"ltp":0.0,"tv":0.0,"id":21580749},{"batb":[[0,2.24,1.68],[1,2.22,1.99]],"ltp":0.0,"tv":0.0,"id":27706761},{"batb":[[0,2.24,1.68],[1,2.22,1.99]],"ltp":0.0,"tv":0.0,"id":24608298}]}]}
{"op":"mcm","clk":"989353298","pt":1580486968474,"mc":[{"id":"1.168096552","rc":[{"batb":[[0,3.25,1.99],[1,3.2,1.68]],"ltp":3.0,"tv":20.0,"id":18286408},{"batb":[[0,2.26,1.99],[1,2.24,1.68]],"ltp":0.0,"tv":0.0,"id":21580749},{"batb":[[0,2.26,1.99],[1,2.24,1.68]],"ltp":0.0,"tv":0.0,"id":52106}]}]}
{"op":"mcm","clk":"989353383","pt":1580486969477,"mc":[{"id":"1.168096552","rc":[{"batb":[[0,2.26,1.99],[1,2.24,1.68]],"ltp":0.0,"tv":0.0,"id":26640937},{"batb":[[0,2.26,1.99],[1,2.24,1.68]],"ltp":0.0,"tv":0.0,"id":27706761},{"batb":[[0,2.26,1.99],[1,2.24,1.68]],"ltp":0.0,"tv":0.0,"id":24608298}]}]}
{"op":"mcm","clk":"989355666","pt":1580486996313,"mc":[{"id":"1.168096552","rc":[{"batb":[[1,2.08,4.97],[2,2,53]],"ltp":0.0,"tv":0.0,"id":21580749},{"batb":[[0,2.28,1.68],[1,2.26,1.99]],"ltp":0.0,"tv":0.0,"id":52106}]}]}
{"op":"mcm","clk":"989355752","pt":1580486997422,"mc":[{"id":"1.168096552","rc":[{"batb":[[0,2.28,1.68],[1,2.26,1.99]],"ltp":0.0,"tv":0.0,"id":26640937},{"batb":[[0,2.28,1.68],[1,2.26,1.99],[2,2.08,4.97]],"ltp":0.0,"tv":0.0,"id":21580749},{"batb":[[0,2.28,1.68],[1,2.26,1.99]],"ltp":0.0,"tv":0.0,"id":27706761},{"batb":[[1,2.08,4.97],[2,2,53]],"ltp":0.0,"tv":0.0,"id":24608298}]}]}
{"op":"mcm","clk":"989355759","pt":1580486997528,"mc":[{"id":"1.168096552","rc":[{"batb":[[0,2.28,1.68],[1,2.26,1.99],[2,2.08,4.97]],"ltp":0.0,"tv":0.0,"id":24608298}]}]}
{"op":"mcm","clk":"989357466","pt":1580487015311,"mc":[{"id":"1.168096552","rc":[{"batb":[[0,2.3,1.99],[1,2.28,1.68]],"ltp":0.0,"tv":0.0,"id":52106}]}]}
{"op":"mcm","clk":"989357547","pt":1580487016229,"mc":[{"id":"1.168096552","rc":[{"batb":[[0,2.3,1.99],[1,2.28,1.68]],"ltp":0.0,"tv":0.0,"id":26640937},{"batb":[[0,2.3,1.99],[1,2.28,1.68]],"ltp":0.0,"tv":0.0,"id":21580749}]}]}
{"op":"mcm","clk":"989357632","pt":1580487017014,"mc":[{"id":"1.168096552","rc":[{"batb":[[0,2.3,1.99],[1,2.28,1.68]],"ltp":0.0,"tv":0.0,"id":27706761},{"batb":[[0,2.3,1.99],[1,2.28,1.68]],"ltp":0.0,"tv":0.0,"id":24608298}]}]}
{"op":"mcm","clk":"989359465","pt":1580487036343,"mc":[{"id":"1.168096552","rc":[{"batb":[[1,2.08,4.97],[2,2,53]],"ltp":0.0,"tv":0.0,"id":26640937},{"batb":[[0,2.32,1.68],[1,2.3,1.99]],"ltp":0.0,"tv":0.0,"id":21580749},{"batb":[[0,2.32,1.68],[1,2.3,1.99]],"ltp":0.0,"tv":0.0,"id":52106}]}]}
{"op":"mcm","clk":"989359515","pt":1580487036934,"mc":[{"id":"1.168096552","rc":[{"batb":[[0,2.32,1.68],[1,2.3,1.99],[2,2.08,4.97]],"ltp":0.0,"tv":0.0,"id":26640937},{"batb":[[0,2.32,1.68],[1,2.3,1.99]],"ltp":0.0,"tv":0.0,"id":27706761},{"batb":[[0,2.32,1.68],[1,2.3,1.99]],"ltp":0.0,"tv":0.0,"id":24608298}]}]}
{"op":"mcm","clk":"989359698","pt":1580487039043,"mc":[{"id":"1.168096552","rc":[{"batb":[[2,2.08,4.22]],"ltp":0.0,"tv":0.0,"id":26640937},{"batb":[[2,2.08,4.22]],"ltp":0.0,"tv":0.0,"id":21580749},{"batb":[[2,2.08,4.22]],"ltp":0.0,"tv":0.0,"id":27706761},{"batb":[[2,2.08,4.22]],"ltp":0.0,"tv":0.0,"id":52106},{"batb":[[2,2.08,4.22]],"ltp":0.0,"tv":0.0,"id":24608298}]}]}
{"op":"mcm","clk":"989360934","pt":1580487051977,"mc":[{"id":"1.168096552","rc":[{"batb":[[0,2.32,2.39]],"ltp":0.0,"tv":0.0,"id":26640937},{"batb":[[0,2.32,2.39]],"ltp":0.0,"tv":0.0,"id":21580749},{"batb":[[0,2.32,2.39]],"ltp":0.0,"tv":0.0,"id":27706761},{"batb":[[0,2.32,2.39]],"ltp":0.0,"tv":0.0,"id":52106},{"batb":[[0,2.32,2.39]],"ltp":0.0,"tv":0.0,"id":24608298}]}]}
{"op":"mcm","clk":"989362766","pt":1580487070393,"mc":[{"id":"1.168096552","rc":[{"batb":[[1,2.08,4.22],[2,2,53]],"ltp":0.0,"tv":0.0,"id":21580749},{"batb":[[1,2.08,4.22],[2,2,53]],"ltp":0.0,"tv":0.0,"id":52106}]}]}
{"op":"mcm","clk":"989362868","pt":1580487071386,"mc":[{"id":"1.168096552","rc":[{"batb":[[1,2.08,4.22],[2,2,53]],"ltp":0.0,"tv":0.0,"id":26640937},{"batb":[[1,2.08,4.22],[2,2,53]],"ltp":0.0,"tv":0.0,"id":27706761}]}]}
{"op":"mcm","clk":"989362972","pt":1580487072493,"mc":[{"id":"1.168096552","rc":[{"batb":[[1,2.08,4.22],[2,2,53]],"ltp":0.0,"tv":0.0,"id":24608298}]}]}
{"op":"mcm","clk":"989363892","pt":1580487083486,"mc":[{"id":"1.168096552","rc":[{"batb":[[0,2.08,4.93],[1,2,53],[2,1.55,18.18]],"ltp":0.0,"tv":0.0,"id":52106}]}]}
{"op":"mcm","clk":"989363999","pt":1580487084491,"mc":[{"id":"1.168096552","rc":[{"batb":[[0,2.1,2.39]],"ltp":0.0,"tv":0.0,"id":26640937},{"batb":[[0,2.1,2.39]],"ltp":0.0,"tv":0.0,"id":21580749},{"batb":[[0,2.08,4.93],[1,2,53],[2,1.55,18.18]],"ltp":0.0,"tv":0.0,"id":27706761},{"batb":[[0,2.1,2.39],[1,2.08,4.22],[2,2,53]],"ltp":0.0,"tv":0.0,"id":52106}]}]}
{"op":"mcm","clk":"989364023","pt":1580487084786,"mc":[{"id":"1.168096552","rc":[{"batb":[[0,2.1,2.39],[1,2.08,4.22],[2,2,53]],"ltp":0.0,"tv":0.0,"id":27706761},{"batb":[[0,2.1,2.39]],"ltp":0.0,"tv":0.0,"id":24608298}]}]}
{"op":"mcm","clk":"989367372","pt":1580487122452,"mc":[{"id":"1.168096552","rc":[{"batb":[[0,2.1,9.54]],"ltp":0.0,"tv":0.0,"id":26640937},{"batb":[[0,2.1,9.54]],"batl":[[0,5.4,3.43]],"ltp":0.0,"tv":0.0,"id":21580749},{"batb":[[0,2.1,9.54]],"ltp":0.0,"tv":0.0,"id":27706761},{"batb":[[0,2.1,9.54]],"batl":[[0,3.9,4.75]],"ltp":0.0,"tv":0.0,"id":52106}]}]}
{"op":"mcm","clk":"989367400","pt":1580487122735,"mc":[{"id":"1.168096552","rc":[{"batb":[[0,2.1,9.54]],"ltp":0.0,"tv":0.0,"id":24608298}]}]}
{"op":"mcm","clk":"989368807","pt":1580487138448,"mc":[{"id":"1.168096552","rc":[{"batb":[[0,2.12,4.78],[1,2.1,8.83]],"ltp":0.0,"tv":0.0,"id":26640937},{"batb":[[0,2.12,4.78],[1,2.1,8.83]],"ltp":0.0,"tv":0.0,"id":21580749},{"batb":[[0,2.12,4.78],[1,2.1,8.83]],"ltp":0.0,"tv":0.0,"id":27706761},{"batb":[[0,2.12,4.78],[1,2.1,8.83]],"ltp":0.0,"tv":0.0,"id":52106},{"batb":[[0,2.12,4.78],[1,2.1,8.83]],"ltp":0.0,"tv":0.0,"id":24608298}]}]}
{"op":"mcm","clk":"989369561","pt":1580487146986,"mc":[{"id":"1.168096552","rc":[{"batb":[[0,3.25,8.14]],"ltp":3.0,"tv":20.0,"id":18286408},{"batb":[[0,2.14,10.06],[1,2.12,4.07],[2,2.1,8.83]],"ltp":0.0,"tv":0.0,"id":26640937},{"batb":[[0,2.14,10.06],[1,2.12,4.07],[2,2.1,8.83]],"ltp":0.0,"tv":0.0,"id":21580749},{"batb":[[0,2.14,10.06],[1,2.12,4.07],[2,2.1,8.83]],"ltp":0.0,"tv":0.0,"id":27706761},{"batb":[[0,2.14,10.06],[1,2.12,4.07],[2,2.1,8.83]],"ltp":0.0,"tv":0.0,"id":52106},{"batb":[[0,2.14,10.06],[1,2.12,4.07],[2,2.1,8.83]],"ltp":0.0,"tv":0.0,"id":24608298}]}]}
{"op":"mcm","clk":"989370691","pt":1580487159515,"mc":[{"id":"1.168096552","rc":[{"batb":[[0,2.34,1.99],[1,2.14,10.06],[2,2.12,4.07]],"ltp":0.0,"tv":0.0,"id":52106}]}]}
{"op":"mcm","clk":"989370786","pt":1580487160416,"mc":[{"id":"1.168096552","rc":[{"batb":[[0,2.34,1.99],[1,2.14,10.06],[2,2.12,4.07]],"ltp":0.0,"tv":0.0,"id":26640937},{"batb":[[0,2.34,1.99],[1,2.14,10.06],[2,2.12,4.07]],"ltp":0.0,"tv":0.0,"id":21580749},{"batb":[[0,2.34,1.99],[1,2.14,10.06],[2,2.12,4.07]],"ltp":0.0,"tv":0.0,"id":27706761}]}]}
{"op":"mcm","clk":"989370886","pt":1580487161425,"mc":[{"id":"1.168096552","rc":[{"batb":[[0,2.34,1.99],[1,2.14,10.06],[2,2.12,4.07]],"ltp":0.0,"tv":0.0,"id":24608298}]}]}
{"op":"mcm","clk":"989371530","pt":1580487168123,"mc":[{"id":"1.168096552","rc":[{"batb":[[1,2.16,4.63],[2,2.14,9.35]],"ltp":0.0,"tv":0.0,"id":26640937},{"batb":[[1,2.16,4.63],[2,2.14,9.35]],"ltp":0.0,"tv":0.0,"id":21580749},{"batb":[[1,2.16,4.63],[2,2.14,9.35]],"ltp":0.0,"tv":0.0,"id":27706761},{"batb":[[1,2.16,4.63],[2,2.14,9.35]],"ltp":0.0,"tv":0.0,"id":52106},{"batb":[[1,2.16,4.63],[2,2.14,9.35]],"ltp":0.0,"tv":0.0,"id":24608298}]}]}
{"op":"mcm","clk":"989373018","pt":1580487182447,"mc":[{"id":"1.168096552","rc":[{"batb":[[0,2.36,1.68],[1,2.34,1.99],[2,2.16,4.63]],"ltp":0.0,"tv":0.0,"id":21580749},{"batb":[[0,2.36,1.68],[1,2.34,1.99],[2,2.16,4.63]],"ltp":0.0,"tv":0.0,"id":52106}]}]}
{"op":"mcm","clk":"989373106","pt":1580487183148,"mc":[{"id":"1.168096552","rc":[{"batb":[[0,2.36,1.68],[1,2.34,1.99],[2,2.16,4.63]],"ltp":0.0,"tv":0.0,"id":26640937},{"batb":[[0,2.36,1.68],[1,2.34,1.99],[2,2.16,4.63]],"ltp":0.0,"tv":0.0,"id":27706761},{"batb":[[0,2.36,1.68],[1,2.34,1.99],[2,2.16,4.63]],"ltp":0.0,"tv":0.0,"id":24608298}]}]}
{"op":"mcm","clk":"989375360","pt":1580487204461,"mc":[{"id":"1.168096552","rc":[{"batb":[[0,2.38,1.99],[1,2.36,1.68]],"ltp":0.0,"tv":0.0,"id":21580749},{"batb":[[0,2.38,1.99],[1,2.36,1.68]],"ltp":0.0,"tv":0.0,"id":52106}]}]}
{"op":"mcm","clk":"989375457","pt":1580487205461,"mc":[{"id":"1.168096552","rc":[{"batb":[[0,2.38,1.99],[1,2.36,1.68]],"ltp":0.0,"tv":0.0,"id":26640937},{"batb":[[1,2.16,4.63],[2,2.14,9.35]],"ltp":0.0,"tv":0.0,"id":27706761}]}]}
{"op":"mcm","clk":"989375592","pt":1580487206328,"mc":[{"id":"1.168096552","rc":[{"batb":[[0,2.38,1.99],[1,2.36,1.68],[2,2.16,4.63]],"ltp":0.0,"tv":0.0,"id":27706761},{"batb":[[0,2.38,1.99],[1,2.36,1.68]],"ltp":0.0,"tv":0.0,"id":24608298}]}]}
{"op":"mcm","clk":"989377539","pt":1580487225508,"mc":[{"id":"1.168096552","rc":[{"batb":[[0,2.4,1.68],[1,2.38,1.99]],"ltp":0.0,"tv":0.0,"id":26640937},{"batb":[[0,2.4,1.68],[1,2.38,1.99]],"ltp":0.0,"tv":0.0,"id":21580749},{"batb":[[0,2.4,1.68],[1,2.38,1.99]],"ltp":0.0,"tv":0.0,"id":27706761},{"batb":[[0,2.4,1.68],[1,2.38,1.99]],"ltp":0.0,"tv":0.0,"id":52106}]}]}
{"op":"mcm","clk":"989377561","pt":1580487225670,"mc":[{"id":"1.168096552","rc":[{"batb":[[0,2.4,1.68],[1,2.38,1.99]],"ltp":0.0,"tv":0.0,"id":24608298}]}]}
{"op":"mcm","clk":"989379988","pt":1580487250420,"mc":[{"id":"1.168096552","rc":[{"batb":[[0,2.42,1.99],[1,2.4,1.68]],"ltp":0.0,"tv":0.0,"id":52106}]}]}
{"op":"mcm","clk":"989380049","pt":1580487251008,"mc":[{"id":"1.168096552","rc":[{"batb":[[0,2.42,1.99],[1,2.4,1.68]],"ltp":0.0,"tv":0.0,"id":21580749}]}]}
{"op":"mcm","clk":"989380186","pt":1580487252488,"mc":[{"id":"1.168096552","rc":[{"batb":[[0,2.42,1.99],[1,2.4,1.68]],"ltp":0.0,"tv":0.0,"id":26640937},{"batb":[[0,2.42,1.99],[1,2.4,1.68]],"ltp":0.0,"tv":0.0,"id":27706761}]}]}
{"op":"mcm","clk":"989380217","pt":1580487252916,"mc":[{"id":"1.168096552","rc":[{"batb":[[0,2.42,1.99],[1,2.4,1.68]],"ltp":0.0,"tv":0.0,"id":24608298}]}]}
{"op":"mcm","clk":"989381933","pt":1580487269448,"mc":[{"id":"1.168096552","rc":[{"batb":[[1,2.16,4.63],[2,2,53]],"ltp":0.0,"tv":0.0,"id":26640937},{"batb":[[0,2.44,1.68],[1,2.42,1.99]],"ltp":0.0,"tv":0.0,"id":21580749},{"batb":[[0,2.44,1.68],[1,2.42,1.99]],"ltp":0.0,"tv":0.0,"id":52106}]}]}
{"op":"mcm","clk":"989381990","pt":1580487270027,"mc":[{"id":"1.168096552","rc":[{"batb":[[0,2.44,1.68],[1,2.42,1.99],[2,2.16,4.63]],"ltp":0.0,"tv":0.0,"id":26640937},{"batb":[[0,2.44,1.68],[1,2.42,1.99]],"ltp":0.0,"tv":0.0,"id":27706761},{"batb":[[0,2.44,1.68],[1,2.42,1.99]],"ltp":0.0,"tv":0.0,"id":24608298}]}]}
{"op":"mcm","clk":"989384374","pt":1580487293367,"mc":[{"id":"1.168096552","rc":[{"batb":[[0,2.46,1.99],[1,2.44,1.68]],"ltp":0.0,"tv":0.0,"id":52106}]}]}
{"op":"mcm","clk":"989384452","pt":1580487294102,"mc":[{"id":"1.168096552","rc":[{"batb":[[0,2.46,1.99],[1,2.44,1.68],[2,2.16,3.92]],"ltp":0.0,"tv":0.0,"id":26640937},{"batb":[[0,2.46,1.99],[1,2.44,1.68],[2,2.16,3.92]],"ltp":0.0,"tv":0.0,"id":21580749},{"batb":[[2,2.16,3.92]],"ltp":0.0,"tv":0.0,"id":27706761},{"batb":[[2,2.16,3.92]],"ltp":0.0,"tv":0.0,"id":52106},{"batb":[[2,2.16,3.92]],"ltp":0.0,"tv":0.0,"id":24608298}]}]}
{"op":"mcm","clk":"989384584","pt":1580487295467,"mc":[{"id":"1.168096552","rc":[{"batb":[[0,2.46,1.99],[1,2.44,1.68]],"ltp":0.0,"tv":0.0,"id":27706761},{"batb":[[0,2.46,1.99],[1,2.44,1.68]],"ltp":0.0,"tv":0.0,"id":24608298}]}]}
{"op":"mcm","clk":"989385691","pt":1580487306501,"mc":[{"id":"1.168096552","rc":[{"batb":[[0,2.46,2.66]],"ltp":0.0,"tv":0.0,"id":26640937},{"batb":[[0,2.46,2.66]],"ltp":0.0,"tv":0.0,"id":21580749},{"batb":[[0,2.46,2.66]],"ltp":0.0,"tv":0.0,"id":27706761},{"batb":[[0,2.46,2.66]],"ltp":0.0,"tv":0.0,"id":52106},{"batb":[[0,2.46,2.66]],"ltp":0.0,"tv":0.0,"id":24608298}]}]}
{"op":"mcm","clk":"989386794","pt":1580487317487,"mc":[{"id":"1.168096552","rc":[{"batb":[[1,2.16,3.92],[2,2,53]],"ltp":0.0,"tv":0.0,"id":26640937},{"batb":[[0,2.48,1.68],[1,2.46,2.66]],"ltp":0.0,"tv":0.0,"id":21580749},{"batb":[[0,2.48,1.68],[1,2.46,2.66]],"ltp":0.0,"tv":0.0,"id":52106}]}]}
{"op":"mcm","clk":"989386845","pt":1580487318009,"mc":[{"id":"1.168096552","rc":[{"batb":[[0,2.48,1.68],[1,2.46,2.66],[2,2.16,3.92]],"ltp":0.0,"tv":0.0,"id":26640937},{"batb":[[0,2.48,1.68],[1,2.46,2.66]],"ltp":0.0,"tv":0.0,"id":27706761},{"batb":[[0,2.48,1.68],[1,2.46,2.66]],"ltp":0.0,"tv":0.0,"id":24608298}]}]}
{"op":"mcm","clk":"989388695","pt":1580487336334,"mc":[{"id":"1.168096552","rc":[{"batb":[[1,2.16,4.59],[2,2,53]],"ltp":0.0,"tv":0.0,"id":21580749},{"batb":[[1,2.16,4.59],[2,2,53]],"ltp":0.0,"tv":0.0,"id":52106}]}]}
{"op":"mcm","clk":"989388773","pt":1580487337030,"mc":[{"id":"1.168096552","rc":[{"batb":[[1,2.16,4.59],[2,2,53]],"ltp":0.0,"tv":0.0,"id":26640937},{"batb":[[1,2.16,4.59],[2,2,53]],"ltp":0.0,"tv":0.0,"id":27706761}]}]}
{"op":"mcm","clk":"989388871","pt":1580487337833,"mc":[{"id":"1.168096552","rc":[{"batb":[[1,2.16,4.59],[2,2,53]],"ltp":0.0,"tv":0.0,"id":24608298}]}]}
{"op":"mcm","clk":"989390446","pt":1580487354786,"mc":[{"id":"1.168096552","rc":[{"batb":[[0,2.48,9.74]],"ltp":0.0,"tv":0.0,"id":26640937},{"batb":[[0,2.48,9.74]],"ltp":0.0,"tv":0.0,"id":21580749},{"batb":[[0,2.48,9.74]],"ltp":0.0,"tv":0.0,"id":27706761},{"batb":[[0,2.48,9.74]],"ltp":0.0,"tv":0.0,"id":52106},{"batb":[[0,2.48,9.74]],"ltp":0.0,"tv":0.0,"id":24608298}]}]}
{"op":"mcm","clk":"989392735","pt":1580487378102,"mc":[{"id":"1.168096552","rc":[{"batb":[[0,2.5,3.03],[1,2.48,9.74],[2,2,53.67]],"ltp":0.0,"tv":0.0,"id":26640937},{"batb":[[0,2.5,3.03],[1,2.48,9.74],[2,2,53.67]],"ltp":0.0,"tv":0.0,"id":21580749},{"batb":[[0,2.5,3.03],[1,2.48,9.74],[2,2,53.67]],"ltp":0.0,"tv":0.0,"id":27706761},{"batb":[[0,2.5,3.03],[1,2.48,9.74],[2,2,53.67]],"ltp":0.0,"tv":0.0,"id":52106},{"batb":[[0,2.5,3.03],[1,2.48,9.74],[2,2,53.67]],"ltp":0.0,"tv":0.0,"id":24608298}]}]}
{"op":"mcm","clk":"989394962","pt":1580487402464,"mc":[{"id":"1.168096552","rc":[{"batb":[[0,2.52,1.68],[1,2.5,3.03],[2,2.48,8.06]],"ltp":0.0,"tv":0.0,"id":52106}]}]}
{"op":"mcm","clk":"989395073","pt":1580487403464,"mc":[{"id":"1.168096552","rc":[{"batb":[[0,2.52,1.68],[1,2.5,3.03],[2,2.48,8.06]],"ltp":0.0,"tv":0.0,"id":26640937},{"batb":[[0,2.52,1.68],[1,2.5,3.03],[2,2.48,8.06]],"ltp":0.0,"tv":0.0,"id":21580749},{"batb":[[0,2.52,1.68],[1,2.5,3.03],[2,2.48,8.06]],"ltp":0.0,"tv":0.0,"id":27706761},{"batb":[[1,2.48,8.06]],"ltp":0.0,"tv":0.0,"id":24608298}]}]}
{"op":"mcm","clk":"989395081","pt":1580487403525,"mc":[{"id":"1.168096552","rc":[{"batb":[[0,2.52,1.68],[1,2.5,3.03],[2,2.48,8.06]],"ltp":0.0,"tv":0.0,"id":24608298}]}]}
{"op":"mcm","clk":"989396828","pt":1580487422467,"mc":[{"id":"1.168096552","rc":[{"batb":[[0,2.54,1.99],[1,2.52,1.68],[2,2.5,3.03]],"ltp":0.0,"tv":0.0,"id":26640937},{"batb":[[0,2.54,1.99],[1,2.52,1.68],[2,2.5,3.03]],"ltp":0.0,"tv":0.0,"id":21580749},{"batb":[[0,2.54,1.99],[1,2.52,1.68],[2,2.5,3.03]],"ltp":0.0,"tv":0.0,"id":52106}]}]}
{"op":"mcm","clk":"989396880","pt":1580487422961,"mc":[{"id":"1.168096552","rc":[{"batb":[[0,2.54,1.99],[1,2.52,1.68],[2,2.5,3.03]],"ltp":0.0,"tv":0.0,"id":27706761}]}]}
{"op":"mcm","clk":"989397024","pt":1580487424374,"mc":[{"id":"1.168096552","rc":[{"batb":[[0,2.54,1.99],[1,2.52,1.68],[2,2.5,3.03]],"ltp":0.0,"tv":0.0,"id":24608298}]}]}
{"op":"mcm","clk":"989398444","pt":1580487440108,"mc":[{"id":"1.168096552","rc":[{"batl":[[0,5.4,16.43],[1,1000,0.2],[2,1000,0]],"ltp":0.0,"tv":0.0,"id":21580749}]}]}
{"op":"mcm","clk":"989399861","pt":1580487456324,"mc":[{"id":"1.168096552","rc":[{"batb":[[1,2.5,3.03],[2,2,53.67]],"ltp":0.0,"tv":0.0,"id":52106}]}]}
{"op":"mcm","clk":"989399964","pt":1580487457496,"mc":[{"id":"1.168096552","rc":[{"batb":[[0,2.56,1.68],[1,2.54,1.99]],"ltp":0.0,"tv":0.0,"id":26640937},{"batb":[[0,2.56,1.68],[1,2.54,1.99]],"ltp":0.0,"tv":0.0,"id":21580749},{"batb":[[0,2.56,1.68],[1,2.54,1.99]],"ltp":0.0,"tv":0.0,"id":27706761},{"batb":[[0,2.56,1.68],[1,2.54,1.99],[2,2.5,3.03]],"ltp":0.0,"tv":0.0,"id":52106}]}]}
{"op":"mcm","clk":"989399986","pt":1580487457702,"mc":[{"id":"1.168096552","rc":[{"batb":[[0,2.56,1.68],[1,2.54,1.99]],"ltp":0.0,"tv":0.0,"id":24608298}]}]}
{"op":"mcm","clk":"989400935","pt":1580487467943,"mc":[{"id":"1.168096552","rc":[{"trd":[[3.25,16]],"batb":[[0,3.2,1.82],[1,3,1.54],[2,2.86,3]],"ltp":3.25,"tv":36.0,"id":18286408}],"tv":36.0}]}
{"op":"mcm","clk":"989401150","pt":1580487470440,"mc":[{"id":"1.168096552","rc":[{"batb":[[1,2.5,3.03],[2,2,53.67]],"ltp":0.0,"tv":0.0,"id":26640937},{"batb":[[0,2.58,1.99],[1,2.56,1.68]],"ltp":0.0,"tv":0.0,"id":21580749},{"batb":[[0,2.58,1.99],[1,2.56,1.68]],"ltp":0.0,"tv":0.0,"id":52106}]}]}
{"op":"mcm","clk":"989401227","pt":1580487471341,"mc":[{"id":"1.168096552","rc":[{"batb":[[0,2.58,1.99],[1,2.56,1.68],[2,2.5,3.03]],"ltp":0.0,"tv":0.0,"id":26640937},{"batb":[[0,2.58,1.99],[1,2.56,1.68]],"ltp":0.0,"tv":0.0,"id":27706761},{"batb":[[0,2.58,1.99],[1,2.56,1.68]],"ltp":0.0,"tv":0.0,"id":24608298}]}]}
{"op":"mcm","clk":"989403362","pt":1580487495989,"mc":[{"id":"1.168096552","rc":[{"batb":[[0,3.2,1.68]],"ltp":3.25,"tv":36.0,"id":18286408}]}]}
{"op":"mcm","clk":"989405584","pt":1580487519736,"mc":[{"id":"1.168096552","rc":[{"batl":[[0,55,1],[1,1000,1.88]],"ltp":0.0,"tv":0.0,"id":24608298}]}]}
{"op":"mcm","clk":"989409619","pt":1580487570417,"mc":[{"id":"1.168096552","rc":[{"batb":[[0,3,1.54],[1,2.88,1.68]],"ltp":3.25,"tv":36.0,"id":18286408},{"batb":[[0,2.6,1.68],[1,2.58,1.99]],"ltp":0.0,"tv":0.0,"id":52106}]}]}
{"op":"mcm","clk":"989409717","pt":1580487571480,"mc":[{"id":"1.168096552","rc":[{"batb":[[0,2.6,1.68],[1,2.58,1.99]],"ltp":0.0,"tv":0.0,"id":26640937},{"batb":[[0,2.6,1.68],[1,2.58,1.99]],"ltp":0.0,"tv":0.0,"id":21580749},{"batb":[[0,2.6,1.68],[1,2.58,1.99]],"ltp":0.0,"tv":0.0,"id":27706761},{"batb":[[1,2.5,3.03],[2,2,53]],"ltp":0.0,"tv":0.0,"id":24608298}]}]}
{"op":"mcm","clk":"989409755","pt":1580487571960,"mc":[{"id":"1.168096552","rc":[{"batb":[[0,2.6,1.68],[1,2.58,1.99],[2,2.5,3.03]],"ltp":0.0,"tv":0.0,"id":24608298}]}]}
{"op":"mcm","clk":"989410178","pt":1580487577015,"mc":[{"id":"1.168096552","rc":[{"batb":[[1,2.9,3],[2,2.88,1.68]],"ltp":3.25,"tv":36.0,"id":18286408}]}]}
{"op":"mcm","clk":"989411121","pt":1580487590410,"mc":[{"id":"1.168096552","rc":[{"batb":[[1,2.88,1.68],[2,2.02,4.46]],"ltp":3.25,"tv":36.0,"id":18286408}]}]}
{"op":"mcm","clk":"989411144","pt":1580487590623,"mc":[{"id":"1.168096552","rc":[{"batb":[[1,2.92,3],[2,2.88,1.68]],"ltp":3.25,"tv":36.0,"id":18286408}]}]}
{"op":"mcm","clk":"989411356","pt":1580487593491,"mc":[{"id":"1.168096552","rc":[{"batb":[[0,2.62,1.99],[1,2.6,1.68]],"ltp":0.0,"tv":0.0,"id":21580749},{"batb":[[0,2.62,1.99],[1,2.6,1.68]],"ltp":0.0,"tv":0.0,"id":52106}]}]}
{"op":"mcm","clk":"989411421","pt":1580487594282,"mc":[{"id":"1.168096552","rc":[{"batb":[[0,2.62,1.99],[1,2.6,1.68]],"ltp":0.0,"tv":0.0,"id":26640937},{"batb":[[0,2.62,1.99],[1,2.6,1.68]],"ltp":0.0,"tv":0.0,"id":27706761}]}]}
{"op":"mcm","clk":"989411463","pt":1580487594701,"mc":[{"id":"1.168096552","rc":[{"batb":[[0,2.62,1.99],[1,2.6,1.68]],"ltp":0.0,"tv":0.0,"id":24608298}]}]}
{"op":"mcm","clk":"989412268","pt":1580487604395,"mc":[{"id":"1.168096552","rc":[{"batb":[[1,2.94,3]],"ltp":3.25,"tv":36.0,"id":18286408}]}]}
{"op":"mcm","clk":"989413514","pt":1580487620075,"mc":[{"id":"1.168096552","rc":[{"batb":[[1,2.96,3]],"ltp":3.25,"tv":36.0,"id":18286408}]}]}
{"op":"mcm","clk":"989414765","pt":1580487634389,"mc":[{"id":"1.168096552","rc":[{"batb":[[1,2.98,3]],"ltp":3.25,"tv":36.0,"id":18286408}]}]}
{"op":"mcm","clk":"989415994","pt":1580487649785,"mc":[{"id":"1.168096552","rc":[{"batb":[[0,3,4.54],[1,2.88,1.68],[2,2.02,4.46]],"ltp":3.25,"tv":36.0,"id":18286408}]}]}
{"op":"mcm","clk":"989416291","pt":1580487652971,"mc":[{"id":"1.168096552","rc":[{"batl":[[0,3.5,150],[1,3.95,1.88],[2,4,10]],"ltp":3.25,"tv":36.0,"id":18286408}]}]}
{"op":"mcm","clk":"989417568","pt":1580487666423,"mc":[{"id":"1.168096552","rc":[{"batb":[[0,3.05,2.22],[1,3,4]],"ltp":3.25,"tv":36.0,"id":18286408},{"batb":[[0,2.64,1.68],[1,2.62,1.99]],"ltp":0.0,"tv":0.0,"id":21580749},{"batb":[[0,2.64,1.68],[1,2.62,1.99]],"ltp":0.0,"tv":0.0,"id":52106}]}]}
{"op":"mcm","clk":"989417667","pt":1580487667436,"mc":[{"id":"1.168096552","rc":[{"batb":[[0,2.64,1.68],[1,2.62,1.99]],"ltp":0.0,"tv":0.0,"id":26640937},{"batb":[[0,2.64,1.68],[1,2.62,1.99]],"ltp":0.0,"tv":0.0,"id":27706761},{"batb":[[0,2.64,1.68],[1,2.62,1.99]],"ltp":0.0,"tv":0.0,"id":24608298}]}]}
{"op":"mcm","clk":"989418977","pt":1580487682436,"mc":[{"id":"1.168096552","rc":[{"batb":[[0,2.66,1.99],[1,2.64,1.68]],"ltp":0.0,"tv":0.0,"id":26640937},{"batb":[[0,2.66,1.99],[1,2.64,1.68]],"ltp":0.0,"tv":0.0,"id":21580749},{"batb":[[1,2.5,3.03],[2,2,53]],"ltp":0.0,"tv":0.0,"id":27706761},{"batb":[[0,2.66,1.99],[1,2.64,1.68]],"ltp":0.0,"tv":0.0,"id":52106}]}]}
{"op":"mcm","clk":"989419005","pt":1580487682820,"mc":[{"id":"1.168096552","rc":[{"batb":[[0,2.66,1.99],[1,2.64,1.68],[2,2.5,3.03]],"ltp":0.0,"tv":0.0,"id":27706761},{"batb":[[0,2.66,1.99],[1,2.64,1.68]],"ltp":0.0,"tv":0.0,"id":24608298}]}]}
{"op":"mcm","clk":"989424362","pt":1580487746415,"mc":[{"id":"1.168096552","rc":[{"batb":[[1,2.5,3.03],[2,2,53]],"ltp":0.0,"tv":0.0,"id":26640937},{"batb":[[0,2.68,1.68],[1,2.66,1.99]],"ltp":0.0,"tv":0.0,"id":21580749},{"batb":[[0,2.68,1.68],[1,2.66,1.99]],"ltp":0.0,"tv":0.0,"id":52106}]}]}
{"op":"mcm","clk":"989424462","pt":1580487747455,"mc":[{"id":"1.168096552","rc":[{"batb":[[0,2.68,1.68],[1,2.66,1.99],[2,2.5,3.03]],"ltp":0.0,"tv":0.0,"id":26640937},{"batb":[[0,2.68,1.68],[1,2.66,1.99]],"ltp":0.0,"tv":0.0,"id":27706761},{"batb":[[0,2.68,1.68],[1,2.66,1.99]],"ltp":0.0,"tv":0.0,"id":24608298}]}]}
{"op":"mcm","clk":"989435223","pt":1580487761569,"mc":[{"id":"1.168096552","rc":[{"batl":[[0,3.3,33],[1,3.5,150],[2,3.95,1.88]],"ltp":3.25,"tv":36.0,"id":18286408}]}]}
{"op":"mcm","clk":"989435423","pt":1580487764249,"mc":[{"id":"1.168096552","rc":[{"batl":[[2,3.95,1.68]],"ltp":3.25,"tv":36.0,"id":18286408}]}]}
{"op":"mcm","clk":"989436141","pt":1580487772491,"mc":[{"id":"1.168096552","rc":[{"batb":[[0,2.7,1.99],[1,2.68,1.68]],"ltp":0.0,"tv":0.0,"id":21580749},{"batb":[[0,2.7,1.99],[1,2.68,1.68]],"ltp":0.0,"tv":0.0,"id":52106}]}]}
{"op":"mcm","clk":"989436215","pt":1580487773274,"mc":[{"id":"1.168096552","rc":[{"batb":[[0,2.7,1.99],[1,2.68,1.68]],"ltp":0.0,"tv":0.0,"id":26640937},{"batb":[[0,2.7,1.99],[1,2.68,1.68]],"ltp":0.0,"tv":0.0,"id":27706761}]}]}
{"op":"mcm","clk":"989436260","pt":1580487773764,"mc":[{"id":"1.168096552","rc":[{"batb":[[0,2.7,1.99],[1,2.68,1.68]],"ltp":0.0,"tv":0.0,"id":24608298}]}]}
{"op":"mcm","clk":"989439801","pt":1580487813505,"mc":[{"id":"1.168096552","rc":[{"batb":[[1,2.5,3.03],[2,2,53]],"ltp":0.0,"tv":0.0,"id":26640937},{"batb":[[0,2.72,1.68],[1,2.7,1.99]],"ltp":0.0,"tv":0.0,"id":21580749},{"batb":[[0,2.72,1.68],[1,2.52,1.99]],"ltp":0.0,"tv":0.0,"id":52106}]}]}
{"op":"mcm","clk":"989439871","pt":1580487814234,"mc":[{"id":"1.168096552","rc":[{"batb":[[0,2.72,1.68],[1,2.7,1.99],[2,2.5,3.03]],"ltp":0.0,"tv":0.0,"id":26640937},{"batb":[[0,2.72,1.68],[1,2.7,1.99]],"ltp":0.0,"tv":0.0,"id":27706761},{"batb":[[0,2.72,1.68],[1,2.7,1.99]],"ltp":0.0,"tv":0.0,"id":24608298}]}]}
{"op":"mcm","clk":"989442444","pt":1580487841362,"mc":[{"id":"1.168096552","rc":[{"batb":[[0,2.72,9.03]],"ltp":0.0,"tv":0.0,"id":26640937},{"batb":[[0,2.72,9.03]],"ltp":0.0,"tv":0.0,"id":21580749},{"batb":[[0,2.72,9.03]],"ltp":0.0,"tv":0.0,"id":27706761},{"batb":[[1,2.54,7.87],[2,2.52,1.99]],"ltp":0.0,"tv":0.0,"id":52106},{"batb":[[0,2.72,9.03]],"ltp":0.0,"tv":0.0,"id":24608298}]}]}
{"op":"mcm","clk":"989443653","pt":1580487854297,"mc":[{"id":"1.168096552","rc":[{"batb":[[0,2.74,1.99],[1,2.72,1.68],[2,2.54,7.87]],"ltp":0.0,"tv":0.0,"id":52106}]}]}
{"op":"mcm","clk":"989443740","pt":1580487855394,"mc":[{"id":"1.168096552","rc":[{"batb":[[0,2.74,1.99],[1,2.72,9.03]],"ltp":0.0,"tv":0.0,"id":26640937},{"batb":[[0,2.74,1.99],[1,2.72,9.03]],"ltp":0.0,"tv":0.0,"id":21580749},{"batb":[[0,2.74,1.99],[1,2.72,9.03]],"ltp":0.0,"tv":0.0,"id":27706761}]}]}
{"op":"mcm","clk":"989443768","pt":1580487855666,"mc":[{"id":"1.168096552","rc":[{"batb":[[0,2.74,1.99],[1,2.72,9.03]],"ltp":0.0,"tv":0.0,"id":24608298}]}]}
{"op":"mcm","clk":"989443962","pt":1580487858198,"mc":[{"id":"1.168096552","rc":[{"batb":[[2,2,53]],"ltp":0.0,"tv":0.0,"id":26640937},{"batb":[[2,2,53]],"ltp":0.0,"tv":0.0,"id":21580749},{"batb":[[2,2,53]],"ltp":0.0,"tv":0.0,"id":27706761},{"batb":[[2,2,53]],"ltp":0.0,"tv":0.0,"id":24608298}]}]}
{"op":"mcm","clk":"989444227","pt":1580487861508,"mc":[{"id":"1.168096552","rc":[{"batb":[[0,2.74,4.61]],"ltp":0.0,"tv":0.0,"id":26640937},{"batb":[[0,2.74,4.61]],"ltp":0.0,"tv":0.0,"id":21580749},{"batb":[[0,2.74,4.61]],"ltp":0.0,"tv":0.0,"id":27706761},{"batb":[[2,2.56,2.92]],"ltp":0.0,"tv":0.0,"id":52106},{"batb":[[0,2.74,4.61]],"ltp":0.0,"tv":0.0,"id":24608298}]}]}
{"op":"mcm","clk":"989446249","pt":1580487884421,"mc":[{"id":"1.168096552","rc":[{"batb":[[0,2.76,1.68],[1,2.74,1.99]],"ltp":0.0,"tv":0.0,"id":52106}]}]}
{"op":"mcm","clk":"989446347","pt":1580487885423,"mc":[{"id":"1.168096552","rc":[{"batb":[[0,2.76,1.68],[1,2.74,4.61],[2,2.72,7.35]],"ltp":0.0,"tv":0.0,"id":26640937},{"batb":[[0,2.76,1.68],[1,2.74,4.61],[2,2.72,7.35]],"ltp":0.0,"tv":0.0,"id":21580749},{"batb":[[0,2.76,1.68],[1,2.74,4.61],[2,2.72,7.35]],"ltp":0.0,"tv":0.0,"id":27706761},{"batb":[[1,2.72,7.35]],"ltp":0.0,"tv":0.0,"id":24608298}]}]}
{"op":"mcm","clk":"989446400","pt":1580487886111,"mc":[{"id":"1.168096552","rc":[{"batb":[[0,2.76,1.68],[1,2.74,4.61],[2,2.72,7.35]],"ltp":0.0,"tv":0.0,"id":24608298}]}]}
{"op":"mcm","clk":"989446566","pt":1580487887906,"mc":[{"id":"1.168096552","rc":[{"batb":[[1,2.74,1.99]],"ltp":0.0,"tv":0.0,"id":26640937},{"batb":[[1,2.74,1.99]],"ltp":0.0,"tv":0.0,"id":21580749},{"batb":[[1,2.74,1.99]],"ltp":0.0,"tv":0.0,"id":27706761},{"batb":[[1,2.74,1.99]],"ltp":0.0,"tv":0.0,"id":24608298}]}]}
{"op":"mcm","clk":"989446747","pt":1580487890328,"mc":[{"id":"1.168096552","rc":[{"batb":[[0,2.76,4.27]],"ltp":0.0,"tv":0.0,"id":26640937},{"batb":[[0,2.76,4.27]],"ltp":0.0,"tv":0.0,"id":21580749},{"batb":[[0,2.76,4.27]],"ltp":0.0,"tv":0.0,"id":27706761},{"batb":[[0,2.76,4.27]],"ltp":0.0,"tv":0.0,"id":24608298}]}]}
{"op":"mcm","clk":"989447320","pt":1580487897351,"mc":[{"id":"1.168096552","rc":[{"batb":[[0,2.78,1.99],[1,2.76,4.27]],"ltp":0.0,"tv":0.0,"id":21580749},{"batb":[[0,2.78,1.99],[1,2.76,1.68]],"ltp":0.0,"tv":0.0,"id":52106}]}]}
{"op":"mcm","clk":"989447400","pt":1580487898314,"mc":[{"id":"1.168096552","rc":[{"batb":[[0,2.78,1.99],[1,2.76,4.27]],"ltp":0.0,"tv":0.0,"id":26640937},{"batb":[[0,2.78,1.99],[1,2.76,4.27]],"ltp":0.0,"tv":0.0,"id":27706761},{"batb":[[0,2.78,1.99],[1,2.76,4.27]],"ltp":0.0,"tv":0.0,"id":24608298}]}]}
{"op":"mcm","clk":"989447769","pt":1580487902545,"mc":[{"id":"1.168096552","rc":[{"batl":[[0,3.25,5],[1,3.3,33],[2,3.5,150]],"ltp":3.25,"tv":36.0,"id":18286408}]}]}
{"op":"mcm","clk":"989448101","pt":1580487906146,"mc":[{"id":"1.168096552","rc":[{"batl":[[0,3.3,33],[1,3.5,150],[2,3.95,1.68]],"ltp":3.25,"tv":36.0,"id":18286408}]}]}
{"op":"mcm","clk":"989448487","pt":1580487910534,"mc":[{"id":"1.168096552","rc":[{"batb":[[2,2,53]],"ltp":0.0,"tv":0.0,"id":26640937},{"batb":[[2,2,53]],"ltp":0.0,"tv":0.0,"id":21580749},{"batb":[[2,2,53]],"ltp":0.0,"tv":0.0,"id":27706761},{"batb":[[2,2,53]],"ltp":0.0,"tv":0.0,"id":24608298}]}]}
{"op":"mcm","clk":"989450676","pt":1580487935499,"mc":[{"id":"1.168096552","rc":[{"batb":[[0,2.76,4.27],[1,2,53],[2,1.55,18.18]],"ltp":0.0,"tv":0.0,"id":26640937},{"batb":[[0,2.76,4.27],[1,2,53],[2,1.55,18.18]],"ltp":0.0,"tv":0.0,"id":21580749}]}]}
{"op":"mcm","clk":"989450743","pt":1580487936285,"mc":[{"id":"1.168096552","rc":[{"batb":[[0,2.76,4.27],[1,2,53],[2,1.55,18.18]],"ltp":0.0,"tv":0.0,"id":27706761},{"batb":[[0,2.76,4.27],[1,2,53],[2,1.55,18.18]],"ltp":0.0,"tv":0.0,"id":24608298}]}]}
{"op":"mcm","clk":"989451960","pt":1580487950415,"mc":[{"id":"1.168096552","rc":[{"batb":[[0,2.76,11.86]],"batl":[[1,1000,1.88]],"ltp":0.0,"tv":0.0,"id":21580749},{"batb":[[0,2.8,1.68],[1,2.78,1.99]],"ltp":0.0,"tv":0.0,"id":52106}]}]}
{"op":"mcm","clk":"989452033","pt":1580487951198,"mc":[{"id":"1.168096552","rc":[{"batb":[[0,2.76,11.86]],"ltp":0.0,"tv":0.0,"id":26640937},{"batl":[[0,5.4,17.74],[1,1000,0.2]],"ltp":0.0,"tv":0.0,"id":21580749},{"batb":[[0,2.76,11.86]],"ltp":0.0,"tv":0.0,"id":27706761},{"batb":[[0,2.76,11.86]],"ltp":0.0,"tv":0.0,"id":24608298}]}]}
{"op":"mcm","clk":"989454169","pt":1580487975741,"mc":[{"id":"1.168096552","rc":[{"batb":[[0,2.82,1.99],[1,2.8,1.68]],"ltp":0.0,"tv":0.0,"id":52106}]}]}
{"op":"mcm","clk":"989459043","pt":1580488030505,"mc":[{"id":"1.168096552","rc":[{"batb":[[0,2.76,2.59]],"ltp":0.0,"tv":0.0,"id":26640937},{"batb":[[0,2.76,2.59],[1,2.02,9.28],[2,2,53]],"ltp":0.0,"tv":0.0,"id":21580749},{"batb":[[0,2.84,1.68],[1,2.82,1.99]],"ltp":0.0,"tv":0.0,"id":52106}]}]}
{"op":"mcm","clk":"989459143","pt":1580488031504,"mc":[{"id":"1.168096552","rc":[{"batb":[[1,2.02,9.28],[2,2,53]],"ltp":0.0,"tv":0.0,"id":26640937},{"batb":[[0,2.76,2.59],[1,2.02,9.28],[2,2,53]],"ltp":0.0,"tv":0.0,"id":27706761},{"batb":[[0,2.76,2.59],[1,2.02,9.28],[2,2,53]],"ltp":0.0,"tv":0.0,"id":24608298}]}]}
{"op":"mcm","clk":"989461859","pt":1580488059469,"mc":[{"id":"1.168096552","rc":[{"batb":[[1,2.56,2.92],[2,2,53]],"ltp":0.0,"tv":0.0,"id":52106}]}]}
{"op":"mcm","clk":"989465011","pt":1580488091499,"mc":[{"id":"1.168096552","rc":[{"batb":[[0,2.58,1.68]],"ltp":0.0,"tv":0.0,"id":52106}]}]}
{"op":"mcm","clk":"989465104","pt":1580488092492,"mc":[{"id":"1.168096552","rc":[{"batb":[[0,2.78,2.97],[1,2.76,2.59]],"ltp":0.0,"tv":0.0,"id":26640937},{"batb":[[0,2.78,2.97],[1,2.76,2.59]],"ltp":0.0,"tv":0.0,"id":21580749},{"batb":[[0,2.78,2.97],[1,2.76,2.59]],"ltp":0.0,"tv":0.0,"id":27706761},{"batb":[[1,2,53],[2,1.55,18.18]],"ltp":0.0,"tv":0.0,"id":24608298}]}]}
{"op":"mcm","clk":"989465120","pt":1580488092611,"mc":[{"id":"1.168096552","rc":[{"batb":[[0,2.78,2.97],[1,2.76,2.59],[2,2,53]],"ltp":0.0,"tv":0.0,"id":24608298}]}]}
{"op":"mcm","clk":"989468274","pt":1580488124519,"mc":[{"id":"1.168096552","rc":[{"batb":[[2,2.02,3]],"ltp":0.0,"tv":0.0,"id":26640937},{"batb":[[2,2.02,3]],"ltp":0.0,"tv":0.0,"id":21580749},{"batb":[[2,2.02,3]],"ltp":0.0,"tv":0.0,"id":27706761},{"batb":[[2,2.02,3]],"ltp":0.0,"tv":0.0,"id":52106},{"batb":[[2,2.02,3]],"ltp":0.0,"tv":0.0,"id":24608298}]}]}
{"op":"mcm","clk":"989469459","pt":1580488134434,"mc":[{"id":"1.168096552","rc":[{"batl":[[0,3.35,33]],"ltp":3.25,"tv":36.0,"id":18286408}]}]}
{"op":"mcm","clk":"989474489","pt":1580488187830,"mc":[{"id":"1.168096552","rc":[{"batb":[[0,2.78,10.16]],"ltp":0.0,"tv":0.0,"id":26640937},{"batb":[[0,2.78,10.16]],"ltp":0.0,"tv":0.0,"id":21580749},{"batb":[[0,2.78,10.16]],"ltp":0.0,"tv":0.0,"id":27706761},{"batb":[[0,2.58,9.43]],"ltp":0.0,"tv":0.0,"id":52106},{"batb":[[0,2.78,10.16]],"ltp":0.0,"tv":0.0,"id":24608298}]}]}
{"op":"mcm","clk":"989477121","pt":1580488218283,"mc":[{"id":"1.168096552","rc":[{"batb":[[1,2.02,3],[2,2,53]],"ltp":0.0,"tv":0.0,"id":26640937},{"batb":[[1,2.02,3],[2,2,53]],"ltp":0.0,"tv":0.0,"id":21580749},{"batb":[[1,2.02,3],[2,2,53]],"ltp":0.0,"tv":0.0,"id":27706761},{"batb":[[1,2.02,3],[2,2,53]],"ltp":0.0,"tv":0.0,"id":52106},{"batb":[[1,2.02,3],[2,2,53]],"ltp":0.0,"tv":0.0,"id":24608298}]}]}
{"op":"mcm","clk":"989477425","pt":1580488221472,"mc":[{"id":"1.168096552","rc":[{"batb":[[0,2.8,2.53],[1,2.78,10.16],[2,2.02,3]],"ltp":0.0,"tv":0.0,"id":26640937},{"batb":[[0,2.8,2.53],[1,2.78,10.16],[2,2.02,3]],"ltp":0.0,"tv":0.0,"id":21580749},{"batb":[[0,2.8,2.53],[1,2.78,10.16],[2,2.02,3]],"ltp":0.0,"tv":0.0,"id":27706761},{"batb":[[0,2.6,2.85],[1,2.58,9.43],[2,2.02,3]],"ltp":0.0,"tv":0.0,"id":52106},{"batb":[[0,2.8,2.53],[1,2.78,10.16],[2,2.02,3]],"ltp":0.0,"tv":0.0,"id":24608298}]}]}
{"op":"mcm","clk":"989477495","pt":1580488222459,"mc":[{"id":"1.168096552","rc":[{"batb":[[0,2.82,2.93],[1,2.8,2.53],[2,2.78,7.19]],"ltp":0.0,"tv":0.0,"id":21580749},{"batb":[[0,2.62,1.68],[1,2.6,2.85],[2,2.58,7.75]],"ltp":0.0,"tv":0.0,"id":52106}]}]}
{"op":"mcm","clk":"989477583","pt":1580488223504,"mc":[{"id":"1.168096552","rc":[{"batb":[[0,2.82,2.93],[1,2.8,2.53],[2,2.78,7.19]],"ltp":0.0,"tv":0.0,"id":26640937},{"batb":[[0,2.82,2.93],[1,2.8,2.53],[2,2.78,7.19]],"ltp":0.0,"tv":0.0,"id":27706761},{"batb":[[0,2.82,2.93],[1,2.8,2.53],[2,2.78,7.19]],"ltp":0.0,"tv":0.0,"id":24608298}]}]}
{"op":"mcm","clk":"989480262","pt":1580488257532,"mc":[{"id":"1.168096552","rc":[{"batb":[[2,2.02,3]],"ltp":0.0,"tv":0.0,"id":26640937},{"batb":[[2,2.02,3]],"ltp":0.0,"tv":0.0,"id":21580749},{"batb":[[2,2.02,3]],"ltp":0.0,"tv":0.0,"id":27706761},{"batb":[[2,2.02,3]],"ltp":0.0,"tv":0.0,"id":52106},{"batb":[[2,2.02,3]],"ltp":0.0,"tv":0.0,"id":24608298}]}]}
{"op":"mcm","clk":"989496897","pt":1580488455563,"mc":[{"id":"1.168096552","rc":[{"batl":[[0,3.9,5.17]],"ltp":0.0,"tv":0.0,"id":52106}]}]}
{"op":"mcm","clk":"989496993","pt":1580488456989,"mc":[{"id":"1.168096552","rc":[{"batl":[[0,3.9,4.75]],"ltp":0.0,"tv":0.0,"id":52106}]}]}
{"op":"mcm","clk":"989526580","pt":1580488687772,"mc":[{"id":"1.168096552","rc":[{"batb":[[1,3,3]],"ltp":3.25,"tv":36.0,"id":18286408},{"batb":[[0,3,53],[1,2.82,2.93],[2,2.8,2.53]],"ltp":0.0,"tv":0.0,"id":26640937},{"batb":[[0,3,53],[1,2.82,2.93],[2,2.8,2.53]],"ltp":0.0,"tv":0.0,"id":21580749},{"batb":[[0,3,53],[1,2.82,2.93],[2,2.8,2.53]],"ltp":0.0,"tv":0.0,"id":27706761},{"batb":[[2,2.04,53]],"ltp":0.0,"tv":0.0,"id":52106},{"batb":[[0,3,53],[1,2.82,2.93],[2,2.8,2.53]],"ltp":0.0,"tv":0.0,"id":24608298}]}]}
{"op":"mcm","clk":"989526645","pt":1580488688706,"mc":[{"id":"1.168096552","rc":[{"batb":[[0,3.05,3],[1,3,53],[2,2.82,2.93]],"ltp":0.0,"tv":0.0,"id":26640937},{"batb":[[0,3.05,3],[1,3,53],[2,2.82,2.93]],"ltp":0.0,"tv":0.0,"id":21580749},{"batb":[[0,3.05,3],[1,3,53],[2,2.82,2.93]],"ltp":0.0,"tv":0.0,"id":27706761},{"batb":[[2,2.06,3]],"ltp":0.0,"tv":0.0,"id":52106},{"batb":[[0,3.05,3],[1,3,53],[2,2.82,2.93]],"ltp":0.0,"tv":0.0,"id":24608298}]}]}
{"op":"mcm","clk":"989527788","pt":1580488702404,"mc":[{"id":"1.168096552","rc":[{"batb":[[0,3.05,5.22]],"ltp":0.0,"tv":0.0,"id":26640937}]}]}
{"op":"mcm","clk":"989527831","pt":1580488702820,"mc":[{"id":"1.168096552","rc":[{"batb":[[0,3.05,5.22]],"ltp":0.0,"tv":0.0,"id":21580749},{"batb":[[0,3.05,5.22]],"ltp":0.0,"tv":0.0,"id":27706761},{"batb":[[0,3.05,5.22]],"ltp":0.0,"tv":0.0,"id":24608298}]}]}
{"op":"mcm","clk":"989528264","pt":1580488707511,"mc":[{"id":"1.168096552","rc":[{"batb":[[0,3.1,1.99],[1,3.05,5.22],[2,3,53]],"ltp":0.0,"tv":0.0,"id":26640937},{"batb":[[0,3.1,1.99],[1,3.05,5.22],[2,3,53]],"ltp":0.0,"tv":0.0,"id":21580749},{"batb":[[0,3.1,1.99],[1,3.05,5.22],[2,3,53]],"ltp":0.0,"tv":0.0,"id":27706761}]}]}
{"op":"mcm","clk":"989528279","pt":1580488707620,"mc":[{"id":"1.168096552","rc":[{"batb":[[0,3.1,1.99],[1,3.05,5.22],[2,3,53]],"ltp":0.0,"tv":0.0,"id":24608298}]}]}
{"op":"mcm","clk":"989528397","pt":1580488708920,"mc":[{"id":"1.168096552","rc":[{"batb":[[1,3.05,58.22],[2,2.82,2.93]],"ltp":0.0,"tv":0.0,"id":26640937},{"batb":[[2,2.84,53]],"ltp":0.0,"tv":0.0,"id":21580749},{"batb":[[1,3.05,58.22],[2,2.82,2.93]],"ltp":0.0,"tv":0.0,"id":27706761},{"batb":[[1,3.05,58.22],[2,2.82,2.93]],"ltp":0.0,"tv":0.0,"id":24608298}]}]}
{"op":"mcm","clk":"989529034","pt":1580488716421,"mc":[{"id":"1.168096552","rc":[{"batb":[[0,3.15,2.62],[1,3.1,1.99],[2,3.05,58.22]],"ltp":0.0,"tv":0.0,"id":26640937},{"batb":[[0,3.15,1.8],[1,3.1,1.99],[2,3.05,5.22]],"ltp":0.0,"tv":0.0,"id":21580749},{"batb":[[0,3.15,2.62],[1,3.1,1.99],[2,3.05,58.22]],"ltp":0.0,"tv":0.0,"id":27706761},{"batb":[[2,1.55,18.18]],"ltp":0.0,"tv":0.0,"id":24608298}]}]}
{"op":"mcm","clk":"989529040","pt":1580488716527,"mc":[{"id":"1.168096552","rc":[{"batb":[[0,3.15,2.62],[1,3.1,1.99],[2,3.05,58.22]],"ltp":0.0,"tv":0.0,"id":24608298}]}]}
{"op":"mcm","clk":"989530175","pt":1580488728347,"mc":[{"id":"1.168096552","rc":[{"batb":[[2,3.05,56]],"ltp":0.0,"tv":0.0,"id":26640937},{"batb":[[2,3.05,3]],"ltp":0.0,"tv":0.0,"id":21580749},{"batb":[[2,3.05,56]],"ltp":0.0,"tv":0.0,"id":27706761},{"batb":[[2,3.05,56]],"ltp":0.0,"tv":0.0,"id":24608298}]}]}
{"op":"mcm","clk":"989530442","pt":1580488731235,"mc":[{"id":"1.168096552","rc":[{"batb":[[1,3.1,4.16]],"ltp":0.0,"tv":0.0,"id":26640937},{"batb":[[1,3.1,4.16]],"ltp":0.0,"tv":0.0,"id":21580749},{"batb":[[1,3.1,4.16]],"ltp":0.0,"tv":0.0,"id":27706761},{"batb":[[1,3.1,4.16]],"ltp":0.0,"tv":0.0,"id":24608298}]}]}
{"op":"mcm","clk":"989530677","pt":1580488733424,"mc":[{"id":"1.168096552","rc":[{"batb":[[0,3.15,55.62],[2,3.05,3]],"ltp":0.0,"tv":0.0,"id":26640937},{"batb":[[0,3.15,55.62],[2,3.05,3]],"ltp":0.0,"tv":0.0,"id":27706761},{"batb":[[2,2.08,53]],"ltp":0.0,"tv":0.0,"id":52106},{"batb":[[0,3.15,55.62],[2,3.05,3]],"ltp":0.0,"tv":0.0,"id":24608298}]}]}
{"op":"mcm","clk":"989531255","pt":1580488739833,"mc":[{"id":"1.168096552","rc":[{"batb":[[0,3.2,3],[1,3.15,55.62],[2,3.1,4.16]],"ltp":0.0,"tv":0.0,"id":26640937},{"batb":[[2,2.88,3]],"ltp":0.0,"tv":0.0,"id":21580749},{"batb":[[0,3.2,3],[1,3.15,55.62],[2,3.1,4.16]],"ltp":0.0,"tv":0.0,"id":27706761},{"batb":[[2,2.1,3]],"ltp":0.0,"tv":0.0,"id":52106},{"batb":[[0,3.2,3],[1,3.15,55.62],[2,3.1,4.16]],"ltp":0.0,"tv":0.0,"id":24608298}]}]}
{"op":"mcm","clk":"989532505","pt":1580488754273,"mc":[{"id":"1.168096552","rc":[{"batb":[[0,3.2,1.99],[1,3.15,1.8],[2,3.1,2.17]],"ltp":0.0,"tv":0.0,"id":21580749}]}]}
{"op":"mcm","clk":"989532596","pt":1580488755364,"mc":[{"id":"1.168096552","rc":[{"batb":[[0,3.25,1.99],[1,3.2,3],[2,3.15,55.62]],"ltp":0.0,"tv":0.0,"id":26640937},{"batb":[[0,3.25,1.99],[1,3.2,3],[2,3.15,55.62]],"ltp":0.0,"tv":0.0,"id":27706761},{"batb":[[0,3.25,1.99],[1,3.2,3],[2,3.15,55.62]],"ltp":0.0,"tv":0.0,"id":24608298}]}]}
{"op":"mcm","clk":"989533036","pt":1580488760769,"mc":[{"id":"1.168096552","rc":[{"batb":[[1,3.2,5.07]],"ltp":0.0,"tv":0.0,"id":26640937},{"batb":[[1,3.2,5.07]],"ltp":0.0,"tv":0.0,"id":27706761},{"batb":[[1,3.2,5.07]],"ltp":0.0,"tv":0.0,"id":24608298}]}]}
{"op":"mcm","clk":"989535233","pt":1580488788078,"mc":[{"id":"1.168096552","rc":[{"batb":[[1,3.2,3]],"ltp":0.0,"tv":0.0,"id":26640937},{"batb":[[1,3.2,3]],"ltp":0.0,"tv":0.0,"id":27706761},{"batb":[[1,3.2,3]],"ltp":0.0,"tv":0.0,"id":24608298}]}]}
{"op":"mcm","clk":"989535509","pt":1580488791292,"mc":[{"id":"1.168096552","rc":[{"batb":[[0,3.25,4.02]],"ltp":0.0,"tv":0.0,"id":26640937},{"batb":[[0,3.25,4.02]],"ltp":0.0,"tv":0.0,"id":27706761},{"batb":[[0,3.25,4.02]],"ltp":0.0,"tv":0.0,"id":24608298}]}]}
{"op":"mcm","clk":"989536176","pt":1580488799506,"mc":[{"id":"1.168096552","rc":[{"batb":[[2,3.15,53]],"ltp":0.0,"tv":0.0,"id":26640937},{"batb":[[0,3.25,1.68],[1,3.2,1.99]],"ltp":0.0,"tv":0.0,"id":21580749}]}]}
{"op":"mcm","clk":"989536252","pt":1580488800247,"mc":[{"id":"1.168096552","rc":[{"batb":[[0,3.3,1.76],[1,3.25,4.02],[2,3.2,3]],"ltp":0.0,"tv":0.0,"id":26640937},{"batb":[[0,3.3,1.76],[1,3.25,4.02],[2,3.2,3]],"ltp":0.0,"tv":0.0,"id":27706761},{"batb":[[0,3.3,1.76],[1,3.25,4.02],[2,3.2,3]],"ltp":0.0,"tv":0.0,"id":24608298}]}]}
{"op":"mcm","clk":"989536388","pt":1580488801393,"mc":[{"id":"1.168096552","rc":[{"batb":[[0,3.35,1.99],[1,3.3,1.76],[2,3.25,2.03]],"ltp":0.0,"tv":0.0,"id":26640937},{"batb":[[0,3.3,1.99],[1,3.25,1.68]],"ltp":0.0,"tv":0.0,"id":21580749},{"batb":[[0,3.35,1.99],[1,3.3,1.76],[2,3.25,2.03]],"ltp":0.0,"tv":0.0,"id":27706761}]}]}
{"op":"mcm","clk":"989536444","pt":1580488802020,"mc":[{"id":"1.168096552","rc":[{"batb":[[0,3.35,1.99],[1,3.3,1.76],[2,3.25,2.03]],"ltp":0.0,"tv":0.0,"id":24608298}]}]}
{"op":"mcm","clk":"989542898","pt":1580488879431,"mc":[{"id":"1.168096552","rc":[{"batb":[[0,3.4,1.68],[1,3.35,1.99]],"ltp":0.0,"tv":0.0,"id":26640937},{"batb":[[0,3.35,1.68],[1,3.3,1.99]],"ltp":0.0,"tv":0.0,"id":21580749},{"batb":[[1,3.25,2.03],[2,3.2,3]],"ltp":0.0,"tv":0.0,"id":27706761}]}]}
{"op":"mcm","clk":"989542920","pt":1580488879743,"mc":[{"id":"1.168096552","rc":[{"batb":[[0,3.4,1.68],[1,3.35,1.99],[2,3.25,2.03]],"ltp":0.0,"tv":0.0,"id":27706761},{"batb":[[0,3.4,1.68],[1,3.35,1.99]],"ltp":0.0,"tv":0.0,"id":24608298}]}]}
{"op":"mcm","clk":"989545365","pt":1580488907460,"mc":[{"id":"1.168096552","rc":[{"batb":[[0,3.45,1.99],[1,3.4,1.68]],"ltp":0.0,"tv":0.0,"id":26640937},{"batb":[[0,3.4,1.99],[1,3.35,1.68]],"ltp":0.0,"tv":0.0,"id":21580749},{"batb":[[0,3.45,1.99],[1,3.4,1.68]],"ltp":0.0,"tv":0.0,"id":27706761}]}]}
{"op":"mcm","clk":"989545447","pt":1580488908385,"mc":[{"id":"1.168096552","rc":[{"batb":[[0,3.45,1.99],[1,3.4,1.68]],"ltp":0.0,"tv":0.0,"id":24608298}]}]}
{"op":"mcm","clk":"989549139","pt":1580488947493,"mc":[{"id":"1.168096552","rc":[{"batb":[[1,3.1,2.17],[2,2.86,3]],"ltp":0.0,"tv":0.0,"id":21580749}]}]}
{"op":"mcm","clk":"989549217","pt":1580488948236,"mc":[{"id":"1.168096552","rc":[{"batb":[[0,3.5,1.68],[1,3.45,1.99]],"ltp":0.0,"tv":0.0,"id":26640937},{"batb":[[0,3.45,1.68],[1,3.4,1.99],[2,3.1,2.17]],"ltp":0.0,"tv":0.0,"id":21580749},{"batb":[[0,3.5,1.68],[1,3.45,1.99]],"ltp":0.0,"tv":0.0,"id":27706761},{"batb":[[0,3.5,1.68],[1,3.45,1.99]],"ltp":0.0,"tv":0.0,"id":24608298}]}]}
{"op":"mcm","clk":"989549904","pt":1580488955416,"mc":[{"id":"1.168096552","rc":[{"batb":[[0,3.5,1.99],[1,3.45,1.68]],"ltp":0.0,"tv":0.0,"id":21580749}]}]}
{"op":"mcm","clk":"989549998","pt":1580488956339,"mc":[{"id":"1.168096552","rc":[{"batb":[[0,3.55,1.99],[1,3.5,1.68]],"ltp":0.0,"tv":0.0,"id":26640937},{"batb":[[0,3.55,1.99],[1,3.5,1.68]],"ltp":0.0,"tv":0.0,"id":27706761}]}]}
{"op":"mcm","clk":"989550029","pt":1580488956757,"mc":[{"id":"1.168096552","rc":[{"batb":[[0,3.55,1.99],[1,3.5,1.68]],"ltp":0.0,"tv":0.0,"id":24608298}]}]}
{"op":"mcm","clk":"989553940","pt":1580489008066,"mc":[{"id":"1.168096552","rc":[{"batl":[[1,5.5,5],[2,1000,0.2]],"ltp":0.0,"tv":0.0,"id":21580749}]}]}
{"op":"mcm","clk":"989554015","pt":1580489009066,"mc":[{"id":"1.168096552","rc":[{"batb":[[0,3.45,1.68],[1,3.1,2.17],[2,2.86,3]],"ltp":0.0,"tv":0.0,"id":21580749}]}]}
{"op":"mcm","clk":"989555709","pt":1580489031494,"mc":[{"id":"1.168096552","rc":[{"batb":[[0,3.1,2.17],[1,2.86,3],[2,2.84,53]],"ltp":0.0,"tv":0.0,"id":21580749}]}]}
{"op":"mcm","clk":"989555768","pt":1580489032234,"mc":[{"id":"1.168096552","rc":[{"batb":[[0,3.6,1.68],[1,3.55,1.99]],"ltp":0.0,"tv":0.0,"id":26640937},{"batb":[[0,3.15,1.68],[1,3.1,2.17],[2,2.86,3]],"ltp":0.0,"tv":0.0,"id":21580749},{"batb":[[0,3.6,1.68],[1,3.55,1.99]],"ltp":0.0,"tv":0.0,"id":27706761},{"batb":[[0,3.6,1.68],[1,3.55,1.99]],"ltp":0.0,"tv":0.0,"id":24608298}]}]}
{"op":"mcm","clk":"989558346","pt":1580489064380,"mc":[{"id":"1.168096552","rc":[{"batb":[[0,3.65,1.99],[1,3.6,1.68]],"ltp":0.0,"tv":0.0,"id":26640937},{"batb":[[0,3.2,1.99],[1,3.15,1.68],[2,3.1,2.17]],"ltp":0.0,"tv":0.0,"id":21580749},{"batb":[[0,3.65,1.99],[1,3.6,1.68]],"ltp":0.0,"tv":0.0,"id":27706761}]}]}
{"op":"mcm","clk":"989558397","pt":1580489064998,"mc":[{"id":"1.168096552","rc":[{"batb":[[0,3.65,1.99],[1,3.6,1.68]],"ltp":0.0,"tv":0.0,"id":24608298}]}]}
{"op":"mcm","clk":"989560291","pt":1580489088904,"mc":[{"id":"1.168096552","rc":[{"batl":[[0,3.3,10],[1,3.35,33],[2,3.5,150]],"ltp":3.25,"tv":36.0,"id":18286408}]}]}
{"op":"mcm","clk":"989561813","pt":1580489108323,"mc":[{"id":"1.168096552","rc":[{"batb":[[0,3.6,1.68],[1,3.25,2.03],[2,3.2,3]],"ltp":0.0,"tv":0.0,"id":26640937}]}]}
{"op":"mcm","clk":"989561890","pt":1580489109320,"mc":[{"id":"1.168096552","rc":[{"batb":[[0,3.6,1.68],[1,3.25,2.03],[2,3.2,3]],"ltp":0.0,"tv":0.0,"id":27706761},{"batb":[[0,3.6,1.68],[1,3.25,2.03],[2,3.2,3]],"ltp":0.0,"tv":0.0,"id":24608298}]}]}
{"op":"mcm","clk":"989562193","pt":1580489113521,"mc":[{"id":"1.168096552","rc":[{"batb":[[0,3.25,2.03],[1,3.2,3],[2,3.15,53]],"ltp":0.0,"tv":0.0,"id":26640937},{"batb":[[0,3.25,1.68],[1,3.2,1.99]],"ltp":0.0,"tv":0.0,"id":21580749}]}]}
{"op":"mcm","clk":"989562258","pt":1580489114216,"mc":[{"id":"1.168096552","rc":[{"batb":[[0,3.3,1.68],[1,3.25,2.03],[2,3.2,3]],"ltp":0.0,"tv":0.0,"id":26640937},{"batb":[[0,3.3,1.68]],"ltp":0.0,"tv":0.0,"id":27706761},{"batb":[[0,3.3,1.68]],"ltp":0.0,"tv":0.0,"id":24608298}]}]}
{"op":"mcm","clk":"989565140","pt":1580489148508,"mc":[{"id":"1.168096552","rc":[{"batb":[[0,3.3,1.99],[1,3.25,1.68]],"ltp":0.0,"tv":0.0,"id":21580749}]}]}
{"op":"mcm","clk":"989565216","pt":1580489149520,"mc":[{"id":"1.168096552","rc":[{"batb":[[0,3.35,1.99],[1,3.3,1.68],[2,3.25,2.03]],"ltp":0.0,"tv":0.0,"id":26640937},{"batb":[[0,3.35,1.99],[1,3.3,1.68],[2,3.25,2.03]],"ltp":0.0,"tv":0.0,"id":27706761},{"batb":[[0,3.35,1.99],[1,3.3,1.68],[2,3.25,2.03]],"ltp":0.0,"tv":0.0,"id":24608298}]}]}
{"op":"mcm","clk":"989567348","pt":1580489177314,"mc":[{"id":"1.168096552","rc":[{"batl":[[1,1000,0.2],[2,1000,0]],"ltp":0.0,"tv":0.0,"id":52106}]}]}
{"op":"mcm","clk":"989568291","pt":1580489190364,"mc":[{"id":"1.168096552","rc":[{"batb":[[1,3.25,2.03],[2,3.2,3]],"ltp":0.0,"tv":0.0,"id":26640937},{"batb":[[0,3.35,1.68],[1,3.3,1.99]],"ltp":0.0,"tv":0.0,"id":21580749}]}]}
{"op":"mcm","clk":"989568362","pt":1580489191356,"mc":[{"id":"1.168096552","rc":[{"batb":[[0,3.4,1.68],[1,3.35,1.99],[2,3.25,2.03]],"ltp":0.0,"tv":0.0,"id":26640937},{"batb":[[0,3.4,1.68],[1,3.35,1.99]],"ltp":0.0,"tv":0.0,"id":27706761},{"batl":[[0,3.85,7],[1,3.9,4.75],[2,1000,0.2]],"ltp":0.0,"tv":0.0,"id":52106},{"batb":[[0,3.4,1.68],[1,3.35,1.99]],"ltp":0.0,"tv":0.0,"id":24608298}]}]}
{"op":"mcm","clk":"989570013","pt":1580489215798,"mc":[{"id":"1.168096552","rc":[{"batb":[[0,3.05,6.28]],"ltp":3.25,"tv":36.0,"id":18286408},{"batb":[[0,3.4,3.67]],"ltp":0.0,"tv":0.0,"id":26640937},{"batb":[[1,3.3,5.61]],"ltp":0.0,"tv":0.0,"id":21580749},{"batb":[[0,3.4,3.67]],"ltp":0.0,"tv":0.0,"id":27706761},{"batb":[[1,2.6,8.06]],"ltp":0.0,"tv":0.0,"id":52106},{"batb":[[0,3.4,3.67]],"ltp":0.0,"tv":0.0,"id":24608298}]}]}
{"op":"mcm","clk":"989571641","pt":1580489238510,"mc":[{"id":"1.168096552","rc":[{"batb":[[2,3.2,3]],"ltp":0.0,"tv":0.0,"id":26640937},{"batb":[[2,2.86,3]],"ltp":0.0,"tv":0.0,"id":21580749},{"batb":[[2,3.2,3]],"ltp":0.0,"tv":0.0,"id":27706761},{"batb":[[1,2.6,5.21]],"ltp":0.0,"tv":0.0,"id":52106},{"batb":[[2,3.2,3]],"ltp":0.0,"tv":0.0,"id":24608298}]}]}
{"op":"mcm","clk":"989571844","pt":1580489241420,"mc":[{"id":"1.168096552","rc":[{"batb":[[1,3.3,3.62]],"ltp":0.0,"tv":0.0,"id":21580749}]}]}
{"op":"mcm","clk":"989571933","pt":1580489242518,"mc":[{"id":"1.168096552","rc":[{"batb":[[0,3.45,3.85],[1,3.4,3.67]],"ltp":0.0,"tv":0.0,"id":26640937},{"batb":[[0,3.35,3.62]],"ltp":0.0,"tv":0.0,"id":21580749},{"batb":[[0,3.45,1.86],[1,3.4,3.67]],"ltp":0.0,"tv":0.0,"id":27706761},{"batb":[[0,2.62,4.49]],"ltp":0.0,"tv":0.0,"id":52106},{"batb":[[0,3.45,1.86],[1,3.4,3.67],[2,3.35,1.99]],"ltp":0.0,"tv":0.0,"id":24608298}]}]}
{"op":"mcm","clk":"989571982","pt":1580489243240,"mc":[{"id":"1.168096552","rc":[{"batb":[[0,3.45,3.85]],"ltp":0.0,"tv":0.0,"id":27706761},{"batb":[[0,3.45,3.85],[2,3.2,3]],"ltp":0.0,"tv":0.0,"id":24608298}]}]}
{"op":"mcm","clk":"989572431","pt":1580489249422,"mc":[{"id":"1.168096552","rc":[{"batb":[[0,3.5,1.68],[1,3.45,3.85],[2,3.4,1.98]],"ltp":0.0,"tv":0.0,"id":26640937},{"batl":[[0,3.8,1.68],[1,3.85,7]],"ltp":0.0,"tv":0.0,"id":52106}]}]}
{"op":"mcm","clk":"989572499","pt":1580489250323,"mc":[{"id":"1.168096552","rc":[{"batb":[[0,3.5,1.68],[1,3.45,3.85],[2,3.4,1.98]],"ltp":0.0,"tv":0.0,"id":27706761},{"batb":[[0,3.5,1.68],[1,3.45,3.85],[2,3.4,1.98]],"ltp":0.0,"tv":0.0,"id":24608298}]}]}
{"op":"mcm","clk":"989573627","pt":1580489268258,"mc":[{"id":"1.168096552","rc":[{"batb":[[1,3.45,1.99]],"ltp":0.0,"tv":0.0,"id":26640937},{"batb":[[1,3.45,1.99]],"ltp":0.0,"tv":0.0,"id":27706761},{"batb":[[1,3.45,1.99]],"ltp":0.0,"tv":0.0,"id":24608298}]}]}
{"op":"mcm","clk":"989573793","pt":1580489270660,"mc":[{"id":"1.168096552","rc":[{"batb":[[0,3.5,3.5]],"ltp":0.0,"tv":0.0,"id":26640937},{"batb":[[0,3.5,3.5]],"ltp":0.0,"tv":0.0,"id":27706761},{"batb":[[0,3.5,3.5]],"ltp":0.0,"tv":0.0,"id":24608298}]}]}
{"op":"mcm","clk":"989575901","pt":1580489301516,"mc":[{"id":"1.168096552","rc":[{"batb":[[0,3.55,1.99],[1,3.5,3.5]],"ltp":0.0,"tv":0.0,"id":26640937}]}]}
{"op":"mcm","clk":"989575960","pt":1580489302186,"mc":[{"id":"1.168096552","rc":[{"batb":[[0,3.55,1.99],[1,3.5,3.5]],"ltp":0.0,"tv":0.0,"id":27706761},{"batb":[[0,3.55,1.99],[1,3.5,3.5]],"ltp":0.0,"tv":0.0,"id":24608298}]}]}
{"op":"mcm","clk":"989576448","pt":1580489309405,"mc":[{"id":"1.168096552","rc":[{"batb":[[0,3.6,1.68],[1,3.55,1.99],[2,3.5,1.82]],"ltp":0.0,"tv":0.0,"id":26640937},{"batb":[[0,3.6,1.68],[1,3.55,1.99],[2,3.5,1.82]],"ltp":0.0,"tv":0.0,"id":27706761},{"batb":[[1,3.5,1.82]],"ltp":0.0,"tv":0.0,"id":24608298}]}]}
{"op":"mcm","clk":"989576458","pt":1580489309613,"mc":[{"id":"1.168096552","rc":[{"batb":[[0,3.6,1.68],[1,3.55,1.99],[2,3.5,1.82]],"ltp":0.0,"tv":0.0,"id":24608298}]}]}
{"op":"mcm","clk":"989578341","pt":1580489339333,"mc":[{"id":"1.168096552","rc":[{"batb":[[0,3.65,1.99],[1,3.6,1.68]],"ltp":0.0,"tv":0.0,"id":26640937}]}]}
{"op":"mcm","clk":"989578382","pt":1580489339954,"mc":[{"id":"1.168096552","rc":[{"batb":[[0,3.65,1.99],[1,3.6,1.68]],"ltp":0.0,"tv":0.0,"id":27706761},{"batb":[[0,3.65,1.99],[1,3.6,1.68]],"ltp":0.0,"tv":0.0,"id":24608298}]}]}
{"op":"mcm","clk":"989580864","pt":1580489378493,"mc":[{"id":"1.168096552","rc":[{"batb":[[0,3.7,1.68],[1,3.65,1.99]],"ltp":0.0,"tv":0.0,"id":26640937},{"batb":[[0,3.7,1.68],[1,3.65,1.99]],"ltp":0.0,"tv":0.0,"id":27706761}]}]}
{"op":"mcm","clk":"989580924","pt":1580489379377,"mc":[{"id":"1.168096552","rc":[{"batb":[[0,3.7,1.68],[1,3.65,1.99]],"ltp":0.0,"tv":0.0,"id":24608298}]}]}
{"op":"mcm","clk":"989583663","pt":1580489420423,"mc":[{"id":"1.168096552","rc":[{"batb":[[0,3.75,1.99],[1,3.7,1.68]],"ltp":0.0,"tv":0.0,"id":26640937}]}]}
{"op":"mcm","clk":"989583723","pt":1580489421250,"mc":[{"id":"1.168096552","rc":[{"batb":[[0,3.75,1.99],[1,3.7,1.68]],"ltp":0.0,"tv":0.0,"id":27706761},{"batb":[[0,3.75,1.99],[1,3.7,1.68]],"ltp":0.0,"tv":0.0,"id":24608298}]}]}
{"op":"mcm","clk":"989585470","pt":1580489444378,"mc":[{"id":"1.168096552","rc":[{"batb":[[0,3.8,1.68],[1,3.75,1.99]],"ltp":0.0,"tv":0.0,"id":26640937},{"batb":[[0,3.8,1.68],[1,3.75,1.99]],"ltp":0.0,"tv":0.0,"id":27706761}]}]}
{"op":"mcm","clk":"989585494","pt":1580489444789,"mc":[{"id":"1.168096552","rc":[{"batb":[[0,3.8,1.68],[1,3.75,1.99]],"ltp":0.0,"tv":0.0,"id":24608298}]}]}
{"op":"mcm","clk":"989587141","pt":1580489467433,"mc":[{"id":"1.168096552","rc":[{"batb":[[0,3.85,1.99],[1,3.8,1.68]],"ltp":0.0,"tv":0.0,"id":26640937},{"batb":[[0,3.85,1.99],[1,3.8,1.68]],"ltp":0.0,"tv":0.0,"id":27706761}]}]}
{"op":"mcm","clk":"989587182","pt":1580489467933,"mc":[{"id":"1.168096552","rc":[{"batb":[[0,3.85,1.99],[1,3.8,1.68]],"ltp":0.0,"tv":0.0,"id":24608298}]}]}
{"op":"mcm","clk":"989587343","pt":1580489470016,"mc":[{"id":"1.168096552","rc":[{"batl":[[0,4.6,8],[1,5.4,17.74],[2,5.5,5]],"ltp":0.0,"tv":0.0,"id":21580749}]}]}
{"op":"mcm","clk":"989590465","pt":1580489512894,"mc":[{"id":"1.168096552","rc":[{"batl":[[0,4.2,4],[1,4.6,8],[2,5.4,17.74]],"ltp":0.0,"tv":0.0,"id":21580749}]}]}
{"op":"mcm","clk":"989590886","pt":1580489518085,"mc":[{"id":"1.168096552","rc":[{"batl":[[0,4,4],[1,4.2,4],[2,4.6,8]],"ltp":0.0,"tv":0.0,"id":21580749}]}]}
{"op":"mcm","clk":"989591167","pt":1580489521479,"mc":[{"id":"1.168096552","rc":[{"batb":[[0,3.9,1.68],[1,3.85,1.99]],"ltp":0.0,"tv":0.0,"id":26640937},{"batb":[[0,3.9,1.68],[1,3.85,1.99]],"ltp":0.0,"tv":0.0,"id":27706761},{"batb":[[0,3.9,1.68],[1,3.85,1.99]],"ltp":0.0,"tv":0.0,"id":24608298}]}]}
{"op":"mcm","clk":"989611381","pt":1580489639460,"mc":[{"id":"1.168096552","rc":[{"batb":[[0,2.64,1.99],[1,2.62,4.49],[2,2.6,5.21]],"ltp":0.0,"tv":0.0,"id":52106}]}]}
{"op":"mcm","clk":"989611449","pt":1580489640494,"mc":[{"id":"1.168096552","rc":[{"batb":[[0,3.95,1.99],[1,3.9,1.68]],"ltp":0.0,"tv":0.0,"id":26640937},{"batb":[[0,3.4,1.99],[1,3.35,3.62],[2,3.3,3.62]],"ltp":0.0,"tv":0.0,"id":21580749},{"batb":[[0,3.95,1.99],[1,3.9,1.68]],"ltp":0.0,"tv":0.0,"id":27706761}]}]}
{"op":"mcm","clk":"989611510","pt":1580489641172,"mc":[{"id":"1.168096552","rc":[{"batb":[[0,3.95,1.99],[1,3.9,1.68]],"ltp":0.0,"tv":0.0,"id":24608298}]}]}
{"op":"mcm","clk":"989613164","pt":1580489663111,"mc":[{"id":"1.168096552","rc":[{"trd":[[2.62,0.44],[2.64,3.98]],"batb":[[0,2.62,4.27],[1,2.6,5.21],[2,2.1,3]],"ltp":2.62,"tv":4.41,"id":52106}],"tv":40.41}]}
{"op":"mcm","clk":"989613334","pt":1580489665390,"mc":[{"id":"1.168096552","rc":[{"trd":[[2.62,8.44]],"batb":[[0,2.6,5.48],[1,2.1,3],[2,2.08,53]],"ltp":2.62,"tv":12.42,"id":52106}],"tv":48.42}]}
{"op":"mcm","clk":"989613483","pt":1580489667306,"mc":[{"id":"1.168096552","rc":[{"trd":[[2.62,8.98]],"batb":[[0,2.6,5.21]],"ltp":2.62,"tv":12.95,"id":52106}],"tv":48.95}]}
{"op":"mcm","clk":"989613651","pt":1580489669381,"mc":[{"id":"1.168096552","rc":[{"trd":[[2.6,8]],"batb":[[0,2.6,1.21]],"ltp":2.6,"tv":20.96,"id":52106}],"tv":56.96}]}
{"op":"mcm","clk":"989613735","pt":1580489670484,"mc":[{"id":"1.168096552","rc":[{"batl":[[2,1000,3.18]],"ltp":2.6,"tv":20.96,"id":52106}]}]}
{"op":"mcm","clk":"989613781","pt":1580489671203,"mc":[{"id":"1.168096552","rc":[{"trd":[[2.6,9.97]],"batb":[[0,2.1,3.23],[1,2.08,53],[2,1.55,18.18]],"batl":[[2,1000,0.2]],"ltp":2.6,"tv":22.92,"id":52106}],"tv":58.92}]}
{"op":"mcm","clk":"989614045","pt":1580489674921,"mc":[{"id":"1.168096552","rc":[{"batb":[[0,3.95,2.41]],"ltp":0.0,"tv":0.0,"id":26640937},{"batb":[[0,3.4,2.47]],"ltp":0.0,"tv":0.0,"id":21580749},{"batb":[[0,3.95,2.41]],"ltp":0.0,"tv":0.0,"id":27706761},{"batb":[[0,2.12,1],[1,2.1,3],[2,2.08,53]],"ltp":2.6,"tv":22.92,"id":52106},{"batb":[[0,3.95,2.41]],"ltp":0.0,"tv":0.0,"id":24608298}]}]}
{"op":"mcm","clk":"989614327","pt":1580489679124,"mc":[{"id":"1.168096552","rc":[{"batb":[[0,2.12,4]],"ltp":2.6,"tv":22.92,"id":52106}]}]}
{"op":"mcm","clk":"989614464","pt":1580489680900,"mc":[{"id":"1.168096552","rc":[{"batb":[[0,2.14,18.66],[1,2.12,3.78],[2,2.1,3]],"ltp":2.6,"tv":22.92,"id":52106}]}]}
{"op":"mcm","clk":"989615086","pt":1580489688327,"mc":[{"id":"1.168096552","rc":[{"batb":[[0,2.36,5.24],[1,2.14,18.44],[2,2.12,3.78]],"ltp":2.6,"tv":22.92,"id":52106}]}]}
{"op":"mcm","clk":"989615295","pt":1580489691038,"mc":[{"id":"1.168096552","rc":[{"batb":[[0,2.38,3.23],[1,2.36,5.02],[2,2.14,18.44]],"ltp":2.6,"tv":22.92,"id":52106}]}]}
{"op":"mcm","clk":"989615826","pt":1580489698350,"mc":[{"id":"1.168096552","rc":[{"batb":[[0,2.4,2.29],[1,2.38,3],[2,2.36,5.02]],"batl":[[0,3.8,1.94]],"ltp":2.6,"tv":22.92,"id":52106}]}]}
{"op":"mcm","clk":"989615913","pt":1580489699341,"mc":[{"id":"1.168096552","rc":[{"batb":[[0,4,1.68],[1,3.95,2.41]],"ltp":0.0,"tv":0.0,"id":26640937},{"batb":[[0,3.45,1.68],[1,3.4,2.47],[2,3.35,1.93]],"ltp":0.0,"tv":0.0,"id":21580749},{"batb":[[0,4,1.68],[1,3.95,2.41]],"ltp":0.0,"tv":0.0,"id":27706761},{"batb":[[0,4,1.68],[1,3.95,2.41]],"ltp":0.0,"tv":0.0,"id":24608298}]}]}
{"op":"mcm","clk":"989616495","pt":1580489705975,"mc":[{"id":"1.168096552","rc":[{"batb":[[0,2.42,3.23],[1,2.4,2.06]],"ltp":2.6,"tv":22.92,"id":52106}]}]}
{"op":"mcm","clk":"989617221","pt":1580489714473,"mc":[{"id":"1.168096552","rc":[{"batb":[[0,4.1,1.99],[1,4,1.68],[2,3.5,2.24]],"ltp":0.0,"tv":0.0,"id":26640937},{"batb":[[0,3.5,1.99],[1,3.45,1.68],[2,3.35,2.42]],"ltp":0.0,"tv":0.0,"id":21580749}]}]}
{"op":"mcm","clk":"989617288","pt":1580489715358,"mc":[{"id":"1.168096552","rc":[{"batb":[[1,3.5,2.24],[2,3.45,3]],"ltp":0.0,"tv":0.0,"id":27706761},{"batb":[[0,4.1,1.99],[1,4,1.68],[2,3.5,2.24]],"ltp":0.0,"tv":0.0,"id":24608298}]}]}
{"op":"mcm","clk":"989617610","pt":1580489719504,"mc":[{"id":"1.168096552","rc":[{"batb":[[0,2.44,3.23]],"ltp":2.6,"tv":22.92,"id":52106}]}]}
{"op":"mcm","clk":"989617620","pt":1580489719554,"mc":[{"id":"1.168096552","rc":[{"batb":[[2,3.55,3.42]],"ltp":0.0,"tv":0.0,"id":26640937},{"batb":[[2,2.38,3]],"ltp":2.6,"tv":22.92,"id":52106},{"batb":[[2,3.55,3.42]],"ltp":0.0,"tv":0.0,"id":24608298}]}]}
{"op":"mcm","clk":"989618204","pt":1580489727008,"mc":[{"id":"1.168096552","rc":[{"batb":[[0,2.46,3.23]],"ltp":2.6,"tv":22.92,"id":52106}]}]}
{"op":"mcm","clk":"989618305","pt":1580489728475,"mc":[{"id":"1.168096552","rc":[{"trd":[[2.46,3.54],[2.6,10.42]],"batb":[[0,2.46,1.23]],"ltp":2.46,"tv":26.92,"id":52106}],"tv":62.92}]}
{"op":"mcm","clk":"989618374","pt":1580489729301,"mc":[{"id":"1.168096552","rc":[{"batl":[[2,1000,0.97]],"ltp":2.46,"tv":26.92,"id":52106}]}]}
{"op":"mcm","clk":"989618404","pt":1580489729713,"mc":[{"id":"1.168096552","rc":[{"trd":[[2.46,5.08]],"batb":[[0,2.4,2.52],[1,2.38,3],[2,2.36,5.02]],"batl":[[2,1000,0.2]],"ltp":2.46,"tv":28.46,"id":52106}],"tv":64.46}]}
{"op":"mcm","clk":"989618912","pt":1580489736499,"mc":[{"id":"1.168096552","rc":[{"batb":[[0,2.4,2.06],[2,2.36,5.48]],"ltp":2.46,"tv":28.46,"id":52106}]}]}
{"op":"mcm","clk":"989620200","pt":1580489753044,"mc":[{"id":"1.168096552","rc":[{"batb":[[1,2.36,5.48],[2,2.1,3]],"ltp":2.46,"tv":28.46,"id":52106}]}]}
{"op":"mcm","clk":"989625849","pt":1580489829233,"mc":[{"id":"1.168096552","rc":[{"batb":[[0,4.2,1.98],[1,4.1,1.99],[2,4,1.68]],"ltp":0.0,"tv":0.0,"id":26640937},{"batb":[[0,3.5,5.61]],"ltp":0.0,"tv":0.0,"id":21580749},{"batb":[[1,3.55,2.4],[2,3.5,1.82]],"ltp":0.0,"tv":0.0,"id":27706761},{"batb":[[0,4.2,1.98],[1,4.1,1.99],[2,4,1.68]],"ltp":0.0,"tv":0.0,"id":24608298}]}]}
{"op":"mcm","clk":"989627847","pt":1580489855331,"mc":[{"id":"1.168096552","rc":[{"batb":[[0,4.3,1.68],[1,4.2,1.98],[2,4.1,1.99]],"ltp":0.0,"tv":0.0,"id":26640937},{"batb":[[0,3.55,1.68],[1,3.5,5.61]],"ltp":0.0,"tv":0.0,"id":21580749},{"batb":[[0,2.36,5.48],[1,2.1,3],[2,2.08,53]],"ltp":2.46,"tv":28.46,"id":52106}]}]}
{"op":"mcm","clk":"989627897","pt":1580489855954,"mc":[{"id":"1.168096552","rc":[{"batb":[[0,3.6,2.1],[1,3.55,1.98]],"ltp":0.0,"tv":0.0,"id":27706761},{"batb":[[0,4.3,1.68],[1,4.2,1.98],[2,4.1,1.99]],"ltp":0.0,"tv":0.0,"id":24608298}]}]}
{"op":"mcm","clk":"989628188","pt":1580489858927,"mc":[{"id":"1.168096552","rc":[{"batb":[[2,3.4,3.48]],"ltp":0.0,"tv":0.0,"id":21580749},{"batb":[[1,3.55,4.98]],"ltp":0.0,"tv":0.0,"id":27706761}]}]}
{"op":"mcm","clk":"989628921","pt":1580489868357,"mc":[{"id":"1.168096552","rc":[{"batb":[[2,3.15,53]],"ltp":0.0,"tv":0.0,"id":27706761}]}]}
{"op":"mcm","clk":"989629097","pt":1580489870563,"mc":[{"id":"1.168096552","rc":[{"batb":[[0,3.6,3.85]],"ltp":0.0,"tv":0.0,"id":27706761}]}]}
{"op":"mcm","clk":"989629909","pt":1580489881465,"mc":[{"id":"1.168096552","rc":[{"batb":[[0,4.4,1.99],[1,4.3,1.68],[2,4.2,1.98]],"ltp":0.0,"tv":0.0,"id":26640937},{"batb":[[0,3.6,1.99],[1,3.55,1.68],[2,3.5,3.62]],"ltp":0.0,"tv":0.0,"id":21580749}]}]}
{"op":"mcm","clk":"989629979","pt":1580489882377,"mc":[{"id":"1.168096552","rc":[{"batb":[[0,4,1.99],[1,3.6,3.85],[2,3.55,4.98]],"ltp":0.0,"tv":0.0,"id":27706761},{"batb":[[0,4.4,1.99],[1,4.3,1.68],[2,4.2,1.98]],"ltp":0.0,"tv":0.0,"id":24608298}]}]}
{"op":"mcm","clk":"989631346","pt":1580489898413,"mc":[{"id":"1.168096552","rc":[{"batb":[[1,3.6,2.1]],"ltp":0.0,"tv":0.0,"id":27706761}]}]}
{"op":"mcm","clk":"989631412","pt":1580489899093,"mc":[{"id":"1.168096552","rc":[{"trd":[[3.05,12.01]],"batb":[[0,3,3.28],[1,2.02,4.46],[2,1.58,53]],"ltp":3.05,"tv":48.0,"id":18286408}],"tv":76.46}]}
{"op":"mcm","clk":"989631581","pt":1580489901395,"mc":[{"id":"1.168096552","rc":[{"batb":[[0,2.88,3.28]],"ltp":3.05,"tv":48.0,"id":18286408},{"batb":[[1,3.65,2.13],[2,3.6,1.68]],"ltp":0.0,"tv":0.0,"id":27706761},{"batb":[[0,2.36,6.17]],"ltp":2.46,"tv":28.46,"id":52106}]}]}
{"op":"mcm","clk":"989632975","pt":1580489920694,"mc":[{"id":"1.168096552","rc":[{"batl":[[0,3.2,4],[1,3.3,10],[2,3.35,33]],"ltp":3.05,"tv":48.0,"id":18286408}]}]}
{"op":"mcm","clk":"989633800","pt":1580489931833,"mc":[{"id":"1.168096552","rc":[{"batl":[[0,4,17]],"ltp":0.0,"tv":0.0,"id":21580749}]}]}
{"op":"mcm","clk":"989635860","pt":1580489960049,"mc":[{"id":"1.168096552","rc":[{"batb":[[2,1.59,3]],"ltp":3.05,"tv":48.0,"id":18286408}]}]}
{"op":"mcm","clk":"989636913","pt":1580489972490,"mc":[{"id":"1.168096552","rc":[{"batb":[[2,1.6,1.93]],"ltp":3.05,"tv":48.0,"id":18286408},{"batb":[[1,2.12,2.29],[2,2.1,3]],"ltp":2.46,"tv":28.46,"id":52106}]}]}
{"op":"mcm","clk":"989637012","pt":1580489973485,"mc":[{"id":"1.168096552","rc":[{"batb":[[1,4.2,1.98],[2,4,3]],"ltp":0.0,"tv":0.0,"id":26640937},{"batb":[[0,3.65,1.68],[1,3.6,1.99]],"ltp":0.0,"tv":0.0,"id":21580749},{"batl":[[0,3.8,2.44]],"ltp":2.46,"tv":28.46,"id":52106}]}]}
{"op":"mcm","clk":"989637089","pt":1580489974276,"mc":[{"id":"1.168096552","rc":[{"batb":[[0,4.5,1.68],[1,4.4,1.99],[2,4.2,1.98]],"ltp":0.0,"tv":0.0,"id":26640937},{"batb":[[0,3.7,1.99],[1,3.65,1.68]],"ltp":0.0,"tv":0.0,"id":21580749},{"batb":[[0,4.1,1.68],[1,4,1.99],[2,3.65,2.13]],"ltp":0.0,"tv":0.0,"id":27706761},{"batb":[[0,4.5,1.68],[1,4.4,1.99]],"ltp":0.0,"tv":0.0,"id":24608298}]}]}
{"op":"mcm","clk":"989640445","pt":1580490011036,"mc":[{"id":"1.168096552","rc":[{"batb":[[0,4.5,2.05]],"ltp":0.0,"tv":0.0,"id":26640937},{"batb":[[0,3.7,2.44]],"ltp":0.0,"tv":0.0,"id":21580749},{"batb":[[0,4.5,2.05]],"ltp":0.0,"tv":0.0,"id":24608298}]}]}
{"op":"mcm","clk":"989641219","pt":1580490019277,"mc":[{"id":"1.168096552","rc":[{"batb":[[0,4.6,1.98],[1,4.5,2.05],[2,4.4,1.99]],"ltp":0.0,"tv":0.0,"id":26640937},{"batb":[[0,3.7,6.05],[2,3.4,3]],"ltp":0.0,"tv":0.0,"id":21580749},{"batb":[[0,4.1,3.67]],"ltp":0.0,"tv":0.0,"id":27706761},{"batb":[[0,4.6,1.98],[1,4.5,2.05],[2,4.4,1.99]],"ltp":0.0,"tv":0.0,"id":24608298}]}]}
{"op":"mcm","clk":"989642496","pt":1580490033665,"mc":[{"id":"1.168096552","rc":[{"batb":[[0,2.36,8.96]],"ltp":2.46,"tv":28.46,"id":52106}]}]}
{"op":"mcm","clk":"989643932","pt":1580490049391,"mc":[{"id":"1.168096552","rc":[{"batb":[[2,3.15,53.42]],"ltp":0.0,"tv":0.0,"id":27706761}]}]}
{"op":"mcm","clk":"989644192","pt":1580490052482,"mc":[{"id":"1.168096552","rc":[{"batb":[[2,3.35,1.93]],"ltp":0.0,"tv":0.0,"id":21580749},{"batb":[[0,4.2,1.43],[1,4.1,3.67],[2,4,1.99]],"ltp":0.0,"tv":0.0,"id":27706761},{"batb":[[2,2.08,53]],"ltp":2.46,"tv":28.46,"id":52106}]}]}
{"op":"mcm","clk":"989644829","pt":1580490059514,"mc":[{"id":"1.168096552","rc":[{"batb":[[0,4.7,1.99],[1,4.6,1.98],[2,4.5,2.05]],"ltp":0.0,"tv":0.0,"id":26640937},{"batb":[[2,3.15,53.42]],"ltp":0.0,"tv":0.0,"id":27706761}]}]}
{"op":"mcm","clk":"989644908","pt":1580490060037,"mc":[{"id":"1.168096552","rc":[{"batb":[[0,4.3,1.99],[1,4.2,1.43],[2,4.1,3.67]],"ltp":0.0,"tv":0.0,"id":27706761},{"batb":[[0,4.7,1.99],[1,4.6,1.98],[2,4.5,2.05]],"ltp":0.0,"tv":0.0,"id":24608298}]}]}
{"op":"mcm","clk":"989645366","pt":1580490064220,"mc":[{"id":"1.168096552","rc":[{"batb":[[0,4.8,1.98],[1,4.7,1.99]],"ltp":0.0,"tv":0.0,"id":26640937},{"batb":[[0,4.4,1.98],[1,4.3,1.99],[2,4.2,1.43]],"ltp":0.0,"tv":0.0,"id":27706761},{"batb":[[0,4.8,1.98],[1,4.7,1.99]],"ltp":0.0,"tv":0.0,"id":24608298}]}]}
{"op":"mcm","clk":"989653530","pt":1580490153333,"mc":[{"id":"1.168096552","rc":[{"batb":[[0,4.9,1.99],[1,4.8,1.98]],"ltp":0.0,"tv":0.0,"id":26640937},{"batb":[[0,4.5,1.99],[1,4.4,1.98]],"ltp":0.0,"tv":0.0,"id":27706761}]}]}
{"op":"mcm","clk":"989653576","pt":1580490153807,"mc":[{"id":"1.168096552","rc":[{"batb":[[0,4.9,1.99],[1,4.8,1.98]],"ltp":0.0,"tv":0.0,"id":24608298}]}]}
{"op":"mcm","clk":"989654487","pt":1580490163936,"mc":[{"id":"1.168096552","rc":[{"batb":[[0,5,1.98],[1,4.9,1.99]],"ltp":0.0,"tv":0.0,"id":26640937},{"batb":[[0,4.6,1.98],[1,4.5,1.99]],"ltp":0.0,"tv":0.0,"id":27706761},{"batb":[[0,5,1.98],[1,4.9,1.99]],"ltp":0.0,"tv":0.0,"id":24608298}]}]}
{"op":"mcm","clk":"989655046","pt":1580490170853,"mc":[{"id":"1.168096552","rc":[{"batb":[[0,5.1,1.11],[1,5,1.98],[2,4.9,1.99]],"ltp":0.0,"tv":0.0,"id":26640937},{"batb":[[0,5.1,1.11],[1,5,1.98],[2,4.9,1.99]],"ltp":0.0,"tv":0.0,"id":24608298}]}]}
{"op":"mcm","clk":"989655319","pt":1580490174327,"mc":[{"id":"1.168096552","rc":[{"batb":[[0,2.9,1.96],[1,2.88,3],[2,2.02,4.46]],"ltp":3.05,"tv":48.0,"id":18286408},{"batb":[[0,2.38,2.73],[1,2.36,8.27]],"ltp":2.46,"tv":28.46,"id":52106}]}]}
{"op":"mcm","clk":"989655417","pt":1580490175378,"mc":[{"id":"1.168096552","rc":[{"batb":[[0,5.1,2.79]],"ltp":0.0,"tv":0.0,"id":26640937},{"batb":[[0,3.75,1.68],[1,3.7,6.05]],"ltp":0.0,"tv":0.0,"id":21580749},{"batb":[[0,4.7,1.68],[1,4.6,1.98],[2,4.5,1.99]],"ltp":0.0,"tv":0.0,"id":27706761},{"batb":[[0,5.1,2.79]],"ltp":0.0,"tv":0.0,"id":24608298}]}]}
{"op":"mcm","clk":"989655652","pt":1580490178270,"mc":[{"id":"1.168096552","rc":[{"batb":[[0,5.2,1.98],[1,5.1,2.79]],"ltp":0.0,"tv":0.0,"id":26640937},{"batb":[[0,2.38,5.52],[1,2.36,5.48]],"ltp":2.46,"tv":28.46,"id":52106},{"batb":[[0,5.2,1.98],[1,5.1,2.79]],"ltp":0.0,"tv":0.0,"id":24608298}]}]}
{"op":"mcm","clk":"989657698","pt":1580490199478,"mc":[{"id":"1.168096552","rc":[{"batb":[[0,5.2,2.3],[1,5.1,1.68]],"ltp":0.0,"tv":0.0,"id":26640937},{"batb":[[0,4.7,2.03]],"ltp":0.0,"tv":0.0,"id":27706761},{"batb":[[0,5.2,2.3],[1,5.1,1.68]],"ltp":0.0,"tv":0.0,"id":24608298}]}]}
{"op":"mcm","clk":"989657839","pt":1580490200892,"mc":[{"id":"1.168096552","rc":[{"batb":[[0,5.3,1.06],[1,5.2,2.3],[2,5.1,1.68]],"ltp":0.0,"tv":0.0,"id":26640937},{"batb":[[0,5.3,1.06],[1,5.2,2.3],[2,5.1,1.68]],"ltp":0.0,"tv":0.0,"id":24608298}]}]}
{"op":"mcm","clk":"989658563","pt":1580490208324,"mc":[{"id":"1.168096552","rc":[{"batb":[[0,4.8,1.98],[1,4.7,2.03]],"ltp":0.0,"tv":0.0,"id":27706761}]}]}
{"op":"mcm","clk":"989660533","pt":1580490229716,"mc":[{"id":"1.168096552","rc":[{"batl":[[0,4,4],[2,4.4,13]],"ltp":0.0,"tv":0.0,"id":21580749}]}]}
{"op":"mcm","clk":"989661651","pt":1580490241350,"mc":[{"id":"1.168096552","rc":[{"batb":[[0,3.8,1.99],[1,3.75,1.68],[2,3.7,4.06]],"ltp":0.0,"tv":0.0,"id":21580749}]}]}
{"op":"mcm","clk":"989661727","pt":1580490242147,"mc":[{"id":"1.168096552","rc":[{"batb":[[0,5.4,1.99],[1,5.3,1.06],[2,5.2,2.3]],"ltp":0.0,"tv":0.0,"id":26640937},{"batb":[[0,4.9,1.99],[1,4.8,1.98],[2,4.7,2.03]],"ltp":0.0,"tv":0.0,"id":27706761}]}]}
{"op":"mcm","clk":"989661779","pt":1580490242623,"mc":[{"id":"1.168096552","rc":[{"batb":[[0,5.4,1.99],[1,5.3,1.06],[2,5.2,2.3]],"ltp":0.0,"tv":0.0,"id":24608298}]}]}
{"op":"mcm","clk":"989662679","pt":1580490251665,"mc":[{"id":"1.168096552","rc":[{"batb":[[0,5.5,1.98],[1,5.4,1.99],[2,5.3,1.06]],"ltp":0.0,"tv":0.0,"id":26640937},{"batb":[[0,3.8,5.61],[2,3.35,2.38]],"ltp":0.0,"tv":0.0,"id":21580749},{"batb":[[0,5,1.98],[1,4.9,1.99]],"ltp":0.0,"tv":0.0,"id":27706761},{"batb":[[0,5.5,1.98],[1,5.4,1.99],[2,5.3,1.06]],"ltp":0.0,"tv":0.0,"id":24608298}]}]}
{"op":"mcm","clk":"989663313","pt":1580490258764,"mc":[{"id":"1.168096552","rc":[{"batb":[[2,5.1,2]],"ltp":0.0,"tv":0.0,"id":26640937},{"batb":[[2,5.1,2]],"ltp":0.0,"tv":0.0,"id":24608298}]}]}
{"op":"mcm","clk":"989663500","pt":1580490261072,"mc":[{"id":"1.168096552","rc":[{"batb":[[0,5.5,2.97]],"ltp":0.0,"tv":0.0,"id":26640937},{"batb":[[0,5.1,1.11],[1,5,1.98],[2,4.9,1.99]],"ltp":0.0,"tv":0.0,"id":27706761},{"batb":[[0,5.5,2.97]],"ltp":0.0,"tv":0.0,"id":24608298}]}]}
{"op":"mcm","clk":"989669089","pt":1580490322454,"mc":[{"id":"1.168096552","rc":[{"batb":[[0,5.7,1.99],[1,5.5,2.97]],"ltp":0.0,"tv":0.0,"id":26640937},{"batb":[[0,5.2,1.99],[1,5.1,1.11],[2,5,1.98]],"ltp":0.0,"tv":0.0,"id":27706761},{"batb":[[0,5.7,1.99],[1,5.5,2.97]],"ltp":0.0,"tv":0.0,"id":24608298}]}]}
{"op":"mcm","clk":"989669600","pt":1580490327567,"mc":[{"id":"1.168096552","rc":[{"batl":[[0,3.15,2],[1,3.2,4],[2,3.3,10]],"ltp":3.05,"tv":48.0,"id":18286408}]}]}
{"op":"mcm","clk":"989671565","pt":1580490348489,"mc":[{"id":"1.168096552","rc":[{"batb":[[1,5.5,1.98]],"ltp":0.0,"tv":0.0,"id":26640937},{"batb":[[1,5,1.98],[2,4.7,2.03]],"ltp":0.0,"tv":0.0,"id":27706761}]}]}
{"op":"mcm","clk":"989671588","pt":1580490348702,"mc":[{"id":"1.168096552","rc":[{"batb":[[1,5.5,1.98]],"ltp":0.0,"tv":0.0,"id":24608298}]}]}
{"op":"mcm","clk":"989671815","pt":1580490351062,"mc":[{"id":"1.168096552","rc":[{"batb":[[0,5.8,2.93],[1,5.7,1.99]],"ltp":0.0,"tv":0.0,"id":26640937},{"batb":[[0,5.3,3.05],[1,5.2,1.99]],"ltp":0.0,"tv":0.0,"id":27706761},{"batb":[[0,5.8,2.93],[1,5.7,1.99]],"ltp":0.0,"tv":0.0,"id":24608298}]}]}
{"op":"mcm","clk":"989673496","pt":1580490369192,"mc":[{"id":"1.168096552","rc":[{"batb":[[2,5.1,1.68]],"ltp":0.0,"tv":0.0,"id":26640937},{"batb":[[2,4.7,1.68]],"ltp":0.0,"tv":0.0,"id":27706761},{"batb":[[2,5.1,1.68]],"ltp":0.0,"tv":0.0,"id":24608298}]}]}
{"op":"mcm","clk":"989673680","pt":1580490371506,"mc":[{"id":"1.168096552","rc":[{"batb":[[0,2.9,4.96]],"ltp":3.05,"tv":48.0,"id":18286408}]}]}
{"op":"mcm","clk":"989673822","pt":1580490373290,"mc":[{"id":"1.168096552","rc":[{"trd":[[2.92,4]],"batb":[[0,2.92,1],[1,2.9,1.96],[2,2.88,3]],"ltp":2.92,"tv":52.0,"id":18286408}],"tv":80.46}]}
{"op":"mcm","clk":"989674320","pt":1580490379510,"mc":[{"id":"1.168096552","rc":[{"batb":[[2,2.02,4.46]],"ltp":2.92,"tv":52.0,"id":18286408}]}]}
{"op":"mcm","clk":"989674328","pt":1580490379611,"mc":[{"id":"1.168096552","rc":[{"batb":[[2,2.74,3]],"ltp":2.92,"tv":52.0,"id":18286408}]}]}
{"op":"mcm","clk":"989674522","pt":1580490382010,"mc":[{"id":"1.168096552","rc":[{"batb":[[0,5.8,3.21]],"ltp":0.0,"tv":0.0,"id":26640937},{"batb":[[0,5.3,3.35]],"ltp":0.0,"tv":0.0,"id":27706761},{"batb":[[0,5.8,3.21]],"ltp":0.0,"tv":0.0,"id":24608298}]}]}
{"op":"mcm","clk":"989674780","pt":1580490385308,"mc":[{"id":"1.168096552","rc":[{"batb":[[0,2.9,1.96],[1,2.74,3],[2,2.02,4.46]],"batl":[[0,2.92,2],[1,3.15,2],[2,3.2,4]],"ltp":2.92,"tv":52.0,"id":18286408}]}]}
{"op":"mcm","clk":"989674959","pt":1580490387406,"mc":[{"id":"1.168096552","rc":[{"trd":[[2.9,3.92]],"batb":[[0,2.74,3],[1,2.02,4.46],[2,1.58,53]],"batl":[[0,3.15,2.05],[1,3.2,4],[2,3.3,10]],"ltp":2.9,"tv":55.92,"id":18286408}],"tv":84.38}]}
{"op":"mcm","clk":"989675123","pt":1580490389515,"mc":[{"id":"1.168096552","rc":[{"batb":[[0,2.74,3.03],[1,2.04,3],[2,2.02,4.46]],"batl":[[0,3.15,2]],"ltp":2.9,"tv":55.92,"id":18286408}]}]}
{"op":"mcm","clk":"989675174","pt":1580490390146,"mc":[{"id":"1.168096552","rc":[{"trd":[[2.74,0.12]],"batb":[[0,2.74,2.97]],"ltp":2.74,"tv":56.04,"id":18286408}],"tv":84.5}]}
{"op":"mcm","clk":"989675908","pt":1580490399128,"mc":[{"id":"1.168096552","rc":[{"batb":[[1,2.62,3]],"ltp":2.74,"tv":56.04,"id":18286408}]}]}
{"op":"mcm","clk":"989676659","pt":1580490408341,"mc":[{"id":"1.168096552","rc":[{"batb":[[0,5.8,2.26]],"ltp":0.0,"tv":0.0,"id":26640937},{"batb":[[0,5.3,2.29]],"ltp":0.0,"tv":0.0,"id":27706761},{"batb":[[0,5.8,2.26]],"ltp":0.0,"tv":0.0,"id":24608298}]}]}
{"op":"mcm","clk":"989676814","pt":1580490410373,"mc":[{"id":"1.168096552","rc":[{"batb":[[0,6,1.99],[1,5.8,2.26]],"ltp":0.0,"tv":0.0,"id":26640937}]}]}
{"op":"mcm","clk":"989676905","pt":1580490411475,"mc":[{"id":"1.168096552","rc":[{"batb":[[1,5.9,1.2],[2,5.8,1.98]],"ltp":0.0,"tv":0.0,"id":26640937},{"batb":[[0,5.5,1.99],[1,5.3,2.29]],"ltp":0.0,"tv":0.0,"id":27706761},{"batb":[[0,5.9,1.2],[1,5.8,1.98],[2,5.7,1.99]],"ltp":0.0,"tv":0.0,"id":24608298}]}]}
{"op":"mcm","clk":"989676936","pt":1580490411765,"mc":[{"id":"1.168096552","rc":[{"batb":[[1,5.4,1.34],[2,5.3,1.98]],"ltp":0.0,"tv":0.0,"id":27706761},{"batb":[[0,6,1.99],[1,5.9,1.2],[2,5.8,1.98]],"ltp":0.0,"tv":0.0,"id":24608298}]}]}
{"op":"mcm","clk":"989678207","pt":1580490426172,"mc":[{"id":"1.168096552","rc":[{"batb":[[0,2.64,2.97]],"ltp":2.74,"tv":56.04,"id":18286408},{"batb":[[0,6.2,1.98],[1,6,1.99],[2,5.9,1.2]],"ltp":0.0,"tv":0.0,"id":26640937},{"batb":[[0,5.6,1.98],[1,5.5,1.99],[2,5.4,1.34]],"ltp":0.0,"tv":0.0,"id":27706761},{"batb":[[0,6.2,1.98],[1,6,1.99],[2,5.9,1.2]],"ltp":0.0,"tv":0.0,"id":24608298}]}]}
{"op":"mcm","clk":"989679313","pt":1580490438686,"mc":[{"id":"1.168096552","rc":[{"batb":[[2,5.1,1.96]],"ltp":0.0,"tv":0.0,"id":26640937},{"batb":[[2,4.7,1.99]],"ltp":0.0,"tv":0.0,"id":27706761},{"batb":[[2,5.1,1.96]],"ltp":0.0,"tv":0.0,"id":24608298}]}]}
{"op":"mcm","clk":"989679503","pt":1580490440876,"mc":[{"id":"1.168096552","rc":[{"batb":[[0,6.2,2.83]],"ltp":0.0,"tv":0.0,"id":26640937},{"batb":[[0,5.6,2.96]],"ltp":0.0,"tv":0.0,"id":27706761},{"batb":[[0,6.2,2.83]],"ltp":0.0,"tv":0.0,"id":24608298}]}]}
{"op":"mcm","clk":"989695008","pt":1580490508454,"mc":[{"id":"1.168096552","rc":[{"batb":[[0,6.6,1.99],[1,6.2,2.83]],"ltp":0.0,"tv":0.0,"id":26640937}]}]}
{"op":"mcm","clk":"989695059","pt":1580490509173,"mc":[{"id":"1.168096552","rc":[{"batb":[[0,5.8,1.99],[1,5.6,2.96]],"ltp":0.0,"tv":0.0,"id":27706761},{"batb":[[0,6.6,1.99],[1,6.2,2.83]],"ltp":0.0,"tv":0.0,"id":24608298}]}]}
{"op":"mcm","clk":"989696009","pt":1580490520671,"mc":[{"id":"1.168096552","rc":[{"batb":[[0,2.74,20],[1,2.64,2.97],[2,2.62,3]],"ltp":2.74,"tv":56.04,"id":18286408}]}]}
{"op":"mcm","clk":"989696772","pt":1580490528394,"mc":[{"id":"1.168096552","rc":[{"batb":[[1,6.2,1.98]],"ltp":0.0,"tv":0.0,"id":26640937}]}]}
{"op":"mcm","clk":"989696848","pt":1580490529131,"mc":[{"id":"1.168096552","rc":[{"batb":[[1,5.6,1.98]],"ltp":0.0,"tv":0.0,"id":27706761},{"batb":[[1,6.2,1.98]],"ltp":0.0,"tv":0.0,"id":24608298}]}]}
{"op":"mcm","clk":"989696987","pt":1580490530704,"mc":[{"id":"1.168096552","rc":[{"batb":[[0,2.76,2.59],[1,2.74,20],[2,2.64,2.97]],"ltp":2.74,"tv":56.04,"id":18286408},{"batb":[[0,6.6,2.77]],"ltp":0.0,"tv":0.0,"id":26640937},{"batb":[[0,5.8,2.92]],"ltp":0.0,"tv":0.0,"id":27706761},{"batb":[[0,6.6,2.77]],"ltp":0.0,"tv":0.0,"id":24608298}]}]}
{"op":"mcm","clk":"989697421","pt":1580490535421,"mc":[{"id":"1.168096552","rc":[{"batb":[[2,2.62,3]],"ltp":2.74,"tv":56.04,"id":18286408},{"batb":[[1,5.1,1.96],[2,3.15,53]],"ltp":0.0,"tv":0.0,"id":26640937},{"batb":[[1,4.7,1.99],[2,3.15,53]],"ltp":0.0,"tv":0.0,"id":27706761},{"batb":[[1,5.1,1.96],[2,3.15,53]],"ltp":0.0,"tv":0.0,"id":24608298}]}]}
{"op":"mcm","clk":"989697432","pt":1580490535529,"mc":[{"id":"1.168096552","rc":[{"batb":[[0,2.76,5.56]],"ltp":2.74,"tv":56.04,"id":18286408},{"batb":[[0,6.8,2.77],[1,6.6,1.99],[2,5.1,1.96]],"ltp":0.0,"tv":0.0,"id":26640937},{"batb":[[0,5.9,2.91],[1,5.8,1.99],[2,4.7,1.99]],"ltp":0.0,"tv":0.0,"id":27706761},{"batb":[[0,6.8,2.77],[1,6.6,1.99],[2,5.1,1.96]],"ltp":0.0,"tv":0.0,"id":24608298}]}]}
{"op":"mcm","clk":"989698508","pt":1580490546230,"mc":[{"id":"1.168096552","rc":[{"trd":[[4,8]],"batl":[[0,4.2,4],[1,4.4,13],[2,4.6,8]],"ltp":4.0,"tv":8.0,"id":21580749}],"tv":92.5}]}
{"op":"mcm","clk":"989698733","pt":1580490548634,"mc":[{"id":"1.168096552","rc":[{"batb":[[1,3.75,4.68]],"ltp":4.0,"tv":8.0,"id":21580749}]}]}
{"op":"mcm","clk":"989700153","pt":1580490563634,"mc":[{"id":"1.168096552","rc":[{"batb":[[2,5.1,1.68]],"ltp":0.0,"tv":0.0,"id":26640937},{"batb":[[2,4.7,1.68]],"ltp":0.0,"tv":0.0,"id":27706761},{"batb":[[2,5.1,1.68]],"ltp":0.0,"tv":0.0,"id":24608298}]}]}
{"op":"mcm","clk":"989701269","pt":1580490575959,"mc":[{"id":"1.168096552","rc":[{"batb":[[0,5.9,3.18]],"ltp":0.0,"tv":0.0,"id":27706761}]}]}
{"op":"mcm","clk":"989702382","pt":1580490588484,"mc":[{"id":"1.168096552","rc":[{"batb":[[0,5.9,2.26]],"ltp":0.0,"tv":0.0,"id":27706761}]}]}
{"op":"mcm","clk":"989702624","pt":1580490590880,"mc":[{"id":"1.168096552","rc":[{"batb":[[0,6,1.18],[1,5.9,1.98],[2,5.8,1.99]],"ltp":0.0,"tv":0.0,"id":27706761}]}]}
{"op":"mcm","clk":"989702767","pt":1580490592501,"mc":[{"id":"1.168096552","rc":[{"batb":[[0,7,1.99],[1,6.8,2.77]],"ltp":0.0,"tv":0.0,"id":26640937},{"batb":[[0,6.2,1.99],[1,6,1.18],[2,5.9,1.98]],"ltp":0.0,"tv":0.0,"id":27706761},{"batb":[[1,5.1,1.68],[2,3.15,53]],"ltp":0.0,"tv":0.0,"id":24608298}]}]}
{"op":"mcm","clk":"989702775","pt":1580490592601,"mc":[{"id":"1.168096552","rc":[{"batb":[[0,7,1.99],[1,6.8,2.77],[2,5.1,1.68]],"ltp":0.0,"tv":0.0,"id":24608298}]}]}
{"op":"mcm","clk":"989705233","pt":1580490618722,"mc":[{"id":"1.168096552","rc":[{"batb":[[1,5.9,2.26],[2,4.7,1.68]],"ltp":0.0,"tv":0.0,"id":27706761}]}]}
{"op":"mcm","clk":"989705467","pt":1580490621021,"mc":[{"id":"1.168096552","rc":[{"batb":[[0,6.2,2.83]],"ltp":0.0,"tv":0.0,"id":27706761}]}]}
{"op":"mcm","clk":"989709051","pt":1580490658176,"mc":[{"id":"1.168096552","rc":[{"batb":[[0,7.2,1.98],[1,7,1.99],[2,5.1,2.46]],"ltp":0.0,"tv":0.0,"id":26640937},{"batb":[[0,6.4,2.83],[1,6.2,1.99],[2,4.7,1.96]],"ltp":0.0,"tv":0.0,"id":27706761},{"batb":[[0,7.2,1.98],[1,7,1.99],[2,5.1,2.46]],"ltp":0.0,"tv":0.0,"id":24608298}]}]}
{"op":"mcm","clk":"989710887","pt":1580490676490,"mc":[{"id":"1.168096552","rc":[{"batb":[[0,7.4,1.99],[1,7.2,1.98]],"ltp":0.0,"tv":0.0,"id":26640937},{"batb":[[0,6.6,1.99],[1,6.4,2.83]],"ltp":0.0,"tv":0.0,"id":27706761}]}]}
{"op":"mcm","clk":"989710944","pt":1580490677068,"mc":[{"id":"1.168096552","rc":[{"batb":[[0,7.4,1.99],[1,7.2,1.98]],"ltp":0.0,"tv":0.0,"id":24608298}]}]}
{"op":"mcm","clk":"989711099","pt":1580490678584,"mc":[{"id":"1.168096552","rc":[{"batb":[[1,6.4,1.98]],"ltp":0.0,"tv":0.0,"id":27706761}]}]}
{"op":"mcm","clk":"989711368","pt":1580490680995,"mc":[{"id":"1.168096552","rc":[{"batb":[[0,6.6,2.77]],"ltp":0.0,"tv":0.0,"id":27706761}]}]}
{"op":"mcm","clk":"989718536","pt":1580490750477,"mc":[{"id":"1.168096552","rc":[{"batb":[[1,5.1,2.46],[2,3.15,53]],"ltp":0.0,"tv":0.0,"id":26640937},{"batb":[[1,4.7,1.96],[2,3.15,53]],"ltp":0.0,"tv":0.0,"id":27706761},{"batb":[[1,5.1,2.46],[2,3.15,53]],"ltp":0.0,"tv":0.0,"id":24608298}]}]}
{"op":"mcm","clk":"989718542","pt":1580490750582,"mc":[{"id":"1.168096552","rc":[{"batb":[[0,7.6,1.98],[1,7.4,1.99],[2,5.1,2.46]],"ltp":0.0,"tv":0.0,"id":26640937},{"batb":[[0,6.8,2.77],[1,6.6,1.99],[2,4.7,1.96]],"ltp":0.0,"tv":0.0,"id":27706761},{"batb":[[0,7.6,1.98],[1,7.4,1.99],[2,5.1,2.46]],"ltp":0.0,"tv":0.0,"id":24608298}]}]}
{"op":"mcm","clk":"989720670","pt":1580490771482,"mc":[{"id":"1.168096552","rc":[{"batb":[[1,5.1,2.46],[2,3.15,53]],"ltp":0.0,"tv":0.0,"id":26640937}]}]}
{"op":"mcm","clk":"989720783","pt":1580490772482,"mc":[{"id":"1.168096552","rc":[{"batb":[[0,7.8,1.99],[1,7.6,1.98],[2,5.1,2.46]],"ltp":0.0,"tv":0.0,"id":26640937},{"batb":[[1,4.7,1.96],[2,3.15,53]],"ltp":0.0,"tv":0.0,"id":27706761},{"batb":[[0,7.8,1.99],[1,7.6,1.98]],"ltp":0.0,"tv":0.0,"id":24608298}]}]}
{"op":"mcm","clk":"989724990","pt":1580490810447,"mc":[{"id":"1.168096552","rc":[{"batl":[[0,4.1,2.83],[1,4.2,4],[2,4.4,13]],"ltp":4.0,"tv":8.0,"id":21580749}]}]}
{"op":"mcm","clk":"989728507","pt":1580490844965,"mc":[{"id":"1.168096552","rc":[{"batl":[[2,4.3,10]],"ltp":4.0,"tv":8.0,"id":21580749}]}]}
{"op":"mcm","clk":"989728619","pt":1580490846169,"mc":[{"id":"1.168096552","rc":[{"batb":[[0,8,1.98],[1,7.8,1.99]],"ltp":0.0,"tv":0.0,"id":26640937},{"batb":[[0,6,1.06],[1,4.8,1.98],[2,4.7,1.68]],"ltp":0.0,"tv":0.0,"id":27706761},{"batb":[[0,8,1.98],[1,7.8,1.99]],"ltp":0.0,"tv":0.0,"id":24608298}]}]}
{"op":"mcm","clk":"989729210","pt":1580490851377,"mc":[{"id":"1.168096552","rc":[{"batl":[[2,4.3,20]],"ltp":4.0,"tv":8.0,"id":21580749}]}]}
{"op":"mcm","clk":"989729442","pt":1580490853372,"mc":[{"id":"1.168096552","rc":[{"batl":[[2,4.3,30]],"ltp":4.0,"tv":8.0,"id":21580749}]}]}
{"op":"mcm","clk":"989730090","pt":1580490859304,"mc":[{"id":"1.168096552","rc":[{"batb":[[0,8.2,1.99],[1,8,1.98]],"ltp":0.0,"tv":0.0,"id":26640937},{"batb":[[0,8.2,1.99],[1,8,1.98]],"ltp":0.0,"tv":0.0,"id":24608298}]}]}
{"op":"mcm","clk":"989730186","pt":1580490860193,"mc":[{"id":"1.168096552","rc":[{"batl":[[2,4.3,40]],"ltp":4.0,"tv":8.0,"id":21580749}]}]}
{"op":"mcm","clk":"989730353","pt":1580490861913,"mc":[{"id":"1.168096552","rc":[{"batl":[[2,4.3,50]],"ltp":4.0,"tv":8.0,"id":21580749}]}]}
{"op":"mcm","clk":"989730862","pt":1580490866307,"mc":[{"id":"1.168096552","rc":[{"batl":[[2,4.3,60]],"ltp":4.0,"tv":8.0,"id":21580749}]}]}
{"op":"mcm","clk":"989731450","pt":1580490871613,"mc":[{"id":"1.168096552","rc":[{"batl":[[2,4.3,70]],"ltp":4.0,"tv":8.0,"id":21580749}]}]}
{"op":"mcm","clk":"989732403","pt":1580490880520,"mc":[{"id":"1.168096552","rc":[{"trd":[[4.1,5.66],[4.2,8],[4.3,138.34]],"batl":[[0,4.4,13.83],[1,4.6,8],[2,5.4,4.74]],"ltp":4.3,"tv":160.0,"id":21580749}],"tv":244.5}]}
{"op":"mcm","clk":"989732824","pt":1580490884635,"mc":[{"id":"1.168096552","rc":[{"batl":[[0,4.3,9.83],[1,4.4,13],[2,4.6,8]],"ltp":4.3,"tv":160.0,"id":21580749}]}]}
{"op":"mcm","clk":"989733293","pt":1580490888719,"mc":[{"id":"1.168096552","rc":[{"batb":[[0,3.85,3],[1,3.8,5.61],[2,3.75,1.68]],"ltp":4.3,"tv":160.0,"id":21580749}]}]}
{"op":"mcm","clk":"989733436","pt":1580490890026,"mc":[{"id":"1.168096552","rc":[{"batb":[[0,4,21],[1,3.85,3],[2,3.8,5.61]],"ltp":4.3,"tv":160.0,"id":21580749}]}]}
{"op":"mcm","clk":"989734327","pt":1580490898461,"mc":[{"id":"1.168096552","rc":[{"batl":[[0,3.1,4],[1,3.15,2]],"ltp":2.74,"tv":56.04,"id":18286408}]}]}
{"op":"mcm","clk":"989734742","pt":1580490902131,"mc":[{"id":"1.168096552","rc":[{"batl":[[0,3.05,2],[1,3.1,4]],"ltp":2.74,"tv":56.04,"id":18286408},{"batb":[[0,4,24],[1,3.8,5.61],[2,3.75,1.68]],"ltp":4.3,"tv":160.0,"id":21580749}]}]}
{"op":"mcm","clk":"989736032","pt":1580490913469,"mc":[{"id":"1.168096552","rc":[{"trd":[[4,26]],"batb":[[0,4,15]],"batl":[[0,4.4,13.83],[1,4.6,8],[2,5.4,4.74]],"ltp":4.0,"tv":178.0,"id":21580749}],"tv":262.5}]}
{"op":"mcm","clk":"989736656","pt":1580490918489,"mc":[{"id":"1.168096552","rc":[{"batb":[[0,4,15.4]],"ltp":4.0,"tv":178.0,"id":21580749}]}]}
{"op":"mcm","clk":"989737024","pt":1580490921790,"mc":[{"id":"1.168096552","rc":[{"batl":[[0,4.5,13.83]],"ltp":4.0,"tv":178.0,"id":21580749}]}]}
{"op":"mcm","clk":"989737166","pt":1580490923091,"mc":[{"id":"1.168096552","rc":[{"batb":[[0,4,12.4],[2,3.75,4.68]],"ltp":4.0,"tv":178.0,"id":21580749}]}]}
{"op":"mcm","clk":"989737354","pt":1580490924474,"mc":[{"id":"1.168096552","rc":[{"batl":[[1,3.1,25]],"ltp":2.74,"tv":56.04,"id":18286408}]}]}
{"op":"mcm","clk":"989738416","pt":1580490934300,"mc":[{"id":"1.168096552","rc":[{"batl":[[0,4.6,21.83],[1,5.4,4.74],[2,5.5,5]],"ltp":4.0,"tv":178.0,"id":21580749}]}]}
{"op":"mcm","clk":"989739210","pt":1580490941484,"mc":[{"id":"1.168096552","rc":[{"batb":[[1,3.8,3.62]],"ltp":4.0,"tv":178.0,"id":21580749}]}]}
{"op":"mcm","clk":"989739286","pt":1580490942112,"mc":[{"id":"1.168096552","rc":[{"batb":[[0,8.4,1.98],[1,8.2,1.99]],"ltp":0.0,"tv":0.0,"id":26640937},{"batb":[[0,4,16.02],[1,3.75,4.68],[2,3.35,1.93]],"ltp":4.0,"tv":178.0,"id":21580749},{"batb":[[0,8.4,1.98],[1,8.2,1.99]],"ltp":0.0,"tv":0.0,"id":24608298}]}]}
{"op":"mcm","clk":"989741933","pt":1580490965931,"mc":[{"id":"1.168096552","rc":[{"batl":[[0,4.5,2.83],[1,4.6,21],[2,5.4,4.74]],"ltp":4.0,"tv":178.0,"id":21580749}]}]}
{"op":"mcm","clk":"989748360","pt":1580491023368,"mc":[{"id":"1.168096552","rc":[{"batb":[[0,8.6,1.99],[1,8.4,1.98]],"ltp":0.0,"tv":0.0,"id":26640937}]}]}
{"op":"mcm","clk":"989748392","pt":1580491023686,"mc":[{"id":"1.168096552","rc":[{"batb":[[0,8.6,1.99],[1,8.4,1.98]],"ltp":0.0,"tv":0.0,"id":24608298}]}]}
{"op":"mcm","clk":"989750876","pt":1580491046298,"mc":[{"id":"1.168096552","rc":[{"batb":[[0,8.8,1.98],[1,8.6,1.99]],"ltp":0.0,"tv":0.0,"id":26640937},{"batb":[[0,8.8,1.98],[1,8.6,1.99]],"ltp":0.0,"tv":0.0,"id":24608298}]}]}
{"op":"mcm","clk":"989759465","pt":1580491130133,"mc":[{"id":"1.168096552","rc":[{"batl":[[0,3.05,12],[2,3.45,6]],"ltp":2.74,"tv":56.04,"id":18286408}]}]}
{"op":"mcm","clk":"989760447","pt":1580491139148,"mc":[{"id":"1.168096552","rc":[{"batb":[[0,9,1.99],[1,8.8,1.98]],"ltp":0.0,"tv":0.0,"id":26640937}]}]}
{"op":"mcm","clk":"989760572","pt":1580491140447,"mc":[{"id":"1.168096552","rc":[{"batb":[[1,5.1,2.46],[2,3.15,53]],"ltp":0.0,"tv":0.0,"id":24608298}]}]}
{"op":"mcm","clk":"989761565","pt":1580491150360,"mc":[{"id":"1.168096552","rc":[{"batb":[[0,9.2,1.98],[1,9,1.99]],"ltp":0.0,"tv":0.0,"id":26640937},{"batb":[[0,5.2,2.77],[1,5.1,1.68]],"ltp":0.0,"tv":0.0,"id":24608298}]}]}
{"op":"mcm","clk":"989762644","pt":1580491159570,"mc":[{"id":"1.168096552","rc":[{"batl":[[0,3,2],[1,3.05,12],[2,3.1,25]],"ltp":2.74,"tv":56.04,"id":18286408}]}]}
{"op":"mcm","clk":"989762820","pt":1580491160954,"mc":[{"id":"1.168096552","rc":[{"batb":[[2,5.2,3.78]],"ltp":0.0,"tv":0.0,"id":26640937},{"batb":[[1,4.8,4.98]],"ltp":0.0,"tv":0.0,"id":27706761},{"batb":[[2,2.1,3]],"ltp":2.46,"tv":28.46,"id":52106},{"batb":[[2,3.2,3]],"ltp":0.0,"tv":0.0,"id":24608298}]}]}
{"op":"mcm","clk":"989769389","pt":1580491224430,"mc":[{"id":"1.168096552","rc":[{"batl":[[0,2.98,2],[1,3,2],[2,3.05,10]],"ltp":2.74,"tv":56.04,"id":18286408}]}]}
{"op":"mcm","clk":"989769571","pt":1580491226254,"mc":[{"id":"1.168096552","rc":[{"batl":[[0,980,9],[1,1000,1.88]],"ltp":0.0,"tv":0.0,"id":26640937},{"batb":[[1,4.9,90],[2,4.8,4.98]],"batl":[[1,980,9]],"ltp":0.0,"tv":0.0,"id":27706761},{"batl":[[2,8,9]],"ltp":2.46,"tv":28.46,"id":52106},{"batb":[[2,3.4,90]],"batl":[[1,980,9.2],[2,1000,1.68]],"ltp":0.0,"tv":0.0,"id":24608298}]}]}
{"op":"mcm","clk":"989770006","pt":1580491231165,"mc":[{"id":"1.168096552","rc":[{"batb":[[0,2.52,18.97],[1,2.38,5.52],[2,2.36,5.48]],"ltp":2.46,"tv":28.46,"id":52106}]}]}
{"op":"mcm","clk":"989770140","pt":1580491232368,"mc":[{"id":"1.168096552","rc":[{"batb":[[0,9.4,1.99],[1,9.2,1.98]],"ltp":0.0,"tv":0.0,"id":26640937},{"batb":[[0,7,1.99],[1,5.2,2.77],[2,5.1,1.68]],"ltp":0.0,"tv":0.0,"id":24608298}]}]}
{"op":"mcm","clk":"989770234","pt":1580491233363,"mc":[{"id":"1.168096552","rc":[{"batl":[[0,980,9.2],[1,1000,1.68]],"ltp":0.0,"tv":0.0,"id":26640937}]}]}
{"op":"mcm","clk":"989770484","pt":1580491235456,"mc":[{"id":"1.168096552","rc":[{"batb":[[2,4.8,1.98]],"ltp":0.0,"tv":0.0,"id":27706761}]}]}
{"op":"mcm","clk":"989770512","pt":1580491235653,"mc":[{"id":"1.168096552","rc":[{"batb":[[1,5,3],[2,4.9,90]],"ltp":0.0,"tv":0.0,"id":27706761},{"batb":[[1,5.2,5.77]],"ltp":0.0,"tv":0.0,"id":24608298}]}]}
{"op":"mcm","clk":"989771001","pt":1580491240442,"mc":[{"id":"1.168096552","rc":[{"batl":[[0,3.75,10.52],[1,3.8,2.44],[2,3.85,7]],"ltp":2.46,"tv":28.46,"id":52106}]}]}
{"op":"mcm","clk":"989771350","pt":1580491243571,"mc":[{"id":"1.168096552","rc":[{"trd":[[2.98,4]],"batl":[[0,3,2],[1,3.05,10],[2,3.1,25]],"ltp":2.98,"tv":60.04,"id":18286408}],"tv":266.5}]}
{"op":"mcm","clk":"989771572","pt":1580491245464,"mc":[{"id":"1.168096552","rc":[{"batb":[[2,2,90]],"ltp":2.98,"tv":60.04,"id":18286408}]}]}
{"op":"mcm","clk":"989771589","pt":1580491245681,"mc":[{"id":"1.168096552","rc":[{"batb":[[0,2.78,3],[1,2.76,5.56],[2,2.74,20]],"ltp":2.98,"tv":60.04,"id":18286408},{"batb":[[1,2.38,4.83]],"ltp":2.46,"tv":28.46,"id":52106}]}]}
{"op":"mcm","clk":"989773122","pt":1580491258482,"mc":[{"id":"1.168096552","rc":[{"batb":[[0,2.52,19.62]],"ltp":2.46,"tv":28.46,"id":52106}]}]}
{"op":"mcm","clk":"989773177","pt":1580491258901,"mc":[{"id":"1.168096552","rc":[{"batb":[[1,2.76,8.56]],"ltp":2.98,"tv":60.04,"id":18286408}]}]}
{"op":"mcm","clk":"989773554","pt":1580491262890,"mc":[{"id":"1.168096552","rc":[{"batl":[[0,4.5,15.83],[1,4.6,8]],"ltp":4.0,"tv":178.0,"id":21580749}]}]}
{"op":"mcm","clk":"989773944","pt":1580491266362,"mc":[{"id":"1.168096552","rc":[{"batb":[[0,2.78,5.97],[1,2.76,5.59]],"ltp":2.98,"tv":60.04,"id":18286408},{"batb":[[0,9.6,1.98],[1,9.4,1.99]],"ltp":0.0,"tv":0.0,"id":26640937},{"batb":[[1,5.1,1.98],[2,5,3]],"ltp":0.0,"tv":0.0,"id":27706761},{"batb":[[0,2.54,3.44],[1,2.52,18.97],[2,2.38,2.03]],"ltp":2.46,"tv":28.46,"id":52106},{"batb":[[0,7.2,1.98],[1,7,1.99],[2,5.2,3.78]],"ltp":0.0,"tv":0.0,"id":24608298}]}]}
{"op":"mcm","clk":"989774190","pt":1580491268365,"mc":[{"id":"1.168096552","rc":[{"batb":[[0,2.8,3],[1,2.78,2.97],[2,2.76,5.59]],"ltp":2.98,"tv":60.04,"id":18286408}]}]}
{"op":"mcm","clk":"989775966","pt":1580491284314,"mc":[{"id":"1.168096552","rc":[{"trd":[[3,24]],"batl":[[0,3.05,10],[1,3.1,25],[2,3.45,6]],"ltp":3.0,"tv":64.04,"id":18286408}],"tv":270.5}]}
{"op":"mcm","clk":"989776561","pt":1580491289125,"mc":[{"id":"1.168096552","rc":[{"batb":[[0,2.82,2.11],[1,2.8,3],[2,2.78,2.97]],"ltp":3.0,"tv":64.04,"id":18286408},{"batl":[[0,4.5,13.83]],"ltp":4.0,"tv":178.0,"id":21580749}]}]}
{"op":"mcm","clk":"989777038","pt":1580491293223,"mc":[{"id":"1.168096552","rc":[{"batb":[[0,2.84,3],[1,2.82,2.11]],"ltp":3.0,"tv":64.04,"id":18286408}]}]}
{"op":"mcm","clk":"989792911","pt":1580491353595,"mc":[{"id":"1.168096552","rc":[{"batb":[[0,2.86,2.08],[1,2.84,3]],"ltp":3.0,"tv":64.04,"id":18286408}]}]}
{"op":"mcm","clk":"989793241","pt":1580491357210,"mc":[{"id":"1.168096552","rc":[{"batb":[[0,2.86,5.08],[1,2.78,2.97],[2,2.76,2.59]],"ltp":3.0,"tv":64.04,"id":18286408}]}]}
{"op":"mcm","clk":"989793504","pt":1580491360640,"mc":[{"id":"1.168096552","rc":[{"batb":[[0,2.86,8.05],[1,2.76,2.59],[2,2.74,20]],"ltp":3.0,"tv":64.04,"id":18286408}]}]}
{"op":"mcm","clk":"989793984","pt":1580491366310,"mc":[{"id":"1.168096552","rc":[{"batb":[[1,5.2,3.78],[2,5.1,1.68]],"ltp":0.0,"tv":0.0,"id":26640937},{"batb":[[0,7.4,1.99],[1,7.2,1.98]],"ltp":0.0,"tv":0.0,"id":24608298}]}]}
{"op":"mcm","clk":"989795594","pt":1580491384052,"mc":[{"id":"1.168096552","rc":[{"batb":[[1,5.1,2.46],[2,3.2,3]],"ltp":0.0,"tv":0.0,"id":26640937}]}]}
{"op":"mcm","clk":"989802641","pt":1580491455521,"mc":[{"id":"1.168096552","rc":[{"batb":[[0,5.2,2.77],[1,5.1,1.68]],"ltp":0.0,"tv":0.0,"id":26640937},{"batb":[[0,7.6,1.98],[1,7.4,1.99]],"ltp":0.0,"tv":0.0,"id":24608298}]}]}
{"op":"mcm","clk":"989807395","pt":1580491503288,"mc":[{"id":"1.168096552","rc":[{"batb":[[0,7,1.99],[1,5.2,2.77],[2,5.1,1.68]],"ltp":0.0,"tv":0.0,"id":26640937}]}]}
{"op":"mcm","clk":"989807454","pt":1580491503765,"mc":[{"id":"1.168096552","rc":[{"batb":[[0,7.8,1.99],[1,7.6,1.98]],"ltp":0.0,"tv":0.0,"id":24608298}]}]}
{"op":"mcm","clk":"989807635","pt":1580491505499,"mc":[{"id":"1.168096552","rc":[{"batb":[[1,5.2,5.77]],"ltp":0.0,"tv":0.0,"id":26640937}]}]}
{"op":"mcm","clk":"989812031","pt":1580491549023,"mc":[{"id":"1.168096552","rc":[{"batb":[[0,7.2,1.98],[1,7,1.99],[2,5.2,3.78]],"ltp":0.0,"tv":0.0,"id":26640937},{"batb":[[0,8,1.98],[1,7.8,1.99]],"ltp":0.0,"tv":0.0,"id":24608298}]}]}
{"op":"mcm","clk":"989815922","pt":1580491586375,"mc":[{"id":"1.168096552","rc":[{"batl":[[0,4.3,2.83],[1,4.5,13],[2,4.6,8]],"ltp":4.0,"tv":178.0,"id":21580749}]}]}
{"op":"mcm","clk":"989819222","pt":1580491617638,"mc":[{"id":"1.168096552","rc":[{"trd":[[3.05,32.01]],"batb":[[0,3.05,10],[1,2.86,8.05],[2,2.76,2.59]],"batl":[[0,3.1,25],[1,3.45,6],[2,3.5,150]],"ltp":3.05,"tv":84.04,"id":18286408}],"tv":290.5}]}
{"op":"mcm","clk":"989819706","pt":1580491622317,"mc":[{"id":"1.168096552","rc":[{"batb":[[1,2.88,3],[2,2.86,5.05]],"ltp":3.05,"tv":84.04,"id":18286408}]}]}
{"op":"mcm","clk":"989820058","pt":1580491625728,"mc":[{"id":"1.168096552","rc":[{"batb":[[0,2.88,3],[1,2.86,5.05],[2,2.76,2.59]],"ltp":3.05,"tv":84.04,"id":18286408}]}]}
{"op":"mcm","clk":"989820318","pt":1580491628420,"mc":[{"id":"1.168096552","rc":[{"batb":[[0,7.4,1.99],[1,7.2,1.98]],"ltp":0.0,"tv":0.0,"id":26640937}]}]}
{"op":"mcm","clk":"989820385","pt":1580491629041,"mc":[{"id":"1.168096552","rc":[{"batb":[[0,8.2,1.99],[1,8,1.98]],"ltp":0.0,"tv":0.0,"id":24608298}]}]}
{"op":"mcm","clk":"989821693","pt":1580491641134,"mc":[{"id":"1.168096552","rc":[{"batb":[[0,2.88,5.97],[1,2.86,2.08]],"ltp":3.05,"tv":84.04,"id":18286408},{"batb":[[0,7.6,1.98],[1,7.4,1.99]],"ltp":0.0,"tv":0.0,"id":26640937},{"batb":[[0,8.4,1.98],[1,8.2,1.99]],"ltp":0.0,"tv":0.0,"id":24608298}]}]}
{"op":"mcm","clk":"989822923","pt":1580491653132,"mc":[{"id":"1.168096552","rc":[{"trd":[[3,33.74]],"batb":[[0,3,5.13],[1,2.88,5.97],[2,2.86,2.08]],"ltp":3.0,"tv":93.78,"id":18286408}],"tv":300.24}]}
{"op":"mcm","clk":"989823772","pt":1580491662043,"mc":[{"id":"1.168096552","rc":[{"batl":[[2,8,9]],"ltp":2.46,"tv":28.46,"id":52106}]}]}
{"op":"mcm","clk":"989823857","pt":1580491662975,"mc":[{"id":"1.168096552","rc":[{"batb":[[1,2.88,2.97],[2,2.86,5.08]],"ltp":3.0,"tv":93.78,"id":18286408}]}]}
{"op":"mcm","clk":"989830969","pt":1580491730737,"mc":[{"id":"1.168096552","rc":[{"trd":[[3.1,12]],"batl":[[0,3.1,19]],"ltp":3.1,"tv":105.78,"id":18286408}],"tv":312.24}]}
{"op":"mcm","clk":"989831255","pt":1580491733234,"mc":[{"id":"1.168096552","rc":[{"batb":[[0,7.8,1.99],[1,7.6,1.98]],"ltp":0.0,"tv":0.0,"id":26640937}]}]}
{"op":"mcm","clk":"989831346","pt":1580491734136,"mc":[{"id":"1.168096552","rc":[{"batb":[[0,8.6,1.99],[1,8.4,1.98]],"ltp":0.0,"tv":0.0,"id":24608298}]}]}
{"op":"mcm","clk":"989831558","pt":1580491736417,"mc":[{"id":"1.168096552","rc":[{"batb":[[1,2.88,3],[2,2.86,2.08]],"ltp":3.1,"tv":105.78,"id":18286408},{"batb":[[1,5.2,3.78],[2,5.1,1.68]],"ltp":0.0,"tv":0.0,"id":26640937},{"batb":[[1,5.2,3.78],[2,5.1,1.68]],"ltp":0.0,"tv":0.0,"id":24608298}]}]}
{"op":"mcm","clk":"989831574","pt":1580491736573,"mc":[{"id":"1.168096552","rc":[{"batb":[[0,3,8.1]],"ltp":3.1,"tv":105.78,"id":18286408},{"batb":[[0,8,1.98],[1,7.8,1.99],[2,5.2,3.78]],"ltp":0.0,"tv":0.0,"id":26640937},{"batb":[[0,8.8,1.98],[1,8.6,1.99],[2,5.2,3.78]],"ltp":0.0,"tv":0.0,"id":24608298}]}]}
{"op":"mcm","clk":"989840347","pt":1580491817347,"mc":[{"id":"1.168096552","rc":[{"batl":[[1,3.4,2.94],[2,3.45,6]],"ltp":3.1,"tv":105.78,"id":18286408}]}]}
{"op":"mcm","clk":"989840531","pt":1580491818461,"mc":[{"id":"1.168096552","rc":[{"batb":[[0,8.2,1.68],[1,8,1.98],[2,7.8,1.99]],"batl":[[1,1000,0]],"ltp":0.0,"tv":0.0,"id":26640937},{"batb":[[1,3.75,3]],"ltp":4.0,"tv":178.0,"id":21580749},{"batb":[[0,2.56,1.89],[1,2.54,3.44],[2,2.52,18.97]],"batl":[[0,3.7,2.5],[1,3.75,10.52]],"ltp":2.46,"tv":28.46,"id":52106}]}]}
{"op":"mcm","clk":"989840661","pt":1580491819255,"mc":[{"id":"1.168096552","rc":[{"batl":[[0,970,1.88],[1,980,9]],"ltp":0.0,"tv":0.0,"id":26640937},{"batb":[[1,5.2,1.68],[2,5.1,1.98]],"ltp":0.0,"tv":0.0,"id":27706761},{"batl":[[1,970,1.88],[2,980,9]],"ltp":0.0,"tv":0.0,"id":24608298}]}]}
{"op":"mcm","clk":"989841393","pt":1580491824942,"mc":[{"id":"1.168096552","rc":[{"batl":[[1,8,9],[2,1000,0.2]],"ltp":2.46,"tv":28.46,"id":52106}]}]}
{"op":"mcm","clk":"989842264","pt":1580491830864,"mc":[{"id":"1.168096552","rc":[{"batl":[[1,950,9.2],[2,970,1.68]],"ltp":0.0,"tv":0.0,"id":24608298}]}]}
{"op":"mcm","clk":"989842407","pt":1580491832082,"mc":[{"id":"1.168096552","rc":[{"batb":[[1,5.3,1.98],[2,5.2,1.68]],"ltp":0.0,"tv":0.0,"id":27706761},{"batb":[[0,2.58,2.79],[1,2.56,1.89],[2,2.52,19.62]],"ltp":2.46,"tv":28.46,"id":52106}]}]}
{"op":"mcm","clk":"989843159","pt":1580491837469,"mc":[{"id":"1.168096552","rc":[{"batb":[[2,5.2,3.78]],"ltp":0.0,"tv":0.0,"id":26640937}]}]}
{"op":"mcm","clk":"989843227","pt":1580491837992,"mc":[{"id":"1.168096552","rc":[{"batb":[[0,8.4,1.99],[1,8.2,1.68],[2,8,1.98]],"ltp":0.0,"tv":0.0,"id":26640937},{"batb":[[1,5.2,3.78],[2,5.1,1.68]],"ltp":0.0,"tv":0.0,"id":24608298}]}]}
{"op":"mcm","clk":"989843684","pt":1580491841453,"mc":[{"id":"1.168096552","rc":[{"batb":[[1,2.98,3.09],[2,2.88,3]],"ltp":3.1,"tv":105.78,"id":18286408},{"batb":[[0,2.6,3.55],[1,2.58,2.79],[2,2.56,1.89]],"ltp":2.46,"tv":28.46,"id":52106}]}]}
{"op":"mcm","clk":"989843764","pt":1580491842081,"mc":[{"id":"1.168096552","rc":[{"batb":[[0,8.4,3.28]],"ltp":0.0,"tv":0.0,"id":26640937},{"batb":[[0,4.1,2.65],[1,4,15.62],[2,3.75,3]],"ltp":4.0,"tv":178.0,"id":21580749},{"batb":[[1,5.4,1.71],[2,5.3,1.98]],"ltp":0.0,"tv":0.0,"id":27706761},{"batb":[[1,7,1.55],[2,5.2,3.78]],"ltp":0.0,"tv":0.0,"id":24608298}]}]}
{"op":"mcm","clk":"989855165","pt":1580491927385,"mc":[{"id":"1.168096552","rc":[{"batb":[[0,8.6,1.98],[1,8.4,3.28],[2,8.2,1.68]],"ltp":0.0,"tv":0.0,"id":26640937},{"batb":[[0,4.1,6.27],[1,4,12]],"ltp":4.0,"tv":178.0,"id":21580749},{"batb":[[1,5.5,1.98],[2,5.4,1.71]],"ltp":0.0,"tv":0.0,"id":27706761},{"batb":[[0,2.62,2.79],[1,2.6,3.55]],"ltp":2.46,"tv":28.46,"id":52106},{"batb":[[0,7,1.55],[1,5.3,2.77],[2,5.2,3]],"ltp":0.0,"tv":0.0,"id":24608298}]}]}
{"op":"mcm","clk":"989855719","pt":1580491931353,"mc":[{"id":"1.168096552","rc":[{"batb":[[0,8.8,1.99],[1,8.6,1.98],[2,8.4,1.29]],"ltp":0.0,"tv":0.0,"id":26640937}]}]}
{"op":"mcm","clk":"989855770","pt":1580491931768,"mc":[{"id":"1.168096552","rc":[{"batb":[[0,7.2,1.99],[1,7,1.55],[2,5.3,2.77]],"ltp":0.0,"tv":0.0,"id":24608298}]}]}
{"op":"mcm","clk":"989857147","pt":1580491940487,"mc":[{"id":"1.168096552","rc":[{"batl":[[1,4.6,8],[2,5.5,5]],"ltp":4.0,"tv":178.0,"id":21580749}]}]}
{"op":"mcm","clk":"989857286","pt":1580491941486,"mc":[{"id":"1.168096552","rc":[{"batl":[[1,4.6,21]],"ltp":4.0,"tv":178.0,"id":21580749}]}]}
{"op":"mcm","clk":"989864156","pt":1580491999255,"mc":[{"id":"1.168096552","rc":[{"batb":[[2,5.4,3.78]],"ltp":0.0,"tv":0.0,"id":24608298}]}]}
{"op":"mcm","clk":"989867532","pt":1580492024495,"mc":[{"id":"1.168096552","rc":[{"batb":[[1,8.4,1.29],[2,8.2,1.68]],"ltp":0.0,"tv":0.0,"id":26640937}]}]}
{"op":"mcm","clk":"989867546","pt":1580492024600,"mc":[{"id":"1.168096552","rc":[{"batb":[[0,9,1.98],[1,8.8,1.99],[2,8.4,1.29]],"ltp":0.0,"tv":0.0,"id":26640937},{"batb":[[0,7.4,1.98],[1,7.2,1.99],[2,7,1.55]],"ltp":0.0,"tv":0.0,"id":24608298}]}]}
{"op":"mcm","clk":"989868039","pt":1580492027290,"mc":[{"id":"1.168096552","rc":[{"batb":[[0,9.2,1.99],[1,9,1.98]],"ltp":0.0,"tv":0.0,"id":26640937}]}]}
{"op":"mcm","clk":"989868113","pt":1580492027671,"mc":[{"id":"1.168096552","rc":[{"batb":[[0,7.6,1.99],[1,7.4,1.98]],"ltp":0.0,"tv":0.0,"id":24608298}]}]}
{"op":"mcm","clk":"989879925","pt":1580492118477,"mc":[{"id":"1.168096552","rc":[{"batb":[[1,8.4,1.29],[2,8.2,1.68]],"ltp":0.0,"tv":0.0,"id":26640937},{"batb":[[1,7,1.55],[2,5.1,2.46]],"ltp":0.0,"tv":0.0,"id":24608298}]}]}
{"op":"mcm","clk":"989879938","pt":1580492118582,"mc":[{"id":"1.168096552","rc":[{"batb":[[0,9.4,1.98],[1,9.2,1.99],[2,8.4,1.29]],"ltp":0.0,"tv":0.0,"id":26640937},{"batb":[[0,7.8,1.98],[1,7.6,1.99],[2,7,1.55]],"ltp":0.0,"tv":0.0,"id":24608298}]}]}
{"op":"mcm","clk":"989881392","pt":1580492130402,"mc":[{"id":"1.168096552","rc":[{"batb":[[0,9.6,1.99],[1,9.4,1.98]],"ltp":0.0,"tv":0.0,"id":26640937}]}]}
{"op":"mcm","clk":"989881433","pt":1580492130689,"mc":[{"id":"1.168096552","rc":[{"batb":[[0,8,1.99],[1,7.8,1.98]],"ltp":0.0,"tv":0.0,"id":24608298}]}]}
{"op":"mcm","clk":"989884789","pt":1580492156324,"mc":[{"id":"1.168096552","rc":[{"batb":[[2,8.2,1.68]],"ltp":0.0,"tv":0.0,"id":26640937}]}]}
{"op":"mcm","clk":"989892213","pt":1580492213470,"mc":[{"id":"1.168096552","rc":[{"batb":[[1,8.2,1.68],[2,7,2.86]],"ltp":0.0,"tv":0.0,"id":26640937},{"batb":[[1,7,1.55],[2,5.1,2.46]],"ltp":0.0,"tv":0.0,"id":24608298}]}]}
{"op":"mcm","clk":"989892225","pt":1580492213574,"mc":[{"id":"1.168096552","rc":[{"batb":[[0,9.8,1.98],[1,9.6,1.99],[2,8.2,1.68]],"ltp":0.0,"tv":0.0,"id":26640937},{"batb":[[0,8.2,1.98],[1,8,1.99],[2,7,1.55]],"ltp":0.0,"tv":0.0,"id":24608298}]}]}
{"op":"mcm","clk":"989894255","pt":1580492230297,"mc":[{"id":"1.168096552","rc":[{"batb":[[2,5.1,2.46]],"ltp":0.0,"tv":0.0,"id":24608298}]}]}
{"op":"mcm","clk":"989894948","pt":1580492236406,"mc":[{"id":"1.168096552","rc":[{"batb":[[1,8.2,1.68],[2,7,2.86]],"ltp":0.0,"tv":0.0,"id":26640937},{"batb":[[0,8.4,1.99],[1,8.2,1.98]],"ltp":0.0,"tv":0.0,"id":24608298}]}]}
{"op":"mcm","clk":"989896556","pt":1580492250206,"mc":[{"id":"1.168096552","rc":[{"batb":[[2,3.15,53.78]],"ltp":0.0,"tv":0.0,"id":26640937}]}]}
{"op":"mcm","clk":"989911842","pt":1580492298468,"mc":[{"id":"1.168096552","rc":[{"batl":[[0,3.15,11.2],[1,3.7,2.5],[2,8,9]],"ltp":2.46,"tv":28.46,"id":52106}]}]}
{"op":"mcm","clk":"989912635","pt":1580492305498,"mc":[{"id":"1.168096552","rc":[{"batb":[[2,3.2,3.78]],"ltp":0.0,"tv":0.0,"id":26640937},{"batb":[[2,5.2,3.78]],"ltp":0.0,"tv":0.0,"id":24608298}]}]}
{"op":"mcm","clk":"989912748","pt":1580492306505,"mc":[{"id":"1.168096552","rc":[{"batb":[[0,8.2,1.68],[1,3.2,3.78],[2,3.15,53]],"ltp":0.0,"tv":0.0,"id":26640937},{"batb":[[1,5.2,3.78],[2,5.1,1.68]],"ltp":0.0,"tv":0.0,"id":24608298}]}]}
{"op":"mcm","clk":"989912760","pt":1580492306611,"mc":[{"id":"1.168096552","rc":[{"batb":[[1,3.25,2.77],[2,3.2,3]],"ltp":0.0,"tv":0.0,"id":26640937},{"batb":[[0,8.6,1.98],[1,8.4,1.99],[2,5.2,3.78]],"ltp":0.0,"tv":0.0,"id":24608298}]}]}
{"op":"mcm","clk":"989913043","pt":1580492309209,"mc":[{"id":"1.168096552","rc":[{"batb":[[1,3.3,1.28],[2,3.25,1.98]],"ltp":0.0,"tv":0.0,"id":26640937}]}]}
{"op":"mcm","clk":"989915159","pt":1580492328327,"mc":[{"id":"1.168096552","rc":[{"batb":[[1,3.3,4.28]],"ltp":0.0,"tv":0.0,"id":26640937}]}]}
{"op":"mcm","clk":"989917674","pt":1580492351348,"mc":[{"id":"1.168096552","rc":[{"batb":[[0,8.4,1.99],[1,8.2,1.68],[2,3.3,4.28]],"ltp":0.0,"tv":0.0,"id":26640937},{"batb":[[1,5.2,3.78],[2,5.1,1.68]],"ltp":0.0,"tv":0.0,"id":24608298}]}]}
{"op":"mcm","clk":"989919736","pt":1580492372976,"mc":[{"id":"1.168096552","rc":[{"batb":[[1,5.1,2.46],[2,3.45,3]],"ltp":0.0,"tv":0.0,"id":24608298}]}]}
{"op":"mcm","clk":"989922369","pt":1580492399797,"mc":[{"id":"1.168096552","rc":[{"batb":[[0,8.6,1.98],[1,8.4,1.99],[2,8.2,1.68]],"ltp":0.0,"tv":0.0,"id":26640937},{"batb":[[0,5.2,2.77],[1,5.1,1.68]],"ltp":0.0,"tv":0.0,"id":24608298}]}]}
{"op":"mcm","clk":"989926406","pt":1580492439031,"mc":[{"id":"1.168096552","rc":[{"batb":[[0,8.8,1.99],[1,8.6,1.98]],"ltp":0.0,"tv":0.0,"id":26640937},{"batb":[[0,7,1.99],[1,5.2,2.77],[2,5.1,1.68]],"ltp":0.0,"tv":0.0,"id":24608298}]}]}
{"op":"mcm","clk":"989942230","pt":1580492597903,"mc":[{"id":"1.168096552","rc":[{"batb":[[1,5.2,5.77]],"ltp":0.0,"tv":0.0,"id":24608298}]}]}
{"op":"mcm","clk":"989945794","pt":1580492634471,"mc":[{"id":"1.168096552","rc":[{"batb":[[1,8.2,1.68],[2,3.3,1.28]],"ltp":0.0,"tv":0.0,"id":26640937},{"batb":[[1,5.2,3.78]],"ltp":0.0,"tv":0.0,"id":24608298}]}]}
{"op":"mcm","clk":"989945849","pt":1580492634948,"mc":[{"id":"1.168096552","rc":[{"batb":[[0,9,1.98],[1,8.8,1.99],[2,8.2,1.68]],"ltp":0.0,"tv":0.0,"id":26640937},{"batb":[[0,7.2,1.98],[1,7,1.99],[2,5.2,3.78]],"ltp":0.0,"tv":0.0,"id":24608298}]}]}
{"op":"mcm","clk":"989951448","pt":1580492689433,"mc":[{"id":"1.168096552","rc":[{"trd":[[3.1,22.26]],"batb":[[0,3,2.97]],"batl":[[0,3.1,13.87]],"ltp":3.1,"tv":116.04,"id":18286408}],"tv":322.5}]}
{"op":"mcm","clk":"989955449","pt":1580492726146,"mc":[{"id":"1.168096552","rc":[{"batb":[[0,9.2,1.99],[1,9,1.98]],"ltp":0.0,"tv":0.0,"id":26640937},{"batb":[[0,7.4,1.99],[1,7.2,1.98]],"ltp":0.0,"tv":0.0,"id":24608298}]}]}
{"op":"mcm","clk":"989957000","pt":1580492741457,"mc":[{"id":"1.168096552","rc":[{"trd":[[11,4]],"ltp":11.0,"tv":4.0,"id":26640937}],"tv":326.5}]}
{"op":"mcm","clk":"989960036","pt":1580492771018,"mc":[{"id":"1.168096552","rc":[{"batb":[[0,9.4,1.98],[1,9.2,1.99]],"ltp":11.0,"tv":4.0,"id":26640937},{"batb":[[0,7.6,1.98],[1,7.4,1.99]],"ltp":0.0,"tv":0.0,"id":24608298}]}]}
{"op":"mcm","clk":"989966497","pt":1580492827266,"mc":[{"id":"1.168096552","rc":[{"batl":[[0,3.05,2],[1,3.1,13.87],[2,3.4,2.94]],"ltp":3.1,"tv":116.04,"id":18286408}]}]}
{"op":"mcm","clk":"989967096","pt":1580492832460,"mc":[{"id":"1.168096552","rc":[{"batb":[[0,9.6,1.99],[1,9.4,1.98]],"ltp":11.0,"tv":4.0,"id":26640937}]}]}
{"op":"mcm","clk":"989967134","pt":1580492832930,"mc":[{"id":"1.168096552","rc":[{"batb":[[0,7.8,1.99],[1,7.6,1.98]],"ltp":0.0,"tv":0.0,"id":24608298}]}]}
{"op":"mcm","clk":"989974548","pt":1580492911427,"mc":[{"id":"1.168096552","rc":[{"batb":[[0,9.8,1.98],[1,9.6,1.99]],"ltp":11.0,"tv":4.0,"id":26640937},{"batb":[[0,8,1.98],[1,7.8,1.99]],"ltp":0.0,"tv":0.0,"id":24608298}]}]}
{"op":"mcm","clk":"989976195","pt":1580492928518,"mc":[{"id":"1.168096552","rc":[{"batb":[[1,8.2,1.68],[2,7,2.86]],"ltp":11.0,"tv":4.0,"id":26640937}]}]}
{"op":"mcm","clk":"989976240","pt":1580492929052,"mc":[{"id":"1.168096552","rc":[{"batb":[[0,8.2,1.99],[1,8,1.98]],"ltp":0.0,"tv":0.0,"id":24608298}]}]}
{"op":"mcm","clk":"989977719","pt":1580492943652,"mc":[{"id":"1.168096552","rc":[{"batb":[[2,3.35,3.78]],"ltp":11.0,"tv":4.0,"id":26640937}]}]}
{"op":"mcm","clk":"989989186","pt":1580493053347,"mc":[{"id":"1.168096552","rc":[{"batb":[[0,8.2,1.68],[1,3.4,2.77],[2,3.35,3]],"ltp":11.0,"tv":4.0,"id":26640937},{"batb":[[0,8.4,1.98],[1,8.2,1.99]],"ltp":0.0,"tv":0.0,"id":24608298}]}]}
{"op":"mcm","clk":"989998307","pt":1580493143180,"mc":[{"id":"1.168096552","rc":[{"batb":[[0,8.4,1.99],[1,8.2,1.68],[2,3.4,2.77]],"ltp":11.0,"tv":4.0,"id":26640937}]}]}
{"op":"mcm","clk":"989998413","pt":1580493144349,"mc":[{"id":"1.168096552","rc":[{"batb":[[2,3.45,3.78]],"ltp":11.0,"tv":4.0,"id":26640937},{"batb":[[0,8.6,1.99],[1,8.4,1.98]],"ltp":0.0,"tv":0.0,"id":24608298}]}]}
{"op":"mcm","clk":"990011690","pt":1580493185495,"mc":[{"id":"1.168096552","rc":[{"batb":[[0,2.64,1.68],[1,2.62,2.79],[2,2.6,3.55]],"batl":[[1,8,9],[2,1000,0.2]],"ltp":2.46,"tv":28.46,"id":52106}]}]}
{"op":"mcm","clk":"990011774","pt":1580493186390,"mc":[{"id":"1.168096552","rc":[{"batb":[[0,8.6,1.68],[1,8.4,1.99]],"ltp":11.0,"tv":4.0,"id":26640937},{"batb":[[1,5.6,1.68],[2,5.5,1.98]],"ltp":0.0,"tv":0.0,"id":27706761},{"batl":[[0,3.05,12.94],[1,3.1,2.99],[2,3.15,11.2]],"ltp":2.46,"tv":28.46,"id":52106},{"batl":[[1,940,1.88],[2,950,9]],"ltp":0.0,"tv":0.0,"id":24608298}]}]}
{"op":"mcm","clk":"990012229","pt":1580493190940,"mc":[{"id":"1.168096552","rc":[{"batl":[[1,920,9.2],[2,940,1.68]],"ltp":0.0,"tv":0.0,"id":24608298}]}]}
{"op":"mcm","clk":"990012472","pt":1580493193306,"mc":[{"id":"1.168096552","rc":[{"batb":[[0,8.6,3.67]],"ltp":11.0,"tv":4.0,"id":26640937},{"batb":[[1,5.7,1.98],[2,5.6,1.68]],"ltp":0.0,"tv":0.0,"id":27706761},{"batb":[[0,8.8,1.98],[1,8.6,1.99]],"ltp":0.0,"tv":0.0,"id":24608298}]}]}
{"op":"mcm","clk":"990016208","pt":1580493232479,"mc":[{"id":"1.168096552","rc":[{"batb":[[2,3.3,1.28]],"ltp":11.0,"tv":4.0,"id":26640937}]}]}
{"op":"mcm","clk":"990016315","pt":1580493233447,"mc":[{"id":"1.168096552","rc":[{"batb":[[2,3.35,3.78]],"ltp":11.0,"tv":4.0,"id":26640937}]}]}
{"op":"mcm","clk":"990020186","pt":1580493275165,"mc":[{"id":"1.168096552","rc":[{"batb":[[0,8.8,1.99],[1,8.6,3.67]],"ltp":11.0,"tv":4.0,"id":26640937},{"batb":[[1,5.2,3.78],[2,5.1,1.68]],"ltp":0.0,"tv":0.0,"id":24608298}]}]}
{"op":"mcm","clk":"990020393","pt":1580493277514,"mc":[{"id":"1.168096552","rc":[{"batb":[[0,8.8,4.26]],"ltp":11.0,"tv":4.0,"id":26640937},{"batb":[[0,4.2,4.76],[1,4.1,6.27],[2,4,12]],"ltp":4.0,"tv":178.0,"id":21580749},{"batb":[[0,6.2,4.01],[1,5.7,2.26]],"ltp":0.0,"tv":0.0,"id":27706761},{"batb":[[0,2.64,9.26]],"ltp":2.46,"tv":28.46,"id":52106},{"batb":[[1,7,2.86],[2,5.2,3.78]],"ltp":0.0,"tv":0.0,"id":24608298}]}]}
{"op":"mcm","clk":"990021665","pt":1580493292500,"mc":[{"id":"1.168096552","rc":[{"batl":[[1,3.15,11.2],[2,8,9]],"ltp":2.46,"tv":28.46,"id":52106}]}]}
{"op":"mcm","clk":"990021719","pt":1580493293227,"mc":[{"id":"1.168096552","rc":[{"batb":[[0,6.4,2.46],[1,6.2,3.23],[2,5.7,2.26]],"ltp":0.0,"tv":0.0,"id":27706761},{"batl":[[0,3,2.95],[1,3.05,12.94],[2,3.15,11.2]],"ltp":2.46,"tv":28.46,"id":52106},{"batl":[[1,910,1.88],[2,920,9]],"ltp":0.0,"tv":0.0,"id":24608298}]}]}
{"op":"mcm","clk":"990021893","pt":1580493295426,"mc":[{"id":"1.168096552","rc":[{"batb":[[0,9,4.39],[1,8.8,4.26],[2,8.6,3.67]],"ltp":11.0,"tv":4.0,"id":26640937},{"trd":[[4.2,17.52]],"batb":[[0,4.1,6.27],[1,4,12],[2,3.75,3]],"batl":[[0,4.2,5.24],[1,4.3,2.83],[2,4.6,21]],"ltp":4.2,"tv":187.52,"id":21580749},{"batl":[[1,3.15,11.2],[2,8,9]],"ltp":2.46,"tv":28.46,"id":52106}],"tv":336.02}]}
{"op":"mcm","clk":"990023448","pt":1580493312414,"mc":[{"id":"1.168096552","rc":[{"batl":[[1,890,9.2],[2,910,1.68]],"ltp":0.0,"tv":0.0,"id":24608298}]}]}
{"op":"mcm","clk":"990025268","pt":1580493334369,"mc":[{"id":"1.168096552","rc":[{"batb":[[0,9.2,1.98],[1,9,4.39],[2,8.8,4.26]],"ltp":11.0,"tv":4.0,"id":26640937},{"batb":[[0,6.6,2.77],[1,6.4,1.68],[2,6.2,3.23]],"ltp":0.0,"tv":0.0,"id":27706761},{"batb":[[0,2.64,12.05],[1,2.6,3.55],[2,2.52,19.62]],"ltp":2.46,"tv":28.46,"id":52106},{"batb":[[0,7.2,1.98]],"ltp":0.0,"tv":0.0,"id":24608298}]}]}
{"op":"mcm","clk":"990025466","pt":1580493336435,"mc":[{"id":"1.168096552","rc":[{"batl":[[0,3.05,2.7]],"ltp":3.1,"tv":116.04,"id":18286408}]}]}
{"op":"mcm","clk":"990026870","pt":1580493351286,"mc":[{"id":"1.168096552","rc":[{"batb":[[2,8.8,1.99]],"ltp":11.0,"tv":4.0,"id":26640937},{"batb":[[2,5.4,1.98]],"ltp":0.0,"tv":0.0,"id":27706761},{"batb":[[0,2.64,4.47]],"ltp":2.46,"tv":28.46,"id":52106}]}]}
{"op":"mcm","clk":"990027171","pt":1580493354459,"mc":[{"id":"1.168096552","rc":[{"batb":[[0,6.8,2.46],[1,6.6,1.98]],"ltp":0.0,"tv":0.0,"id":27706761},{"batl":[[0,3.1,2.85]],"ltp":2.46,"tv":28.46,"id":52106},{"batb":[[0,7.4,1.68],[1,7.2,1.98],[2,7,2.86]],"batl":[[1,880,1.88],[2,890,9]],"ltp":0.0,"tv":0.0,"id":24608298}]}]}
{"op":"mcm","clk":"990027863","pt":1580493362488,"mc":[{"id":"1.168096552","rc":[{"batl":[[0,13,75],[1,970,1.88],[2,980,9]],"ltp":11.0,"tv":4.0,"id":26640937}]}]}
{"op":"mcm","clk":"990028252","pt":1580493367375,"mc":[{"id":"1.168096552","rc":[{"batl":[[0,3.05,12.94],[1,3.1,2.85],[2,3.15,11.2]],"ltp":2.46,"tv":28.46,"id":52106}]}]}
{"op":"mcm","clk":"990028653","pt":1580493372311,"mc":[{"id":"1.168096552","rc":[{"batl":[[1,32,9],[2,970,1.88]],"ltp":11.0,"tv":4.0,"id":26640937},{"batl":[[1,860,9.2],[2,880,1.68]],"ltp":0.0,"tv":0.0,"id":24608298}]}]}
{"op":"mcm","clk":"990030561","pt":1580493397520,"mc":[{"id":"1.168096552","rc":[{"batl":[[0,12.5,1.68],[1,13,75],[2,32,9]],"ltp":11.0,"tv":4.0,"id":26640937},{"batl":[[0,3,2.95],[1,3.05,12.94]],"ltp":2.46,"tv":28.46,"id":52106},{"batl":[[2,880,0]],"ltp":0.0,"tv":0.0,"id":24608298}]}]}
{"op":"mcm","clk":"990030570","pt":1580493397619,"mc":[{"id":"1.168096552","rc":[{"batl":[[1,850,1.88],[2,860,9]],"ltp":0.0,"tv":0.0,"id":24608298}]}]}
{"op":"mcm","clk":"990031039","pt":1580493403122,"mc":[{"id":"1.168096552","rc":[{"batl":[[1,3.15,11.2],[2,8,9]],"ltp":2.46,"tv":28.46,"id":52106}]}]}
{"op":"mcm","clk":"990031710","pt":1580493412147,"mc":[{"id":"1.168096552","rc":[{"batl":[[1,830,9.2],[2,850,1.68]],"ltp":0.0,"tv":0.0,"id":24608298}]}]}
{"op":"mcm","clk":"990031793","pt":1580493413243,"mc":[{"id":"1.168096552","rc":[{"batb":[[0,9.4,1.99],[1,9.2,1.98],[2,9,4.39]],"ltp":11.0,"tv":4.0,"id":26640937},{"batb":[[0,7.6,1.99],[1,7.4,1.68],[2,7.2,1.98]],"ltp":0.0,"tv":0.0,"id":24608298}]}]}
{"op":"mcm","clk":"990032408","pt":1580493421343,"mc":[{"id":"1.168096552","rc":[{"batb":[[2,8.6,1.68]],"ltp":11.0,"tv":4.0,"id":26640937}]}]}
{"op":"mcm","clk":"990032783","pt":1580493425443,"mc":[{"id":"1.168096552","rc":[{"trd":[[3,37.74]],"batb":[[0,2.98,4.06],[1,2.88,3],[2,2.86,2.08]],"ltp":3.0,"tv":120.04,"id":18286408}],"tv":340.02}]}
{"op":"mcm","clk":"990033373","pt":1580493433741,"mc":[{"id":"1.168096552","rc":[{"batb":[[1,2.86,5.08],[2,2.76,2.59]],"ltp":3.0,"tv":120.04,"id":18286408}]}]}
{"op":"mcm","clk":"990033881","pt":1580493440479,"mc":[{"id":"1.168096552","rc":[{"batl":[[0,3.1,2.85]],"ltp":2.46,"tv":28.46,"id":52106},{"batb":[[0,7.8,1.68],[1,7.6,1.99]],"batl":[[1,820,1.88],[2,830,9]],"ltp":0.0,"tv":0.0,"id":24608298}]}]}
{"op":"mcm","clk":"990034875","pt":1580493452285,"mc":[{"id":"1.168096552","rc":[{"batl":[[1,800,9.2],[2,820,1.68]],"ltp":0.0,"tv":0.0,"id":24608298}]}]}
{"op":"mcm","clk":"990035363","pt":1580493457694,"mc":[{"id":"1.168096552","rc":[{"batl":[[0,3.05,12.94],[1,3.1,2.85],[2,3.15,11.2]],"ltp":2.46,"tv":28.46,"id":52106}]}]}
{"op":"mcm","clk":"990036665","pt":1580493472818,"mc":[{"id":"1.168096552","rc":[{"trd":[[3.05,37.41]],"batb":[[0,3.05,4.17],[1,2.98,4.06],[2,2.86,5.08]],"batl":[[0,3.1,13.87],[1,3.4,2.94],[2,3.45,6]],"ltp":3.05,"tv":125.44,"id":18286408},{"batb":[[0,9.6,2.18],[1,9.4,1.99],[2,9.2,1.98]],"ltp":11.0,"tv":4.0,"id":26640937},{"trd":[[4.2,28]],"batl":[[0,4.3,2.83],[1,4.6,21],[2,5.5,5]],"ltp":4.2,"tv":198.0,"id":21580749},{"batb":[[0,18,1.16],[1,6.8,2.46],[2,6.6,1.98]],"ltp":0.0,"tv":0.0,"id":27706761},{"trd":[[3.05,13.74]],"batl":[[0,3.05,6.06]],"ltp":3.05,"tv":42.2,"id":52106},{"batb":[[0,7.8,2.3]],"ltp":0.0,"tv":0.0,"id":24608298}],"tv":369.65}]}
{"op":"mcm","clk":"990036944","pt":1580493476092,"mc":[{"id":"1.168096552","rc":[{"batb":[[0,3.05,5.14],[1,2.98,3.09]],"ltp":3.05,"tv":125.44,"id":18286408},{"batb":[[0,9.8,1.98],[1,9.6,2.18],[2,9.4,1.99]],"ltp":11.0,"tv":4.0,"id":26640937},{"batb":[[0,2.64,16.63],[1,2.62,2.79],[2,2.6,3.55]],"ltp":3.05,"tv":42.2,"id":52106},{"batb":[[0,8,2.6],[1,7.8,1.68],[2,7.6,1.99]],"ltp":0.0,"tv":0.0,"id":24608298}]}]}
{"op":"mcm","clk":"990037350","pt":1580493481327,"mc":[{"id":"1.168096552","rc":[{"batl":[[0,3,2.23],[1,3.05,6.06]],"ltp":3.05,"tv":42.2,"id":52106},{"batb":[[0,8.2,2.3],[1,8,1.98]],"batl":[[1,790,1.88],[2,800,9]],"ltp":0.0,"tv":0.0,"id":24608298}]}]}
{"op":"mcm","clk":"990037604","pt":1580493484288,"mc":[{"id":"1.168096552","rc":[{"batb":[[2,2.88,3]],"ltp":3.05,"tv":125.44,"id":18286408},{"batb":[[0,2.64,17.09]],"ltp":3.05,"tv":42.2,"id":52106}]}]}
{"op":"mcm","clk":"990038263","pt":1580493491901,"mc":[{"id":"1.168096552","rc":[{"batl":[[1,770,9.2],[2,790,1.68]],"ltp":0.0,"tv":0.0,"id":24608298}]}]}
{"op":"mcm","clk":"990040420","pt":1580493519908,"mc":[{"id":"1.168096552","rc":[{"batb":[[0,2.7,50],[1,2.64,17.09],[2,2.62,2.79]],"ltp":3.05,"tv":42.2,"id":52106}]}]}
{"op":"mcm","clk":"990040702","pt":1580493523435,"mc":[{"id":"1.168096552","rc":[{"batb":[[0,2.72,2.14],[1,2.7,50],[2,2.64,14.95]],"ltp":3.05,"tv":42.2,"id":52106},{"batl":[[2,790,0]],"ltp":0.0,"tv":0.0,"id":24608298}]}]}
{"op":"mcm","clk":"990040720","pt":1580493523644,"mc":[{"id":"1.168096552","rc":[{"batl":[[1,760,1.88],[2,770,9]],"ltp":0.0,"tv":0.0,"id":24608298}]}]}
{"op":"mcm","clk":"990041242","pt":1580493530436,"mc":[{"id":"1.168096552","rc":[{"batb":[[2,2.62,2.79]],"ltp":3.05,"tv":42.2,"id":52106}]}]}
{"op":"mcm","clk":"990041293","pt":1580493531112,"mc":[{"id":"1.168096552","rc":[{"batb":[[0,2.72,9.85]],"ltp":3.05,"tv":42.2,"id":52106}]}]}
{"op":"mcm","clk":"990041364","pt":1580493532159,"mc":[{"id":"1.168096552","rc":[{"batl":[[1,740,9.2],[2,760,1.68]],"ltp":0.0,"tv":0.0,"id":24608298}]}]}
{"op":"mcm","clk":"990042016","pt":1580493541154,"mc":[{"id":"1.168096552","rc":[{"batb":[[1,17,5],[2,6.8,2.46]],"ltp":0.0,"tv":0.0,"id":27706761}]}]}
{"op":"mcm","clk":"990043801","pt":1580493564445,"mc":[{"id":"1.168096552","rc":[{"batb":[[2,6.6,2.77]],"ltp":0.0,"tv":0.0,"id":27706761}]}]}
{"op":"mcm","clk":"990043841","pt":1580493564962,"mc":[{"id":"1.168096552","rc":[{"batb":[[1,17.5,1.68],[2,17,5]],"ltp":0.0,"tv":0.0,"id":27706761},{"batl":[[1,730,1.88],[2,740,9]],"ltp":0.0,"tv":0.0,"id":24608298}]}]}
{"op":"mcm","clk":"990044024","pt":1580493567369,"mc":[{"id":"1.168096552","rc":[{"batb":[[1,3,25],[2,2.98,3.09]],"ltp":3.05,"tv":125.44,"id":18286408}]}]}
{"op":"mcm","clk":"990044150","pt":1580493569188,"mc":[{"id":"1.168096552","rc":[{"batb":[[0,34,1.18],[1,8.2,1.68],[2,8,1.98]],"ltp":0.0,"tv":0.0,"id":24608298}]}]}
{"op":"mcm","clk":"990044412","pt":1580493572655,"mc":[{"id":"1.168096552","rc":[{"batl":[[1,710,9.2],[2,730,1.68]],"ltp":0.0,"tv":0.0,"id":24608298}]}]}
{"op":"mcm","clk":"990046905","pt":1580493605496,"mc":[{"id":"1.168096552","rc":[{"trd":[[2.9,3.92],[3,37.74],[3.05,37.4]],"batb":[[0,3.05,5.14]],"batl":[[1,3.45,6],[2,3.5,150]],"ltp":3.05,"tv":125.43,"id":18286408},{"batb":[[0,9.8,1.98]],"batl":[[0,12.5,1.68]],"ltp":11.0,"tv":4.0,"id":26640937},{"batb":[[0,4.1,6.26]],"ltp":4.2,"tv":198.0,"id":21580749},{"batb":[[1,17.5,1.68]],"batl":[[0,65,1.88]],"ltp":0.0,"tv":0.0,"id":27706761},{"trd":[[2.6,10.42],[2.62,8.97],[3.05,13.74]],"batb":[[0,2.72,9.84],[2,2.62,2.79]],"batl":[[0,3,2.23],[1,3.05,6.05]],"ltp":3.05,"tv":42.18,"id":52106},{"batb":[[1,8.2,1.68],[2,8,1.98]],"batl":[[2,730,0]],"ltp":0.0,"tv":0.0,"id":24608298}],"tv":369.61}]}
{"op":"mcm","clk":"990046916","pt":1580493605607,"mc":[{"id":"1.168096552","rc":[{"batl":[[1,700,1.88],[2,710,9]],"ltp":0.0,"tv":0.0,"id":24608298}]}]}
{"op":"mcm","clk":"990047962","pt":1580493616449,"mc":[{"id":"1.168096552","rc":[{"batb":[[2,8.6,1.68]],"ltp":11.0,"tv":4.0,"id":26640937}]}]}
{"op":"mcm","clk":"990048030","pt":1580493617242,"mc":[{"id":"1.168096552","rc":[{"batl":[[1,680,9],[2,700,1.88]],"ltp":0.0,"tv":0.0,"id":24608298}]}]}
{"op":"mcm","clk":"990048280","pt":1580493620438,"mc":[{"id":"1.168096552","rc":[{"batb":[[0,18,3.14]],"ltp":0.0,"tv":0.0,"id":27706761},{"batb":[[0,2.72,12.63],[2,2.6,3.55]],"ltp":3.05,"tv":42.18,"id":52106}]}]}
{"op":"mcm","clk":"990050005","pt":1580493641456,"mc":[{"id":"1.168096552","rc":[{"batb":[[0,9.8,4.02]],"ltp":11.0,"tv":4.0,"id":26640937},{"batb":[[0,18.5,1.08],[1,18,3.14],[2,17.5,1.68]],"ltp":0.0,"tv":0.0,"id":27706761},{"batb":[[0,2.74,7.76],[1,2.72,12.17],[2,2.7,50]],"ltp":3.05,"tv":42.18,"id":52106}]}]}
{"op":"mcm","clk":"990050042","pt":1580493641978,"mc":[{"id":"1.168096552","rc":[{"batb":[[0,2.76,7.59],[1,2.74,7.76],[2,2.72,4.47]],"ltp":3.05,"tv":42.18,"id":52106}]}]}
{"op":"mcm","clk":"990050387","pt":1580493645452,"mc":[{"id":"1.168096552","rc":[{"batb":[[0,2.76,8.05],[1,2.74,7.3]],"ltp":3.05,"tv":42.18,"id":52106}]}]}
{"op":"mcm","clk":"990052875","pt":1580493671077,"mc":[{"id":"1.168096552","rc":[{"batl":[[0,4.2,10],[1,4.3,2.83],[2,4.6,21]],"ltp":4.2,"tv":198.0,"id":21580749}]}]}
{"op":"mcm","clk":"990052996","pt":1580493672071,"mc":[{"id":"1.168096552","rc":[{"batl":[[0,4.2,20]],"ltp":4.2,"tv":198.0,"id":21580749}]}]}
{"op":"mcm","clk":"990053077","pt":1580493672797,"mc":[{"id":"1.168096552","rc":[{"trd":[[4.2,68]],"batb":[[0,4.1,6.63]],"batl":[[0,4.3,2.83],[1,4.6,21],[2,5.5,5]],"ltp":4.2,"tv":238.0,"id":21580749}],"tv":409.61}]}
{"op":"mcm","clk":"990053244","pt":1580493674488,"mc":[{"id":"1.168096552","rc":[{"batb":[[0,2.78,1.05],[1,2.76,7.59],[2,2.74,7.3]],"ltp":3.05,"tv":42.18,"id":52106}]}]}
{"op":"mcm","clk":"990055985","pt":1580493704842,"mc":[{"id":"1.168096552","rc":[{"batb":[[2,2.72,4.47]],"ltp":3.05,"tv":42.18,"id":52106}]}]}
{"op":"mcm","clk":"990056554","pt":1580493711510,"mc":[{"id":"1.168096552","rc":[{"trd":[[4.2,88]],"ltp":4.2,"tv":258.0,"id":21580749}],"tv":429.61}]}
{"op":"mcm","clk":"990057795","pt":1580493725862,"mc":[{"id":"1.168096552","rc":[{"trd":[[4.1,8.92]],"batb":[[0,4.1,4.63]],"ltp":4.1,"tv":261.26,"id":21580749}],"tv":432.88}]}
{"op":"mcm","clk":"990058283","pt":1580493731439,"mc":[{"id":"1.168096552","rc":[{"batb":[[0,9.8,4.69]],"ltp":11.0,"tv":4.0,"id":26640937},{"batb":[[0,2.78,2.87]],"ltp":3.05,"tv":42.18,"id":52106},{"batb":[[1,8.2,2.48]],"ltp":0.0,"tv":0.0,"id":24608298}]}]}
{"op":"mcm","clk":"990058577","pt":1580493733449,"mc":[{"id":"1.168096552","rc":[{"batb":[[0,2.78,2.41]],"ltp":3.05,"tv":42.18,"id":52106}]}]}
{"op":"mcm","clk":"990058645","pt":1580493734080,"mc":[{"id":"1.168096552","rc":[{"batb":[[0,2.8,7.94],[1,2.78,2.41]],"ltp":3.05,"tv":42.18,"id":52106}]}]}
{"op":"mcm","clk":"990061339","pt":1580493763685,"mc":[{"id":"1.168096552","rc":[{"batb":[[0,2.8,10.73],[2,2.72,1.68]],"ltp":3.05,"tv":42.18,"id":52106}]}]}
{"op":"mcm","clk":"990083135","pt":1580494003024,"mc":[{"id":"1.168096552","rc":[{"batl":[[0,12.5,4.68]],"ltp":11.0,"tv":4.0,"id":26640937}]}]}
{"op":"mcm","clk":"990086485","pt":1580494038445,"mc":[{"id":"1.168096552","rc":[{"batb":[[0,2.82,7.55],[1,2.8,10.27],[2,2.78,2.41]],"ltp":3.05,"tv":42.18,"id":52106}]}]}
{"op":"mcm","clk":"990086734","pt":1580494041349,"mc":[{"id":"1.168096552","rc":[{"batb":[[1,2.8,2.79]],"ltp":3.05,"tv":42.18,"id":52106}]}]}
{"op":"mcm","clk":"990086766","pt":1580494041766,"mc":[{"id":"1.168096552","rc":[{"batb":[[0,2.84,7.37],[1,2.82,7.55],[2,2.8,2.79]],"ltp":3.05,"tv":42.18,"id":52106}]}]}
{"op":"mcm","clk":"990087208","pt":1580494046184,"mc":[{"id":"1.168096552","rc":[{"batb":[[0,2.84,7.83],[1,2.82,7.09]],"ltp":3.05,"tv":42.18,"id":52106}]}]}
{"op":"mcm","clk":"990101532","pt":1580494099462,"mc":[{"id":"1.168096552","rc":[{"batb":[[1,2.8,2.79],[2,2.78,2.41]],"ltp":3.05,"tv":42.18,"id":52106}]}]}
{"op":"mcm","clk":"990101633","pt":1580494100472,"mc":[{"id":"1.168096552","rc":[{"trd":[[2.84,13.08],[2.86,0.92]],"batb":[[0,2.8,3.62],[1,2.78,2.41],[2,2.72,1.68]],"batl":[[0,2.98,2],[1,3,2.23],[2,3.05,6.05]],"ltp":2.84,"tv":56.18,"id":52106}],"tv":446.88}]}
{"op":"mcm","clk":"990103007","pt":1580494114317,"mc":[{"id":"1.168096552","rc":[{"batl":[[2,3.15,11.2]],"ltp":2.84,"tv":56.18,"id":52106}]}]}
{"op":"mcm","clk":"990107482","pt":1580494160451,"mc":[{"id":"1.168096552","rc":[{"trd":[[3.1,30.08]],"batl":[[0,3.1,9.96]],"ltp":3.1,"tv":133.25,"id":18286408},{"batb":[[0,10.5,1.16],[1,9.8,4.69],[2,9.6,2.18]],"ltp":11.0,"tv":4.0,"id":26640937},{"trd":[[4.3,144]],"batl":[[0,4.6,21],[1,5.5,5],[2,11,6.87]],"ltp":4.3,"tv":266.92,"id":21580749},{"batb":[[0,18.5,1.72]],"ltp":0.0,"tv":0.0,"id":27706761},{"batb":[[0,2.98,2.07],[1,2.8,3.62],[2,2.78,2.41]],"batl":[[0,3,2.23],[1,3.15,11.2],[2,8,9]],"ltp":2.84,"tv":56.18,"id":52106},{"batb":[[0,34,1.5]],"ltp":0.0,"tv":0.0,"id":24608298}],"tv":460.36}]}
{"op":"mcm","clk":"990107639","pt":1580494162283,"mc":[{"id":"1.168096552","rc":[{"batl":[[2,700,1.68]],"ltp":0.0,"tv":0.0,"id":24608298}]}]}
{"op":"mcm","clk":"990108094","pt":1580494168273,"mc":[{"id":"1.168096552","rc":[{"batb":[[1,4,15],[2,3.35,1.93]],"ltp":4.3,"tv":266.92,"id":21580749}]}]}
{"op":"mcm","clk":"990113000","pt":1580494221924,"mc":[{"id":"1.168096552","rc":[{"batb":[[1,2.82,2.94],[2,2.8,2.79]],"ltp":2.84,"tv":56.18,"id":52106}]}]}
{"op":"mcm","clk":"990113577","pt":1580494228481,"mc":[{"id":"1.168096552","rc":[{"batl":[[1,32,9],[2,32,0]],"ltp":11.0,"tv":4.0,"id":26640937}]}]}
{"op":"mcm","clk":"990113583","pt":1580494228534,"mc":[{"id":"1.168096552","rc":[{"batl":[[0,12,75],[1,12.5,4.68],[2,32,9]],"ltp":11.0,"tv":4.0,"id":26640937}]}]}
{"op":"mcm","clk":"990114247","pt":1580494235458,"mc":[{"id":"1.168096552","rc":[{"batb":[[0,19,2.62],[1,18.5,1.08],[2,18,1.16]],"ltp":0.0,"tv":0.0,"id":27706761},{"batb":[[0,2.98,4.86],[2,2.78,2.41]],"ltp":2.84,"tv":56.18,"id":52106}]}]}
{"op":"mcm","clk":"990114821","pt":1580494241378,"mc":[{"id":"1.168096552","rc":[{"batb":[[1,2.82,2.11]],"ltp":2.84,"tv":56.18,"id":52106}]}]}
{"op":"mcm","clk":"990114898","pt":1580494242273,"mc":[{"id":"1.168096552","rc":[{"trd":[[3,4.45]],"batl":[[0,3.15,11.2],[1,8,9],[2,8,0]],"ltp":3.0,"tv":60.63,"id":52106}],"tv":464.81}]}
{"op":"mcm","clk":"990116147","pt":1580494255913,"mc":[{"id":"1.168096552","rc":[{"batb":[[2,2.72,1.68]],"ltp":3.0,"tv":60.63,"id":52106}]}]}
{"op":"mcm","clk":"990117341","pt":1580494268899,"mc":[{"id":"1.168096552","rc":[{"batb":[[0,3,2.23],[1,2.98,4.86],[2,2.82,2.11]],"ltp":3.0,"tv":60.63,"id":52106}]}]}
{"op":"mcm","clk":"990118501","pt":1580494281704,"mc":[{"id":"1.168096552","rc":[{"batb":[[1,18,1.16],[2,17.5,1.68]],"ltp":0.0,"tv":0.0,"id":27706761}]}]}
{"op":"mcm","clk":"990122268","pt":1580494323083,"mc":[{"id":"1.168096552","rc":[{"batb":[[0,3.05,14.37]],"ltp":3.1,"tv":133.25,"id":18286408},{"batb":[[0,4.1,10.51]],"ltp":4.3,"tv":266.92,"id":21580749}]}]}
{"op":"mcm","clk":"990130815","pt":1580494420437,"mc":[{"id":"1.168096552","rc":[{"batb":[[0,18,1.8],[1,17.5,1.68],[2,17,5]],"ltp":0.0,"tv":0.0,"id":27706761},{"batb":[[1,2.98,2.07]],"ltp":3.0,"tv":60.63,"id":52106}]}]}
{"op":"mcm","clk":"990130827","pt":1580494420543,"mc":[{"id":"1.168096552","rc":[{"batb":[[0,18.5,2.62],[1,18,1.16],[2,17.5,1.68]],"ltp":0.0,"tv":0.0,"id":27706761},{"batb":[[0,3,5.02]],"ltp":3.0,"tv":60.63,"id":52106}]}]}
{"op":"mcm","clk":"990134869","pt":1580494463473,"mc":[{"id":"1.168096552","rc":[{"batb":[[1,4,21.37]],"batl":[[1,5.4,4.72],[2,5.5,5]],"ltp":4.3,"tv":266.92,"id":21580749},{"batb":[[0,19,2.32],[1,18.5,1.98],[2,18,1.16]],"ltp":0.0,"tv":0.0,"id":27706761},{"batb":[[1,8.6,1.68],[2,8,2.78]],"batl":[[2,700,0]],"ltp":0.0,"tv":0.0,"id":24608298}]}]}
{"op":"mcm","clk":"990134938","pt":1580494464315,"mc":[{"id":"1.168096552","rc":[{"batl":[[1,670,1.68],[2,680,9]],"ltp":0.0,"tv":0.0,"id":24608298}]}]}
{"op":"mcm","clk":"990135608","pt":1580494471810,"mc":[{"id":"1.168096552","rc":[{"batb":[[2,2.72,3.03]],"ltp":3.0,"tv":60.63,"id":52106}]}]}
{"op":"mcm","clk":"990136639","pt":1580494482439,"mc":[{"id":"1.168096552","rc":[{"batl":[[1,650,9],[2,670,1.68]],"ltp":0.0,"tv":0.0,"id":24608298}]}]}
{"op":"mcm","clk":"990158448","pt":1580494704761,"mc":[{"id":"1.168096552","rc":[{"batb":[[0,19.5,1.98],[1,19,2.32]],"ltp":0.0,"tv":0.0,"id":27706761}]}]}
{"op":"mcm","clk":"990164211","pt":1580494761349,"mc":[{"id":"1.168096552","rc":[{"batb":[[0,20,1.68],[1,19.5,1.98],[2,18,1.8]],"ltp":0.0,"tv":0.0,"id":27706761}]}]}
{"op":"mcm","clk":"990164264","pt":1580494761871,"mc":[{"id":"1.168096552","rc":[{"batb":[[1,8.6,7.35]],"batl":[[1,640,1.68],[2,650,9]],"ltp":0.0,"tv":0.0,"id":24608298}]}]}
{"op":"mcm","clk":"990165781","pt":1580494777867,"mc":[{"id":"1.168096552","rc":[{"trd":[[3.1,50]],"batb":[[0,3.1,40.04],[1,3.05,14.37],[2,3,25]],"batl":[[0,3.45,6],[1,3.5,150],[2,3.8,2.63]],"ltp":3.1,"tv":153.17,"id":18286408}],"tv":484.73}]}
{"op":"mcm","clk":"990166035","pt":1580494780482,"mc":[{"id":"1.168096552","rc":[{"batl":[[2,650,0]],"ltp":0.0,"tv":0.0,"id":24608298}]}]}
{"op":"mcm","clk":"990166060","pt":1580494780799,"mc":[{"id":"1.168096552","rc":[{"batl":[[1,620,9],[2,640,1.68]],"ltp":0.0,"tv":0.0,"id":24608298}]}]}
{"op":"mcm","clk":"990167641","pt":1580494796516,"mc":[{"id":"1.168096552","rc":[{"batl":[[0,3.4,4],[1,3.45,6],[2,3.5,150]],"ltp":3.1,"tv":153.17,"id":18286408},{"batb":[[2,2.72,6.03]],"ltp":3.0,"tv":60.63,"id":52106}]}]}
{"op":"mcm","clk":"990174207","pt":1580494857503,"mc":[{"id":"1.168096552","rc":[{"trd":[[3.4,5.8]],"batl":[[0,3.4,1.1]],"ltp":3.4,"tv":158.97,"id":18286408}],"tv":490.53}]}
{"op":"mcm","clk":"990174216","pt":1580494857600,"mc":[{"id":"1.168096552","rc":[{"trd":[[3.4,8]],"batl":[[0,3.45,6],[1,3.5,150],[2,3.8,2.63]],"ltp":3.4,"tv":161.17,"id":18286408}],"tv":492.73}]}
{"op":"mcm","clk":"990174542","pt":1580494860500,"mc":[{"id":"1.168096552","rc":[{"batb":[[0,3.15,4.32],[1,3.1,40.04],[2,3.05,14.37]],"ltp":3.4,"tv":161.17,"id":18286408}]}]}
{"op":"mcm","clk":"990174724","pt":1580494861933,"mc":[{"id":"1.168096552","rc":[{"batb":[[1,3.1,43.04]],"ltp":3.4,"tv":161.17,"id":18286408}]}]}
{"op":"mcm","clk":"990183531","pt":1580494944948,"mc":[{"id":"1.168096552","rc":[{"batb":[[2,2.72,24.97]],"ltp":3.0,"tv":60.63,"id":52106}]}]}
{"op":"mcm","clk":"990183863","pt":1580494948049,"mc":[{"id":"1.168096552","rc":[{"batb":[[0,3.15,5.29],[2,3.05,13.41]],"ltp":3.4,"tv":161.17,"id":18286408},{"batb":[[0,21,1.98],[1,20,1.68]],"ltp":0.0,"tv":0.0,"id":27706761}]}]}
{"op":"mcm","clk":"990184227","pt":1580494951474,"mc":[{"id":"1.168096552","rc":[{"trd":[[4.1,24.92]],"batb":[[0,4.1,2.51]],"ltp":4.1,"tv":282.91,"id":21580749}],"tv":508.73}]}
{"op":"mcm","clk":"990194479","pt":1580494957477,"mc":[{"id":"1.168096552","rc":[{"batb":[[0,3.05,1.37],[1,3,5.02],[2,2.98,2.07]],"ltp":3.0,"tv":60.63,"id":52106}]}]}
{"op":"mcm","clk":"990194674","pt":1580494959491,"mc":[{"id":"1.168096552","rc":[{"batl":[[1,4.5,18.95],[2,8,9]],"ltp":3.0,"tv":60.63,"id":52106}]}]}
{"op":"mcm","clk":"990195047","pt":1580494963883,"mc":[{"id":"1.168096552","rc":[{"batb":[[1,4,18.37],[2,3.75,3]],"ltp":4.1,"tv":282.91,"id":21580749},{"batl":[[2,5.7,18.95]],"ltp":3.0,"tv":60.63,"id":52106}]}]}
{"op":"mcm","clk":"990195264","pt":1580494966300,"mc":[{"id":"1.168096552","rc":[{"batl":[[2,5.4,18.95]],"ltp":3.0,"tv":60.63,"id":52106}]}]}
{"op":"mcm","clk":"990195531","pt":1580494969007,"mc":[{"id":"1.168096552","rc":[{"batl":[[1,5.3,9],[2,5.4,4.72]],"ltp":4.1,"tv":282.91,"id":21580749}]}]}
{"op":"mcm","clk":"990196861","pt":1580494984222,"mc":[{"id":"1.168096552","rc":[{"batb":[[2,3.05,4.17]],"ltp":3.4,"tv":161.17,"id":18286408},{"batb":[[0,4,18.37],[1,3.75,3],[2,3.35,1.93]],"ltp":4.1,"tv":282.91,"id":21580749}]}]}
{"op":"mcm","clk":"990198503","pt":1580495001460,"mc":[{"id":"1.168096552","rc":[{"batl":[[0,3.4,2.94],[1,3.45,6],[2,3.5,150]],"ltp":3.4,"tv":161.17,"id":18286408},{"batl":[[1,5.2,4.9],[2,5.3,9]],"ltp":4.1,"tv":282.91,"id":21580749},{"batb":[[1,8.2,8.14],[2,8,1.98]],"ltp":0.0,"tv":0.0,"id":24608298}]}]}
{"op":"mcm","clk":"990198546","pt":1580495001934,"mc":[{"id":"1.168096552","rc":[{"batl":[[1,610,1.68],[2,620,9]],"ltp":0.0,"tv":0.0,"id":24608298}]}]}
{"op":"mcm","clk":"990199176","pt":1580495008332,"mc":[{"id":"1.168096552","rc":[{"batl":[[0,4.5,2],[1,4.6,21],[2,5.2,4.9]],"ltp":4.1,"tv":282.91,"id":21580749}]}]}
{"op":"mcm","clk":"990200289","pt":1580495021459,"mc":[{"id":"1.168096552","rc":[{"batl":[[2,620,0]],"ltp":0.0,"tv":0.0,"id":24608298}]}]}
{"op":"mcm","clk":"990200300","pt":1580495021560,"mc":[{"id":"1.168096552","rc":[{"batl":[[1,590,9],[2,610,1.68]],"ltp":0.0,"tv":0.0,"id":24608298}]}]}
{"op":"mcm","clk":"990209175","pt":1580495111998,"mc":[{"id":"1.168096552","rc":[{"batl":[[0,4.5,15],[1,4.6,8]],"ltp":4.1,"tv":282.91,"id":21580749}]}]}
{"op":"mcm","clk":"990210648","pt":1580495127721,"mc":[{"id":"1.168096552","rc":[{"batl":[[0,4.5,13]],"ltp":4.1,"tv":282.91,"id":21580749}]}]}
{"op":"mcm","clk":"990220642","pt":1580495230422,"mc":[{"id":"1.168096552","rc":[{"batb":[[0,4.1,1.98],[1,4,18.37],[2,3.75,3]],"ltp":4.1,"tv":282.91,"id":21580749},{"batb":[[0,20,1.68],[1,18.5,2.62],[2,18,1.16]],"ltp":0.0,"tv":0.0,"id":27706761}]}]}
{"op":"mcm","clk":"990221028","pt":1580495235107,"mc":[{"id":"1.168096552","rc":[{"batb":[[1,19,1.21],[2,18.5,1.98]],"ltp":0.0,"tv":0.0,"id":27706761}]}]}
{"op":"mcm","clk":"990221428","pt":1580495239365,"mc":[{"id":"1.168096552","rc":[{"batb":[[0,19,2.89],[1,18.5,1.98],[2,18,1.16]],"ltp":0.0,"tv":0.0,"id":27706761},{"batb":[[1,8.6,2.41],[2,8,2.78]],"batl":[[1,580,1.68],[2,590,9]],"ltp":0.0,"tv":0.0,"id":24608298}]}]}
{"op":"mcm","clk":"990221661","pt":1580495242149,"mc":[{"id":"1.168096552","rc":[{"batl":[[1,560,9],[2,580,1.68]],"ltp":0.0,"tv":0.0,"id":24608298}]}]}
{"op":"mcm","clk":"990230013","pt":1580495344154,"mc":[{"id":"1.168096552","rc":[{"batb":[[1,4,43.37]],"ltp":4.1,"tv":282.91,"id":21580749}]}]}
{"op":"mcm","clk":"990230187","pt":1580495346498,"mc":[{"id":"1.168096552","rc":[{"trd":[[4.5,4]],"batl":[[0,4.5,11]],"ltp":4.5,"tv":286.91,"id":21580749}],"tv":512.73}]}
{"op":"mcm","clk":"990230265","pt":1580495347464,"mc":[{"id":"1.168096552","rc":[{"trd":[[4.5,15.14]],"batl":[[0,4.5,5.43]],"ltp":4.5,"tv":298.05,"id":21580749}],"tv":523.87}]}
{"op":"mcm","clk":"990230371","pt":1580495348365,"mc":[{"id":"1.168096552","rc":[{"batb":[[1,4,46.37],[2,3.35,1.93]],"ltp":4.5,"tv":298.05,"id":21580749}]}]}
{"op":"mcm","clk":"990232531","pt":1580495374482,"mc":[{"id":"1.168096552","rc":[{"batb":[[0,4.1,4.98]],"ltp":4.5,"tv":298.05,"id":21580749},{"batb":[[1,9,10],[2,8.6,2.41]],"ltp":0.0,"tv":0.0,"id":24608298}]}]}
{"op":"mcm","clk":"990233822","pt":1580495391433,"mc":[{"id":"1.168096552","rc":[{"batl":[[2,580,0]],"ltp":0.0,"tv":0.0,"id":24608298}]}]}
{"op":"mcm","clk":"990233834","pt":1580495391595,"mc":[{"id":"1.168096552","rc":[{"batl":[[1,550,1.68],[2,560,9]],"ltp":0.0,"tv":0.0,"id":24608298}]}]}
{"op":"mcm","clk":"990234866","pt":1580495404167,"mc":[{"id":"1.168096552","rc":[{"batl":[[1,530,9],[2,550,1.68]],"ltp":0.0,"tv":0.0,"id":24608298}]}]}
{"op":"mcm","clk":"990235106","pt":1580495406313,"mc":[{"id":"1.168096552","rc":[{"batb":[[0,3.15,25.29]],"ltp":3.4,"tv":161.17,"id":18286408}]}]}
{"op":"mcm","clk":"990240780","pt":1580495476476,"mc":[{"id":"1.168096552","rc":[{"trd":[[4.5,19.14]],"batl":[[0,4.5,3.43]],"ltp":4.5,"tv":302.05,"id":21580749}],"tv":527.87}]}
{"op":"mcm","clk":"990240797","pt":1580495476676,"mc":[{"id":"1.168096552","rc":[{"trd":[[4.5,23.72]],"batl":[[0,4.5,1.14]],"ltp":4.5,"tv":306.63,"id":21580749}],"tv":532.45}]}
{"op":"mcm","clk":"990242272","pt":1580495496416,"mc":[{"id":"1.168096552","rc":[{"batl":[[1,520,1.68],[2,530,9]],"ltp":0.0,"tv":0.0,"id":24608298}]}]}
{"op":"mcm","clk":"990242870","pt":1580495504513,"mc":[{"id":"1.168096552","rc":[{"batl":[[1,500,9],[2,520,1.68]],"ltp":0.0,"tv":0.0,"id":24608298}]}]}
{"op":"mcm","clk":"990243329","pt":1580495511422,"mc":[{"id":"1.168096552","rc":[{"batb":[[0,19.5,1.98],[1,19,2.89]],"ltp":0.0,"tv":0.0,"id":27706761}]}]}
{"op":"mcm","clk":"990246196","pt":1580495545408,"mc":[{"id":"1.168096552","rc":[{"batb":[[0,20,1.68],[1,19.5,1.98],[2,19,1.21]],"ltp":0.0,"tv":0.0,"id":27706761}]}]}
{"op":"mcm","clk":"990246254","pt":1580495546096,"mc":[{"id":"1.168096552","rc":[{"batl":[[1,490,1.68],[2,500,9]],"ltp":0.0,"tv":0.0,"id":24608298}]}]}
{"op":"mcm","clk":"990247810","pt":1580495564323,"mc":[{"id":"1.168096552","rc":[{"batl":[[1,470,9],[2,490,1.68]],"ltp":0.0,"tv":0.0,"id":24608298}]}]}
{"op":"mcm","clk":"990250026","pt":1580495584865,"mc":[{"id":"1.168096552","rc":[{"batl":[[1,460,1.68],[2,470,9]],"ltp":0.0,"tv":0.0,"id":24608298}]}]}
{"op":"mcm","clk":"990252128","pt":1580495604504,"mc":[{"id":"1.168096552","rc":[{"batl":[[2,470,0]],"ltp":0.0,"tv":0.0,"id":24608298}]}]}
{"op":"mcm","clk":"990252141","pt":1580495604608,"mc":[{"id":"1.168096552","rc":[{"batl":[[1,440,9],[2,460,1.68]],"ltp":0.0,"tv":0.0,"id":24608298}]}]}
{"op":"mcm","clk":"990254759","pt":1580495632345,"mc":[{"id":"1.168096552","rc":[{"batl":[[1,430,1.68],[2,440,9]],"ltp":0.0,"tv":0.0,"id":24608298}]}]}
{"op":"mcm","clk":"990256011","pt":1580495645775,"mc":[{"id":"1.168096552","rc":[{"batl":[[1,410,9],[2,430,1.68]],"ltp":0.0,"tv":0.0,"id":24608298}]}]}
{"op":"mcm","clk":"990258742","pt":1580495673521,"mc":[{"id":"1.168096552","rc":[{"batl":[[2,430,0]],"ltp":0.0,"tv":0.0,"id":24608298}]}]}
{"op":"mcm","clk":"990258753","pt":1580495673631,"mc":[{"id":"1.168096552","rc":[{"batl":[[1,400,1.68],[2,410,9]],"ltp":0.0,"tv":0.0,"id":24608298}]}]}
{"op":"mcm","clk":"990259970","pt":1580495685649,"mc":[{"id":"1.168096552","rc":[{"batl":[[1,380,9],[2,400,1.68]],"ltp":0.0,"tv":0.0,"id":24608298}]}]}
{"op":"mcm","clk":"990262368","pt":1580495706781,"mc":[{"id":"1.168096552","rc":[{"batl":[[1,370,1.68],[2,380,9]],"ltp":0.0,"tv":0.0,"id":24608298}]}]}
{"op":"mcm","clk":"990264463","pt":1580495725493,"mc":[{"id":"1.168096552","rc":[{"batl":[[1,350,9],[2,370,1.68]],"ltp":0.0,"tv":0.0,"id":24608298}]}]}
{"op":"mcm","clk":"990266424","pt":1580495744359,"mc":[{"id":"1.168096552","rc":[{"batb":[[0,21,1.98],[1,20,1.68]],"ltp":0.0,"tv":0.0,"id":27706761}]}]}
{"op":"mcm","clk":"990269232","pt":1580495769068,"mc":[{"id":"1.168096552","rc":[{"batl":[[1,340,1.68],[2,350,9]],"ltp":0.0,"tv":0.0,"id":24608298}]}]}
{"op":"mcm","clk":"990271163","pt":1580495785712,"mc":[{"id":"1.168096552","rc":[{"batl":[[1,320,9],[2,340,1.68]],"ltp":0.0,"tv":0.0,"id":24608298}]}]}
{"op":"mcm","clk":"990272979","pt":1580495804158,"mc":[{"id":"1.168096552","rc":[{"batl":[[1,310,1.68],[2,320,9]],"ltp":0.0,"tv":0.0,"id":24608298}]}]}
{"op":"mcm","clk":"990273174","pt":1580495805949,"mc":[{"id":"1.168096552","rc":[{"batl":[[1,290,9],[2,310,1.68]],"ltp":0.0,"tv":0.0,"id":24608298}]}]}
{"op":"mcm","clk":"990276251","pt":1580495836003,"mc":[{"id":"1.168096552","rc":[{"batl":[[1,280,1.68],[2,290,9]],"ltp":0.0,"tv":0.0,"id":24608298}]}]}
{"op":"mcm","clk":"990276906","pt":1580495842389,"mc":[{"id":"1.168096552","rc":[{"batl":[[0,280,1.68],[1,290,9],[2,290,0]],"ltp":0.0,"tv":0.0,"id":24608298}]}]}
{"op":"mcm","clk":"990288257","pt":1580495858902,"mc":[{"id":"1.168096552","rc":[{"batb":[[0,21,2.89]],"ltp":0.0,"tv":0.0,"id":27706761}]}]}
{"op":"mcm","clk":"990291027","pt":1580495884878,"mc":[{"id":"1.168096552","rc":[{"trd":[[3.15,30.06],[3.2,1.94]],"batb":[[0,3.15,9.29]],"ltp":3.15,"tv":193.16,"id":18286408}],"tv":564.44}]}
{"op":"mcm","clk":"990291415","pt":1580495887893,"mc":[{"id":"1.168096552","rc":[{"batb":[[1,3.1,40.04]],"ltp":3.15,"tv":193.16,"id":18286408}]}]}
{"op":"mcm","clk":"990296442","pt":1580495929929,"mc":[{"id":"1.168096552","rc":[{"trd":[[3,14.49],[3.05,16.47]],"batb":[[0,2.98,2.07],[1,2.72,24.97],[2,2.7,50]],"batl":[[0,3,13.61],[1,3.15,11.2],[2,4.5,18.95]],"ltp":3.0,"tv":73.41,"id":52106}],"tv":577.22}]}
{"op":"mcm","clk":"990296810","pt":1580495932636,"mc":[{"id":"1.168096552","rc":[{"batl":[[0,3.4,6.94]],"ltp":3.15,"tv":193.16,"id":18286408}]}]}
{"op":"mcm","clk":"990297362","pt":1580495936963,"mc":[{"id":"1.168096552","rc":[{"batb":[[0,3.15,11.81]],"ltp":3.15,"tv":193.16,"id":18286408},{"batb":[[0,2.98,4.65]],"ltp":3.0,"tv":73.41,"id":52106}]}]}
{"op":"mcm","clk":"990301933","pt":1580495980509,"mc":[{"id":"1.168096552","rc":[{"batb":[[1,2.74,7.3],[2,2.72,24.97]],"ltp":3.0,"tv":73.41,"id":52106}]}]}
{"op":"mcm","clk":"990303517","pt":1580495997427,"mc":[{"id":"1.168096552","rc":[{"batb":[[2,2.72,21.97]],"ltp":3.0,"tv":73.41,"id":52106}]}]}
{"op":"mcm","clk":"990303537","pt":1580495997632,"mc":[{"id":"1.168096552","rc":[{"batb":[[1,2.76,3],[2,2.74,7.3]],"ltp":3.0,"tv":73.41,"id":52106}]}]}
{"op":"mcm","clk":"990307717","pt":1580496040196,"mc":[{"id":"1.168096552","rc":[{"batb":[[2,2.72,21.97]],"ltp":3.0,"tv":73.41,"id":52106}]}]}
{"op":"mcm","clk":"990309826","pt":1580496060312,"mc":[{"id":"1.168096552","rc":[{"trd":[[4.1,29.44]],"batb":[[0,4.1,2.72]],"ltp":4.1,"tv":311.16,"id":21580749}],"tv":581.74}]}
{"op":"mcm","clk":"990310528","pt":1580496066436,"mc":[{"id":"1.168096552","rc":[{"batb":[[1,4,43.37],[2,3.75,3]],"ltp":4.1,"tv":311.16,"id":21580749}]}]}
{"op":"mcm","clk":"990310594","pt":1580496067017,"mc":[{"id":"1.168096552","rc":[{"batb":[[0,3.25,2.85],[1,3.15,11.81],[2,3.1,40.04]],"ltp":3.15,"tv":193.16,"id":18286408}]}]}
{"op":"mcm","clk":"990310831","pt":1580496069445,"mc":[{"id":"1.168096552","rc":[{"batb":[[0,4,43.37],[1,3.75,3],[2,3.35,1.93]],"ltp":4.1,"tv":311.16,"id":21580749},{"batb":[[1,2.72,21.97],[2,2.7,50]],"ltp":3.0,"tv":73.41,"id":52106}]}]}
{"op":"mcm","clk":"990310843","pt":1580496069551,"mc":[{"id":"1.168096552","rc":[{"batb":[[1,2.74,3],[2,2.72,21.97]],"ltp":3.0,"tv":73.41,"id":52106}]}]}
{"op":"mcm","clk":"990311217","pt":1580496072952,"mc":[{"id":"1.168096552","rc":[{"batl":[[2,4.8,4]],"ltp":4.1,"tv":311.16,"id":21580749}]}]}
{"op":"mcm","clk":"990313368","pt":1580496092465,"mc":[{"id":"1.168096552","rc":[{"batl":[[2,4.7,3.28]],"ltp":4.1,"tv":311.16,"id":21580749}]}]}
{"op":"mcm","clk":"990314223","pt":1580496100164,"mc":[{"id":"1.168096552","rc":[{"batl":[[0,4.5,3.14]],"ltp":4.1,"tv":311.16,"id":21580749}]}]}
{"op":"mcm","clk":"990320945","pt":1580496160184,"mc":[{"id":"1.168096552","rc":[{"batb":[[1,2.76,7.25],[2,2.74,3]],"ltp":3.0,"tv":73.41,"id":52106}]}]}
{"op":"mcm","clk":"990321766","pt":1580496167275,"mc":[{"id":"1.168096552","rc":[{"batl":[[0,3.4,36.94]],"ltp":3.15,"tv":193.16,"id":18286408}]}]}
{"op":"mcm","clk":"990323241","pt":1580496180481,"mc":[{"id":"1.168096552","rc":[{"batb":[[2,2.72,21.97]],"ltp":3.0,"tv":73.41,"id":52106}]}]}
{"op":"mcm","clk":"990323277","pt":1580496180814,"mc":[{"id":"1.168096552","rc":[{"batb":[[1,2.78,3],[2,2.76,7.25]],"ltp":3.0,"tv":73.41,"id":52106}]}]}
{"op":"mcm","clk":"990324192","pt":1580496188801,"mc":[{"id":"1.168096552","rc":[{"batb":[[0,4.3,83.98],[1,4,43.37],[2,3.75,3]],"ltp":4.1,"tv":311.16,"id":21580749}]}]}
{"op":"mcm","clk":"990325748","pt":1580496203709,"mc":[{"id":"1.168096552","rc":[{"batb":[[0,4,43.37],[1,3.75,20.8],[2,3.35,1.93]],"ltp":4.1,"tv":311.16,"id":21580749}]}]}
{"op":"mcm","clk":"990327524","pt":1580496221349,"mc":[{"id":"1.168096552","rc":[{"batb":[[0,4.1,4.98],[1,4,43.37],[2,3.75,20.8]],"ltp":4.1,"tv":311.16,"id":21580749},{"batb":[[1,2.82,3],[2,2.8,7.14]],"ltp":3.0,"tv":73.41,"id":52106}]}]}
{"op":"mcm","clk":"990327565","pt":1580496221772,"mc":[{"id":"1.168096552","rc":[{"batb":[[0,3.25,5.37],[1,3.15,9.29]],"ltp":3.15,"tv":193.16,"id":18286408}]}]}
{"op":"mcm","clk":"990328650","pt":1580496233474,"mc":[{"id":"1.168096552","rc":[{"batb":[[2,3.75,9.03]],"ltp":4.1,"tv":311.16,"id":21580749}]}]}
{"op":"mcm","clk":"990331414","pt":1580496261934,"mc":[{"id":"1.168096552","rc":[{"batl":[[0,3.4,32.94]],"ltp":3.15,"tv":193.16,"id":18286408}]}]}
{"op":"mcm","clk":"990331549","pt":1580496263309,"mc":[{"id":"1.168096552","rc":[{"batb":[[2,3.75,3]],"ltp":4.1,"tv":311.16,"id":21580749}]}]}
{"op":"mcm","clk":"990333218","pt":1580496282328,"mc":[{"id":"1.168096552","rc":[{"batb":[[1,2.84,7.04],[2,2.82,3]],"ltp":3.0,"tv":73.41,"id":52106}]}]}
{"op":"mcm","clk":"990333230","pt":1580496282540,"mc":[{"id":"1.168096552","rc":[{"batl":[[0,4.5,1.14]],"ltp":4.1,"tv":311.16,"id":21580749}]}]}
{"op":"mcm","clk":"990334421","pt":1580496296368,"mc":[{"id":"1.168096552","rc":[{"batl":[[0,4.6,8],[1,4.7,3.28],[2,4.8,4]],"ltp":4.1,"tv":311.16,"id":21580749}]}]}
{"op":"mcm","clk":"990335025","pt":1580496303152,"mc":[{"id":"1.168096552","rc":[{"batb":[[0,4.1,1.98]],"ltp":4.1,"tv":311.16,"id":21580749},{"batb":[[1,2.86,3],[2,2.84,7.04]],"ltp":3.0,"tv":73.41,"id":52106}]}]}
{"op":"mcm","clk":"990336214","pt":1580496315400,"mc":[{"id":"1.168096552","rc":[{"trd":[[4.5,47.44]],"ltp":4.5,"tv":334.88,"id":21580749}],"tv":605.46}]}
{"op":"mcm","clk":"990336608","pt":1580496319495,"mc":[{"id":"1.168096552","rc":[{"batb":[[2,3.35,1.93]],"ltp":4.5,"tv":334.88,"id":21580749}]}]}
{"op":"mcm","clk":"990336652","pt":1580496320119,"mc":[{"id":"1.168096552","rc":[{"trd":[[4.1,39.77]],"batb":[[0,4,46.37],[1,3.35,1.93],[2,2.2,90]],"ltp":4.1,"tv":345.2,"id":21580749}],"tv":615.79}]}
{"op":"mcm","clk":"990337296","pt":1580496327726,"mc":[{"id":"1.168096552","rc":[{"batb":[[0,4,43.37],[1,3.75,3],[2,3.35,1.93]],"ltp":4.1,"tv":345.2,"id":21580749}]}]}
{"op":"mcm","clk":"990338652","pt":1580496342651,"mc":[{"id":"1.168096552","rc":[{"batb":[[2,2.72,21.97]],"ltp":3.0,"tv":73.41,"id":52106}]}]}
{"op":"mcm","clk":"990339270","pt":1580496349333,"mc":[{"id":"1.168096552","rc":[{"batb":[[1,2.74,3]],"ltp":3.0,"tv":73.41,"id":52106}]}]}
{"op":"mcm","clk":"990342652","pt":1580496385714,"mc":[{"id":"1.168096552","rc":[{"batl":[[0,3,33.61]],"ltp":3.0,"tv":73.41,"id":52106}]}]}
{"op":"mcm","clk":"990344241","pt":1580496404005,"mc":[{"id":"1.168096552","rc":[{"batl":[[0,4.5,2],[1,4.6,8],[2,4.7,3.28]],"ltp":4.1,"tv":345.2,"id":21580749}]}]}
{"op":"mcm","clk":"990344924","pt":1580496412221,"mc":[{"id":"1.168096552","rc":[{"batb":[[0,4.1,1.98],[1,4,43.37],[2,3.75,3]],"ltp":4.1,"tv":345.2,"id":21580749}]}]}
{"op":"mcm","clk":"990347296","pt":1580496439969,"mc":[{"id":"1.168096552","rc":[{"batl":[[0,280,1.88]],"ltp":0.0,"tv":0.0,"id":24608298}]}]}
{"op":"mcm","clk":"990349536","pt":1580496465517,"mc":[{"id":"1.168096552","rc":[{"batl":[[0,4.6,8],[1,4.7,3.28],[2,4.8,4]],"ltp":4.1,"tv":345.2,"id":21580749}]}]}
{"op":"mcm","clk":"990351361","pt":1580496487451,"mc":[{"id":"1.168096552","rc":[{"batl":[[2,15,2]],"ltp":11.0,"tv":4.0,"id":26640937}]}]}
{"op":"mcm","clk":"990359635","pt":1580496584503,"mc":[{"id":"1.168096552","rc":[{"batb":[[1,2.76,7.25],[2,2.74,3]],"ltp":3.0,"tv":73.41,"id":52106}]}]}
{"op":"mcm","clk":"990360291","pt":1580496592320,"mc":[{"id":"1.168096552","rc":[{"trd":[[3.25,26]],"batb":[[0,3.15,9.66],[1,3.1,40.04],[2,3.05,4.17]],"ltp":3.25,"tv":203.16,"id":18286408}],"tv":625.79}]}
{"op":"mcm","clk":"990361869","pt":1580496609398,"mc":[{"id":"1.168096552","rc":[{"batl":[[0,3.35,4],[1,3.4,32.94],[2,3.45,6]],"ltp":3.25,"tv":203.16,"id":18286408}]}]}
{"op":"mcm","clk":"990361926","pt":1580496609921,"mc":[{"id":"1.168096552","rc":[{"batb":[[1,2.78,3],[2,2.76,7.25]],"ltp":3.0,"tv":73.41,"id":52106}]}]}
{"op":"mcm","clk":"990364195","pt":1580496634178,"mc":[{"id":"1.168096552","rc":[{"batl":[[0,3.3,3.03],[1,3.35,4],[2,3.4,30]],"ltp":3.25,"tv":203.16,"id":18286408}]}]}
{"op":"mcm","clk":"990365246","pt":1580496645207,"mc":[{"id":"1.168096552","rc":[{"batb":[[2,2.72,21.97]],"ltp":3.0,"tv":73.41,"id":52106}]}]}
{"op":"mcm","clk":"990365857","pt":1580496651277,"mc":[{"id":"1.168096552","rc":[{"batl":[[1,3.4,30],[2,3.45,6]],"ltp":3.25,"tv":203.16,"id":18286408},{"batb":[[1,2.74,3]],"ltp":3.0,"tv":73.41,"id":52106}]}]}
{"op":"mcm","clk":"990367310","pt":1580496665424,"mc":[{"id":"1.168096552","rc":[{"batl":[[0,3.4,30],[1,3.45,6],[2,3.5,150]],"ltp":3.25,"tv":203.16,"id":18286408}]}]}
{"op":"mcm","clk":"990367431","pt":1580496666314,"mc":[{"id":"1.168096552","rc":[{"batl":[[0,3.35,2.98],[1,3.4,30],[2,3.45,6]],"ltp":3.25,"tv":203.16,"id":18286408}]}]}
{"op":"mcm","clk":"990388043","pt":1580496766627,"mc":[{"id":"1.168096552","rc":[{"batb":[[1,2.76,7.25],[2,2.74,3]],"ltp":3.0,"tv":73.41,"id":52106}]}]}
{"op":"mcm","clk":"990388828","pt":1580496772204,"mc":[{"id":"1.168096552","rc":[{"batb":[[1,2.78,3],[2,2.76,7.25]],"ltp":3.0,"tv":73.41,"id":52106}]}]}
{"op":"mcm","clk":"990395102","pt":1580496827398,"mc":[{"id":"1.168096552","rc":[{"batb":[[2,2.72,21.97]],"ltp":3.0,"tv":73.41,"id":52106}]}]}
{"op":"mcm","clk":"990398979","pt":1580496864490,"mc":[{"id":"1.168096552","rc":[{"batb":[[1,2.74,3]],"ltp":3.0,"tv":73.41,"id":52106}]}]}
{"op":"mcm","clk":"990408943","pt":1580496948909,"mc":[{"id":"1.168096552","rc":[{"batb":[[1,2.76,7.25],[2,2.74,3]],"ltp":3.0,"tv":73.41,"id":52106}]}]}
{"op":"mcm","clk":"990416439","pt":1580497023003,"mc":[{"id":"1.168096552","rc":[{"batb":[[2,2.72,21.97]],"ltp":3.0,"tv":73.41,"id":52106}]}]}
{"op":"mcm","clk":"990417767","pt":1580497035321,"mc":[{"id":"1.168096552","rc":[{"batb":[[1,2.74,7.3]],"ltp":3.0,"tv":73.41,"id":52106}]}]}
{"op":"mcm","clk":"990424039","pt":1580497095431,"mc":[{"id":"1.168096552","rc":[{"trd":[[2.98,9.3]],"batb":[[0,2.74,7.3],[1,2.72,21.97],[2,2.7,50]],"batl":[[0,2.98,15.35],[1,3,33.61],[2,3.15,11.2]],"ltp":2.98,"tv":82.71,"id":52106}],"tv":635.09}]}
{"op":"mcm","clk":"990426825","pt":1580497126389,"mc":[{"id":"1.168096552","rc":[{"batb":[[1,2.72,21.14]],"ltp":2.98,"tv":82.71,"id":52106}]}]}
{"op":"mcm","clk":"990426851","pt":1580497126556,"mc":[{"id":"1.168096552","rc":[{"batb":[[0,2.76,1.68],[1,2.74,7.3],[2,2.72,21.14]],"ltp":2.98,"tv":82.71,"id":52106}]}]}
{"op":"mcm","clk":"990432403","pt":1580497181348,"mc":[{"id":"1.168096552","rc":[{"trd":[[3.35,4]],"batl":[[0,3.4,30.98],[1,3.45,6],[2,3.5,150]],"ltp":3.35,"tv":207.16,"id":18286408}],"tv":639.09}]}
{"op":"mcm","clk":"990432414","pt":1580497181553,"mc":[{"id":"1.168096552","rc":[{"trd":[[3.35,5.96]],"batl":[[0,3.4,30]],"ltp":3.35,"tv":209.13,"id":18286408}],"tv":641.05}]}
{"op":"mcm","clk":"990432552","pt":1580497182851,"mc":[{"id":"1.168096552","rc":[{"batb":[[1,3.1,43.04]],"ltp":3.35,"tv":209.13,"id":18286408}]}]}
{"op":"mcm","clk":"990433056","pt":1580497187845,"mc":[{"id":"1.168096552","rc":[{"batb":[[0,2.76,11.93]],"ltp":2.98,"tv":82.71,"id":52106}]}]}
{"op":"mcm","clk":"990433437","pt":1580497191769,"mc":[{"id":"1.168096552","rc":[{"batl":[[0,3.35,11.8],[1,3.4,30],[2,3.45,6]],"ltp":3.35,"tv":209.13,"id":18286408}]}]}
{"op":"mcm","clk":"990436733","pt":1580497216882,"mc":[{"id":"1.168096552","rc":[{"batb":[[0,2.76,15.41]],"ltp":2.98,"tv":82.71,"id":52106}]}]}
{"op":"mcm","clk":"990437167","pt":1580497220493,"mc":[{"id":"1.168096552","rc":[{"batb":[[0,2.78,7.19],[1,2.76,15.41]],"ltp":2.98,"tv":82.71,"id":52106}]}]}
{"op":"mcm","clk":"990437588","pt":1580497223505,"mc":[{"id":"1.168096552","rc":[{"batb":[[1,2.76,13.73]],"ltp":2.98,"tv":82.71,"id":52106}]}]}
{"op":"mcm","clk":"990437663","pt":1580497224201,"mc":[{"id":"1.168096552","rc":[{"batb":[[0,2.8,1.68],[1,2.78,7.19],[2,2.76,13.73]],"ltp":2.98,"tv":82.71,"id":52106}]}]}
{"op":"mcm","clk":"990437801","pt":1580497225271,"mc":[{"id":"1.168096552","rc":[{"trd":[[3.15,48.64],[3.2,2.68]],"batb":[[0,3.1,43.04],[1,3.05,4.17],[2,3,59.18]],"batl":[[0,3.35,12.14]],"ltp":3.15,"tv":228.45,"id":18286408}],"tv":660.37}]}
{"op":"mcm","clk":"990438208","pt":1580497228379,"mc":[{"id":"1.168096552","rc":[{"batl":[[0,3.35,11.8]],"ltp":3.15,"tv":228.45,"id":18286408}]}]}
{"op":"mcm","clk":"990439093","pt":1580497235004,"mc":[{"id":"1.168096552","rc":[{"batb":[[0,3.1,40.04],[2,3,62.18]],"ltp":3.15,"tv":228.45,"id":18286408}]}]}
{"op":"mcm","clk":"990439668","pt":1580497239298,"mc":[{"id":"1.168096552","rc":[{"trd":[[3.1,60]],"batb":[[0,3.1,35.04]],"ltp":3.1,"tv":238.45,"id":18286408}],"tv":670.37}]}
{"op":"mcm","clk":"990440217","pt":1580497243432,"mc":[{"id":"1.168096552","rc":[{"batb":[[2,3,59.18]],"ltp":3.1,"tv":238.45,"id":18286408}]}]}
{"op":"mcm","clk":"990452217","pt":1580497334294,"mc":[{"id":"1.168096552","rc":[{"batb":[[2,2.76,3.48]],"ltp":2.98,"tv":82.71,"id":52106}]}]}
{"op":"mcm","clk":"990456145","pt":1580497363344,"mc":[{"id":"1.168096552","rc":[{"batb":[[0,3.1,38.05]],"ltp":3.1,"tv":238.45,"id":18286408},{"batb":[[0,2.8,5.16],[2,2.72,18.95]],"ltp":2.98,"tv":82.71,"id":52106}]}]}
{"op":"mcm","clk":"990461821","pt":1580497404178,"mc":[{"id":"1.168096552","rc":[{"batb":[[1,2.72,18.95],[2,2.7,50]],"ltp":2.98,"tv":82.71,"id":52106}]}]}
{"op":"mcm","clk":"990468331","pt":1580497452034,"mc":[{"id":"1.168096552","rc":[{"trd":[[3.1,90]],"batb":[[0,3.1,23.05]],"ltp":3.1,"tv":268.45,"id":18286408}],"tv":700.37}]}
{"op":"mcm","clk":"990477736","pt":1580497520332,"mc":[{"id":"1.168096552","rc":[{"batb":[[0,2.82,2.11],[1,2.8,5.16],[2,2.72,18.95]],"ltp":2.98,"tv":82.71,"id":52106}]}]}
{"op":"mcm","clk":"990482354","pt":1580497553493,"mc":[{"id":"1.168096552","rc":[{"batb":[[1,2.8,3.48]],"ltp":2.98,"tv":82.71,"id":52106}]}]}
{"op":"mcm","clk":"990482383","pt":1580497553713,"mc":[{"id":"1.168096552","rc":[{"batb":[[0,2.84,1.68],[1,2.82,2.11],[2,2.8,3.48]],"ltp":2.98,"tv":82.71,"id":52106}]}]}
{"op":"mcm","clk":"990494722","pt":1580497642452,"mc":[{"id":"1.168096552","rc":[{"batb":[[0,2.84,5.16],[2,2.72,18.95]],"ltp":2.98,"tv":82.71,"id":52106}]}]}
{"op":"mcm","clk":"990511461","pt":1580497692416,"mc":[{"id":"1.168096552","rc":[{"batb":[[0,2.86,2.08],[1,2.84,5.16]],"ltp":2.98,"tv":82.71,"id":52106}]}]}
{"op":"mcm","clk":"990516452","pt":1580497727252,"mc":[{"id":"1.168096552","rc":[{"batb":[[0,2.88,1.68],[1,2.86,2.08],[2,2.84,3.48]],"ltp":2.98,"tv":82.71,"id":52106}]}]}
{"op":"mcm","clk":"990521003","pt":1580497759799,"mc":[{"id":"1.168096552","rc":[{"batb":[[0,2.86,2.87],[1,2.84,3.48],[2,2.74,50]],"ltp":2.98,"tv":82.71,"id":52106}]}]}
{"op":"mcm","clk":"990541714","pt":1580497896429,"mc":[{"id":"1.168096552","rc":[{"batl":[[0,4.5,10],[1,4.6,8],[2,4.7,3.28]],"ltp":4.1,"tv":345.2,"id":21580749}]}]}
{"op":"mcm","clk":"990542087","pt":1580497898910,"mc":[{"id":"1.168096552","rc":[{"batl":[[0,4.4,2],[1,4.5,10],[2,4.6,8]],"ltp":4.1,"tv":345.2,"id":21580749}]}]}
{"op":"mcm","clk":"990542343","pt":1580497900414,"mc":[{"id":"1.168096552","rc":[{"batl":[[1,4.5,20]],"ltp":4.1,"tv":345.2,"id":21580749}]}]}
{"op":"mcm","clk":"990542461","pt":1580497901342,"mc":[{"id":"1.168096552","rc":[{"trd":[[4.1,43.73]],"batb":[[0,4,37],[1,3.75,3],[2,3.35,1.93]],"batl":[[0,4.1,3.18],[1,4.4,2],[2,4.5,20]],"ltp":4.1,"tv":349.17,"id":21580749}],"tv":704.33}]}
{"op":"mcm","clk":"990543093","pt":1580497905418,"mc":[{"id":"1.168096552","rc":[{"batl":[[2,4.5,30]],"ltp":4.1,"tv":349.17,"id":21580749}]}]}
{"op":"mcm","clk":"990544079","pt":1580497911740,"mc":[{"id":"1.168096552","rc":[{"batl":[[2,4.5,40]],"ltp":4.1,"tv":349.17,"id":21580749}]}]}
{"op":"mcm","clk":"990544709","pt":1580497916363,"mc":[{"id":"1.168096552","rc":[{"batl":[[2,4.5,50]],"ltp":4.1,"tv":349.17,"id":21580749}]}]}
{"op":"mcm","clk":"990545949","pt":1580497924447,"mc":[{"id":"1.168096552","rc":[{"batl":[[2,4.5,60]],"ltp":4.1,"tv":349.17,"id":21580749}]}]}
{"op":"mcm","clk":"990546547","pt":1580497928162,"mc":[{"id":"1.168096552","rc":[{"batl":[[2,4.5,70]],"ltp":4.1,"tv":349.17,"id":21580749}]}]}
{"op":"mcm","clk":"990547834","pt":1580497936456,"mc":[{"id":"1.168096552","rc":[{"trd":[[4.1,50.11],[4.4,4],[4.5,187.06]],"batb":[[0,4,40],[1,3.35,1.93],[2,2.2,90]],"batl":[[0,4.6,8.19],[1,4.8,4],[2,5.3,9]],"ltp":4.5,"tv":499.16,"id":21580749}],"tv":854.33}]}
{"op":"mcm","clk":"990548283","pt":1580497939156,"mc":[{"id":"1.168096552","rc":[{"batb":[[0,4.1,2],[1,4,40],[2,3.35,1.93]],"ltp":4.5,"tv":499.16,"id":21580749}]}]}
{"op":"mcm","clk":"990548403","pt":1580497939961,"mc":[{"id":"1.168096552","rc":[{"batl":[[0,4.4,8],[1,4.6,8.19],[2,4.8,4]],"ltp":4.5,"tv":499.16,"id":21580749}]}]}
{"op":"mcm","clk":"990558926","pt":1580498007947,"mc":[{"id":"1.168096552","rc":[{"batb":[[2,2.76,18.95]],"ltp":2.98,"tv":82.71,"id":52106}]}]}
{"op":"mcm","clk":"990560083","pt":1580498015970,"mc":[{"id":"1.168096552","rc":[{"batb":[[0,2.86,6.35],[1,2.76,18.95],[2,2.74,50]],"ltp":2.98,"tv":82.71,"id":52106}]}]}
{"op":"mcm","clk":"990561365","pt":1580498024383,"mc":[{"id":"1.168096552","rc":[{"batl":[[0,3.3,20],[1,3.35,11.8],[2,3.4,30]],"ltp":3.1,"tv":268.45,"id":18286408}]}]}
{"op":"mcm","clk":"990563042","pt":1580498036400,"mc":[{"id":"1.168096552","rc":[{"trd":[[4.4,20]],"batb":[[0,4.4,1],[1,4.1,2],[2,4,40]],"batl":[[0,4.5,4.58],[1,4.6,8]],"ltp":4.4,"tv":515.16,"id":21580749}],"tv":870.33}]}
{"op":"mcm","clk":"990565350","pt":1580498051509,"mc":[{"id":"1.168096552","rc":[{"batb":[[1,4.2,18],[2,4.1,2]],"ltp":4.4,"tv":515.16,"id":21580749}]}]}
{"op":"mcm","clk":"990569098","pt":1580498076418,"mc":[{"id":"1.168096552","rc":[{"batl":[[2,3.1,4]],"ltp":2.98,"tv":82.71,"id":52106}]}]}
{"op":"mcm","clk":"990574727","pt":1580498113165,"mc":[{"id":"1.168096552","rc":[{"trd":[[3.1,110]],"batb":[[0,3.1,13.05]],"ltp":3.1,"tv":288.45,"id":18286408}],"tv":890.33}]}
{"op":"mcm","clk":"990578175","pt":1580498134501,"mc":[{"id":"1.168096552","rc":[{"trd":[[3.3,40.82]],"batl":[[0,3.3,4.6]],"ltp":3.3,"tv":329.27,"id":18286408}],"tv":931.15}]}
{"op":"mcm","clk":"990579230","pt":1580498140818,"mc":[{"id":"1.168096552","rc":[{"batb":[[0,3.15,5.55],[1,3.1,16.05],[2,3.05,4.17]],"batl":[[0,3.35,11.8],[1,3.4,30],[2,3.45,6]],"ltp":3.3,"tv":329.27,"id":18286408}]}]}
{"op":"mcm","clk":"990580500","pt":1580498148120,"mc":[{"id":"1.168096552","rc":[{"batb":[[0,3.15,8.56],[1,3.1,13.04]],"ltp":3.3,"tv":329.27,"id":18286408}]}]}
{"op":"mcm","clk":"990584750","pt":1580498175741,"mc":[{"id":"1.168096552","rc":[{"batb":[[1,3.1,3]],"ltp":3.3,"tv":329.27,"id":18286408}]}]}
{"op":"mcm","clk":"990591380","pt":1580498218010,"mc":[{"id":"1.168096552","rc":[{"batb":[[0,2.88,7.73],[1,2.86,5.56],[2,2.76,18.95]],"ltp":2.98,"tv":82.71,"id":52106}]}]}
{"op":"mcm","clk":"990592182","pt":1580498223514,"mc":[{"id":"1.168096552","rc":[{"batb":[[0,2.88,11.21],[1,2.86,2.08]],"ltp":2.98,"tv":82.71,"id":52106}]}]}
{"op":"mcm","clk":"990599383","pt":1580498273402,"mc":[{"id":"1.168096552","rc":[{"batb":[[0,2.88,4.27]],"ltp":2.98,"tv":82.71,"id":52106}]}]}
{"op":"mcm","clk":"990614192","pt":1580498384453,"mc":[{"id":"1.168096552","rc":[{"batb":[[2,2.78,7.19]],"ltp":2.98,"tv":82.71,"id":52106}]}]}
{"op":"mcm","clk":"990617389","pt":1580498410285,"mc":[{"id":"1.168096552","rc":[{"batb":[[1,10.5,2],[2,9,10]],"ltp":0.0,"tv":0.0,"id":24608298}]}]}
{"op":"mcm","clk":"990619397","pt":1580498425461,"mc":[{"id":"1.168096552","rc":[{"batl":[[0,2.96,75],[1,2.98,15.35],[2,3,33.61]],"ltp":2.98,"tv":82.71,"id":52106}]}]}
{"op":"mcm","clk":"990621660","pt":1580498442197,"mc":[{"id":"1.168096552","rc":[{"batb":[[1,10.5,2.99]],"ltp":0.0,"tv":0.0,"id":24608298}]}]}
{"op":"mcm","clk":"990626962","pt":1580498480344,"mc":[{"id":"1.168096552","rc":[{"batb":[[1,9,10.99],[2,8.6,2.41]],"ltp":0.0,"tv":0.0,"id":24608298}]}]}
{"op":"mcm","clk":"990631357","pt":1580498513320,"mc":[{"id":"1.168096552","rc":[{"batb":[[2,9.6,2.28]],"ltp":11.0,"tv":4.0,"id":26640937},{"batb":[[1,20,1.72]],"ltp":0.0,"tv":0.0,"id":27706761}]}]}
{"op":"mcm","clk":"990646939","pt":1580498552668,"mc":[{"id":"1.168096552","rc":[{"trd":[[2.88,8.54]],"batb":[[0,2.86,2.08],[1,2.78,7.19],[2,2.76,18.95]],"batl":[[0,2.96,75.73]],"ltp":2.88,"tv":91.25,"id":52106}],"tv":939.68}]}
{"op":"mcm","clk":"990647726","pt":1580498558367,"mc":[{"id":"1.168096552","rc":[{"batl":[[0,2.96,75]],"ltp":2.88,"tv":91.25,"id":52106}]}]}
{"op":"mcm","clk":"990650265","pt":1580498575992,"mc":[{"id":"1.168096552","rc":[{"batb":[[1,2.8,2.32],[2,2.78,7.19]],"batl":[[0,2.94,2.21],[1,2.96,75],[2,2.98,15.35]],"ltp":2.88,"tv":91.25,"id":52106}]}]}
{"op":"mcm","clk":"990650357","pt":1580498576574,"mc":[{"id":"1.168096552","rc":[{"trd":[[3.15,52.64]],"batb":[[0,3.15,6.56]],"ltp":3.15,"tv":333.27,"id":18286408}],"tv":943.68}]}
{"op":"mcm","clk":"990651052","pt":1580498580980,"mc":[{"id":"1.168096552","rc":[{"batb":[[1,3.05,4.17],[2,3,62.18]],"ltp":3.15,"tv":333.27,"id":18286408}]}]}
{"op":"mcm","clk":"990651570","pt":1580498584280,"mc":[{"id":"1.168096552","rc":[{"batl":[[0,3.3,2],[1,3.35,11.8],[2,3.4,30]],"ltp":3.15,"tv":333.27,"id":18286408}]}]}
{"op":"mcm","clk":"990653037","pt":1580498594513,"mc":[{"id":"1.168096552","rc":[{"batl":[[0,3.25,2],[1,3.3,2],[2,3.35,11.8]],"ltp":3.15,"tv":333.27,"id":18286408}]}]}
{"op":"mcm","clk":"990653066","pt":1580498594683,"mc":[{"id":"1.168096552","rc":[{"batl":[[0,2.92,6],[1,2.94,2.21],[2,2.96,75]],"ltp":2.88,"tv":91.25,"id":52106}]}]}
{"op":"mcm","clk":"990653540","pt":1580498597729,"mc":[{"id":"1.168096552","rc":[{"batb":[[0,2.86,3.76]],"ltp":2.88,"tv":91.25,"id":52106}]}]}
{"op":"mcm","clk":"990654831","pt":1580498606333,"mc":[{"id":"1.168096552","rc":[{"trd":[[2.86,4.28]],"batb":[[0,2.82,2.11],[2,2.76,18.95]],"ltp":2.86,"tv":94.61,"id":52106}],"tv":947.04}]}
{"op":"mcm","clk":"990655158","pt":1580498608421,"mc":[{"id":"1.168096552","rc":[{"batb":[[2,3,49]],"batl":[[2,3.4,30]],"ltp":3.15,"tv":333.27,"id":18286408}]}]}
{"op":"mcm","clk":"990655225","pt":1580498608911,"mc":[{"id":"1.168096552","rc":[{"batb":[[0,2.84,1.68],[1,2.82,2.11]],"ltp":2.86,"tv":94.61,"id":52106}]}]}
{"op":"mcm","clk":"990656352","pt":1580498615715,"mc":[{"id":"1.168096552","rc":[{"batl":[[0,3.2,2],[1,3.25,2],[2,3.3,2]],"ltp":3.15,"tv":333.27,"id":18286408}]}]}
{"op":"mcm","clk":"990658992","pt":1580498634431,"mc":[{"id":"1.168096552","rc":[{"trd":[[3.2,6.68]],"batb":[[1,3.05,14.17]],"batl":[[0,3.25,2],[1,3.3,2],[2,3.4,30]],"ltp":3.2,"tv":337.27,"id":18286408}],"tv":951.04}]}
{"op":"mcm","clk":"990659054","pt":1580498634916,"mc":[{"id":"1.168096552","rc":[{"trd":[[2.82,4.22],[2.84,16.44]],"batb":[[0,2.76,18.95],[1,2.74,50],[2,2.52,18.95]],"batl":[[0,2.82,16.21],[1,2.92,6],[2,2.94,2.21]],"ltp":2.82,"tv":102.19,"id":52106}],"tv":958.62}]}
{"op":"mcm","clk":"990659474","pt":1580498637922,"mc":[{"id":"1.168096552","rc":[{"trd":[[3.25,30]],"batb":[[1,3.05,16.17]],"batl":[[0,3.3,2],[1,3.4,30],[2,3.45,6]],"ltp":3.25,"tv":341.27,"id":18286408}],"tv":962.62}]}
{"op":"mcm","clk":"990660158","pt":1580498642459,"mc":[{"id":"1.168096552","rc":[{"batb":[[1,3.1,2],[2,3.05,16.17]],"ltp":3.25,"tv":341.27,"id":18286408}]}]}
{"op":"mcm","clk":"990660322","pt":1580498643447,"mc":[{"id":"1.168096552","rc":[{"batb":[[1,4.2,19.68]],"ltp":4.4,"tv":515.16,"id":21580749},{"trd":[[2.76,32.4]],"batb":[[0,2.76,2.75]],"batl":[[0,2.92,6],[1,2.94,2.21],[2,2.96,75]],"ltp":2.76,"tv":134.59,"id":52106}],"tv":995.03}]}
{"op":"mcm","clk":"990663267","pt":1580498663255,"mc":[{"id":"1.168096552","rc":[{"batb":[[1,4.3,6.72],[2,4.2,19.68]],"ltp":4.4,"tv":515.16,"id":21580749},{"batb":[[0,2.76,19.55]],"ltp":2.76,"tv":134.59,"id":52106}]}]}
{"op":"mcm","clk":"990664689","pt":1580498672286,"mc":[{"id":"1.168096552","rc":[{"trd":[[4.4,22]],"batb":[[0,4.3,6.72],[1,4.2,19.68],[2,4.1,2]],"batl":[[0,4.4,1],[1,4.5,4.58],[2,4.6,8]],"ltp":4.4,"tv":517.16,"id":21580749}],"tv":997.03}]}
{"op":"mcm","clk":"990665101","pt":1580498675299,"mc":[{"id":"1.168096552","rc":[{"batl":[[2,3.45,14.4]],"ltp":3.25,"tv":341.27,"id":18286408}]}]}
{"op":"mcm","clk":"990665390","pt":1580498677406,"mc":[{"id":"1.168096552","rc":[{"batl":[[0,3.25,2],[1,3.3,2],[2,3.4,30]],"ltp":3.25,"tv":341.27,"id":18286408}]}]}
{"op":"mcm","clk":"990667180","pt":1580498689392,"mc":[{"id":"1.168096552","rc":[{"batb":[[0,4.3,8.4],[1,4.2,18]],"ltp":4.4,"tv":517.16,"id":21580749}]}]}
{"op":"mcm","clk":"990671345","pt":1580498716319,"mc":[{"id":"1.168096552","rc":[{"batl":[[0,2.9,2],[1,2.92,6],[2,2.94,2.21]],"ltp":2.76,"tv":134.59,"id":52106}]}]}
{"op":"mcm","clk":"990678173","pt":1580498760278,"mc":[{"id":"1.168096552","rc":[{"batl":[[0,4.4,11]],"ltp":4.4,"tv":517.16,"id":21580749}]}]}
{"op":"mcm","clk":"990685304","pt":1580498805264,"mc":[{"id":"1.168096552","rc":[{"batl":[[2,2.94,17.41]],"ltp":2.76,"tv":134.59,"id":52106}]}]}
{"op":"mcm","clk":"990685540","pt":1580498806780,"mc":[{"id":"1.168096552","rc":[{"batl":[[2,2.94,2.21]],"ltp":2.76,"tv":134.59,"id":52106}]}]}
{"op":"mcm","clk":"990685785","pt":1580498808389,"mc":[{"id":"1.168096552","rc":[{"batl":[[0,2.9,17.41]],"ltp":2.76,"tv":134.59,"id":52106}]}]}
{"op":"mcm","clk":"990693267","pt":1580498857124,"mc":[{"id":"1.168096552","rc":[{"batb":[[0,2.8,20],[1,2.76,19.55],[2,2.74,50]],"ltp":2.76,"tv":134.59,"id":52106}]}]}
{"op":"mcm","clk":"990693380","pt":1580498857828,"mc":[{"id":"1.168096552","rc":[{"batb":[[0,2.82,5.88],[1,2.8,20],[2,2.76,2.75]],"ltp":2.76,"tv":134.59,"id":52106}]}]}
{"op":"mcm","clk":"990693576","pt":1580498859031,"mc":[{"id":"1.168096552","rc":[{"trd":[[2.8,28.24],[2.82,15.98]],"batb":[[0,2.8,5.88],[1,2.76,2.75],[2,2.74,50]],"ltp":2.8,"tv":174.59,"id":52106}],"tv":1037.03}]}
{"op":"mcm","clk":"990695612","pt":1580498871455,"mc":[{"id":"1.168096552","rc":[{"trd":[[4.4,44]],"batb":[[0,4.4,2],[1,4.3,8.4],[2,4.2,18]],"batl":[[0,4.5,4.58],[1,4.6,8],[2,4.8,4]],"ltp":4.4,"tv":539.16,"id":21580749}],"tv":1059.03}]}
{"op":"mcm","clk":"990695906","pt":1580498873483,"mc":[{"id":"1.168096552","rc":[{"batl":[[2,2.96,75]],"ltp":2.8,"tv":174.59,"id":52106}]}]}
{"op":"mcm","clk":"990695987","pt":1580498873961,"mc":[{"id":"1.168096552","rc":[{"batl":[[0,2.88,1.65],[1,2.9,17.41],[2,2.92,6]],"ltp":2.8,"tv":174.59,"id":52106}]}]}
{"op":"mcm","clk":"990696837","pt":1580498879869,"mc":[{"id":"1.168096552","rc":[{"batb":[[0,4.4,3.68],[1,4.3,6.72]],"ltp":4.4,"tv":539.16,"id":21580749}]}]}
{"op":"mcm","clk":"990699062","pt":1580498894993,"mc":[{"id":"1.168096552","rc":[{"batl":[[1,2.9,15.41]],"ltp":2.8,"tv":174.59,"id":52106}]}]}
{"op":"mcm","clk":"990699256","pt":1580498896303,"mc":[{"id":"1.168096552","rc":[{"batb":[[0,3.2,17],[1,3.15,6.56],[2,3.1,2]],"ltp":3.25,"tv":341.27,"id":18286408}]}]}
{"op":"mcm","clk":"990700626","pt":1580498905177,"mc":[{"id":"1.168096552","rc":[{"batb":[[0,3.2,24.56]],"ltp":3.25,"tv":341.27,"id":18286408}]}]}
{"op":"mcm","clk":"990700980","pt":1580498907503,"mc":[{"id":"1.168096552","rc":[{"batb":[[0,3.2,15.56]],"ltp":3.25,"tv":341.27,"id":18286408}]}]}
{"op":"mcm","clk":"990702545","pt":1580498917441,"mc":[{"id":"1.168096552","rc":[{"batb":[[0,3.2,8]],"ltp":3.25,"tv":341.27,"id":18286408}]}]}
{"op":"mcm","clk":"990702708","pt":1580498918514,"mc":[{"id":"1.168096552","rc":[{"trd":[[3.25,34]],"batb":[[0,3.25,6],[1,3.2,8],[2,3.15,6.56]],"batl":[[0,3.3,2],[1,3.4,30],[2,3.45,14.4]],"ltp":3.25,"tv":345.27,"id":18286408}],"tv":1063.03}]}
{"op":"mcm","clk":"990703845","pt":1580498925925,"mc":[{"id":"1.168096552","rc":[{"trd":[[3.3,44.82]],"batb":[[0,3.25,6.79],[2,3.15,3.01]],"batl":[[0,3.35,6.45]],"ltp":3.3,"tv":349.26,"id":18286408}],"tv":1067.03}]}
{"op":"mcm","clk":"990704121","pt":1580498927856,"mc":[{"id":"1.168096552","rc":[{"batb":[[2,3.15,5.01]],"ltp":3.3,"tv":349.26,"id":18286408}]}]}
{"op":"mcm","clk":"990704310","pt":1580498928932,"mc":[{"id":"1.168096552","rc":[{"batb":[[0,3.2,8.79],[1,3.15,11.01],[2,3.1,5]],"ltp":3.3,"tv":349.26,"id":18286408}]}]}
{"op":"mcm","clk":"990707764","pt":1580498951478,"mc":[{"id":"1.168096552","rc":[{"batb":[[1,12,5],[2,9,10.99]],"ltp":0.0,"tv":0.0,"id":24608298}]}]}
{"op":"mcm","clk":"990710282","pt":1580498967497,"mc":[{"id":"1.168096552","rc":[{"trd":[[4.5,196.22],[4.6,16]],"batb":[[0,4.6,1.42],[1,4.4,3.68],[2,4.3,6.72]],"batl":[[0,4.8,4],[1,5.2,2.9],[2,5.3,14.1]],"ltp":4.6,"tv":564.32,"id":21580749}],"tv":1092.19}]}
{"op":"mcm","clk":"990711173","pt":1580498973204,"mc":[{"id":"1.168096552","rc":[{"batb":[[0,3.2,11.8],[1,3.15,8]],"ltp":3.3,"tv":349.26,"id":18286408}]}]}
{"op":"mcm","clk":"990711288","pt":1580498974012,"mc":[{"id":"1.168096552","rc":[{"batb":[[2,4.3,9.72]],"ltp":4.6,"tv":564.32,"id":21580749},{"batb":[[0,26,2],[1,21,2.89],[2,20,1.72]],"ltp":0.0,"tv":0.0,"id":27706761}]}]}
{"op":"mcm","clk":"990711774","pt":1580498977518,"mc":[{"id":"1.168096552","rc":[{"batb":[[0,4.6,10.06],[1,4.5,18],[2,4.4,3.68]],"ltp":4.6,"tv":564.32,"id":21580749}]}]}
{"op":"mcm","clk":"990711916","pt":1580498978502,"mc":[{"id":"1.168096552","rc":[{"batb":[[2,20,1.68]],"ltp":0.0,"tv":0.0,"id":27706761}]}]}
{"op":"mcm","clk":"990712009","pt":1580498979110,"mc":[{"id":"1.168096552","rc":[{"batb":[[1,21,2.93]],"ltp":0.0,"tv":0.0,"id":27706761}]}]}
{"op":"mcm","clk":"990713096","pt":1580498986419,"mc":[{"id":"1.168096552","rc":[{"batb":[[0,4.6,18.46]],"ltp":4.6,"tv":564.32,"id":21580749}]}]}
{"op":"mcm","clk":"990713159","pt":1580498986839,"mc":[{"id":"1.168096552","rc":[{"batb":[[0,4.6,20.46]],"ltp":4.6,"tv":564.32,"id":21580749}]}]}
{"op":"mcm","clk":"990714245","pt":1580498994348,"mc":[{"id":"1.168096552","rc":[{"batl":[[0,4.7,2],[1,4.8,4],[2,5.2,2.9]],"ltp":4.6,"tv":564.32,"id":21580749}]}]}
{"op":"mcm","clk":"990714399","pt":1580498995343,"mc":[{"id":"1.168096552","rc":[{"batl":[[2,5.3,9]],"ltp":4.6,"tv":564.32,"id":21580749}]}]}
{"op":"mcm","clk":"990717407","pt":1580499014515,"mc":[{"id":"1.168096552","rc":[{"batb":[[1,21,2.02]],"ltp":0.0,"tv":0.0,"id":27706761}]}]}
{"op":"mcm","clk":"990718411","pt":1580499021112,"mc":[{"id":"1.168096552","rc":[{"batb":[[0,3.25,4.15],[1,3.2,11.01],[2,3.15,8]],"ltp":3.3,"tv":349.26,"id":18286408}]}]}
{"op":"mcm","clk":"990719716","pt":1580499029940,"mc":[{"id":"1.168096552","rc":[{"batl":[[0,4.8,4],[1,5.3,9],[2,5.5,5]],"ltp":4.6,"tv":564.32,"id":21580749}]}]}
{"op":"mcm","clk":"990733950","pt":1580499124763,"mc":[{"id":"1.168096552","rc":[{"batb":[[0,3.25,10.15],[2,3.15,2]],"ltp":3.3,"tv":349.26,"id":18286408}]}]}
{"op":"mcm","clk":"990746889","pt":1580499208006,"mc":[{"id":"1.168096552","rc":[{"batb":[[0,2.82,5.12],[1,2.8,5.88],[2,2.76,2.75]],"ltp":2.8,"tv":174.59,"id":52106}]}]}
