{"op":"mcm","clk":"992139118","pt":1580514726835,"mc":[{"id":"1.168096552","rc":[{"batl":[[1,20,1.68],[2,21,1.5]],"ltp":11.5,"tv":244.14,"id":26640937}]}]}
{"op":"mcm","clk":"992149492","pt":1580514757945,"mc":[{"id":"1.168096552","rc":[{"batl":[[1,21,1.5],[2,30,1.85]],"ltp":11.5,"tv":244.14,"id":26640937}]}]}
{"op":"mcm","clk":"992150351","pt":1580514788192,"mc":[{"id":"1.168096552","rc":[{"batb":[[0,3,172.21],[1,2.98,4],[2,2.9,13.44]],"ltp":3.0,"tv":1729.65,"id":18286408}]}]}
{"op":"mcm","clk":"992150402","pt":1580514789483,"mc":[{"id":"1.168096552","rc":[{"batb":[[0,3.05,19.08],[1,3,172.21],[2,2.98,4]],"ltp":3.0,"tv":1729.65,"id":18286408},{"batl":[[2,32,9.17]],"ltp":11.5,"tv":244.14,"id":26640937}]}]}
{"op":"mcm","clk":"992150407","pt":1580514789588,"mc":[{"id":"1.168096552","rc":[{"batl":[[1,20,1.68],[2,21,1.5]],"ltp":11.5,"tv":244.14,"id":26640937}]}]}
{"op":"mcm","clk":"992151012","pt":1580514808827,"mc":[{"id":"1.168096552","rc":[{"batb":[[1,2.98,4],[2,2.9,13.44]],"ltp":3.0,"tv":1729.65,"id":18286408}]}]}
{"op":"mcm","clk":"992151033","pt":1580514809806,"mc":[{"id":"1.168096552","rc":[{"batb":[[0,3.05,10.43]],"ltp":3.0,"tv":1729.65,"id":18286408}]}]}
{"op":"mcm","clk":"992151235","pt":1580514820139,"mc":[{"id":"1.168096552","rc":[{"trd":[[3.05,185.45]],"batb":[[0,2.98,4],[1,2.9,13.44],[2,2.88,39]],"batl":[[0,3.05,8.5],[1,3.1,58.62],[2,3.15,100]],"ltp":3.05,"tv":1750.51,"id":18286408}],"tv":7244.05}]}
{"op":"mcm","clk":"992151254","pt":1580514820914,"mc":[{"id":"1.168096552","rc":[{"batl":[[1,21,1.5],[2,30,1.85]],"ltp":11.5,"tv":244.14,"id":26640937}]}]}
{"op":"mcm","clk":"992151860","pt":1580514852176,"mc":[{"id":"1.168096552","rc":[{"batl":[[1,20,1.68],[2,21,1.5]],"ltp":11.5,"tv":244.14,"id":26640937}]}]}
{"op":"mcm","clk":"992152696","pt":1580514883517,"mc":[{"id":"1.168096552","rc":[{"batl":[[1,21,1.5],[2,30,1.85]],"ltp":11.5,"tv":244.14,"id":26640937}]}]}
{"op":"mcm","clk":"992153534","pt":1580514915176,"mc":[{"id":"1.168096552","rc":[{"batl":[[1,20,1.68],[2,21,1.5]],"ltp":11.5,"tv":244.14,"id":26640937}]}]}
{"op":"mcm","clk":"992153642","pt":1580514919770,"mc":[{"id":"1.168096552","rc":[{"trd":[[4.6,142.51]],"batb":[[0,4.6,3.8]],"ltp":4.6,"tv":1109.36,"id":21580749}],"tv":7264.06}]}
{"op":"mcm","clk":"992154407","pt":1580514946422,"mc":[{"id":"1.168096552","rc":[{"batl":[[1,21,1.5],[2,30,1.85]],"ltp":11.5,"tv":244.14,"id":26640937},{"trd":[[2.96,144.3]],"batb":[[0,2.96,32.85]],"ltp":2.96,"tv":4175.91,"id":52106}],"tv":7324.64}]}
{"op":"mcm","clk":"992154464","pt":1580514949194,"mc":[{"id":"1.168096552","rc":[{"trd":[[3,324.69],[3.05,66.19]],"batl":[[0,3.05,143.18],[1,3.1,2.36],[2,3.15,11.2]],"ltp":3.05,"tv":4236.49,"id":52106}],"tv":7385.22}]}
{"op":"mcm","clk":"992154508","pt":1580514951096,"mc":[{"id":"1.168096552","rc":[{"batl":[[0,3,2],[1,3.05,143.18],[2,3.1,2.36]],"ltp":3.05,"tv":4236.49,"id":52106}]}]}
{"op":"mcm","clk":"992154555","pt":1580514953101,"mc":[{"id":"1.168096552","rc":[{"batb":[[0,4.6,36.8]],"ltp":4.6,"tv":1109.36,"id":21580749}]}]}
{"op":"mcm","clk":"992154876","pt":1580514965407,"mc":[{"id":"1.168096552","rc":[{"batl":[[0,5,38.06],[1,5.1,20],[2,5.3,9]],"ltp":4.6,"tv":1109.36,"id":21580749}]}]}
{"op":"mcm","clk":"992154992","pt":1580514969516,"mc":[{"id":"1.168096552","rc":[{"batb":[[1,2.94,60.58],[2,2.9,8.88]],"ltp":3.05,"tv":4236.49,"id":52106}]}]}
{"op":"mcm","clk":"992155043","pt":1580514971417,"mc":[{"id":"1.168096552","rc":[{"batb":[[0,2.96,51.01],[1,2.9,8.88],[2,2.86,13.93]],"ltp":3.05,"tv":4236.49,"id":52106}]}]}
{"op":"mcm","clk":"992155067","pt":1580514972449,"mc":[{"id":"1.168096552","rc":[{"batb":[[0,2.96,32.85]],"ltp":3.05,"tv":4236.49,"id":52106}]}]}
{"op":"mcm","clk":"992155149","pt":1580514976407,"mc":[{"id":"1.168096552","rc":[{"trd":[[2.96,189.74]],"batb":[[0,2.96,10.13]],"ltp":2.96,"tv":4281.93,"id":52106}],"tv":7430.66}]}
{"op":"mcm","clk":"992155190","pt":1580514978515,"mc":[{"id":"1.168096552","rc":[{"batl":[[2,32,9.17]],"ltp":11.5,"tv":244.14,"id":26640937}]}]}
{"op":"mcm","clk":"992155216","pt":1580514979436,"mc":[{"id":"1.168096552","rc":[{"batl":[[1,20,1.68],[2,21,1.5]],"ltp":11.5,"tv":244.14,"id":26640937}]}]}
{"op":"mcm","clk":"992155321","pt":1580514985030,"mc":[{"id":"1.168096552","rc":[{"batb":[[0,12,1.67],[1,11.5,1.9],[2,11,4.36]],"ltp":11.5,"tv":244.14,"id":26640937}]}]}
{"op":"mcm","clk":"992155819","pt":1580515010409,"mc":[{"id":"1.168096552","rc":[{"batl":[[1,21,1.5],[2,30,1.85]],"ltp":11.5,"tv":244.14,"id":26640937}]}]}
{"op":"mcm","clk":"992156186","pt":1580515025407,"mc":[{"id":"1.168096552","rc":[{"trd":[[2.96,210]],"batb":[[0,2.9,8.88],[1,2.86,13.93],[2,2.84,47.08]],"batl":[[0,2.96,89.87],[1,3,2],[2,3.05,143.18]],"ltp":2.96,"tv":4302.19,"id":52106}],"tv":7450.92}]}
{"op":"mcm","clk":"992156306","pt":1580515031316,"mc":[{"id":"1.168096552","rc":[{"batl":[[0,3,2],[1,3.05,143.18],[2,3.1,2.36]],"ltp":2.96,"tv":4302.19,"id":52106}]}]}
{"op":"mcm","clk":"992156362","pt":1580515034088,"mc":[{"id":"1.168096552","rc":[{"trd":[[3.05,202.32]],"batb":[[0,3,172.21],[1,2.98,4],[2,2.9,13.44]],"batl":[[0,3.1,58.69],[1,3.15,100],[2,3.2,22]],"ltp":3.05,"tv":1767.38,"id":18286408}],"tv":7467.79}]}
{"op":"mcm","clk":"992156393","pt":1580515036097,"mc":[{"id":"1.168096552","rc":[{"batl":[[0,3.1,66.99]],"ltp":3.05,"tv":1767.38,"id":18286408}]}]}
{"op":"mcm","clk":"992156413","pt":1580515037426,"mc":[{"id":"1.168096552","rc":[{"trd":[[2.9,112.74]],"batb":[[0,2.88,9.54]],"batl":[[0,2.9,61.12],[1,3,2],[2,3.05,143.18]],"ltp":2.9,"tv":4319.95,"id":52106}],"tv":7485.55}]}
{"op":"mcm","clk":"992156481","pt":1580515040509,"mc":[{"id":"1.168096552","rc":[{"batl":[[0,3,2],[1,3.05,143.18],[2,3.1,2.36]],"ltp":2.9,"tv":4319.95,"id":52106}]}]}
{"op":"mcm","clk":"992156530","pt":1580515042417,"mc":[{"id":"1.168096552","rc":[{"batb":[[0,2.88,15.4]],"batl":[[0,2.98,5.67],[1,3,2],[2,3.05,143.18]],"ltp":2.9,"tv":4319.95,"id":52106}]}]}
{"op":"mcm","clk":"992156540","pt":1580515042722,"mc":[{"id":"1.168096552","rc":[{"batl":[[1,20,1.68],[2,21,1.5]],"ltp":11.5,"tv":244.14,"id":26640937}]}]}
{"op":"mcm","clk":"992156669","pt":1580515049442,"mc":[{"id":"1.168096552","rc":[{"trd":[[2.88,136.24]],"batb":[[0,2.86,13.93],[1,2.84,47.08],[2,2.82,7.61]],"batl":[[0,2.88,34.6],[1,2.98,5.67],[2,3,2]],"ltp":2.88,"tv":4350.75,"id":52106}],"tv":7516.35}]}
{"op":"mcm","clk":"992156756","pt":1580515053510,"mc":[{"id":"1.168096552","rc":[{"batl":[[0,2.98,5.67],[1,3,12.37],[2,3.05,143.18]],"ltp":2.88,"tv":4350.75,"id":52106}]}]}
{"op":"mcm","clk":"992157105","pt":1580515070360,"mc":[{"id":"1.168096552","rc":[{"batl":[[0,2.96,4],[1,2.98,5.67],[2,3,12.37]],"ltp":2.88,"tv":4350.75,"id":52106}]}]}
{"op":"mcm","clk":"992157110","pt":1580515070564,"mc":[{"id":"1.168096552","rc":[{"batl":[[2,3,2]],"ltp":2.88,"tv":4350.75,"id":52106}]}]}
{"op":"mcm","clk":"992157205","pt":1580515074738,"mc":[{"id":"1.168096552","rc":[{"batl":[[1,21,1.5],[2,30,1.85]],"ltp":11.5,"tv":244.14,"id":26640937}]}]}
{"op":"mcm","clk":"992157275","pt":1580515077774,"mc":[{"id":"1.168096552","rc":[{"batb":[[0,3,174.6]],"ltp":3.05,"tv":1767.38,"id":18286408},{"batb":[[0,2.86,15.61]],"ltp":2.88,"tv":4350.75,"id":52106}]}]}
{"op":"mcm","clk":"992157449","pt":1580515085348,"mc":[{"id":"1.168096552","rc":[{"batl":[[0,2.96,5.51]],"ltp":2.88,"tv":4350.75,"id":52106}]}]}
{"op":"mcm","clk":"992157512","pt":1580515087092,"mc":[{"id":"1.168096552","rc":[{"batl":[[0,2.96,4]],"ltp":2.88,"tv":4350.75,"id":52106}]}]}
{"op":"mcm","clk":"992157581","pt":1580515089981,"mc":[{"id":"1.168096552","rc":[{"trd":[[2.96,217.99]],"batl":[[0,2.98,5.67],[1,3,2],[2,3.05,143.18]],"ltp":2.96,"tv":4358.75,"id":52106}],"tv":7524.35}]}
{"op":"mcm","clk":"992157605","pt":1580515091271,"mc":[{"id":"1.168096552","rc":[{"trd":[[2.98,151.87],[3,324.93]],"batl":[[0,3,1.88],[1,3.05,143.18],[2,3.1,2.36]],"ltp":3.0,"tv":4370.33,"id":52106}],"tv":7535.93}]}
{"op":"mcm","clk":"992157714","pt":1580515096502,"mc":[{"id":"1.168096552","rc":[{"trd":[[2.88,140]],"batl":[[0,3.05,143.18],[1,3.1,2.36],[2,3.15,11.2]],"ltp":2.88,"tv":4374.09,"id":52106}],"tv":7539.69}]}
{"op":"mcm","clk":"992157744","pt":1580515097376,"mc":[{"id":"1.168096552","rc":[{"batl":[[0,3,1.51],[1,3.05,143.18],[2,3.1,2.36]],"ltp":2.88,"tv":4374.09,"id":52106}]}]}
{"op":"mcm","clk":"992157783","pt":1580515099183,"mc":[{"id":"1.168096552","rc":[{"batl":[[0,3.05,143.18],[1,3.1,2.36],[2,3.15,11.2]],"ltp":2.88,"tv":4374.09,"id":52106}]}]}
{"op":"mcm","clk":"992157871","pt":1580515103506,"mc":[{"id":"1.168096552","rc":[{"batb":[[0,2.88,4.11],[1,2.86,15.61],[2,2.84,49.08]],"batl":[[0,3,10.37],[1,3.05,143.18],[2,3.1,2.36]],"ltp":2.88,"tv":4374.09,"id":52106}]}]}
{"op":"mcm","clk":"992157917","pt":1580515105502,"mc":[{"id":"1.168096552","rc":[{"batb":[[1,2.86,34.54]],"ltp":2.88,"tv":4374.09,"id":52106}]}]}
{"op":"mcm","clk":"992157945","pt":1580515106475,"mc":[{"id":"1.168096552","rc":[{"batl":[[1,20,1.68],[2,21,1.5]],"ltp":11.5,"tv":244.14,"id":26640937},{"batb":[[0,2.88,13.77],[1,2.86,53.33]],"batl":[[0,2.98,9.33],[1,3,10.37],[2,3.05,143.18]],"ltp":2.88,"tv":4374.09,"id":52106}]}]}
{"op":"mcm","clk":"992157972","pt":1580515107705,"mc":[{"id":"1.168096552","rc":[{"batb":[[0,2.88,32.7],[1,2.86,34.4]],"ltp":2.88,"tv":4374.09,"id":52106}]}]}
{"op":"mcm","clk":"992158122","pt":1580515118113,"mc":[{"id":"1.168096552","rc":[{"batl":[[0,2.98,11.61]],"ltp":2.88,"tv":4374.09,"id":52106}]}]}
{"op":"mcm","clk":"992158414","pt":1580515131432,"mc":[{"id":"1.168096552","rc":[{"trd":[[3.05,202.46]],"batb":[[0,3.05,1.93],[1,3,174.6],[2,2.98,4]],"batl":[[0,3.1,66.92]],"ltp":3.05,"tv":1767.52,"id":18286408}],"tv":7539.83}]}
{"op":"mcm","clk":"992158453","pt":1580515132511,"mc":[{"id":"1.168096552","rc":[{"batb":[[0,3,174.6],[1,2.98,4],[2,2.9,13.44]],"ltp":3.05,"tv":1767.52,"id":18286408}]}]}
{"op":"mcm","clk":"992158555","pt":1580515137341,"mc":[{"id":"1.168096552","rc":[{"batl":[[1,21,1.5],[2,30,1.85]],"ltp":11.5,"tv":244.14,"id":26640937}]}]}
{"op":"mcm","clk":"992159454","pt":1580515169174,"mc":[{"id":"1.168096552","rc":[{"batl":[[1,20,1.68],[2,21,1.5]],"ltp":11.5,"tv":244.14,"id":26640937}]}]}
{"op":"mcm","clk":"992159567","pt":1580515173499,"mc":[{"id":"1.168096552","rc":[{"batl":[[0,2.96,1.77],[1,2.98,11.61]],"ltp":2.88,"tv":4374.09,"id":52106}]}]}
{"op":"mcm","clk":"992159601","pt":1580515174372,"mc":[{"id":"1.168096552","rc":[{"batl":[[0,2.98,11.61],[1,3.05,143.18],[2,3.1,2.36]],"ltp":2.88,"tv":4374.09,"id":52106}]}]}
{"op":"mcm","clk":"992160342","pt":1580515201502,"mc":[{"id":"1.168096552","rc":[{"batl":[[0,2.98,2.27],[1,3,9.27],[2,3.05,143.18]],"ltp":2.88,"tv":4374.09,"id":52106}]}]}
{"op":"mcm","clk":"992160392","pt":1580515202431,"mc":[{"id":"1.168096552","rc":[{"batl":[[1,21,1.5],[2,30,1.85]],"ltp":11.5,"tv":244.14,"id":26640937}]}]}
{"op":"mcm","clk":"992160648","pt":1580515210434,"mc":[{"id":"1.168096552","rc":[{"batl":[[0,3.05,2],[1,3.1,66.92],[2,3.15,100]],"ltp":3.05,"tv":1767.52,"id":18286408}]}]}
{"op":"mcm","clk":"992160776","pt":1580515216006,"mc":[{"id":"1.168096552","rc":[{"trd":[[3,187.59]],"batb":[[0,3,156.82]],"ltp":3.0,"tv":1803.11,"id":18286408},{"trd":[[2.98,156.41]],"batb":[[0,2.88,32.96]],"batl":[[0,3,9.27],[1,3.05,143.18],[2,3.1,2.36]],"ltp":2.98,"tv":4378.63,"id":52106}],"tv":7579.95}]}
{"op":"mcm","clk":"992160791","pt":1580515216695,"mc":[{"id":"1.168096552","rc":[{"batl":[[0,3,19.64]],"ltp":2.98,"tv":4378.63,"id":52106}]}]}
{"op":"mcm","clk":"992161253","pt":1580515233359,"mc":[{"id":"1.168096552","rc":[{"batl":[[1,20,1.68],[2,21,1.5]],"ltp":11.5,"tv":244.14,"id":26640937}]}]}
{"op":"mcm","clk":"992161327","pt":1580515234963,"mc":[{"id":"1.168096552","rc":[{"trd":[[3.05,206.46]],"batb":[[0,3.05,16.93],[1,3,156.82],[2,2.98,4]],"batl":[[0,3.1,66.92],[1,3.15,100],[2,3.2,22]],"ltp":3.05,"tv":1807.11,"id":18286408}],"tv":7583.95}]}
{"op":"mcm","clk":"992162410","pt":1580515265268,"mc":[{"id":"1.168096552","rc":[{"batl":[[1,21,1.5],[2,30,1.85]],"ltp":11.5,"tv":244.14,"id":26640937}]}]}
{"op":"mcm","clk":"992163358","pt":1580515296425,"mc":[{"id":"1.168096552","rc":[{"batl":[[1,20,1.68],[2,21,1.5]],"ltp":11.5,"tv":244.14,"id":26640937}]}]}
{"op":"mcm","clk":"992164306","pt":1580515327459,"mc":[{"id":"1.168096552","rc":[{"batl":[[1,21,1.5],[2,32,9.17]],"ltp":11.5,"tv":244.14,"id":26640937}]}]}
{"op":"mcm","clk":"992164312","pt":1580515327570,"mc":[{"id":"1.168096552","rc":[{"batl":[[2,30,1.85]],"ltp":11.5,"tv":244.14,"id":26640937}]}]}
{"op":"mcm","clk":"992165328","pt":1580515358832,"mc":[{"id":"1.168096552","rc":[{"batl":[[1,20,1.68],[2,21,1.5]],"ltp":11.5,"tv":244.14,"id":26640937}]}]}
{"op":"mcm","clk":"992166285","pt":1580515389843,"mc":[{"id":"1.168096552","rc":[{"batl":[[1,21,1.5],[2,30,1.85]],"ltp":11.5,"tv":244.14,"id":26640937}]}]}
{"op":"mcm","clk":"992167501","pt":1580515421458,"mc":[{"id":"1.168096552","rc":[{"batl":[[1,20,1.68],[2,21,1.5]],"ltp":11.5,"tv":244.14,"id":26640937}]}]}
{"op":"mcm","clk":"992168326","pt":1580515452895,"mc":[{"id":"1.168096552","rc":[{"batl":[[1,21,1.5],[2,30,1.85]],"ltp":11.5,"tv":244.14,"id":26640937}]}]}
{"op":"mcm","clk":"992169281","pt":1580515483448,"mc":[{"id":"1.168096552","rc":[{"trd":[[3.05,240.32]],"batb":[[0,3,156.82],[1,2.98,4],[2,2.96,2]],"batl":[[0,3.05,53.07],[1,3.1,66.92],[2,3.15,100]],"ltp":3.05,"tv":1840.97,"id":18286408},{"trd":[[2.88,205.4],[2.98,156.91]],"batb":[[0,2.86,15.61],[1,2.84,49.08],[2,2.82,7.61]],"batl":[[0,2.88,47.05],[1,3,19.64],[2,3.05,143.18]],"ltp":2.88,"tv":4444.53,"id":52106}],"tv":7683.72}]}
{"op":"mcm","clk":"992169314","pt":1580515484480,"mc":[{"id":"1.168096552","rc":[{"batl":[[1,3,10.37]],"ltp":2.88,"tv":4444.53,"id":52106}]}]}
{"op":"mcm","clk":"992169345","pt":1580515485256,"mc":[{"id":"1.168096552","rc":[{"batl":[[1,20,1.68],[2,21,1.5]],"ltp":11.5,"tv":244.14,"id":26640937}]}]}
{"op":"mcm","clk":"992169386","pt":1580515486233,"mc":[{"id":"1.168096552","rc":[{"trd":[[2.84,167.18],[2.86,188.1],[2.88,233.26]],"batb":[[0,2.84,48.76],[1,2.82,7.61],[2,2.76,6]],"batl":[[0,2.88,33.12]],"ltp":2.84,"tv":4476.4,"id":52106}],"tv":7715.58}]}
{"op":"mcm","clk":"992169434","pt":1580515487470,"mc":[{"id":"1.168096552","rc":[{"batl":[[0,5,45.56]],"ltp":4.6,"tv":1109.36,"id":21580749}]}]}
{"op":"mcm","clk":"992169494","pt":1580515489326,"mc":[{"id":"1.168096552","rc":[{"batb":[[1,11.5,24.31]],"ltp":11.5,"tv":244.14,"id":26640937},{"batl":[[0,4.9,7.5],[1,5,38.06],[2,5.1,20]],"ltp":4.6,"tv":1109.36,"id":21580749},{"trd":[[2.88,271.12]],"batl":[[0,2.88,14.19]],"ltp":2.88,"tv":4514.26,"id":52106}],"tv":7753.44}]}
{"op":"mcm","clk":"992169538","pt":1580515490361,"mc":[{"id":"1.168096552","rc":[{"batb":[[0,12,3.11],[2,11,2.8]],"ltp":11.5,"tv":244.14,"id":26640937},{"batl":[[0,4.8,7.5],[1,5,30]],"ltp":4.6,"tv":1109.36,"id":21580749}]}]}
{"op":"mcm","clk":"992169580","pt":1580515491444,"mc":[{"id":"1.168096552","rc":[{"trd":[[2.88,308.98]],"batl":[[0,2.88,4.74],[1,3.05,143.18],[2,3.1,2.36]],"ltp":2.88,"tv":4552.12,"id":52106}],"tv":7791.3}]}
{"op":"mcm","clk":"992169611","pt":1580515492473,"mc":[{"id":"1.168096552","rc":[{"trd":[[4.7,173.85]],"batl":[[0,5,30],[1,5.1,20],[2,5.3,9]],"ltp":4.7,"tv":1124.36,"id":21580749},{"batl":[[0,2.88,9.48]],"ltp":2.88,"tv":4552.12,"id":52106}],"tv":7806.3}]}
{"op":"mcm","clk":"992170028","pt":1580515506454,"mc":[{"id":"1.168096552","rc":[{"batb":[[0,12,24.58],[1,11.5,1.9]],"ltp":11.5,"tv":244.14,"id":26640937}]}]}
{"op":"mcm","clk":"992170285","pt":1580515515264,"mc":[{"id":"1.168096552","rc":[{"batl":[[1,20,9.18]],"ltp":11.5,"tv":244.14,"id":26640937}]}]}
{"op":"mcm","clk":"992170316","pt":1580515516495,"mc":[{"id":"1.168096552","rc":[{"batl":[[1,20,1.68]],"ltp":11.5,"tv":244.14,"id":26640937}]}]}
{"op":"mcm","clk":"992170320","pt":1580515516597,"mc":[{"id":"1.168096552","rc":[{"batl":[[1,19.5,7.5],[2,20,1.68]],"ltp":11.5,"tv":244.14,"id":26640937}]}]}
{"op":"mcm","clk":"992170356","pt":1580515518090,"mc":[{"id":"1.168096552","rc":[{"batl":[[1,19,7.5]],"ltp":11.5,"tv":244.14,"id":26640937}]}]}
{"op":"mcm","clk":"992170385","pt":1580515519479,"mc":[{"id":"1.168096552","rc":[{"batl":[[1,18.5,7.5]],"ltp":11.5,"tv":244.14,"id":26640937}]}]}
{"op":"mcm","clk":"992170450","pt":1580515521380,"mc":[{"id":"1.168096552","rc":[{"batl":[[1,18,7.5]],"ltp":11.5,"tv":244.14,"id":26640937}]}]}
{"op":"mcm","clk":"992170486","pt":1580515522469,"mc":[{"id":"1.168096552","rc":[{"trd":[[2.88,339.26]],"batb":[[0,2.84,48.77]],"batl":[[0,3.05,143.18],[1,3.1,2.36],[2,3.15,11.2]],"ltp":2.88,"tv":4582.39,"id":52106}],"tv":7836.58}]}
{"op":"mcm","clk":"992170514","pt":1580515523295,"mc":[{"id":"1.168096552","rc":[{"batl":[[1,17.5,7.5]],"ltp":11.5,"tv":244.14,"id":26640937},{"trd":[[2.88,339.27]],"batb":[[0,2.84,48.76]],"batl":[[0,2.88,11.31],[1,3.05,143.18],[2,3.1,2.36]],"ltp":2.88,"tv":4582.41,"id":52106}],"tv":7836.59}]}
{"op":"mcm","clk":"992170556","pt":1580515524168,"mc":[{"id":"1.168096552","rc":[{"batl":[[1,17,7.5]],"ltp":11.5,"tv":244.14,"id":26640937}]}]}
{"op":"mcm","clk":"992170597","pt":1580515525508,"mc":[{"id":"1.168096552","rc":[{"batl":[[1,16.5,7.5]],"ltp":11.5,"tv":244.14,"id":26640937}]}]}
{"op":"mcm","clk":"992170675","pt":1580515527464,"mc":[{"id":"1.168096552","rc":[{"batl":[[1,16,7.5]],"ltp":11.5,"tv":244.14,"id":26640937}]}]}
{"op":"mcm","clk":"992170707","pt":1580515528492,"mc":[{"id":"1.168096552","rc":[{"batl":[[1,15.5,7.5]],"ltp":11.5,"tv":244.14,"id":26640937},{"trd":[[2.88,369.56]],"batl":[[0,2.88,3.84]],"ltp":2.88,"tv":4612.7,"id":52106}],"tv":7866.88}]}
{"op":"mcm","clk":"992170735","pt":1580515529465,"mc":[{"id":"1.168096552","rc":[{"batl":[[0,15,10.55],[1,21,1.5],[2,32,9.17]],"ltp":11.5,"tv":244.14,"id":26640937},{"batl":[[0,2.88,7.68]],"ltp":2.88,"tv":4612.7,"id":52106}]}]}
{"op":"mcm","clk":"992170803","pt":1580515531375,"mc":[{"id":"1.168096552","rc":[{"trd":[[2.88,399.85]],"batl":[[0,2.88,14.93]],"ltp":2.88,"tv":4642.99,"id":52106}],"tv":7897.17}]}
{"op":"mcm","clk":"992170844","pt":1580515532716,"mc":[{"id":"1.168096552","rc":[{"batl":[[0,14.5,7.5],[1,15,3.05],[2,21,1.5]],"ltp":11.5,"tv":244.14,"id":26640937}]}]}
{"op":"mcm","clk":"992170879","pt":1580515534108,"mc":[{"id":"1.168096552","rc":[{"batl":[[0,14,7.5]],"ltp":11.5,"tv":244.14,"id":26640937}]}]}
{"op":"mcm","clk":"992170907","pt":1580515535390,"mc":[{"id":"1.168096552","rc":[{"batl":[[0,13.5,7.5]],"ltp":11.5,"tv":244.14,"id":26640937}]}]}
{"op":"mcm","clk":"992170944","pt":1580515536992,"mc":[{"id":"1.168096552","rc":[{"trd":[[13,4]],"batl":[[0,13,5.5]],"ltp":13.0,"tv":248.14,"id":26640937}],"tv":7901.17}]}
{"op":"mcm","clk":"992171061","pt":1580515541419,"mc":[{"id":"1.168096552","rc":[{"batb":[[0,12,3.11]],"ltp":13.0,"tv":248.14,"id":26640937}]}]}
{"op":"mcm","clk":"992171326","pt":1580515550395,"mc":[{"id":"1.168096552","rc":[{"batb":[[0,12,1.44]],"ltp":13.0,"tv":248.14,"id":26640937}]}]}
{"op":"mcm","clk":"992171578","pt":1580515560815,"mc":[{"id":"1.168096552","rc":[{"batl":[[0,2.86,7.44],[1,2.88,14.93],[2,3.05,143.18]],"ltp":2.88,"tv":4642.99,"id":52106}]}]}
{"op":"mcm","clk":"992171701","pt":1580515565167,"mc":[{"id":"1.168096552","rc":[{"batb":[[2,10.5,4.14]],"batl":[[1,15,1]],"ltp":13.0,"tv":248.14,"id":26640937}]}]}
{"op":"mcm","clk":"992172609","pt":1580515593485,"mc":[{"id":"1.168096552","rc":[{"trd":[[2.86,202.98]],"batb":[[0,2.84,48.89]],"batl":[[0,2.88,14.93],[1,3.05,143.18],[2,3.1,2.36]],"ltp":2.86,"tv":4657.87,"id":52106}],"tv":7916.06}]}
{"op":"mcm","clk":"992172663","pt":1580515595287,"mc":[{"id":"1.168096552","rc":[{"batb":[[0,2.84,48.76]],"ltp":2.86,"tv":4657.87,"id":52106}]}]}
{"op":"mcm","clk":"992188427","pt":1580515789433,"mc":[{"id":"1.168096552","rc":[{"batb":[[1,10.5,4.14],[2,10,5.17]],"ltp":13.0,"tv":248.14,"id":26640937}]}]}
{"op":"mcm","clk":"992188450","pt":1580515790411,"mc":[{"id":"1.168096552","rc":[{"batb":[[1,11,1.9],[2,10.5,4.14]],"ltp":13.0,"tv":248.14,"id":26640937}]}]}
{"op":"mcm","clk":"992192255","pt":1580515932483,"mc":[{"id":"1.168096552","rc":[{"batl":[[0,5,33.5]],"ltp":4.7,"tv":1124.36,"id":21580749}]}]}
{"op":"mcm","clk":"992192293","pt":1580515934484,"mc":[{"id":"1.168096552","rc":[{"batl":[[0,4.9,3.5],[1,5,30],[2,5.1,20]],"ltp":4.7,"tv":1124.36,"id":21580749}]}]}
{"op":"mcm","clk":"992192314","pt":1580515935304,"mc":[{"id":"1.168096552","rc":[{"batl":[[0,4.8,3.5]],"ltp":4.7,"tv":1124.36,"id":21580749}]}]}
{"op":"mcm","clk":"992192339","pt":1580515936488,"mc":[{"id":"1.168096552","rc":[{"trd":[[4.8,58.41]],"batl":[[0,5,30],[1,5.1,20],[2,5.3,9]],"ltp":4.8,"tv":1131.37,"id":21580749}],"tv":7923.06}]}
{"op":"mcm","clk":"992193343","pt":1580515979814,"mc":[{"id":"1.168096552","rc":[{"trd":[[3,192.37]],"batb":[[0,2.98,4],[1,2.96,2],[2,2.9,13.44]],"batl":[[0,3,8.13],[1,3.05,53.07],[2,3.1,66.92]],"ltp":3.0,"tv":1845.74,"id":18286408}],"tv":7927.84}]}
{"op":"mcm","clk":"992193397","pt":1580515981355,"mc":[{"id":"1.168096552","rc":[{"batb":[[2,2.88,39]],"ltp":3.0,"tv":1845.74,"id":18286408}]}]}
{"op":"mcm","clk":"992193693","pt":1580515991460,"mc":[{"id":"1.168096552","rc":[{"batb":[[2,2.88,36]],"ltp":3.0,"tv":1845.74,"id":18286408}]}]}
{"op":"mcm","clk":"992193847","pt":1580515997352,"mc":[{"id":"1.168096552","rc":[{"batb":[[1,11,25.33]],"ltp":13.0,"tv":248.14,"id":26640937},{"batb":[[0,4.7,75.25],[1,4.6,36.8],[2,4.5,27.25]],"ltp":4.8,"tv":1131.37,"id":21580749}]}]}
{"op":"mcm","clk":"992194205","pt":1580516010473,"mc":[{"id":"1.168096552","rc":[{"trd":[[3,208.58]],"batl":[[0,3.05,53.09],[1,3.1,66.92],[2,3.15,100]],"ltp":3.0,"tv":1861.96,"id":18286408}],"tv":7944.05}]}
{"op":"mcm","clk":"992194211","pt":1580516010677,"mc":[{"id":"1.168096552","rc":[{"trd":[[3,208.62]],"batl":[[0,3.05,53.07]],"ltp":3.0,"tv":1862.0,"id":18286408}],"tv":7944.09}]}
{"op":"mcm","clk":"992195213","pt":1580516057124,"mc":[{"id":"1.168096552","rc":[{"trd":[[3.05,345.72]],"batl":[[0,3.1,67.26],[1,3.15,100],[2,3.2,22]],"ltp":3.05,"tv":1967.4,"id":18286408}],"tv":8049.5}]}
{"op":"mcm","clk":"992195283","pt":1580516060998,"mc":[{"id":"1.168096552","rc":[{"batb":[[2,2.88,39]],"ltp":3.05,"tv":1967.4,"id":18286408}]}]}
{"op":"mcm","clk":"992195370","pt":1580516067428,"mc":[{"id":"1.168096552","rc":[{"batb":[[1,11,1.9]],"ltp":13.0,"tv":248.14,"id":26640937},{"batb":[[0,4.6,36.8],[1,4.5,27.25],[2,4.3,4.21]],"ltp":4.8,"tv":1131.37,"id":21580749}]}]}
{"op":"mcm","clk":"992195374","pt":1580516067587,"mc":[{"id":"1.168096552","rc":[{"batb":[[1,4.5,30.68]],"ltp":4.8,"tv":1131.37,"id":21580749}]}]}
{"op":"mcm","clk":"992195525","pt":1580516075828,"mc":[{"id":"1.168096552","rc":[{"trd":[[12,2.88]],"batb":[[0,11,1.9],[1,10.5,4.14],[2,10,5.17]],"batl":[[0,13,6.06]],"ltp":12.0,"tv":251.02,"id":26640937},{"batb":[[1,4.5,27.25]],"ltp":4.8,"tv":1131.37,"id":21580749}],"tv":8052.37}]}
{"op":"mcm","clk":"992195573","pt":1580516078506,"mc":[{"id":"1.168096552","rc":[{"batb":[[0,2.86,6.02],[1,2.84,48.76],[2,2.82,7.61]],"ltp":2.86,"tv":4657.87,"id":52106}]}]}
{"op":"mcm","clk":"992195833","pt":1580516097022,"mc":[{"id":"1.168096552","rc":[{"trd":[[2.86,210.56]],"batb":[[0,2.86,2.23]],"ltp":2.86,"tv":4665.44,"id":52106}],"tv":8059.95}]}
{"op":"mcm","clk":"992195982","pt":1580516102456,"mc":[{"id":"1.168096552","rc":[{"batb":[[0,11,25.33]],"ltp":12.0,"tv":251.02,"id":26640937},{"batb":[[0,4.7,75.25],[1,4.6,36.8],[2,4.5,27.25]],"ltp":4.8,"tv":1131.37,"id":21580749}]}]}
{"op":"mcm","clk":"992196000","pt":1580516103133,"mc":[{"id":"1.168096552","rc":[{"batb":[[0,3,5.74],[1,2.98,4],[2,2.96,2]],"ltp":3.05,"tv":1967.4,"id":18286408}]}]}
{"op":"mcm","clk":"992196299","pt":1580516116252,"mc":[{"id":"1.168096552","rc":[{"batb":[[0,3,99.44]],"ltp":3.05,"tv":1967.4,"id":18286408}]}]}
{"op":"mcm","clk":"992196341","pt":1580516119350,"mc":[{"id":"1.168096552","rc":[{"batb":[[0,11,1.9]],"ltp":12.0,"tv":251.02,"id":26640937},{"batb":[[0,4.6,36.8],[1,4.5,27.25],[2,4.3,4.21]],"ltp":4.8,"tv":1131.37,"id":21580749}]}]}
{"op":"mcm","clk":"992196343","pt":1580516119559,"mc":[{"id":"1.168096552","rc":[{"batb":[[2,10,7.81]],"ltp":12.0,"tv":251.02,"id":26640937},{"batb":[[1,4.5,30.68]],"ltp":4.8,"tv":1131.37,"id":21580749}]}]}
{"op":"mcm","clk":"992196576","pt":1580516129460,"mc":[{"id":"1.168096552","rc":[{"trd":[[2.88,415]],"batl":[[0,2.88,7.36]],"ltp":2.88,"tv":4680.59,"id":52106}],"tv":8075.09}]}
{"op":"mcm","clk":"992196766","pt":1580516137399,"mc":[{"id":"1.168096552","rc":[{"batl":[[1,3,68.15],[2,3.05,143.18]],"ltp":2.88,"tv":4680.59,"id":52106}]}]}
{"op":"mcm","clk":"992197025","pt":1580516146496,"mc":[{"id":"1.168096552","rc":[{"batl":[[1,3,136.3]],"ltp":2.88,"tv":4680.59,"id":52106}]}]}
{"op":"mcm","clk":"992197101","pt":1580516149217,"mc":[{"id":"1.168096552","rc":[{"batb":[[2,10,5.17]],"ltp":12.0,"tv":251.02,"id":26640937},{"batb":[[1,4.5,27.25]],"ltp":4.8,"tv":1131.37,"id":21580749}]}]}
{"op":"mcm","clk":"992197527","pt":1580516165096,"mc":[{"id":"1.168096552","rc":[{"trd":[[2.88,429.72]],"batl":[[0,2.98,10.42]],"ltp":2.88,"tv":4695.31,"id":52106}],"tv":8089.82}]}
{"op":"mcm","clk":"992197572","pt":1580516166598,"mc":[{"id":"1.168096552","rc":[{"batl":[[0,2.96,9.39],[1,2.98,10.42],[2,3,136.3]],"ltp":2.88,"tv":4695.31,"id":52106}]}]}
{"op":"mcm","clk":"992197626","pt":1580516168514,"mc":[{"id":"1.168096552","rc":[{"trd":[[2.96,231.62]],"batl":[[0,2.96,2.58]],"ltp":2.96,"tv":4708.94,"id":52106}],"tv":8103.45}]}
{"op":"mcm","clk":"992197659","pt":1580516169498,"mc":[{"id":"1.168096552","rc":[{"trd":[[2.96,236.78]],"batb":[[0,2.96,4.99],[1,2.86,2.23],[2,2.84,48.76]],"batl":[[0,2.98,10.42],[1,3,136.3],[2,3.05,143.18]],"ltp":2.96,"tv":4714.11,"id":52106}],"tv":8108.61}]}
{"op":"mcm","clk":"992197684","pt":1580516170216,"mc":[{"id":"1.168096552","rc":[{"trd":[[2.96,246.76]],"batb":[[0,2.86,2.23],[1,2.84,48.76],[2,2.82,7.61]],"batl":[[0,2.96,9.98],[1,2.98,10.42],[2,3,136.3]],"ltp":2.96,"tv":4724.09,"id":52106}],"tv":8118.59}]}
{"op":"mcm","clk":"992197704","pt":1580516171200,"mc":[{"id":"1.168096552","rc":[{"trd":[[2.96,260.39]],"batl":[[0,2.96,3.17]],"ltp":2.96,"tv":4737.72,"id":52106}],"tv":8132.22}]}
{"op":"mcm","clk":"992197757","pt":1580516173424,"mc":[{"id":"1.168096552","rc":[{"batl":[[1,2.98,78.57],[2,3,68.15]],"ltp":2.96,"tv":4737.72,"id":52106}]}]}
{"op":"mcm","clk":"992197831","pt":1580516176217,"mc":[{"id":"1.168096552","rc":[{"trd":[[2.96,411.85],[2.98,177.75]],"batl":[[0,2.98,68.15],[1,3,68.15],[2,3.05,143.18]],"ltp":2.98,"tv":4910.01,"id":52106}],"tv":8304.51}]}
{"op":"mcm","clk":"992197867","pt":1580516177510,"mc":[{"id":"1.168096552","rc":[{"batl":[[0,2.96,4.41],[1,2.98,68.15],[2,3,68.15]],"ltp":2.98,"tv":4910.01,"id":52106}]}]}
{"op":"mcm","clk":"992197875","pt":1580516177718,"mc":[{"id":"1.168096552","rc":[{"batl":[[0,2.96,8.81]],"ltp":2.98,"tv":4910.01,"id":52106}]}]}
{"op":"mcm","clk":"992197931","pt":1580516180250,"mc":[{"id":"1.168096552","rc":[{"trd":[[4.7,190.55]],"batl":[[0,4.7,54.15],[1,5,30],[2,5.1,20]],"ltp":4.7,"tv":1148.07,"id":21580749},{"batl":[[1,3,136.3],[2,3.05,143.18]],"ltp":2.98,"tv":4910.01,"id":52106}],"tv":8321.21}]}
{"op":"mcm","clk":"992198154","pt":1580516189454,"mc":[{"id":"1.168096552","rc":[{"batb":[[0,11,25.33]],"ltp":12.0,"tv":251.02,"id":26640937},{"batb":[[0,2.86,90.79]],"ltp":2.98,"tv":4910.01,"id":52106}]}]}
{"op":"mcm","clk":"992198167","pt":1580516190163,"mc":[{"id":"1.168096552","rc":[{"batb":[[0,2.88,29.44],[1,2.86,90.79],[2,2.84,48.76]],"ltp":2.98,"tv":4910.01,"id":52106}]}]}
{"op":"mcm","clk":"992198693","pt":1580516207366,"mc":[{"id":"1.168096552","rc":[{"batb":[[0,11,1.9]],"ltp":12.0,"tv":251.02,"id":26640937},{"batb":[[1,2.86,2.23]],"ltp":2.98,"tv":4910.01,"id":52106}]}]}
{"op":"mcm","clk":"992198710","pt":1580516208143,"mc":[{"id":"1.168096552","rc":[{"batb":[[0,2.88,10.78]],"ltp":2.98,"tv":4910.01,"id":52106}]}]}
{"op":"mcm","clk":"992202247","pt":1580516366041,"mc":[{"id":"1.168096552","rc":[{"batl":[[0,12.5,3.56],[1,13,5.5],[2,15,1]],"ltp":12.0,"tv":251.02,"id":26640937}]}]}
{"op":"mcm","clk":"992202532","pt":1580516382467,"mc":[{"id":"1.168096552","rc":[{"batb":[[0,11,25.33]],"ltp":12.0,"tv":251.02,"id":26640937}]}]}
{"op":"mcm","clk":"992202537","pt":1580516382651,"mc":[{"id":"1.168096552","rc":[{"batb":[[0,11.5,1.5],[1,11,25.33],[2,10.5,4.14]],"ltp":12.0,"tv":251.02,"id":26640937}]}]}
{"op":"mcm","clk":"992202605","pt":1580516385947,"mc":[{"id":"1.168096552","rc":[{"trd":[[11,154.98],[11.5,3.16]],"batb":[[0,11,24.83],[1,10.5,4.14],[2,10,5.17]],"ltp":11.0,"tv":255.02,"id":26640937}],"tv":8325.21}]}
{"op":"mcm","clk":"992202904","pt":1580516406186,"mc":[{"id":"1.168096552","rc":[{"batb":[[0,3,101.12]],"ltp":3.05,"tv":1967.4,"id":18286408},{"batb":[[0,2.88,12.46]],"ltp":2.98,"tv":4910.01,"id":52106}]}]}
{"op":"mcm","clk":"992203182","pt":1580516423301,"mc":[{"id":"1.168096552","rc":[{"batl":[[0,13,6.06],[1,14.5,3]],"ltp":11.0,"tv":255.02,"id":26640937}]}]}
{"op":"mcm","clk":"992203597","pt":1580516441445,"mc":[{"id":"1.168096552","rc":[{"batb":[[0,11,1.39]],"ltp":11.0,"tv":255.02,"id":26640937}]}]}
{"op":"mcm","clk":"992203610","pt":1580516441714,"mc":[{"id":"1.168096552","rc":[{"batb":[[2,10,7.81]],"ltp":11.0,"tv":255.02,"id":26640937}]}]}
{"op":"mcm","clk":"992204395","pt":1580516471290,"mc":[{"id":"1.168096552","rc":[{"batb":[[2,10,5.17]],"ltp":11.0,"tv":255.02,"id":26640937}]}]}
{"op":"mcm","clk":"992219516","pt":1580516687030,"mc":[{"id":"1.168096552","rc":[{"trd":[[4.6,179.57]],"batb":[[0,4.6,18.27]],"ltp":4.6,"tv":1185.12,"id":21580749}],"tv":8362.27}]}
{"op":"mcm","clk":"992221393","pt":1580516755446,"mc":[{"id":"1.168096552","rc":[{"trd":[[4.7,194.55]],"batl":[[0,4.7,52.15]],"ltp":4.7,"tv":1189.12,"id":21580749}],"tv":8366.27}]}
{"op":"mcm","clk":"992222426","pt":1580516802711,"mc":[{"id":"1.168096552","rc":[{"trd":[[4.7,260.55]],"batl":[[0,4.7,19.15]],"ltp":4.7,"tv":1255.12,"id":21580749}],"tv":8432.27}]}
{"op":"mcm","clk":"992224755","pt":1580516897402,"mc":[{"id":"1.168096552","rc":[{"trd":[[4.7,298.85]],"batb":[[0,4.7,3.66],[1,4.6,18.27],[2,4.5,27.25]],"batl":[[0,5,30],[1,5.1,23.11],[2,5.3,9]],"ltp":4.7,"tv":1293.42,"id":21580749}],"tv":8470.57}]}
{"op":"mcm","clk":"992224773","pt":1580516898223,"mc":[{"id":"1.168096552","rc":[{"trd":[[4.6,192.25],[4.7,306.17]],"batb":[[0,4.6,11.93],[1,4.5,27.25],[2,4.3,4.21]],"ltp":4.6,"tv":1313.43,"id":21580749}],"tv":8490.57}]}
{"op":"mcm","clk":"992225040","pt":1580516909445,"mc":[{"id":"1.168096552","rc":[{"batl":[[0,4.9,4],[1,5,30],[2,5.1,23.11]],"ltp":4.6,"tv":1313.43,"id":21580749}]}]}
{"op":"mcm","clk":"992225507","pt":1580516927050,"mc":[{"id":"1.168096552","rc":[{"batl":[[2,5.1,20]],"ltp":4.6,"tv":1313.43,"id":21580749}]}]}
{"op":"mcm","clk":"992227083","pt":1580516991273,"mc":[{"id":"1.168096552","rc":[{"batl":[[1,3,68.15]],"ltp":2.98,"tv":4910.01,"id":52106}]}]}
{"op":"mcm","clk":"992227481","pt":1580517003666,"mc":[{"id":"1.168096552","rc":[{"batl":[[1,3,117.37]],"ltp":2.98,"tv":4910.01,"id":52106}]}]}
{"op":"mcm","clk":"992228021","pt":1580517017417,"mc":[{"id":"1.168096552","rc":[{"batb":[[0,4.6,15.11]],"ltp":4.6,"tv":1313.43,"id":21580749}]}]}
{"op":"mcm","clk":"992231677","pt":1580517122411,"mc":[{"id":"1.168096552","rc":[{"trd":[[3,228.62]],"batb":[[0,3,91.13]],"ltp":3.0,"tv":1987.4,"id":18286408}],"tv":8510.56}]}
{"op":"mcm","clk":"992231722","pt":1580517124006,"mc":[{"id":"1.168096552","rc":[{"batb":[[0,2.9,5.94],[1,2.88,12.46]],"ltp":2.98,"tv":4910.01,"id":52106}]}]}
{"op":"mcm","clk":"992231983","pt":1580517130301,"mc":[{"id":"1.168096552","rc":[{"trd":[[2.96,429.47]],"batb":[[1,2.88,1.68]],"batl":[[0,3,117.37],[1,3.05,143.18],[2,3.1,2.36]],"ltp":2.96,"tv":4927.63,"id":52106}],"tv":8528.19}]}
{"op":"mcm","clk":"992232133","pt":1580517134495,"mc":[{"id":"1.168096552","rc":[{"batl":[[0,2.98,4],[1,3,117.37],[2,3.05,143.18]],"ltp":2.96,"tv":4927.63,"id":52106}]}]}
{"op":"mcm","clk":"992232155","pt":1580517135216,"mc":[{"id":"1.168096552","rc":[{"batl":[[0,2.98,72.15],[1,3,49.22]],"ltp":2.96,"tv":4927.63,"id":52106}]}]}
{"op":"mcm","clk":"992232270","pt":1580517137433,"mc":[{"id":"1.168096552","rc":[{"trd":[[2.98,322.05]],"batl":[[0,3,49.22],[1,3.05,143.18],[2,3.1,2.36]],"ltp":2.98,"tv":5071.93,"id":52106}],"tv":8672.48}]}
{"op":"mcm","clk":"992232646","pt":1580517152938,"mc":[{"id":"1.168096552","rc":[{"batb":[[1,2.88,3.74]],"batl":[[0,2.98,1.99],[1,3,49.22],[2,3.05,143.18]],"ltp":2.98,"tv":5071.93,"id":52106}]}]}
{"op":"mcm","clk":"992232716","pt":1580517155832,"mc":[{"id":"1.168096552","rc":[{"batl":[[1,3.15,102]],"ltp":3.0,"tv":1987.4,"id":18286408}]}]}
{"op":"mcm","clk":"992232747","pt":1580517157435,"mc":[{"id":"1.168096552","rc":[{"batb":[[0,2.92,4.08],[1,2.9,5.94],[2,2.88,3.74]],"ltp":2.98,"tv":5071.93,"id":52106}]}]}
{"op":"mcm","clk":"992232950","pt":1580517165481,"mc":[{"id":"1.168096552","rc":[{"trd":[[3.05,346.4]],"batb":[[0,3.05,1.34],[1,3,91.13],[2,2.98,4]],"batl":[[0,3.1,66.92]],"ltp":3.05,"tv":1988.07,"id":18286408},{"batb":[[0,4.7,1.68],[1,4.6,15.11],[2,4.5,27.25]],"ltp":4.6,"tv":1313.43,"id":21580749},{"batb":[[1,2.9,7.62]],"ltp":2.98,"tv":5071.93,"id":52106}],"tv":8673.16}]}
{"op":"mcm","clk":"992233471","pt":1580517184419,"mc":[{"id":"1.168096552","rc":[{"batb":[[2,2.88,1.68]],"batl":[[0,3,49.22],[1,3.05,143.18],[2,3.1,2.36]],"ltp":2.98,"tv":5071.93,"id":52106}]}]}
{"op":"mcm","clk":"992236126","pt":1580517276552,"mc":[{"id":"1.168096552","rc":[{"trd":[[4.9,28]],"batb":[[0,4.7,1.88]],"batl":[[0,5,30],[1,5.1,20],[2,5.3,9]],"ltp":4.9,"tv":1321.43,"id":21580749}],"tv":8681.16}]}
{"op":"mcm","clk":"992236145","pt":1580517277534,"mc":[{"id":"1.168096552","rc":[{"batl":[[1,3.15,100]],"ltp":3.05,"tv":1988.07,"id":18286408}]}]}
{"op":"mcm","clk":"992236331","pt":1580517285472,"mc":[{"id":"1.168096552","rc":[{"batb":[[0,4.8,4.28],[1,4.7,1.68],[2,4.6,15.11]],"ltp":4.9,"tv":1321.43,"id":21580749}]}]}
{"op":"mcm","clk":"992237463","pt":1580517323701,"mc":[{"id":"1.168096552","rc":[{"batb":[[1,4.7,5.53]],"ltp":4.9,"tv":1321.43,"id":21580749}]}]}
{"op":"mcm","clk":"992237770","pt":1580517333924,"mc":[{"id":"1.168096552","rc":[{"trd":[[5,0.4]],"batb":[[0,4.8,4.08]],"batl":[[0,5,29.8]],"ltp":5.0,"tv":1321.83,"id":21580749}],"tv":8681.56}]}
{"op":"mcm","clk":"992239993","pt":1580517412621,"mc":[{"id":"1.168096552","rc":[{"trd":[[3,334.69]],"batl":[[0,3,44.34]],"ltp":3.0,"tv":5081.69,"id":52106}],"tv":8691.32}]}
{"op":"mcm","clk":"992250994","pt":1580517452415,"mc":[{"id":"1.168096552","rc":[{"batb":[[0,2.94,5.86],[1,2.92,4.08],[2,2.9,1.68]],"ltp":3.0,"tv":5081.69,"id":52106}]}]}
{"op":"mcm","clk":"992251111","pt":1580517459510,"mc":[{"id":"1.168096552","rc":[{"batb":[[0,2.96,4.03],[1,2.94,5.86]],"ltp":3.0,"tv":5081.69,"id":52106}]}]}
{"op":"mcm","clk":"992253313","pt":1580517584430,"mc":[{"id":"1.168096552","rc":[{"batl":[[0,48,5],[1,640,1.88],[2,650,9]],"ltp":36.0,"tv":7.99,"id":27706761}]}]}
{"op":"mcm","clk":"992253355","pt":1580517586444,"mc":[{"id":"1.168096552","rc":[{"batb":[[2,30,2]],"batl":[[1,640,1.68]],"ltp":36.0,"tv":7.99,"id":27706761}]}]}
{"op":"mcm","clk":"992253379","pt":1580517587430,"mc":[{"id":"1.168096552","rc":[{"batb":[[1,34,1.84]],"ltp":36.0,"tv":7.99,"id":27706761}]}]}
{"op":"mcm","clk":"992253480","pt":1580517593148,"mc":[{"id":"1.168096552","rc":[{"trd":[[3,264.56],[3.05,349.09]],"batb":[[0,3,73.17],[1,2.98,4],[2,2.96,2]],"ltp":3.0,"tv":2026.7,"id":18286408}],"tv":8729.95}]}
{"op":"mcm","clk":"992253501","pt":1580517594339,"mc":[{"id":"1.168096552","rc":[{"batb":[[0,3.05,1.68],[1,3,73.17],[2,2.98,4]],"ltp":3.0,"tv":2026.7,"id":18286408}]}]}
{"op":"mcm","clk":"992253738","pt":1580517603458,"mc":[{"id":"1.168096552","rc":[{"batb":[[0,2.98,5.78],[1,2.96,4.03]],"ltp":3.0,"tv":5081.69,"id":52106}]}]}
{"op":"mcm","clk":"992253756","pt":1580517604383,"mc":[{"id":"1.168096552","rc":[{"trd":[[4.8,58.71]],"batb":[[0,4.8,3.93]],"ltp":4.8,"tv":1322.13,"id":21580749},{"trd":[[2.98,322.35]],"batb":[[0,2.98,5.63]],"ltp":2.98,"tv":5081.99,"id":52106}],"tv":8730.55}]}
{"op":"mcm","clk":"992253798","pt":1580517606453,"mc":[{"id":"1.168096552","rc":[{"trd":[[2.98,322.65]],"batb":[[0,2.98,5.48]],"ltp":2.98,"tv":5082.29,"id":52106}],"tv":8730.85}]}
{"op":"mcm","clk":"992253834","pt":1580517607172,"mc":[{"id":"1.168096552","rc":[{"batl":[[0,46,1.68],[1,48,5]],"ltp":36.0,"tv":7.99,"id":27706761}]}]}
{"op":"mcm","clk":"992254045","pt":1580517617505,"mc":[{"id":"1.168096552","rc":[{"trd":[[36,7.58]],"batb":[[0,34,1.84],[1,30,2],[2,20,1.68]],"batl":[[0,46,1.97]],"ltp":36.0,"tv":12.45,"id":27706761}],"tv":8735.31}]}
{"op":"mcm","clk":"992254918","pt":1580517651440,"mc":[{"id":"1.168096552","rc":[{"trd":[[3.1,306.74]],"batl":[[0,3.1,41.7]],"ltp":3.1,"tv":2077.14,"id":18286408},{"trd":[[12,4],[13,15]],"batl":[[0,14.5,3],[1,15,1],[2,21,1.5]],"ltp":13.0,"tv":267.14,"id":26640937},{"trd":[[5,31.66]],"batl":[[0,5,14.17]],"ltp":5.0,"tv":1353.39,"id":21580749},{"trd":[[3,386.8]],"batl":[[0,3,18.29]],"ltp":3.0,"tv":5134.41,"id":52106},{"trd":[[21,18.78],[22,5.19]],"batb":[[0,13,8.32],[1,9.4,7.91],[2,9.2,4.59]],"batl":[[0,21,19.33],[1,55,3.33],[2,140,9]],"ltp":21.0,"tv":58.04,"id":24608298}],"tv":8902.59}]}
{"op":"mcm","clk":"992254928","pt":1580517651952,"mc":[{"id":"1.168096552","rc":[{"trd":[[36,8.16]],"batl":[[0,46,1.68]],"ltp":36.0,"tv":13.03,"id":27706761}],"tv":8903.17}]}
{"op":"mcm","clk":"992254960","pt":1580517653236,"mc":[{"id":"1.168096552","rc":[{"batb":[[0,13,2.31]],"ltp":21.0,"tv":58.04,"id":24608298}]}]}
{"op":"mcm","clk":"992254985","pt":1580517654370,"mc":[{"id":"1.168096552","rc":[{"batb":[[1,9.4,1.87]],"ltp":21.0,"tv":58.04,"id":24608298}]}]}
{"op":"mcm","clk":"992255042","pt":1580517655966,"mc":[{"id":"1.168096552","rc":[{"batb":[[0,13,2.4]],"batl":[[1,55,3.38]],"ltp":21.0,"tv":58.04,"id":24608298}]}]}
{"op":"mcm","clk":"992255117","pt":1580517659478,"mc":[{"id":"1.168096552","rc":[{"batb":[[1,9.2,4.59],[2,9,10]],"ltp":21.0,"tv":58.04,"id":24608298}]}]}
{"op":"mcm","clk":"992255181","pt":1580517662411,"mc":[{"id":"1.168096552","rc":[{"batb":[[0,11,24.83]],"ltp":13.0,"tv":267.14,"id":26640937},{"batb":[[1,30,18.39]],"ltp":36.0,"tv":13.03,"id":27706761},{"batb":[[0,2.98,90.47]],"ltp":3.0,"tv":5134.41,"id":52106},{"batb":[[1,9.4,38.79],[2,9.2,4.59]],"ltp":21.0,"tv":58.04,"id":24608298}]}]}
{"op":"mcm","clk":"992255220","pt":1580517664369,"mc":[{"id":"1.168096552","rc":[{"batb":[[0,2.98,108.5]],"ltp":3.0,"tv":5134.41,"id":52106}]}]}
{"op":"mcm","clk":"992255247","pt":1580517665397,"mc":[{"id":"1.168096552","rc":[{"batb":[[2,2.88,1.68]],"ltp":3.0,"tv":5134.41,"id":52106},{"batb":[[1,9.6,1.84],[2,9.4,38.79]],"ltp":21.0,"tv":58.04,"id":24608298}]}]}
{"op":"mcm","clk":"992255278","pt":1580517667416,"mc":[{"id":"1.168096552","rc":[{"batl":[[2,240,9]],"ltp":36.0,"tv":13.03,"id":27706761}]}]}
{"op":"mcm","clk":"992255347","pt":1580517670512,"mc":[{"id":"1.168096552","rc":[{"batb":[[0,11.5,1.54],[1,11,24.83],[2,10.5,4.14]],"ltp":13.0,"tv":267.14,"id":26640937},{"batb":[[1,30,18.95]],"ltp":36.0,"tv":13.03,"id":27706761},{"trd":[[3,390.16]],"batl":[[0,3,16.61]],"ltp":3.0,"tv":5137.77,"id":52106}],"tv":8906.53}]}
{"op":"mcm","clk":"992255385","pt":1580517672521,"mc":[{"id":"1.168096552","rc":[{"batb":[[1,11,30.46]],"batl":[[0,14,4.43],[1,14.5,3],[2,15,1]],"ltp":13.0,"tv":267.14,"id":26640937}]}]}
{"op":"mcm","clk":"992255424","pt":1580517675502,"mc":[{"id":"1.168096552","rc":[{"batb":[[1,3,100.22]],"ltp":3.1,"tv":2077.14,"id":18286408},{"batb":[[0,11.5,8.59]],"ltp":13.0,"tv":267.14,"id":26640937},{"batb":[[1,4.7,22.8]],"ltp":5.0,"tv":1353.39,"id":21580749},{"trd":[[3,393.53]],"batb":[[0,2.98,135.73]],"batl":[[0,3,14.93]],"ltp":3.0,"tv":5141.13,"id":52106}],"tv":8909.89}]}
{"op":"mcm","clk":"992255445","pt":1580517676330,"mc":[{"id":"1.168096552","rc":[{"batb":[[0,4.8,12.38]],"ltp":5.0,"tv":1353.39,"id":21580749},{"batb":[[1,32,3.09],[2,30,18.39]],"ltp":36.0,"tv":13.03,"id":27706761},{"batb":[[1,9.8,8.28],[2,9.6,1.84]],"ltp":21.0,"tv":58.04,"id":24608298}]}]}
{"op":"mcm","clk":"992255466","pt":1580517677417,"mc":[{"id":"1.168096552","rc":[{"batb":[[0,2.98,137.73]],"ltp":3.0,"tv":5141.13,"id":52106}]}]}
{"op":"mcm","clk":"992255505","pt":1580517679419,"mc":[{"id":"1.168096552","rc":[{"batb":[[0,12,21.48],[1,11.5,8.59],[2,11,7.03]],"ltp":13.0,"tv":267.14,"id":26640937},{"batb":[[0,34,16.3],[2,30,2]],"ltp":36.0,"tv":13.03,"id":27706761},{"trd":[[3,423.36]],"batb":[[0,3,69.51],[1,2.98,52.74],[2,2.96,4.03]],"batl":[[0,3.05,143.18],[1,3.1,2.36],[2,3.15,11.2]],"ltp":3.0,"tv":5170.97,"id":52106},{"batb":[[1,10,45.08],[2,9.8,8.28]],"ltp":21.0,"tv":58.04,"id":24608298}],"tv":8939.73}]}
{"op":"mcm","clk":"992255552","pt":1580517682111,"mc":[{"id":"1.168096552","rc":[{"batb":[[1,11.5,7.06]],"ltp":13.0,"tv":267.14,"id":26640937},{"batb":[[1,4.7,21.12]],"ltp":5.0,"tv":1353.39,"id":21580749},{"batb":[[1,32,2.54]],"ltp":36.0,"tv":13.03,"id":27706761},{"trd":[[3.05,71.15]],"batl":[[0,3.05,140.7]],"ltp":3.05,"tv":5175.92,"id":52106}],"tv":8944.69}]}
{"op":"mcm","clk":"992255669","pt":1580517687419,"mc":[{"id":"1.168096552","rc":[{"batb":[[0,3.05,5.88]],"ltp":3.1,"tv":2077.14,"id":18286408},{"batb":[[0,12.5,8.13],[1,12,21.48],[2,11.5,7.06]],"ltp":13.0,"tv":267.14,"id":26640937},{"batb":[[0,4.9,5.04],[1,4.8,12.38],[2,4.7,21.12]],"ltp":5.0,"tv":1353.39,"id":21580749},{"batb":[[0,36,5.53],[1,34,16.3],[2,32,2.54]],"ltp":36.0,"tv":13.03,"id":27706761},{"batb":[[0,3,77.91]],"ltp":3.05,"tv":5175.92,"id":52106},{"batb":[[1,10.5,1.68],[2,10,45.08]],"ltp":21.0,"tv":58.04,"id":24608298}]}]}
{"op":"mcm","clk":"992255748","pt":1580517691442,"mc":[{"id":"1.168096552","rc":[{"trd":[[3,574.74]],"batb":[[0,3,2.26]],"ltp":3.0,"tv":5327.3,"id":52106},{"batb":[[1,11,1.82],[2,10.5,1.68]],"ltp":21.0,"tv":58.04,"id":24608298}],"tv":9096.06}]}
{"op":"mcm","clk":"992255762","pt":1580517692113,"mc":[{"id":"1.168096552","rc":[{"trd":[[3.05,263.67]],"batb":[[0,3,12.72]],"batl":[[0,3.05,44.44]],"ltp":3.05,"tv":5519.82,"id":52106}],"tv":9288.58}]}
{"op":"mcm","clk":"992255779","pt":1580517693140,"mc":[{"id":"1.168096552","rc":[{"batb":[[1,2.98,34.71]],"ltp":3.05,"tv":5519.82,"id":52106}]}]}
{"op":"mcm","clk":"992255830","pt":1580517697422,"mc":[{"id":"1.168096552","rc":[{"batb":[[1,11.5,7.06],[2,11,7.03]],"ltp":13.0,"tv":267.14,"id":26640937},{"batb":[[1,34,1.84]],"ltp":36.0,"tv":13.03,"id":27706761}]}]}
{"op":"mcm","clk":"992255848","pt":1580517698346,"mc":[{"id":"1.168096552","rc":[{"trd":[[3.1,327.2]],"batb":[[0,3.05,107.88]],"batl":[[0,3.1,31.47]],"ltp":3.1,"tv":2097.6,"id":18286408},{"batb":[[0,12.5,1.41]],"ltp":13.0,"tv":267.14,"id":26640937},{"batb":[[0,4.9,77.22]],"ltp":5.0,"tv":1353.39,"id":21580749},{"batb":[[0,38,12.94],[1,36,5.53],[2,34,1.84]],"ltp":36.0,"tv":13.03,"id":27706761},{"batb":[[1,11,34.97]],"ltp":21.0,"tv":58.04,"id":24608298}],"tv":9309.04}]}
{"op":"mcm","clk":"992255893","pt":1580517701449,"mc":[{"id":"1.168096552","rc":[{"batb":[[2,34,1.81]],"ltp":36.0,"tv":13.03,"id":27706761}]}]}
{"op":"mcm","clk":"992255911","pt":1580517702427,"mc":[{"id":"1.168096552","rc":[{"batb":[[0,40,4.2],[1,38,12.94],[2,34,2.32]],"ltp":36.0,"tv":13.03,"id":27706761}]}]}
{"op":"mcm","clk":"992255915","pt":1580517703146,"mc":[{"id":"1.168096552","rc":[{"batb":[[0,11.5,7.06],[1,11,7.03],[2,10.5,4.14]],"ltp":13.0,"tv":267.14,"id":26640937},{"batb":[[2,34,1.84]],"ltp":36.0,"tv":13.03,"id":27706761},{"batb":[[2,10,8.62]],"ltp":21.0,"tv":58.04,"id":24608298}]}]}
{"op":"mcm","clk":"992255958","pt":1580517706443,"mc":[{"id":"1.168096552","rc":[{"batl":[[0,14.5,3],[1,15,1],[2,21,1.5]],"ltp":13.0,"tv":267.14,"id":26640937}]}]}
{"op":"mcm","clk":"992255978","pt":1580517707372,"mc":[{"id":"1.168096552","rc":[{"batl":[[2,20,1.86]],"ltp":13.0,"tv":267.14,"id":26640937},{"batb":[[1,38,12.97],[2,34,1.81]],"batl":[[0,48,5],[1,240,9],[2,660,0.33]],"ltp":36.0,"tv":13.03,"id":27706761}]}]}
{"op":"mcm","clk":"992255994","pt":1580517708461,"mc":[{"id":"1.168096552","rc":[{"batb":[[0,11.5,8.59]],"ltp":13.0,"tv":267.14,"id":26640937},{"batb":[[0,40,4.64]],"ltp":36.0,"tv":13.03,"id":27706761},{"batb":[[1,11.5,1.54],[2,11,34.97]],"ltp":21.0,"tv":58.04,"id":24608298}]}]}
{"op":"mcm","clk":"992256011","pt":1580517709079,"mc":[{"id":"1.168096552","rc":[{"batb":[[2,11,33.15]],"ltp":21.0,"tv":58.04,"id":24608298}]}]}
{"op":"mcm","clk":"992256054","pt":1580517711456,"mc":[{"id":"1.168096552","rc":[{"batb":[[0,11.5,13.64]],"ltp":13.0,"tv":267.14,"id":26640937}]}]}
{"op":"mcm","clk":"992256119","pt":1580517715483,"mc":[{"id":"1.168096552","rc":[{"batb":[[0,3.05,5.88]],"ltp":3.1,"tv":2097.6,"id":18286408},{"batb":[[0,4.9,5.04]],"ltp":5.0,"tv":1353.39,"id":21580749},{"batb":[[1,34,1.84],[2,32,2.54]],"ltp":36.0,"tv":13.03,"id":27706761},{"batb":[[2,10,8.62]],"ltp":21.0,"tv":58.04,"id":24608298}]}]}
{"op":"mcm","clk":"992256127","pt":1580517715687,"mc":[{"id":"1.168096552","rc":[{"batb":[[0,12,21.48],[1,11.5,13.64],[2,11,7.03]],"ltp":13.0,"tv":267.14,"id":26640937},{"batb":[[0,42,11.71],[1,40,4.64],[2,34,1.84]],"ltp":36.0,"tv":13.03,"id":27706761},{"batb":[[1,11.5,33.24]],"ltp":21.0,"tv":58.04,"id":24608298}]}]}
{"op":"mcm","clk":"992256192","pt":1580517718468,"mc":[{"id":"1.168096552","rc":[{"batb":[[1,11.5,12.1]],"ltp":13.0,"tv":267.14,"id":26640937},{"batb":[[1,40,4.2]],"ltp":36.0,"tv":13.03,"id":27706761}]}]}
{"op":"mcm","clk":"992256210","pt":1580517718984,"mc":[{"id":"1.168096552","rc":[{"batb":[[0,44,3.36],[1,42,11.71]],"ltp":36.0,"tv":13.03,"id":27706761}]}]}
{"op":"mcm","clk":"992256286","pt":1580517722499,"mc":[{"id":"1.168096552","rc":[{"batb":[[2,34,1.81]],"ltp":36.0,"tv":13.03,"id":27706761}]}]}
{"op":"mcm","clk":"992256314","pt":1580517723276,"mc":[{"id":"1.168096552","rc":[{"batb":[[0,12.5,1.41],[1,12,21.48],[2,11.5,12.1]],"ltp":13.0,"tv":267.14,"id":26640937},{"batb":[[0,44,3.76],[1,42,11.73]],"ltp":36.0,"tv":13.03,"id":27706761}]}]}
{"op":"mcm","clk":"992256459","pt":1580517731271,"mc":[{"id":"1.168096552","rc":[{"batb":[[0,12.5,8.97],[2,11.5,7.06]],"ltp":13.0,"tv":267.14,"id":26640937}]}]}
{"op":"mcm","clk":"992256487","pt":1580517732513,"mc":[{"id":"1.168096552","rc":[{"batb":[[0,3.05,107.88]],"ltp":3.1,"tv":2097.6,"id":18286408},{"batb":[[0,13,19.82],[1,12.5,8.97]],"ltp":13.0,"tv":267.14,"id":26640937},{"batb":[[0,4.9,77.22]],"ltp":5.0,"tv":1353.39,"id":21580749},{"batb":[[1,34,1.83],[2,32,2.54]],"ltp":36.0,"tv":13.03,"id":27706761}]}]}
{"op":"mcm","clk":"992256501","pt":1580517733176,"mc":[{"id":"1.168096552","rc":[{"batb":[[0,34,2.23],[1,32,2.54],[2,30,2]],"ltp":36.0,"tv":13.03,"id":27706761}]}]}
{"op":"mcm","clk":"992256517","pt":1580517733793,"mc":[{"id":"1.168096552","rc":[{"batb":[[1,12.5,7.56]],"ltp":13.0,"tv":267.14,"id":26640937},{"batb":[[0,34,1.83]],"ltp":36.0,"tv":13.03,"id":27706761}]}]}
{"op":"mcm","clk":"992256628","pt":1580517739018,"mc":[{"id":"1.168096552","rc":[{"batb":[[0,13.5,1.31],[1,13,19.82],[2,12.5,7.56]],"ltp":13.0,"tv":267.14,"id":26640937}]}]}
{"op":"mcm","clk":"992256650","pt":1580517739586,"mc":[{"id":"1.168096552","rc":[{"batl":[[2,21,1.5]],"ltp":13.0,"tv":267.14,"id":26640937}]}]}
{"op":"mcm","clk":"992256796","pt":1580517748729,"mc":[{"id":"1.168096552","rc":[{"batb":[[1,12,1.67],[2,11.5,33.24]],"ltp":21.0,"tv":58.04,"id":24608298}]}]}
{"op":"mcm","clk":"992256837","pt":1580517750436,"mc":[{"id":"1.168096552","rc":[{"batb":[[0,3.05,5.88]],"ltp":3.1,"tv":2097.6,"id":18286408},{"batb":[[0,4.9,5.04]],"ltp":5.0,"tv":1353.39,"id":21580749},{"batb":[[2,11.5,1.54]],"ltp":21.0,"tv":58.04,"id":24608298}]}]}
{"op":"mcm","clk":"992256846","pt":1580517750639,"mc":[{"id":"1.168096552","rc":[{"batb":[[1,12,32.06]],"ltp":21.0,"tv":58.04,"id":24608298}]}]}
{"op":"mcm","clk":"992256906","pt":1580517753696,"mc":[{"id":"1.168096552","rc":[{"batb":[[0,13.5,8.03],[2,11.5,7.06]],"ltp":13.0,"tv":267.14,"id":26640937}]}]}
{"op":"mcm","clk":"992256928","pt":1580517754522,"mc":[{"id":"1.168096552","rc":[{"batb":[[2,10,8.62]],"ltp":21.0,"tv":58.04,"id":24608298}]}]}
{"op":"mcm","clk":"992257007","pt":1580517759629,"mc":[{"id":"1.168096552","rc":[{"batb":[[1,12.5,1.41],[2,12,32.06]],"ltp":21.0,"tv":58.04,"id":24608298}]}]}
{"op":"mcm","clk":"992257200","pt":1580517767438,"mc":[{"id":"1.168096552","rc":[{"batb":[[1,11.5,7.06],[2,11,1.39]],"ltp":13.0,"tv":267.14,"id":26640937},{"trd":[[3,589.89]],"batb":[[0,3,5.14]],"ltp":3.0,"tv":5534.97,"id":52106},{"batb":[[2,12,1.67]],"ltp":21.0,"tv":58.04,"id":24608298}],"tv":9324.19}]}
{"op":"mcm","clk":"992257235","pt":1580517768521,"mc":[{"id":"1.168096552","rc":[{"batb":[[1,12.5,30.58]],"ltp":21.0,"tv":58.04,"id":24608298}]}]}
{"op":"mcm","clk":"992257292","pt":1580517770428,"mc":[{"id":"1.168096552","rc":[{"batb":[[0,11.5,7.06],[1,11,1.39],[2,10.5,4.14]],"ltp":13.0,"tv":267.14,"id":26640937}]}]}
{"op":"mcm","clk":"992257350","pt":1580517772235,"mc":[{"id":"1.168096552","rc":[{"batb":[[0,13.5,3.32],[1,13,12.08],[2,12.5,30.58]],"ltp":21.0,"tv":58.04,"id":24608298}]}]}
{"op":"mcm","clk":"992257369","pt":1580517772646,"mc":[{"id":"1.168096552","rc":[{"batb":[[1,11,4.54]],"batl":[[0,14,2.47],[1,14.5,3],[2,15,1]],"ltp":13.0,"tv":267.14,"id":26640937}]}]}
{"op":"mcm","clk":"992257420","pt":1580517775267,"mc":[{"id":"1.168096552","rc":[{"batb":[[0,11.5,8.59]],"ltp":13.0,"tv":267.14,"id":26640937}]}]}
{"op":"mcm","clk":"992257429","pt":1580517775533,"mc":[{"id":"1.168096552","rc":[{"batb":[[2,12.5,29.17]],"ltp":21.0,"tv":58.04,"id":24608298}]}]}
{"op":"mcm","clk":"992257571","pt":1580517781254,"mc":[{"id":"1.168096552","rc":[{"batb":[[0,13.5,4.63]],"ltp":21.0,"tv":58.04,"id":24608298}]}]}
{"op":"mcm","clk":"992257700","pt":1580517785445,"mc":[{"id":"1.168096552","rc":[{"batb":[[2,10,8.62]],"ltp":21.0,"tv":58.04,"id":24608298}]}]}
{"op":"mcm","clk":"992257716","pt":1580517786262,"mc":[{"id":"1.168096552","rc":[{"batb":[[0,3.05,107.88]],"ltp":3.1,"tv":2097.6,"id":18286408},{"batb":[[0,12,21.48],[1,11.5,7.06],[2,11,4.54]],"ltp":13.0,"tv":267.14,"id":26640937},{"batb":[[0,4.9,77.22]],"ltp":5.0,"tv":1353.39,"id":21580749},{"batb":[[0,14,26.45],[1,13.5,2.92],[2,13,12.08]],"ltp":21.0,"tv":58.04,"id":24608298}]}]}
{"op":"mcm","clk":"992257824","pt":1580517791263,"mc":[{"id":"1.168096552","rc":[{"batb":[[0,12.5,1.41],[1,12,21.48],[2,11.5,7.06]],"ltp":13.0,"tv":267.14,"id":26640937},{"batb":[[0,14.5,1.62],[1,14,26.04],[2,13.5,2.92]],"ltp":21.0,"tv":58.04,"id":24608298}]}]}
{"op":"mcm","clk":"992257835","pt":1580517791882,"mc":[{"id":"1.168096552","rc":[{"batb":[[0,12.5,8.97]],"ltp":13.0,"tv":267.14,"id":26640937},{"batb":[[2,13,12.08]],"ltp":21.0,"tv":58.04,"id":24608298}]}]}
{"op":"mcm","clk":"992257958","pt":1580517797246,"mc":[{"id":"1.168096552","rc":[{"batb":[[0,14.5,10.02],[2,13,2]],"ltp":21.0,"tv":58.04,"id":24608298}]}]}
{"op":"mcm","clk":"992258098","pt":1580517802474,"mc":[{"id":"1.168096552","rc":[{"batb":[[0,3.05,5.88]],"ltp":3.1,"tv":2097.6,"id":18286408},{"batb":[[1,11.5,7.06],[2,11,4.54]],"ltp":13.0,"tv":267.14,"id":26640937},{"batb":[[0,4.9,5.04]],"ltp":5.0,"tv":1353.39,"id":21580749},{"batb":[[1,13,2],[2,10,8.62]],"ltp":21.0,"tv":58.04,"id":24608298}]}]}
{"op":"mcm","clk":"992258104","pt":1580517802682,"mc":[{"id":"1.168096552","rc":[{"batb":[[0,13,19.82],[1,12.5,8.97],[2,11.5,7.06]],"ltp":13.0,"tv":267.14,"id":26640937},{"batb":[[0,15,24.71],[1,14.5,9.62],[2,13,2]],"ltp":21.0,"tv":58.04,"id":24608298}]}]}
{"op":"mcm","clk":"992258136","pt":1580517804181,"mc":[{"id":"1.168096552","rc":[{"batl":[[0,14.5,3],[1,15,1],[2,21,1.5]],"ltp":13.0,"tv":267.14,"id":26640937}]}]}
{"op":"mcm","clk":"992258200","pt":1580517806767,"mc":[{"id":"1.168096552","rc":[{"batb":[[1,12.5,7.56]],"ltp":13.0,"tv":267.14,"id":26640937},{"batb":[[1,14.5,8.4]],"ltp":21.0,"tv":58.04,"id":24608298}]}]}
{"op":"mcm","clk":"992258362","pt":1580517812508,"mc":[{"id":"1.168096552","rc":[{"batb":[[0,13.5,1.31],[1,13,19.82],[2,12.5,7.56]],"ltp":13.0,"tv":267.14,"id":26640937},{"batb":[[0,15.5,4.07],[1,15,24.31],[2,14.5,8.4]],"ltp":21.0,"tv":58.04,"id":24608298}]}]}
{"op":"mcm","clk":"992258467","pt":1580517817520,"mc":[{"id":"1.168096552","rc":[{"trd":[[4.9,41.92]],"batb":[[0,4.8,12.38],[1,4.7,21.12],[2,4.6,15.11]],"batl":[[0,4.9,3.04],[1,5,14.17],[2,5.1,20]],"ltp":4.9,"tv":1367.31,"id":21580749}],"tv":9338.12}]}
{"op":"mcm","clk":"992258500","pt":1580517818915,"mc":[{"id":"1.168096552","rc":[{"batb":[[0,13.5,8.03],[2,11.5,7.06]],"ltp":13.0,"tv":267.14,"id":26640937}]}]}
{"op":"mcm","clk":"992258536","pt":1580517820515,"mc":[{"id":"1.168096552","rc":[{"batb":[[0,3.05,107.88]],"ltp":3.1,"tv":2097.6,"id":18286408},{"batb":[[1,11.5,7.06],[2,11,1.39]],"ltp":13.0,"tv":267.14,"id":26640937},{"trd":[[4.9,48]],"batb":[[0,4.9,69.14],[1,4.8,12.38],[2,4.7,21.12]],"batl":[[0,5,14.17],[1,5.1,20],[2,5.3,9]],"ltp":4.9,"tv":1373.39,"id":21580749},{"batb":[[0,15.5,27.6],[1,14.5,8.4],[2,13,2]],"ltp":21.0,"tv":58.04,"id":24608298}],"tv":9344.2}]}
{"op":"mcm","clk":"992258552","pt":1580517821440,"mc":[{"id":"1.168096552","rc":[{"batb":[[0,13.5,1.31]],"ltp":13.0,"tv":267.14,"id":26640937}]}]}
{"op":"mcm","clk":"992258620","pt":1580517823401,"mc":[{"id":"1.168096552","rc":[{"batb":[[0,11.5,7.06],[1,11,1.39],[2,10.5,4.14]],"ltp":13.0,"tv":267.14,"id":26640937}]}]}
{"op":"mcm","clk":"992258650","pt":1580517824434,"mc":[{"id":"1.168096552","rc":[{"batb":[[0,16,8.8],[1,15.5,27.19]],"ltp":21.0,"tv":58.04,"id":24608298}]}]}
{"op":"mcm","clk":"992258755","pt":1580517828425,"mc":[{"id":"1.168096552","rc":[{"batb":[[1,11,3]],"ltp":13.0,"tv":267.14,"id":26640937},{"batb":[[1,4.8,15.51]],"ltp":4.9,"tv":1373.39,"id":21580749}]}]}
{"op":"mcm","clk":"992258868","pt":1580517832036,"mc":[{"id":"1.168096552","rc":[{"batb":[[2,10.5,7.73]],"ltp":13.0,"tv":267.14,"id":26640937},{"batb":[[0,16.5,2.48],[1,16,8.71],[2,15.5,24.66]],"ltp":21.0,"tv":58.04,"id":24608298}]}]}
{"op":"mcm","clk":"992258944","pt":1580517834366,"mc":[{"id":"1.168096552","rc":[{"batb":[[2,15.5,23.52]],"ltp":21.0,"tv":58.04,"id":24608298}]}]}
{"op":"mcm","clk":"992259060","pt":1580517837469,"mc":[{"id":"1.168096552","rc":[{"batb":[[0,3.05,5.88]],"ltp":3.1,"tv":2097.6,"id":18286408},{"batb":[[0,4.8,15.51],[1,4.7,21.12],[2,4.6,15.11]],"ltp":4.9,"tv":1373.39,"id":21580749},{"batb":[[2,13,2]],"ltp":21.0,"tv":58.04,"id":24608298}]}]}
{"op":"mcm","clk":"992259072","pt":1580517837732,"mc":[{"id":"1.168096552","rc":[{"batb":[[0,12,21.48],[1,11.5,7.06],[2,11,3]],"ltp":13.0,"tv":267.14,"id":26640937},{"batb":[[0,4.8,12.38],[1,4.7,24.9]],"ltp":4.9,"tv":1373.39,"id":21580749},{"batb":[[0,16.5,24.58]],"ltp":21.0,"tv":58.04,"id":24608298}]}]}
{"op":"mcm","clk":"992259112","pt":1580517838885,"mc":[{"id":"1.168096552","rc":[{"batb":[[2,11,1.39]],"ltp":13.0,"tv":267.14,"id":26640937},{"batb":[[0,17,1.04],[1,16.5,24.58],[2,16,8.71]],"ltp":21.0,"tv":58.04,"id":24608298}]}]}
{"op":"mcm","clk":"992259181","pt":1580517840853,"mc":[{"id":"1.168096552","rc":[{"trd":[[5,50.48]],"batl":[[0,5,4.76]],"ltp":5.0,"tv":1392.21,"id":21580749}],"tv":9363.02}]}
{"op":"mcm","clk":"992259237","pt":1580517843279,"mc":[{"id":"1.168096552","rc":[{"batb":[[0,4.9,3.36],[1,4.8,12.38],[2,4.7,21.12]],"ltp":5.0,"tv":1392.21,"id":21580749}]}]}
{"op":"mcm","clk":"992259264","pt":1580517844056,"mc":[{"id":"1.168096552","rc":[{"batb":[[0,12.5,1.41],[1,12,21.48],[2,11.5,7.06]],"ltp":13.0,"tv":267.14,"id":26640937}]}]}
{"op":"mcm","clk":"992259307","pt":1580517845970,"mc":[{"id":"1.168096552","rc":[{"batb":[[0,12.5,8.97]],"ltp":13.0,"tv":267.14,"id":26640937}]}]}
{"op":"mcm","clk":"992259446","pt":1580517852082,"mc":[{"id":"1.168096552","rc":[{"batb":[[0,17,9.44],[2,13,2.31]],"ltp":21.0,"tv":58.04,"id":24608298}]}]}
{"op":"mcm","clk":"992259521","pt":1580517855477,"mc":[{"id":"1.168096552","rc":[{"batb":[[0,13,19.82],[1,12.5,8.97]],"ltp":13.0,"tv":267.14,"id":26640937},{"batb":[[0,17.5,20.83],[1,17,9.44],[2,16.5,2.48]],"ltp":21.0,"tv":58.04,"id":24608298}]}]}
{"op":"mcm","clk":"992259583","pt":1580517858490,"mc":[{"id":"1.168096552","rc":[{"trd":[[13,54.67]],"batb":[[0,12.5,8.97],[1,11.5,7.06],[2,11,1.39]],"ltp":13.0,"tv":306.81,"id":26640937},{"trd":[[5,60.01]],"batl":[[0,5.1,20],[1,5.3,9],[2,6,2.5]],"ltp":5.0,"tv":1401.74,"id":21580749}],"tv":9412.21}]}
{"op":"mcm","clk":"992259621","pt":1580517860100,"mc":[{"id":"1.168096552","rc":[{"batb":[[0,11.5,7.06],[1,11,1.39],[2,10.5,7.73]],"ltp":13.0,"tv":306.81,"id":26640937},{"batb":[[1,17,8.4]],"ltp":21.0,"tv":58.04,"id":24608298}]}]}
{"op":"mcm","clk":"992259635","pt":1580517860874,"mc":[{"id":"1.168096552","rc":[{"batl":[[1,55,3.18]],"ltp":21.0,"tv":58.04,"id":24608298}]}]}
{"op":"mcm","clk":"992259716","pt":1580517865295,"mc":[{"id":"1.168096552","rc":[{"batb":[[1,11,3]],"ltp":13.0,"tv":306.81,"id":26640937},{"batb":[[0,17.5,21.82]],"ltp":21.0,"tv":58.04,"id":24608298}]}]}
{"op":"mcm","clk":"992259828","pt":1580517872509,"mc":[{"id":"1.168096552","rc":[{"batb":[[0,17,9.38],[1,13,2.4],[2,10.5,5.68]],"ltp":21.0,"tv":58.04,"id":24608298}]}]}
{"op":"mcm","clk":"992259851","pt":1580517873281,"mc":[{"id":"1.168096552","rc":[{"batb":[[0,16.5,1.08],[1,13,2.31]],"ltp":21.0,"tv":58.04,"id":24608298}]}]}
{"op":"mcm","clk":"992259937","pt":1580517876501,"mc":[{"id":"1.168096552","rc":[{"trd":[[2.98,350.24],[3,600.17]],"batb":[[0,2.98,20.92],[1,2.96,4.03],[2,2.88,1.68]],"ltp":2.98,"tv":5572.83,"id":52106},{"batb":[[0,13,2.4],[1,10.5,5.68],[2,10,8.62]],"ltp":21.0,"tv":58.04,"id":24608298}],"tv":9450.08}]}
{"op":"mcm","clk":"992259980","pt":1580517878425,"mc":[{"id":"1.168096552","rc":[{"batb":[[1,10,8.62],[2,9.2,4.59]],"ltp":21.0,"tv":58.04,"id":24608298}]}]}
{"op":"mcm","clk":"992260006","pt":1580517880032,"mc":[{"id":"1.168096552","rc":[{"batb":[[1,10.5,2.36],[2,10,8.62]],"ltp":21.0,"tv":58.04,"id":24608298}]}]}
{"op":"mcm","clk":"992260054","pt":1580517882422,"mc":[{"id":"1.168096552","rc":[{"batb":[[1,10.5,4.04]],"ltp":21.0,"tv":58.04,"id":24608298}]}]}
{"op":"mcm","clk":"992260211","pt":1580517890314,"mc":[{"id":"1.168096552","rc":[{"batb":[[0,3.05,107.88]],"ltp":3.1,"tv":2097.6,"id":18286408},{"batb":[[1,11,33.15],[2,10.5,4.04]],"ltp":21.0,"tv":58.04,"id":24608298}]}]}
{"op":"mcm","clk":"992260291","pt":1580517893462,"mc":[{"id":"1.168096552","rc":[{"batb":[[2,10.5,2.36]],"ltp":21.0,"tv":58.04,"id":24608298}]}]}
{"op":"mcm","clk":"992260409","pt":1580517899460,"mc":[{"id":"1.168096552","rc":[{"batb":[[1,11.5,1.54],[2,11,33.15]],"ltp":21.0,"tv":58.04,"id":24608298}]}]}
{"op":"mcm","clk":"992260530","pt":1580517907478,"mc":[{"id":"1.168096552","rc":[{"batb":[[0,3.05,5.88]],"ltp":3.1,"tv":2097.6,"id":18286408},{"batb":[[2,10.5,2.36]],"ltp":21.0,"tv":58.04,"id":24608298}]}]}
{"op":"mcm","clk":"992260539","pt":1580517908151,"mc":[{"id":"1.168096552","rc":[{"batb":[[1,11.5,33.24]],"ltp":21.0,"tv":58.04,"id":24608298}]}]}
{"op":"mcm","clk":"992260821","pt":1580517925381,"mc":[{"id":"1.168096552","rc":[{"batb":[[0,3.05,107.88]],"ltp":3.1,"tv":2097.6,"id":18286408}]}]}
{"op":"mcm","clk":"992261138","pt":1580517942429,"mc":[{"id":"1.168096552","rc":[{"batb":[[0,3.05,5.88]],"ltp":3.1,"tv":2097.6,"id":18286408}]}]}
{"op":"mcm","clk":"992261450","pt":1580517960448,"mc":[{"id":"1.168096552","rc":[{"batb":[[0,3.05,107.88]],"ltp":3.1,"tv":2097.6,"id":18286408}]}]}
{"op":"mcm","clk":"992261907","pt":1580517977390,"mc":[{"id":"1.168096552","rc":[{"batb":[[0,3.05,5.88]],"ltp":3.1,"tv":2097.6,"id":18286408}]}]}
{"op":"mcm","clk":"992262312","pt":1580517993406,"mc":[{"id":"1.168096552","rc":[{"batb":[[0,12,1.44],[1,11.5,7.06],[2,11,3]],"ltp":13.0,"tv":306.81,"id":26640937},{"batb":[[0,5,3.44],[1,4.9,3.36],[2,4.8,12.38]],"ltp":5.0,"tv":1401.74,"id":21580749}]}]}
{"op":"mcm","clk":"992262365","pt":1580517995317,"mc":[{"id":"1.168096552","rc":[{"batb":[[0,3.05,107.88]],"ltp":3.1,"tv":2097.6,"id":18286408},{"batb":[[0,5,71.21]],"ltp":5.0,"tv":1401.74,"id":21580749}]}]}
{"op":"mcm","clk":"992262375","pt":1580517995632,"mc":[{"id":"1.168096552","rc":[{"batb":[[1,11.5,10.42]],"ltp":13.0,"tv":306.81,"id":26640937}]}]}
{"op":"mcm","clk":"992262431","pt":1580517997144,"mc":[{"id":"1.168096552","rc":[{"batb":[[2,11,1.39]],"ltp":13.0,"tv":306.81,"id":26640937}]}]}
{"op":"mcm","clk":"992262619","pt":1580518003432,"mc":[{"id":"1.168096552","rc":[{"batb":[[0,12,2.91]],"ltp":13.0,"tv":306.81,"id":26640937}]}]}
{"op":"mcm","clk":"992262862","pt":1580518012454,"mc":[{"id":"1.168096552","rc":[{"batb":[[0,3.05,5.88]],"ltp":3.1,"tv":2097.6,"id":18286408},{"batb":[[0,5,3.44]],"ltp":5.0,"tv":1401.74,"id":21580749}]}]}
{"op":"mcm","clk":"992263284","pt":1580518030365,"mc":[{"id":"1.168096552","rc":[{"batb":[[0,3.05,107.88]],"ltp":3.1,"tv":2097.6,"id":18286408},{"batb":[[0,5,71.21]],"ltp":5.0,"tv":1401.74,"id":21580749}]}]}
{"op":"mcm","clk":"992263655","pt":1580518047403,"mc":[{"id":"1.168096552","rc":[{"batb":[[0,3.05,5.88]],"ltp":3.1,"tv":2097.6,"id":18286408},{"batb":[[0,5,3.44]],"ltp":5.0,"tv":1401.74,"id":21580749}]}]}
{"op":"mcm","clk":"992264083","pt":1580518065353,"mc":[{"id":"1.168096552","rc":[{"batb":[[0,3.05,107.88]],"ltp":3.1,"tv":2097.6,"id":18286408},{"batb":[[0,5,71.21]],"ltp":5.0,"tv":1401.74,"id":21580749}]}]}
{"op":"mcm","clk":"992264406","pt":1580518082349,"mc":[{"id":"1.168096552","rc":[{"batb":[[0,3.05,5.88]],"ltp":3.1,"tv":2097.6,"id":18286408},{"batb":[[0,5,3.44]],"ltp":5.0,"tv":1401.74,"id":21580749}]}]}
{"op":"mcm","clk":"992264456","pt":1580518084359,"mc":[{"id":"1.168096552","rc":[{"batl":[[0,3,42.62],[1,3.05,44.44],[2,3.1,2.36]],"ltp":2.98,"tv":5572.83,"id":52106}]}]}
{"op":"mcm","clk":"992264746","pt":1580518098207,"mc":[{"id":"1.168096552","rc":[{"trd":[[3,685.4]],"batl":[[0,3.05,44.44],[1,3.1,2.36],[2,3.15,11.2]],"ltp":3.0,"tv":5658.07,"id":52106}],"tv":9535.31}]}
{"op":"mcm","clk":"992264807","pt":1580518100382,"mc":[{"id":"1.168096552","rc":[{"batb":[[0,3.05,107.88]],"ltp":3.1,"tv":2097.6,"id":18286408},{"batb":[[0,5,71.21]],"ltp":5.0,"tv":1401.74,"id":21580749}]}]}
{"op":"mcm","clk":"992265171","pt":1580518117423,"mc":[{"id":"1.168096552","rc":[{"batb":[[0,3.05,5.88]],"ltp":3.1,"tv":2097.6,"id":18286408},{"batb":[[0,5,3.44]],"ltp":5.0,"tv":1401.74,"id":21580749}]}]}
{"op":"mcm","clk":"992265579","pt":1580518135362,"mc":[{"id":"1.168096552","rc":[{"batb":[[0,3.05,107.88]],"ltp":3.1,"tv":2097.6,"id":18286408},{"batb":[[0,5,71.21]],"ltp":5.0,"tv":1401.74,"id":21580749}]}]}
{"op":"mcm","clk":"992265954","pt":1580518152492,"mc":[{"id":"1.168096552","rc":[{"batb":[[0,3.05,5.88]],"ltp":3.1,"tv":2097.6,"id":18286408},{"batb":[[0,5,3.44]],"ltp":5.0,"tv":1401.74,"id":21580749}]}]}
{"op":"mcm","clk":"992266334","pt":1580518170308,"mc":[{"id":"1.168096552","rc":[{"batb":[[0,3.05,107.88]],"ltp":3.1,"tv":2097.6,"id":18286408},{"batb":[[0,5,71.21]],"ltp":5.0,"tv":1401.74,"id":21580749}]}]}
{"op":"mcm","clk":"992266703","pt":1580518187425,"mc":[{"id":"1.168096552","rc":[{"batb":[[0,3.05,5.88]],"ltp":3.1,"tv":2097.6,"id":18286408},{"batb":[[0,5,3.44]],"ltp":5.0,"tv":1401.74,"id":21580749}]}]}
{"op":"mcm","clk":"992267188","pt":1580518211358,"mc":[{"id":"1.168096552","rc":[{"batb":[[0,3.05,107.88]],"ltp":3.1,"tv":2097.6,"id":18286408},{"batb":[[0,5,71.21]],"ltp":5.0,"tv":1401.74,"id":21580749}]}]}
{"op":"mcm","clk":"992267659","pt":1580518229516,"mc":[{"id":"1.168096552","rc":[{"batb":[[0,3.05,5.88]],"ltp":3.1,"tv":2097.6,"id":18286408},{"batb":[[0,5,3.44]],"ltp":5.0,"tv":1401.74,"id":21580749}]}]}
{"op":"mcm","clk":"992268116","pt":1580518246325,"mc":[{"id":"1.168096552","rc":[{"batb":[[0,3.05,107.88]],"ltp":3.1,"tv":2097.6,"id":18286408},{"batb":[[0,5,71.21]],"ltp":5.0,"tv":1401.74,"id":21580749}]}]}
{"op":"mcm","clk":"992268652","pt":1580518264441,"mc":[{"id":"1.168096552","rc":[{"batb":[[0,3.05,5.88]],"ltp":3.1,"tv":2097.6,"id":18286408},{"batb":[[0,5,3.44]],"ltp":5.0,"tv":1401.74,"id":21580749}]}]}
{"op":"mcm","clk":"992269153","pt":1580518281418,"mc":[{"id":"1.168096552","rc":[{"batb":[[0,3.05,107.88]],"ltp":3.1,"tv":2097.6,"id":18286408},{"batb":[[0,5,71.21]],"ltp":5.0,"tv":1401.74,"id":21580749}]}]}
{"op":"mcm","clk":"992269620","pt":1580518299419,"mc":[{"id":"1.168096552","rc":[{"batb":[[0,3.05,5.88]],"ltp":3.1,"tv":2097.6,"id":18286408},{"batb":[[0,5,3.44]],"ltp":5.0,"tv":1401.74,"id":21580749}]}]}
{"op":"mcm","clk":"992270127","pt":1580518329471,"mc":[{"id":"1.168096552","rc":[{"batb":[[0,3.05,107.88]],"ltp":3.1,"tv":2097.6,"id":18286408},{"batb":[[0,5,71.21]],"ltp":5.0,"tv":1401.74,"id":21580749}]}]}
{"op":"mcm","clk":"992270481","pt":1580518347397,"mc":[{"id":"1.168096552","rc":[{"batb":[[0,3.05,5.88]],"ltp":3.1,"tv":2097.6,"id":18286408},{"batb":[[0,5,3.44]],"ltp":5.0,"tv":1401.74,"id":21580749}]}]}
{"op":"mcm","clk":"992280721","pt":1580518364389,"mc":[{"id":"1.168096552","rc":[{"batb":[[0,3.05,107.88]],"ltp":3.1,"tv":2097.6,"id":18286408},{"batb":[[0,5,71.21]],"ltp":5.0,"tv":1401.74,"id":21580749}]}]}
{"op":"mcm","clk":"992281060","pt":1580518382438,"mc":[{"id":"1.168096552","rc":[{"batb":[[0,3.05,5.88]],"ltp":3.1,"tv":2097.6,"id":18286408},{"batb":[[0,5,3.44]],"ltp":5.0,"tv":1401.74,"id":21580749}]}]}
{"op":"mcm","clk":"992281345","pt":1580518399346,"mc":[{"id":"1.168096552","rc":[{"batb":[[0,3.05,107.88]],"ltp":3.1,"tv":2097.6,"id":18286408},{"batb":[[0,5,71.21]],"ltp":5.0,"tv":1401.74,"id":21580749}]}]}
{"op":"mcm","clk":"992281623","pt":1580518417450,"mc":[{"id":"1.168096552","rc":[{"batb":[[0,3.05,5.88]],"ltp":3.1,"tv":2097.6,"id":18286408},{"batb":[[0,5,3.44]],"ltp":5.0,"tv":1401.74,"id":21580749}]}]}
{"op":"mcm","clk":"992281841","pt":1580518429975,"mc":[{"id":"1.168096552","rc":[{"trd":[[5,66.89]],"batb":[[0,4.9,3.36],[1,4.8,12.38],[2,4.7,21.12]],"batl":[[0,5,6.56],[1,5.1,20],[2,5.3,9]],"ltp":5.0,"tv":1408.62,"id":21580749}],"tv":9542.19}]}
{"op":"mcm","clk":"992281941","pt":1580518434404,"mc":[{"id":"1.168096552","rc":[{"batb":[[0,3.05,107.88]],"ltp":3.1,"tv":2097.6,"id":18286408},{"batb":[[0,4.9,72.5]],"ltp":5.0,"tv":1408.62,"id":21580749}]}]}
{"op":"mcm","clk":"992282292","pt":1580518452505,"mc":[{"id":"1.168096552","rc":[{"batb":[[0,3.05,5.88]],"ltp":3.1,"tv":2097.6,"id":18286408},{"batb":[[0,4.9,3.36]],"ltp":5.0,"tv":1408.62,"id":21580749}]}]}
{"op":"mcm","clk":"992282302","pt":1580518452913,"mc":[{"id":"1.168096552","rc":[{"batb":[[0,34,2.33],[1,32,17.9]],"ltp":36.0,"tv":13.03,"id":27706761}]}]}
{"op":"mcm","clk":"992282437","pt":1580518460016,"mc":[{"id":"1.168096552","rc":[{"batb":[[0,34,8.21]],"ltp":36.0,"tv":13.03,"id":27706761}]}]}
{"op":"mcm","clk":"992282481","pt":1580518462946,"mc":[{"id":"1.168096552","rc":[{"batb":[[0,34,8.73]],"ltp":36.0,"tv":13.03,"id":27706761}]}]}
{"op":"mcm","clk":"992282636","pt":1580518469436,"mc":[{"id":"1.168096552","rc":[{"batb":[[1,32,2.54]],"ltp":36.0,"tv":13.03,"id":27706761}]}]}
{"op":"mcm","clk":"992282639","pt":1580518469539,"mc":[{"id":"1.168096552","rc":[{"batb":[[0,3.05,107.88]],"ltp":3.1,"tv":2097.6,"id":18286408},{"batb":[[0,4.9,72.5]],"ltp":5.0,"tv":1408.62,"id":21580749},{"batb":[[0,36,13.68],[1,34,8.72],[2,32,2.54]],"ltp":36.0,"tv":13.03,"id":27706761}]}]}
{"op":"mcm","clk":"992282773","pt":1580518475730,"mc":[{"id":"1.168096552","rc":[{"batb":[[1,34,8.2]],"ltp":36.0,"tv":13.03,"id":27706761}]}]}
{"op":"mcm","clk":"992282922","pt":1580518482172,"mc":[{"id":"1.168096552","rc":[{"batb":[[0,36,14.14]],"ltp":36.0,"tv":13.03,"id":27706761}]}]}
{"op":"mcm","clk":"992283046","pt":1580518487480,"mc":[{"id":"1.168096552","rc":[{"batb":[[0,3.05,5.88]],"ltp":3.1,"tv":2097.6,"id":18286408},{"batb":[[0,4.9,3.36]],"ltp":5.0,"tv":1408.62,"id":21580749}]}]}
{"op":"mcm","clk":"992283401","pt":1580518504479,"mc":[{"id":"1.168096552","rc":[{"batb":[[0,3.05,107.88]],"ltp":3.1,"tv":2097.6,"id":18286408},{"batb":[[0,4.9,72.5]],"ltp":5.0,"tv":1408.62,"id":21580749}]}]}
{"op":"mcm","clk":"992283800","pt":1580518522404,"mc":[{"id":"1.168096552","rc":[{"batb":[[0,3.05,5.88]],"ltp":3.1,"tv":2097.6,"id":18286408},{"batb":[[0,4.9,3.36]],"ltp":5.0,"tv":1408.62,"id":21580749}]}]}
{"op":"mcm","clk":"992284096","pt":1580518537451,"mc":[{"id":"1.168096552","rc":[{"batb":[[0,38,4.68],[1,36,13.66],[2,34,2.31]],"ltp":36.0,"tv":13.03,"id":27706761}]}]}
{"op":"mcm","clk":"992284137","pt":1580518539517,"mc":[{"id":"1.168096552","rc":[{"batb":[[0,3.05,107.88]],"ltp":3.1,"tv":2097.6,"id":18286408},{"batb":[[0,4.9,72.5]],"ltp":5.0,"tv":1408.62,"id":21580749},{"batb":[[0,40,12.31],[1,38,4.66]],"ltp":36.0,"tv":13.03,"id":27706761}]}]}
{"op":"mcm","clk":"992284162","pt":1580518541424,"mc":[{"id":"1.168096552","rc":[{"batb":[[1,38,4.2]],"ltp":36.0,"tv":13.03,"id":27706761}]}]}
{"op":"mcm","clk":"992284302","pt":1580518547435,"mc":[{"id":"1.168096552","rc":[{"batb":[[0,40,12.73]],"ltp":36.0,"tv":13.03,"id":27706761}]}]}
{"op":"mcm","clk":"992284474","pt":1580518557464,"mc":[{"id":"1.168096552","rc":[{"batb":[[0,3.05,5.88]],"ltp":3.1,"tv":2097.6,"id":18286408},{"batb":[[0,4.9,3.36]],"ltp":5.0,"tv":1408.62,"id":21580749}]}]}
{"op":"mcm","clk":"992284854","pt":1580518574369,"mc":[{"id":"1.168096552","rc":[{"batb":[[0,3.05,107.88]],"ltp":3.1,"tv":2097.6,"id":18286408},{"batb":[[0,4.9,72.5]],"ltp":5.0,"tv":1408.62,"id":21580749}]}]}
{"op":"mcm","clk":"992284978","pt":1580518578483,"mc":[{"id":"1.168096552","rc":[{"trd":[[40,24.6],[42,0.87]],"batb":[[0,38,4.2],[1,34,2.31],[2,32,2.54]],"ltp":40.0,"tv":38.51,"id":27706761}],"tv":9567.67}]}
{"op":"mcm","clk":"992285146","pt":1580518582591,"mc":[{"id":"1.168096552","rc":[{"batb":[[1,34,2.34]],"batl":[[0,48,5.02]],"ltp":40.0,"tv":38.51,"id":27706761}]}]}
{"op":"mcm","clk":"992285271","pt":1580518587015,"mc":[{"id":"1.168096552","rc":[{"batb":[[0,34,2.34],[1,32,2.54],[2,30,2]],"ltp":40.0,"tv":38.51,"id":27706761}]}]}
{"op":"mcm","clk":"992285437","pt":1580518592483,"mc":[{"id":"1.168096552","rc":[{"batb":[[0,3.05,5.88]],"ltp":3.1,"tv":2097.6,"id":18286408},{"batb":[[0,4.9,3.36]],"ltp":5.0,"tv":1408.62,"id":21580749}]}]}
{"op":"mcm","clk":"992285945","pt":1580518609424,"mc":[{"id":"1.168096552","rc":[{"batb":[[0,3.05,107.88]],"ltp":3.1,"tv":2097.6,"id":18286408},{"batb":[[0,4.9,72.5]],"ltp":5.0,"tv":1408.62,"id":21580749}]}]}
{"op":"mcm","clk":"992286464","pt":1580518627447,"mc":[{"id":"1.168096552","rc":[{"batb":[[0,3.05,5.88]],"ltp":3.1,"tv":2097.6,"id":18286408},{"batb":[[0,4.9,3.36]],"ltp":5.0,"tv":1408.62,"id":21580749}]}]}
{"op":"mcm","clk":"992286956","pt":1580518644476,"mc":[{"id":"1.168096552","rc":[{"batb":[[0,3.05,107.88]],"ltp":3.1,"tv":2097.6,"id":18286408},{"batb":[[0,4.9,72.5]],"ltp":5.0,"tv":1408.62,"id":21580749}]}]}
{"op":"mcm","clk":"992287388","pt":1580518662502,"mc":[{"id":"1.168096552","rc":[{"batb":[[0,3.05,5.88]],"ltp":3.1,"tv":2097.6,"id":18286408},{"batb":[[0,4.9,3.36]],"ltp":5.0,"tv":1408.62,"id":21580749}]}]}
{"op":"mcm","clk":"992287821","pt":1580518679413,"mc":[{"id":"1.168096552","rc":[{"batb":[[0,3.05,107.88]],"ltp":3.1,"tv":2097.6,"id":18286408},{"batb":[[0,4.9,72.5]],"ltp":5.0,"tv":1408.62,"id":21580749}]}]}
{"op":"mcm","clk":"992288313","pt":1580518697519,"mc":[{"id":"1.168096552","rc":[{"batb":[[0,3.05,5.88]],"ltp":3.1,"tv":2097.6,"id":18286408},{"batb":[[0,4.9,3.36]],"ltp":5.0,"tv":1408.62,"id":21580749}]}]}
{"op":"mcm","clk":"992288781","pt":1580518714447,"mc":[{"id":"1.168096552","rc":[{"batb":[[0,3.05,107.88]],"ltp":3.1,"tv":2097.6,"id":18286408},{"batb":[[0,4.9,72.5]],"ltp":5.0,"tv":1408.62,"id":21580749}]}]}
{"op":"mcm","clk":"992289345","pt":1580518732378,"mc":[{"id":"1.168096552","rc":[{"batb":[[0,3.05,5.88]],"ltp":3.1,"tv":2097.6,"id":18286408},{"batb":[[0,4.9,3.36]],"ltp":5.0,"tv":1408.62,"id":21580749}]}]}
{"op":"mcm","clk":"992289755","pt":1580518749376,"mc":[{"id":"1.168096552","rc":[{"batb":[[0,3.05,107.88]],"ltp":3.1,"tv":2097.6,"id":18286408},{"batb":[[0,4.9,72.5]],"ltp":5.0,"tv":1408.62,"id":21580749}]}]}
{"op":"mcm","clk":"992290177","pt":1580518767494,"mc":[{"id":"1.168096552","rc":[{"batb":[[0,3.05,5.88]],"ltp":3.1,"tv":2097.6,"id":18286408},{"batb":[[0,4.9,3.36]],"ltp":5.0,"tv":1408.62,"id":21580749}]}]}
{"op":"mcm","clk":"992290371","pt":1580518776411,"mc":[{"id":"1.168096552","rc":[{"trd":[[3.05,360.85]],"batb":[[0,3,100.22],[1,2.98,4],[2,2.96,2]],"ltp":3.05,"tv":2109.36,"id":18286408},{"batb":[[0,3,3.36],[1,2.98,20.92],[2,2.96,4.03]],"ltp":3.0,"tv":5658.07,"id":52106}],"tv":9579.43}]}
{"op":"mcm","clk":"992290386","pt":1580518776925,"mc":[{"id":"1.168096552","rc":[{"batb":[[0,3.05,2.43],[1,3,100.22],[2,2.98,4]],"ltp":3.05,"tv":2109.36,"id":18286408}]}]}
{"op":"mcm","clk":"992290586","pt":1580518784437,"mc":[{"id":"1.168096552","rc":[{"batb":[[0,4.9,72.5]],"ltp":5.0,"tv":1408.62,"id":21580749}]}]}
{"op":"mcm","clk":"992291082","pt":1580518802394,"mc":[{"id":"1.168096552","rc":[{"batb":[[0,4.9,3.36]],"ltp":5.0,"tv":1408.62,"id":21580749}]}]}
{"op":"mcm","clk":"992291347","pt":1580518808485,"mc":[{"id":"1.168096552","rc":[{"trd":[[3.05,364.85]],"batb":[[0,3,100.65],[1,2.98,4],[2,2.96,2]],"ltp":3.05,"tv":2113.36,"id":18286408}],"tv":9583.43}]}
{"op":"mcm","clk":"992291353","pt":1580518808591,"mc":[{"id":"1.168096552","rc":[{"trd":[[3.05,365.71]],"batb":[[0,3,100.22]],"ltp":3.05,"tv":2114.22,"id":18286408}],"tv":9584.29}]}
{"op":"mcm","clk":"992291715","pt":1580518818983,"mc":[{"id":"1.168096552","rc":[{"trd":[[5,80.01]],"batl":[[0,5.1,20],[1,5.3,9],[2,6,2.5]],"ltp":5.0,"tv":1421.74,"id":21580749}],"tv":9597.41}]}
{"op":"mcm","clk":"992292793","pt":1580518852048,"mc":[{"id":"1.168096552","rc":[{"batb":[[0,12.5,1.39],[1,12,2.91],[2,11.5,10.42]],"ltp":13.0,"tv":306.81,"id":26640937},{"batb":[[0,4.9,6.54]],"ltp":5.0,"tv":1421.74,"id":21580749},{"batb":[[0,36,1.98],[1,34,2.34],[2,32,2.54]],"ltp":40.0,"tv":38.51,"id":27706761},{"batb":[[0,3,5.04]],"ltp":3.0,"tv":5658.07,"id":52106},{"batb":[[0,13.5,2.39],[1,13,2],[2,11.5,33.24]],"ltp":21.0,"tv":58.04,"id":24608298}]}]}
{"op":"mcm","clk":"992292857","pt":1580518854431,"mc":[{"id":"1.168096552","rc":[{"batb":[[1,13,30.05],[2,11.5,1.54]],"ltp":21.0,"tv":58.04,"id":24608298}]}]}
{"op":"mcm","clk":"992292889","pt":1580518855051,"mc":[{"id":"1.168096552","rc":[{"batb":[[2,10.5,2.36]],"ltp":21.0,"tv":58.04,"id":24608298}]}]}
{"op":"mcm","clk":"992293054","pt":1580518861437,"mc":[{"id":"1.168096552","rc":[{"batb":[[0,13.5,3.7]],"ltp":21.0,"tv":58.04,"id":24608298}]}]}
{"op":"mcm","clk":"992293102","pt":1580518862930,"mc":[{"id":"1.168096552","rc":[{"batb":[[0,3.05,5.88],[1,3,100.22],[2,2.98,4]],"ltp":3.05,"tv":2114.22,"id":18286408},{"batb":[[0,13.5,14.62]],"ltp":21.0,"tv":58.04,"id":24608298}]}]}
{"op":"mcm","clk":"992293172","pt":1580518865433,"mc":[{"id":"1.168096552","rc":[{"batb":[[0,14,3.21],[1,13.5,14.22],[2,13,30.05]],"ltp":21.0,"tv":58.04,"id":24608298}]}]}
{"op":"mcm","clk":"992293579","pt":1580518872449,"mc":[{"id":"1.168096552","rc":[{"batb":[[0,14,29.26],[2,13,2]],"ltp":21.0,"tv":58.04,"id":24608298}]}]}
{"op":"mcm","clk":"992293690","pt":1580518873848,"mc":[{"id":"1.168096552","rc":[{"batb":[[1,13.5,12.91]],"ltp":21.0,"tv":58.04,"id":24608298}]}]}
{"op":"mcm","clk":"992293858","pt":1580518880281,"mc":[{"id":"1.168096552","rc":[{"batb":[[0,14.5,1.62],[1,14,28.85],[2,13.5,12.91]],"ltp":21.0,"tv":58.04,"id":24608298}]}]}
{"op":"mcm","clk":"992294331","pt":1580518888497,"mc":[{"id":"1.168096552","rc":[{"batb":[[0,14.5,3.33]],"ltp":21.0,"tv":58.04,"id":24608298}]}]}
{"op":"mcm","clk":"992294397","pt":1580518889474,"mc":[{"id":"1.168096552","rc":[{"batb":[[1,14,2.81]],"ltp":21.0,"tv":58.04,"id":24608298}]}]}
{"op":"mcm","clk":"992294412","pt":1580518889577,"mc":[{"id":"1.168096552","rc":[{"batb":[[0,14.5,28.48]],"ltp":21.0,"tv":58.04,"id":24608298}]}]}
{"op":"mcm","clk":"992294826","pt":1580518897172,"mc":[{"id":"1.168096552","rc":[{"trd":[[3,689.94]],"batb":[[0,3,2.77]],"ltp":3.0,"tv":5662.61,"id":52106}],"tv":9601.95}]}
{"op":"mcm","clk":"992294898","pt":1580518898881,"mc":[{"id":"1.168096552","rc":[{"trd":[[3,694.49]],"batb":[[0,2.98,21.41],[1,2.96,4.03],[2,2.84,46.76]],"ltp":3.0,"tv":5667.16,"id":52106}],"tv":9606.5}]}
{"op":"mcm","clk":"992294986","pt":1580518900076,"mc":[{"id":"1.168096552","rc":[{"trd":[[3.05,290.23]],"batl":[[0,3.05,31.15]],"ltp":3.05,"tv":5693.72,"id":52106}],"tv":9633.06}]}
{"op":"mcm","clk":"992295166","pt":1580518905486,"mc":[{"id":"1.168096552","rc":[{"batb":[[1,13.5,12.91],[2,13,2]],"ltp":21.0,"tv":58.04,"id":24608298}]}]}
{"op":"mcm","clk":"992295618","pt":1580518921233,"mc":[{"id":"1.168096552","rc":[{"trd":[[3.05,328.09]],"batl":[[0,3.05,12.22]],"ltp":3.05,"tv":5731.58,"id":52106}],"tv":9670.92}]}
{"op":"mcm","clk":"992295682","pt":1580518923448,"mc":[{"id":"1.168096552","rc":[{"trd":[[3.05,352.54],[3.1,8.01],[3.15,8.7]],"batl":[[0,3.15,6.85],[1,3.85,10],[2,5.3,6.98]],"ltp":3.15,"tv":5769.45,"id":52106}],"tv":9708.79}]}
{"op":"mcm","clk":"992295930","pt":1580518931844,"mc":[{"id":"1.168096552","rc":[{"trd":[[3.15,22.39]],"batl":[[0,3.85,10],[1,5.3,6.98],[2,5.6,12]],"ltp":3.15,"tv":5783.14,"id":52106}],"tv":9722.49}]}
{"op":"mcm","clk":"992295992","pt":1580518934361,"mc":[{"id":"1.168096552","rc":[{"batl":[[0,3.55,38.54],[1,3.85,10],[2,5.3,6.98]],"ltp":3.15,"tv":5783.14,"id":52106}]}]}
{"op":"mcm","clk":"992296005","pt":1580518935032,"mc":[{"id":"1.168096552","rc":[{"batl":[[0,5,10],[1,5.1,20],[2,5.3,9]],"ltp":5.0,"tv":1421.74,"id":21580749},{"batl":[[0,3.5,9.37],[1,3.55,38.54],[2,3.85,10]],"ltp":3.15,"tv":5783.14,"id":52106}]}]}
{"op":"mcm","clk":"992296066","pt":1580518937262,"mc":[{"id":"1.168096552","rc":[{"batl":[[0,3.85,10.19],[1,5.3,6.98],[2,5.6,12]],"ltp":3.15,"tv":5783.14,"id":52106}]}]}
{"op":"mcm","clk":"992296177","pt":1580518942457,"mc":[{"id":"1.168096552","rc":[{"batb":[[0,14.5,3.33]],"ltp":21.0,"tv":58.04,"id":24608298}]}]}
{"op":"mcm","clk":"992296220","pt":1580518944263,"mc":[{"id":"1.168096552","rc":[{"batb":[[2,2.88,6.36]],"batl":[[0,3.8,5.01],[1,3.85,10],[2,5.3,6.98]],"ltp":3.15,"tv":5783.14,"id":52106},{"batb":[[0,14.5,2.11]],"ltp":21.0,"tv":58.04,"id":24608298}]}]}
{"op":"mcm","clk":"992296264","pt":1580518945468,"mc":[{"id":"1.168096552","rc":[{"batl":[[0,3.7,9.01],[1,3.75,10.5],[2,3.8,5.01]],"ltp":3.15,"tv":5783.14,"id":52106}]}]}
{"op":"mcm","clk":"992296367","pt":1580518949379,"mc":[{"id":"1.168096552","rc":[{"batl":[[0,3.7,9.2],[2,3.8,4.82]],"ltp":3.15,"tv":5783.14,"id":52106},{"batb":[[1,14,1.26],[2,13.5,12.91]],"ltp":21.0,"tv":58.04,"id":24608298}]}]}
{"op":"mcm","clk":"992296384","pt":1580518949893,"mc":[{"id":"1.168096552","rc":[{"batb":[[2,13.5,1.98]],"ltp":21.0,"tv":58.04,"id":24608298}]}]}
{"op":"mcm","clk":"992296542","pt":1580518956000,"mc":[{"id":"1.168096552","rc":[{"batb":[[1,13.5,1.98],[2,13,2]],"ltp":21.0,"tv":58.04,"id":24608298}]}]}
{"op":"mcm","clk":"992296804","pt":1580518965015,"mc":[{"id":"1.168096552","rc":[{"batl":[[0,3.8,5.01],[1,3.85,10],[2,5.3,6.98]],"ltp":3.15,"tv":5783.14,"id":52106}]}]}
{"op":"mcm","clk":"992297291","pt":1580518983943,"mc":[{"id":"1.168096552","rc":[{"batl":[[0,3.75,10.69],[1,3.8,4.82],[2,3.85,10]],"ltp":3.15,"tv":5783.14,"id":52106}]}]}
{"op":"mcm","clk":"992297523","pt":1580518995729,"mc":[{"id":"1.168096552","rc":[{"batl":[[0,3.7,4.07],[1,3.75,10.5]],"ltp":3.15,"tv":5783.14,"id":52106}]}]}
{"op":"mcm","clk":"992297723","pt":1580519004360,"mc":[{"id":"1.168096552","rc":[{"batl":[[1,3.85,10],[2,5.3,6.98]],"ltp":3.15,"tv":5783.14,"id":52106}]}]}
{"op":"mcm","clk":"992298337","pt":1580519029470,"mc":[{"id":"1.168096552","rc":[{"batl":[[0,3.8,3.71]],"ltp":3.15,"tv":5783.14,"id":52106}]}]}
{"op":"mcm","clk":"992298586","pt":1580519042247,"mc":[{"id":"1.168096552","rc":[{"batl":[[0,3.75,10.69],[1,3.8,3.52],[2,3.85,10]],"ltp":3.15,"tv":5783.14,"id":52106}]}]}
{"op":"mcm","clk":"992298665","pt":1580519047710,"mc":[{"id":"1.168096552","rc":[{"batl":[[0,3.55,9.27],[1,3.6,37.86],[2,3.75,10.69]],"ltp":3.15,"tv":5783.14,"id":52106}]}]}
{"op":"mcm","clk":"992298711","pt":1580519051060,"mc":[{"id":"1.168096552","rc":[{"batl":[[0,3.5,38.05],[1,3.55,9.27],[2,3.6,37.86]],"ltp":3.15,"tv":5783.14,"id":52106}]}]}
{"op":"mcm","clk":"992299378","pt":1580519073468,"mc":[{"id":"1.168096552","rc":[{"batl":[[0,3.45,5.5],[1,3.5,37.86],[2,3.55,9.27]],"ltp":3.15,"tv":5783.14,"id":52106}]}]}
{"op":"mcm","clk":"992299459","pt":1580519076101,"mc":[{"id":"1.168096552","rc":[{"batl":[[1,3.55,9.27],[2,3.85,10]],"ltp":3.15,"tv":5783.14,"id":52106}]}]}
{"op":"mcm","clk":"992300326","pt":1580519104513,"mc":[{"id":"1.168096552","rc":[{"trd":[[3.45,0.38]],"batl":[[0,3.5,3.7],[1,3.85,10],[2,5.3,6.98]],"ltp":3.45,"tv":5783.52,"id":52106}],"tv":9722.87}]}
{"op":"mcm","clk":"992300372","pt":1580519106167,"mc":[{"id":"1.168096552","rc":[{"batl":[[0,3.5,3.89]],"ltp":3.45,"tv":5783.52,"id":52106}]}]}
{"op":"mcm","clk":"992300521","pt":1580519113037,"mc":[{"id":"1.168096552","rc":[{"batl":[[1,3.6,2],[2,3.85,10]],"ltp":3.45,"tv":5783.52,"id":52106}]}]}
{"op":"mcm","clk":"992300672","pt":1580519120446,"mc":[{"id":"1.168096552","rc":[{"batl":[[1,3.6,3]],"ltp":3.45,"tv":5783.52,"id":52106}]}]}
{"op":"mcm","clk":"992300825","pt":1580519127165,"mc":[{"id":"1.168096552","rc":[{"batl":[[1,3.6,1]],"ltp":3.45,"tv":5783.52,"id":52106}]}]}
{"op":"mcm","clk":"992301034","pt":1580519137388,"mc":[{"id":"1.168096552","rc":[{"batl":[[0,3.5,4.89],[1,3.85,10],[2,5.3,6.98]],"ltp":3.45,"tv":5783.52,"id":52106}]}]}
{"op":"mcm","clk":"992301256","pt":1580519146301,"mc":[{"id":"1.168096552","rc":[{"batl":[[0,3.5,1.19],[1,3.8,3.72],[2,3.85,10]],"ltp":3.45,"tv":5783.52,"id":52106}]}]}
{"op":"mcm","clk":"992314430","pt":1580519289090,"mc":[{"id":"1.168096552","rc":[{"batl":[[0,3.35,37.86],[1,3.5,1.19],[2,3.8,3.72]],"ltp":3.45,"tv":5783.52,"id":52106}]}]}
{"op":"mcm","clk":"992314571","pt":1580519294492,"mc":[{"id":"1.168096552","rc":[{"trd":[[4.9,61.08]],"batb":[[0,4.8,12.38],[1,4.7,21.12],[2,4.5,27.25]],"batl":[[0,4.9,3.46],[1,5,10],[2,5.1,20]],"ltp":4.9,"tv":1434.82,"id":21580749}],"tv":9735.94}]}
{"op":"mcm","clk":"992314607","pt":1580519295419,"mc":[{"id":"1.168096552","rc":[{"trd":[[4.9,68],[5,86.93]],"batl":[[0,5,6.54],[1,5.1,20],[2,5.3,9]],"ltp":5.0,"tv":1448.66,"id":21580749}],"tv":9749.78}]}
{"op":"mcm","clk":"992314862","pt":1580519302731,"mc":[{"id":"1.168096552","rc":[{"batl":[[0,3.3,5.55],[1,3.35,37.86],[2,3.5,1.19]],"ltp":3.45,"tv":5783.52,"id":52106}]}]}
{"op":"mcm","clk":"992314961","pt":1580519305199,"mc":[{"id":"1.168096552","rc":[{"batl":[[1,3.5,1],[2,3.85,10]],"ltp":3.45,"tv":5783.52,"id":52106}]}]}
{"op":"mcm","clk":"992315569","pt":1580519334165,"mc":[{"id":"1.168096552","rc":[{"batl":[[0,3.5,1],[1,3.8,4.13]],"ltp":3.45,"tv":5783.52,"id":52106}]}]}
{"op":"mcm","clk":"992315753","pt":1580519340975,"mc":[{"id":"1.168096552","rc":[{"batl":[[0,3.5,1.2]],"ltp":3.45,"tv":5783.52,"id":52106}]}]}
{"op":"mcm","clk":"992318966","pt":1580519458733,"mc":[{"id":"1.168096552","rc":[{"batb":[[2,4.6,39.3]],"ltp":5.0,"tv":1448.66,"id":21580749}]}]}
{"op":"mcm","clk":"992320430","pt":1580519522556,"mc":[{"id":"1.168096552","rc":[{"batl":[[0,3.25,37.86],[1,3.5,1.2],[2,3.8,4.13]],"ltp":3.45,"tv":5783.52,"id":52106}]}]}
{"op":"mcm","clk":"992320541","pt":1580519526636,"mc":[{"id":"1.168096552","rc":[{"batl":[[1,3.5,1]],"ltp":3.45,"tv":5783.52,"id":52106}]}]}
{"op":"mcm","clk":"992321226","pt":1580519554162,"mc":[{"id":"1.168096552","rc":[{"batl":[[0,3.15,10.11],[1,3.2,5.72],[2,3.25,37.86]],"ltp":3.45,"tv":5783.52,"id":52106}]}]}
{"op":"mcm","clk":"992321251","pt":1580519555343,"mc":[{"id":"1.168096552","rc":[{"batb":[[1,13.5,28.99]],"ltp":21.0,"tv":58.04,"id":24608298}]}]}
{"op":"mcm","clk":"992321265","pt":1580519555858,"mc":[{"id":"1.168096552","rc":[{"batb":[[1,14,1.23],[2,13.5,28.99]],"ltp":21.0,"tv":58.04,"id":24608298}]}]}
{"op":"mcm","clk":"992321493","pt":1580519565171,"mc":[{"id":"1.168096552","rc":[{"batb":[[1,14,2.49]],"ltp":21.0,"tv":58.04,"id":24608298}]}]}
{"op":"mcm","clk":"992321593","pt":1580519568352,"mc":[{"id":"1.168096552","rc":[{"batb":[[0,14.5,4.83]],"ltp":21.0,"tv":58.04,"id":24608298}]}]}
{"op":"mcm","clk":"992321714","pt":1580519572465,"mc":[{"id":"1.168096552","rc":[{"batb":[[0,15,24.71],[1,14.5,4.43],[2,14,2.49]],"ltp":21.0,"tv":58.04,"id":24608298}]}]}
{"op":"mcm","clk":"992321903","pt":1580519579413,"mc":[{"id":"1.168096552","rc":[{"batb":[[2,14,1.23]],"ltp":21.0,"tv":58.04,"id":24608298}]}]}
{"op":"mcm","clk":"992322056","pt":1580519586111,"mc":[{"id":"1.168096552","rc":[{"batb":[[0,15.5,1.54],[1,15,24.31],[2,14.5,4.43]],"ltp":21.0,"tv":58.04,"id":24608298}]}]}
{"op":"mcm","clk":"992322090","pt":1580519587807,"mc":[{"id":"1.168096552","rc":[{"batb":[[2,14.5,1.71]],"ltp":21.0,"tv":58.04,"id":24608298}]}]}
{"op":"mcm","clk":"992322136","pt":1580519590391,"mc":[{"id":"1.168096552","rc":[{"batb":[[1,14.5,1.71],[2,14,1.23]],"ltp":21.0,"tv":58.04,"id":24608298}]}]}
{"op":"mcm","clk":"992322139","pt":1580519590525,"mc":[{"id":"1.168096552","rc":[{"batb":[[2,14,27.27]],"ltp":21.0,"tv":58.04,"id":24608298}]}]}
{"op":"mcm","clk":"992322214","pt":1580519593697,"mc":[{"id":"1.168096552","rc":[{"batb":[[0,14.5,2.11],[1,14,27.27],[2,13.5,1.98]],"ltp":21.0,"tv":58.04,"id":24608298}]}]}
{"op":"mcm","clk":"992322462","pt":1580519601309,"mc":[{"id":"1.168096552","rc":[{"batb":[[0,14.5,3.33]],"ltp":21.0,"tv":58.04,"id":24608298}]}]}
{"op":"mcm","clk":"992322498","pt":1580519602444,"mc":[{"id":"1.168096552","rc":[{"batl":[[2,3.5,1]],"ltp":3.45,"tv":5783.52,"id":52106}]}]}
{"op":"mcm","clk":"992322648","pt":1580519607497,"mc":[{"id":"1.168096552","rc":[{"batb":[[0,15,3.03],[1,14.5,28.08],[2,14,1.23]],"ltp":21.0,"tv":58.04,"id":24608298}]}]}
{"op":"mcm","clk":"992322758","pt":1580519611305,"mc":[{"id":"1.168096552","rc":[{"batl":[[1,3.2,7.72]],"ltp":3.45,"tv":5783.52,"id":52106}]}]}
{"op":"mcm","clk":"992323151","pt":1580519625453,"mc":[{"id":"1.168096552","rc":[{"batb":[[0,15,27.34],[1,14.5,2.93]],"ltp":21.0,"tv":58.04,"id":24608298}]}]}
{"op":"mcm","clk":"992323282","pt":1580519629826,"mc":[{"id":"1.168096552","rc":[{"batb":[[1,14.5,1.71]],"ltp":21.0,"tv":58.04,"id":24608298}]}]}
{"op":"mcm","clk":"992323420","pt":1580519635474,"mc":[{"id":"1.168096552","rc":[{"batl":[[0,4.9,10],[1,5,6.54],[2,5.1,20]],"ltp":5.0,"tv":1448.66,"id":21580749}]}]}
{"op":"mcm","clk":"992323472","pt":1580519637142,"mc":[{"id":"1.168096552","rc":[{"batb":[[0,15.5,1.54],[1,15,26.93],[2,14.5,1.71]],"ltp":21.0,"tv":58.04,"id":24608298}]}]}
{"op":"mcm","clk":"992324181","pt":1580519673200,"mc":[{"id":"1.168096552","rc":[{"batb":[[0,4.8,23.3]],"ltp":5.0,"tv":1448.66,"id":21580749},{"batb":[[0,15.5,10.78]],"ltp":21.0,"tv":58.04,"id":24608298}]}]}
{"op":"mcm","clk":"992324279","pt":1580519677479,"mc":[{"id":"1.168096552","rc":[{"trd":[[4.9,87.99]],"batb":[[0,4.9,59.16],[1,4.8,23.3],[2,4.7,21.12]],"batl":[[0,5,6.54],[1,5.1,20],[2,5.3,9]],"ltp":4.9,"tv":1468.65,"id":21580749},{"batb":[[0,16,23.19],[1,15.5,10.38],[2,15,2.63]],"ltp":21.0,"tv":58.04,"id":24608298}],"tv":9769.77}]}
{"op":"mcm","clk":"992324339","pt":1580519681494,"mc":[{"id":"1.168096552","rc":[{"batb":[[1,15.5,9.24]],"ltp":21.0,"tv":58.04,"id":24608298}]}]}
{"op":"mcm","clk":"992324406","pt":1580519684485,"mc":[{"id":"1.168096552","rc":[{"batb":[[2,14.5,1.71]],"ltp":21.0,"tv":58.04,"id":24608298}]}]}
{"op":"mcm","clk":"992324412","pt":1580519684795,"mc":[{"id":"1.168096552","rc":[{"batb":[[0,16.5,2.48],[1,16,23.1],[2,15.5,9.24]],"ltp":21.0,"tv":58.04,"id":24608298}]}]}
{"op":"mcm","clk":"992324458","pt":1580519688030,"mc":[{"id":"1.168096552","rc":[{"batb":[[0,16.5,3.54]],"ltp":21.0,"tv":58.04,"id":24608298}]}]}
{"op":"mcm","clk":"992324601","pt":1580519695441,"mc":[{"id":"1.168096552","rc":[{"batb":[[0,4.8,23.3],[1,4.7,21.12],[2,4.6,39.3]],"ltp":4.9,"tv":1468.65,"id":21580749},{"batb":[[1,15.5,9.55],[2,14.5,1.71]],"ltp":21.0,"tv":58.04,"id":24608298}]}]}
{"op":"mcm","clk":"992324606","pt":1580519695646,"mc":[{"id":"1.168096552","rc":[{"batb":[[0,16.5,25.64]],"ltp":21.0,"tv":58.04,"id":24608298}]}]}
{"op":"mcm","clk":"992325350","pt":1580519728869,"mc":[{"id":"1.168096552","rc":[{"batl":[[0,3.15,29.04]],"ltp":3.45,"tv":5783.52,"id":52106}]}]}
{"op":"mcm","clk":"992325478","pt":1580519736175,"mc":[{"id":"1.168096552","rc":[{"batl":[[1,3.2,5.72]],"ltp":3.45,"tv":5783.52,"id":52106}]}]}
{"op":"mcm","clk":"992326445","pt":1580519779463,"mc":[{"id":"1.168096552","rc":[{"trd":[[5,100.01]],"batl":[[0,5.1,20],[1,5.3,9],[2,6,2.5]],"ltp":5.0,"tv":1481.73,"id":21580749},{"trd":[[3.15,80.48]],"batl":[[0,3.2,5.72],[1,3.5,1],[2,3.85,10]],"ltp":3.15,"tv":5841.61,"id":52106}],"tv":9840.93}]}
{"op":"mcm","clk":"992327047","pt":1580519804060,"mc":[{"id":"1.168096552","rc":[{"batl":[[0,3.5,1],[1,3.8,4.18]],"ltp":3.15,"tv":5841.61,"id":52106}]}]}
{"op":"mcm","clk":"992327142","pt":1580519807157,"mc":[{"id":"1.168096552","rc":[{"batl":[[0,3.5,1.19]],"ltp":3.15,"tv":5841.61,"id":52106}]}]}
{"op":"mcm","clk":"992327433","pt":1580519818410,"mc":[{"id":"1.168096552","rc":[{"batb":[[0,16.5,3.54]],"ltp":21.0,"tv":58.04,"id":24608298}]}]}
{"op":"mcm","clk":"992327466","pt":1580519819494,"mc":[{"id":"1.168096552","rc":[{"batl":[[1,3.75,10.5],[2,3.8,4.18]],"ltp":3.15,"tv":5841.61,"id":52106}]}]}
{"op":"mcm","clk":"992327593","pt":1580519823726,"mc":[{"id":"1.168096552","rc":[{"batb":[[0,17,1.02],[1,16.5,3.54],[2,15.5,9.55]],"ltp":21.0,"tv":58.04,"id":24608298}]}]}
{"op":"mcm","clk":"992327631","pt":1580519825013,"mc":[{"id":"1.168096552","rc":[{"batb":[[1,16.5,2.48],[2,14.5,2.02]],"ltp":21.0,"tv":58.04,"id":24608298}]}]}
{"op":"mcm","clk":"992327894","pt":1580519835634,"mc":[{"id":"1.168096552","rc":[{"batl":[[1,3.7,3.97],[2,3.75,10.5]],"ltp":3.15,"tv":5841.61,"id":52106}]}]}
{"op":"mcm","clk":"992327954","pt":1580519839521,"mc":[{"id":"1.168096552","rc":[{"batl":[[2,3.85,10]],"ltp":3.15,"tv":5841.61,"id":52106},{"batb":[[1,14.5,2.11],[2,13.5,1.98]],"ltp":21.0,"tv":58.04,"id":24608298}]}]}
{"op":"mcm","clk":"992328314","pt":1580519856438,"mc":[{"id":"1.168096552","rc":[{"batl":[[1,3.7,22.9]],"ltp":3.15,"tv":5841.61,"id":52106}]}]}
{"op":"mcm","clk":"992328363","pt":1580519859055,"mc":[{"id":"1.168096552","rc":[{"batl":[[2,3.8,18.93]],"ltp":3.15,"tv":5841.61,"id":52106}]}]}
{"op":"mcm","clk":"992331081","pt":1580519964273,"mc":[{"id":"1.168096552","rc":[{"batb":[[1,4.7,24.04]],"ltp":5.0,"tv":1481.73,"id":21580749}]}]}
{"op":"mcm","clk":"992331343","pt":1580519974197,"mc":[{"id":"1.168096552","rc":[{"batl":[[1,5.2,10],[2,5.3,9]],"ltp":5.0,"tv":1481.73,"id":21580749}]}]}
{"op":"mcm","clk":"992331433","pt":1580519977400,"mc":[{"id":"1.168096552","rc":[{"batl":[[0,3.3,1.51],[1,3.5,1.19],[2,3.7,22.9]],"ltp":3.15,"tv":5841.61,"id":52106}]}]}
{"op":"mcm","clk":"992331464","pt":1580519978506,"mc":[{"id":"1.168096552","rc":[{"batl":[[0,3.5,1.19],[1,3.7,22.9],[2,3.8,18.93]],"ltp":3.15,"tv":5841.61,"id":52106}]}]}
{"op":"mcm","clk":"992348290","pt":1580520269669,"mc":[{"id":"1.168096552","rc":[{"trd":[[3.1,32.01]],"ltp":3.1,"tv":5865.61,"id":52106}],"tv":9864.93}]}
{"op":"mcm","clk":"992348642","pt":1580520280672,"mc":[{"id":"1.168096552","rc":[{"batl":[[1,5.2,15]],"ltp":5.0,"tv":1481.73,"id":21580749}]}]}
{"op":"mcm","clk":"992348729","pt":1580520283880,"mc":[{"id":"1.168096552","rc":[{"batl":[[1,5.2,10]],"ltp":5.0,"tv":1481.73,"id":21580749}]}]}
{"op":"mcm","clk":"992348961","pt":1580520291102,"mc":[{"id":"1.168096552","rc":[{"batl":[[0,5,5],[1,5.1,20],[2,5.2,10]],"ltp":5.0,"tv":1481.73,"id":21580749}]}]}
{"op":"mcm","clk":"992350342","pt":1580520341362,"mc":[{"id":"1.168096552","rc":[{"batl":[[0,3.25,12],[1,3.5,1.19],[2,3.7,22.9]],"ltp":3.1,"tv":5865.61,"id":52106}]}]}
{"op":"mcm","clk":"992350391","pt":1580520342445,"mc":[{"id":"1.168096552","rc":[{"batl":[[1,3.5,1]],"ltp":3.1,"tv":5865.61,"id":52106}]}]}
{"op":"mcm","clk":"992350473","pt":1580520344463,"mc":[{"id":"1.168096552","rc":[{"batb":[[1,14.5,27.26]],"ltp":21.0,"tv":58.04,"id":24608298}]}]}
{"op":"mcm","clk":"992350577","pt":1580520347242,"mc":[{"id":"1.168096552","rc":[{"trd":[[2.98,357.65],[3,695.48]],"batb":[[0,2.98,17.21]],"ltp":2.98,"tv":5874.01,"id":52106}],"tv":9873.33}]}
{"op":"mcm","clk":"992350742","pt":1580520354473,"mc":[{"id":"1.168096552","rc":[{"batb":[[0,3,3],[1,2.98,17.21],[2,2.96,4.03]],"ltp":2.98,"tv":5874.01,"id":52106}]}]}
{"op":"mcm","clk":"992350769","pt":1580520355960,"mc":[{"id":"1.168096552","rc":[{"batb":[[1,15,1.58],[2,14.5,26.86]],"ltp":21.0,"tv":58.04,"id":24608298}]}]}
{"op":"mcm","clk":"992350885","pt":1580520362474,"mc":[{"id":"1.168096552","rc":[{"batb":[[2,14.5,1.71]],"ltp":21.0,"tv":58.04,"id":24608298}]}]}
{"op":"mcm","clk":"992350889","pt":1580520362580,"mc":[{"id":"1.168096552","rc":[{"batb":[[1,15,25.89]],"ltp":21.0,"tv":58.04,"id":24608298}]}]}
{"op":"mcm","clk":"992351104","pt":1580520370497,"mc":[{"id":"1.168096552","rc":[{"batl":[[2,3.7,18.93]],"ltp":2.98,"tv":5874.01,"id":52106}]}]}
{"op":"mcm","clk":"992351124","pt":1580520371299,"mc":[{"id":"1.168096552","rc":[{"batl":[[0,3.2,5.72],[1,3.25,12],[2,3.5,1]],"ltp":2.98,"tv":5874.01,"id":52106}]}]}
{"op":"mcm","clk":"992351943","pt":1580520402243,"mc":[{"id":"1.168096552","rc":[{"batl":[[0,3.25,12],[1,3.5,1],[2,3.65,4.43]],"ltp":2.98,"tv":5874.01,"id":52106}]}]}
{"op":"mcm","clk":"992354747","pt":1580520513462,"mc":[{"id":"1.168096552","rc":[{"trd":[[3,701.48]],"batb":[[0,2.98,17.21],[1,2.96,4.03],[2,2.88,6.36]],"batl":[[0,3,10.81],[1,3.25,12],[2,3.5,1]],"ltp":3.0,"tv":5880.01,"id":52106}],"tv":9879.33}]}
{"op":"mcm","clk":"992354997","pt":1580520520488,"mc":[{"id":"1.168096552","rc":[{"batb":[[0,3.05,107.88]],"ltp":3.05,"tv":2114.22,"id":18286408}]}]}
{"op":"mcm","clk":"992355265","pt":1580520528594,"mc":[{"id":"1.168096552","rc":[{"batb":[[2,2.84,46.76]],"ltp":3.0,"tv":5880.01,"id":52106}]}]}
{"op":"mcm","clk":"992355343","pt":1580520531489,"mc":[{"id":"1.168096552","rc":[{"batb":[[1,15.5,8.8],[2,15,25.48]],"ltp":21.0,"tv":58.04,"id":24608298}]}]}
{"op":"mcm","clk":"992355527","pt":1580520537473,"mc":[{"id":"1.168096552","rc":[{"batb":[[0,3.05,5.88]],"ltp":3.05,"tv":2114.22,"id":18286408},{"batb":[[2,15,1.18]],"ltp":21.0,"tv":58.04,"id":24608298}]}]}
{"op":"mcm","clk":"992355533","pt":1580520537578,"mc":[{"id":"1.168096552","rc":[{"batb":[[1,16,23.19],[2,15.5,8.4]],"ltp":21.0,"tv":58.04,"id":24608298}]}]}
{"op":"mcm","clk":"992355643","pt":1580520540712,"mc":[{"id":"1.168096552","rc":[{"batb":[[1,16.5,2.48],[2,16,23.1]],"ltp":21.0,"tv":58.04,"id":24608298}]}]}
{"op":"mcm","clk":"992355768","pt":1580520545479,"mc":[{"id":"1.168096552","rc":[{"trd":[[4.8,62.71]],"batb":[[0,4.8,21.3]],"ltp":4.8,"tv":1485.73,"id":21580749}],"tv":9883.33}]}
{"op":"mcm","clk":"992355810","pt":1580520546708,"mc":[{"id":"1.168096552","rc":[{"batb":[[1,16.5,3.54]],"ltp":21.0,"tv":58.04,"id":24608298}]}]}
{"op":"mcm","clk":"992356104","pt":1580520555484,"mc":[{"id":"1.168096552","rc":[{"batb":[[2,15.5,8.71]],"ltp":21.0,"tv":58.04,"id":24608298}]}]}
{"op":"mcm","clk":"992356111","pt":1580520555585,"mc":[{"id":"1.168096552","rc":[{"batb":[[0,3.05,107.88]],"ltp":3.05,"tv":2114.22,"id":18286408},{"batb":[[0,17,22.46]],"ltp":21.0,"tv":58.04,"id":24608298}]}]}
{"op":"mcm","clk":"992356234","pt":1580520560219,"mc":[{"id":"1.168096552","rc":[{"batb":[[1,16.5,1.16]],"ltp":21.0,"tv":58.04,"id":24608298}]}]}
{"op":"mcm","clk":"992356288","pt":1580520562388,"mc":[{"id":"1.168096552","rc":[{"batb":[[1,15.5,8.8],[2,14.5,1.71]],"ltp":21.0,"tv":58.04,"id":24608298}]}]}
{"op":"mcm","clk":"992356468","pt":1580520569932,"mc":[{"id":"1.168096552","rc":[{"batb":[[0,17.5,1.01],[1,17,22.46],[2,15.5,8.8]],"ltp":21.0,"tv":58.04,"id":24608298}]}]}
{"op":"mcm","clk":"992356521","pt":1580520572416,"mc":[{"id":"1.168096552","rc":[{"batb":[[0,3.05,5.88]],"ltp":3.05,"tv":2114.22,"id":18286408}]}]}
{"op":"mcm","clk":"992356661","pt":1580520578210,"mc":[{"id":"1.168096552","rc":[{"trd":[[3,723.11]],"batb":[[0,3.05,10.48],[1,3,4.33],[2,2.98,17.21]],"batl":[[0,3.25,12],[1,3.5,1],[2,3.7,18.93]],"ltp":3.0,"tv":5901.63,"id":52106}],"tv":9904.96}]}
{"op":"mcm","clk":"992356865","pt":1580520585246,"mc":[{"id":"1.168096552","rc":[{"batb":[[0,17.5,3.06]],"ltp":21.0,"tv":58.04,"id":24608298}]}]}
{"op":"mcm","clk":"992356946","pt":1580520587829,"mc":[{"id":"1.168096552","rc":[{"batl":[[0,3.2,2.81],[1,3.25,12],[2,3.5,1]],"ltp":3.0,"tv":5901.63,"id":52106}]}]}
{"op":"mcm","clk":"992357031","pt":1580520590477,"mc":[{"id":"1.168096552","rc":[{"batb":[[1,17,1.02]],"ltp":21.0,"tv":58.04,"id":24608298}]}]}
{"op":"mcm","clk":"992357107","pt":1580520593431,"mc":[{"id":"1.168096552","rc":[{"batb":[[0,17.5,2.05]],"ltp":21.0,"tv":58.04,"id":24608298}]}]}
{"op":"mcm","clk":"992357312","pt":1580520600769,"mc":[{"id":"1.168096552","rc":[{"batb":[[2,16,1.5]],"ltp":21.0,"tv":58.04,"id":24608298}]}]}
{"op":"mcm","clk":"992357625","pt":1580520608657,"mc":[{"id":"1.168096552","rc":[{"batb":[[2,13.5,2.39]],"ltp":21.0,"tv":58.04,"id":24608298}]}]}
{"op":"mcm","clk":"992360209","pt":1580520697496,"mc":[{"id":"1.168096552","rc":[{"batl":[[2,5.2,43]],"ltp":4.8,"tv":1485.73,"id":21580749}]}]}
{"op":"mcm","clk":"992361250","pt":1580520734328,"mc":[{"id":"1.168096552","rc":[{"batb":[[0,3.05,5.28]],"batl":[[0,3.15,34.81],[1,3.2,2.81],[2,3.25,12]],"ltp":3.0,"tv":5901.63,"id":52106}]}]}
{"op":"mcm","clk":"992361435","pt":1580520739814,"mc":[{"id":"1.168096552","rc":[{"trd":[[5,110.01]],"batl":[[0,5.1,20],[1,5.2,43],[2,5.3,9]],"ltp":5.0,"tv":1495.72,"id":21580749}],"tv":9914.96}]}
{"op":"mcm","clk":"992362003","pt":1580520761246,"mc":[{"id":"1.168096552","rc":[{"batl":[[0,3.2,2.81],[1,3.25,12],[2,3.5,1]],"ltp":3.0,"tv":5901.63,"id":52106}]}]}
{"op":"mcm","clk":"992362063","pt":1580520763357,"mc":[{"id":"1.168096552","rc":[{"trd":[[3.05,363.1]],"batb":[[0,3,4.33],[1,2.98,17.21],[2,2.96,4.03]],"ltp":3.05,"tv":5912.19,"id":52106}],"tv":9925.51}]}
{"op":"mcm","clk":"992362210","pt":1580520769242,"mc":[{"id":"1.168096552","rc":[{"batl":[[0,3.1,30.18],[1,3.2,2.81],[2,3.25,12]],"ltp":3.05,"tv":5912.19,"id":52106}]}]}
{"op":"mcm","clk":"992362372","pt":1580520776170,"mc":[{"id":"1.168096552","rc":[{"batb":[[0,4.8,23.5]],"ltp":5.0,"tv":1495.72,"id":21580749}]}]}
{"op":"mcm","clk":"992362833","pt":1580520794411,"mc":[{"id":"1.168096552","rc":[{"batl":[[0,3.05,2.95],[1,3.1,30.18]],"ltp":3.05,"tv":5912.19,"id":52106}]}]}
{"op":"mcm","clk":"992363473","pt":1580520818123,"mc":[{"id":"1.168096552","rc":[{"batl":[[0,5,8],[1,5.1,20],[2,5.2,43]],"ltp":5.0,"tv":1495.72,"id":21580749}]}]}
{"op":"mcm","clk":"992363571","pt":1580520822323,"mc":[{"id":"1.168096552","rc":[{"trd":[[4.9,91.99]],"batl":[[0,4.9,6]],"ltp":4.9,"tv":1499.72,"id":21580749}],"tv":9929.51}]}
{"op":"mcm","clk":"992363671","pt":1580520826452,"mc":[{"id":"1.168096552","rc":[{"batl":[[0,5,6]],"ltp":4.9,"tv":1499.72,"id":21580749}]}]}
{"op":"mcm","clk":"992363723","pt":1580520829036,"mc":[{"id":"1.168096552","rc":[{"batl":[[0,4.9,6]],"ltp":4.9,"tv":1499.72,"id":21580749}]}]}
{"op":"mcm","clk":"992363787","pt":1580520832869,"mc":[{"id":"1.168096552","rc":[{"batl":[[0,5,6]],"ltp":4.9,"tv":1499.72,"id":21580749}]}]}
{"op":"mcm","clk":"992363859","pt":1580520836072,"mc":[{"id":"1.168096552","rc":[{"batl":[[0,4.9,6]],"ltp":4.9,"tv":1499.72,"id":21580749}]}]}
{"op":"mcm","clk":"992363916","pt":1580520839474,"mc":[{"id":"1.168096552","rc":[{"batl":[[0,5.1,20],[1,5.2,43],[2,5.3,9]],"ltp":4.9,"tv":1499.72,"id":21580749}]}]}
{"op":"mcm","clk":"992363917","pt":1580520839578,"mc":[{"id":"1.168096552","rc":[{"trd":[[4.8,74.71]],"batb":[[0,4.8,17.5]],"ltp":4.8,"tv":1511.72,"id":21580749}],"tv":9941.51}]}
{"op":"mcm","clk":"992367035","pt":1580520967046,"mc":[{"id":"1.168096552","rc":[{"trd":[[3.05,369]],"batl":[[0,3.1,30.18],[1,3.25,12],[2,3.5,1]],"ltp":3.05,"tv":5918.09,"id":52106}],"tv":9947.42}]}
{"op":"mcm","clk":"992367073","pt":1580520969519,"mc":[{"id":"1.168096552","rc":[{"batb":[[0,3,6.6]],"ltp":3.05,"tv":5918.09,"id":52106}]}]}
{"op":"mcm","clk":"992367242","pt":1580520980135,"mc":[{"id":"1.168096552","rc":[{"trd":[[3.1,60.89]],"batl":[[0,3.1,15.74]],"ltp":3.1,"tv":5946.97,"id":52106}],"tv":9976.3}]}
{"op":"mcm","clk":"992367798","pt":1580521007068,"mc":[{"id":"1.168096552","rc":[{"batl":[[0,3.25,12],[1,3.5,1],[2,3.7,18.93]],"ltp":3.1,"tv":5946.97,"id":52106}]}]}
{"op":"mcm","clk":"992367856","pt":1580521009482,"mc":[{"id":"1.168096552","rc":[{"batl":[[0,3.05,18.26],[1,3.25,12],[2,3.5,1]],"ltp":3.1,"tv":5946.97,"id":52106}]}]}
{"op":"mcm","clk":"992381782","pt":1580521206520,"mc":[{"id":"1.168096552","rc":[{"batl":[[0,48,5.13]],"ltp":40.0,"tv":38.51,"id":27706761}]}]}
{"op":"mcm","clk":"992382602","pt":1580521248486,"mc":[{"id":"1.168096552","rc":[{"trd":[[3,736.31]],"batb":[[0,2.98,17.21],[1,2.96,4.03],[2,2.84,46.76]],"batl":[[0,3,13.4],[1,3.05,18.26],[2,3.25,12]],"ltp":3.0,"tv":5960.18,"id":52106}],"tv":9989.5}]}
{"op":"mcm","clk":"992382613","pt":1580521249260,"mc":[{"id":"1.168096552","rc":[{"batl":[[1,3.25,12],[2,3.5,1]],"ltp":3.0,"tv":5960.18,"id":52106}]}]}
{"op":"mcm","clk":"992382665","pt":1580521252485,"mc":[{"id":"1.168096552","rc":[{"batl":[[1,3.05,24.76],[2,3.25,12]],"ltp":3.0,"tv":5960.18,"id":52106}]}]}
{"op":"mcm","clk":"992382686","pt":1580521253567,"mc":[{"id":"1.168096552","rc":[{"batl":[[1,3.25,12],[2,3.5,1]],"ltp":3.0,"tv":5960.18,"id":52106}]}]}
{"op":"mcm","clk":"992382750","pt":1580521256248,"mc":[{"id":"1.168096552","rc":[{"trd":[[2.98,392.06]],"batb":[[0,2.96,4.03],[1,2.84,46.76],[2,2.82,7.61]],"batl":[[0,2.98,8.14],[1,3,13.4],[2,3.25,12]],"ltp":2.98,"tv":5994.59,"id":52106}],"tv":10023.92}]}
{"op":"mcm","clk":"992382765","pt":1580521257387,"mc":[{"id":"1.168096552","rc":[{"batb":[[0,3.05,107.88]],"ltp":3.05,"tv":2114.22,"id":18286408},{"batl":[[0,3,13.4],[1,3.25,12],[2,3.5,1]],"ltp":2.98,"tv":5994.59,"id":52106}]}]}
{"op":"mcm","clk":"992382824","pt":1580521260487,"mc":[{"id":"1.168096552","rc":[{"batb":[[0,17.5,5.6],[1,13.5,2.39],[2,13,2]],"ltp":21.0,"tv":58.04,"id":24608298}]}]}
{"op":"mcm","clk":"992382835","pt":1580521260894,"mc":[{"id":"1.168096552","rc":[{"batl":[[0,3,21.49]],"ltp":2.98,"tv":5994.59,"id":52106}]}]}
{"op":"mcm","clk":"992382971","pt":1580521266875,"mc":[{"id":"1.168096552","rc":[{"batl":[[0,3,30.06]],"ltp":2.98,"tv":5994.59,"id":52106}]}]}
{"op":"mcm","clk":"992383047","pt":1580521270073,"mc":[{"id":"1.168096552","rc":[{"batb":[[0,2.86,7.17]],"ltp":2.98,"tv":5994.59,"id":52106}]}]}
{"op":"mcm","clk":"992383129","pt":1580521274398,"mc":[{"id":"1.168096552","rc":[{"batb":[[0,3.05,5.88]],"ltp":3.05,"tv":2114.22,"id":18286408}]}]}
{"op":"mcm","clk":"992383263","pt":1580521280991,"mc":[{"id":"1.168096552","rc":[{"batb":[[0,2.88,13.48],[1,2.86,7.17],[2,2.84,46.76]],"batl":[[1,3.2,12.13],[2,3.25,12]],"ltp":2.98,"tv":5994.59,"id":52106}]}]}
{"op":"mcm","clk":"992383481","pt":1580521288409,"mc":[{"id":"1.168096552","rc":[{"batb":[[0,2.9,7.11],[1,2.88,13.48]],"ltp":2.98,"tv":5994.59,"id":52106}]}]}
{"op":"mcm","clk":"992383587","pt":1580521292431,"mc":[{"id":"1.168096552","rc":[{"batb":[[0,3.05,107.88]],"ltp":3.05,"tv":2114.22,"id":18286408}]}]}
{"op":"mcm","clk":"992383611","pt":1580521293230,"mc":[{"id":"1.168096552","rc":[{"batl":[[0,3,32.06]],"ltp":2.98,"tv":5994.59,"id":52106}]}]}
{"op":"mcm","clk":"992383875","pt":1580521309417,"mc":[{"id":"1.168096552","rc":[{"batb":[[0,3.05,5.88]],"ltp":3.05,"tv":2114.22,"id":18286408}]}]}
{"op":"mcm","clk":"992384257","pt":1580521327447,"mc":[{"id":"1.168096552","rc":[{"batb":[[0,3.05,107.88]],"ltp":3.05,"tv":2114.22,"id":18286408}]}]}
{"op":"mcm","clk":"992384357","pt":1580521332169,"mc":[{"id":"1.168096552","rc":[{"batb":[[0,12.5,2.99]],"ltp":13.0,"tv":306.81,"id":26640937}]}]}
{"op":"mcm","clk":"992384596","pt":1580521344490,"mc":[{"id":"1.168096552","rc":[{"batb":[[0,3.05,5.88]],"ltp":3.05,"tv":2114.22,"id":18286408}]}]}
{"op":"mcm","clk":"992384941","pt":1580521362375,"mc":[{"id":"1.168096552","rc":[{"batb":[[0,3.05,107.88]],"ltp":3.05,"tv":2114.22,"id":18286408}]}]}
{"op":"mcm","clk":"992385250","pt":1580521379422,"mc":[{"id":"1.168096552","rc":[{"batb":[[0,3.05,5.88]],"ltp":3.05,"tv":2114.22,"id":18286408}]}]}
{"op":"mcm","clk":"992385651","pt":1580521397423,"mc":[{"id":"1.168096552","rc":[{"batb":[[0,3.05,107.88]],"ltp":3.05,"tv":2114.22,"id":18286408}]}]}
{"op":"mcm","clk":"992386060","pt":1580521414355,"mc":[{"id":"1.168096552","rc":[{"batb":[[0,3.05,5.88]],"ltp":3.05,"tv":2114.22,"id":18286408}]}]}
{"op":"mcm","clk":"992386456","pt":1580521432353,"mc":[{"id":"1.168096552","rc":[{"batb":[[0,3.05,107.88]],"ltp":3.05,"tv":2114.22,"id":18286408}]}]}
{"op":"mcm","clk":"992386864","pt":1580521449481,"mc":[{"id":"1.168096552","rc":[{"batb":[[0,3.05,5.88]],"ltp":3.05,"tv":2114.22,"id":18286408}]}]}
{"op":"mcm","clk":"992387298","pt":1580521467437,"mc":[{"id":"1.168096552","rc":[{"batb":[[0,3.05,107.88]],"ltp":3.05,"tv":2114.22,"id":18286408}]}]}
{"op":"mcm","clk":"992387676","pt":1580521484424,"mc":[{"id":"1.168096552","rc":[{"batb":[[0,3.05,5.88]],"ltp":3.05,"tv":2114.22,"id":18286408}]}]}
{"op":"mcm","clk":"992388064","pt":1580521502377,"mc":[{"id":"1.168096552","rc":[{"batb":[[0,3.05,107.88]],"ltp":3.05,"tv":2114.22,"id":18286408}]}]}
{"op":"mcm","clk":"992388195","pt":1580521507059,"mc":[{"id":"1.168096552","rc":[{"batl":[[0,2.98,10],[1,3,32.06],[2,3.2,12.13]],"ltp":2.98,"tv":5994.59,"id":52106}]}]}
{"op":"mcm","clk":"992388466","pt":1580521519474,"mc":[{"id":"1.168096552","rc":[{"batb":[[0,3.05,5.88]],"ltp":3.05,"tv":2114.22,"id":18286408}]}]}
{"op":"mcm","clk":"992388846","pt":1580521537412,"mc":[{"id":"1.168096552","rc":[{"batb":[[0,3.05,107.88]],"ltp":3.05,"tv":2114.22,"id":18286408}]}]}
{"op":"mcm","clk":"992389134","pt":1580521552619,"mc":[{"id":"1.168096552","rc":[{"batl":[[1,3,15.4]],"ltp":2.98,"tv":5994.59,"id":52106}]}]}
{"op":"mcm","clk":"992389168","pt":1580521554521,"mc":[{"id":"1.168096552","rc":[{"batb":[[0,3.05,5.88]],"ltp":3.05,"tv":2114.22,"id":18286408}]}]}
{"op":"mcm","clk":"992389571","pt":1580521572469,"mc":[{"id":"1.168096552","rc":[{"batb":[[0,3.05,107.88]],"ltp":3.05,"tv":2114.22,"id":18286408}]}]}
{"op":"mcm","clk":"992390089","pt":1580521589456,"mc":[{"id":"1.168096552","rc":[{"batb":[[0,3.05,5.88]],"ltp":3.05,"tv":2114.22,"id":18286408}]}]}
{"op":"mcm","clk":"992390761","pt":1580521607387,"mc":[{"id":"1.168096552","rc":[{"batb":[[0,3.05,107.88]],"ltp":3.05,"tv":2114.22,"id":18286408}]}]}
{"op":"mcm","clk":"992390942","pt":1580521614503,"mc":[{"id":"1.168096552","rc":[{"batb":[[0,2.9,18.47]],"ltp":2.98,"tv":5994.59,"id":52106}]}]}
{"op":"mcm","clk":"992390983","pt":1580521615991,"mc":[{"id":"1.168096552","rc":[{"batb":[[0,2.9,15.47]],"ltp":2.98,"tv":5994.59,"id":52106}]}]}
{"op":"mcm","clk":"992391201","pt":1580521624407,"mc":[{"id":"1.168096552","rc":[{"batb":[[0,3.05,5.88]],"ltp":3.05,"tv":2114.22,"id":18286408}]}]}
{"op":"mcm","clk":"992391660","pt":1580521642429,"mc":[{"id":"1.168096552","rc":[{"batb":[[0,3.05,107.88]],"ltp":3.05,"tv":2114.22,"id":18286408}]}]}
{"op":"mcm","clk":"992392084","pt":1580521659450,"mc":[{"id":"1.168096552","rc":[{"batb":[[0,3.05,5.88]],"ltp":3.05,"tv":2114.22,"id":18286408}]}]}
{"op":"mcm","clk":"992392509","pt":1580521677503,"mc":[{"id":"1.168096552","rc":[{"batb":[[0,3.05,107.88]],"ltp":3.05,"tv":2114.22,"id":18286408}]}]}
{"op":"mcm","clk":"992392862","pt":1580521694425,"mc":[{"id":"1.168096552","rc":[{"batb":[[0,3.05,5.88]],"ltp":3.05,"tv":2114.22,"id":18286408}]}]}
{"op":"mcm","clk":"992393250","pt":1580521712421,"mc":[{"id":"1.168096552","rc":[{"batb":[[0,3.05,107.88]],"ltp":3.05,"tv":2114.22,"id":18286408}]}]}
{"op":"mcm","clk":"992393616","pt":1580521729466,"mc":[{"id":"1.168096552","rc":[{"batb":[[0,3.05,5.88]],"ltp":3.05,"tv":2114.22,"id":18286408}]}]}
{"op":"mcm","clk":"992393932","pt":1580521747365,"mc":[{"id":"1.168096552","rc":[{"batb":[[0,3.05,107.88]],"ltp":3.05,"tv":2114.22,"id":18286408}]}]}
{"op":"mcm","clk":"992394125","pt":1580521757392,"mc":[{"id":"1.168096552","rc":[{"batl":[[2,3.15,7.7]],"ltp":2.98,"tv":5994.59,"id":52106}]}]}
{"op":"mcm","clk":"992394165","pt":1580521758524,"mc":[{"id":"1.168096552","rc":[{"batl":[[2,3.2,12.13]],"ltp":2.98,"tv":5994.59,"id":52106}]}]}
{"op":"mcm","clk":"992394330","pt":1580521765516,"mc":[{"id":"1.168096552","rc":[{"batb":[[0,3.05,5.88]],"ltp":3.05,"tv":2114.22,"id":18286408}]}]}
{"op":"mcm","clk":"992394706","pt":1580521782555,"mc":[{"id":"1.168096552","rc":[{"batb":[[0,3.05,107.88]],"ltp":3.05,"tv":2114.22,"id":18286408}]}]}
{"op":"mcm","clk":"992395275","pt":1580521807475,"mc":[{"id":"1.168096552","rc":[{"batb":[[0,3.05,5.88]],"ltp":3.05,"tv":2114.22,"id":18286408}]}]}
{"op":"mcm","clk":"992395680","pt":1580521823482,"mc":[{"id":"1.168096552","rc":[{"batb":[[0,3.05,107.88]],"ltp":3.05,"tv":2114.22,"id":18286408}]}]}
{"op":"mcm","clk":"992396134","pt":1580521841513,"mc":[{"id":"1.168096552","rc":[{"batb":[[0,3.05,5.88]],"ltp":3.05,"tv":2114.22,"id":18286408}]}]}
{"op":"mcm","clk":"992396495","pt":1580521858427,"mc":[{"id":"1.168096552","rc":[{"batb":[[0,3.05,107.88]],"ltp":3.05,"tv":2114.22,"id":18286408}]}]}
{"op":"mcm","clk":"992396804","pt":1580521876423,"mc":[{"id":"1.168096552","rc":[{"batb":[[0,3.05,5.88]],"ltp":3.05,"tv":2114.22,"id":18286408}]}]}
{"op":"mcm","clk":"992397214","pt":1580521893486,"mc":[{"id":"1.168096552","rc":[{"batb":[[0,3.05,107.88]],"ltp":3.05,"tv":2114.22,"id":18286408}]}]}
{"op":"mcm","clk":"992398109","pt":1580521924392,"mc":[{"id":"1.168096552","rc":[{"batb":[[0,3.05,5.88]],"ltp":3.05,"tv":2114.22,"id":18286408}]}]}
{"op":"mcm","clk":"992398464","pt":1580521936505,"mc":[{"id":"1.168096552","rc":[{"trd":[[2.98,412.07],[3,766.27]],"batl":[[0,3.05,25.41],[1,3.2,12.13],[2,3.25,12]],"ltp":3.0,"tv":6044.56,"id":52106}],"tv":10073.89}]}
{"op":"mcm","clk":"992398554","pt":1580521940625,"mc":[{"id":"1.168096552","rc":[{"trd":[[3,767.11],[3.05,415.38]],"batl":[[0,3.05,1.8]],"ltp":3.05,"tv":6091.78,"id":52106}],"tv":10121.1}]}
{"op":"mcm","clk":"992398662","pt":1580521944508,"mc":[{"id":"1.168096552","rc":[{"batl":[[0,3.2,12.13],[1,3.25,12],[2,3.5,1]],"ltp":3.05,"tv":6091.78,"id":52106}]}]}
{"op":"mcm","clk":"992398818","pt":1580521951498,"mc":[{"id":"1.168096552","rc":[{"batb":[[0,2.92,15.14],[1,2.9,4.11],[2,2.88,13.48]],"ltp":3.05,"tv":6091.78,"id":52106}]}]}
{"op":"mcm","clk":"992408683","pt":1580521952427,"mc":[{"id":"1.168096552","rc":[{"batb":[[0,2.94,7.05],[1,2.92,15.14]],"ltp":3.05,"tv":6091.78,"id":52106}]}]}
{"op":"mcm","clk":"992409480","pt":1580521981586,"mc":[{"id":"1.168096552","rc":[{"batl":[[0,3.15,2],[1,3.2,12.13],[2,3.25,12]],"ltp":3.05,"tv":6091.78,"id":52106}]}]}
{"op":"mcm","clk":"992410124","pt":1580522003005,"mc":[{"id":"1.168096552","rc":[{"batl":[[0,3.1,3.53],[1,3.15,2]],"ltp":3.05,"tv":6091.78,"id":52106}]}]}
{"op":"mcm","clk":"992411142","pt":1580522035032,"mc":[{"id":"1.168096552","rc":[{"batl":[[0,3.15,2],[1,3.2,1.68]],"ltp":3.05,"tv":6091.78,"id":52106}]}]}
{"op":"mcm","clk":"992412006","pt":1580522066479,"mc":[{"id":"1.168096552","rc":[{"batl":[[1,3.25,12],[2,3.5,1]],"ltp":3.05,"tv":6091.78,"id":52106}]}]}
{"op":"mcm","clk":"992412032","pt":1580522067461,"mc":[{"id":"1.168096552","rc":[{"batl":[[0,3.1,1.68],[1,3.15,2],[2,3.25,12]],"ltp":3.05,"tv":6091.78,"id":52106}]}]}
{"op":"mcm","clk":"992412557","pt":1580522089234,"mc":[{"id":"1.168096552","rc":[{"batb":[[0,2.96,5.28],[1,2.94,7.05],[2,2.92,15.14]],"batl":[[1,3.25,12],[2,3.5,1]],"ltp":3.05,"tv":6091.78,"id":52106}]}]}
{"op":"mcm","clk":"992412752","pt":1580522098407,"mc":[{"id":"1.168096552","rc":[{"batl":[[0,3.2,3.42]],"ltp":3.05,"tv":6091.78,"id":52106}]}]}
{"op":"mcm","clk":"992414408","pt":1580522164829,"mc":[{"id":"1.168096552","rc":[{"batl":[[0,3.15,10],[1,3.2,3.42],[2,3.25,12]],"ltp":3.05,"tv":6091.78,"id":52106}]}]}
{"op":"mcm","clk":"992414706","pt":1580522176224,"mc":[{"id":"1.168096552","rc":[{"batl":[[0,3.05,9.28],[1,3.15,10],[2,3.2,3.42]],"ltp":3.05,"tv":6091.78,"id":52106}]}]}
{"op":"mcm","clk":"992414736","pt":1580522177305,"mc":[{"id":"1.168096552","rc":[{"batl":[[0,3.15,10],[1,3.2,3.42],[2,3.25,12]],"ltp":3.05,"tv":6091.78,"id":52106}]}]}
{"op":"mcm","clk":"992414783","pt":1580522179424,"mc":[{"id":"1.168096552","rc":[{"batl":[[0,3,9.44],[1,3.15,10],[2,3.2,3.42]],"ltp":3.05,"tv":6091.78,"id":52106}]}]}
{"op":"mcm","clk":"992414804","pt":1580522180302,"mc":[{"id":"1.168096552","rc":[{"trd":[[3,785.99]],"batl":[[0,3.15,10],[1,3.2,3.42],[2,3.25,12]],"ltp":3.0,"tv":6110.65,"id":52106}],"tv":10139.98}]}
{"op":"mcm","clk":"992415084","pt":1580522193446,"mc":[{"id":"1.168096552","rc":[{"batl":[[1,3.25,12],[2,3.5,1]],"ltp":3.0,"tv":6110.65,"id":52106}]}]}
{"op":"mcm","clk":"992415086","pt":1580522193547,"mc":[{"id":"1.168096552","rc":[{"batl":[[0,3.1,3.35],[1,3.15,10],[2,3.25,12]],"ltp":3.0,"tv":6110.65,"id":52106}]}]}
{"op":"mcm","clk":"992415477","pt":1580522210448,"mc":[{"id":"1.168096552","rc":[{"batl":[[1,3.25,12],[2,3.5,1]],"ltp":3.0,"tv":6110.65,"id":52106}]}]}
{"op":"mcm","clk":"992415854","pt":1580522226081,"mc":[{"id":"1.168096552","rc":[{"batl":[[0,3.2,3.84]],"ltp":3.0,"tv":6110.65,"id":52106}]}]}
{"op":"mcm","clk":"992416352","pt":1580522244006,"mc":[{"id":"1.168096552","rc":[{"batl":[[0,3.15,10],[1,3.2,3.84],[2,3.25,12]],"ltp":3.0,"tv":6110.65,"id":52106}]}]}
{"op":"mcm","clk":"992416718","pt":1580522258041,"mc":[{"id":"1.168096552","rc":[{"batl":[[0,3.1,3.46],[1,3.15,10]],"ltp":3.0,"tv":6110.65,"id":52106}]}]}
{"op":"mcm","clk":"992417237","pt":1580522281057,"mc":[{"id":"1.168096552","rc":[{"batl":[[0,3.05,2],[1,3.1,3.46],[2,3.15,10]],"ltp":3.0,"tv":6110.65,"id":52106}]}]}
{"op":"mcm","clk":"992417394","pt":1580522287078,"mc":[{"id":"1.168096552","rc":[{"batl":[[0,3,15.14],[1,3.05,2],[2,3.1,3.46]],"ltp":3.0,"tv":6110.65,"id":52106}]}]}
{"op":"mcm","clk":"992417471","pt":1580522289545,"mc":[{"id":"1.168096552","rc":[{"batl":[[2,3.15,10]],"ltp":3.0,"tv":6110.65,"id":52106}]}]}
{"op":"mcm","clk":"992417594","pt":1580522294376,"mc":[{"id":"1.168096552","rc":[{"trd":[[3.05,369.71]],"batb":[[0,3.05,3.88]],"ltp":3.05,"tv":2118.22,"id":18286408},{"trd":[[12.5,4]],"batb":[[0,12,3.9],[1,11.5,10.42],[2,10.5,7.73]],"ltp":12.5,"tv":310.81,"id":26640937}],"tv":10147.98}]}
{"op":"mcm","clk":"992417620","pt":1580522295449,"mc":[{"id":"1.168096552","rc":[{"batb":[[0,3.05,105.88]],"ltp":3.05,"tv":2118.22,"id":18286408}]}]}
{"op":"mcm","clk":"992417713","pt":1580522298444,"mc":[{"id":"1.168096552","rc":[{"batb":[[0,2.94,7.05],[1,2.84,46.76],[2,2.82,7.61]],"batl":[[0,2.98,5.24],[1,3,15.14],[2,3.05,2]],"ltp":3.0,"tv":6110.65,"id":52106}]}]}
{"op":"mcm","clk":"992417726","pt":1580522298850,"mc":[{"id":"1.168096552","rc":[{"batb":[[1,2.88,15.14],[2,2.84,46.76]],"ltp":3.0,"tv":6110.65,"id":52106}]}]}
{"op":"mcm","clk":"992417844","pt":1580522303482,"mc":[{"id":"1.168096552","rc":[{"batb":[[0,2.94,3],[1,2.9,4.11],[2,2.88,15.14]],"ltp":3.0,"tv":6110.65,"id":52106}]}]}
{"op":"mcm","clk":"992417858","pt":1580522303895,"mc":[{"id":"1.168096552","rc":[{"batb":[[0,2.9,7.11],[1,2.88,15.14],[2,2.84,46.76]],"ltp":3.0,"tv":6110.65,"id":52106}]}]}
{"op":"mcm","clk":"992417918","pt":1580522306387,"mc":[{"id":"1.168096552","rc":[{"batl":[[0,2.98,14.33]],"ltp":3.0,"tv":6110.65,"id":52106}]}]}
{"op":"mcm","clk":"992418066","pt":1580522312406,"mc":[{"id":"1.168096552","rc":[{"batb":[[0,3.05,3.88]],"ltp":3.05,"tv":2118.22,"id":18286408}]}]}
{"op":"mcm","clk":"992418497","pt":1580522330416,"mc":[{"id":"1.168096552","rc":[{"batb":[[0,3.05,105.88]],"ltp":3.05,"tv":2118.22,"id":18286408}]}]}
{"op":"mcm","clk":"992418582","pt":1580522333514,"mc":[{"id":"1.168096552","rc":[{"batl":[[2,3.25,12]],"ltp":3.0,"tv":6110.65,"id":52106}]}]}
{"op":"mcm","clk":"992418876","pt":1580522346421,"mc":[{"id":"1.168096552","rc":[{"batb":[[2,10.5,4.14]],"ltp":12.5,"tv":310.81,"id":26640937}]}]}
{"op":"mcm","clk":"992418912","pt":1580522348018,"mc":[{"id":"1.168096552","rc":[{"batb":[[0,3.05,3.88]],"ltp":3.05,"tv":2118.22,"id":18286408}]}]}
{"op":"mcm","clk":"992419277","pt":1580522365482,"mc":[{"id":"1.168096552","rc":[{"batb":[[0,3.05,105.88]],"ltp":3.05,"tv":2118.22,"id":18286408}]}]}
{"op":"mcm","clk":"992419512","pt":1580522374056,"mc":[{"id":"1.168096552","rc":[{"batl":[[0,2.96,3.03],[1,2.98,14.33],[2,3,15.14]],"ltp":3.0,"tv":6110.65,"id":52106}]}]}
{"op":"mcm","clk":"992419536","pt":1580522375037,"mc":[{"id":"1.168096552","rc":[{"batl":[[0,2.98,14.33],[1,3,15.14],[2,3.25,12]],"ltp":3.0,"tv":6110.65,"id":52106}]}]}
{"op":"mcm","clk":"992419757","pt":1580522382368,"mc":[{"id":"1.168096552","rc":[{"batb":[[0,3.05,3.88]],"ltp":3.05,"tv":2118.22,"id":18286408}]}]}
{"op":"mcm","clk":"992420418","pt":1580522400468,"mc":[{"id":"1.168096552","rc":[{"batb":[[0,3.05,105.88]],"ltp":3.05,"tv":2118.22,"id":18286408}]}]}
{"op":"mcm","clk":"992421023","pt":1580522417414,"mc":[{"id":"1.168096552","rc":[{"batb":[[0,3.05,3.88]],"ltp":3.05,"tv":2118.22,"id":18286408}]}]}
{"op":"mcm","clk":"992421277","pt":1580522425518,"mc":[{"id":"1.168096552","rc":[{"batb":[[0,2.9,10.47]],"ltp":3.0,"tv":6110.65,"id":52106}]}]}
{"op":"mcm","clk":"992421586","pt":1580522435452,"mc":[{"id":"1.168096552","rc":[{"batb":[[0,3.05,105.88]],"ltp":3.05,"tv":2118.22,"id":18286408}]}]}
{"op":"mcm","clk":"992422223","pt":1580522452436,"mc":[{"id":"1.168096552","rc":[{"batb":[[0,3.05,3.88]],"ltp":3.05,"tv":2118.22,"id":18286408}]}]}
{"op":"mcm","clk":"992423079","pt":1580522470369,"mc":[{"id":"1.168096552","rc":[{"batb":[[0,3.05,105.88]],"ltp":3.05,"tv":2118.22,"id":18286408}]}]}
{"op":"mcm","clk":"992423717","pt":1580522487409,"mc":[{"id":"1.168096552","rc":[{"batb":[[0,3.05,3.88]],"ltp":3.05,"tv":2118.22,"id":18286408}]}]}
{"op":"mcm","clk":"992424120","pt":1580522505323,"mc":[{"id":"1.168096552","rc":[{"batb":[[0,3.05,105.88]],"ltp":3.05,"tv":2118.22,"id":18286408}]}]}
{"op":"mcm","clk":"992424676","pt":1580522522450,"mc":[{"id":"1.168096552","rc":[{"batb":[[0,3.05,3.88]],"ltp":3.05,"tv":2118.22,"id":18286408}]}]}
{"op":"mcm","clk":"992425248","pt":1580522540486,"mc":[{"id":"1.168096552","rc":[{"batb":[[0,3.05,105.88]],"ltp":3.05,"tv":2118.22,"id":18286408}]}]}
{"op":"mcm","clk":"992425713","pt":1580522557376,"mc":[{"id":"1.168096552","rc":[{"batb":[[0,3.05,3.88]],"ltp":3.05,"tv":2118.22,"id":18286408}]}]}
{"op":"mcm","clk":"992426142","pt":1580522575399,"mc":[{"id":"1.168096552","rc":[{"batb":[[0,3.05,105.88]],"ltp":3.05,"tv":2118.22,"id":18286408}]}]}
{"op":"mcm","clk":"992426660","pt":1580522592431,"mc":[{"id":"1.168096552","rc":[{"batb":[[0,3.05,3.88]],"ltp":3.05,"tv":2118.22,"id":18286408}]}]}
{"op":"mcm","clk":"992427251","pt":1580522610416,"mc":[{"id":"1.168096552","rc":[{"batb":[[0,3.05,105.88]],"ltp":3.05,"tv":2118.22,"id":18286408}]}]}
{"op":"mcm","clk":"992427684","pt":1580522627564,"mc":[{"id":"1.168096552","rc":[{"batb":[[0,3.05,3.88]],"ltp":3.05,"tv":2118.22,"id":18286408}]}]}
{"op":"mcm","clk":"992428255","pt":1580522645393,"mc":[{"id":"1.168096552","rc":[{"batb":[[0,3.05,105.88]],"ltp":3.05,"tv":2118.22,"id":18286408}]}]}
{"op":"mcm","clk":"992428755","pt":1580522662417,"mc":[{"id":"1.168096552","rc":[{"batb":[[0,3.05,3.88]],"ltp":3.05,"tv":2118.22,"id":18286408}]}]}
{"op":"mcm","clk":"992429125","pt":1580522680410,"mc":[{"id":"1.168096552","rc":[{"batb":[[0,3.05,105.88]],"ltp":3.05,"tv":2118.22,"id":18286408}]}]}
{"op":"mcm","clk":"992429573","pt":1580522697544,"mc":[{"id":"1.168096552","rc":[{"batb":[[0,3.05,3.88]],"ltp":3.05,"tv":2118.22,"id":18286408}]}]}
{"op":"mcm","clk":"992430082","pt":1580522715514,"mc":[{"id":"1.168096552","rc":[{"batb":[[0,3.05,105.88]],"ltp":3.05,"tv":2118.22,"id":18286408}]}]}
{"op":"mcm","clk":"992430560","pt":1580522732377,"mc":[{"id":"1.168096552","rc":[{"batb":[[0,3.05,3.88]],"ltp":3.05,"tv":2118.22,"id":18286408}]}]}
{"op":"mcm","clk":"992430987","pt":1580522750425,"mc":[{"id":"1.168096552","rc":[{"batb":[[0,3.05,105.88]],"ltp":3.05,"tv":2118.22,"id":18286408}]}]}
{"op":"mcm","clk":"992431546","pt":1580522767414,"mc":[{"id":"1.168096552","rc":[{"batb":[[0,3.05,3.88]],"ltp":3.05,"tv":2118.22,"id":18286408}]}]}
{"op":"mcm","clk":"992432190","pt":1580522785457,"mc":[{"id":"1.168096552","rc":[{"batb":[[0,3.05,105.88]],"ltp":3.05,"tv":2118.22,"id":18286408}]}]}
{"op":"mcm","clk":"992432348","pt":1580522790247,"mc":[{"id":"1.168096552","rc":[{"batl":[[1,3.25,12],[2,3.3,15.14]],"ltp":3.0,"tv":6110.65,"id":52106}]}]}
{"op":"mcm","clk":"992432456","pt":1580522793175,"mc":[{"id":"1.168096552","rc":[{"batl":[[1,3.15,13.63],[2,3.25,12]],"ltp":3.0,"tv":6110.65,"id":52106}]}]}
{"op":"mcm","clk":"992432682","pt":1580522802397,"mc":[{"id":"1.168096552","rc":[{"batb":[[0,3.05,3.88]],"ltp":3.05,"tv":2118.22,"id":18286408}]}]}
{"op":"mcm","clk":"992433154","pt":1580522823376,"mc":[{"id":"1.168096552","rc":[{"batb":[[0,3.05,105.88]],"ltp":3.05,"tv":2118.22,"id":18286408}]}]}
{"op":"mcm","clk":"992433577","pt":1580522841433,"mc":[{"id":"1.168096552","rc":[{"batb":[[0,3.05,3.88]],"ltp":3.05,"tv":2118.22,"id":18286408}]}]}
{"op":"mcm","clk":"992443717","pt":1580522858368,"mc":[{"id":"1.168096552","rc":[{"batb":[[0,3.05,105.88]],"ltp":3.05,"tv":2118.22,"id":18286408}]}]}
{"op":"mcm","clk":"992444119","pt":1580522876341,"mc":[{"id":"1.168096552","rc":[{"batb":[[0,3.05,3.88]],"ltp":3.05,"tv":2118.22,"id":18286408}]}]}
{"op":"mcm","clk":"992444522","pt":1580522893468,"mc":[{"id":"1.168096552","rc":[{"batb":[[0,3.05,105.88]],"ltp":3.05,"tv":2118.22,"id":18286408}]}]}
{"op":"mcm","clk":"992444783","pt":1580522901501,"mc":[{"id":"1.168096552","rc":[{"trd":[[2.98,440.73]],"batb":[[0,2.92,10.66],[1,2.9,10.47],[2,2.88,15.14]],"batl":[[0,3.15,13.63],[1,3.25,12],[2,3.3,15.14]],"ltp":2.98,"tv":6139.31,"id":52106}],"tv":10176.64}]}
{"op":"mcm","clk":"992445023","pt":1580522911415,"mc":[{"id":"1.168096552","rc":[{"batb":[[0,3.05,3.88]],"ltp":3.05,"tv":2118.22,"id":18286408}]}]}
{"op":"mcm","clk":"992445156","pt":1580522917432,"mc":[{"id":"1.168096552","rc":[{"batb":[[0,2.94,4.05],[1,2.92,10.66],[2,2.9,6.36]],"ltp":2.98,"tv":6139.31,"id":52106}]}]}
{"op":"mcm","clk":"992445160","pt":1580522917536,"mc":[{"id":"1.168096552","rc":[{"batb":[[2,2.9,3.36]],"ltp":2.98,"tv":6139.31,"id":52106}]}]}
{"op":"mcm","clk":"992447819","pt":1580523047994,"mc":[{"id":"1.168096552","rc":[{"batl":[[0,3.15,25.63],[1,3.3,15.14],[2,3.5,16.14]],"ltp":2.98,"tv":6139.31,"id":52106}]}]}
{"op":"mcm","clk":"992449680","pt":1580523123457,"mc":[{"id":"1.168096552","rc":[{"batb":[[1,2.9,3.36],[2,2.88,15.14]],"batl":[[0,3.05,9.09],[1,3.15,25.63],[2,3.3,15.14]],"ltp":2.98,"tv":6139.31,"id":52106}]}]}
{"op":"mcm","clk":"992449910","pt":1580523134493,"mc":[{"id":"1.168096552","rc":[{"batb":[[0,2.9,7.47],[1,2.88,15.14],[2,2.84,46.76]],"ltp":2.98,"tv":6139.31,"id":52106}]}]}
{"op":"mcm","clk":"992454858","pt":1580523322327,"mc":[{"id":"1.168096552","rc":[{"batl":[[0,3,4.54],[1,3.05,9.09],[2,3.15,25.63]],"ltp":2.98,"tv":6139.31,"id":52106}]}]}
{"op":"mcm","clk":"992454870","pt":1580523322640,"mc":[{"id":"1.168096552","rc":[{"batl":[[0,3,9.09]],"ltp":2.98,"tv":6139.31,"id":52106}]}]}
{"op":"mcm","clk":"992454920","pt":1580523324030,"mc":[{"id":"1.168096552","rc":[{"batb":[[0,2.92,10.66],[1,2.9,7.47],[2,2.88,15.14]],"batl":[[0,3,13.63],[1,3.15,25.63],[2,3.3,15.14]],"ltp":2.98,"tv":6139.31,"id":52106}]}]}
{"op":"mcm","clk":"992454967","pt":1580523325522,"mc":[{"id":"1.168096552","rc":[{"batl":[[0,3,18.17]],"ltp":2.98,"tv":6139.31,"id":52106}]}]}
{"op":"mcm","clk":"992455116","pt":1580523331444,"mc":[{"id":"1.168096552","rc":[{"batb":[[0,3.05,105.88]],"ltp":3.05,"tv":2118.22,"id":18286408}]}]}
{"op":"mcm","clk":"992455205","pt":1580523334473,"mc":[{"id":"1.168096552","rc":[{"batb":[[0,2.94,4.05],[1,2.92,10.66],[2,2.9,3.36]],"ltp":2.98,"tv":6139.31,"id":52106}]}]}
{"op":"mcm","clk":"992455692","pt":1580523349475,"mc":[{"id":"1.168096552","rc":[{"batb":[[0,3.05,3.88]],"ltp":3.05,"tv":2118.22,"id":18286408}]}]}
{"op":"mcm","clk":"992456220","pt":1580523366485,"mc":[{"id":"1.168096552","rc":[{"batb":[[0,3.05,105.88]],"ltp":3.05,"tv":2118.22,"id":18286408}]}]}
{"op":"mcm","clk":"992456747","pt":1580523384434,"mc":[{"id":"1.168096552","rc":[{"batb":[[0,3.05,3.88]],"ltp":3.05,"tv":2118.22,"id":18286408}]}]}
{"op":"mcm","clk":"992457250","pt":1580523401441,"mc":[{"id":"1.168096552","rc":[{"batb":[[0,3.05,105.88]],"ltp":3.05,"tv":2118.22,"id":18286408}]}]}
{"op":"mcm","clk":"992457769","pt":1580523419442,"mc":[{"id":"1.168096552","rc":[{"batb":[[0,3.05,3.88]],"ltp":3.05,"tv":2118.22,"id":18286408}]}]}
{"op":"mcm","clk":"992458285","pt":1580523436492,"mc":[{"id":"1.168096552","rc":[{"batb":[[0,3.05,105.88]],"ltp":3.05,"tv":2118.22,"id":18286408}]}]}
{"op":"mcm","clk":"992458769","pt":1580523454614,"mc":[{"id":"1.168096552","rc":[{"batb":[[0,3.05,3.88]],"ltp":3.05,"tv":2118.22,"id":18286408}]}]}
{"op":"mcm","clk":"992459255","pt":1580523471415,"mc":[{"id":"1.168096552","rc":[{"batb":[[0,3.05,105.88]],"ltp":3.05,"tv":2118.22,"id":18286408}]}]}
{"op":"mcm","clk":"992459889","pt":1580523489501,"mc":[{"id":"1.168096552","rc":[{"batb":[[0,3.05,3.88]],"ltp":3.05,"tv":2118.22,"id":18286408}]}]}
{"op":"mcm","clk":"992460535","pt":1580523506543,"mc":[{"id":"1.168096552","rc":[{"batb":[[0,3.05,105.88]],"ltp":3.05,"tv":2118.22,"id":18286408}]}]}
{"op":"mcm","clk":"992461165","pt":1580523524575,"mc":[{"id":"1.168096552","rc":[{"batb":[[0,3.05,3.88]],"ltp":3.05,"tv":2118.22,"id":18286408}]}]}
{"op":"mcm","clk":"992461672","pt":1580523541597,"mc":[{"id":"1.168096552","rc":[{"batb":[[0,3.05,105.88]],"ltp":3.05,"tv":2118.22,"id":18286408}]}]}
{"op":"mcm","clk":"992462230","pt":1580523559476,"mc":[{"id":"1.168096552","rc":[{"batb":[[0,3.05,3.88]],"ltp":3.05,"tv":2118.22,"id":18286408}]}]}
{"op":"mcm","clk":"992462667","pt":1580523576498,"mc":[{"id":"1.168096552","rc":[{"batb":[[0,3.05,105.88]],"ltp":3.05,"tv":2118.22,"id":18286408}]}]}
{"op":"mcm","clk":"992463297","pt":1580523597415,"mc":[{"id":"1.168096552","rc":[{"batb":[[0,3.05,3.88]],"ltp":3.05,"tv":2118.22,"id":18286408}]}]}
{"op":"mcm","clk":"992463876","pt":1580523618535,"mc":[{"id":"1.168096552","rc":[{"batb":[[0,3.05,105.88]],"ltp":3.05,"tv":2118.22,"id":18286408}]}]}
{"op":"mcm","clk":"992464402","pt":1580523635567,"mc":[{"id":"1.168096552","rc":[{"batb":[[0,3.05,3.88]],"ltp":3.05,"tv":2118.22,"id":18286408}]}]}
{"op":"mcm","clk":"992465033","pt":1580523653572,"mc":[{"id":"1.168096552","rc":[{"batb":[[0,3.05,105.88]],"ltp":3.05,"tv":2118.22,"id":18286408}]}]}
{"op":"mcm","clk":"992465587","pt":1580523670404,"mc":[{"id":"1.168096552","rc":[{"batb":[[0,3.05,3.88]],"ltp":3.05,"tv":2118.22,"id":18286408}]}]}
{"op":"mcm","clk":"992466237","pt":1580523688511,"mc":[{"id":"1.168096552","rc":[{"batb":[[0,3.05,105.88]],"ltp":3.05,"tv":2118.22,"id":18286408}]}]}
{"op":"mcm","clk":"992466733","pt":1580523705333,"mc":[{"id":"1.168096552","rc":[{"batb":[[0,3.05,3.88]],"ltp":3.05,"tv":2118.22,"id":18286408},{"trd":[[2.94,329.41]],"batb":[[0,2.92,11.16],[1,2.9,3.36],[2,2.88,15.14]],"ltp":2.94,"tv":6146.41,"id":52106}],"tv":10183.74}]}
{"op":"mcm","clk":"992467159","pt":1580523717080,"mc":[{"id":"1.168096552","rc":[{"trd":[[2.92,893.86],[2.94,330.41]],"batb":[[0,2.9,3.36],[1,2.88,15.14],[2,2.84,46.76]],"batl":[[0,2.92,5.57],[1,3,18.17],[2,3.15,25.63]],"ltp":2.92,"tv":6168.72,"id":52106}],"tv":10206.05}]}
{"op":"mcm","clk":"992467327","pt":1580523722447,"mc":[{"id":"1.168096552","rc":[{"trd":[[3.05,376.8]],"batb":[[0,3,100.56],[1,2.98,4],[2,2.96,2]],"ltp":3.05,"tv":2125.31,"id":18286408}],"tv":10213.14}]}
{"op":"mcm","clk":"992467334","pt":1580523722652,"mc":[{"id":"1.168096552","rc":[{"trd":[[3.05,377.48]],"batb":[[0,3,100.22]],"ltp":3.05,"tv":2125.99,"id":18286408}],"tv":10213.81}]}
{"op":"mcm","clk":"992467452","pt":1580523727449,"mc":[{"id":"1.168096552","rc":[{"trd":[[3,297.99]],"batb":[[0,3,83.51]],"ltp":3.0,"tv":2159.42,"id":18286408}],"tv":10247.24}]}
{"op":"mcm","clk":"992467476","pt":1580523728481,"mc":[{"id":"1.168096552","rc":[{"batb":[[0,2.9,6.36]],"ltp":2.92,"tv":6168.72,"id":52106}]}]}
{"op":"mcm","clk":"992480192","pt":1580523821336,"mc":[{"id":"1.168096552","rc":[{"batl":[[0,5,10],[1,5.1,20],[2,5.2,43]],"ltp":4.8,"tv":1511.72,"id":21580749}]}]}
{"op":"mcm","clk":"992480522","pt":1580523836876,"mc":[{"id":"1.168096552","rc":[{"trd":[[3.1,337.7]],"batl":[[0,3.1,26.22]],"ltp":3.1,"tv":2169.92,"id":18286408},{"batb":[[0,13,1.25],[1,12,3.9],[2,11.5,10.42]],"ltp":12.5,"tv":310.81,"id":26640937},{"trd":[[5,116.51]],"batl":[[0,5,6.75]],"ltp":5.0,"tv":1518.22,"id":21580749},{"batb":[[0,36,2.41]],"ltp":40.0,"tv":38.51,"id":27706761},{"trd":[[2.92,905]],"batb":[[0,2.9,6.37]],"batl":[[0,3,18.17],[1,3.15,25.63],[2,3.3,15.14]],"ltp":2.92,"tv":6179.85,"id":52106},{"trd":[[21,20.32]],"batl":[[0,21,18.56]],"ltp":21.0,"tv":59.58,"id":24608298}],"tv":10276.92}]}
{"op":"mcm","clk":"992480720","pt":1580523844761,"mc":[{"id":"1.168096552","rc":[{"batb":[[0,3.05,5.65],[1,3,83.51],[2,2.98,4]],"ltp":3.1,"tv":2169.92,"id":18286408}]}]}
{"op":"mcm","clk":"992481039","pt":1580523858965,"mc":[{"id":"1.168096552","rc":[{"batb":[[0,3.05,107.65]],"ltp":3.1,"tv":2169.92,"id":18286408}]}]}
{"op":"mcm","clk":"992481105","pt":1580523861705,"mc":[{"id":"1.168096552","rc":[{"trd":[[3,792.79]],"batl":[[0,3,14.77]],"ltp":3.0,"tv":6186.66,"id":52106}],"tv":10283.72}]}
{"op":"mcm","clk":"992481407","pt":1580523875494,"mc":[{"id":"1.168096552","rc":[{"batb":[[0,3.05,5.65]],"ltp":3.1,"tv":2169.92,"id":18286408}]}]}
{"op":"mcm","clk":"992481833","pt":1580523893410,"mc":[{"id":"1.168096552","rc":[{"batb":[[0,3.05,107.65]],"ltp":3.1,"tv":2169.92,"id":18286408}]}]}
{"op":"mcm","clk":"992482227","pt":1580523910404,"mc":[{"id":"1.168096552","rc":[{"batb":[[0,3.05,5.65]],"ltp":3.1,"tv":2169.92,"id":18286408}]}]}
{"op":"mcm","clk":"992482662","pt":1580523928553,"mc":[{"id":"1.168096552","rc":[{"batb":[[0,3.05,107.65]],"ltp":3.1,"tv":2169.92,"id":18286408}]}]}
{"op":"mcm","clk":"992483286","pt":1580523946484,"mc":[{"id":"1.168096552","rc":[{"batb":[[0,3.05,5.65]],"ltp":3.1,"tv":2169.92,"id":18286408}]}]}
{"op":"mcm","clk":"992483835","pt":1580523963478,"mc":[{"id":"1.168096552","rc":[{"batb":[[0,3.05,107.65]],"ltp":3.1,"tv":2169.92,"id":18286408}]}]}
{"op":"mcm","clk":"992484386","pt":1580523982481,"mc":[{"id":"1.168096552","rc":[{"batb":[[0,3.05,5.65]],"ltp":3.1,"tv":2169.92,"id":18286408}]}]}
{"op":"mcm","clk":"992484940","pt":1580524000516,"mc":[{"id":"1.168096552","rc":[{"batb":[[0,3.05,107.65]],"ltp":3.1,"tv":2169.92,"id":18286408}]}]}
{"op":"mcm","clk":"992485307","pt":1580524012393,"mc":[{"id":"1.168096552","rc":[{"batb":[[0,3.05,5.65]],"ltp":3.1,"tv":2169.92,"id":18286408}]}]}
{"op":"mcm","clk":"992485806","pt":1580524027228,"mc":[{"id":"1.168096552","rc":[{"batb":[[0,3.05,9.01]],"ltp":3.1,"tv":2169.92,"id":18286408}]}]}
{"op":"mcm","clk":"992485926","pt":1580524031506,"mc":[{"id":"1.168096552","rc":[{"trd":[[3.1,410.74]],"batb":[[0,3.1,63.86],[1,3.05,9.01],[2,3,83.51]],"batl":[[0,3.15,100],[1,3.2,22],[2,3.25,380]],"ltp":3.1,"tv":2242.96,"id":18286408}],"tv":10356.76}]}
{"op":"mcm","clk":"992485929","pt":1580524031606,"mc":[{"id":"1.168096552","rc":[{"batl":[[1,3.2,26.7]],"ltp":3.1,"tv":2242.96,"id":18286408}]}]}
{"op":"mcm","clk":"992486494","pt":1580524049479,"mc":[{"id":"1.168096552","rc":[{"batb":[[0,3.05,9.01],[1,3,83.51],[2,2.98,4]],"ltp":3.1,"tv":2242.96,"id":18286408}]}]}
{"op":"mcm","clk":"992486499","pt":1580524049657,"mc":[{"id":"1.168096552","rc":[{"batl":[[1,3.2,22]],"ltp":3.1,"tv":2242.96,"id":18286408}]}]}
{"op":"mcm","clk":"992490589","pt":1580524162757,"mc":[{"id":"1.168096552","rc":[{"batl":[[2,900,2.33]],"ltp":40.0,"tv":38.51,"id":27706761}]}]}
{"op":"mcm","clk":"992490835","pt":1580524170476,"mc":[{"id":"1.168096552","rc":[{"batl":[[2,900,2.83]],"ltp":40.0,"tv":38.51,"id":27706761}]}]}
{"op":"mcm","clk":"992490997","pt":1580524175465,"mc":[{"id":"1.168096552","rc":[{"batl":[[2,900,0.83]],"ltp":40.0,"tv":38.51,"id":27706761}]}]}
{"op":"mcm","clk":"992491216","pt":1580524182263,"mc":[{"id":"1.168096552","rc":[{"batl":[[2,900,1.33]],"ltp":40.0,"tv":38.51,"id":27706761}]}]}
{"op":"mcm","clk":"992491710","pt":1580524198305,"mc":[{"id":"1.168096552","rc":[{"batl":[[1,85,1],[2,240,9]],"ltp":40.0,"tv":38.51,"id":27706761},{"batl":[[1,48,1.08],[2,55,3.1]],"ltp":21.0,"tv":59.58,"id":24608298}]}]}
{"op":"mcm","clk":"992503547","pt":1580524513420,"mc":[{"id":"1.168096552","rc":[{"batl":[[0,5,16.75],[2,5.2,33]],"ltp":5.0,"tv":1518.22,"id":21580749}]}]}
{"op":"mcm","clk":"992505721","pt":1580524572371,"mc":[{"id":"1.168096552","rc":[{"batl":[[0,2.98,2],[1,3,14.77],[2,3.15,25.63]],"ltp":3.0,"tv":6186.66,"id":52106}]}]}
{"op":"mcm","clk":"992506830","pt":1580524602284,"mc":[{"id":"1.168096552","rc":[{"batl":[[0,2.96,2],[1,2.98,2],[2,3,14.77]],"ltp":3.0,"tv":6186.66,"id":52106}]}]}
{"op":"mcm","clk":"992524103","pt":1580524822197,"mc":[{"id":"1.168096552","rc":[{"trd":[[2.96,434.51]],"batl":[[0,2.96,9.98]],"ltp":2.96,"tv":6191.7,"id":52106}],"tv":10361.8}]}
{"op":"mcm","clk":"992524272","pt":1580524827876,"mc":[{"id":"1.168096552","rc":[{"batb":[[0,2.9,3.37]],"ltp":2.96,"tv":6191.7,"id":52106}]}]}
{"op":"mcm","clk":"992527054","pt":1580524901226,"mc":[{"id":"1.168096552","rc":[{"batb":[[0,2.92,10.01],[1,2.9,3.36],[2,2.88,15.14]],"ltp":2.96,"tv":6191.7,"id":52106}]}]}
{"op":"mcm","clk":"992528094","pt":1580524928381,"mc":[{"id":"1.168096552","rc":[{"batb":[[0,2.9,3.37],[1,2.88,15.14],[2,2.84,46.76]],"ltp":2.96,"tv":6191.7,"id":52106}]}]}
{"op":"mcm","clk":"992529010","pt":1580524950779,"mc":[{"id":"1.168096552","rc":[{"batb":[[0,2.94,10],[1,2.9,3.37],[2,2.88,15.14]],"ltp":2.96,"tv":6191.7,"id":52106}]}]}
{"op":"mcm","clk":"992529636","pt":1580524966400,"mc":[{"id":"1.168096552","rc":[{"batb":[[0,2.9,3.37],[1,2.88,15.14],[2,2.84,46.76]],"ltp":2.96,"tv":6191.7,"id":52106}]}]}
{"op":"mcm","clk":"992529947","pt":1580524973868,"mc":[{"id":"1.168096552","rc":[{"trd":[[2.96,454.47]],"batb":[[0,2.9,3.39]],"batl":[[0,2.98,2],[1,3,14.77],[2,3.15,25.63]],"ltp":2.96,"tv":6211.66,"id":52106}],"tv":10381.76}]}
{"op":"mcm","clk":"992530022","pt":1580524975776,"mc":[{"id":"1.168096552","rc":[{"batl":[[0,2.98,12]],"ltp":2.96,"tv":6211.66,"id":52106}]}]}
{"op":"mcm","clk":"992530179","pt":1580524979600,"mc":[{"id":"1.168096552","rc":[{"batl":[[0,3,14.77],[1,3.15,25.63],[2,3.3,15.14]],"ltp":2.96,"tv":6211.66,"id":52106}]}]}
{"op":"mcm","clk":"992530826","pt":1580524994115,"mc":[{"id":"1.168096552","rc":[{"batb":[[0,2.9,6.39]],"ltp":2.96,"tv":6211.66,"id":52106}]}]}
{"op":"mcm","clk":"992531153","pt":1580525002904,"mc":[{"id":"1.168096552","rc":[{"trd":[[3,792.83]],"batb":[[0,2.92,10.66],[1,2.9,6.36],[2,2.88,15.14]],"batl":[[0,3,14.75]],"ltp":3.0,"tv":6211.7,"id":52106}],"tv":10381.81}]}
{"op":"mcm","clk":"992531628","pt":1580525015234,"mc":[{"id":"1.168096552","rc":[{"batb":[[0,2.94,3.36],[1,2.92,10.66],[2,2.9,3]],"ltp":3.0,"tv":6211.7,"id":52106}]}]}
{"op":"mcm","clk":"992531710","pt":1580525017342,"mc":[{"id":"1.168096552","rc":[{"trd":[[3,796.83]],"batl":[[0,3,12.75]],"ltp":3.0,"tv":6215.7,"id":52106}],"tv":10385.81}]}
{"op":"mcm","clk":"992531896","pt":1580525022947,"mc":[{"id":"1.168096552","rc":[{"batb":[[2,2.88,15.14]],"ltp":3.0,"tv":6215.7,"id":52106}]}]}
{"op":"mcm","clk":"992545592","pt":1580525417578,"mc":[{"id":"1.168096552","rc":[{"batb":[[1,3,88.51]],"ltp":3.1,"tv":2242.96,"id":18286408}]}]}
{"op":"mcm","clk":"992560023","pt":1580525563698,"mc":[{"id":"1.168096552","rc":[{"trd":[[5,122.51]],"batl":[[0,5,13.75]],"ltp":5.0,"tv":1524.22,"id":21580749}],"tv":10391.81}]}
{"op":"mcm","clk":"992569422","pt":1580525884732,"mc":[{"id":"1.168096552","rc":[{"batb":[[0,3.05,5.65]],"ltp":3.1,"tv":2242.96,"id":18286408},{"batb":[[2,11.5,7.06]],"ltp":12.5,"tv":310.81,"id":26640937},{"batb":[[0,4.8,6.58]],"ltp":5.0,"tv":1524.22,"id":21580749},{"batb":[[0,2.92,10.66],[1,2.88,15.14],[2,2.84,46.76]],"ltp":3.0,"tv":6215.7,"id":52106}]}]}
{"op":"mcm","clk":"992570156","pt":1580525917417,"mc":[{"id":"1.168096552","rc":[{"trd":[[5,143.55]],"batb":[[1,4.7,21.12]],"batl":[[0,5,3.23]],"ltp":5.0,"tv":1545.26,"id":21580749}],"tv":10412.85}]}
{"op":"mcm","clk":"992649515","pt":1580527694289,"mc":[{"id":"1.168096552","rc":[{"batl":[[0,2.98,3.03],[1,3,12.75],[2,3.15,25.63]],"ltp":3.0,"tv":6215.7,"id":52106}]}]}
{"op":"mcm","clk":"992649523","pt":1580527695004,"mc":[{"id":"1.168096552","rc":[{"batl":[[0,3,12.75],[1,3.15,25.63],[2,3.3,15.14]],"ltp":3.0,"tv":6215.7,"id":52106}]}]}
{"op":"mcm","clk":"992691410","pt":1580528749499,"mc":[{"id":"1.168096552","rc":[{"trd":[[5,150]],"batb":[[0,5,1.81],[1,4.8,6.58],[2,4.7,21.12]],"batl":[[0,5.1,20],[1,5.2,33],[2,5.3,9]],"ltp":5.0,"tv":1551.72,"id":21580749}],"tv":10419.3}]}
{"op":"mcm","clk":"992691465","pt":1580528751421,"mc":[{"id":"1.168096552","rc":[{"trd":[[5,153.63]],"batb":[[0,4.8,2.2],[1,4.7,21.12],[2,4.6,39.3]],"batl":[[0,5,2.3],[1,5.1,20],[2,5.2,33]],"ltp":5.0,"tv":1555.35,"id":21580749}],"tv":10422.93}]}
{"op":"mcm","clk":"992691954","pt":1580528764327,"mc":[{"id":"1.168096552","rc":[{"trd":[[12.5,5.99],[13,57.17]],"batb":[[0,12,2.91],[1,11.5,7.06],[2,10.5,4.14]],"batl":[[0,12.5,5.32],[1,14.5,3],[2,15,1]],"ltp":12.5,"tv":315.29,"id":26640937}],"tv":10427.41}]}
{"op":"mcm","clk":"992692133","pt":1580528769420,"mc":[{"id":"1.168096552","rc":[{"trd":[[11.5,7.99],[12,9.81]],"batb":[[0,11.5,4.65],[1,10.5,4.14],[2,10,20.61]],"batl":[[0,14.5,3],[1,15,1],[2,21,1.5]],"ltp":11.5,"tv":325.93,"id":26640937}],"tv":10438.05}]}
{"op":"mcm","clk":"992692167","pt":1580528770504,"mc":[{"id":"1.168096552","rc":[{"batb":[[0,3.05,6.2]],"ltp":3.1,"tv":2242.96,"id":18286408},{"batb":[[0,11.5,4.79]],"ltp":11.5,"tv":325.93,"id":26640937},{"batb":[[0,4.8,2.55]],"ltp":5.0,"tv":1555.35,"id":21580749},{"batb":[[0,2.92,11.23]],"ltp":3.0,"tv":6215.7,"id":52106},{"batb":[[0,18,1.05],[1,17.5,4.64],[2,13.5,2.39]],"ltp":21.0,"tv":59.58,"id":24608298}]}]}
{"op":"mcm","clk":"992692444","pt":1580528775821,"mc":[{"id":"1.168096552","rc":[{"batb":[[1,11,2.23],[2,10.5,4.14]],"batl":[[0,14,1.76],[1,14.5,3],[2,15,1]],"ltp":11.5,"tv":325.93,"id":26640937}]}]}
{"op":"mcm","clk":"992693999","pt":1580528808180,"mc":[{"id":"1.168096552","rc":[{"batl":[[0,14.5,3],[1,15,1],[2,20,1.68]],"ltp":11.5,"tv":325.93,"id":26640937},{"batb":[[0,2.94,8.13],[1,2.92,10.66],[2,2.88,15.14]],"ltp":3.0,"tv":6215.7,"id":52106}]}]}
{"op":"mcm","clk":"992695795","pt":1580528839480,"mc":[{"id":"1.168096552","rc":[{"batl":[[0,14,1.68],[1,14.5,3],[2,15,1]],"ltp":11.5,"tv":325.93,"id":26640937}]}]}
{"op":"mcm","clk":"992696991","pt":1580528872129,"mc":[{"id":"1.168096552","rc":[{"batl":[[0,14.5,3],[1,15,1],[2,20,1.68]],"ltp":11.5,"tv":325.93,"id":26640937}]}]}
{"op":"mcm","clk":"992698135","pt":1580528904312,"mc":[{"id":"1.168096552","rc":[{"batl":[[0,14,1.68],[1,14.5,3],[2,15,1]],"ltp":11.5,"tv":325.93,"id":26640937}]}]}
{"op":"mcm","clk":"992699233","pt":1580528934209,"mc":[{"id":"1.168096552","rc":[{"trd":[[3,836.83]],"batl":[[0,3,7.25]],"ltp":3.0,"tv":6255.7,"id":52106}],"tv":10478.05}]}
{"op":"mcm","clk":"992699244","pt":1580528934623,"mc":[{"id":"1.168096552","rc":[{"batl":[[0,3,14.49]],"ltp":3.0,"tv":6255.7,"id":52106}]}]}
{"op":"mcm","clk":"992699306","pt":1580528936317,"mc":[{"id":"1.168096552","rc":[{"batl":[[0,14.5,3],[1,15,1],[2,20,1.68]],"ltp":11.5,"tv":325.93,"id":26640937}]}]}
{"op":"mcm","clk":"992700333","pt":1580528961176,"mc":[{"id":"1.168096552","rc":[{"trd":[[4.8,95.65]],"batb":[[0,4.7,21.46],[1,4.6,39.3],[2,4.5,27.25]],"batl":[[0,5.1,20],[1,5.2,33],[2,5.3,9]],"ltp":4.8,"tv":1576.29,"id":21580749}],"tv":10498.99}]}
{"op":"mcm","clk":"992700635","pt":1580528967986,"mc":[{"id":"1.168096552","rc":[{"batl":[[0,14,1.68],[1,14.5,3],[2,15,1]],"ltp":11.5,"tv":325.93,"id":26640937}]}]}
{"op":"mcm","clk":"992702213","pt":1580528999683,"mc":[{"id":"1.168096552","rc":[{"batl":[[0,14.5,3],[1,15,1],[2,20,1.68]],"ltp":11.5,"tv":325.93,"id":26640937}]}]}
{"op":"mcm","clk":"992703741","pt":1580529031323,"mc":[{"id":"1.168096552","rc":[{"batl":[[0,14,1.68],[1,14.5,3],[2,15,1]],"ltp":11.5,"tv":325.93,"id":26640937}]}]}
{"op":"mcm","clk":"992705237","pt":1580529063511,"mc":[{"id":"1.168096552","rc":[{"batl":[[0,14.5,3],[1,15,1],[2,20,1.68]],"ltp":11.5,"tv":325.93,"id":26640937}]}]}
{"op":"mcm","clk":"992706448","pt":1580529096666,"mc":[{"id":"1.168096552","rc":[{"batl":[[0,14,1.68],[1,14.5,3],[2,15,1]],"ltp":11.5,"tv":325.93,"id":26640937}]}]}
{"op":"mcm","clk":"992706623","pt":1580529100431,"mc":[{"id":"1.168096552","rc":[{"batb":[[0,4.8,60.73],[1,4.7,21.12],[2,4.6,39.3]],"ltp":4.8,"tv":1576.29,"id":21580749}]}]}
{"op":"mcm","clk":"992707696","pt":1580529129711,"mc":[{"id":"1.168096552","rc":[{"batl":[[0,14.5,3],[1,15,1],[2,20,1.68]],"ltp":11.5,"tv":325.93,"id":26640937}]}]}
{"op":"mcm","clk":"992708046","pt":1580529141582,"mc":[{"id":"1.168096552","rc":[{"trd":[[46,0.22],[48,4.04]],"batl":[[0,48,3]],"ltp":48.0,"tv":42.77,"id":27706761}],"tv":10503.25}]}
{"op":"mcm","clk":"992718607","pt":1580529162828,"mc":[{"id":"1.168096552","rc":[{"batl":[[0,14,1.68],[1,14.5,3],[2,15,1]],"ltp":11.5,"tv":325.93,"id":26640937}]}]}
{"op":"mcm","clk":"992719617","pt":1580529195471,"mc":[{"id":"1.168096552","rc":[{"batl":[[0,14.5,3],[1,15,1],[2,21,1.5]],"ltp":11.5,"tv":325.93,"id":26640937}]}]}
{"op":"mcm","clk":"992719638","pt":1580529196135,"mc":[{"id":"1.168096552","rc":[{"batl":[[2,20,1.68]],"ltp":11.5,"tv":325.93,"id":26640937}]}]}
{"op":"mcm","clk":"992720574","pt":1580529228517,"mc":[{"id":"1.168096552","rc":[{"batl":[[2,21,1.5]],"ltp":11.5,"tv":325.93,"id":26640937},{"trd":[[48,4.88]],"batl":[[0,48,2.58],[1,85,1.35]],"ltp":48.0,"tv":43.61,"id":27706761}],"tv":10504.09}]}
{"op":"mcm","clk":"992720582","pt":1580529228722,"mc":[{"id":"1.168096552","rc":[{"batl":[[0,14,1.68],[1,14.5,3],[2,15,1]],"ltp":11.5,"tv":325.93,"id":26640937}]}]}
{"op":"mcm","clk":"992721713","pt":1580529261798,"mc":[{"id":"1.168096552","rc":[{"batl":[[0,14.5,3],[1,15,1],[2,20,1.68]],"ltp":11.5,"tv":325.93,"id":26640937}]}]}
{"op":"mcm","clk":"992722767","pt":1580529294240,"mc":[{"id":"1.168096552","rc":[{"batl":[[0,14,1.68],[1,14.5,3],[2,15,1]],"ltp":11.5,"tv":325.93,"id":26640937}]}]}
{"op":"mcm","clk":"992723661","pt":1580529326484,"mc":[{"id":"1.168096552","rc":[{"batl":[[0,14.5,3],[1,15,1],[2,21,1.5]],"ltp":11.5,"tv":325.93,"id":26640937}]}]}
{"op":"mcm","clk":"992723666","pt":1580529326589,"mc":[{"id":"1.168096552","rc":[{"batl":[[2,20,1.68]],"ltp":11.5,"tv":325.93,"id":26640937}]}]}
{"op":"mcm","clk":"992724871","pt":1580529359022,"mc":[{"id":"1.168096552","rc":[{"batl":[[0,14,1.68],[1,14.5,3],[2,15,1]],"ltp":11.5,"tv":325.93,"id":26640937}]}]}
{"op":"mcm","clk":"992725978","pt":1580529391274,"mc":[{"id":"1.168096552","rc":[{"batl":[[0,14.5,3],[1,15,1],[2,20,1.68]],"ltp":11.5,"tv":325.93,"id":26640937}]}]}
{"op":"mcm","clk":"992726911","pt":1580529423507,"mc":[{"id":"1.168096552","rc":[{"batl":[[0,14,1.68],[1,14.5,3],[2,15,1]],"ltp":11.5,"tv":325.93,"id":26640937}]}]}
{"op":"mcm","clk":"992727947","pt":1580529455338,"mc":[{"id":"1.168096552","rc":[{"batl":[[0,14.5,3],[1,15,1],[2,20,1.68]],"ltp":11.5,"tv":325.93,"id":26640937}]}]}
{"op":"mcm","clk":"992728985","pt":1580529487164,"mc":[{"id":"1.168096552","rc":[{"batl":[[0,14,1.68],[1,14.5,3],[2,15,1]],"ltp":11.5,"tv":325.93,"id":26640937}]}]}
{"op":"mcm","clk":"992730094","pt":1580529519131,"mc":[{"id":"1.168096552","rc":[{"batl":[[0,14.5,3],[1,15,1],[2,20,1.68]],"ltp":11.5,"tv":325.93,"id":26640937}]}]}
{"op":"mcm","clk":"992731377","pt":1580529551194,"mc":[{"id":"1.168096552","rc":[{"batl":[[0,14,1.68],[1,14.5,3],[2,15,1]],"ltp":11.5,"tv":325.93,"id":26640937}]}]}
{"op":"mcm","clk":"992732656","pt":1580529583221,"mc":[{"id":"1.168096552","rc":[{"batl":[[0,14.5,3],[1,15,1],[2,20,1.68]],"ltp":11.5,"tv":325.93,"id":26640937}]}]}
{"op":"mcm","clk":"992734063","pt":1580529614921,"mc":[{"id":"1.168096552","rc":[{"batl":[[0,14,1.68],[1,14.5,3],[2,15,1]],"ltp":11.5,"tv":325.93,"id":26640937}]}]}
{"op":"mcm","clk":"992735772","pt":1580529651995,"mc":[{"id":"1.168096552","rc":[{"batl":[[0,14.5,3],[1,15,1],[2,20,1.68]],"ltp":11.5,"tv":325.93,"id":26640937}]}]}
{"op":"mcm","clk":"992737628","pt":1580529690250,"mc":[{"id":"1.168096552","rc":[{"batl":[[0,14,1.68],[1,14.5,3],[2,15,1]],"ltp":11.5,"tv":325.93,"id":26640937}]}]}
{"op":"mcm","clk":"992739762","pt":1580529727303,"mc":[{"id":"1.168096552","rc":[{"batl":[[0,14.5,3],[1,15,1],[2,20,1.68]],"ltp":11.5,"tv":325.93,"id":26640937}]}]}
{"op":"mcm","clk":"992740914","pt":1580529764317,"mc":[{"id":"1.168096552","rc":[{"batl":[[0,14,1.68],[1,14.5,3],[2,15,1]],"ltp":11.5,"tv":325.93,"id":26640937}]}]}
{"op":"mcm","clk":"992742890","pt":1580529812482,"mc":[{"id":"1.168096552","rc":[{"batl":[[0,14.5,3],[1,15,1],[2,20,1.68]],"ltp":11.5,"tv":325.93,"id":26640937}]}]}
{"op":"mcm","clk":"992744194","pt":1580529849432,"mc":[{"id":"1.168096552","rc":[{"batl":[[0,14,1.68],[1,14.5,3],[2,15,1]],"ltp":11.5,"tv":325.93,"id":26640937}]}]}
{"op":"mcm","clk":"992745525","pt":1580529885816,"mc":[{"id":"1.168096552","rc":[{"batl":[[0,14.5,3],[1,15,1],[2,20,1.68]],"ltp":11.5,"tv":325.93,"id":26640937}]}]}
{"op":"mcm","clk":"992746900","pt":1580529923890,"mc":[{"id":"1.168096552","rc":[{"batl":[[0,14,1.68],[1,14.5,3],[2,15,1]],"ltp":11.5,"tv":325.93,"id":26640937}]}]}
{"op":"mcm","clk":"992748333","pt":1580529960935,"mc":[{"id":"1.168096552","rc":[{"batl":[[0,14.5,3],[1,15,1],[2,20,1.68]],"ltp":11.5,"tv":325.93,"id":26640937}]}]}
{"op":"mcm","clk":"992749645","pt":1580529993493,"mc":[{"id":"1.168096552","rc":[{"batl":[[0,14,1.68],[1,14.5,3],[2,15,1]],"ltp":11.5,"tv":325.93,"id":26640937}]}]}
{"op":"mcm","clk":"992750686","pt":1580530025673,"mc":[{"id":"1.168096552","rc":[{"batl":[[0,14.5,3],[1,15,1],[2,20,1.68]],"ltp":11.5,"tv":325.93,"id":26640937}]}]}
{"op":"mcm","clk":"992761649","pt":1580530057520,"mc":[{"id":"1.168096552","rc":[{"batl":[[2,21,1.5]],"ltp":11.5,"tv":325.93,"id":26640937}]}]}
{"op":"mcm","clk":"992761652","pt":1580530057622,"mc":[{"id":"1.168096552","rc":[{"batl":[[0,14,1.68],[1,14.5,3],[2,15,1]],"ltp":11.5,"tv":325.93,"id":26640937}]}]}
{"op":"mcm","clk":"992763374","pt":1580530089460,"mc":[{"id":"1.168096552","rc":[{"batl":[[0,14.5,3],[1,15,1],[2,21,1.5]],"ltp":11.5,"tv":325.93,"id":26640937}]}]}
{"op":"mcm","clk":"992763434","pt":1580530089670,"mc":[{"id":"1.168096552","rc":[{"batl":[[2,20,1.68]],"ltp":11.5,"tv":325.93,"id":26640937}]}]}
{"op":"mcm","clk":"992765642","pt":1580530122019,"mc":[{"id":"1.168096552","rc":[{"batl":[[0,14,1.68],[1,14.5,3],[2,15,1]],"ltp":11.5,"tv":325.93,"id":26640937}]}]}
{"op":"mcm","clk":"992767377","pt":1580530153853,"mc":[{"id":"1.168096552","rc":[{"batl":[[0,14.5,3],[1,15,1],[2,20,1.68]],"ltp":11.5,"tv":325.93,"id":26640937}]}]}
{"op":"mcm","clk":"992769249","pt":1580530185642,"mc":[{"id":"1.168096552","rc":[{"batl":[[0,14,1.68],[1,14.5,3],[2,15,1]],"ltp":11.5,"tv":325.93,"id":26640937}]}]}
{"op":"mcm","clk":"992770066","pt":1580530200886,"mc":[{"id":"1.168096552","rc":[{"trd":[[3.05,389.87]],"batb":[[0,3,88.51],[1,2.98,4],[2,2.96,2]],"batl":[[0,3.05,3.94],[1,3.15,100],[2,3.2,22]],"ltp":3.05,"tv":2255.35,"id":18286408}],"tv":10516.49}]}
{"op":"mcm","clk":"992770181","pt":1580530203273,"mc":[{"id":"1.168096552","rc":[{"batb":[[0,2.96,5.82],[1,2.94,8.13],[2,2.92,10.66]],"ltp":3.0,"tv":6255.7,"id":52106}]}]}
{"op":"mcm","clk":"992770428","pt":1580530207450,"mc":[{"id":"1.168096552","rc":[{"trd":[[3.05,397.75]],"batl":[[0,3.15,100],[1,3.2,22],[2,3.25,380]],"ltp":3.05,"tv":2263.23,"id":18286408},{"batb":[[0,11.5,5.34]],"ltp":11.5,"tv":325.93,"id":26640937},{"batb":[[0,2.96,8.09]],"ltp":3.0,"tv":6255.7,"id":52106}],"tv":10524.36}]}
{"op":"mcm","clk":"992770472","pt":1580530208238,"mc":[{"id":"1.168096552","rc":[{"batb":[[0,4.9,1.71],[1,4.8,60.39],[2,4.7,21.12]],"ltp":4.8,"tv":1576.29,"id":21580749},{"batb":[[0,18,1.43]],"ltp":21.0,"tv":59.58,"id":24608298}]}]}
{"op":"mcm","clk":"992771106","pt":1580530217657,"mc":[{"id":"1.168096552","rc":[{"batl":[[0,14.5,3],[1,15,1],[2,20,1.68]],"ltp":11.5,"tv":325.93,"id":26640937}]}]}
{"op":"mcm","clk":"992772714","pt":1580530251472,"mc":[{"id":"1.168096552","rc":[{"batl":[[0,14,1.68],[1,14.5,3],[2,15,1]],"ltp":11.5,"tv":325.93,"id":26640937}]}]}
{"op":"mcm","clk":"992773818","pt":1580530282482,"mc":[{"id":"1.168096552","rc":[{"batl":[[0,14.5,3],[1,15,1],[2,21,1.5]],"ltp":11.5,"tv":325.93,"id":26640937}]}]}
{"op":"mcm","clk":"992773832","pt":1580530282900,"mc":[{"id":"1.168096552","rc":[{"batl":[[2,20,1.68]],"ltp":11.5,"tv":325.93,"id":26640937}]}]}
{"op":"mcm","clk":"992775398","pt":1580530314427,"mc":[{"id":"1.168096552","rc":[{"batl":[[2,21,1.5]],"ltp":11.5,"tv":325.93,"id":26640937}]}]}
{"op":"mcm","clk":"992775451","pt":1580530315513,"mc":[{"id":"1.168096552","rc":[{"batl":[[0,14,1.68],[1,14.5,3],[2,15,1]],"ltp":11.5,"tv":325.93,"id":26640937}]}]}
{"op":"mcm","clk":"992776865","pt":1580530346349,"mc":[{"id":"1.168096552","rc":[{"batl":[[0,14.5,3],[1,15,1],[2,20,1.68]],"ltp":11.5,"tv":325.93,"id":26640937}]}]}
{"op":"mcm","clk":"992778709","pt":1580530378383,"mc":[{"id":"1.168096552","rc":[{"batl":[[0,14,1.68],[1,14.5,3],[2,15,1]],"ltp":11.5,"tv":325.93,"id":26640937}]}]}
{"op":"mcm","clk":"992780564","pt":1580530410417,"mc":[{"id":"1.168096552","rc":[{"batl":[[0,14.5,3],[1,15,1],[2,20,1.68]],"ltp":11.5,"tv":325.93,"id":26640937}]}]}
{"op":"mcm","clk":"992782176","pt":1580530443272,"mc":[{"id":"1.168096552","rc":[{"batl":[[0,14,1.68],[1,14.5,3],[2,15,1]],"ltp":11.5,"tv":325.93,"id":26640937}]}]}
{"op":"mcm","clk":"992782741","pt":1580530455981,"mc":[{"id":"1.168096552","rc":[{"trd":[[11.5,12.61],[12,11.2]],"batb":[[0,11.5,2.34]],"ltp":11.5,"tv":331.94,"id":26640937}],"tv":10530.37}]}
{"op":"mcm","clk":"992783506","pt":1580530475317,"mc":[{"id":"1.168096552","rc":[{"batl":[[0,14.5,3],[1,15,1],[2,20,1.68]],"ltp":11.5,"tv":331.94,"id":26640937}]}]}
{"op":"mcm","clk":"992784666","pt":1580530504646,"mc":[{"id":"1.168096552","rc":[{"trd":[[3,473.94]],"batb":[[0,2.98,4.55],[1,2.96,2],[2,2.9,88]],"ltp":3.0,"tv":2439.19,"id":18286408}],"tv":10706.33}]}
{"op":"mcm","clk":"992784777","pt":1580530507325,"mc":[{"id":"1.168096552","rc":[{"batl":[[0,14,1.68],[1,14.5,3],[2,15,1]],"ltp":11.5,"tv":331.94,"id":26640937}]}]}
{"op":"mcm","clk":"992786051","pt":1580530539273,"mc":[{"id":"1.168096552","rc":[{"batl":[[0,14.5,3],[1,15,1],[2,20,1.68]],"ltp":11.5,"tv":331.94,"id":26640937}]}]}
{"op":"mcm","clk":"992787385","pt":1580530571294,"mc":[{"id":"1.168096552","rc":[{"batl":[[0,14,1.68],[1,14.5,3],[2,15,1]],"ltp":11.5,"tv":331.94,"id":26640937}]}]}
{"op":"mcm","clk":"992789194","pt":1580530603341,"mc":[{"id":"1.168096552","rc":[{"batl":[[0,14.5,3],[1,15,1],[2,20,1.68]],"ltp":11.5,"tv":331.94,"id":26640937}]}]}
{"op":"mcm","clk":"992790748","pt":1580530635226,"mc":[{"id":"1.168096552","rc":[{"batl":[[0,14,1.68],[1,14.5,3],[2,15,1]],"ltp":11.5,"tv":331.94,"id":26640937}]}]}
{"op":"mcm","clk":"992792142","pt":1580530667185,"mc":[{"id":"1.168096552","rc":[{"batl":[[0,14.5,3],[1,15,1],[2,20,1.68]],"ltp":11.5,"tv":331.94,"id":26640937}]}]}
{"op":"mcm","clk":"992792437","pt":1580530674882,"mc":[{"id":"1.168096552","rc":[{"batl":[[0,3.1,5],[1,3.15,100],[2,3.2,22]],"ltp":3.0,"tv":2439.19,"id":18286408}]}]}
{"op":"mcm","clk":"992792476","pt":1580530676124,"mc":[{"id":"1.168096552","rc":[{"batl":[[0,3.1,10]],"ltp":3.0,"tv":2439.19,"id":18286408}]}]}
{"op":"mcm","clk":"992792522","pt":1580530677414,"mc":[{"id":"1.168096552","rc":[{"batl":[[0,3.05,5],[1,3.1,10],[2,3.15,100]],"ltp":3.0,"tv":2439.19,"id":18286408}]}]}
{"op":"mcm","clk":"992792539","pt":1580530677776,"mc":[{"id":"1.168096552","rc":[{"batl":[[0,3.05,10]],"ltp":3.0,"tv":2439.19,"id":18286408}]}]}
{"op":"mcm","clk":"992792689","pt":1580530681395,"mc":[{"id":"1.168096552","rc":[{"trd":[[3,475.04]],"batb":[[0,2.98,4]],"batl":[[0,3,4.45],[1,3.05,10],[2,3.1,10]],"ltp":3.0,"tv":2440.29,"id":18286408}],"tv":10707.43}]}
{"op":"mcm","clk":"992792705","pt":1580530681912,"mc":[{"id":"1.168096552","rc":[{"batl":[[0,3,9.45]],"ltp":3.0,"tv":2440.29,"id":18286408}]}]}
{"op":"mcm","clk":"992792835","pt":1580530685224,"mc":[{"id":"1.168096552","rc":[{"batb":[[2,2.92,6]],"ltp":3.0,"tv":2440.29,"id":18286408}]}]}
{"op":"mcm","clk":"992793401","pt":1580530699116,"mc":[{"id":"1.168096552","rc":[{"batl":[[0,14,1.68],[1,14.5,3],[2,15,1]],"ltp":11.5,"tv":331.94,"id":26640937}]}]}
{"op":"mcm","clk":"992793715","pt":1580530706435,"mc":[{"id":"1.168096552","rc":[{"trd":[[3,493.94]],"batl":[[0,3.05,10],[1,3.1,10],[2,3.15,100]],"ltp":3.0,"tv":2459.19,"id":18286408},{"batb":[[0,12,1.96],[1,11.5,2.34],[2,11,2.23]],"ltp":11.5,"tv":331.94,"id":26640937},{"trd":[[5.1,9.24]],"batl":[[0,5.1,15.38]],"ltp":5.1,"tv":1585.53,"id":21580749},{"batb":[[0,38,1.02],[1,36,1.98],[2,34,2.34]],"ltp":48.0,"tv":43.61,"id":27706761},{"trd":[[3,852.51]],"batl":[[0,3,6.66]],"ltp":3.0,"tv":6271.38,"id":52106},{"trd":[[21,22.56]],"batl":[[0,21,17.44]],"ltp":21.0,"tv":61.82,"id":24608298}],"tv":10753.49}]}
{"op":"mcm","clk":"992794691","pt":1580530729229,"mc":[{"id":"1.168096552","rc":[{"batb":[[2,2.94,3]],"ltp":3.0,"tv":2459.19,"id":18286408}]}]}
{"op":"mcm","clk":"992794787","pt":1580530731054,"mc":[{"id":"1.168096552","rc":[{"batl":[[0,14.5,3],[1,15,1],[2,20,1.68]],"ltp":11.5,"tv":331.94,"id":26640937}]}]}
{"op":"mcm","clk":"992796051","pt":1580530763121,"mc":[{"id":"1.168096552","rc":[{"batl":[[0,14,1.68],[1,14.5,3],[2,15,1]],"ltp":11.5,"tv":331.94,"id":26640937}]}]}
{"op":"mcm","clk":"992797185","pt":1580530795022,"mc":[{"id":"1.168096552","rc":[{"batl":[[0,14.5,3],[1,15,1],[2,20,1.68]],"ltp":11.5,"tv":331.94,"id":26640937}]}]}
{"op":"mcm","clk":"992798452","pt":1580530827377,"mc":[{"id":"1.168096552","rc":[{"batl":[[0,14,1.68],[1,14.5,3],[2,15,1]],"ltp":11.5,"tv":331.94,"id":26640937}]}]}
{"op":"mcm","clk":"992799553","pt":1580530859398,"mc":[{"id":"1.168096552","rc":[{"batl":[[0,14.5,3],[1,15,1],[2,20,1.68]],"ltp":11.5,"tv":331.94,"id":26640937}]}]}
{"op":"mcm","clk":"992800749","pt":1580530891753,"mc":[{"id":"1.168096552","rc":[{"batl":[[0,14,1.68],[1,14.5,3],[2,15,1]],"ltp":11.5,"tv":331.94,"id":26640937}]}]}
{"op":"mcm","clk":"992801991","pt":1580530923809,"mc":[{"id":"1.168096552","rc":[{"batl":[[0,14.5,3],[1,15,1],[2,20,1.68]],"ltp":11.5,"tv":331.94,"id":26640937}]}]}
{"op":"mcm","clk":"992813105","pt":1580530956019,"mc":[{"id":"1.168096552","rc":[{"batl":[[0,14,1.68],[1,14.5,3],[2,15,1]],"ltp":11.5,"tv":331.94,"id":26640937}]}]}
{"op":"mcm","clk":"992814674","pt":1580530988299,"mc":[{"id":"1.168096552","rc":[{"batl":[[0,14.5,3],[1,15,1],[2,20,1.68]],"ltp":11.5,"tv":331.94,"id":26640937}]}]}
{"op":"mcm","clk":"992814790","pt":1580530991060,"mc":[{"id":"1.168096552","rc":[{"batl":[[1,3.1,20],[2,3.15,25.63]],"ltp":3.0,"tv":6271.38,"id":52106}]}]}
{"op":"mcm","clk":"992815937","pt":1580531020307,"mc":[{"id":"1.168096552","rc":[{"batl":[[0,14,1.68],[1,14.5,3],[2,15,1]],"ltp":11.5,"tv":331.94,"id":26640937}]}]}
{"op":"mcm","clk":"992817210","pt":1580531052128,"mc":[{"id":"1.168096552","rc":[{"batl":[[0,14.5,3],[1,15,1],[2,20,1.68]],"ltp":11.5,"tv":331.94,"id":26640937}]}]}
{"op":"mcm","clk":"992818388","pt":1580531084297,"mc":[{"id":"1.168096552","rc":[{"batl":[[0,14,1.68],[1,14.5,3],[2,15,1]],"ltp":11.5,"tv":331.94,"id":26640937}]}]}
{"op":"mcm","clk":"992819701","pt":1580531116424,"mc":[{"id":"1.168096552","rc":[{"batl":[[0,14.5,3],[1,15,1],[2,21,1.5]],"ltp":11.5,"tv":331.94,"id":26640937}]}]}
{"op":"mcm","clk":"992819704","pt":1580531116527,"mc":[{"id":"1.168096552","rc":[{"batl":[[2,20,1.68]],"ltp":11.5,"tv":331.94,"id":26640937}]}]}
{"op":"mcm","clk":"992821143","pt":1580531148685,"mc":[{"id":"1.168096552","rc":[{"batl":[[0,14,1.68],[1,14.5,3],[2,15,1]],"ltp":11.5,"tv":331.94,"id":26640937}]}]}
{"op":"mcm","clk":"992822513","pt":1580531180514,"mc":[{"id":"1.168096552","rc":[{"batl":[[0,14.5,3],[1,15,1],[2,21,1.5]],"ltp":11.5,"tv":331.94,"id":26640937}]}]}
{"op":"mcm","clk":"992822520","pt":1580531180722,"mc":[{"id":"1.168096552","rc":[{"batl":[[2,20,1.68]],"ltp":11.5,"tv":331.94,"id":26640937}]}]}
{"op":"mcm","clk":"992823830","pt":1580531212822,"mc":[{"id":"1.168096552","rc":[{"batl":[[0,14,1.68],[1,14.5,3],[2,15,1]],"ltp":11.5,"tv":331.94,"id":26640937}]}]}
{"op":"mcm","clk":"992825170","pt":1580531244886,"mc":[{"id":"1.168096552","rc":[{"batl":[[0,14.5,3],[1,15,1],[2,20,1.68]],"ltp":11.5,"tv":331.94,"id":26640937}]}]}
{"op":"mcm","clk":"992826338","pt":1580531277007,"mc":[{"id":"1.168096552","rc":[{"batl":[[0,14,1.68],[1,14.5,3],[2,15,1]],"ltp":11.5,"tv":331.94,"id":26640937}]}]}
{"op":"mcm","clk":"992827320","pt":1580531309143,"mc":[{"id":"1.168096552","rc":[{"batl":[[0,14.5,3],[1,15,1],[2,20,1.68]],"ltp":11.5,"tv":331.94,"id":26640937}]}]}
{"op":"mcm","clk":"992828255","pt":1580531341104,"mc":[{"id":"1.168096552","rc":[{"batl":[[0,14,1.68],[1,14.5,3],[2,15,1]],"ltp":11.5,"tv":331.94,"id":26640937}]}]}
{"op":"mcm","clk":"992829349","pt":1580531372996,"mc":[{"id":"1.168096552","rc":[{"batl":[[0,14.5,3],[1,15,1],[2,20,1.68]],"ltp":11.5,"tv":331.94,"id":26640937}]}]}
{"op":"mcm","clk":"992830163","pt":1580531405865,"mc":[{"id":"1.168096552","rc":[{"batl":[[0,14,1.68],[1,14.5,3],[2,15,1]],"ltp":11.5,"tv":331.94,"id":26640937}]}]}
{"op":"mcm","clk":"992830389","pt":1580531412772,"mc":[{"id":"1.168096552","rc":[{"trd":[[2.96,456.47]],"batb":[[0,2.96,7.09]],"ltp":2.96,"tv":6273.38,"id":52106}],"tv":10755.49}]}
{"op":"mcm","clk":"992830771","pt":1580531425076,"mc":[{"id":"1.168096552","rc":[{"trd":[[2.96,458.47]],"batb":[[0,2.96,6.09]],"ltp":2.96,"tv":6275.38,"id":52106}],"tv":10757.49}]}
{"op":"mcm","clk":"992830867","pt":1580531428073,"mc":[{"id":"1.168096552","rc":[{"batb":[[0,3,5.74],[1,2.98,4],[2,2.96,2]],"ltp":3.0,"tv":2459.19,"id":18286408},{"batb":[[0,4.9,5.22]],"ltp":5.1,"tv":1585.53,"id":21580749}]}]}
{"op":"mcm","clk":"992831165","pt":1580531436496,"mc":[{"id":"1.168096552","rc":[{"batb":[[1,4.7,21.12],[2,4.6,39.3]],"ltp":5.1,"tv":1585.53,"id":21580749}]}]}
{"op":"mcm","clk":"992831172","pt":1580531436703,"mc":[{"id":"1.168096552","rc":[{"batb":[[0,3,71.73]],"ltp":3.0,"tv":2459.19,"id":18286408}]}]}
{"op":"mcm","clk":"992831227","pt":1580531438512,"mc":[{"id":"1.168096552","rc":[{"batl":[[0,14.5,3],[1,15,1],[2,20,1.68]],"ltp":11.5,"tv":331.94,"id":26640937}]}]}
{"op":"mcm","clk":"992831693","pt":1580531453417,"mc":[{"id":"1.168096552","rc":[{"batb":[[0,3,5.74]],"ltp":3.0,"tv":2459.19,"id":18286408}]}]}
{"op":"mcm","clk":"992832443","pt":1580531470415,"mc":[{"id":"1.168096552","rc":[{"batl":[[0,14,1.68],[1,14.5,3],[2,15,1]],"ltp":11.5,"tv":331.94,"id":26640937}]}]}
{"op":"mcm","clk":"992832555","pt":1580531471355,"mc":[{"id":"1.168096552","rc":[{"batb":[[0,3,71.73]],"ltp":3.0,"tv":2459.19,"id":18286408}]}]}
{"op":"mcm","clk":"992833340","pt":1580531488356,"mc":[{"id":"1.168096552","rc":[{"batb":[[0,3,5.74]],"ltp":3.0,"tv":2459.19,"id":18286408}]}]}
{"op":"mcm","clk":"992834352","pt":1580531502480,"mc":[{"id":"1.168096552","rc":[{"batl":[[0,14.5,3],[1,15,1],[2,21,1.5]],"ltp":11.5,"tv":331.94,"id":26640937}]}]}
{"op":"mcm","clk":"992834356","pt":1580531502584,"mc":[{"id":"1.168096552","rc":[{"batl":[[2,20,1.68]],"ltp":11.5,"tv":331.94,"id":26640937}]}]}
{"op":"mcm","clk":"992834510","pt":1580531506510,"mc":[{"id":"1.168096552","rc":[{"batb":[[0,3,71.73]],"ltp":3.0,"tv":2459.19,"id":18286408}]}]}
{"op":"mcm","clk":"992835272","pt":1580531523503,"mc":[{"id":"1.168096552","rc":[{"batb":[[0,3,5.74]],"ltp":3.0,"tv":2459.19,"id":18286408}]}]}
{"op":"mcm","clk":"992835723","pt":1580531534498,"mc":[{"id":"1.168096552","rc":[{"batl":[[0,14,1.68],[1,14.5,3],[2,15,1]],"ltp":11.5,"tv":331.94,"id":26640937}]}]}
{"op":"mcm","clk":"992835995","pt":1580531541332,"mc":[{"id":"1.168096552","rc":[{"batb":[[0,3,71.73]],"ltp":3.0,"tv":2459.19,"id":18286408}]}]}
{"op":"mcm","clk":"992836769","pt":1580531558467,"mc":[{"id":"1.168096552","rc":[{"batb":[[0,3,5.74]],"ltp":3.0,"tv":2459.19,"id":18286408}]}]}
{"op":"mcm","clk":"992837143","pt":1580531566434,"mc":[{"id":"1.168096552","rc":[{"batl":[[0,14.5,3],[1,15,1],[2,20,1.68]],"ltp":11.5,"tv":331.94,"id":26640937}]}]}
{"op":"mcm","clk":"992837623","pt":1580531576472,"mc":[{"id":"1.168096552","rc":[{"batb":[[0,3,71.73]],"ltp":3.0,"tv":2459.19,"id":18286408}]}]}
{"op":"mcm","clk":"992838343","pt":1580531593483,"mc":[{"id":"1.168096552","rc":[{"batb":[[0,3,5.74]],"ltp":3.0,"tv":2459.19,"id":18286408}]}]}
{"op":"mcm","clk":"992838524","pt":1580531598318,"mc":[{"id":"1.168096552","rc":[{"batl":[[0,14,1.68],[1,14.5,3],[2,15,1]],"ltp":11.5,"tv":331.94,"id":26640937}]}]}
{"op":"mcm","clk":"992839021","pt":1580531611390,"mc":[{"id":"1.168096552","rc":[{"batb":[[0,3,71.73]],"ltp":3.0,"tv":2459.19,"id":18286408}]}]}
{"op":"mcm","clk":"992839789","pt":1580531628337,"mc":[{"id":"1.168096552","rc":[{"batb":[[0,3,5.74]],"ltp":3.0,"tv":2459.19,"id":18286408}]}]}
{"op":"mcm","clk":"992839877","pt":1580531630242,"mc":[{"id":"1.168096552","rc":[{"batl":[[0,14.5,3],[1,15,1],[2,20,1.68]],"ltp":11.5,"tv":331.94,"id":26640937}]}]}
{"op":"mcm","clk":"992840585","pt":1580531646463,"mc":[{"id":"1.168096552","rc":[{"batb":[[0,3,71.73]],"ltp":3.0,"tv":2459.19,"id":18286408}]}]}
{"op":"mcm","clk":"992841180","pt":1580531662154,"mc":[{"id":"1.168096552","rc":[{"batl":[[0,14,1.68],[1,14.5,3],[2,15,1]],"ltp":11.5,"tv":331.94,"id":26640937}]}]}
{"op":"mcm","clk":"992841225","pt":1580531663386,"mc":[{"id":"1.168096552","rc":[{"batb":[[0,3,5.74]],"ltp":3.0,"tv":2459.19,"id":18286408}]}]}
{"op":"mcm","clk":"992841844","pt":1580531681403,"mc":[{"id":"1.168096552","rc":[{"batb":[[0,3,71.73]],"ltp":3.0,"tv":2459.19,"id":18286408}]}]}
{"op":"mcm","clk":"992842293","pt":1580531694328,"mc":[{"id":"1.168096552","rc":[{"batl":[[0,14.5,3],[1,15,1],[2,20,1.68]],"ltp":11.5,"tv":331.94,"id":26640937}]}]}
{"op":"mcm","clk":"992842409","pt":1580531698435,"mc":[{"id":"1.168096552","rc":[{"batb":[[0,3,5.74]],"ltp":3.0,"tv":2459.19,"id":18286408}]}]}
{"op":"mcm","clk":"992843078","pt":1580531716356,"mc":[{"id":"1.168096552","rc":[{"batb":[[0,3,71.73]],"ltp":3.0,"tv":2459.19,"id":18286408}]}]}
{"op":"mcm","clk":"992843448","pt":1580531726348,"mc":[{"id":"1.168096552","rc":[{"batl":[[0,14,1.68],[1,14.5,3],[2,15,1]],"ltp":11.5,"tv":331.94,"id":26640937}]}]}
{"op":"mcm","clk":"992843759","pt":1580531733470,"mc":[{"id":"1.168096552","rc":[{"batb":[[0,3,5.74]],"ltp":3.0,"tv":2459.19,"id":18286408}]}]}
{"op":"mcm","clk":"992844461","pt":1580531751510,"mc":[{"id":"1.168096552","rc":[{"batb":[[0,3,71.73]],"ltp":3.0,"tv":2459.19,"id":18286408}]}]}
{"op":"mcm","clk":"992844708","pt":1580531759076,"mc":[{"id":"1.168096552","rc":[{"batl":[[0,14.5,3],[1,15,1],[2,20,1.68]],"ltp":11.5,"tv":331.94,"id":26640937}]}]}
{"op":"mcm","clk":"992845064","pt":1580531769508,"mc":[{"id":"1.168096552","rc":[{"batb":[[0,3,5.74]],"ltp":3.0,"tv":2459.19,"id":18286408}]}]}
{"op":"mcm","clk":"992845630","pt":1580531786514,"mc":[{"id":"1.168096552","rc":[{"batb":[[0,3,71.73]],"ltp":3.0,"tv":2459.19,"id":18286408}]}]}
{"op":"mcm","clk":"992845805","pt":1580531791042,"mc":[{"id":"1.168096552","rc":[{"batl":[[0,14,1.68],[1,14.5,3],[2,15,1]],"ltp":11.5,"tv":331.94,"id":26640937}]}]}
{"op":"mcm","clk":"992846168","pt":1580531804442,"mc":[{"id":"1.168096552","rc":[{"batb":[[0,3,5.74]],"ltp":3.0,"tv":2459.19,"id":18286408}]}]}
{"op":"mcm","clk":"992846712","pt":1580531821453,"mc":[{"id":"1.168096552","rc":[{"batb":[[0,3,71.73]],"ltp":3.0,"tv":2459.19,"id":18286408}]}]}
{"op":"mcm","clk":"992846757","pt":1580531822955,"mc":[{"id":"1.168096552","rc":[{"batl":[[0,14.5,3],[1,15,1],[2,20,1.68]],"ltp":11.5,"tv":331.94,"id":26640937}]}]}
{"op":"mcm","clk":"992847243","pt":1580531839586,"mc":[{"id":"1.168096552","rc":[{"batb":[[0,3,5.74]],"ltp":3.0,"tv":2459.19,"id":18286408}]}]}
{"op":"mcm","clk":"992857630","pt":1580531855041,"mc":[{"id":"1.168096552","rc":[{"batl":[[0,14,1.68],[1,14.5,3],[2,15,1]],"ltp":11.5,"tv":331.94,"id":26640937}]}]}
{"op":"mcm","clk":"992857694","pt":1580531856492,"mc":[{"id":"1.168096552","rc":[{"batb":[[0,3,71.73]],"ltp":3.0,"tv":2459.19,"id":18286408}]}]}
{"op":"mcm","clk":"992858365","pt":1580531874552,"mc":[{"id":"1.168096552","rc":[{"batb":[[0,3,5.74]],"ltp":3.0,"tv":2459.19,"id":18286408}]}]}
{"op":"mcm","clk":"992858794","pt":1580531887287,"mc":[{"id":"1.168096552","rc":[{"batl":[[0,14.5,3],[1,15,1],[2,20,1.68]],"ltp":11.5,"tv":331.94,"id":26640937}]}]}
{"op":"mcm","clk":"992858920","pt":1580531891384,"mc":[{"id":"1.168096552","rc":[{"batb":[[0,3,71.73]],"ltp":3.0,"tv":2459.19,"id":18286408}]}]}
{"op":"mcm","clk":"992859482","pt":1580531909385,"mc":[{"id":"1.168096552","rc":[{"batb":[[0,3,5.74]],"ltp":3.0,"tv":2459.19,"id":18286408}]}]}
{"op":"mcm","clk":"992859736","pt":1580531919011,"mc":[{"id":"1.168096552","rc":[{"batl":[[0,14,1.68],[1,14.5,3],[2,15,1]],"ltp":11.5,"tv":331.94,"id":26640937}]}]}
{"op":"mcm","clk":"992859994","pt":1580531926429,"mc":[{"id":"1.168096552","rc":[{"batb":[[0,3,71.73]],"ltp":3.0,"tv":2459.19,"id":18286408}]}]}
{"op":"mcm","clk":"992860548","pt":1580531944451,"mc":[{"id":"1.168096552","rc":[{"batb":[[0,3,5.74]],"ltp":3.0,"tv":2459.19,"id":18286408}]}]}
{"op":"mcm","clk":"992860790","pt":1580531951054,"mc":[{"id":"1.168096552","rc":[{"batl":[[0,14.5,3],[1,15,1],[2,20,1.68]],"ltp":11.5,"tv":331.94,"id":26640937}]}]}
{"op":"mcm","clk":"992861198","pt":1580531961458,"mc":[{"id":"1.168096552","rc":[{"batb":[[0,3,71.73]],"ltp":3.0,"tv":2459.19,"id":18286408}]}]}
{"op":"mcm","clk":"992861322","pt":1580531964954,"mc":[{"id":"1.168096552","rc":[{"batb":[[0,3,75.09]],"ltp":3.0,"tv":2459.19,"id":18286408},{"batb":[[0,2.96,10.29]],"ltp":2.96,"tv":6275.38,"id":52106}]}]}
{"op":"mcm","clk":"992861803","pt":1580531979683,"mc":[{"id":"1.168096552","rc":[{"trd":[[3.05,417.74]],"batb":[[0,3.05,54.92],[1,3,9.1],[2,2.98,4]],"batl":[[0,3.1,10],[1,3.15,100],[2,3.2,22]],"ltp":3.05,"tv":2479.18,"id":18286408}],"tv":10777.47}]}
{"op":"mcm","clk":"992861911","pt":1580531982978,"mc":[{"id":"1.168096552","rc":[{"batl":[[0,14,1.68],[1,14.5,3],[2,15,1]],"ltp":11.5,"tv":331.94,"id":26640937}]}]}
{"op":"mcm","clk":"992862365","pt":1580531996606,"mc":[{"id":"1.168096552","rc":[{"batb":[[0,3,9.1],[1,2.98,4],[2,2.96,2]],"ltp":3.05,"tv":2479.18,"id":18286408}]}]}
{"op":"mcm","clk":"992862975","pt":1580532015438,"mc":[{"id":"1.168096552","rc":[{"batl":[[0,14.5,3],[1,15,1],[2,20,1.68]],"ltp":11.5,"tv":331.94,"id":26640937}]}]}
{"op":"mcm","clk":"992863863","pt":1580532047286,"mc":[{"id":"1.168096552","rc":[{"batl":[[0,14,1.68],[1,14.5,3],[2,15,1]],"ltp":11.5,"tv":331.94,"id":26640937}]}]}
{"op":"mcm","clk":"992864955","pt":1580532078942,"mc":[{"id":"1.168096552","rc":[{"batl":[[0,14.5,3],[1,15,1],[2,20,1.68]],"ltp":11.5,"tv":331.94,"id":26640937}]}]}
{"op":"mcm","clk":"992866214","pt":1580532111278,"mc":[{"id":"1.168096552","rc":[{"batl":[[0,14,1.68],[1,14.5,3],[2,15,1]],"ltp":11.5,"tv":331.94,"id":26640937}]}]}
{"op":"mcm","clk":"992867475","pt":1580532143078,"mc":[{"id":"1.168096552","rc":[{"batl":[[0,14.5,3],[1,15,1],[2,20,1.68]],"ltp":11.5,"tv":331.94,"id":26640937}]}]}
{"op":"mcm","clk":"992867944","pt":1580532157515,"mc":[{"id":"1.168096552","rc":[{"trd":[[5,170.25],[5.1,14.48]],"batb":[[0,5,55.66],[1,4.9,5.22],[2,4.7,21.12]],"batl":[[0,5.1,22.76]],"ltp":5.1,"tv":1607.39,"id":21580749}],"tv":10799.33}]}
{"op":"mcm","clk":"992868282","pt":1580532166350,"mc":[{"id":"1.168096552","rc":[{"batb":[[0,5,75.82]],"ltp":5.1,"tv":1607.39,"id":21580749}]}]}
{"op":"mcm","clk":"992868642","pt":1580532175447,"mc":[{"id":"1.168096552","rc":[{"batl":[[0,14,1.68],[1,14.5,3],[2,15,1]],"ltp":11.5,"tv":331.94,"id":26640937},{"trd":[[5.1,59.98]],"batb":[[0,5.1,31.83],[1,5,20.16],[2,4.9,5.22]],"batl":[[0,5.2,33],[1,5.3,9],[2,6,2.5]],"ltp":5.1,"tv":1652.89,"id":21580749}],"tv":10844.83}]}
{"op":"mcm","clk":"992869118","pt":1580532189874,"mc":[{"id":"1.168096552","rc":[{"batb":[[1,4.9,5.22],[2,4.7,21.12]],"ltp":5.1,"tv":1652.89,"id":21580749}]}]}
{"op":"mcm","clk":"992869214","pt":1580532192350,"mc":[{"id":"1.168096552","rc":[{"batb":[[0,4.9,5.22],[1,4.7,21.12],[2,4.6,39.3]],"ltp":5.1,"tv":1652.89,"id":21580749}]}]}
{"op":"mcm","clk":"992869772","pt":1580532208463,"mc":[{"id":"1.168096552","rc":[{"batl":[[0,14.5,3],[1,15,1],[2,20,1.68]],"ltp":11.5,"tv":331.94,"id":26640937}]}]}
{"op":"mcm","clk":"992870086","pt":1580532214872,"mc":[{"id":"1.168096552","rc":[{"batb":[[1,4.8,3],[2,4.7,21.12]],"ltp":5.1,"tv":1652.89,"id":21580749}]}]}
{"op":"mcm","clk":"992870720","pt":1580532234024,"mc":[{"id":"1.168096552","rc":[{"trd":[[2.96,478.13]],"batb":[[0,2.94,8.6],[1,2.92,10.66],[2,2.88,15.14]],"ltp":2.96,"tv":6295.04,"id":52106}],"tv":10864.49}]}
{"op":"mcm","clk":"992870945","pt":1580532239837,"mc":[{"id":"1.168096552","rc":[{"batl":[[0,14,1.68],[1,14.5,3],[2,15,1]],"ltp":11.5,"tv":331.94,"id":26640937}]}]}
{"op":"mcm","clk":"992872113","pt":1580532271697,"mc":[{"id":"1.168096552","rc":[{"batl":[[0,14.5,3],[1,15,1],[2,20,1.68]],"ltp":11.5,"tv":331.94,"id":26640937}]}]}
{"op":"mcm","clk":"992873228","pt":1580532303742,"mc":[{"id":"1.168096552","rc":[{"batl":[[0,14,1.68],[1,14.5,3],[2,15,1]],"ltp":11.5,"tv":331.94,"id":26640937}]}]}
{"op":"mcm","clk":"992874414","pt":1580532336090,"mc":[{"id":"1.168096552","rc":[{"batl":[[0,14.5,3],[1,15,1],[2,20,1.68]],"ltp":11.5,"tv":331.94,"id":26640937}]}]}
{"op":"mcm","clk":"992875751","pt":1580532367730,"mc":[{"id":"1.168096552","rc":[{"batl":[[0,14,1.68],[1,14.5,3],[2,15,1]],"ltp":11.5,"tv":331.94,"id":26640937}]}]}
{"op":"mcm","clk":"992875859","pt":1580532370510,"mc":[{"id":"1.168096552","rc":[{"batb":[[0,2.94,8.02]],"ltp":2.96,"tv":6295.04,"id":52106}]}]}
{"op":"mcm","clk":"992875891","pt":1580532371438,"mc":[{"id":"1.168096552","rc":[{"batb":[[0,18,1.34]],"ltp":21.0,"tv":61.82,"id":24608298}]}]}
{"op":"mcm","clk":"992877339","pt":1580532399457,"mc":[{"id":"1.168096552","rc":[{"batl":[[0,14.5,3],[1,15,1],[2,20,1.68]],"ltp":11.5,"tv":331.94,"id":26640937}]}]}
{"op":"mcm","clk":"992878739","pt":1580532431475,"mc":[{"id":"1.168096552","rc":[{"batl":[[0,14,1.68],[1,14.5,3],[2,15,1]],"ltp":11.5,"tv":331.94,"id":26640937}]}]}
{"op":"mcm","clk":"992879803","pt":1580532463638,"mc":[{"id":"1.168096552","rc":[{"batl":[[0,14.5,3],[1,15,1],[2,20,1.68]],"ltp":11.5,"tv":331.94,"id":26640937}]}]}
{"op":"mcm","clk":"992881112","pt":1580532495795,"mc":[{"id":"1.168096552","rc":[{"batl":[[0,14,1.68],[1,14.5,3],[2,15,1]],"ltp":11.5,"tv":331.94,"id":26640937}]}]}
{"op":"mcm","clk":"992882647","pt":1580532528453,"mc":[{"id":"1.168096552","rc":[{"batl":[[0,14.5,3],[1,15,1],[2,21,1.5]],"ltp":11.5,"tv":331.94,"id":26640937}]}]}
{"op":"mcm","clk":"992882651","pt":1580532528554,"mc":[{"id":"1.168096552","rc":[{"batl":[[2,20,1.68]],"ltp":11.5,"tv":331.94,"id":26640937}]}]}
{"op":"mcm","clk":"992884143","pt":1580532560450,"mc":[{"id":"1.168096552","rc":[{"batl":[[2,21,1.5]],"ltp":11.5,"tv":331.94,"id":26640937}]}]}
{"op":"mcm","clk":"992884165","pt":1580532561176,"mc":[{"id":"1.168096552","rc":[{"batl":[[0,14,1.68],[1,14.5,3],[2,15,1]],"ltp":11.5,"tv":331.94,"id":26640937}]}]}
{"op":"mcm","clk":"992885536","pt":1580532593216,"mc":[{"id":"1.168096552","rc":[{"batl":[[0,14.5,3],[1,15,1],[2,20,1.68]],"ltp":11.5,"tv":331.94,"id":26640937}]}]}
{"op":"mcm","clk":"992886607","pt":1580532624473,"mc":[{"id":"1.168096552","rc":[{"batl":[[2,21,1.5]],"ltp":11.5,"tv":331.94,"id":26640937}]}]}
{"op":"mcm","clk":"992886615","pt":1580532624571,"mc":[{"id":"1.168096552","rc":[{"batl":[[0,14,1.68],[1,14.5,3],[2,15,1]],"ltp":11.5,"tv":331.94,"id":26640937}]}]}
{"op":"mcm","clk":"992887901","pt":1580532656388,"mc":[{"id":"1.168096552","rc":[{"batl":[[0,14.5,3],[1,15,1],[2,20,1.68]],"ltp":11.5,"tv":331.94,"id":26640937}]}]}
{"op":"mcm","clk":"992889277","pt":1580532688246,"mc":[{"id":"1.168096552","rc":[{"batl":[[0,14,1.68],[1,14.5,3],[2,15,1]],"ltp":11.5,"tv":331.94,"id":26640937}]}]}
{"op":"mcm","clk":"992890548","pt":1580532720501,"mc":[{"id":"1.168096552","rc":[{"batl":[[0,14.5,3],[1,15,1],[2,20,1.68]],"ltp":11.5,"tv":331.94,"id":26640937}]}]}
{"op":"mcm","clk":"992901695","pt":1580532752323,"mc":[{"id":"1.168096552","rc":[{"batl":[[0,14,1.68],[1,14.5,3],[2,15,1]],"ltp":11.5,"tv":331.94,"id":26640937}]}]}
{"op":"mcm","clk":"992902973","pt":1580532784463,"mc":[{"id":"1.168096552","rc":[{"batl":[[0,14.5,3],[1,15,1],[2,20,1.68]],"ltp":11.5,"tv":331.94,"id":26640937}]}]}
{"op":"mcm","clk":"992904278","pt":1580532817235,"mc":[{"id":"1.168096552","rc":[{"batl":[[0,14,1.68],[1,14.5,3],[2,15,1]],"ltp":11.5,"tv":331.94,"id":26640937}]}]}
{"op":"mcm","clk":"992905406","pt":1580532849401,"mc":[{"id":"1.168096552","rc":[{"batl":[[0,14.5,3],[1,15,1],[2,20,1.68]],"ltp":11.5,"tv":331.94,"id":26640937}]}]}
{"op":"mcm","clk":"992906070","pt":1580532868307,"mc":[{"id":"1.168096552","rc":[{"trd":[[4.9,95.99]],"batb":[[0,4.9,3.22]],"ltp":4.9,"tv":1656.89,"id":21580749}],"tv":10868.49}]}
{"op":"mcm","clk":"992906526","pt":1580532880800,"mc":[{"id":"1.168096552","rc":[{"batl":[[0,14,1.68],[1,14.5,3],[2,15,1]],"ltp":11.5,"tv":331.94,"id":26640937}]}]}
{"op":"mcm","clk":"992907842","pt":1580532912767,"mc":[{"id":"1.168096552","rc":[{"batl":[[0,14.5,3],[1,15,1],[2,20,1.68]],"ltp":11.5,"tv":331.94,"id":26640937}]}]}
{"op":"mcm","clk":"992909295","pt":1580532945291,"mc":[{"id":"1.168096552","rc":[{"batl":[[0,14,1.68],[1,14.5,3],[2,15,1]],"ltp":11.5,"tv":331.94,"id":26640937}]}]}
{"op":"mcm","clk":"992910667","pt":1580532977424,"mc":[{"id":"1.168096552","rc":[{"batl":[[0,14.5,3],[1,15,1],[2,20,1.68]],"ltp":11.5,"tv":331.94,"id":26640937}]}]}
{"op":"mcm","clk":"992911988","pt":1580533009459,"mc":[{"id":"1.168096552","rc":[{"batl":[[2,21,1.5]],"ltp":11.5,"tv":331.94,"id":26640937}]}]}
{"op":"mcm","clk":"992912039","pt":1580533010448,"mc":[{"id":"1.168096552","rc":[{"batl":[[0,14,1.68],[1,14.5,3],[2,15,1]],"ltp":11.5,"tv":331.94,"id":26640937}]}]}
{"op":"mcm","clk":"992913441","pt":1580533041381,"mc":[{"id":"1.168096552","rc":[{"batl":[[0,14.5,3],[1,15,1],[2,21,1.5]],"ltp":11.5,"tv":331.94,"id":26640937}]}]}
{"op":"mcm","clk":"992913452","pt":1580533041588,"mc":[{"id":"1.168096552","rc":[{"batl":[[2,20,1.68]],"ltp":11.5,"tv":331.94,"id":26640937}]}]}
{"op":"mcm","clk":"992914768","pt":1580533073854,"mc":[{"id":"1.168096552","rc":[{"batl":[[0,14,1.68],[1,14.5,3],[2,15,1]],"ltp":11.5,"tv":331.94,"id":26640937}]}]}
{"op":"mcm","clk":"992914876","pt":1580533076083,"mc":[{"id":"1.168096552","rc":[{"trd":[[11.5,12.69],[12,15.12]],"batb":[[0,11.5,2.29],[1,11,2.23],[2,10.5,4.14]],"ltp":11.5,"tv":335.94,"id":26640937}],"tv":10872.49}]}
{"op":"mcm","clk":"992915092","pt":1580533080131,"mc":[{"id":"1.168096552","rc":[{"batl":[[0,14,2.82]],"ltp":11.5,"tv":335.94,"id":26640937}]}]}
{"op":"mcm","clk":"992917300","pt":1580533132744,"mc":[{"id":"1.168096552","rc":[{"trd":[[3.1,430.74]],"batl":[[0,3.15,100],[1,3.2,22],[2,3.25,380]],"ltp":3.1,"tv":2499.18,"id":18286408}],"tv":10892.49}]}
{"op":"mcm","clk":"992920716","pt":1580533205027,"mc":[{"id":"1.168096552","rc":[{"batb":[[1,11,3.8]],"ltp":11.5,"tv":335.94,"id":26640937}]}]}
{"op":"mcm","clk":"992922294","pt":1580533244417,"mc":[{"id":"1.168096552","rc":[{"batl":[[0,3.1,4],[1,3.15,100],[2,3.2,22]],"ltp":3.1,"tv":2499.18,"id":18286408}]}]}
{"op":"mcm","clk":"992925047","pt":1580533304905,"mc":[{"id":"1.168096552","rc":[{"batl":[[0,14,1.68]],"ltp":11.5,"tv":335.94,"id":26640937}]}]}
{"op":"mcm","clk":"992927015","pt":1580533352392,"mc":[{"id":"1.168096552","rc":[{"batb":[[2,2.96,90]],"ltp":3.1,"tv":2499.18,"id":18286408}]}]}
{"op":"mcm","clk":"992927186","pt":1580533355434,"mc":[{"id":"1.168096552","rc":[{"batl":[[0,14.5,3],[1,15,1],[2,20,1.68]],"ltp":11.5,"tv":335.94,"id":26640937}]}]}
{"op":"mcm","clk":"992927792","pt":1580533370863,"mc":[{"id":"1.168096552","rc":[{"batb":[[0,2.98,3],[1,2.94,8.02],[2,2.92,10.66]],"ltp":2.96,"tv":6295.04,"id":52106}]}]}
{"op":"mcm","clk":"992928513","pt":1580533387499,"mc":[{"id":"1.168096552","rc":[{"batb":[[0,3.05,2],[1,3,9.1],[2,2.98,4]],"ltp":3.1,"tv":2499.18,"id":18286408}]}]}
{"op":"mcm","clk":"992928957","pt":1580533398082,"mc":[{"id":"1.168096552","rc":[{"batb":[[0,5,2],[1,4.9,3.22],[2,4.8,3]],"ltp":4.9,"tv":1656.89,"id":21580749}]}]}
{"op":"mcm","clk":"992929866","pt":1580533418129,"mc":[{"id":"1.168096552","rc":[{"batl":[[0,14,1.68],[1,14.5,3],[2,15,1]],"ltp":11.5,"tv":335.94,"id":26640937}]}]}
{"op":"mcm","clk":"992932401","pt":1580533476472,"mc":[{"id":"1.168096552","rc":[{"trd":[[3,865.83]],"batb":[[2,2.88,15.15]],"batl":[[0,3.1,20],[1,3.15,25.63],[2,3.3,15.14]],"ltp":3.0,"tv":6308.35,"id":52106}],"tv":10905.81}]}
{"op":"mcm","clk":"992932752","pt":1580533481483,"mc":[{"id":"1.168096552","rc":[{"batl":[[0,14.5,3],[1,15,1],[2,20,1.68]],"ltp":11.5,"tv":335.94,"id":26640937}]}]}
{"op":"mcm","clk":"992934589","pt":1580533516404,"mc":[{"id":"1.168096552","rc":[{"trd":[[3.1,438.74]],"batl":[[0,3.15,100],[1,3.2,22],[2,3.25,380]],"ltp":3.1,"tv":2507.18,"id":18286408}],"tv":10913.81}]}
{"op":"mcm","clk":"992934632","pt":1580533517232,"mc":[{"id":"1.168096552","rc":[{"batb":[[1,3,13.1]],"ltp":3.1,"tv":2507.18,"id":18286408}]}]}
{"op":"mcm","clk":"992937165","pt":1580533571071,"mc":[{"id":"1.168096552","rc":[{"batl":[[0,14,1.68],[1,14.5,3],[2,15,1]],"ltp":11.5,"tv":335.94,"id":26640937}]}]}
{"op":"mcm","clk":"992937570","pt":1580533579495,"mc":[{"id":"1.168096552","rc":[{"batb":[[0,3.1,2],[1,3.05,2],[2,3,13.1]],"ltp":3.1,"tv":2507.18,"id":18286408},{"batb":[[0,3,2],[1,2.98,3],[2,2.94,8.02]],"ltp":3.0,"tv":6308.35,"id":52106}]}]}
{"op":"mcm","clk":"992938599","pt":1580533603071,"mc":[{"id":"1.168096552","rc":[{"batl":[[0,14.5,3],[1,15,1],[2,20,1.68]],"ltp":11.5,"tv":335.94,"id":26640937}]}]}
{"op":"mcm","clk":"992940094","pt":1580533635097,"mc":[{"id":"1.168096552","rc":[{"batl":[[0,14,1.68],[1,14.5,3],[2,15,1]],"ltp":11.5,"tv":335.94,"id":26640937}]}]}
{"op":"mcm","clk":"992951175","pt":1580533664752,"mc":[{"id":"1.168096552","rc":[{"batb":[[1,2.96,3.46],[2,2.94,7.56]],"ltp":3.0,"tv":6308.35,"id":52106}]}]}
{"op":"mcm","clk":"992951328","pt":1580533668424,"mc":[{"id":"1.168096552","rc":[{"batl":[[0,14.5,3],[1,15,1],[2,20,1.68]],"ltp":11.5,"tv":335.94,"id":26640937}]}]}
{"op":"mcm","clk":"992952544","pt":1580533700003,"mc":[{"id":"1.168096552","rc":[{"batl":[[0,14,1.68],[1,14.5,3],[2,15,1]],"ltp":11.5,"tv":335.94,"id":26640937}]}]}
{"op":"mcm","clk":"992952844","pt":1580533709430,"mc":[{"id":"1.168096552","rc":[{"trd":[[3,869.83]],"batb":[[0,2.96,3.46],[1,2.94,7.56],[2,2.88,15.15]],"batl":[[0,3,1],[1,3.1,20],[2,3.15,25.63]],"ltp":3.0,"tv":6312.35,"id":52106}],"tv":10917.81}]}
{"op":"mcm","clk":"992953776","pt":1580533732431,"mc":[{"id":"1.168096552","rc":[{"batl":[[0,14.5,3],[1,15,1],[2,20,1.68]],"ltp":11.5,"tv":335.94,"id":26640937}]}]}
{"op":"mcm","clk":"992954715","pt":1580533757078,"mc":[{"id":"1.168096552","rc":[{"batb":[[0,4.9,3.22],[1,4.8,5],[2,4.7,21.12]],"ltp":4.9,"tv":1656.89,"id":21580749}]}]}
{"op":"mcm","clk":"992955031","pt":1580533764689,"mc":[{"id":"1.168096552","rc":[{"batl":[[0,14,1.68],[1,14.5,3],[2,15,1]],"ltp":11.5,"tv":335.94,"id":26640937}]}]}
{"op":"mcm","clk":"992955232","pt":1580533768294,"mc":[{"id":"1.168096552","rc":[{"batb":[[1,4.8,3],[2,4.7,23.12]],"ltp":4.9,"tv":1656.89,"id":21580749}]}]}
{"op":"mcm","clk":"992955567","pt":1580533775291,"mc":[{"id":"1.168096552","rc":[{"batb":[[1,3,15.1],[2,2.98,4]],"ltp":3.1,"tv":2507.18,"id":18286408}]}]}
{"op":"mcm","clk":"992956556","pt":1580533796923,"mc":[{"id":"1.168096552","rc":[{"batl":[[0,14.5,3],[1,15,1],[2,20,1.68]],"ltp":11.5,"tv":335.94,"id":26640937}]}]}
{"op":"mcm","clk":"992957040","pt":1580533807815,"mc":[{"id":"1.168096552","rc":[{"batb":[[0,17.5,5.6],[1,13.5,2.39],[2,13,2]],"ltp":21.0,"tv":61.82,"id":24608298}]}]}
{"op":"mcm","clk":"992957529","pt":1580533817349,"mc":[{"id":"1.168096552","rc":[{"batb":[[1,3,13.1],[2,2.98,6]],"ltp":3.1,"tv":2507.18,"id":18286408}]}]}
{"op":"mcm","clk":"992957997","pt":1580533829165,"mc":[{"id":"1.168096552","rc":[{"batl":[[0,14,1.68],[1,14.5,3],[2,15,1]],"ltp":11.5,"tv":335.94,"id":26640937}]}]}
{"op":"mcm","clk":"992958293","pt":1580533835443,"mc":[{"id":"1.168096552","rc":[{"batb":[[0,2.98,3],[1,2.94,8.02]],"ltp":3.0,"tv":6312.35,"id":52106}]}]}
{"op":"mcm","clk":"992959606","pt":1580533861242,"mc":[{"id":"1.168096552","rc":[{"batl":[[0,14.5,3],[1,15,1],[2,20,1.68]],"ltp":11.5,"tv":335.94,"id":26640937}]}]}
{"op":"mcm","clk":"992961218","pt":1580533893483,"mc":[{"id":"1.168096552","rc":[{"batl":[[0,14,1.68],[1,14.5,3],[2,15,1]],"ltp":11.5,"tv":335.94,"id":26640937}]}]}
{"op":"mcm","clk":"992962601","pt":1580533925500,"mc":[{"id":"1.168096552","rc":[{"batl":[[0,14.5,3],[1,15,1],[2,21,1.5]],"ltp":11.5,"tv":335.94,"id":26640937}]}]}
{"op":"mcm","clk":"992962627","pt":1580533925915,"mc":[{"id":"1.168096552","rc":[{"batl":[[2,20,1.68]],"ltp":11.5,"tv":335.94,"id":26640937}]}]}
{"op":"mcm","clk":"992962707","pt":1580533928018,"mc":[{"id":"1.168096552","rc":[{"batl":[[1,3.05,2],[2,3.1,20]],"ltp":3.0,"tv":6312.35,"id":52106}]}]}
{"op":"mcm","clk":"992964016","pt":1580533958360,"mc":[{"id":"1.168096552","rc":[{"batl":[[0,14,1.68],[1,14.5,3],[2,15,1]],"ltp":11.5,"tv":335.94,"id":26640937}]}]}
{"op":"mcm","clk":"992965117","pt":1580533990378,"mc":[{"id":"1.168096552","rc":[{"batl":[[0,14.5,3],[1,15,1],[2,20,1.68]],"ltp":11.5,"tv":335.94,"id":26640937}]}]}
{"op":"mcm","clk":"992965667","pt":1580534003087,"mc":[{"id":"1.168096552","rc":[{"batb":[[0,2.98,2]],"ltp":3.0,"tv":6312.35,"id":52106}]}]}
{"op":"mcm","clk":"992966433","pt":1580534022006,"mc":[{"id":"1.168096552","rc":[{"batl":[[0,14,1.68],[1,14.5,3],[2,15,1]],"ltp":11.5,"tv":335.94,"id":26640937}]}]}
{"op":"mcm","clk":"992967522","pt":1580534050240,"mc":[{"id":"1.168096552","rc":[{"batl":[[1,3.1,20],[2,3.15,25.63]],"ltp":3.0,"tv":6312.35,"id":52106}]}]}
{"op":"mcm","clk":"992967719","pt":1580534054466,"mc":[{"id":"1.168096552","rc":[{"batl":[[0,14.5,3],[1,15,1],[2,20,1.68]],"ltp":11.5,"tv":335.94,"id":26640937}]}]}
{"op":"mcm","clk":"992968929","pt":1580534086312,"mc":[{"id":"1.168096552","rc":[{"batl":[[0,14,1.68],[1,14.5,3],[2,15,1]],"ltp":11.5,"tv":335.94,"id":26640937}]}]}
{"op":"mcm","clk":"992970149","pt":1580534118246,"mc":[{"id":"1.168096552","rc":[{"batl":[[0,14.5,3],[1,15,1],[2,20,1.68]],"ltp":11.5,"tv":335.94,"id":26640937}]}]}
{"op":"mcm","clk":"992971541","pt":1580534150404,"mc":[{"id":"1.168096552","rc":[{"batl":[[0,14,1.68],[1,14.5,3],[2,15,1]],"ltp":11.5,"tv":335.94,"id":26640937}]}]}
{"op":"mcm","clk":"992971917","pt":1580534157827,"mc":[{"id":"1.168096552","rc":[{"trd":[[3,871.83],[3.1,63.09]],"batl":[[0,3.1,18.9],[1,3.15,25.63],[2,3.3,15.14]],"ltp":3.1,"tv":6316.55,"id":52106}],"tv":10922.01}]}
{"op":"mcm","clk":"992973079","pt":1580534182233,"mc":[{"id":"1.168096552","rc":[{"batl":[[0,14.5,3],[1,15,1],[2,20,1.68]],"ltp":11.5,"tv":335.94,"id":26640937}]}]}
{"op":"mcm","clk":"992974430","pt":1580534213891,"mc":[{"id":"1.168096552","rc":[{"batl":[[0,14,1.68],[1,14.5,3],[2,15,1]],"ltp":11.5,"tv":335.94,"id":26640937}]}]}
{"op":"mcm","clk":"992975868","pt":1580534245521,"mc":[{"id":"1.168096552","rc":[{"batl":[[0,14.5,3],[1,15,1],[2,21,1.5]],"ltp":11.5,"tv":335.94,"id":26640937}]}]}
{"op":"mcm","clk":"992975871","pt":1580534245625,"mc":[{"id":"1.168096552","rc":[{"batl":[[2,20,1.68]],"ltp":11.5,"tv":335.94,"id":26640937}]}]}
{"op":"mcm","clk":"992977104","pt":1580534278270,"mc":[{"id":"1.168096552","rc":[{"batl":[[0,14,1.68],[1,14.5,3],[2,15,1]],"ltp":11.5,"tv":335.94,"id":26640937}]}]}
{"op":"mcm","clk":"992978250","pt":1580534309997,"mc":[{"id":"1.168096552","rc":[{"batl":[[0,14.5,3],[1,15,1],[2,20,1.68]],"ltp":11.5,"tv":335.94,"id":26640937}]}]}
{"op":"mcm","clk":"992979584","pt":1580534341941,"mc":[{"id":"1.168096552","rc":[{"batl":[[0,14,1.68],[1,14.5,3],[2,15,1]],"ltp":11.5,"tv":335.94,"id":26640937}]}]}
{"op":"mcm","clk":"992979842","pt":1580534347731,"mc":[{"id":"1.168096552","rc":[{"batl":[[0,3.05,2.02],[1,3.1,18.9],[2,3.15,25.63]],"ltp":3.1,"tv":6316.55,"id":52106}]}]}
{"op":"mcm","clk":"992979883","pt":1580534348752,"mc":[{"id":"1.168096552","rc":[{"batl":[[0,3.1,18.9],[1,3.15,25.63],[2,3.3,15.14]],"ltp":3.1,"tv":6316.55,"id":52106}]}]}
{"op":"mcm","clk":"992980779","pt":1580534374466,"mc":[{"id":"1.168096552","rc":[{"batl":[[0,14.5,3],[1,15,1],[2,20,1.68]],"ltp":11.5,"tv":335.94,"id":26640937}]}]}
{"op":"mcm","clk":"992982369","pt":1580534405728,"mc":[{"id":"1.168096552","rc":[{"batl":[[0,14,1.68],[1,14.5,3],[2,15,1]],"ltp":11.5,"tv":335.94,"id":26640937}]}]}
{"op":"mcm","clk":"992983739","pt":1580534439067,"mc":[{"id":"1.168096552","rc":[{"batl":[[0,14.5,3],[1,15,1],[2,20,1.68]],"ltp":11.5,"tv":335.94,"id":26640937}]}]}
{"op":"mcm","clk":"992985201","pt":1580534472405,"mc":[{"id":"1.168096552","rc":[{"batl":[[0,14,1.68],[1,14.5,3],[2,15,1]],"ltp":11.5,"tv":335.94,"id":26640937}]}]}
{"op":"mcm","clk":"992986589","pt":1580534509480,"mc":[{"id":"1.168096552","rc":[{"batl":[[0,14.5,3],[1,15,1],[2,20,1.68]],"ltp":11.5,"tv":335.94,"id":26640937}]}]}
{"op":"mcm","clk":"992988022","pt":1580534541045,"mc":[{"id":"1.168096552","rc":[{"batl":[[0,14,1.68],[1,14.5,3],[2,15,1]],"ltp":11.5,"tv":335.94,"id":26640937}]}]}
{"op":"mcm","clk":"992999196","pt":1580534572975,"mc":[{"id":"1.168096552","rc":[{"batl":[[0,14.5,3],[1,15,1],[2,20,1.68]],"ltp":11.5,"tv":335.94,"id":26640937}]}]}
{"op":"mcm","clk":"993000296","pt":1580534605202,"mc":[{"id":"1.168096552","rc":[{"batl":[[0,14,1.68],[1,14.5,3],[2,15,1]],"ltp":11.5,"tv":335.94,"id":26640937}]}]}
{"op":"mcm","clk":"993001287","pt":1580534634445,"mc":[{"id":"1.168096552","rc":[{"trd":[[2.98,444.73]],"batb":[[0,2.94,8.02],[1,2.88,15.15],[2,2.84,46.76]],"ltp":2.98,"tv":6320.55,"id":52106}],"tv":10926.01}]}
{"op":"mcm","clk":"993001369","pt":1580534637056,"mc":[{"id":"1.168096552","rc":[{"batl":[[0,14.5,3],[1,15,1],[2,20,1.68]],"ltp":11.5,"tv":335.94,"id":26640937},{"batb":[[2,2.86,5.8]],"batl":[[0,3.05,5.44],[1,3.1,18.9],[2,3.15,25.63]],"ltp":2.98,"tv":6320.55,"id":52106}]}]}
{"op":"mcm","clk":"993001635","pt":1580534645773,"mc":[{"id":"1.168096552","rc":[{"batb":[[1,3,9.74]],"ltp":3.1,"tv":2507.18,"id":18286408},{"batb":[[0,2.94,7.56]],"ltp":2.98,"tv":6320.55,"id":52106}]}]}
{"op":"mcm","clk":"993001999","pt":1580534656406,"mc":[{"id":"1.168096552","rc":[{"trd":[[2.94,341.59]],"batb":[[0,2.94,1.97]],"ltp":2.94,"tv":6331.73,"id":52106}],"tv":10937.19}]}
{"op":"mcm","clk":"993002246","pt":1580534663314,"mc":[{"id":"1.168096552","rc":[{"batl":[[0,3,2],[1,3.05,5.44],[2,3.1,18.9]],"ltp":2.94,"tv":6331.73,"id":52106}]}]}
{"op":"mcm","clk":"993002381","pt":1580534666502,"mc":[{"id":"1.168096552","rc":[{"batl":[[0,2.98,2],[1,3,2],[2,3.05,5.44]],"ltp":2.94,"tv":6331.73,"id":52106}]}]}
{"op":"mcm","clk":"993002472","pt":1580534668807,"mc":[{"id":"1.168096552","rc":[{"batl":[[0,14,1.68],[1,14.5,3],[2,15,1]],"ltp":11.5,"tv":335.94,"id":26640937},{"batb":[[2,2.84,46.76]],"batl":[[2,3.1,18.9]],"ltp":2.94,"tv":6331.73,"id":52106}]}]}
{"op":"mcm","clk":"993003125","pt":1580534687241,"mc":[{"id":"1.168096552","rc":[{"batb":[[1,2.9,2.01],[2,2.88,15.14]],"ltp":2.94,"tv":6331.73,"id":52106}]}]}
{"op":"mcm","clk":"993003291","pt":1580534691766,"mc":[{"id":"1.168096552","rc":[{"batb":[[0,2.96,10.54],[1,2.94,1.97],[2,2.9,5.01]],"ltp":2.94,"tv":6331.73,"id":52106}]}]}
{"op":"mcm","clk":"993003643","pt":1580534701087,"mc":[{"id":"1.168096552","rc":[{"batl":[[0,14.5,3],[1,15,1],[2,20,1.68]],"ltp":11.5,"tv":335.94,"id":26640937}]}]}
{"op":"mcm","clk":"993003960","pt":1580534709503,"mc":[{"id":"1.168096552","rc":[{"trd":[[2.98,448.73],[3,875.83]],"batl":[[0,3.1,18.9],[1,3.15,25.63],[2,3.3,15.14]],"ltp":3.0,"tv":6339.73,"id":52106}],"tv":10945.19}]}
{"op":"mcm","clk":"993004033","pt":1580534711307,"mc":[{"id":"1.168096552","rc":[{"batb":[[1,2.94,3.97],[2,2.92,2.01]],"ltp":3.0,"tv":6339.73,"id":52106}]}]}
{"op":"mcm","clk":"993004566","pt":1580534724455,"mc":[{"id":"1.168096552","rc":[{"batb":[[0,3.05,2]],"ltp":3.1,"tv":2507.18,"id":18286408}]}]}
{"op":"mcm","clk":"993004926","pt":1580534732970,"mc":[{"id":"1.168096552","rc":[{"batl":[[0,14,1.68],[1,14.5,3],[2,15,1]],"ltp":11.5,"tv":335.94,"id":26640937}]}]}
{"op":"mcm","clk":"993006281","pt":1580534764732,"mc":[{"id":"1.168096552","rc":[{"batl":[[0,14.5,3],[1,15,1],[2,20,1.68]],"ltp":11.5,"tv":335.94,"id":26640937}]}]}
{"op":"mcm","clk":"993007581","pt":1580534796476,"mc":[{"id":"1.168096552","rc":[{"batl":[[2,21,1.5]],"ltp":11.5,"tv":335.94,"id":26640937}]}]}
{"op":"mcm","clk":"993007584","pt":1580534796579,"mc":[{"id":"1.168096552","rc":[{"batl":[[0,14,1.68],[1,14.5,3],[2,15,1]],"ltp":11.5,"tv":335.94,"id":26640937}]}]}
{"op":"mcm","clk":"993008681","pt":1580534828004,"mc":[{"id":"1.168096552","rc":[{"batl":[[0,14.5,3],[1,15,1],[2,20,1.68]],"ltp":11.5,"tv":335.94,"id":26640937}]}]}
{"op":"mcm","clk":"993009945","pt":1580534860071,"mc":[{"id":"1.168096552","rc":[{"batl":[[0,3.1,2],[1,3.15,100],[2,3.2,22]],"ltp":3.1,"tv":2507.18,"id":18286408},{"batl":[[0,14,1.68],[1,14.5,3],[2,15,1]],"ltp":11.5,"tv":335.94,"id":26640937}]}]}
{"op":"mcm","clk":"993011196","pt":1580534891294,"mc":[{"id":"1.168096552","rc":[{"trd":[[3.05,421.74]],"batb":[[0,3,9.74],[1,2.98,6],[2,2.96,90]],"batl":[[0,3.05,18],[1,3.1,2],[2,3.15,100]],"ltp":3.05,"tv":2511.18,"id":18286408}],"tv":10949.19}]}
{"op":"mcm","clk":"993011220","pt":1580534892111,"mc":[{"id":"1.168096552","rc":[{"batl":[[0,14.5,3],[1,15,1],[2,20,1.68]],"ltp":11.5,"tv":335.94,"id":26640937}]}]}
{"op":"mcm","clk":"993012250","pt":1580534923475,"mc":[{"id":"1.168096552","rc":[{"batl":[[0,14,1.68],[1,14.5,3],[2,15,1]],"ltp":11.5,"tv":335.94,"id":26640937}]}]}
{"op":"mcm","clk":"993013414","pt":1580534955143,"mc":[{"id":"1.168096552","rc":[{"batl":[[0,14.5,3],[1,15,1],[2,20,1.68]],"ltp":11.5,"tv":335.94,"id":26640937}]}]}
{"op":"mcm","clk":"993014227","pt":1580534981274,"mc":[{"id":"1.168096552","rc":[{"batl":[[0,3.05,23]],"ltp":3.05,"tv":2511.18,"id":18286408}]}]}
{"op":"mcm","clk":"993014372","pt":1580534986415,"mc":[{"id":"1.168096552","rc":[{"batl":[[0,14,1.68],[1,14.5,3],[2,15,1]],"ltp":11.5,"tv":335.94,"id":26640937}]}]}
{"op":"mcm","clk":"993015611","pt":1580535019745,"mc":[{"id":"1.168096552","rc":[{"batl":[[0,14.5,3],[1,15,1],[2,20,1.68]],"ltp":11.5,"tv":335.94,"id":26640937}]}]}
{"op":"mcm","clk":"993016713","pt":1580535051390,"mc":[{"id":"1.168096552","rc":[{"batl":[[0,14,1.68],[1,14.5,3],[2,15,1]],"ltp":11.5,"tv":335.94,"id":26640937}]}]}
{"op":"mcm","clk":"993018102","pt":1580535083474,"mc":[{"id":"1.168096552","rc":[{"batl":[[0,14.5,3],[1,15,1],[2,21,1.5]],"ltp":11.5,"tv":335.94,"id":26640937}]}]}
{"op":"mcm","clk":"993018113","pt":1580535083678,"mc":[{"id":"1.168096552","rc":[{"batl":[[2,20,1.68]],"ltp":11.5,"tv":335.94,"id":26640937}]}]}
{"op":"mcm","clk":"993019851","pt":1580535114899,"mc":[{"id":"1.168096552","rc":[{"batl":[[0,14,1.68],[1,14.5,3],[2,15,1]],"ltp":11.5,"tv":335.94,"id":26640937}]}]}
{"op":"mcm","clk":"993020697","pt":1580535132963,"mc":[{"id":"1.168096552","rc":[{"trd":[[2.96,168.52],[2.98,16],[3,513.42]],"batb":[[0,2.96,5.74],[1,2.88,39],[2,2.86,2.08]],"ltp":2.96,"tv":2711.17,"id":18286408}],"tv":11149.19}]}
{"op":"mcm","clk":"993020898","pt":1580535136156,"mc":[{"id":"1.168096552","rc":[{"batl":[[0,3,2],[1,3.05,23],[2,3.1,2]],"ltp":2.96,"tv":2711.17,"id":18286408}]}]}
{"op":"mcm","clk":"993021025","pt":1580535138471,"mc":[{"id":"1.168096552","rc":[{"batb":[[0,2.96,10.85]],"ltp":2.96,"tv":2711.17,"id":18286408},{"batb":[[0,2.98,5.64],[1,2.96,10.54],[2,2.94,3.97]],"ltp":3.0,"tv":6339.73,"id":52106}]}]}
{"op":"mcm","clk":"993021048","pt":1580535138833,"mc":[{"id":"1.168096552","rc":[{"batb":[[0,38,1.64]],"ltp":48.0,"tv":43.61,"id":27706761},{"batb":[[0,18,2.27],[1,17.5,4.64],[2,13.5,2.39]],"ltp":21.0,"tv":61.82,"id":24608298}]}]}
{"op":"mcm","clk":"993021139","pt":1580535140133,"mc":[{"id":"1.168096552","rc":[{"batb":[[0,5,3.02],[1,4.9,3.22],[2,4.8,3]],"ltp":4.9,"tv":1656.89,"id":21580749}]}]}
{"op":"mcm","clk":"993021207","pt":1580535141333,"mc":[{"id":"1.168096552","rc":[{"batb":[[1,2.88,36],[2,2.86,5.08]],"ltp":2.96,"tv":2711.17,"id":18286408},{"batb":[[0,12,1.26],[1,11.5,2.29],[2,11,3.8]],"ltp":11.5,"tv":335.94,"id":26640937}]}]}
{"op":"mcm","clk":"993021551","pt":1580535146464,"mc":[{"id":"1.168096552","rc":[{"batl":[[0,14.5,3],[1,15,1],[2,21,1.5]],"ltp":11.5,"tv":335.94,"id":26640937}]}]}
{"op":"mcm","clk":"993021561","pt":1580535146672,"mc":[{"id":"1.168096552","rc":[{"batl":[[2,20,1.68]],"ltp":11.5,"tv":335.94,"id":26640937}]}]}
{"op":"mcm","clk":"993021703","pt":1580535149150,"mc":[{"id":"1.168096552","rc":[{"batl":[[0,3,7]],"ltp":2.96,"tv":2711.17,"id":18286408}]}]}
{"op":"mcm","clk":"993021884","pt":1580535152391,"mc":[{"id":"1.168096552","rc":[{"batb":[[2,13.5,3.7]],"ltp":21.0,"tv":61.82,"id":24608298}]}]}
{"op":"mcm","clk":"993022364","pt":1580535161488,"mc":[{"id":"1.168096552","rc":[{"trd":[[2.96,190.22]],"batb":[[0,2.88,36],[1,2.86,5.08],[2,2.76,2.58]],"ltp":2.96,"tv":2732.87,"id":18286408}],"tv":11170.88}]}
{"op":"mcm","clk":"993022369","pt":1580535161589,"mc":[{"id":"1.168096552","rc":[{"batb":[[0,2.9,10.84],[1,2.88,36],[2,2.86,5.08]],"ltp":2.96,"tv":2732.87,"id":18286408}]}]}
{"op":"mcm","clk":"993023158","pt":1580535175520,"mc":[{"id":"1.168096552","rc":[{"batb":[[0,2.92,57.36],[1,2.9,10.84],[2,2.88,36]],"ltp":2.96,"tv":2732.87,"id":18286408}]}]}
{"op":"mcm","clk":"993023298","pt":1580535178307,"mc":[{"id":"1.168096552","rc":[{"batl":[[0,14,1.68],[1,14.5,3],[2,15,1]],"ltp":11.5,"tv":335.94,"id":26640937}]}]}
{"op":"mcm","clk":"993023658","pt":1580535184707,"mc":[{"id":"1.168096552","rc":[{"batb":[[0,2.94,2.03],[1,2.92,57.36],[2,2.9,10.84]],"ltp":2.96,"tv":2732.87,"id":18286408}]}]}
{"op":"mcm","clk":"993024907","pt":1580535209760,"mc":[{"id":"1.168096552","rc":[{"batl":[[0,14.5,3],[1,15,1],[2,20,1.68]],"ltp":11.5,"tv":335.94,"id":26640937}]}]}
{"op":"mcm","clk":"993026188","pt":1580535241020,"mc":[{"id":"1.168096552","rc":[{"batl":[[0,14,1.68],[1,14.5,3],[2,15,1]],"ltp":11.5,"tv":335.94,"id":26640937}]}]}
{"op":"mcm","clk":"993027328","pt":1580535265481,"mc":[{"id":"1.168096552","rc":[{"batl":[[2,3.15,100]],"ltp":2.96,"tv":2732.87,"id":18286408}]}]}
{"op":"mcm","clk":"993027432","pt":1580535268261,"mc":[{"id":"1.168096552","rc":[{"batb":[[0,2.98,3],[1,2.94,2.03],[2,2.92,57.36]],"ltp":2.96,"tv":2732.87,"id":18286408}]}]}
{"op":"mcm","clk":"993027665","pt":1580535273481,"mc":[{"id":"1.168096552","rc":[{"batl":[[0,14.5,3],[1,15,1],[2,20,1.68]],"ltp":11.5,"tv":335.94,"id":26640937}]}]}
{"op":"mcm","clk":"993028614","pt":1580535294612,"mc":[{"id":"1.168096552","rc":[{"batb":[[0,2.98,7.64]],"ltp":3.0,"tv":6339.73,"id":52106}]}]}
{"op":"mcm","clk":"993029126","pt":1580535305125,"mc":[{"id":"1.168096552","rc":[{"batl":[[0,14,1.68],[1,14.5,3],[2,15,1]],"ltp":11.5,"tv":335.94,"id":26640937}]}]}
{"op":"mcm","clk":"993030551","pt":1580535337094,"mc":[{"id":"1.168096552","rc":[{"batl":[[0,14.5,3],[1,15,1],[2,20,1.68]],"ltp":11.5,"tv":335.94,"id":26640937}]}]}
{"op":"mcm","clk":"993031808","pt":1580535368520,"mc":[{"id":"1.168096552","rc":[{"batl":[[2,21,1.5]],"ltp":11.5,"tv":335.94,"id":26640937}]}]}
{"op":"mcm","clk":"993031811","pt":1580535368622,"mc":[{"id":"1.168096552","rc":[{"batl":[[0,14,1.68],[1,14.5,3],[2,15,1]],"ltp":11.5,"tv":335.94,"id":26640937}]}]}
{"op":"mcm","clk":"993033131","pt":1580535400411,"mc":[{"id":"1.168096552","rc":[{"batl":[[0,14.5,3],[1,15,1],[2,21,1.5]],"ltp":11.5,"tv":335.94,"id":26640937}]}]}
{"op":"mcm","clk":"993033142","pt":1580535400620,"mc":[{"id":"1.168096552","rc":[{"batl":[[2,20,1.68]],"ltp":11.5,"tv":335.94,"id":26640937}]}]}
{"op":"mcm","clk":"993034411","pt":1580535433163,"mc":[{"id":"1.168096552","rc":[{"batl":[[0,14,1.68],[1,14.5,3],[2,15,1]],"ltp":11.5,"tv":335.94,"id":26640937}]}]}
{"op":"mcm","clk":"993035401","pt":1580535450300,"mc":[{"id":"1.168096552","rc":[{"trd":[[3,526.6]],"batl":[[0,3.05,23.41],[1,3.15,100],[2,3.2,22]],"ltp":3.0,"tv":2746.05,"id":18286408}],"tv":11184.06}]}
{"op":"mcm","clk":"993045631","pt":1580535455691,"mc":[{"id":"1.168096552","rc":[{"batb":[[1,2.94,4.03]],"ltp":3.0,"tv":2746.05,"id":18286408}]}]}
{"op":"mcm","clk":"993046055","pt":1580535462422,"mc":[{"id":"1.168096552","rc":[{"batb":[[2,2.9,10.84]],"ltp":3.0,"tv":2746.05,"id":18286408}]}]}
{"op":"mcm","clk":"993046277","pt":1580535466441,"mc":[{"id":"1.168096552","rc":[{"batl":[[0,14.5,3],[1,15,1],[2,20,1.68]],"ltp":11.5,"tv":335.94,"id":26640937}]}]}
{"op":"mcm","clk":"993046794","pt":1580535476513,"mc":[{"id":"1.168096552","rc":[{"trd":[[3,527.42]],"batb":[[0,3,4.65],[1,2.98,3],[2,2.94,4.03]],"batl":[[0,3.05,23]],"ltp":3.0,"tv":2746.87,"id":18286408}],"tv":11184.88}]}
{"op":"mcm","clk":"993047694","pt":1580535498963,"mc":[{"id":"1.168096552","rc":[{"batl":[[0,14,1.68],[1,14.5,3],[2,15,1]],"ltp":11.5,"tv":335.94,"id":26640937}]}]}
{"op":"mcm","clk":"993048466","pt":1580535515297,"mc":[{"id":"1.168096552","rc":[{"trd":[[3.05,431.05]],"batb":[[0,2.98,3],[1,2.94,4.03],[2,2.88,36]],"batl":[[0,3.05,18.34]],"ltp":3.05,"tv":2756.18,"id":18286408}],"tv":11194.19}]}
{"op":"mcm","clk":"993048506","pt":1580535516429,"mc":[{"id":"1.168096552","rc":[{"batb":[[2,2.88,39]],"ltp":3.05,"tv":2756.18,"id":18286408}]}]}
{"op":"mcm","clk":"993049080","pt":1580535530217,"mc":[{"id":"1.168096552","rc":[{"batl":[[0,14.5,3],[1,15,1],[2,20,1.68]],"ltp":11.5,"tv":335.94,"id":26640937}]}]}
{"op":"mcm","clk":"993049712","pt":1580535548248,"mc":[{"id":"1.168096552","rc":[{"trd":[[2.96,499.21],[2.98,464.01]],"batb":[[0,2.94,3.97],[1,2.92,2.01],[2,2.88,15.14]],"batl":[[0,2.96,11.9],[1,2.98,22.36],[2,3.1,18.9]],"ltp":2.96,"tv":6376.09,"id":52106}],"tv":11230.55}]}
{"op":"mcm","clk":"993050211","pt":1580535562477,"mc":[{"id":"1.168096552","rc":[{"batl":[[0,14,1.68],[1,14.5,3],[2,15,1]],"ltp":11.5,"tv":335.94,"id":26640937}]}]}
{"op":"mcm","clk":"993050529","pt":1580535569997,"mc":[{"id":"1.168096552","rc":[{"batl":[[1,3.1,18.9],[2,3.15,25.63]],"ltp":2.96,"tv":6376.09,"id":52106}]}]}
{"op":"mcm","clk":"993051665","pt":1580535593722,"mc":[{"id":"1.168096552","rc":[{"batl":[[0,14.5,3],[1,15,1],[2,20,1.68]],"ltp":11.5,"tv":335.94,"id":26640937}]}]}
{"op":"mcm","clk":"993052046","pt":1580535601140,"mc":[{"id":"1.168096552","rc":[{"batb":[[0,2.94,5.97]],"ltp":2.96,"tv":6376.09,"id":52106}]}]}
{"op":"mcm","clk":"993052096","pt":1580535602273,"mc":[{"id":"1.168096552","rc":[{"trd":[[2.94,353.54]],"batb":[[0,2.92,2.01],[1,2.88,15.14],[2,2.84,46.76]],"batl":[[0,2.94,16.5],[1,2.96,11.9],[2,3.1,18.9]],"ltp":2.94,"tv":6388.03,"id":52106}],"tv":11242.5}]}
{"op":"mcm","clk":"993052144","pt":1580535603255,"mc":[{"id":"1.168096552","rc":[{"trd":[[2.98,22]],"batb":[[0,2.94,4.03],[1,2.88,39],[2,2.76,2.58]],"ltp":2.98,"tv":2762.18,"id":18286408}],"tv":11248.5}]}
{"op":"mcm","clk":"993052361","pt":1580535607884,"mc":[{"id":"1.168096552","rc":[{"batb":[[1,2.88,36],[2,2.86,3]],"ltp":2.98,"tv":2762.18,"id":18286408}]}]}
{"op":"mcm","clk":"993052582","pt":1580535612269,"mc":[{"id":"1.168096552","rc":[{"batb":[[0,2.92,4.01]],"ltp":2.94,"tv":6388.03,"id":52106}]}]}
{"op":"mcm","clk":"993052736","pt":1580535615361,"mc":[{"id":"1.168096552","rc":[{"batl":[[0,2.96,11.9],[1,3.1,18.9],[2,3.15,25.63]],"ltp":2.94,"tv":6388.03,"id":52106}]}]}
{"op":"mcm","clk":"993053039","pt":1580535621389,"mc":[{"id":"1.168096552","rc":[{"batb":[[0,2.94,61]],"ltp":2.98,"tv":2762.18,"id":18286408}]}]}
{"op":"mcm","clk":"993053095","pt":1580535622696,"mc":[{"id":"1.168096552","rc":[{"batb":[[1,2.9,4],[2,2.88,15.14]],"ltp":2.94,"tv":6388.03,"id":52106}]}]}
{"op":"mcm","clk":"993053241","pt":1580535626410,"mc":[{"id":"1.168096552","rc":[{"batl":[[0,14,1.68],[1,14.5,3],[2,15,1]],"ltp":11.5,"tv":335.94,"id":26640937}]}]}
{"op":"mcm","clk":"993053743","pt":1580535637047,"mc":[{"id":"1.168096552","rc":[{"batb":[[0,2.96,3],[1,2.94,61],[2,2.88,36]],"ltp":2.98,"tv":2762.18,"id":18286408}]}]}
{"op":"mcm","clk":"993054340","pt":1580535650048,"mc":[{"id":"1.168096552","rc":[{"trd":[[2.92,913.02]],"batb":[[0,2.9,4],[1,2.88,15.14],[2,2.84,46.76]],"batl":[[0,2.92,7.99],[1,2.96,11.9],[2,3.1,18.9]],"ltp":2.92,"tv":6396.05,"id":52106}],"tv":11256.52}]}
{"op":"mcm","clk":"993054445","pt":1580535652738,"mc":[{"id":"1.168096552","rc":[{"trd":[[3.05,446.35]],"batl":[[0,3.05,10.69]],"ltp":3.05,"tv":2777.48,"id":18286408},{"batb":[[0,12.5,1.87],[1,12,1.26],[2,11.5,2.29]],"ltp":11.5,"tv":335.94,"id":26640937},{"trd":[[5.2,8.96]],"batl":[[0,5.2,28.52]],"ltp":5.2,"tv":1665.85,"id":21580749},{"batb":[[0,40,1.14],[1,38,1.05],[2,36,1.98]],"ltp":48.0,"tv":43.61,"id":27706761},{"trd":[[2.92,929]],"batl":[[0,2.96,11.9],[1,3.1,18.9],[2,3.15,25.63]],"ltp":2.92,"tv":6412.03,"id":52106},{"trd":[[21,24.78]],"batl":[[0,21,16.33]],"ltp":21.0,"tv":64.04,"id":24608298}],"tv":11298.98}]}
{"op":"mcm","clk":"993054612","pt":1580535656255,"mc":[{"id":"1.168096552","rc":[{"batb":[[2,2.88,39]],"ltp":3.05,"tv":2777.48,"id":18286408}]}]}
{"op":"mcm","clk":"993054702","pt":1580535658469,"mc":[{"id":"1.168096552","rc":[{"batl":[[0,14.5,3],[1,15,1],[2,21,1.5]],"ltp":11.5,"tv":335.94,"id":26640937}]}]}
{"op":"mcm","clk":"993095970","pt":1580536377505,"mc":[{"id":"1.168096552","rc":[{"trd":[[3.05,467.73]],"batl":[[0,3.15,100],[1,3.2,22],[2,3.25,380]],"ltp":3.05,"tv":2798.86,"id":18286408},{"trd":[[14.5,6]],"batl":[[0,15,1],[1,21,1.5],[2,32,9.17]],"ltp":14.5,"tv":341.94,"id":26640937},{"trd":[[5,190.25]],"batb":[[0,4.9,3.22],[1,4.8,3],[2,4.7,23.12]],"ltp":5.0,"tv":1685.85,"id":21580749},{"trd":[[48,6.24]],"batl":[[0,48,1.9]],"ltp":48.0,"tv":44.97,"id":27706761},{"trd":[[2.96,523.01]],"batl":[[0,3.1,18.9],[1,3.15,25.63],[2,3.3,15.14]],"ltp":2.96,"tv":6435.83,"id":52106},{"trd":[[21,27.88]],"batl":[[0,21,14.78]],"ltp":21.0,"tv":67.14,"id":24608298}],"tv":11374.62}]}
