{"op":"mcm","clk":"993742717","pt":1580545897502,"mc":[{"id":"1.168096552","rc":[{"batb":[[0,24,15.19],[1,23,5.04],[2,21,10.8]],"ltp":21.0,"tv":198.69,"id":24608298}]}]}
{"op":"mcm","clk":"993742852","pt":1580545899311,"mc":[{"id":"1.168096552","rc":[{"trd":[[3.05,952.96]],"batl":[[0,3.05,15.37]],"ltp":3.05,"tv":3943.8,"id":18286408}],"tv":16031.12}]}
{"op":"mcm","clk":"993743024","pt":1580545901500,"mc":[{"id":"1.168096552","rc":[{"batb":[[0,3,91.5]],"ltp":3.05,"tv":3943.8,"id":18286408},{"batb":[[0,13.5,2],[1,13,7.7],[2,12.5,1.87]],"batl":[[0,14.5,2.22],[1,15,9.8],[2,15.5,5]],"ltp":14.5,"tv":553.35,"id":26640937},{"batb":[[0,60,1.19]],"ltp":65.0,"tv":99.56,"id":27706761},{"batb":[[0,2.96,2]],"ltp":2.98,"tv":7496.16,"id":52106},{"batb":[[1,22,4.27],[2,21,15.07]],"ltp":21.0,"tv":198.69,"id":24608298}]}]}
{"op":"mcm","clk":"993743225","pt":1580545903487,"mc":[{"id":"1.168096552","rc":[{"batb":[[1,55,4]],"ltp":65.0,"tv":99.56,"id":27706761},{"batb":[[0,2.96,6.23],[1,2.94,40.31]],"ltp":2.98,"tv":7496.16,"id":52106},{"batb":[[1,22,8.54]],"ltp":21.0,"tv":198.69,"id":24608298}]}]}
{"op":"mcm","clk":"993743371","pt":1580545905305,"mc":[{"id":"1.168096552","rc":[{"batb":[[1,22,12.8]],"ltp":21.0,"tv":198.69,"id":24608298}]}]}
{"op":"mcm","clk":"993743689","pt":1580545909506,"mc":[{"id":"1.168096552","rc":[{"batb":[[1,23,8.8],[2,22,12.8]],"ltp":21.0,"tv":198.69,"id":24608298}]}]}
{"op":"mcm","clk":"993743988","pt":1580545913347,"mc":[{"id":"1.168096552","rc":[{"trd":[[4.6,741.22]],"batl":[[0,4.6,3.61]],"ltp":4.6,"tv":3743.53,"id":21580749}],"tv":16035.12}]}
{"op":"mcm","clk":"993744452","pt":1580545919314,"mc":[{"id":"1.168096552","rc":[{"trd":[[4.5,473.24]],"batb":[[0,4.5,28.18]],"ltp":4.5,"tv":3763.53,"id":21580749}],"tv":16055.12}]}
{"op":"mcm","clk":"993746427","pt":1580545942460,"mc":[{"id":"1.168096552","rc":[{"trd":[[4.6,748.44]],"batb":[[0,4.6,6.83],[1,4.5,28.18],[2,4.4,9.98]],"batl":[[0,4.7,16.44],[1,4.8,12.06],[2,4.9,68.91]],"ltp":4.6,"tv":3770.75,"id":21580749}],"tv":16062.34}]}
{"op":"mcm","clk":"993747126","pt":1580545949481,"mc":[{"id":"1.168096552","rc":[{"trd":[[4.5,479.58],[4.6,762.1]],"batb":[[0,4.5,25.01],[1,4.4,16.61],[2,4.3,27.43]],"ltp":4.5,"tv":3790.75,"id":21580749}],"tv":16082.34}]}
{"op":"mcm","clk":"993747431","pt":1580545952488,"mc":[{"id":"1.168096552","rc":[{"trd":[[4.7,1234.53]],"batl":[[0,4.7,7.9]],"ltp":4.7,"tv":3807.83,"id":21580749}],"tv":16099.42}]}
{"op":"mcm","clk":"993747693","pt":1580545955482,"mc":[{"id":"1.168096552","rc":[{"batb":[[1,4.4,9.98]],"ltp":4.7,"tv":3807.83,"id":21580749}]}]}
{"op":"mcm","clk":"993748915","pt":1580545968487,"mc":[{"id":"1.168096552","rc":[{"batl":[[0,3.05,18.37]],"ltp":3.05,"tv":3943.8,"id":18286408},{"trd":[[14.5,83.74]],"batb":[[0,14.5,6.07],[1,14,2.26],[2,13.5,2]],"batl":[[0,15,9.8],[1,15.5,5],[2,17,1.76]],"ltp":14.5,"tv":557.79,"id":26640937}],"tv":16103.86}]}
{"op":"mcm","clk":"993749290","pt":1580545972408,"mc":[{"id":"1.168096552","rc":[{"batb":[[0,23,8.8],[1,22,12.8],[2,21,2]],"ltp":21.0,"tv":198.69,"id":24608298}]}]}
{"op":"mcm","clk":"993749468","pt":1580545974519,"mc":[{"id":"1.168096552","rc":[{"batb":[[1,21,2],[2,20,3.46]],"ltp":21.0,"tv":198.69,"id":24608298}]}]}
{"op":"mcm","clk":"993749805","pt":1580545978498,"mc":[{"id":"1.168096552","rc":[{"trd":[[2.98,506.05]],"batb":[[0,2.98,3.48],[1,2.96,6.23],[2,2.94,40.31]],"batl":[[0,3,9.2],[1,3.05,11],[2,3.1,63.9]],"ltp":2.98,"tv":7515.9,"id":52106},{"batb":[[1,21,6.37],[2,20,7.83]],"ltp":21.0,"tv":198.69,"id":24608298}],"tv":16123.6}]}
{"op":"mcm","clk":"993749888","pt":1580545979423,"mc":[{"id":"1.168096552","rc":[{"trd":[[4.5,499.58]],"batb":[[0,4.5,15.01]],"ltp":4.5,"tv":3827.83,"id":21580749}],"tv":16143.6}]}
{"op":"mcm","clk":"993750382","pt":1580545984520,"mc":[{"id":"1.168096552","rc":[{"trd":[[3.05,971.46]],"batl":[[0,3.05,9.12]],"ltp":3.05,"tv":3962.3,"id":18286408}],"tv":16162.1}]}
{"op":"mcm","clk":"993750742","pt":1580545988491,"mc":[{"id":"1.168096552","rc":[{"batl":[[0,3.05,6.12]],"ltp":3.05,"tv":3962.3,"id":18286408},{"batb":[[0,21,6.37],[1,20,7.83],[2,19.5,3.14]],"ltp":21.0,"tv":198.69,"id":24608298}]}]}
{"op":"mcm","clk":"993752311","pt":1580546008465,"mc":[{"id":"1.168096552","rc":[{"batb":[[0,22,2.15],[1,21,25.37],[2,20,7.83]],"ltp":21.0,"tv":198.69,"id":24608298}]}]}
{"op":"mcm","clk":"993753023","pt":1580546017469,"mc":[{"id":"1.168096552","rc":[{"batb":[[1,21,21],[2,20,3.46]],"ltp":21.0,"tv":198.69,"id":24608298}]}]}
{"op":"mcm","clk":"993753717","pt":1580546025946,"mc":[{"id":"1.168096552","rc":[{"batb":[[2,4.3,21.43]],"ltp":4.5,"tv":3827.83,"id":21580749}]}]}
{"op":"mcm","clk":"993753829","pt":1580546027439,"mc":[{"id":"1.168096552","rc":[{"batl":[[1,3.05,13]],"ltp":2.98,"tv":7515.9,"id":52106}]}]}
{"op":"mcm","clk":"993754909","pt":1580546040328,"mc":[{"id":"1.168096552","rc":[{"batl":[[0,3,59.2]],"ltp":2.98,"tv":7515.9,"id":52106}]}]}
{"op":"mcm","clk":"993755577","pt":1580546048510,"mc":[{"id":"1.168096552","rc":[{"trd":[[55,5.62],[60,3.08]],"batb":[[0,55,3.19],[1,50,3.01],[2,48,4.37]],"ltp":55.0,"tv":103.56,"id":27706761}],"tv":16166.1}]}
{"op":"mcm","clk":"993756223","pt":1580546056520,"mc":[{"id":"1.168096552","rc":[{"batb":[[0,14.5,8.07]],"batl":[[1,15.5,7]],"ltp":14.5,"tv":557.79,"id":26640937},{"batb":[[0,4.6,3.09],[1,4.5,15.01],[2,4.4,9.98]],"ltp":4.5,"tv":3827.83,"id":21580749},{"trd":[[22,11.05]],"batb":[[0,21,21],[1,20,3.46],[2,19.5,3.14]],"batl":[[0,22,2.85],[1,32,2.98],[2,34,2.21]],"ltp":22.0,"tv":202.99,"id":24608298}],"tv":16170.4}]}
{"op":"mcm","clk":"993756301","pt":1580546057444,"mc":[{"id":"1.168096552","rc":[{"batl":[[0,15,7.8]],"ltp":14.5,"tv":557.79,"id":26640937},{"batl":[[0,4.7,14.47]],"ltp":4.5,"tv":3827.83,"id":21580749},{"batb":[[1,48,4.71],[2,46,2.22]],"ltp":55.0,"tv":103.56,"id":27706761}]}]}
{"op":"mcm","clk":"993756395","pt":1580546058427,"mc":[{"id":"1.168096552","rc":[{"trd":[[3.05,983.7]],"batb":[[0,3.05,7.93],[1,3,91.5],[2,2.98,54.78]],"batl":[[0,3.1,113.38],[1,3.15,85.82],[2,3.2,26]],"ltp":3.05,"tv":3974.53,"id":18286408},{"batb":[[0,4.6,12.41]],"ltp":4.5,"tv":3827.83,"id":21580749},{"batb":[[1,2.96,20.71]],"ltp":2.98,"tv":7515.9,"id":52106}],"tv":16182.63}]}
{"op":"mcm","clk":"993756495","pt":1580546059521,"mc":[{"id":"1.168096552","rc":[{"batb":[[2,2.98,41]],"batl":[[0,3.1,112.38],[2,3.2,24]],"ltp":3.05,"tv":3974.53,"id":18286408},{"batb":[[0,14.5,11.03]],"ltp":14.5,"tv":557.79,"id":26640937},{"batb":[[0,4.6,9.32]],"batl":[[0,4.7,16.47]],"ltp":4.5,"tv":3827.83,"id":21580749},{"batb":[[0,60,1.49],[1,55,3.19],[2,48,4.71]],"ltp":55.0,"tv":103.56,"id":27706761},{"batb":[[1,2.96,16.48]],"ltp":2.98,"tv":7515.9,"id":52106},{"trd":[[22,16.75]],"batb":[[0,22,2.1],[1,21,21],[2,20,3.46]],"batl":[[0,30,2.18],[1,32,6.29]],"ltp":22.0,"tv":208.69,"id":24608298}],"tv":16188.33}]}
{"op":"mcm","clk":"993756623","pt":1580546061321,"mc":[{"id":"1.168096552","rc":[{"batb":[[2,48,7.25]],"ltp":55.0,"tv":103.56,"id":27706761},{"batl":[[1,32,2.91]],"ltp":22.0,"tv":208.69,"id":24608298}]}]}
{"op":"mcm","clk":"993756764","pt":1580546062449,"mc":[{"id":"1.168096552","rc":[{"batl":[[0,30,2.71]],"ltp":22.0,"tv":208.69,"id":24608298}]}]}
{"op":"mcm","clk":"993756839","pt":1580546063328,"mc":[{"id":"1.168096552","rc":[{"batl":[[0,29,1.72],[1,30,2.66],[2,32,1.23]],"ltp":22.0,"tv":208.69,"id":24608298}]}]}
{"op":"mcm","clk":"993757086","pt":1580546066145,"mc":[{"id":"1.168096552","rc":[{"batb":[[1,55,2]],"ltp":55.0,"tv":103.56,"id":27706761}]}]}
{"op":"mcm","clk":"993758316","pt":1580546080322,"mc":[{"id":"1.168096552","rc":[{"batl":[[2,34,2.21]],"ltp":22.0,"tv":208.69,"id":24608298}]}]}
{"op":"mcm","clk":"993758473","pt":1580546082443,"mc":[{"id":"1.168096552","rc":[{"batl":[[0,4.7,26.47]],"ltp":4.5,"tv":3827.83,"id":21580749}]}]}
{"op":"mcm","clk":"993759051","pt":1580546089245,"mc":[{"id":"1.168096552","rc":[{"trd":[[14.5,87.74]],"batb":[[0,14.5,9.03]],"ltp":14.5,"tv":561.79,"id":26640937}],"tv":16192.33}]}
{"op":"mcm","clk":"993759147","pt":1580546090427,"mc":[{"id":"1.168096552","rc":[{"trd":[[14.5,105.8]],"batb":[[0,13.5,5.68],[1,13,8.83],[2,12.5,1.87]],"batl":[[0,14.5,2.98],[1,15,9.8],[2,15.5,7]],"ltp":14.5,"tv":579.85,"id":26640937}],"tv":16210.39}]}
{"op":"mcm","clk":"993759229","pt":1580546091459,"mc":[{"id":"1.168096552","rc":[{"batb":[[0,13,5.7],[1,12.5,1.87],[2,11,23.86]],"ltp":14.5,"tv":579.85,"id":26640937}]}]}
{"op":"mcm","clk":"993759252","pt":1580546091869,"mc":[{"id":"1.168096552","rc":[{"batb":[[0,13.5,2.28],[1,13,5.7],[2,12.5,1.87]],"batl":[[0,14.5,4.98]],"ltp":14.5,"tv":579.85,"id":26640937}]}]}
{"op":"mcm","clk":"993759601","pt":1580546096354,"mc":[{"id":"1.168096552","rc":[{"batb":[[2,50,2.34]],"ltp":55.0,"tv":103.56,"id":27706761}]}]}
{"op":"mcm","clk":"993760268","pt":1580546104499,"mc":[{"id":"1.168096552","rc":[{"batl":[[0,28,2.04],[1,29,1.68],[2,30,2.66]],"ltp":22.0,"tv":208.69,"id":24608298}]}]}
{"op":"mcm","clk":"993760328","pt":1580546105183,"mc":[{"id":"1.168096552","rc":[{"trd":[[4.7,1254.95]],"batl":[[0,4.7,16.26]],"ltp":4.7,"tv":3848.25,"id":21580749}],"tv":16230.81}]}
{"op":"mcm","clk":"993761698","pt":1580546120500,"mc":[{"id":"1.168096552","rc":[{"trd":[[13.5,31.32]],"batb":[[0,13,5.7],[1,12.5,1.87],[2,10.5,6.77]],"batl":[[0,13.5,5.76],[1,14.5,4.98],[2,15,9.8]],"ltp":13.5,"tv":584.41,"id":26640937},{"batl":[[0,27,2.15],[1,28,3.41],[2,29,1.68]],"ltp":22.0,"tv":208.69,"id":24608298}],"tv":16235.37}]}
{"op":"mcm","clk":"993761781","pt":1580546121477,"mc":[{"id":"1.168096552","rc":[{"batb":[[0,3.05,13.93]],"ltp":3.05,"tv":3974.53,"id":18286408},{"batb":[[0,13,7.7]],"batl":[[1,14,2.11],[2,14.5,4.98]],"ltp":13.5,"tv":584.41,"id":26640937},{"batb":[[0,4.6,12.32]],"batl":[[0,4.7,14.26]],"ltp":4.7,"tv":3848.25,"id":21580749},{"batb":[[1,2.96,19.48]],"ltp":2.98,"tv":7515.9,"id":52106}]}]}
{"op":"mcm","clk":"993761927","pt":1580546123436,"mc":[{"id":"1.168096552","rc":[{"batl":[[0,3.1,97.54]],"ltp":3.05,"tv":3974.53,"id":18286408}]}]}
{"op":"mcm","clk":"993762060","pt":1580546125405,"mc":[{"id":"1.168096552","rc":[{"batb":[[0,22,18.67]],"ltp":22.0,"tv":208.69,"id":24608298}]}]}
{"op":"mcm","clk":"993762408","pt":1580546129412,"mc":[{"id":"1.168096552","rc":[{"batl":[[0,26,1.72],[1,27,2.11],[2,28,3.41]],"ltp":22.0,"tv":208.69,"id":24608298}]}]}
{"op":"mcm","clk":"993762491","pt":1580546130448,"mc":[{"id":"1.168096552","rc":[{"batl":[[0,3.1,95.54]],"ltp":3.05,"tv":3974.53,"id":18286408}]}]}
{"op":"mcm","clk":"993762661","pt":1580546132509,"mc":[{"id":"1.168096552","rc":[{"trd":[[3.05,1007.7]],"batb":[[0,3.05,1.93],[2,2.98,48.05]],"ltp":3.05,"tv":3998.54,"id":18286408},{"trd":[[4.6,782.09]],"batb":[[0,4.6,2.32]],"ltp":4.6,"tv":3868.24,"id":21580749}],"tv":16279.37}]}
{"op":"mcm","clk":"993762698","pt":1580546132923,"mc":[{"id":"1.168096552","rc":[{"batb":[[0,3.05,5]],"ltp":3.05,"tv":3998.54,"id":18286408},{"batl":[[0,4.7,16.26]],"ltp":4.6,"tv":3868.24,"id":21580749}]}]}
{"op":"mcm","clk":"993762907","pt":1580546135457,"mc":[{"id":"1.168096552","rc":[{"batb":[[2,2.98,41]],"ltp":3.05,"tv":3998.54,"id":18286408},{"batb":[[0,13,8.93]],"ltp":13.5,"tv":584.41,"id":26640937}]}]}
{"op":"mcm","clk":"993763315","pt":1580546140310,"mc":[{"id":"1.168096552","rc":[{"batl":[[2,28,2]],"ltp":22.0,"tv":208.69,"id":24608298}]}]}
{"op":"mcm","clk":"993763393","pt":1580546141233,"mc":[{"id":"1.168096552","rc":[{"trd":[[3.05,1017.7]],"batb":[[0,3.05,4]],"ltp":3.05,"tv":4008.54,"id":18286408}],"tv":16289.37}]}
{"op":"mcm","clk":"993763646","pt":1580546144434,"mc":[{"id":"1.168096552","rc":[{"batb":[[0,22,2.1]],"ltp":22.0,"tv":208.69,"id":24608298}]}]}
{"op":"mcm","clk":"993763682","pt":1580546144956,"mc":[{"id":"1.168096552","rc":[{"batb":[[2,10.5,9.17]],"ltp":13.5,"tv":584.41,"id":26640937}]}]}
{"op":"mcm","clk":"993764019","pt":1580546149442,"mc":[{"id":"1.168096552","rc":[{"trd":[[3.05,1025.7]],"batb":[[0,3,91.5],[1,2.98,41],[2,2.96,33]],"ltp":3.05,"tv":4016.54,"id":18286408},{"batl":[[1,3.05,11]],"ltp":2.98,"tv":7515.9,"id":52106}],"tv":16297.37}]}
{"op":"mcm","clk":"993764106","pt":1580546150421,"mc":[{"id":"1.168096552","rc":[{"batb":[[0,3.05,4],[1,3,91.5],[2,2.98,38]],"ltp":3.05,"tv":4016.54,"id":18286408},{"batl":[[1,3.05,9]],"ltp":2.98,"tv":7515.9,"id":52106}]}]}
{"op":"mcm","clk":"993764695","pt":1580546157465,"mc":[{"id":"1.168096552","rc":[{"batb":[[2,10.5,11.56]],"ltp":13.5,"tv":584.41,"id":26640937},{"trd":[[4.6,793.27]],"batb":[[0,4.5,15.01],[1,4.4,9.98],[2,4.3,21.43]],"batl":[[0,4.6,4.41],[1,4.7,16.26],[2,4.8,12.06]],"ltp":4.6,"tv":3879.42,"id":21580749},{"batl":[[0,25,2.04],[1,26,1.68],[2,27,2.11]],"ltp":22.0,"tv":208.69,"id":24608298}],"tv":16308.55}]}
{"op":"mcm","clk":"993764779","pt":1580546158444,"mc":[{"id":"1.168096552","rc":[{"trd":[[3.05,1031.7]],"batb":[[0,3.05,31.22]],"ltp":3.05,"tv":4022.54,"id":18286408},{"batb":[[2,10.5,13.95]],"ltp":13.5,"tv":584.41,"id":26640937},{"batb":[[0,2.98,37.41]],"ltp":2.98,"tv":7515.9,"id":52106}],"tv":16314.55}]}
{"op":"mcm","clk":"993764879","pt":1580546159474,"mc":[{"id":"1.168096552","rc":[{"batb":[[0,3.05,34.22]],"batl":[[0,3.1,98.54]],"ltp":3.05,"tv":4022.54,"id":18286408},{"trd":[[13.5,42.85]],"batb":[[0,13.5,3.38],[1,13,8.93],[2,12.5,1.87]],"batl":[[0,14.5,4.98],[1,15,9.8],[2,15.5,5]],"ltp":13.5,"tv":595.93,"id":26640937},{"trd":[[4.6,802.09]],"batb":[[0,4.6,18.63],[1,4.5,15.01],[2,4.4,9.98]],"batl":[[0,4.7,14.26],[1,4.8,12.06],[2,4.9,68.91]],"ltp":4.6,"tv":3888.25,"id":21580749},{"batb":[[0,2.98,34.41]],"ltp":2.98,"tv":7515.9,"id":52106},{"batb":[[0,22,6.29]],"ltp":22.0,"tv":208.69,"id":24608298}],"tv":16334.89}]}
{"op":"mcm","clk":"993765166","pt":1580546162479,"mc":[{"id":"1.168096552","rc":[{"batl":[[0,14,2],[1,14.5,4.98],[2,15,9.8]],"ltp":13.5,"tv":595.93,"id":26640937},{"batl":[[1,27,2.11],[2,40,5.13]],"ltp":22.0,"tv":208.69,"id":24608298}]}]}
{"op":"mcm","clk":"993766081","pt":1580546172476,"mc":[{"id":"1.168096552","rc":[{"batl":[[1,4.8,3.51]],"ltp":4.6,"tv":3888.25,"id":21580749}]}]}
{"op":"mcm","clk":"993766150","pt":1580546173363,"mc":[{"id":"1.168096552","rc":[{"trd":[[4.7,1259.03]],"batl":[[0,4.7,12.22]],"ltp":4.7,"tv":3892.33,"id":21580749}],"tv":16338.97}]}
{"op":"mcm","clk":"993766293","pt":1580546175172,"mc":[{"id":"1.168096552","rc":[{"trd":[[4.6,822.1]],"batb":[[0,4.6,8.63]],"batl":[[0,4.7,14.22]],"ltp":4.6,"tv":3912.33,"id":21580749}],"tv":16358.98}]}
{"op":"mcm","clk":"993767811","pt":1580546194304,"mc":[{"id":"1.168096552","rc":[{"trd":[[3.05,1039.92]],"batb":[[0,3.05,30.11]],"ltp":3.05,"tv":4030.76,"id":18286408}],"tv":16367.2}]}
{"op":"mcm","clk":"993768042","pt":1580546197428,"mc":[{"id":"1.168096552","rc":[{"trd":[[4.6,839.34]],"batb":[[0,4.5,15.01],[1,4.4,9.98],[2,4.3,21.43]],"batl":[[0,4.6,1.38],[1,4.7,14.22],[2,4.8,3.51]],"ltp":4.6,"tv":3929.57,"id":21580749},{"batb":[[0,22,7.04]],"ltp":22.0,"tv":208.69,"id":24608298}],"tv":16384.44}]}
{"op":"mcm","clk":"993768072","pt":1580546197796,"mc":[{"id":"1.168096552","rc":[{"trd":[[4.6,842.1]],"batb":[[0,4.6,5.11],[1,4.5,15.01],[2,4.4,15.08]],"batl":[[0,4.7,12],[1,4.8,3.51],[2,4.9,68.91]],"ltp":4.6,"tv":3932.33,"id":21580749},{"batb":[[1,2.96,30.82]],"ltp":2.98,"tv":7515.9,"id":52106}],"tv":16387.2}]}
{"op":"mcm","clk":"993768202","pt":1580546199410,"mc":[{"id":"1.168096552","rc":[{"batb":[[1,2.96,19.48]],"ltp":2.98,"tv":7515.9,"id":52106}]}]}
{"op":"mcm","clk":"993768497","pt":1580546202518,"mc":[{"id":"1.168096552","rc":[{"batb":[[2,2.94,50.45]],"ltp":2.98,"tv":7515.9,"id":52106}]}]}
{"op":"mcm","clk":"993769010","pt":1580546208124,"mc":[{"id":"1.168096552","rc":[{"trd":[[3.1,859.07]],"batl":[[0,3.1,94.41]],"ltp":3.1,"tv":4039.02,"id":18286408},{"trd":[[4.7,1279.59]],"batb":[[0,4.6,8.11]],"batl":[[0,4.7,1.72]],"ltp":4.7,"tv":3952.89,"id":21580749}],"tv":16416.03}]}
{"op":"mcm","clk":"993769189","pt":1580546210149,"mc":[{"id":"1.168096552","rc":[{"batb":[[0,3.05,27.11]],"ltp":3.1,"tv":4039.02,"id":18286408},{"trd":[[25,0.08]],"batl":[[0,26,2],[1,40,5.13],[2,48,1]],"ltp":25.0,"tv":208.78,"id":24608298}],"tv":16416.11}]}
{"op":"mcm","clk":"993769816","pt":1580546216459,"mc":[{"id":"1.168096552","rc":[{"batb":[[0,22,7.09]],"ltp":25.0,"tv":208.78,"id":24608298}]}]}
{"op":"mcm","clk":"993771406","pt":1580546235513,"mc":[{"id":"1.168096552","rc":[{"trd":[[4.6,858.32]],"batb":[[0,4.5,15.01],[1,4.4,15.08],[2,4.3,41.43]],"batl":[[0,4.6,1.89],[1,4.7,1.72],[2,4.8,3.51]],"ltp":4.6,"tv":3969.11,"id":21580749}],"tv":16432.33}]}
{"op":"mcm","clk":"993771485","pt":1580546236504,"mc":[{"id":"1.168096552","rc":[{"batb":[[0,3.05,31.11]],"ltp":3.1,"tv":4039.02,"id":18286408},{"batb":[[0,4.5,13.01],[1,4.4,13.08]],"ltp":4.6,"tv":3969.11,"id":21580749},{"batb":[[1,2.96,30.82]],"ltp":2.98,"tv":7515.9,"id":52106}]}]}
{"op":"mcm","clk":"993771889","pt":1580546241378,"mc":[{"id":"1.168096552","rc":[{"batl":[[0,4.6,11.89]],"ltp":4.6,"tv":3969.11,"id":21580749}]}]}
{"op":"mcm","clk":"993771949","pt":1580546242062,"mc":[{"id":"1.168096552","rc":[{"batb":[[1,4.4,7.98]],"ltp":4.6,"tv":3969.11,"id":21580749}]}]}
{"op":"mcm","clk":"993783200","pt":1580546259389,"mc":[{"id":"1.168096552","rc":[{"trd":[[4.5,519.58]],"batb":[[0,4.5,5.01]],"ltp":4.5,"tv":3989.11,"id":21580749},{"batb":[[0,2.98,38.41]],"ltp":2.98,"tv":7515.9,"id":52106}],"tv":16452.33}]}
{"op":"mcm","clk":"993784157","pt":1580546264306,"mc":[{"id":"1.168096552","rc":[{"batb":[[0,3.05,27.11]],"ltp":3.1,"tv":4039.02,"id":18286408},{"batl":[[0,4.6,13.89]],"ltp":4.5,"tv":3989.11,"id":21580749},{"batb":[[0,2.98,34.41]],"ltp":2.98,"tv":7515.9,"id":52106},{"batl":[[0,38,2.93],[1,40,2]],"ltp":25.0,"tv":208.78,"id":24608298}]}]}
{"op":"mcm","clk":"993784287","pt":1580546265507,"mc":[{"id":"1.168096552","rc":[{"batl":[[0,36,2.86],[1,38,2.37],[2,40,2]],"ltp":25.0,"tv":208.78,"id":24608298}]}]}
{"op":"mcm","clk":"993784369","pt":1580546266487,"mc":[{"id":"1.168096552","rc":[{"trd":[[4.5,533.6]],"batb":[[0,4.4,7.98],[1,4.3,41.43],[2,4.2,13.79]],"batl":[[0,4.5,2.99],[1,4.6,13.89],[2,4.7,1.72]],"ltp":4.5,"tv":4003.14,"id":21580749}],"tv":16466.35}]}
{"op":"mcm","clk":"993784415","pt":1580546267011,"mc":[{"id":"1.168096552","rc":[{"trd":[[4.5,539.58]],"batb":[[1,4.3,46.09]],"batl":[[0,4.6,13.89],[1,4.7,1.72],[2,4.8,3.51]],"ltp":4.5,"tv":4009.12,"id":21580749},{"batb":[[1,2.96,32.82]],"ltp":2.98,"tv":7515.9,"id":52106},{"batl":[[0,38,2.93],[1,40,2],[2,48,1]],"ltp":25.0,"tv":208.78,"id":24608298}],"tv":16472.33}]}
{"op":"mcm","clk":"993784543","pt":1580546268515,"mc":[{"id":"1.168096552","rc":[{"batb":[[0,4.5,2],[1,4.4,7.98],[2,4.3,43.43]],"ltp":4.5,"tv":4009.12,"id":21580749}]}]}
{"op":"mcm","clk":"993785005","pt":1580546274113,"mc":[{"id":"1.168096552","rc":[{"batl":[[0,4.6,23.89]],"ltp":4.5,"tv":4009.12,"id":21580749},{"batl":[[0,38,2.84]],"ltp":25.0,"tv":208.78,"id":24608298}]}]}
{"op":"mcm","clk":"993785276","pt":1580546276505,"mc":[{"id":"1.168096552","rc":[{"trd":[[4.5,543.58]],"batb":[[0,4.4,7.98],[1,4.3,43.43],[2,4.2,13.79]],"batl":[[0,4.5,8],[1,4.6,23.89],[2,4.7,1.72]],"ltp":4.5,"tv":4013.12,"id":21580749}],"tv":16476.33}]}
{"op":"mcm","clk":"993785636","pt":1580546279437,"mc":[{"id":"1.168096552","rc":[{"trd":[[4.5,559.58],[4.6,863.2]],"batl":[[0,4.6,21.45],[1,4.7,1.72],[2,4.8,3.51]],"ltp":4.6,"tv":4034.0,"id":21580749}],"tv":16497.21}]}
{"op":"mcm","clk":"993785836","pt":1580546281326,"mc":[{"id":"1.168096552","rc":[{"batb":[[0,23,16.6],[1,22,6.34],[2,21,21]],"ltp":25.0,"tv":208.78,"id":24608298}]}]}
{"op":"mcm","clk":"993785957","pt":1580546282436,"mc":[{"id":"1.168096552","rc":[{"batb":[[0,24,2],[1,23,16.6],[2,22,6.34]],"ltp":25.0,"tv":208.78,"id":24608298}]}]}
{"op":"mcm","clk":"993787335","pt":1580546297366,"mc":[{"id":"1.168096552","rc":[{"batl":[[0,38,2.4]],"ltp":25.0,"tv":208.78,"id":24608298}]}]}
{"op":"mcm","clk":"993787632","pt":1580546300962,"mc":[{"id":"1.168096552","rc":[{"batb":[[0,23,2.86],[1,22,6.34],[2,21,19]],"ltp":25.0,"tv":208.78,"id":24608298}]}]}
{"op":"mcm","clk":"993787828","pt":1580546303151,"mc":[{"id":"1.168096552","rc":[{"batb":[[0,25,2.12],[1,24,19],[2,23,2.86]],"ltp":25.0,"tv":208.78,"id":24608298}]}]}
{"op":"mcm","clk":"993788391","pt":1580546309458,"mc":[{"id":"1.168096552","rc":[{"batb":[[1,4.3,46.73]],"ltp":4.6,"tv":4034.0,"id":21580749}]}]}
{"op":"mcm","clk":"993788926","pt":1580546315352,"mc":[{"id":"1.168096552","rc":[{"batb":[[1,50,4.34],[2,48,6.91]],"ltp":55.0,"tv":103.56,"id":27706761}]}]}
{"op":"mcm","clk":"993789099","pt":1580546317352,"mc":[{"id":"1.168096552","rc":[{"batb":[[0,3.05,32.11]],"batl":[[0,3.1,91.41]],"ltp":3.1,"tv":4039.02,"id":18286408},{"trd":[[4.4,91.27]],"batb":[[0,4.3,46.73],[1,4.2,17.79],[2,4.1,19.4]],"batl":[[0,4.4,5.35],[1,4.5,14],[2,4.6,21.45]],"ltp":4.4,"tv":4057.95,"id":21580749},{"batb":[[0,2.98,39.41]],"ltp":2.98,"tv":7515.9,"id":52106}],"tv":16521.16}]}
{"op":"mcm","clk":"993789197","pt":1580546318446,"mc":[{"id":"1.168096552","rc":[{"batl":[[0,3.1,93.41]],"ltp":3.1,"tv":4039.02,"id":18286408},{"trd":[[4.4,101.96]],"batb":[[0,4.4,4.2],[1,4.3,46.73],[2,4.2,15.79]],"batl":[[0,4.5,10],[1,4.6,21.45],[2,4.7,1.72]],"ltp":4.4,"tv":4068.63,"id":21580749},{"batb":[[2,48,4.72]],"ltp":55.0,"tv":103.56,"id":27706761},{"batb":[[0,2.98,34.41]],"ltp":2.98,"tv":7515.9,"id":52106}],"tv":16531.85}]}
{"op":"mcm","clk":"993789277","pt":1580546319271,"mc":[{"id":"1.168096552","rc":[{"batb":[[0,3.05,27.11]],"ltp":3.1,"tv":4039.02,"id":18286408},{"trd":[[4.5,579.58],[4.6,884.86]],"batl":[[0,4.6,13],[1,4.7,1.72],[2,4.8,1.51]],"ltp":4.6,"tv":4110.29,"id":21580749}],"tv":16573.51}]}
{"op":"mcm","clk":"993789470","pt":1580546321460,"mc":[{"id":"1.168096552","rc":[{"trd":[[3,987.3]],"batl":[[0,3,9.2]],"ltp":3.0,"tv":7615.9,"id":52106},{"batl":[[1,48,1],[2,75,1.68]],"ltp":25.0,"tv":208.78,"id":24608298}],"tv":16673.51}]}
{"op":"mcm","clk":"993789572","pt":1580546322495,"mc":[{"id":"1.168096552","rc":[{"batl":[[0,36,2.03],[1,48,1.13]],"ltp":25.0,"tv":208.78,"id":24608298}]}]}
{"op":"mcm","clk":"993789673","pt":1580546323480,"mc":[{"id":"1.168096552","rc":[{"batl":[[0,4.5,10],[1,4.6,13],[2,4.7,1.72]],"ltp":4.6,"tv":4110.29,"id":21580749}]}]}
{"op":"mcm","clk":"993789823","pt":1580546325350,"mc":[{"id":"1.168096552","rc":[{"batl":[[0,34,1.71],[1,36,2],[2,48,1.13]],"ltp":25.0,"tv":208.78,"id":24608298}]}]}
{"op":"mcm","clk":"993790767","pt":1580546338392,"mc":[{"id":"1.168096552","rc":[{"batb":[[0,25,16.7]],"ltp":25.0,"tv":208.78,"id":24608298}]}]}
{"op":"mcm","clk":"993790844","pt":1580546339478,"mc":[{"id":"1.168096552","rc":[{"trd":[[4.4,110.36]],"batb":[[0,4.3,46.73],[1,4.2,15.79],[2,4.1,17.38]],"batl":[[0,4.4,5.8],[1,4.5,10],[2,4.6,13]],"ltp":4.4,"tv":4118.69,"id":21580749},{"trd":[[2.98,550.05]],"batb":[[0,2.98,12.41]],"ltp":2.98,"tv":7659.91,"id":52106}],"tv":16725.91}]}
{"op":"mcm","clk":"993790904","pt":1580546340512,"mc":[{"id":"1.168096552","rc":[{"trd":[[3.05,1089.92]],"batb":[[0,3.05,2.11]],"batl":[[0,3.1,91.41]],"ltp":3.05,"tv":4089.03,"id":18286408},{"trd":[[4.4,114.36]],"batb":[[0,4.3,43.43],[1,4.2,20.87]],"batl":[[0,4.4,3.8],[1,4.5,14]],"ltp":4.4,"tv":4122.69,"id":21580749},{"trd":[[3,1005.7]],"batb":[[0,2.98,17.41]],"batl":[[0,3.05,6],[1,3.1,65.9],[2,3.15,11.96]],"ltp":3.0,"tv":7678.31,"id":52106}],"tv":16798.32}]}
{"op":"mcm","clk":"993790977","pt":1580546341393,"mc":[{"id":"1.168096552","rc":[{"trd":[[4.4,121.96]],"batb":[[0,4.4,2],[1,4.3,43.43],[2,4.2,20.87]],"batl":[[0,4.5,10],[1,4.6,13],[2,4.7,4]],"ltp":4.4,"tv":4130.29,"id":21580749},{"trd":[[2.98,565.79]],"batb":[[0,2.98,9.54]],"batl":[[0,3.05,8]],"ltp":2.98,"tv":7694.04,"id":52106}],"tv":16821.66}]}
{"op":"mcm","clk":"993791062","pt":1580546342375,"mc":[{"id":"1.168096552","rc":[{"batb":[[0,4.4,4]],"ltp":4.4,"tv":4130.29,"id":21580749}]}]}
{"op":"mcm","clk":"993791150","pt":1580546343515,"mc":[{"id":"1.168096552","rc":[{"batb":[[1,13,7.7]],"ltp":13.5,"tv":595.93,"id":26640937},{"trd":[[4.4,125.96]],"batb":[[0,4.4,2]],"ltp":4.4,"tv":4134.29,"id":21580749}],"tv":16825.66}]}
{"op":"mcm","clk":"993791222","pt":1580546344292,"mc":[{"id":"1.168096552","rc":[{"batb":[[0,4.4,4]],"ltp":4.4,"tv":4134.29,"id":21580749}]}]}
{"op":"mcm","clk":"993791380","pt":1580546346316,"mc":[{"id":"1.168096552","rc":[{"batl":[[2,4.7,5.51]],"ltp":4.4,"tv":4134.29,"id":21580749},{"batb":[[1,2.96,24.81]],"ltp":2.98,"tv":7694.04,"id":52106}]}]}
{"op":"mcm","clk":"993791572","pt":1580546349320,"mc":[{"id":"1.168096552","rc":[{"batl":[[0,3.1,93.41]],"ltp":3.05,"tv":4089.03,"id":18286408},{"batl":[[0,3.05,22]],"ltp":2.98,"tv":7694.04,"id":52106}]}]}
{"op":"mcm","clk":"993791701","pt":1580546351130,"mc":[{"id":"1.168096552","rc":[{"trd":[[4.5,582.94]],"batl":[[0,4.5,8.32]],"ltp":4.5,"tv":4137.65,"id":21580749}],"tv":16829.02}]}
{"op":"mcm","clk":"993792462","pt":1580546360502,"mc":[{"id":"1.168096552","rc":[{"trd":[[2.98,569.79]],"batb":[[0,2.98,7.54]],"ltp":2.98,"tv":7698.05,"id":52106}],"tv":16833.02}]}
{"op":"mcm","clk":"993792878","pt":1580546365420,"mc":[{"id":"1.168096552","rc":[{"trd":[[3.05,1093.93]],"batb":[[0,3,91.61],[1,2.98,38],[2,2.96,33]],"ltp":3.05,"tv":4093.03,"id":18286408},{"batl":[[0,4.5,18.32]],"ltp":4.5,"tv":4137.65,"id":21580749},{"batb":[[1,2.96,21.48]],"ltp":2.98,"tv":7698.05,"id":52106}],"tv":16837.02}]}
{"op":"mcm","clk":"993793468","pt":1580546372311,"mc":[{"id":"1.168096552","rc":[{"trd":[[4.5,603.82]],"batl":[[0,4.5,7.88]],"ltp":4.5,"tv":4158.53,"id":21580749}],"tv":16857.9}]}
{"op":"mcm","clk":"993793722","pt":1580546375058,"mc":[{"id":"1.168096552","rc":[{"batb":[[1,2.98,51.78]],"ltp":3.05,"tv":4093.03,"id":18286408},{"trd":[[4.5,619.58]],"batb":[[0,4.5,4.16],[1,4.4,4],[2,4.3,43.43]],"batl":[[0,4.6,10],[1,4.7,5.51],[2,4.8,1.51]],"ltp":4.5,"tv":4174.29,"id":21580749}],"tv":16873.66}]}
{"op":"mcm","clk":"993793832","pt":1580546376363,"mc":[{"id":"1.168096552","rc":[{"batb":[[0,4.5,43.36]],"ltp":4.5,"tv":4174.29,"id":21580749}]}]}
{"op":"mcm","clk":"993793901","pt":1580546377447,"mc":[{"id":"1.168096552","rc":[{"batb":[[0,25,2.12]],"ltp":25.0,"tv":208.78,"id":24608298}]}]}
{"op":"mcm","clk":"993794090","pt":1580546379520,"mc":[{"id":"1.168096552","rc":[{"batl":[[2,3.2,17]],"ltp":3.05,"tv":4093.03,"id":18286408}]}]}
{"op":"mcm","clk":"993796067","pt":1580546398156,"mc":[{"id":"1.168096552","rc":[{"batl":[[0,34,1.68]],"ltp":25.0,"tv":208.78,"id":24608298}]}]}
{"op":"mcm","clk":"993798492","pt":1580546427497,"mc":[{"id":"1.168096552","rc":[{"trd":[[4.5,639.58]],"batb":[[0,4.5,35.36]],"ltp":4.5,"tv":4194.29,"id":21580749}],"tv":16893.66}]}
{"op":"mcm","clk":"993798631","pt":1580546429222,"mc":[{"id":"1.168096552","rc":[{"batl":[[0,34,1.71]],"ltp":25.0,"tv":208.78,"id":24608298}]}]}
{"op":"mcm","clk":"993798744","pt":1580546430421,"mc":[{"id":"1.168096552","rc":[{"trd":[[4.6,888.86]],"batl":[[0,4.6,8]],"ltp":4.6,"tv":4198.29,"id":21580749}],"tv":16897.66}]}
{"op":"mcm","clk":"993798834","pt":1580546431319,"mc":[{"id":"1.168096552","rc":[{"batb":[[0,13.5,1.06]],"batl":[[0,14,4]],"ltp":13.5,"tv":595.93,"id":26640937},{"trd":[[4.6,904.86],[4.7,1283.59]],"batl":[[0,4.7,3.51],[1,4.8,1.51],[2,4.9,66.91]],"ltp":4.7,"tv":4218.29,"id":21580749},{"batb":[[0,2.98,2.54]],"ltp":2.98,"tv":7698.05,"id":52106}],"tv":16917.66}]}
{"op":"mcm","clk":"993799138","pt":1580546434451,"mc":[{"id":"1.168096552","rc":[{"batb":[[0,25,2.81],[2,23,2.11]],"ltp":25.0,"tv":208.78,"id":24608298}]}]}
{"op":"mcm","clk":"993799167","pt":1580546434712,"mc":[{"id":"1.168096552","rc":[{"batl":[[0,4.7,5.51]],"ltp":4.7,"tv":4218.29,"id":21580749},{"batb":[[0,24,19.69],[1,23,2.29],[2,22,4.19]],"ltp":25.0,"tv":208.78,"id":24608298}]}]}
{"op":"mcm","clk":"993799320","pt":1580546436447,"mc":[{"id":"1.168096552","rc":[{"batb":[[0,4.6,10.2],[1,4.5,35.36],[2,4.4,4]],"batl":[[1,4.8,14.15]],"ltp":4.7,"tv":4218.29,"id":21580749},{"batb":[[0,25,2.88],[1,24,19]],"ltp":25.0,"tv":208.78,"id":24608298}]}]}
{"op":"mcm","clk":"993799394","pt":1580546437239,"mc":[{"id":"1.168096552","rc":[{"batb":[[0,24,19.69],[1,22,4.19],[2,20,1.46]],"ltp":25.0,"tv":208.78,"id":24608298}]}]}
{"op":"mcm","clk":"993799493","pt":1580546438440,"mc":[{"id":"1.168096552","rc":[{"batb":[[1,22,12.74]],"ltp":25.0,"tv":208.78,"id":24608298}]}]}
{"op":"mcm","clk":"993801128","pt":1580546456485,"mc":[{"id":"1.168096552","marketDefinition":{"bspMarket":true,"turnInPlayEnabled":true,"persistenceEnabled":true,"marketBaseRate":5.0,"eventId":"29677422","eventTypeId":"7","numberOfWinners":1,"bettingType":"ODDS","marketType":"WIN","marketTime":"2020-02-01T12:40:00.000Z","suspendTime":"2020-02-01T12:40:00.000Z","bspReconciled":false,"complete":true,"inPlay":false,"crossMatching":true,"runnersVoidable":false,"numberOfActiveRunners":6,"betDelay":0,"status":"OPEN","runners":[{"adjustmentFactor":29.13,"status":"ACTIVE","sortPriority":1,"id":52106,"name":"Palladium"},{"adjustmentFactor":33.3,"status":"ACTIVE","sortPriority":2,"id":18286408,"name":"Flic Ou Voyou"},{"adjustmentFactor":16.07,"status":"ACTIVE","sortPriority":3,"id":21580749,"name":"Golden Taipan"},{"adjustmentFactor":13.18,"status":"ACTIVE","sortPriority":4,"id":26640937,"name":"The Newest One"},{"adjustmentFactor":2.81,"status":"ACTIVE","sortPriority":5,"id":24608298,"name":"Vorashann"},{"adjustmentFactor":5.48,"status":"ACTIVE","sortPriority":6,"id":27706761,"name":"Kalakawa Enki"}],"regulators":["MR_INT"],"venue":"Sandown","countryCode":"GB","discountAllowed":true,"timezone":"Europe/London","openDate":"2020-02-01T12:40:00.000Z","version":3143797494,"name":"2m Nov Hrd","eventName":"Sand  1st Feb"}}]}
{"op":"mcm","clk":"993801391","pt":1580546459456,"mc":[{"id":"1.168096552","rc":[{"batb":[[0,22,13.42],[1,20,1.46],[2,19.5,4.48]],"ltp":25.0,"tv":208.78,"id":24608298}]}]}
{"op":"mcm","clk":"993801439","pt":1580546460079,"mc":[{"id":"1.168096552","rc":[{"batb":[[0,23,3.01],[1,22,12.74],[2,20,1.46]],"ltp":25.0,"tv":208.78,"id":24608298}]}]}
{"op":"mcm","clk":"993802264","pt":1580546469489,"mc":[{"id":"1.168096552","rc":[{"batb":[[0,23,24.01]],"ltp":25.0,"tv":208.78,"id":24608298}]}]}
{"op":"mcm","clk":"993802563","pt":1580546472485,"mc":[{"id":"1.168096552","rc":[{"batb":[[1,2.98,38]],"ltp":3.05,"tv":4093.03,"id":18286408},{"trd":[[4.7,1303.6]],"batl":[[0,4.8,14.15],[1,4.9,66.91],[2,5,17.39]],"ltp":4.7,"tv":4238.3,"id":21580749},{"batb":[[1,22,4.19]],"ltp":25.0,"tv":208.78,"id":24608298}],"tv":16937.66}]}
{"op":"mcm","clk":"993802667","pt":1580546473379,"mc":[{"id":"1.168096552","rc":[{"trd":[[4.6,924.86]],"batb":[[0,4.5,35.56],[1,4.4,4],[2,4.3,43.43]],"ltp":4.6,"tv":4258.3,"id":21580749}],"tv":16957.66}]}
{"op":"mcm","clk":"993802753","pt":1580546474163,"mc":[{"id":"1.168096552","rc":[{"batb":[[1,2.98,51.78]],"ltp":3.05,"tv":4093.03,"id":18286408},{"batb":[[1,4.4,11.1]],"ltp":4.6,"tv":4258.3,"id":21580749}]}]}
{"op":"mcm","clk":"993802885","pt":1580546475358,"mc":[{"id":"1.168096552","rc":[{"batb":[[0,4.6,2.28],[1,4.5,35.36],[2,4.4,11.1]],"batl":[[0,4.7,2],[1,4.8,14.15],[2,4.9,66.91]],"ltp":4.6,"tv":4258.3,"id":21580749}]}]}
{"op":"mcm","clk":"993804856","pt":1580546495405,"mc":[{"id":"1.168096552","rc":[{"batl":[[0,4.7,5.08]],"ltp":4.6,"tv":4258.3,"id":21580749}]}]}
{"op":"mcm","clk":"993804955","pt":1580546496499,"mc":[{"id":"1.168096552","rc":[{"batb":[[0,4.5,35.56],[1,4.4,4],[2,4.3,43.43]],"ltp":4.6,"tv":4258.3,"id":21580749}]}]}
{"op":"mcm","clk":"993806084","pt":1580546508420,"mc":[{"id":"1.168096552","rc":[{"trd":[[4.6,925.26]],"batb":[[0,4.5,35.36]],"batl":[[0,4.6,9.8],[1,4.7,5.08],[2,4.8,14.15]],"ltp":4.6,"tv":4258.7,"id":21580749}],"tv":16958.06}]}
{"op":"mcm","clk":"993806175","pt":1580546509515,"mc":[{"id":"1.168096552","rc":[{"batb":[[2,2.94,37.1]],"ltp":2.98,"tv":7698.05,"id":52106}]}]}
{"op":"mcm","clk":"993809055","pt":1580546539085,"mc":[{"id":"1.168096552","rc":[{"batl":[[0,3,4.85],[1,3.05,22],[2,3.1,65.9]],"ltp":2.98,"tv":7698.05,"id":52106}]}]}
{"op":"mcm","clk":"993809186","pt":1580546540456,"mc":[{"id":"1.168096552","rc":[{"batl":[[0,3.05,22],[1,3.1,65.9],[2,3.15,11.96]],"ltp":2.98,"tv":7698.05,"id":52106}]}]}
{"op":"mcm","clk":"993812237","pt":1580546573427,"mc":[{"id":"1.168096552","rc":[{"trd":[[4.6,944.86]],"batb":[[0,4.5,35.58]],"batl":[[0,4.7,5.08],[1,4.8,14.15],[2,4.9,66.91]],"ltp":4.6,"tv":4278.3,"id":21580749}],"tv":16977.66}]}
{"op":"mcm","clk":"993812312","pt":1580546574203,"mc":[{"id":"1.168096552","rc":[{"trd":[[4.6,945.3]],"batb":[[0,4.5,35.36]],"ltp":4.6,"tv":4278.74,"id":21580749}],"tv":16978.1}]}
{"op":"mcm","clk":"993814173","pt":1580546594105,"mc":[{"id":"1.168096552","rc":[{"batb":[[0,4.6,2.29],[1,4.5,35.36],[2,4.4,4]],"ltp":4.6,"tv":4278.74,"id":21580749}]}]}
{"op":"mcm","clk":"993814379","pt":1580546596434,"mc":[{"id":"1.168096552","rc":[{"batl":[[0,3.05,25]],"ltp":2.98,"tv":7698.05,"id":52106}]}]}
{"op":"mcm","clk":"993814556","pt":1580546598505,"mc":[{"id":"1.168096552","rc":[{"batl":[[0,65,5],[1,85,1],[2,100,2]],"ltp":55.0,"tv":103.56,"id":27706761}]}]}
{"op":"mcm","clk":"993814623","pt":1580546599430,"mc":[{"id":"1.168096552","rc":[{"batl":[[0,4.7,2]],"ltp":4.6,"tv":4278.74,"id":21580749},{"batl":[[0,65,7]],"ltp":55.0,"tv":103.56,"id":27706761}]}]}
{"op":"mcm","clk":"993814925","pt":1580546603331,"mc":[{"id":"1.168096552","rc":[{"batl":[[0,4.7,12]],"ltp":4.6,"tv":4278.74,"id":21580749}]}]}
{"op":"mcm","clk":"993815228","pt":1580546606429,"mc":[{"id":"1.168096552","rc":[{"batb":[[0,24,15.88],[1,23,23.32],[2,22,4.19]],"ltp":25.0,"tv":208.78,"id":24608298}]}]}
{"op":"mcm","clk":"993815317","pt":1580546607407,"mc":[{"id":"1.168096552","rc":[{"batb":[[1,23,21]],"ltp":25.0,"tv":208.78,"id":24608298}]}]}
{"op":"mcm","clk":"993816736","pt":1580546624368,"mc":[{"id":"1.168096552","rc":[{"batb":[[0,25,2.93],[1,24,15.19],[2,23,21]],"ltp":25.0,"tv":208.78,"id":24608298}]}]}
{"op":"mcm","clk":"993816838","pt":1580546625459,"mc":[{"id":"1.168096552","rc":[{"batb":[[0,24,15.88],[1,23,21],[2,22,4.19]],"ltp":25.0,"tv":208.78,"id":24608298}]}]}
{"op":"mcm","clk":"993816934","pt":1580546626446,"mc":[{"id":"1.168096552","rc":[{"trd":[[4.5,655],[4.6,949.88]],"batb":[[0,4.5,27.65],[1,4.4,4],[2,4.3,43.43]],"batl":[[0,4.7,15]],"ltp":4.5,"tv":4298.74,"id":21580749}],"tv":16998.1}]}
{"op":"mcm","clk":"993817095","pt":1580546628362,"mc":[{"id":"1.168096552","rc":[{"batl":[[0,4.6,10],[1,4.7,15],[2,4.8,14.15]],"ltp":4.5,"tv":4298.74,"id":21580749}]}]}
{"op":"mcm","clk":"993817178","pt":1580546629348,"mc":[{"id":"1.168096552","rc":[{"batl":[[0,14,2]],"ltp":13.5,"tv":595.93,"id":26640937},{"batb":[[0,2.98,7.8]],"ltp":2.98,"tv":7698.05,"id":52106}]}]}
{"op":"mcm","clk":"993817277","pt":1580546630485,"mc":[{"id":"1.168096552","rc":[{"trd":[[3,659.92],[3.05,1094.14]],"batb":[[0,3,76.61]],"ltp":3.0,"tv":4123.02,"id":18286408},{"batb":[[0,13.5,3.33]],"ltp":13.5,"tv":595.93,"id":26640937}],"tv":17028.1}]}
{"op":"mcm","clk":"993817486","pt":1580546632461,"mc":[{"id":"1.168096552","rc":[{"trd":[[3,669.92]],"batb":[[0,3,71.61]],"ltp":3.0,"tv":4133.02,"id":18286408}],"tv":17038.1}]}
{"op":"mcm","clk":"993818460","pt":1580546642495,"mc":[{"id":"1.168096552","rc":[{"trd":[[4.5,675]],"batb":[[0,4.5,17.65]],"ltp":4.5,"tv":4318.74,"id":21580749}],"tv":17058.1}]}
{"op":"mcm","clk":"993818662","pt":1580546644475,"mc":[{"id":"1.168096552","rc":[{"trd":[[4.5,695]],"batb":[[0,4.5,7.65]],"ltp":4.5,"tv":4338.74,"id":21580749}],"tv":17078.1}]}
{"op":"mcm","clk":"993818752","pt":1580546645462,"mc":[{"id":"1.168096552","rc":[{"batb":[[0,23,21.69],[1,22,4.19],[2,20,1.46]],"ltp":25.0,"tv":208.78,"id":24608298}]}]}
{"op":"mcm","clk":"993819623","pt":1580546654494,"mc":[{"id":"1.168096552","rc":[{"trd":[[3.1,959.41]],"batl":[[0,3.1,43.24]],"ltp":3.1,"tv":4233.36,"id":18286408},{"batb":[[0,24,2.76],[1,23,21],[2,22,4.19]],"ltp":25.0,"tv":208.78,"id":24608298}],"tv":17178.44}]}
{"op":"mcm","clk":"993819728","pt":1580546655482,"mc":[{"id":"1.168096552","rc":[{"batb":[[0,3,82.5]],"ltp":3.1,"tv":4233.36,"id":18286408},{"batb":[[0,23,21.69],[1,22,4.19],[2,20,1.46]],"ltp":25.0,"tv":208.78,"id":24608298}]}]}
{"op":"mcm","clk":"993820411","pt":1580546663476,"mc":[{"id":"1.168096552","rc":[{"trd":[[4.5,715]],"batb":[[0,4.4,4],[1,4.3,51.75],[2,4.2,13.79]],"ltp":4.5,"tv":4358.74,"id":21580749},{"batb":[[0,24,15.88],[1,23,21],[2,22,4.19]],"ltp":25.0,"tv":208.78,"id":24608298}],"tv":17198.44}]}
{"op":"mcm","clk":"993820947","pt":1580546669397,"mc":[{"id":"1.168096552","rc":[{"trd":[[3.1,969.63]],"batl":[[0,3.1,38.13]],"ltp":3.1,"tv":4243.58,"id":18286408}],"tv":17208.66}]}
{"op":"mcm","clk":"993821310","pt":1580546673211,"mc":[{"id":"1.168096552","rc":[{"trd":[[4.4,145.96]],"batb":[[0,4.4,2.18],[1,4.3,43.43],[2,4.2,20]],"batl":[[2,4.8,5.7]],"ltp":4.4,"tv":4378.74,"id":21580749}],"tv":17228.66}]}
{"op":"mcm","clk":"993821417","pt":1580546674513,"mc":[{"id":"1.168096552","rc":[{"batb":[[1,2.98,54.11]],"ltp":3.1,"tv":4243.58,"id":18286408},{"batb":[[0,4.4,4.18],[1,4.3,46.1]],"ltp":4.4,"tv":4378.74,"id":21580749},{"batb":[[0,25,2.87],[1,24,15.19],[2,23,21]],"ltp":25.0,"tv":208.78,"id":24608298}]}]}
{"op":"mcm","clk":"993821431","pt":1580546674719,"mc":[{"id":"1.168096552","rc":[{"batb":[[1,2.98,40.34]],"ltp":3.1,"tv":4243.58,"id":18286408},{"batb":[[0,24,15.88],[1,23,21],[2,22,4.19]],"ltp":25.0,"tv":208.78,"id":24608298}]}]}
{"op":"mcm","clk":"993822473","pt":1580546686458,"mc":[{"id":"1.168096552","rc":[{"batb":[[1,2.98,51.78]],"ltp":3.1,"tv":4243.58,"id":18286408}]}]}
{"op":"mcm","clk":"993823036","pt":1580546693442,"mc":[{"id":"1.168096552","rc":[{"trd":[[4.6,969.88]],"batl":[[0,4.6,8.7]],"ltp":4.6,"tv":4398.74,"id":21580749}],"tv":17248.66}]}
{"op":"mcm","clk":"993823648","pt":1580546701351,"mc":[{"id":"1.168096552","rc":[{"batl":[[0,4.6,18.7]],"ltp":4.6,"tv":4398.74,"id":21580749}]}]}
{"op":"mcm","clk":"993823808","pt":1580546703449,"mc":[{"id":"1.168096552","rc":[{"batb":[[0,4.4,24.18]],"ltp":4.6,"tv":4398.74,"id":21580749}]}]}
{"op":"mcm","clk":"993823968","pt":1580546705172,"mc":[{"id":"1.168096552","rc":[{"batb":[[0,4.5,12],[1,4.4,24.18],[2,4.3,46.1]],"ltp":4.6,"tv":4398.74,"id":21580749}]}]}
{"op":"mcm","clk":"993824418","pt":1580546710380,"mc":[{"id":"1.168096552","rc":[{"batb":[[0,4.5,17]],"ltp":4.6,"tv":4398.74,"id":21580749}]}]}
{"op":"mcm","clk":"993824600","pt":1580546712464,"mc":[{"id":"1.168096552","rc":[{"trd":[[4.5,735]],"batb":[[0,4.5,9]],"ltp":4.5,"tv":4418.74,"id":21580749}],"tv":17268.66}]}
{"op":"mcm","clk":"993825195","pt":1580546719388,"mc":[{"id":"1.168096552","rc":[{"batl":[[0,3.05,22]],"ltp":2.98,"tv":7698.05,"id":52106},{"batb":[[0,25,2.79],[1,24,15.19],[2,23,21]],"ltp":25.0,"tv":208.78,"id":24608298}]}]}
{"op":"mcm","clk":"993825302","pt":1580546720477,"mc":[{"id":"1.168096552","rc":[{"batb":[[0,13.5,4.61]],"batl":[[0,14.5,4.98],[1,15,9.8],[2,15.5,5]],"ltp":13.5,"tv":595.93,"id":26640937},{"batb":[[0,23,21.69],[1,22,4.19],[2,20,1.46]],"ltp":25.0,"tv":208.78,"id":24608298}]}]}
{"op":"mcm","clk":"993825483","pt":1580546722514,"mc":[{"id":"1.168096552","rc":[{"batb":[[1,22,12.54]],"ltp":25.0,"tv":208.78,"id":24608298}]}]}
{"op":"mcm","clk":"993826028","pt":1580546729320,"mc":[{"id":"1.168096552","rc":[{"batb":[[1,2.98,57.18]],"ltp":3.1,"tv":4243.58,"id":18286408},{"trd":[[4.5,752.99]],"batb":[[0,4.4,24.18],[1,4.3,52.45],[2,4.2,15.79]],"batl":[[0,4.5,16.34],[1,4.6,23.7],[2,4.7,17]],"ltp":4.5,"tv":4436.72,"id":21580749},{"batb":[[1,22,4.19]],"ltp":25.0,"tv":208.78,"id":24608298}],"tv":17286.65}]}
{"op":"mcm","clk":"993826204","pt":1580546731367,"mc":[{"id":"1.168096552","rc":[{"trd":[[4.5,753.27]],"batb":[[1,4.3,46.1]],"batl":[[0,4.5,16.2]],"ltp":4.5,"tv":4437.01,"id":21580749}],"tv":17286.93}]}
{"op":"mcm","clk":"993826289","pt":1580546732458,"mc":[{"id":"1.168096552","rc":[{"trd":[[4.5,753.55]],"batl":[[0,4.5,16.06]],"ltp":4.5,"tv":4437.29,"id":21580749}],"tv":17287.21}]}
{"op":"mcm","clk":"993826981","pt":1580546740483,"mc":[{"id":"1.168096552","rc":[{"batb":[[0,24,15.88],[1,23,21],[2,22,4.19]],"ltp":25.0,"tv":208.78,"id":24608298}]}]}
{"op":"mcm","clk":"993827217","pt":1580546743337,"mc":[{"id":"1.168096552","rc":[{"trd":[[3.1,979.85]],"batl":[[0,3.1,33.02]],"ltp":3.1,"tv":4253.8,"id":18286408},{"batb":[[0,4.4,4.18]],"ltp":4.5,"tv":4437.29,"id":21580749}],"tv":17297.43}]}
{"op":"mcm","clk":"993827359","pt":1580546745455,"mc":[{"id":"1.168096552","rc":[{"batb":[[0,4.4,29.51]],"ltp":4.5,"tv":4437.29,"id":21580749}]}]}
{"op":"mcm","clk":"993828021","pt":1580546753448,"mc":[{"id":"1.168096552","rc":[{"trd":[[4.5,773]],"batl":[[0,4.5,6.34]],"ltp":4.5,"tv":4456.74,"id":21580749}],"tv":17316.88}]}
{"op":"mcm","clk":"993828182","pt":1580546755445,"mc":[{"id":"1.168096552","rc":[{"batb":[[0,3,88.45]],"ltp":3.1,"tv":4253.8,"id":18286408}]}]}
{"op":"mcm","clk":"993828247","pt":1580546756173,"mc":[{"id":"1.168096552","rc":[{"trd":[[4.4,165.95]],"batb":[[0,4.4,21.51]],"ltp":4.4,"tv":4476.73,"id":21580749}],"tv":17336.87}]}
{"op":"mcm","clk":"993828348","pt":1580546757473,"mc":[{"id":"1.168096552","rc":[{"trd":[[4.5,785.68]],"batb":[[0,4.5,5.91],[1,4.4,21.51],[2,4.3,46.1]],"batl":[[0,4.6,18.7],[1,4.7,17],[2,4.8,5.7]],"ltp":4.5,"tv":4489.41,"id":21580749}],"tv":17349.55}]}
{"op":"mcm","clk":"993828436","pt":1580546758461,"mc":[{"id":"1.168096552","rc":[{"trd":[[4.4,174.13],[4.5,797.5]],"batb":[[0,4.4,17.42],[1,4.3,46.1],[2,4.2,15.79]],"ltp":4.4,"tv":4509.41,"id":21580749},{"batb":[[0,25,3.01],[1,24,15.19],[2,23,21]],"ltp":25.0,"tv":208.78,"id":24608298}],"tv":17369.55}]}
{"op":"mcm","clk":"993828531","pt":1580546759458,"mc":[{"id":"1.168096552","rc":[{"batb":[[1,4.3,48.32]],"ltp":4.4,"tv":4509.41,"id":21580749},{"batb":[[0,24,15.88],[1,23,21],[2,22,4.19]],"ltp":25.0,"tv":208.78,"id":24608298}]}]}
{"op":"mcm","clk":"993829427","pt":1580546769412,"mc":[{"id":"1.168096552","rc":[{"batb":[[0,4.5,2.04],[1,4.4,37.42],[2,4.3,48.32]],"batl":[[0,4.6,10]],"ltp":4.4,"tv":4509.41,"id":21580749},{"batb":[[0,25,2.73],[1,24,15.19],[2,23,21]],"ltp":25.0,"tv":208.78,"id":24608298}]}]}
{"op":"mcm","clk":"993829516","pt":1580546770495,"mc":[{"id":"1.168096552","rc":[{"batb":[[0,3,82.5]],"ltp":3.1,"tv":4253.8,"id":18286408},{"batb":[[0,4.5,2]],"ltp":4.4,"tv":4509.41,"id":21580749},{"batb":[[0,25,2.69]],"ltp":25.0,"tv":208.78,"id":24608298}]}]}
{"op":"mcm","clk":"993829599","pt":1580546771381,"mc":[{"id":"1.168096552","rc":[{"batb":[[0,2.98,2.54]],"ltp":2.98,"tv":7698.05,"id":52106},{"batb":[[0,24,15.88],[1,23,21],[2,22,4.19]],"ltp":25.0,"tv":208.78,"id":24608298}]}]}
{"op":"mcm","clk":"993829860","pt":1580546774389,"mc":[{"id":"1.168096552","rc":[{"batb":[[2,4.3,46.1]],"ltp":4.4,"tv":4509.41,"id":21580749}]}]}
{"op":"mcm","clk":"993829965","pt":1580546775478,"mc":[{"id":"1.168096552","rc":[{"batb":[[1,4.4,37.48]],"ltp":4.4,"tv":4509.41,"id":21580749}]}]}
{"op":"mcm","clk":"993830445","pt":1580546781384,"mc":[{"id":"1.168096552","rc":[{"batb":[[0,4.5,12]],"ltp":4.4,"tv":4509.41,"id":21580749}]}]}
{"op":"mcm","clk":"993831233","pt":1580546789305,"mc":[{"id":"1.168096552","rc":[{"batb":[[2,4.3,66.1]],"ltp":4.4,"tv":4509.41,"id":21580749}]}]}
{"op":"mcm","clk":"993831777","pt":1580546795430,"mc":[{"id":"1.168096552","rc":[{"batb":[[0,3.05,5.65],[1,3,82.5],[2,2.98,38]],"ltp":3.1,"tv":4253.8,"id":18286408},{"batb":[[1,4.4,17.48]],"ltp":4.4,"tv":4509.41,"id":21580749}]}]}
{"op":"mcm","clk":"993831956","pt":1580546797512,"mc":[{"id":"1.168096552","rc":[{"batb":[[0,23,21.69],[1,22,4.19],[2,20,1.46]],"ltp":25.0,"tv":208.78,"id":24608298}]}]}
{"op":"mcm","clk":"993832362","pt":1580546802521,"mc":[{"id":"1.168096552","rc":[{"trd":[[4.6,1009.88]],"batl":[[0,4.7,17],[1,4.8,5.7],[2,4.9,56.91]],"ltp":4.6,"tv":4549.41,"id":21580749}],"tv":17409.55}]}
{"op":"mcm","clk":"993833609","pt":1580546816445,"mc":[{"id":"1.168096552","rc":[{"trd":[[4.5,817.5]],"batb":[[0,4.5,4]],"ltp":4.5,"tv":4569.41,"id":21580749},{"batb":[[0,24,2.99],[1,23,21],[2,22,4.19]],"ltp":25.0,"tv":208.78,"id":24608298}],"tv":17429.55}]}
{"op":"mcm","clk":"993833693","pt":1580546817231,"mc":[{"id":"1.168096552","rc":[{"batb":[[0,23,21.69],[1,22,4.19],[2,20,1.46]],"ltp":25.0,"tv":208.78,"id":24608298}]}]}
{"op":"mcm","clk":"993834149","pt":1580546822441,"mc":[{"id":"1.168096552","rc":[{"batl":[[0,4.6,2],[1,4.7,17],[2,4.8,5.7]],"ltp":4.5,"tv":4569.41,"id":21580749}]}]}
{"op":"mcm","clk":"993835052","pt":1580546833474,"mc":[{"id":"1.168096552","rc":[{"batb":[[0,4.5,7]],"ltp":4.5,"tv":4569.41,"id":21580749}]}]}
{"op":"mcm","clk":"993835907","pt":1580546843478,"mc":[{"id":"1.168096552","rc":[{"trd":[[4.6,1013.88]],"batb":[[0,4.6,6.7],[1,4.5,32],[2,4.4,17.48]],"batl":[[0,4.7,17],[1,4.8,5.7],[2,4.9,56.91]],"ltp":4.6,"tv":4573.41,"id":21580749},{"batb":[[0,24,2.81],[1,23,21],[2,22,4.19]],"ltp":25.0,"tv":208.78,"id":24608298}],"tv":17433.55}]}
{"op":"mcm","clk":"993835984","pt":1580546844460,"mc":[{"id":"1.168096552","rc":[{"batb":[[0,23,21.69],[1,22,4.19],[2,20,1.46]],"ltp":25.0,"tv":208.78,"id":24608298}]}]}
{"op":"mcm","clk":"993836233","pt":1580546848480,"mc":[{"id":"1.168096552","rc":[{"batb":[[2,4.4,19.48]],"ltp":4.6,"tv":4573.41,"id":21580749}]}]}
{"op":"mcm","clk":"993836762","pt":1580546856486,"mc":[{"id":"1.168096552","rc":[{"trd":[[3.05,1098.14]],"batb":[[0,3.05,3.65]],"ltp":3.05,"tv":4257.8,"id":18286408}],"tv":17437.55}]}
{"op":"mcm","clk":"993836904","pt":1580546858389,"mc":[{"id":"1.168096552","rc":[{"trd":[[4.6,1027.28]],"batb":[[0,4.5,32],[1,4.4,19.48],[2,4.3,63.43]],"batl":[[0,4.6,3.3],[1,4.7,17],[2,4.8,5.7]],"ltp":4.6,"tv":4586.81,"id":21580749}],"tv":17450.95}]}
{"op":"mcm","clk":"993836989","pt":1580546859429,"mc":[{"id":"1.168096552","rc":[{"batb":[[1,4.4,23.7]],"ltp":4.6,"tv":4586.81,"id":21580749}]}]}
{"op":"mcm","clk":"993837076","pt":1580546860411,"mc":[{"id":"1.168096552","rc":[{"batb":[[1,4.4,19.48]],"ltp":4.6,"tv":4586.81,"id":21580749}]}]}
{"op":"mcm","clk":"993837400","pt":1580546865417,"mc":[{"id":"1.168096552","rc":[{"batl":[[0,4.6,13.3]],"ltp":4.6,"tv":4586.81,"id":21580749}]}]}
{"op":"mcm","clk":"993838365","pt":1580546878434,"mc":[{"id":"1.168096552","rc":[{"trd":[[4.6,1053.88]],"batb":[[0,4.6,10.7],[1,4.5,32],[2,4.4,19.48]],"batl":[[0,4.7,17],[1,4.8,5.7],[2,4.9,56.91]],"ltp":4.6,"tv":4613.41,"id":21580749}],"tv":17477.55}]}
{"op":"mcm","clk":"993839016","pt":1580546886435,"mc":[{"id":"1.168096552","rc":[{"trd":[[4.6,1075.28]],"batb":[[0,4.5,32],[1,4.4,19.48],[2,4.3,63.43]],"ltp":4.6,"tv":4634.81,"id":21580749},{"batb":[[0,24,2.72],[1,23,21],[2,22,4.19]],"ltp":25.0,"tv":208.78,"id":24608298}],"tv":17498.95}]}
{"op":"mcm","clk":"993839112","pt":1580546887519,"mc":[{"id":"1.168096552","rc":[{"batb":[[1,4.4,25.87]],"ltp":4.6,"tv":4634.81,"id":21580749},{"batb":[[0,23,21.69],[1,22,4.19],[2,20,1.46]],"ltp":25.0,"tv":208.78,"id":24608298}]}]}
{"op":"mcm","clk":"993839324","pt":1580546890455,"mc":[{"id":"1.168096552","rc":[{"batl":[[0,4.6,10],[1,4.7,17],[2,4.8,5.7]],"ltp":4.6,"tv":4634.81,"id":21580749},{"batb":[[0,24,2.74],[1,23,21],[2,22,4.19]],"ltp":25.0,"tv":208.78,"id":24608298}]}]}
{"op":"mcm","clk":"993839388","pt":1580546891240,"mc":[{"id":"1.168096552","rc":[{"batb":[[1,4.4,19.48]],"ltp":4.6,"tv":4634.81,"id":21580749},{"batb":[[0,23,21.69],[1,22,4.19],[2,20,1.46]],"ltp":25.0,"tv":208.78,"id":24608298}]}]}
{"op":"mcm","clk":"993839464","pt":1580546892371,"mc":[{"id":"1.168096552","rc":[{"batl":[[0,4.6,20]],"ltp":4.6,"tv":4634.81,"id":21580749}]}]}
{"op":"mcm","clk":"993839782","pt":1580546896450,"mc":[{"id":"1.168096552","rc":[{"trd":[[4.6,1079.28]],"batl":[[0,4.6,18]],"ltp":4.6,"tv":4638.81,"id":21580749}],"tv":17502.95}]}
{"op":"mcm","clk":"993839884","pt":1580546897479,"mc":[{"id":"1.168096552","rc":[{"batb":[[2,4.3,43.43]],"ltp":4.6,"tv":4638.81,"id":21580749},{"batb":[[0,24,2.78],[1,23,21],[2,22,4.19]],"ltp":25.0,"tv":208.78,"id":24608298}]}]}
{"op":"mcm","clk":"993839953","pt":1580546898458,"mc":[{"id":"1.168096552","rc":[{"batb":[[0,23,21.69],[1,22,4.19],[2,20,1.46]],"ltp":25.0,"tv":208.78,"id":24608298}]}]}
{"op":"mcm","clk":"993840432","pt":1580546904474,"mc":[{"id":"1.168096552","rc":[{"trd":[[4.6,1115.28]],"batb":[[0,4.6,2],[1,4.5,32],[2,4.4,19.48]],"batl":[[0,4.7,17],[1,4.8,5.7],[2,4.9,56.91]],"ltp":4.6,"tv":4674.81,"id":21580749}],"tv":17538.95}]}
{"op":"mcm","clk":"993840515","pt":1580546905455,"mc":[{"id":"1.168096552","rc":[{"trd":[[3.1,987.85]],"batl":[[0,3.1,29.02]],"ltp":3.1,"tv":4265.8,"id":18286408}],"tv":17546.95}]}
{"op":"mcm","clk":"993841058","pt":1580546912477,"mc":[{"id":"1.168096552","rc":[{"batb":[[1,4.5,52]],"ltp":4.6,"tv":4674.81,"id":21580749},{"trd":[[2.98,573.79]],"batb":[[0,2.98,6.71]],"ltp":2.98,"tv":7702.05,"id":52106},{"batb":[[0,24,2.86],[1,23,21],[2,22,4.19]],"ltp":25.0,"tv":208.78,"id":24608298}],"tv":17550.95}]}
{"op":"mcm","clk":"993841144","pt":1580546913401,"mc":[{"id":"1.168096552","rc":[{"batb":[[0,2.96,22.01],[1,2.94,37.1],[2,2.92,155.29]],"ltp":2.98,"tv":7702.05,"id":52106},{"batb":[[0,23,21.69],[1,22,4.19],[2,20,1.46]],"ltp":25.0,"tv":208.78,"id":24608298}]}]}
{"op":"mcm","clk":"993841223","pt":1580546914382,"mc":[{"id":"1.168096552","rc":[{"batb":[[0,2.98,6.72],[1,2.96,21.48],[2,2.94,37.1]],"ltp":2.98,"tv":7702.05,"id":52106},{"batb":[[0,24,2.87],[1,23,21],[2,22,4.19]],"ltp":25.0,"tv":208.78,"id":24608298}]}]}
{"op":"mcm","clk":"993841310","pt":1580546915474,"mc":[{"id":"1.168096552","rc":[{"batb":[[0,2.96,22.01],[1,2.94,37.1],[2,2.92,155.29]],"ltp":2.98,"tv":7702.05,"id":52106},{"batb":[[0,23,21.69],[1,22,4.19],[2,20,1.46]],"ltp":25.0,"tv":208.78,"id":24608298}]}]}
{"op":"mcm","clk":"993841533","pt":1580546918487,"mc":[{"id":"1.168096552","rc":[{"trd":[[4.6,1119.28]],"batb":[[0,4.5,52],[1,4.4,19.48],[2,4.3,43.43]],"batl":[[0,4.6,8],[1,4.7,17],[2,4.8,5.7]],"ltp":4.6,"tv":4678.81,"id":21580749}],"tv":17554.95}]}
{"op":"mcm","clk":"993841618","pt":1580546919518,"mc":[{"id":"1.168096552","rc":[{"batb":[[1,2.94,44.46]],"ltp":2.98,"tv":7702.05,"id":52106}]}]}
{"op":"mcm","clk":"993841691","pt":1580546920507,"mc":[{"id":"1.168096552","rc":[{"trd":[[4.6,1128.84]],"batl":[[0,4.6,3.22]],"ltp":4.6,"tv":4688.37,"id":21580749},{"batb":[[0,24,2.91],[1,23,21],[2,22,4.19]],"ltp":25.0,"tv":208.78,"id":24608298}],"tv":17564.51}]}
{"op":"mcm","clk":"993841779","pt":1580546921519,"mc":[{"id":"1.168096552","rc":[{"batb":[[1,2.94,37.1]],"ltp":2.98,"tv":7702.05,"id":52106},{"batb":[[0,23,21.69],[1,22,4.19],[2,20,1.46]],"ltp":25.0,"tv":208.78,"id":24608298}]}]}
{"op":"mcm","clk":"993841922","pt":1580546923505,"mc":[{"id":"1.168096552","rc":[{"batb":[[0,13.5,2.34]],"ltp":13.5,"tv":595.93,"id":26640937},{"batb":[[0,4.5,77]],"ltp":4.6,"tv":4688.37,"id":21580749},{"trd":[[3.05,423.88]],"batl":[[0,3.05,17.75]],"ltp":3.05,"tv":7710.55,"id":52106}],"tv":17573.01}]}
{"op":"mcm","clk":"993842148","pt":1580546926384,"mc":[{"id":"1.168096552","rc":[{"batb":[[0,3,10],[1,2.98,6.79],[2,2.96,21.48]],"ltp":3.05,"tv":7710.55,"id":52106}]}]}
{"op":"mcm","clk":"993842792","pt":1580546934502,"mc":[{"id":"1.168096552","rc":[{"batb":[[0,3,14.25]],"ltp":3.05,"tv":7710.55,"id":52106}]}]}
{"op":"mcm","clk":"993842929","pt":1580546936210,"mc":[{"id":"1.168096552","rc":[{"trd":[[4.6,1135.28]],"batb":[[0,4.6,16.78],[1,4.5,77],[2,4.4,19.48]],"batl":[[0,4.7,12],[1,4.8,5.7],[2,4.9,56.91]],"ltp":4.6,"tv":4694.81,"id":21580749}],"tv":17579.45}]}
{"op":"mcm","clk":"993843086","pt":1580546938496,"mc":[{"id":"1.168096552","rc":[{"trd":[[4.6,1155.28]],"batb":[[0,4.6,6.78]],"ltp":4.6,"tv":4714.81,"id":21580749},{"batb":[[2,46,4.76]],"ltp":55.0,"tv":103.56,"id":27706761}],"tv":17599.45}]}
{"op":"mcm","clk":"993843296","pt":1580546941238,"mc":[{"id":"1.168096552","rc":[{"trd":[[3.1,991.85]],"batl":[[0,3.1,27.02]],"ltp":3.1,"tv":4269.8,"id":18286408}],"tv":17603.45}]}
{"op":"mcm","clk":"993843920","pt":1580546949521,"mc":[{"id":"1.168096552","rc":[{"batl":[[0,3.05,3.75]],"ltp":3.05,"tv":7710.55,"id":52106}]}]}
{"op":"mcm","clk":"993844200","pt":1580546953259,"mc":[{"id":"1.168096552","rc":[{"trd":[[3.05,431.38]],"batl":[[0,3.05,2.07]],"ltp":3.05,"tv":7718.05,"id":52106}],"tv":17610.95}]}
{"op":"mcm","clk":"993844597","pt":1580546958451,"mc":[{"id":"1.168096552","rc":[{"batl":[[0,4.7,20]],"ltp":4.6,"tv":4714.81,"id":21580749}]}]}
{"op":"mcm","clk":"993844731","pt":1580546960261,"mc":[{"id":"1.168096552","rc":[{"trd":[[3.05,1105.44]],"batb":[[0,3,82.5],[1,2.98,38],[2,2.96,33]],"batl":[[0,3.05,6.35],[1,3.1,27.02],[2,3.15,85.82]],"ltp":3.05,"tv":4277.1,"id":18286408}],"tv":17618.24}]}
{"op":"mcm","clk":"993845696","pt":1580546972494,"mc":[{"id":"1.168096552","rc":[{"batb":[[1,2.98,51.78]],"ltp":3.05,"tv":4277.1,"id":18286408},{"batb":[[0,13.5,4.34]],"ltp":13.5,"tv":595.93,"id":26640937},{"trd":[[4.6,1168.84]],"batb":[[0,4.5,77],[1,4.4,23.74],[2,4.3,43.43]],"batl":[[0,4.6,3.22],[1,4.7,25],[2,4.8,5.7]],"ltp":4.6,"tv":4728.37,"id":21580749},{"batb":[[1,2.98,11.64]],"ltp":3.05,"tv":7718.05,"id":52106}],"tv":17631.8}]}
{"op":"mcm","clk":"993845910","pt":1580546974977,"mc":[{"id":"1.168096552","rc":[{"batb":[[1,4.4,19.48]],"ltp":4.6,"tv":4728.37,"id":21580749}]}]}
{"op":"mcm","clk":"993846908","pt":1580546986487,"mc":[{"id":"1.168096552","rc":[{"trd":[[3,729.89]],"batb":[[0,3,52.53]],"ltp":3.0,"tv":4337.08,"id":18286408},{"batb":[[0,24,2.94],[1,23,21],[2,22,4.19]],"ltp":25.0,"tv":208.78,"id":24608298}],"tv":17691.78}]}
{"op":"mcm","clk":"993846957","pt":1580546987156,"mc":[{"id":"1.168096552","rc":[{"batb":[[0,23,21.69],[1,22,4.19],[2,20,1.46]],"ltp":25.0,"tv":208.78,"id":24608298}]}]}
{"op":"mcm","clk":"993847664","pt":1580546995483,"mc":[{"id":"1.168096552","rc":[{"batl":[[0,4.6,13.22]],"ltp":4.6,"tv":4728.37,"id":21580749},{"batb":[[0,24,2.99],[1,23,21],[2,22,4.19]],"ltp":25.0,"tv":208.78,"id":24608298}]}]}
{"op":"mcm","clk":"993847754","pt":1580546996416,"mc":[{"id":"1.168096552","rc":[{"batb":[[0,14,5],[1,13.5,4.34],[2,13,7.7]],"ltp":13.5,"tv":595.93,"id":26640937},{"batb":[[0,3,20.25]],"ltp":3.05,"tv":7718.05,"id":52106},{"batb":[[0,23,21.69],[1,22,4.19],[2,20,1.46]],"ltp":25.0,"tv":208.78,"id":24608298}]}]}
{"op":"mcm","clk":"993847841","pt":1580546997400,"mc":[{"id":"1.168096552","rc":[{"batl":[[0,4.6,23.22]],"ltp":4.6,"tv":4728.37,"id":21580749},{"batb":[[0,3,14.25],[1,2.98,6.79]],"ltp":3.05,"tv":7718.05,"id":52106}]}]}
{"op":"mcm","clk":"993848456","pt":1580547004424,"mc":[{"id":"1.168096552","rc":[{"trd":[[4.5,837.5]],"batb":[[0,4.5,69]],"ltp":4.5,"tv":4748.37,"id":21580749}],"tv":17711.78}]}
{"op":"mcm","clk":"993848545","pt":1580547005506,"mc":[{"id":"1.168096552","rc":[{"trd":[[4.6,1215.28]],"batb":[[0,4.6,6.78],[1,4.5,69],[2,4.4,19.48]],"batl":[[0,4.7,25],[1,4.8,5.7],[2,4.9,56.91]],"ltp":4.6,"tv":4794.81,"id":21580749}],"tv":17758.22}]}
{"op":"mcm","clk":"993848691","pt":1580547007420,"mc":[{"id":"1.168096552","rc":[{"batb":[[0,3,40.43],[1,2.98,38]],"ltp":3.0,"tv":4337.08,"id":18286408},{"batb":[[1,50,2.34]],"ltp":55.0,"tv":103.56,"id":27706761}]}]}
{"op":"mcm","clk":"993848761","pt":1580547008203,"mc":[{"id":"1.168096552","rc":[{"batb":[[1,2.98,61.15]],"ltp":3.0,"tv":4337.08,"id":18286408}]}]}
{"op":"mcm","clk":"993848963","pt":1580547010409,"mc":[{"id":"1.168096552","rc":[{"trd":[[4.7,1308.12]],"batl":[[0,4.7,22.74]],"ltp":4.7,"tv":4799.33,"id":21580749}],"tv":17762.74}]}
{"op":"mcm","clk":"993849108","pt":1580547012228,"mc":[{"id":"1.168096552","rc":[{"batb":[[1,4.5,71]],"ltp":4.7,"tv":4799.33,"id":21580749},{"batb":[[0,24,2.75],[1,23,21],[2,22,4.19]],"ltp":25.0,"tv":208.78,"id":24608298}]}]}
{"op":"mcm","clk":"993849209","pt":1580547013521,"mc":[{"id":"1.168096552","rc":[{"batb":[[0,23,21.69],[1,22,4.19],[2,20,1.46]],"ltp":25.0,"tv":208.78,"id":24608298}]}]}
{"op":"mcm","clk":"993849343","pt":1580547015428,"mc":[{"id":"1.168096552","rc":[{"batb":[[1,2.98,74.42]],"ltp":3.0,"tv":4337.08,"id":18286408},{"trd":[[4.6,1228.84]],"batb":[[0,4.5,71],[1,4.4,23.91],[2,4.3,43.43]],"batl":[[0,4.6,7.22],[1,4.7,22.74],[2,4.8,5.7]],"ltp":4.6,"tv":4812.89,"id":21580749}],"tv":17776.3}]}
{"op":"mcm","clk":"993849407","pt":1580547016513,"mc":[{"id":"1.168096552","rc":[{"batl":[[1,4.7,32.74]],"ltp":4.6,"tv":4812.89,"id":21580749},{"batb":[[0,24,2.77],[1,23,21],[2,22,4.19]],"ltp":25.0,"tv":208.78,"id":24608298}]}]}
{"op":"mcm","clk":"993849476","pt":1580547017431,"mc":[{"id":"1.168096552","rc":[{"batb":[[1,2.98,63.46]],"ltp":3.0,"tv":4337.08,"id":18286408},{"batl":[[0,4.6,17.22]],"ltp":4.6,"tv":4812.89,"id":21580749},{"batb":[[2,48,2]],"ltp":55.0,"tv":103.56,"id":27706761},{"batb":[[0,23,21.69],[1,22,4.19],[2,20,1.46]],"ltp":25.0,"tv":208.78,"id":24608298}]}]}
{"op":"mcm","clk":"993850184","pt":1580547027454,"mc":[{"id":"1.168096552","rc":[{"batb":[[1,4.4,19.48]],"ltp":4.6,"tv":4812.89,"id":21580749}]}]}
{"op":"mcm","clk":"993850567","pt":1580547032157,"mc":[{"id":"1.168096552","rc":[{"batb":[[0,4.5,121]],"ltp":4.6,"tv":4812.89,"id":21580749}]}]}
{"op":"mcm","clk":"993850735","pt":1580547034425,"mc":[{"id":"1.168096552","rc":[{"trd":[[4.6,1249.1]],"batl":[[0,4.6,7.09],[1,4.7,42.74]],"ltp":4.6,"tv":4833.14,"id":21580749}],"tv":17796.55}]}
{"op":"mcm","clk":"993850941","pt":1580547035467,"mc":[{"id":"1.168096552","rc":[{"batl":[[2,4.8,15.41]],"ltp":4.6,"tv":4833.14,"id":21580749}]}]}
{"op":"mcm","clk":"993851246","pt":1580547037446,"mc":[{"id":"1.168096552","rc":[{"trd":[[4.6,1263.28]],"batb":[[0,4.6,3.04],[1,4.5,121],[2,4.4,19.48]],"batl":[[0,4.7,42.74],[1,4.8,15.41],[2,4.9,56.91]],"ltp":4.6,"tv":4847.32,"id":21580749}],"tv":17810.74}]}
{"op":"mcm","clk":"993851306","pt":1580547038373,"mc":[{"id":"1.168096552","rc":[{"batb":[[1,2.98,50.18]],"ltp":3.0,"tv":4337.08,"id":18286408}]}]}
{"op":"mcm","clk":"993851796","pt":1580547045479,"mc":[{"id":"1.168096552","rc":[{"batb":[[0,4.6,28.04]],"ltp":4.6,"tv":4847.32,"id":21580749}]}]}
{"op":"mcm","clk":"993851946","pt":1580547047459,"mc":[{"id":"1.168096552","rc":[{"batb":[[0,3,34.43]],"batl":[[0,3.05,8.35]],"ltp":3.0,"tv":4337.08,"id":18286408},{"trd":[[4.6,1303.28]],"batb":[[0,4.6,8.04]],"ltp":4.6,"tv":4887.32,"id":21580749},{"batb":[[0,3,58.25]],"ltp":3.05,"tv":7718.05,"id":52106}],"tv":17850.74}]}
{"op":"mcm","clk":"993852014","pt":1580547048443,"mc":[{"id":"1.168096552","rc":[{"batb":[[1,2.98,63.46]],"ltp":3.0,"tv":4337.08,"id":18286408},{"trd":[[4.6,1319.36]],"batb":[[0,4.5,121],[1,4.4,28.13],[2,4.3,43.43]],"batl":[[0,4.6,1.96],[1,4.7,42.74],[2,4.8,25.12]],"ltp":4.6,"tv":4903.4,"id":21580749},{"batb":[[0,3,64.25]],"batl":[[0,3.1,65.9],[1,3.15,13.96],[2,3.35,6]],"ltp":3.05,"tv":7718.05,"id":52106}],"tv":17866.82}]}
{"op":"mcm","clk":"993852100","pt":1580547049476,"mc":[{"id":"1.168096552","rc":[{"batb":[[0,3,23.54]],"ltp":3.0,"tv":4337.08,"id":18286408},{"batb":[[1,2.98,24.82]],"ltp":3.05,"tv":7718.05,"id":52106}]}]}
{"op":"mcm","clk":"993852147","pt":1580547050246,"mc":[{"id":"1.168096552","rc":[{"batb":[[1,4.4,19.48]],"ltp":4.6,"tv":4903.4,"id":21580749}]}]}
{"op":"mcm","clk":"993852239","pt":1580547051390,"mc":[{"id":"1.168096552","rc":[{"batb":[[0,4.5,71]],"ltp":4.6,"tv":4903.4,"id":21580749}]}]}
{"op":"mcm","clk":"993852300","pt":1580547052266,"mc":[{"id":"1.168096552","rc":[{"batb":[[0,3,34.43]],"ltp":3.0,"tv":4337.08,"id":18286408}]}]}
{"op":"mcm","clk":"993852417","pt":1580547053456,"mc":[{"id":"1.168096552","rc":[{"batb":[[0,3,78.43]],"ltp":3.0,"tv":4337.08,"id":18286408}]}]}
{"op":"mcm","clk":"993852698","pt":1580547055476,"mc":[{"id":"1.168096552","rc":[{"trd":[[4.6,1323.28],[4.7,1322.62]],"batl":[[0,4.7,35.49],[1,4.8,25.12],[2,4.9,56.91]],"ltp":4.7,"tv":4921.82,"id":21580749}],"tv":17885.24}]}
{"op":"mcm","clk":"993852868","pt":1580547057491,"mc":[{"id":"1.168096552","rc":[{"batl":[[0,4.7,45.49]],"ltp":4.7,"tv":4921.82,"id":21580749}]}]}
{"op":"mcm","clk":"993853547","pt":1580547066519,"mc":[{"id":"1.168096552","rc":[{"trd":[[4.6,1340.68]],"batb":[[0,4.6,11.3],[1,4.5,71],[2,4.4,19.48]],"ltp":4.6,"tv":4939.22,"id":21580749}],"tv":17902.64}]}
{"op":"mcm","clk":"993853618","pt":1580547067400,"mc":[{"id":"1.168096552","rc":[{"batb":[[1,2.98,50.18]],"batl":[[1,3.1,52.23]],"ltp":3.0,"tv":4337.08,"id":18286408}]}]}
{"op":"mcm","clk":"993854018","pt":1580547072415,"mc":[{"id":"1.168096552","rc":[{"batb":[[0,3,103.63]],"ltp":3.0,"tv":4337.08,"id":18286408}]}]}
{"op":"mcm","clk":"993854146","pt":1580547073913,"mc":[{"id":"1.168096552","rc":[{"trd":[[3.05,1122.14]],"batb":[[0,3.05,12.14],[1,3,103.63],[2,2.98,38]],"batl":[[0,3.1,52.23],[1,3.15,85.82],[2,3.2,17]],"ltp":3.05,"tv":4353.78,"id":18286408}],"tv":17919.34}]}
{"op":"mcm","clk":"993854287","pt":1580547075514,"mc":[{"id":"1.168096552","rc":[{"batb":[[1,3,109.63]],"ltp":3.05,"tv":4353.78,"id":18286408},{"trd":[[4.6,1363.28]],"batb":[[0,4.5,71],[1,4.4,19.48],[2,4.3,43.43]],"batl":[[0,4.7,35.49]],"ltp":4.6,"tv":4961.82,"id":21580749},{"batb":[[0,3,58.25]],"ltp":3.05,"tv":7718.05,"id":52106}],"tv":17941.94}]}
{"op":"mcm","clk":"993854358","pt":1580547076334,"mc":[{"id":"1.168096552","rc":[{"batb":[[1,4.4,27.31]],"ltp":4.6,"tv":4961.82,"id":21580749}]}]}
{"op":"mcm","clk":"993854524","pt":1580547078325,"mc":[{"id":"1.168096552","rc":[{"batb":[[1,4.4,19.48]],"ltp":4.6,"tv":4961.82,"id":21580749}]}]}
{"op":"mcm","clk":"993854613","pt":1580547079424,"mc":[{"id":"1.168096552","rc":[{"batl":[[2,3.4,3.63]],"ltp":3.05,"tv":7718.05,"id":52106}]}]}
{"op":"mcm","clk":"993854854","pt":1580547082322,"mc":[{"id":"1.168096552","rc":[{"batb":[[0,3.05,46.14]],"ltp":3.05,"tv":4353.78,"id":18286408}]}]}
{"op":"mcm","clk":"993856078","pt":1580547098458,"mc":[{"id":"1.168096552","rc":[{"batb":[[0,4.6,20],[1,4.5,71],[2,4.4,19.48]],"ltp":4.6,"tv":4961.82,"id":21580749},{"batb":[[0,24,2.9],[1,23,21],[2,22,4.19]],"ltp":25.0,"tv":208.78,"id":24608298}]}]}
{"op":"mcm","clk":"993856117","pt":1580547098978,"mc":[{"id":"1.168096552","rc":[{"batl":[[0,3.05,2.21],[1,3.1,65.9],[2,3.15,13.96]],"ltp":3.05,"tv":7718.05,"id":52106},{"batb":[[0,23,21.69],[1,22,4.19],[2,20,1.46]],"ltp":25.0,"tv":208.78,"id":24608298}]}]}
{"op":"mcm","clk":"993857179","pt":1580547113288,"mc":[{"id":"1.168096552","rc":[{"trd":[[3.05,1126.14]],"batb":[[0,3.05,44.14]],"ltp":3.05,"tv":4357.78,"id":18286408}],"tv":17945.94}]}
{"op":"mcm","clk":"993857475","pt":1580547116978,"mc":[{"id":"1.168096552","rc":[{"trd":[[4.6,1383.28]],"batb":[[0,4.6,10]],"ltp":4.6,"tv":4981.82,"id":21580749}],"tv":17965.94}]}
{"op":"mcm","clk":"993857599","pt":1580547118484,"mc":[{"id":"1.168096552","rc":[{"trd":[[3,1039.31]],"batb":[[0,3,41.45]],"ltp":3.0,"tv":7751.65,"id":52106}],"tv":17999.54}]}
{"op":"mcm","clk":"993857673","pt":1580547119519,"mc":[{"id":"1.168096552","rc":[{"batb":[[1,2.98,6.79]],"ltp":3.0,"tv":7751.65,"id":52106}]}]}
{"op":"mcm","clk":"993857916","pt":1580547122473,"mc":[{"id":"1.168096552","rc":[{"trd":[[3.05,435.8]],"batl":[[0,3.05,2]],"ltp":3.05,"tv":7756.07,"id":52106}],"tv":18003.96}]}
{"op":"mcm","clk":"993858218","pt":1580547125518,"mc":[{"id":"1.168096552","rc":[{"batl":[[0,4.7,45.49]],"ltp":4.6,"tv":4981.82,"id":21580749}]}]}
{"op":"mcm","clk":"993858280","pt":1580547126191,"mc":[{"id":"1.168096552","rc":[{"trd":[[3.1,1002.07]],"batl":[[0,3.1,47.12]],"ltp":3.1,"tv":4368.0,"id":18286408}],"tv":18014.18}]}
{"op":"mcm","clk":"993858445","pt":1580547128478,"mc":[{"id":"1.168096552","rc":[{"trd":[[4.6,1403.28]],"batb":[[0,4.5,71],[1,4.4,19.48],[2,4.3,43.43]],"ltp":4.6,"tv":5001.82,"id":21580749},{"batb":[[0,24,2.73],[1,23,21],[2,22,4.19]],"ltp":25.0,"tv":208.78,"id":24608298}],"tv":18034.18}]}
{"op":"mcm","clk":"993858485","pt":1580547128992,"mc":[{"id":"1.168096552","rc":[{"batb":[[1,4.4,22.15]],"ltp":4.6,"tv":5001.82,"id":21580749},{"batb":[[0,23,21.69],[1,22,4.19],[2,20,1.46]],"ltp":25.0,"tv":208.78,"id":24608298}]}]}
{"op":"mcm","clk":"993858987","pt":1580547135481,"mc":[{"id":"1.168096552","rc":[{"batb":[[0,24,2.77],[1,23,21],[2,22,4.19]],"ltp":25.0,"tv":208.78,"id":24608298}]}]}
{"op":"mcm","clk":"993859081","pt":1580547136512,"mc":[{"id":"1.168096552","rc":[{"batb":[[0,23,21.69],[1,22,4.19],[2,20,1.46]],"ltp":25.0,"tv":208.78,"id":24608298}]}]}
{"op":"mcm","clk":"993859613","pt":1580547143443,"mc":[{"id":"1.168096552","rc":[{"batb":[[0,4.5,121]],"ltp":4.6,"tv":5001.82,"id":21580749},{"batb":[[0,24,2.81],[1,23,21],[2,22,4.19]],"ltp":25.0,"tv":208.78,"id":24608298}]}]}
{"op":"mcm","clk":"993859642","pt":1580547143700,"mc":[{"id":"1.168096552","rc":[{"batb":[[0,23,21.69],[1,22,4.19],[2,20,1.46]],"ltp":25.0,"tv":208.78,"id":24608298}]}]}
{"op":"mcm","clk":"993860083","pt":1580547149453,"mc":[{"id":"1.168096552","rc":[{"trd":[[3,1059.31]],"batb":[[0,3,31.45]],"ltp":3.0,"tv":7776.07,"id":52106}],"tv":18054.18}]}
{"op":"mcm","clk":"993860259","pt":1580547151431,"mc":[{"id":"1.168096552","rc":[{"trd":[[4.7,1338.78]],"batl":[[0,4.7,37.41]],"ltp":4.7,"tv":5017.98,"id":21580749}],"tv":18070.34}]}
{"op":"mcm","clk":"993870297","pt":1580547153453,"mc":[{"id":"1.168096552","rc":[{"batb":[[0,3.05,69.35]],"ltp":3.1,"tv":4368.0,"id":18286408},{"batb":[[0,24,2.87],[1,23,21],[2,22,4.19]],"ltp":25.0,"tv":208.78,"id":24608298}]}]}
{"op":"mcm","clk":"993870382","pt":1580547154231,"mc":[{"id":"1.168096552","rc":[{"batb":[[0,23,21.69],[1,22,4.19],[2,20,1.46]],"ltp":25.0,"tv":208.78,"id":24608298}]}]}
{"op":"mcm","clk":"993870472","pt":1580547155426,"mc":[{"id":"1.168096552","rc":[{"trd":[[36,27.12],[38,11.48],[42,5.04],[46,4.66],[48,11.95],[50,14.04],[60,6.06]],"batb":[[0,34,3.04],[1,32,2.54],[2,30,2]],"ltp":36.0,"tv":133.55,"id":27706761},{"batb":[[0,24,2.88],[1,23,21],[2,22,4.19]],"ltp":25.0,"tv":208.78,"id":24608298}],"tv":18100.34}]}
{"op":"mcm","clk":"993870569","pt":1580547156466,"mc":[{"id":"1.168096552","rc":[{"batb":[[0,38,2.19],[1,36,3.6],[2,34,6.44]],"batl":[[0,65,7.08]],"ltp":36.0,"tv":133.55,"id":27706761},{"batb":[[1,2.98,17.17]],"ltp":3.0,"tv":7776.07,"id":52106},{"batb":[[0,23,21.69],[1,22,4.19],[2,20,1.46]],"ltp":25.0,"tv":208.78,"id":24608298}]}]}
{"op":"mcm","clk":"993870657","pt":1580547157419,"mc":[{"id":"1.168096552","rc":[{"batb":[[0,36,2.3],[1,34,6.44],[2,32,2.54]],"ltp":36.0,"tv":133.55,"id":27706761},{"batb":[[0,24,2.89],[1,23,21],[2,22,4.19]],"ltp":25.0,"tv":208.78,"id":24608298}]}]}
{"op":"mcm","clk":"993870724","pt":1580547158288,"mc":[{"id":"1.168096552","rc":[{"batb":[[0,23,21.69],[1,22,4.19],[2,20,1.46]],"ltp":25.0,"tv":208.78,"id":24608298}]}]}
{"op":"mcm","clk":"993870807","pt":1580547159445,"mc":[{"id":"1.168096552","rc":[{"batb":[[0,36,4.86]],"ltp":36.0,"tv":133.55,"id":27706761}]}]}
{"op":"mcm","clk":"993870871","pt":1580547160434,"mc":[{"id":"1.168096552","rc":[{"batb":[[2,2.98,41]],"ltp":3.1,"tv":4368.0,"id":18286408},{"batl":[[0,4.6,10],[1,4.7,37.41],[2,4.8,25.12]],"ltp":4.7,"tv":5017.98,"id":21580749},{"batb":[[1,34,2.94]],"ltp":36.0,"tv":133.55,"id":27706761},{"batb":[[0,24,2.91],[1,23,21],[2,22,4.19]],"ltp":25.0,"tv":208.78,"id":24608298}]}]}
{"op":"mcm","clk":"993870929","pt":1580547161160,"mc":[{"id":"1.168096552","rc":[{"batb":[[0,3.05,75.35]],"batl":[[0,3.1,45.12]],"ltp":3.1,"tv":4368.0,"id":18286408},{"batb":[[0,3,38.45]],"batl":[[0,3.1,65.9],[1,3.15,13.96],[2,3.35,6]],"ltp":3.0,"tv":7776.07,"id":52106},{"batb":[[0,23,21.69],[1,22,4.19],[2,20,1.46]],"ltp":25.0,"tv":208.78,"id":24608298}]}]}
{"op":"mcm","clk":"993870999","pt":1580547162140,"mc":[{"id":"1.168096552","rc":[{"batb":[[1,34,6.15]],"ltp":36.0,"tv":133.55,"id":27706761},{"batb":[[1,2.98,19.42]],"ltp":3.0,"tv":7776.07,"id":52106}]}]}
{"op":"mcm","clk":"993871089","pt":1580547163333,"mc":[{"id":"1.168096552","rc":[{"batb":[[0,36,6.86]],"ltp":36.0,"tv":133.55,"id":27706761}]}]}
{"op":"mcm","clk":"993871169","pt":1580547164470,"mc":[{"id":"1.168096552","rc":[{"batb":[[0,3.05,69.35]],"ltp":3.1,"tv":4368.0,"id":18286408},{"batl":[[0,55,1.64],[1,65,7.08],[2,85,1]],"ltp":36.0,"tv":133.55,"id":27706761},{"batb":[[0,3,31.45]],"ltp":3.0,"tv":7776.07,"id":52106},{"batb":[[0,24,2.93],[1,23,21],[2,22,4.19]],"ltp":25.0,"tv":208.78,"id":24608298}]}]}
{"op":"mcm","clk":"993871238","pt":1580547165248,"mc":[{"id":"1.168096552","rc":[{"batl":[[0,3.1,48.12]],"ltp":3.1,"tv":4368.0,"id":18286408},{"batl":[[0,3.05,3.24],[1,3.1,65.9],[2,3.15,13.96]],"ltp":3.0,"tv":7776.07,"id":52106},{"batb":[[0,23,21.69],[1,22,4.19],[2,20,1.46]],"ltp":25.0,"tv":208.78,"id":24608298}]}]}
{"op":"mcm","clk":"993871607","pt":1580547169457,"mc":[{"id":"1.168096552","rc":[{"trd":[[3.05,1146.15]],"batb":[[0,3.05,59.34]],"ltp":3.05,"tv":4388.0,"id":18286408}],"tv":18120.35}]}
{"op":"mcm","clk":"993871686","pt":1580547170333,"mc":[{"id":"1.168096552","rc":[{"batb":[[0,3.05,59.21]],"ltp":3.05,"tv":4388.0,"id":18286408},{"batl":[[0,4.6,20]],"ltp":4.7,"tv":5017.98,"id":21580749}]}]}
{"op":"mcm","clk":"993871893","pt":1580547172461,"mc":[{"id":"1.168096552","rc":[{"batl":[[0,3.1,56.43]],"ltp":3.05,"tv":4388.0,"id":18286408}]}]}
{"op":"mcm","clk":"993871973","pt":1580547173472,"mc":[{"id":"1.168096552","rc":[{"trd":[[3,1079.31]],"batb":[[0,3,21.45]],"ltp":3.0,"tv":7796.07,"id":52106},{"batb":[[0,24,2.98],[1,23,21],[2,22,4.19]],"ltp":25.0,"tv":208.78,"id":24608298}],"tv":18140.35}]}
{"op":"mcm","clk":"993872031","pt":1580547174153,"mc":[{"id":"1.168096552","rc":[{"trd":[[36,37.12]],"batb":[[0,36,1.86]],"ltp":36.0,"tv":143.56,"id":27706761},{"batb":[[0,23,21.69],[1,22,4.19],[2,20,1.46]],"ltp":25.0,"tv":208.78,"id":24608298}],"tv":18150.35}]}
{"op":"mcm","clk":"993872156","pt":1580547175453,"mc":[{"id":"1.168096552","rc":[{"trd":[[3.05,1156.15]],"batb":[[0,3.05,54.21]],"ltp":3.05,"tv":4398.0,"id":18286408},{"batb":[[0,24,2.99],[1,23,21],[2,22,4.19]],"ltp":25.0,"tv":208.78,"id":24608298}],"tv":18160.35}]}
{"op":"mcm","clk":"993872259","pt":1580547176488,"mc":[{"id":"1.168096552","rc":[{"batb":[[0,23,21.69],[1,22,4.19],[2,20,1.46]],"ltp":25.0,"tv":208.78,"id":24608298}]}]}
{"op":"mcm","clk":"993872417","pt":1580547178454,"mc":[{"id":"1.168096552","rc":[{"batb":[[1,34,2.94]],"ltp":36.0,"tv":143.56,"id":27706761}]}]}
{"op":"mcm","clk":"993872666","pt":1580547181469,"mc":[{"id":"1.168096552","rc":[{"trd":[[3.05,1176.15]],"batb":[[0,3.05,44.21]],"ltp":3.05,"tv":4418.0,"id":18286408}],"tv":18180.35}]}
{"op":"mcm","clk":"993872899","pt":1580547184372,"mc":[{"id":"1.168096552","rc":[{"trd":[[4.6,1443.28]],"batl":[[0,4.7,37.41],[1,4.8,25.12],[2,4.9,56.91]],"ltp":4.6,"tv":5057.98,"id":21580749}],"tv":18220.35}]}
{"op":"mcm","clk":"993873459","pt":1580547191198,"mc":[{"id":"1.168096552","rc":[{"batl":[[0,4.6,10],[1,4.7,37.41],[2,4.8,25.12]],"ltp":4.6,"tv":5057.98,"id":21580749}]}]}
{"op":"mcm","clk":"993873574","pt":1580547192456,"mc":[{"id":"1.168096552","rc":[{"trd":[[3,1099.31]],"batb":[[0,3,11.45]],"ltp":3.0,"tv":7816.07,"id":52106},{"batb":[[0,24,2.75],[1,23,21],[2,22,4.19]],"ltp":25.0,"tv":208.78,"id":24608298}],"tv":18240.35}]}
{"op":"mcm","clk":"993873651","pt":1580547193439,"mc":[{"id":"1.168096552","rc":[{"batb":[[0,23,21.69],[1,22,4.19],[2,20,1.46]],"ltp":25.0,"tv":208.78,"id":24608298}]}]}
{"op":"mcm","clk":"993874915","pt":1580547209495,"mc":[{"id":"1.168096552","rc":[{"trd":[[4.6,1463.28]],"batb":[[0,4.6,10.41],[1,4.5,121],[2,4.4,22.15]],"batl":[[0,4.7,37.41],[1,4.8,25.12],[2,4.9,56.91]],"ltp":4.6,"tv":5077.98,"id":21580749}],"tv":18260.35}]}
{"op":"mcm","clk":"993874999","pt":1580547210318,"mc":[{"id":"1.168096552","rc":[{"batb":[[1,2.98,6.79]],"ltp":3.0,"tv":7816.07,"id":52106}]}]}
{"op":"mcm","clk":"993875177","pt":1580547212417,"mc":[{"id":"1.168096552","rc":[{"batb":[[1,2.98,10.75]],"ltp":3.0,"tv":7816.07,"id":52106}]}]}
{"op":"mcm","clk":"993876201","pt":1580547224417,"mc":[{"id":"1.168096552","rc":[{"batb":[[2,4.4,23.66]],"ltp":4.6,"tv":5077.98,"id":21580749}]}]}
{"op":"mcm","clk":"993876665","pt":1580547230446,"mc":[{"id":"1.168096552","rc":[{"trd":[[4.6,1483.28]],"batb":[[0,4.5,121.41],[1,4.4,31.18],[2,4.3,43.43]],"ltp":4.6,"tv":5097.98,"id":21580749}],"tv":18280.35}]}
{"op":"mcm","clk":"993876759","pt":1580547231429,"mc":[{"id":"1.168096552","rc":[{"batb":[[1,4.4,32.7]],"ltp":4.6,"tv":5097.98,"id":21580749}]}]}
{"op":"mcm","clk":"993877012","pt":1580547234459,"mc":[{"id":"1.168096552","rc":[{"batl":[[0,4.7,38.92]],"ltp":4.6,"tv":5097.98,"id":21580749}]}]}
{"op":"mcm","clk":"993877093","pt":1580547235340,"mc":[{"id":"1.168096552","rc":[{"batb":[[0,14.5,3],[1,14,5],[2,13.5,3.06]],"batl":[[0,15,7.8],[1,15.5,7],[2,17,2.41]],"ltp":13.5,"tv":595.93,"id":26640937},{"batb":[[1,4.4,25.18]],"batl":[[0,4.7,33.92]],"ltp":4.6,"tv":5097.98,"id":21580749},{"batl":[[0,3.05,3.3]],"ltp":3.0,"tv":7816.07,"id":52106},{"trd":[[22,38.37],[23,54.35],[25,1.46]],"batb":[[0,21,6.73],[1,20,5.92],[2,19.5,4.73]],"batl":[[0,30,2.3],[1,34,1.71],[2,36,2]],"ltp":22.0,"tv":273.78,"id":24608298}],"tv":18345.35}]}
{"op":"mcm","clk":"993877197","pt":1580547236481,"mc":[{"id":"1.168096552","rc":[{"batb":[[1,4.4,26.69]],"ltp":4.6,"tv":5097.98,"id":21580749},{"batb":[[2,32,4.71]],"ltp":36.0,"tv":143.56,"id":27706761},{"batb":[[1,2.98,13]],"ltp":3.0,"tv":7816.07,"id":52106},{"batb":[[0,21,2],[1,20,3.76]],"ltp":22.0,"tv":273.78,"id":24608298}]}]}
{"op":"mcm","clk":"993877268","pt":1580547237462,"mc":[{"id":"1.168096552","rc":[{"batl":[[0,15,9.8]],"ltp":13.5,"tv":595.93,"id":26640937}]}]}
{"op":"mcm","clk":"993877362","pt":1580547238498,"mc":[{"id":"1.168096552","rc":[{"batb":[[0,3.05,51.21]],"batl":[[0,3.1,53.43]],"ltp":3.05,"tv":4418.0,"id":18286408},{"batb":[[0,4.6,2.72],[1,4.5,121],[2,4.4,26.69]],"ltp":4.6,"tv":5097.98,"id":21580749},{"batb":[[2,19,4.31]],"batl":[[0,25,2.31],[1,26,5],[2,34,1.71]],"ltp":22.0,"tv":273.78,"id":24608298}]}]}
{"op":"mcm","clk":"993877472","pt":1580547239441,"mc":[{"id":"1.168096552","rc":[{"batb":[[0,21,19.36]],"ltp":22.0,"tv":273.78,"id":24608298}]}]}
{"op":"mcm","clk":"993877577","pt":1580547240482,"mc":[{"id":"1.168096552","rc":[{"batb":[[0,22,2.32],[1,21,36.36],[2,20,3.76]],"batl":[[0,26,7],[1,34,1.71],[2,36,2]],"ltp":22.0,"tv":273.78,"id":24608298}]}]}
{"op":"mcm","clk":"993877850","pt":1580547243450,"mc":[{"id":"1.168096552","rc":[{"trd":[[4.5,852.06],[4.6,1488.72]],"batb":[[0,4.5,113.72],[1,4.4,26.69],[2,4.3,43.43]],"ltp":4.5,"tv":5117.98,"id":21580749},{"batl":[[0,26,5],[1,27,2.01],[2,34,1.71]],"ltp":22.0,"tv":273.78,"id":24608298}],"tv":18365.35}]}
{"op":"mcm","clk":"993878561","pt":1580547250461,"mc":[{"id":"1.168096552","rc":[{"batb":[[0,34,2.94],[1,32,4.71],[2,30,2]],"ltp":36.0,"tv":143.56,"id":27706761}]}]}
{"op":"mcm","clk":"993878631","pt":1580547251392,"mc":[{"id":"1.168096552","rc":[{"batl":[[2,34,1.68]],"ltp":22.0,"tv":273.78,"id":24608298}]}]}
{"op":"mcm","clk":"993878709","pt":1580547252377,"mc":[{"id":"1.168096552","rc":[{"batl":[[0,26,5.03]],"ltp":22.0,"tv":273.78,"id":24608298}]}]}
{"op":"mcm","clk":"993879188","pt":1580547258377,"mc":[{"id":"1.168096552","rc":[{"batb":[[1,21,19]],"ltp":22.0,"tv":273.78,"id":24608298}]}]}
{"op":"mcm","clk":"993879396","pt":1580547260459,"mc":[{"id":"1.168096552","rc":[{"batb":[[0,4.6,2.11],[1,4.5,113.72],[2,4.4,26.69]],"ltp":4.5,"tv":5117.98,"id":21580749},{"trd":[[38,17.48]],"ltp":38.0,"tv":149.56,"id":27706761},{"batb":[[0,3,18.45],[2,2.96,24.48]],"batl":[[0,3.05,33]],"ltp":3.0,"tv":7816.07,"id":52106}],"tv":18371.35}]}
{"op":"mcm","clk":"993879466","pt":1580547261393,"mc":[{"id":"1.168096552","rc":[{"batb":[[0,3,11.45]],"ltp":3.0,"tv":7816.07,"id":52106}]}]}
{"op":"mcm","clk":"993879573","pt":1580547262487,"mc":[{"id":"1.168096552","rc":[{"trd":[[4.6,1508.72],[4.7,1346.62]],"batb":[[0,4.6,2.93]],"batl":[[0,4.7,30]],"ltp":4.7,"tv":5145.82,"id":21580749}],"tv":18399.19}]}
{"op":"mcm","clk":"993881043","pt":1580547279496,"mc":[{"id":"1.168096552","rc":[{"trd":[[2.96,726.73],[2.98,599.79],[3,1122.21]],"batb":[[0,2.94,27.55],[1,2.92,155.29],[2,2.9,6]],"batl":[[0,2.96,112.51],[1,3.05,33],[2,3.1,65.9]],"ltp":2.96,"tv":7935.04,"id":52106}],"tv":18518.16}]}
{"op":"mcm","clk":"993881128","pt":1580547280232,"mc":[{"id":"1.168096552","rc":[{"trd":[[2.96,739.69]],"batb":[[0,2.94,33.77],[1,2.92,163.92],[2,2.9,11]],"batl":[[0,2.96,106.03],[1,3,3.21],[2,3.05,33]],"ltp":2.96,"tv":7948.0,"id":52106}],"tv":18531.12}]}
{"op":"mcm","clk":"993881209","pt":1580547281216,"mc":[{"id":"1.168096552","rc":[{"batb":[[0,3.05,60.67]],"ltp":3.05,"tv":4418.0,"id":18286408},{"batb":[[0,2.94,24.58]],"ltp":2.96,"tv":7948.0,"id":52106}]}]}
{"op":"mcm","clk":"993881341","pt":1580547282514,"mc":[{"id":"1.168096552","rc":[{"batb":[[0,2.94,18.36],[1,2.92,160.29]],"ltp":2.96,"tv":7948.0,"id":52106}]}]}
{"op":"mcm","clk":"993881446","pt":1580547283507,"mc":[{"id":"1.168096552","rc":[{"trd":[[3.1,1059.41]],"batl":[[0,3.1,24.77]],"ltp":3.1,"tv":4475.34,"id":18286408},{"batb":[[0,14.5,9.13]],"batl":[[0,15,7.8]],"ltp":13.5,"tv":595.93,"id":26640937},{"batb":[[0,4.6,22.26]],"ltp":4.7,"tv":5145.82,"id":21580749},{"batb":[[0,2.94,48.6]],"ltp":2.96,"tv":7948.0,"id":52106},{"batb":[[0,24,3.7],[1,22,2.32],[2,21,19]],"batl":[[0,26,7.03]],"ltp":22.0,"tv":273.78,"id":24608298}],"tv":18588.46}]}
{"op":"mcm","clk":"993881531","pt":1580547284429,"mc":[{"id":"1.168096552","rc":[{"batb":[[0,38,1.6],[1,34,2.94],[2,32,4.71]],"ltp":38.0,"tv":149.56,"id":27706761},{"batb":[[1,2.92,166.48]],"batl":[[0,3.05,33],[1,3.1,93.38],[2,3.15,13.96]],"ltp":2.96,"tv":7948.0,"id":52106},{"batb":[[0,24,6.26]],"ltp":22.0,"tv":273.78,"id":24608298}]}]}
{"op":"mcm","clk":"993881704","pt":1580547286518,"mc":[{"id":"1.168096552","rc":[{"batl":[[0,48,2],[1,55,1.64],[2,65,7.08]],"ltp":38.0,"tv":149.56,"id":27706761},{"batl":[[1,3.1,65.9]],"ltp":2.96,"tv":7948.0,"id":52106},{"batb":[[1,22,6.43]],"ltp":22.0,"tv":273.78,"id":24608298}]}]}
{"op":"mcm","clk":"993881775","pt":1580547287399,"mc":[{"id":"1.168096552","rc":[{"batb":[[1,2.92,174.1]],"ltp":2.96,"tv":7948.0,"id":52106}]}]}
{"op":"mcm","clk":"993881866","pt":1580547288434,"mc":[{"id":"1.168096552","rc":[{"batb":[[1,3,112.63]],"ltp":3.1,"tv":4475.34,"id":18286408},{"trd":[[4.6,1528.72]],"batb":[[0,4.6,12.25]],"ltp":4.6,"tv":5165.83,"id":21580749},{"batl":[[1,65,7.08],[2,85,1]],"ltp":38.0,"tv":149.56,"id":27706761},{"batl":[[0,3.05,30]],"ltp":2.96,"tv":7948.0,"id":52106}],"tv":18608.47}]}
{"op":"mcm","clk":"993881941","pt":1580547289218,"mc":[{"id":"1.168096552","rc":[{"trd":[[4.6,1548.72]],"batb":[[0,4.6,2.25]],"ltp":4.6,"tv":5185.83,"id":21580749}],"tv":18628.47}]}
{"op":"mcm","clk":"993882051","pt":1580547290508,"mc":[{"id":"1.168096552","rc":[{"trd":[[3.05,1180.15]],"batb":[[0,3.05,58.67]],"ltp":3.05,"tv":4479.34,"id":18286408}],"tv":18632.47}]}
{"op":"mcm","clk":"993883096","pt":1580547302440,"mc":[{"id":"1.168096552","rc":[{"batb":[[1,36,2.47],[2,34,2.94]],"ltp":38.0,"tv":149.56,"id":27706761}]}]}
{"op":"mcm","clk":"993883527","pt":1580547307449,"mc":[{"id":"1.168096552","rc":[{"batl":[[2,36,2]],"ltp":22.0,"tv":273.78,"id":24608298}]}]}
{"op":"mcm","clk":"993883989","pt":1580547312477,"mc":[{"id":"1.168096552","rc":[{"trd":[[3.1,1059.68]],"batb":[[0,3.05,75.28]],"batl":[[0,3.1,24.5]],"ltp":3.1,"tv":4479.61,"id":18286408},{"trd":[[15,56.78]],"batb":[[0,14.5,12.63]],"batl":[[0,15,7.74]],"ltp":15.0,"tv":595.99,"id":26640937},{"trd":[[4.6,1553.41]],"batb":[[0,4.5,124.97],[1,4.4,26.69],[2,4.3,43.43]],"batl":[[0,4.6,7.7],[1,4.7,36],[2,4.8,25.12]],"ltp":4.6,"tv":5190.51,"id":21580749},{"trd":[[48,11.97]],"batb":[[0,38,2.94]],"batl":[[0,48,1.98]],"ltp":48.0,"tv":149.58,"id":27706761},{"trd":[[3,1122.49]],"batb":[[0,2.98,17],[1,2.94,48.6],[2,2.92,174.1]],"batl":[[0,3,10.16],[1,3.05,30],[2,3.1,65.9]],"ltp":3.0,"tv":7948.28,"id":52106},{"trd":[[25,1.49]],"batb":[[0,24,8.37]],"batl":[[0,26,7]],"ltp":25.0,"tv":273.81,"id":24608298}],"tv":18637.81}]}
{"op":"mcm","clk":"993884079","pt":1580547313461,"mc":[{"id":"1.168096552","rc":[{"batb":[[0,14.5,14.63],[1,14,7]],"ltp":15.0,"tv":595.99,"id":26640937},{"trd":[[48,15.93]],"batb":[[0,40,2.06],[1,38,2.94],[2,36,2.47]],"batl":[[0,65,7.08],[1,85,1],[2,100,2]],"ltp":48.0,"tv":153.54,"id":27706761},{"trd":[[3,1132.61]],"batb":[[0,2.98,22],[1,2.96,5.06],[2,2.94,48.6]],"batl":[[0,3,5.1],[1,3.05,33]],"ltp":3.0,"tv":7958.4,"id":52106},{"batb":[[0,24,10.37],[2,21,17]],"batl":[[0,26,5]],"ltp":25.0,"tv":273.81,"id":24608298}],"tv":18651.89}]}
{"op":"mcm","clk":"993884181","pt":1580547314459,"mc":[{"id":"1.168096552","rc":[{"trd":[[4.6,1568.82],[4.7,1392.24]],"batb":[[0,4.6,2.07],[1,4.5,124.97],[2,4.4,26.69]],"batl":[[0,4.7,7.19],[1,4.8,25.12],[2,4.9,56.91]],"ltp":4.7,"tv":5251.54,"id":21580749},{"batl":[[0,65,9.25]],"ltp":48.0,"tv":153.54,"id":27706761}],"tv":18712.92}]}
{"op":"mcm","clk":"993884266","pt":1580547315477,"mc":[{"id":"1.168096552","rc":[{"batl":[[1,4.8,15.41],[2,4.9,66.43]],"ltp":4.7,"tv":5251.54,"id":21580749}]}]}
{"op":"mcm","clk":"993884321","pt":1580547316155,"mc":[{"id":"1.168096552","rc":[{"batb":[[2,4.4,24.03]],"batl":[[1,4.8,5.7],[2,4.9,75.93]],"ltp":4.7,"tv":5251.54,"id":21580749},{"batl":[[0,65,7.08]],"ltp":48.0,"tv":153.54,"id":27706761},{"batb":[[1,22,10.5]],"ltp":25.0,"tv":273.81,"id":24608298}]}]}
{"op":"mcm","clk":"993884667","pt":1580547319470,"mc":[{"id":"1.168096552","rc":[{"trd":[[3.05,1184.15]],"batb":[[0,3.05,73.28]],"ltp":3.05,"tv":4483.61,"id":18286408},{"batb":[[2,20,1.46]],"ltp":25.0,"tv":273.81,"id":24608298}],"tv":18716.92}]}
{"op":"mcm","clk":"993884756","pt":1580547320397,"mc":[{"id":"1.168096552","rc":[{"batb":[[1,23,17],[2,22,10.5]],"ltp":25.0,"tv":273.81,"id":24608298}]}]}
{"op":"mcm","clk":"993884918","pt":1580547322074,"mc":[{"id":"1.168096552","rc":[{"trd":[[4.6,1576.96]],"batb":[[0,4.5,124.97],[1,4.4,24.03],[2,4.3,43.43]],"batl":[[0,4.6,5.93],[1,4.7,7.19],[2,4.8,5.7]],"ltp":4.6,"tv":5259.68,"id":21580749}],"tv":18725.06}]}
{"op":"mcm","clk":"993885050","pt":1580547323469,"mc":[{"id":"1.168096552","rc":[{"batb":[[1,4.4,27.46]],"batl":[[1,4.7,13.19]],"ltp":4.6,"tv":5259.68,"id":21580749},{"batb":[[1,2.96,12.42]],"ltp":3.0,"tv":7958.4,"id":52106}]}]}
{"op":"mcm","clk":"993885222","pt":1580547325487,"mc":[{"id":"1.168096552","rc":[{"trd":[[3.1,1108.68]],"batl":[[0,3.1,10.27]],"ltp":3.1,"tv":4532.61,"id":18286408},{"batb":[[0,42,1.68],[1,40,2.06],[2,38,2.94]],"ltp":48.0,"tv":153.54,"id":27706761},{"batb":[[0,2.98,45.68]],"ltp":3.0,"tv":7958.4,"id":52106},{"batb":[[0,25,2.82],[1,24,10.37],[2,23,17]],"ltp":25.0,"tv":273.81,"id":24608298}],"tv":18774.06}]}
{"op":"mcm","clk":"993885307","pt":1580547326371,"mc":[{"id":"1.168096552","rc":[{"trd":[[15,66.2]],"batl":[[0,15,3.03],[2,17,1.76]],"ltp":15.0,"tv":605.41,"id":26640937},{"trd":[[4.6,1588.82]],"batb":[[0,4.6,11.41],[1,4.5,124.97],[2,4.4,27.46]],"batl":[[0,4.7,7.19],[1,4.8,5.7],[2,4.9,75.93]],"ltp":4.6,"tv":5271.54,"id":21580749},{"batb":[[1,2.96,5.06]],"ltp":3.0,"tv":7958.4,"id":52106},{"batb":[[1,24,8.37]],"ltp":25.0,"tv":273.81,"id":24608298}],"tv":18795.34}]}
{"op":"mcm","clk":"993885386","pt":1580547327294,"mc":[{"id":"1.168096552","rc":[{"batb":[[2,38,5.29]],"ltp":48.0,"tv":153.54,"id":27706761},{"batb":[[0,25,4.82]],"ltp":25.0,"tv":273.81,"id":24608298}]}]}
{"op":"mcm","clk":"993885496","pt":1580547328493,"mc":[{"id":"1.168096552","rc":[{"batl":[[0,26,5.61]],"ltp":25.0,"tv":273.81,"id":24608298}]}]}
{"op":"mcm","clk":"993885591","pt":1580547329479,"mc":[{"id":"1.168096552","rc":[{"trd":[[3.05,1188.15]],"batb":[[0,3.05,71.28]],"ltp":3.05,"tv":4536.61,"id":18286408}],"tv":18799.34}]}
{"op":"mcm","clk":"993885714","pt":1580547330511,"mc":[{"id":"1.168096552","rc":[{"batl":[[0,4.7,23.19]],"ltp":4.6,"tv":5271.54,"id":21580749}]}]}
{"op":"mcm","clk":"993885794","pt":1580547331289,"mc":[{"id":"1.168096552","rc":[{"batb":[[1,4.5,135.1]],"ltp":4.6,"tv":5271.54,"id":21580749}]}]}
{"op":"mcm","clk":"993886390","pt":1580547337393,"mc":[{"id":"1.168096552","rc":[{"batb":[[0,3.05,80.79]],"ltp":3.05,"tv":4536.61,"id":18286408}]}]}
{"op":"mcm","clk":"993886495","pt":1580547338483,"mc":[{"id":"1.168096552","rc":[{"trd":[[4.6,1611.64]],"batb":[[0,4.5,135.1],[1,4.4,34.78],[2,4.3,43.43]],"ltp":4.6,"tv":5294.36,"id":21580749}],"tv":18822.16}]}
{"op":"mcm","clk":"993886597","pt":1580547339514,"mc":[{"id":"1.168096552","rc":[{"trd":[[3.05,1192.15]],"batb":[[0,3.05,78.79]],"ltp":3.05,"tv":4540.61,"id":18286408},{"trd":[[4.7,1412.58]],"batl":[[0,4.7,13.02]],"ltp":4.7,"tv":5314.7,"id":21580749}],"tv":18846.5}]}
{"op":"mcm","clk":"993886696","pt":1580547340505,"mc":[{"id":"1.168096552","rc":[{"batb":[[0,4.6,2.21],[1,4.5,135.1],[2,4.4,24.03]],"ltp":4.7,"tv":5314.7,"id":21580749}]}]}
{"op":"mcm","clk":"993887164","pt":1580547345480,"mc":[{"id":"1.168096552","rc":[{"batb":[[0,4.6,12.21]],"ltp":4.7,"tv":5314.7,"id":21580749}]}]}
{"op":"mcm","clk":"993887428","pt":1580547348296,"mc":[{"id":"1.168096552","rc":[{"trd":[[4.6,1631.64]],"batb":[[0,4.6,2.21]],"ltp":4.6,"tv":5334.7,"id":21580749}],"tv":18866.5}]}
{"op":"mcm","clk":"993888210","pt":1580547356429,"mc":[{"id":"1.168096552","rc":[{"trd":[[4.7,1431.82]],"batb":[[0,4.6,4.21]],"batl":[[0,4.7,3.4]],"ltp":4.7,"tv":5353.94,"id":21580749}],"tv":18885.74}]}
{"op":"mcm","clk":"993888407","pt":1580547358400,"mc":[{"id":"1.168096552","rc":[{"batl":[[2,17,2.41]],"ltp":15.0,"tv":605.41,"id":26640937},{"trd":[[4.7,1438.62]],"batb":[[0,4.7,5.81],[1,4.6,4.21],[2,4.5,135.1]],"batl":[[0,4.8,5.7],[1,4.9,81.93],[2,5,17.39]],"ltp":4.7,"tv":5360.74,"id":21580749},{"batb":[[0,2.98,40.68]],"ltp":3.0,"tv":7958.4,"id":52106}],"tv":18892.54}]}
{"op":"mcm","clk":"993888509","pt":1580547359432,"mc":[{"id":"1.168096552","rc":[{"batl":[[2,17,1.76]],"ltp":15.0,"tv":605.41,"id":26640937},{"trd":[[4.6,1640.02],[4.7,1450.24]],"batb":[[0,4.5,135.12],[1,4.4,24.03],[2,4.3,41.43]],"ltp":4.6,"tv":5380.74,"id":21580749},{"batl":[[2,34,4.07]],"ltp":25.0,"tv":273.81,"id":24608298}],"tv":18912.54}]}
{"op":"mcm","clk":"993888675","pt":1580547361245,"mc":[{"id":"1.168096552","rc":[{"batb":[[1,4.4,30.85]],"ltp":4.6,"tv":5380.74,"id":21580749},{"batl":[[2,34,8.15]],"ltp":25.0,"tv":273.81,"id":24608298}]}]}
{"op":"mcm","clk":"993889054","pt":1580547365411,"mc":[{"id":"1.168096552","rc":[{"batl":[[2,17,2.41]],"ltp":15.0,"tv":605.41,"id":26640937},{"batb":[[0,4.7,10.17],[1,4.5,135.12],[2,4.4,24.03]],"ltp":4.6,"tv":5380.74,"id":21580749},{"trd":[[2.98,605.79]],"batb":[[0,2.98,37.68],[2,2.94,58.01]],"ltp":2.98,"tv":7964.4,"id":52106}],"tv":18918.54}]}
{"op":"mcm","clk":"993889223","pt":1580547367142,"mc":[{"id":"1.168096552","rc":[{"batl":[[0,4.8,19.7]],"ltp":4.6,"tv":5380.74,"id":21580749}]}]}
{"op":"mcm","clk":"993889341","pt":1580547368434,"mc":[{"id":"1.168096552","rc":[{"trd":[[3.05,1196.15]],"batb":[[0,3.05,76.79]],"ltp":3.05,"tv":4544.61,"id":18286408}],"tv":18922.54}]}
{"op":"mcm","clk":"993889756","pt":1580547372489,"mc":[{"id":"1.168096552","rc":[{"batb":[[0,4.7,20.34],[1,4.6,2.02],[2,4.5,135.1]],"ltp":4.6,"tv":5380.74,"id":21580749},{"batl":[[0,60,2.14],[1,65,7],[2,85,1]],"ltp":48.0,"tv":153.54,"id":27706761}]}]}
{"op":"mcm","clk":"993890336","pt":1580547378419,"mc":[{"id":"1.168096552","rc":[{"batb":[[0,3.05,69.79]],"batl":[[0,3.1,12.27]],"ltp":3.05,"tv":4544.61,"id":18286408},{"batb":[[0,25,21.82],[1,24,10.37],[2,22,4.11]],"ltp":25.0,"tv":273.81,"id":24608298}]}]}
{"op":"mcm","clk":"993891086","pt":1580547386438,"mc":[{"id":"1.168096552","rc":[{"batl":[[0,48,2],[1,60,2.14],[2,65,7]],"ltp":48.0,"tv":153.54,"id":27706761}]}]}
{"op":"mcm","clk":"993891269","pt":1580547388450,"mc":[{"id":"1.168096552","rc":[{"trd":[[3.05,1200.15]],"batb":[[0,3.05,67.79]],"ltp":3.05,"tv":4548.61,"id":18286408}],"tv":18926.54}]}
{"op":"mcm","clk":"993891474","pt":1580547390474,"mc":[{"id":"1.168096552","rc":[{"trd":[[25,19.52]],"batb":[[0,25,12.81]],"ltp":25.0,"tv":291.84,"id":24608298}],"tv":18944.57}]}
{"op":"mcm","clk":"993892024","pt":1580547396472,"mc":[{"id":"1.168096552","rc":[{"batl":[[0,3.1,21.94]],"ltp":3.05,"tv":4548.61,"id":18286408},{"batl":[[1,3.05,41.65]],"ltp":2.98,"tv":7964.4,"id":52106}]}]}
{"op":"mcm","clk":"993892174","pt":1580547398354,"mc":[{"id":"1.168096552","rc":[{"trd":[[3.05,1204.15],[3.1,1118.68]],"batb":[[0,3.05,60.79]],"batl":[[0,3.1,16.94]],"ltp":3.1,"tv":4562.61,"id":18286408}],"tv":18958.57}]}
{"op":"mcm","clk":"993893787","pt":1580547415480,"mc":[{"id":"1.168096552","rc":[{"batb":[[0,4.7,10.17]],"ltp":4.6,"tv":5380.74,"id":21580749}]}]}
{"op":"mcm","clk":"993893934","pt":1580547417492,"mc":[{"id":"1.168096552","rc":[{"trd":[[3.05,1208.15]],"batb":[[0,3.05,58.79]],"ltp":3.05,"tv":4566.61,"id":18286408}],"tv":18962.57}]}
{"op":"mcm","clk":"993894612","pt":1580547425476,"mc":[{"id":"1.168096552","rc":[{"batb":[[1,4.6,12.02]],"ltp":4.6,"tv":5380.74,"id":21580749}]}]}
{"op":"mcm","clk":"993894710","pt":1580547426517,"mc":[{"id":"1.168096552","rc":[{"batl":[[2,17,1.76]],"ltp":15.0,"tv":605.41,"id":26640937},{"trd":[[4.7,1470.58]],"batb":[[0,4.6,12.02],[1,4.5,135.1],[2,4.4,24.03]],"ltp":4.7,"tv":5401.08,"id":21580749}],"tv":18982.91}]}
{"op":"mcm","clk":"993894801","pt":1580547427509,"mc":[{"id":"1.168096552","rc":[{"trd":[[3.05,1212.14]],"batb":[[0,3.05,65.79]],"ltp":3.05,"tv":4570.61,"id":18286408},{"batb":[[1,40,4.06]],"ltp":48.0,"tv":153.54,"id":27706761}],"tv":18986.91}]}
{"op":"mcm","clk":"993894879","pt":1580547428388,"mc":[{"id":"1.168096552","rc":[{"batl":[[0,3.1,5.27]],"ltp":3.05,"tv":4570.61,"id":18286408},{"trd":[[4.8,342.26]],"batl":[[0,4.8,9.74]],"ltp":4.8,"tv":5421.01,"id":21580749},{"batl":[[1,3.05,33]],"ltp":2.98,"tv":7964.4,"id":52106}],"tv":19006.83}]}
{"op":"mcm","clk":"993894963","pt":1580547429425,"mc":[{"id":"1.168096552","rc":[{"batl":[[2,17,2.41]],"ltp":15.0,"tv":605.41,"id":26640937},{"batb":[[0,4.7,4.35],[1,4.6,12.02],[2,4.5,135.1]],"batl":[[0,4.8,15.74]],"ltp":4.8,"tv":5421.01,"id":21580749}]}]}
{"op":"mcm","clk":"993895608","pt":1580547436236,"mc":[{"id":"1.168096552","rc":[{"batl":[[0,4.8,35.74]],"ltp":4.8,"tv":5421.01,"id":21580749}]}]}
{"op":"mcm","clk":"993895831","pt":1580547438490,"mc":[{"id":"1.168096552","rc":[{"trd":[[3.05,1216.14]],"batb":[[0,3.05,63.79]],"ltp":3.05,"tv":4574.61,"id":18286408}],"tv":19010.83}]}
{"op":"mcm","clk":"993896179","pt":1580547442402,"mc":[{"id":"1.168096552","rc":[{"batl":[[2,17,1.76]],"ltp":15.0,"tv":605.41,"id":26640937},{"trd":[[4.7,1479.28]],"batb":[[0,4.6,12.02],[1,4.5,135.1],[2,4.4,24.03]],"batl":[[0,4.7,5.65],[1,4.8,35.74],[2,4.9,81.93]],"ltp":4.7,"tv":5429.71,"id":21580749},{"batb":[[0,2.98,42.68]],"ltp":2.98,"tv":7964.4,"id":52106}],"tv":19019.53}]}
{"op":"mcm","clk":"993896249","pt":1580547443127,"mc":[{"id":"1.168096552","rc":[{"trd":[[4.7,1490.58]],"batl":[[0,4.8,35.74],[1,4.9,81.93],[2,5,17.39]],"ltp":4.7,"tv":5441.01,"id":21580749}],"tv":19030.83}]}
{"op":"mcm","clk":"993896356","pt":1580547444320,"mc":[{"id":"1.168096552","rc":[{"batl":[[0,4.7,12],[1,4.8,35.74],[2,4.9,81.93]],"ltp":4.7,"tv":5441.01,"id":21580749}]}]}
{"op":"mcm","clk":"993896652","pt":1580547447500,"mc":[{"id":"1.168096552","rc":[{"trd":[[3.05,1220.14]],"batb":[[0,3.05,61.79]],"ltp":3.05,"tv":4578.61,"id":18286408},{"trd":[[4.7,1499.62]],"batl":[[0,4.7,7.48]],"ltp":4.7,"tv":5450.05,"id":21580749}],"tv":19043.87}]}
{"op":"mcm","clk":"993896849","pt":1580547449367,"mc":[{"id":"1.168096552","rc":[{"batl":[[1,4.8,15.74]],"ltp":4.7,"tv":5450.05,"id":21580749}]}]}
{"op":"mcm","clk":"993897589","pt":1580547457488,"mc":[{"id":"1.168096552","rc":[{"trd":[[3.05,1224.14]],"batb":[[0,3.05,59.79]],"ltp":3.05,"tv":4582.61,"id":18286408}],"tv":19047.87}]}
{"op":"mcm","clk":"993897773","pt":1580547459430,"mc":[{"id":"1.168096552","rc":[{"trd":[[4.7,1514.58]],"batb":[[0,4.7,2.69],[1,4.6,12.02],[2,4.5,135.1]],"batl":[[0,4.8,15.74],[1,4.9,81.93],[2,5,17.39]],"ltp":4.7,"tv":5465.01,"id":21580749},{"batb":[[0,2.98,37.68]],"ltp":2.98,"tv":7964.4,"id":52106}],"tv":19062.83}]}
{"op":"mcm","clk":"993897891","pt":1580547460520,"mc":[{"id":"1.168096552","rc":[{"trd":[[4.7,1519.96]],"batb":[[0,4.6,12.02],[1,4.5,135.1],[2,4.4,24.03]],"batl":[[0,4.7,18.31],[1,4.8,15.74],[2,4.9,81.93]],"ltp":4.7,"tv":5470.39,"id":21580749}],"tv":19068.21}]}
{"op":"mcm","clk":"993897970","pt":1580547461455,"mc":[{"id":"1.168096552","rc":[{"trd":[[4.7,1527.5]],"batb":[[1,4.5,139.29]],"batl":[[0,4.7,14.54]],"ltp":4.7,"tv":5477.93,"id":21580749},{"batb":[[0,2.98,42.68]],"ltp":2.98,"tv":7964.4,"id":52106}],"tv":19075.75}]}
{"op":"mcm","clk":"993898127","pt":1580547463426,"mc":[{"id":"1.168096552","rc":[{"batb":[[1,4.5,135.1]],"ltp":4.7,"tv":5477.93,"id":21580749}]}]}
{"op":"mcm","clk":"993898246","pt":1580547465229,"mc":[{"id":"1.168096552","rc":[{"batb":[[1,4.5,137.1]],"ltp":4.7,"tv":5477.93,"id":21580749}]}]}
{"op":"mcm","clk":"993898772","pt":1580547471973,"mc":[{"id":"1.168096552","rc":[{"batb":[[1,4.5,138.62]],"ltp":4.7,"tv":5477.93,"id":21580749}]}]}
{"op":"mcm","clk":"993899687","pt":1580547484478,"mc":[{"id":"1.168096552","rc":[{"batb":[[0,4.6,32.02]],"ltp":4.7,"tv":5477.93,"id":21580749}]}]}
{"op":"mcm","clk":"993900202","pt":1580547491883,"mc":[{"id":"1.168096552","rc":[{"batl":[[0,26,5]],"ltp":25.0,"tv":291.84,"id":24608298}]}]}
{"op":"mcm","clk":"993900607","pt":1580547497478,"mc":[{"id":"1.168096552","rc":[{"batl":[[0,3.1,7.27]],"ltp":3.05,"tv":4582.61,"id":18286408},{"batb":[[0,14.5,19.63],[1,14,2]],"ltp":15.0,"tv":605.41,"id":26640937},{"batl":[[0,4.7,20.54]],"ltp":4.7,"tv":5477.93,"id":21580749},{"trd":[[3,1142.81],[3.05,456.5]],"batb":[[0,3,203.98],[1,2.98,42.68],[2,2.96,5.06]],"batl":[[0,3.05,19.65],[1,3.1,65.9],[2,3.15,13.96]],"ltp":3.05,"tv":7995.3,"id":52106}],"tv":19106.65}]}
{"op":"mcm","clk":"993900633","pt":1580547497789,"mc":[{"id":"1.168096552","rc":[{"trd":[[3.05,1228.14]],"batb":[[0,3.05,48.79]],"ltp":3.05,"tv":4586.61,"id":18286408},{"batb":[[2,13.5,12.49]],"ltp":15.0,"tv":605.41,"id":26640937},{"batb":[[0,4.6,30]],"ltp":4.7,"tv":5477.93,"id":21580749}],"tv":19110.65}]}
{"op":"mcm","clk":"993900762","pt":1580547499389,"mc":[{"id":"1.168096552","rc":[{"batb":[[2,13.5,15.11]],"ltp":15.0,"tv":605.41,"id":26640937},{"batb":[[0,3,221.89]],"ltp":3.05,"tv":7995.3,"id":52106}]}]}
{"op":"mcm","clk":"993901059","pt":1580547503501,"mc":[{"id":"1.168096552","rc":[{"batl":[[0,4.7,26.54]],"ltp":4.7,"tv":5477.93,"id":21580749}]}]}
{"op":"mcm","clk":"993901381","pt":1580547507420,"mc":[{"id":"1.168096552","rc":[{"trd":[[3.1,1128.68]],"batl":[[0,3.1,2.27]],"ltp":3.1,"tv":4596.61,"id":18286408}],"tv":19120.65}]}
{"op":"mcm","clk":"993901466","pt":1580547508507,"mc":[{"id":"1.168096552","rc":[{"trd":[[4.6,1660.02]],"batb":[[0,4.6,20]],"ltp":4.6,"tv":5497.93,"id":21580749}],"tv":19140.65}]}
{"op":"mcm","clk":"993902135","pt":1580547516422,"mc":[{"id":"1.168096552","rc":[{"trd":[[3.05,1232.14]],"batb":[[0,3.05,46.79]],"ltp":3.05,"tv":4600.61,"id":18286408},{"batb":[[0,42,2.06]],"ltp":48.0,"tv":153.54,"id":27706761}],"tv":19144.65}]}
{"op":"mcm","clk":"993902483","pt":1580547520497,"mc":[{"id":"1.168096552","rc":[{"batl":[[0,4.7,46.54]],"ltp":4.6,"tv":5497.93,"id":21580749}]}]}
{"op":"mcm","clk":"993902572","pt":1580547521440,"mc":[{"id":"1.168096552","rc":[{"batl":[[0,4.7,56.54]],"ltp":4.6,"tv":5497.93,"id":21580749}]}]}
{"op":"mcm","clk":"993902659","pt":1580547522434,"mc":[{"id":"1.168096552","rc":[{"batl":[[0,4.7,66.54]],"ltp":4.6,"tv":5497.93,"id":21580749}]}]}
{"op":"mcm","clk":"993904288","pt":1580547543418,"mc":[{"id":"1.168096552","rc":[{"batl":[[0,3.05,35.65]],"ltp":3.05,"tv":7995.3,"id":52106}]}]}
{"op":"mcm","clk":"993904644","pt":1580547547477,"mc":[{"id":"1.168096552","rc":[{"trd":[[42,9.03]],"batb":[[0,40,4.12],[1,38,5.29],[2,36,2.47]],"batl":[[0,60,2.14],[1,65,9.17],[2,85,1]],"ltp":42.0,"tv":157.53,"id":27706761}],"tv":19148.65}]}
{"op":"mcm","clk":"993904790","pt":1580547549278,"mc":[{"id":"1.168096552","rc":[{"batl":[[1,65,7]],"ltp":42.0,"tv":157.53,"id":27706761}]}]}
{"op":"mcm","clk":"993904937","pt":1580547551268,"mc":[{"id":"1.168096552","rc":[{"trd":[[4.7,1547.92]],"batl":[[0,4.7,56.33]],"ltp":4.7,"tv":5518.35,"id":21580749}],"tv":19169.07}]}
{"op":"mcm","clk":"993905016","pt":1580547552469,"mc":[{"id":"1.168096552","rc":[{"trd":[[4.6,1680.02]],"batb":[[0,4.6,10],[2,4.4,26.03]],"ltp":4.6,"tv":5538.35,"id":21580749}],"tv":19189.07}]}
{"op":"mcm","clk":"993905242","pt":1580547555280,"mc":[{"id":"1.168096552","rc":[{"batl":[[0,4.7,64.33]],"ltp":4.6,"tv":5538.35,"id":21580749}]}]}
{"op":"mcm","clk":"993905556","pt":1580547559493,"mc":[{"id":"1.168096552","rc":[{"batb":[[0,3.05,56.79]],"ltp":3.05,"tv":4600.61,"id":18286408},{"trd":[[4.6,1700.02]],"batb":[[0,4.5,138.62],[1,4.4,40.73],[2,4.3,43.43]],"ltp":4.6,"tv":5558.35,"id":21580749}],"tv":19209.07}]}
{"op":"mcm","clk":"993905644","pt":1580547560484,"mc":[{"id":"1.168096552","rc":[{"batb":[[0,4.5,140.13]],"batl":[[0,4.6,10],[1,4.7,64.33],[2,4.8,15.74]],"ltp":4.6,"tv":5558.35,"id":21580749}]}]}
{"op":"mcm","clk":"993905727","pt":1580547561518,"mc":[{"id":"1.168096552","rc":[{"trd":[[3.1,1129.22]],"batb":[[0,3.05,46.79]],"batl":[[0,3.1,3.11]],"ltp":3.1,"tv":4601.15,"id":18286408},{"trd":[[4.6,1720.02],[4.7,1552.92]],"batl":[[0,4.7,61.83],[1,4.8,15.74],[2,4.9,81.93]],"ltp":4.7,"tv":5583.35,"id":21580749}],"tv":19234.61}]}
{"op":"mcm","clk":"993905961","pt":1580547564492,"mc":[{"id":"1.168096552","rc":[{"batb":[[0,40,4.06]],"ltp":42.0,"tv":157.53,"id":27706761}]}]}
{"op":"mcm","clk":"993906030","pt":1580547565272,"mc":[{"id":"1.168096552","rc":[{"batl":[[1,4.8,17.25]],"ltp":4.7,"tv":5583.35,"id":21580749}]}]}
{"op":"mcm","clk":"993906426","pt":1580547570507,"mc":[{"id":"1.168096552","rc":[{"batl":[[0,4.6,24],[1,4.7,61.83],[2,4.8,17.25]],"ltp":4.7,"tv":5583.35,"id":21580749}]}]}
{"op":"mcm","clk":"993906502","pt":1580547571495,"mc":[{"id":"1.168096552","rc":[{"trd":[[4.6,1729.9]],"batl":[[0,4.6,19.06],[1,4.7,71.74]],"ltp":4.6,"tv":5593.23,"id":21580749}],"tv":19244.49}]}
{"op":"mcm","clk":"993907124","pt":1580547578472,"mc":[{"id":"1.168096552","rc":[{"batb":[[1,4.4,29.71]],"ltp":4.6,"tv":5593.23,"id":21580749}]}]}
{"op":"mcm","clk":"993907206","pt":1580547579504,"mc":[{"id":"1.168096552","rc":[{"batl":[[2,28,2]],"ltp":25.0,"tv":291.84,"id":24608298}]}]}
{"op":"mcm","clk":"993907308","pt":1580547580498,"mc":[{"id":"1.168096552","rc":[{"batl":[[0,4.6,29.19]],"ltp":4.6,"tv":5593.23,"id":21580749}]}]}
{"op":"mcm","clk":"993907384","pt":1580547581428,"mc":[{"id":"1.168096552","rc":[{"batl":[[0,4.6,39.19],[1,4.7,61.74]],"ltp":4.6,"tv":5593.23,"id":21580749},{"trd":[[40,41.14]],"batb":[[0,40,2.06]],"ltp":40.0,"tv":161.53,"id":27706761}],"tv":19248.49}]}
{"op":"mcm","clk":"993907454","pt":1580547582209,"mc":[{"id":"1.168096552","rc":[{"batl":[[0,4.6,49.19],[1,4.7,51.74]],"ltp":4.6,"tv":5593.23,"id":21580749}]}]}
{"op":"mcm","clk":"993907551","pt":1580547583410,"mc":[{"id":"1.168096552","rc":[{"batl":[[0,4.6,69.19],[1,4.7,31.74]],"ltp":4.6,"tv":5593.23,"id":21580749}]}]}
{"op":"mcm","clk":"993907702","pt":1580547585501,"mc":[{"id":"1.168096552","rc":[{"batb":[[1,4.4,26.03]],"ltp":4.6,"tv":5593.23,"id":21580749}]}]}
{"op":"mcm","clk":"993908185","pt":1580547591800,"mc":[{"id":"1.168096552","rc":[{"trd":[[4.5,868.86]],"batb":[[0,4.5,131.73]],"ltp":4.5,"tv":5610.03,"id":21580749}],"tv":19265.29}]}
{"op":"mcm","clk":"993909441","pt":1580547604475,"mc":[{"id":"1.168096552","rc":[{"trd":[[4.5,870.86]],"batb":[[0,4.5,130.73]],"ltp":4.5,"tv":5612.03,"id":21580749},{"trd":[[3,1144.81]],"batb":[[0,3,220.89]],"ltp":3.0,"tv":7997.3,"id":52106}],"tv":19269.29}]}
{"op":"mcm","clk":"993909576","pt":1580547605426,"mc":[{"id":"1.168096552","rc":[{"trd":[[3,1146.81]],"batb":[[0,3,219.89]],"ltp":3.0,"tv":7999.3,"id":52106}],"tv":19271.29}]}
{"op":"mcm","clk":"993909686","pt":1580547606435,"mc":[{"id":"1.168096552","rc":[{"trd":[[4.5,871.86]],"batb":[[0,4.5,130.23]],"ltp":4.5,"tv":5613.03,"id":21580749},{"trd":[[3,1147.81]],"batb":[[0,3,219.39]],"ltp":3.0,"tv":8000.3,"id":52106}],"tv":19273.29}]}
{"op":"mcm","clk":"993910345","pt":1580547612454,"mc":[{"id":"1.168096552","rc":[{"batb":[[2,2.98,45]],"ltp":3.1,"tv":4601.15,"id":18286408},{"trd":[[4.6,1750.7]],"batb":[[2,4.3,46.43]],"batl":[[0,4.6,58.79]],"ltp":4.6,"tv":5633.83,"id":21580749},{"batb":[[0,40,4.06]],"ltp":40.0,"tv":161.53,"id":27706761},{"batl":[[1,3.1,67.9],[2,3.15,15.96]],"ltp":3.0,"tv":8000.3,"id":52106}],"tv":19294.09}]}
{"op":"mcm","clk":"993910540","pt":1580547614441,"mc":[{"id":"1.168096552","rc":[{"batl":[[0,4.6,48.66],[1,4.7,41.65]],"ltp":4.6,"tv":5633.83,"id":21580749}]}]}
{"op":"mcm","clk":"993910639","pt":1580547615483,"mc":[{"id":"1.168096552","rc":[{"trd":[[14.5,109.8]],"batb":[[0,14.5,17.63]],"ltp":14.5,"tv":609.41,"id":26640937}],"tv":19298.09}]}
{"op":"mcm","clk":"993912232","pt":1580547633497,"mc":[{"id":"1.168096552","rc":[{"trd":[[4.6,1829.3]],"batl":[[0,4.6,9.36],[1,4.7,31.74],[2,4.8,26.96]],"ltp":4.6,"tv":5712.43,"id":21580749}],"tv":19376.69}]}
{"op":"mcm","clk":"993912399","pt":1580547635490,"mc":[{"id":"1.168096552","rc":[{"batl":[[1,4.7,21.83],[2,4.8,36.67]],"ltp":4.6,"tv":5712.43,"id":21580749}]}]}
{"op":"mcm","clk":"993913808","pt":1580547651484,"mc":[{"id":"1.168096552","rc":[{"trd":[[4.6,1848.02]],"batb":[[0,4.6,27.71],[1,4.5,130.23],[2,4.4,26.03]],"batl":[[0,4.7,21.83],[1,4.8,36.67],[2,4.9,62.91]],"ltp":4.6,"tv":5731.15,"id":21580749}],"tv":19395.41}]}
{"op":"mcm","clk":"993915547","pt":1580547668339,"mc":[{"id":"1.168096552","rc":[{"batb":[[1,4.5,80.23]],"ltp":4.6,"tv":5731.15,"id":21580749}]}]}
{"op":"mcm","clk":"993915842","pt":1580547670412,"mc":[{"id":"1.168096552","rc":[{"trd":[[4.6,1868.02]],"batb":[[0,4.6,17.71]],"ltp":4.6,"tv":5751.15,"id":21580749}],"tv":19415.41}]}
{"op":"mcm","clk":"993916553","pt":1580547676362,"mc":[{"id":"1.168096552","rc":[{"batl":[[1,3.15,87.82]],"ltp":3.1,"tv":4601.15,"id":18286408},{"trd":[[4.7,1573.34]],"batl":[[0,4.7,18.62]],"ltp":4.7,"tv":5771.57,"id":21580749}],"tv":19435.83}]}
{"op":"mcm","clk":"993916744","pt":1580547678513,"mc":[{"id":"1.168096552","rc":[{"trd":[[4.7,1610.58]],"batb":[[0,4.7,3.18],[1,4.6,17.71],[2,4.5,80.23]],"batl":[[0,4.8,36.67],[1,4.9,62.91],[2,5,17.39]],"ltp":4.7,"tv":5808.81,"id":21580749}],"tv":19473.07}]}
{"op":"mcm","clk":"993916798","pt":1580547679083,"mc":[{"id":"1.168096552","rc":[{"batl":[[2,3.2,19]],"ltp":3.1,"tv":4601.15,"id":18286408},{"trd":[[4.7,1616.94]],"batb":[[0,4.6,17.71],[1,4.5,80.23],[2,4.4,26.03]],"batl":[[0,4.7,11.39],[1,4.8,36.67],[2,4.9,62.91]],"ltp":4.7,"tv":5815.17,"id":21580749}],"tv":19479.43}]}
{"op":"mcm","clk":"993917793","pt":1580547689441,"mc":[{"id":"1.168096552","rc":[{"trd":[[4.7,1625.78]],"batl":[[0,4.7,6.97]],"ltp":4.7,"tv":5824.01,"id":21580749},{"trd":[[25,23.52]],"batb":[[0,25,10.81]],"batl":[[2,34,8.15]],"ltp":25.0,"tv":295.84,"id":24608298}],"tv":19492.27}]}
{"op":"mcm","clk":"993918651","pt":1580547697440,"mc":[{"id":"1.168096552","rc":[{"batb":[[0,40,4.47]],"ltp":40.0,"tv":161.53,"id":27706761}]}]}
{"op":"mcm","clk":"993919009","pt":1580547700264,"mc":[{"id":"1.168096552","rc":[{"trd":[[4.7,1639.38]],"batl":[[0,4.8,36.84],[1,4.9,62.91],[2,5,17.39]],"ltp":4.7,"tv":5837.61,"id":21580749}],"tv":19505.87}]}
{"op":"mcm","clk":"993919409","pt":1580547703419,"mc":[{"id":"1.168096552","rc":[{"trd":[[4.6,1888.02]],"batb":[[0,4.6,7.71]],"ltp":4.6,"tv":5857.61,"id":21580749}],"tv":19525.87}]}
{"op":"mcm","clk":"993919511","pt":1580547704363,"mc":[{"id":"1.168096552","rc":[{"batl":[[0,3.05,85.65]],"ltp":3.0,"tv":8000.3,"id":52106}]}]}
{"op":"mcm","clk":"993919793","pt":1580547707301,"mc":[{"id":"1.168096552","rc":[{"trd":[[3.05,1252.16]],"batb":[[0,3.05,36.78]],"ltp":3.05,"tv":4621.17,"id":18286408}],"tv":19545.89}]}
{"op":"mcm","clk":"993920293","pt":1580547711388,"mc":[{"id":"1.168096552","rc":[{"batb":[[0,4.6,19.71]],"batl":[[0,4.7,5],[1,4.8,36.67],[2,4.9,62.91]],"ltp":4.6,"tv":5857.61,"id":21580749},{"batl":[[0,3.05,90.65]],"ltp":3.0,"tv":8000.3,"id":52106}]}]}
{"op":"mcm","clk":"993920998","pt":1580547715279,"mc":[{"id":"1.168096552","rc":[{"trd":[[3.05,465.5]],"batl":[[0,3.05,86.15]],"ltp":3.05,"tv":8009.3,"id":52106}],"tv":19554.89}]}
{"op":"mcm","clk":"993921783","pt":1580547722517,"mc":[{"id":"1.168096552","rc":[{"trd":[[4.7,1648.94]],"batb":[[0,4.6,22.71],[1,4.5,82.23],[2,4.4,28.03]],"batl":[[0,4.7,4]],"ltp":4.7,"tv":5867.17,"id":21580749},{"batb":[[0,40,2.41]],"ltp":40.0,"tv":161.53,"id":27706761}],"tv":19564.45}]}
{"op":"mcm","clk":"993923760","pt":1580547739437,"mc":[{"id":"1.168096552","rc":[{"trd":[[3.05,1298.83]],"batb":[[0,3.05,13.45]],"ltp":3.05,"tv":4667.83,"id":18286408}],"tv":19611.12}]}
{"op":"mcm","clk":"993923784","pt":1580547739701,"mc":[{"id":"1.168096552","rc":[{"trd":[[3.05,1305.55]],"batb":[[0,3.05,18.58]],"ltp":3.05,"tv":4674.55,"id":18286408}],"tv":19617.83}]}
{"op":"mcm","clk":"993924290","pt":1580547743511,"mc":[{"id":"1.168096552","rc":[{"trd":[[3.05,475.44]],"batl":[[0,3.05,81.18]],"ltp":3.05,"tv":8019.24,"id":52106}],"tv":19627.77}]}
{"op":"mcm","clk":"993924494","pt":1580547745507,"mc":[{"id":"1.168096552","rc":[{"trd":[[4.7,1664.94]],"batb":[[0,4.7,32],[1,4.6,22.71],[2,4.5,82.23]],"batl":[[0,4.8,36.67],[1,4.9,62.91],[2,5,17.39]],"ltp":4.7,"tv":5883.17,"id":21580749},{"batb":[[0,3,214.39]],"ltp":3.05,"tv":8019.24,"id":52106}],"tv":19643.77}]}
{"op":"mcm","clk":"993924614","pt":1580547746505,"mc":[{"id":"1.168096552","rc":[{"batb":[[2,13.5,3.06]],"ltp":14.5,"tv":609.41,"id":26640937},{"batb":[[1,38,2.94]],"ltp":40.0,"tv":161.53,"id":27706761},{"batb":[[2,20,1.46]],"ltp":25.0,"tv":295.84,"id":24608298}]}]}
{"op":"mcm","clk":"993925564","pt":1580547756452,"mc":[{"id":"1.168096552","rc":[{"batl":[[0,3.1,14.69]],"ltp":3.05,"tv":4674.55,"id":18286408},{"trd":[[4.8,362.26]],"batl":[[0,4.8,26.67]],"ltp":4.8,"tv":5903.17,"id":21580749}],"tv":19663.77}]}
{"op":"mcm","clk":"993925662","pt":1580547757447,"mc":[{"id":"1.168096552","rc":[{"batb":[[0,4.7,41.95]],"batl":[[0,4.8,23.67],[1,4.9,59.91]],"ltp":4.8,"tv":5903.17,"id":21580749}]}]}
{"op":"mcm","clk":"993926212","pt":1580547762438,"mc":[{"id":"1.168096552","rc":[{"batl":[[0,55,4.6],[1,60,2.14],[2,65,7]],"ltp":40.0,"tv":161.53,"id":27706761}]}]}
{"op":"mcm","clk":"993926333","pt":1580547763436,"mc":[{"id":"1.168096552","rc":[{"batl":[[0,50,2.23],[1,55,4.6],[2,60,2.14]],"ltp":40.0,"tv":161.53,"id":27706761},{"batb":[[0,3,219.39]],"ltp":3.05,"tv":8019.24,"id":52106}]}]}
{"op":"mcm","clk":"993926446","pt":1580547764474,"mc":[{"id":"1.168096552","rc":[{"batl":[[1,3.1,49]],"ltp":3.05,"tv":8019.24,"id":52106}]}]}
{"op":"mcm","clk":"993926555","pt":1580547765361,"mc":[{"id":"1.168096552","rc":[{"batb":[[1,3,121.63]],"ltp":3.05,"tv":4674.55,"id":18286408}]}]}
{"op":"mcm","clk":"993926661","pt":1580547766464,"mc":[{"id":"1.168096552","rc":[{"trd":[[4.7,1684.94]],"batb":[[0,4.7,31.95]],"ltp":4.7,"tv":5923.17,"id":21580749}],"tv":19683.77}]}
{"op":"mcm","clk":"993926760","pt":1580547767450,"mc":[{"id":"1.168096552","rc":[{"trd":[[4.7,1687.97]],"batb":[[0,4.7,30.44]],"ltp":4.7,"tv":5926.19,"id":21580749}],"tv":19686.8}]}
{"op":"mcm","clk":"993926957","pt":1580547769475,"mc":[{"id":"1.168096552","rc":[{"batb":[[1,4.6,24.22]],"ltp":4.7,"tv":5926.19,"id":21580749}]}]}
{"op":"mcm","clk":"993927522","pt":1580547775456,"mc":[{"id":"1.168096552","rc":[{"trd":[[4.8,391.84]],"batl":[[0,4.8,11.88]],"ltp":4.8,"tv":5955.77,"id":21580749}],"tv":19716.38}]}
{"op":"mcm","clk":"993927623","pt":1580547776447,"mc":[{"id":"1.168096552","rc":[{"trd":[[4.8,395.84]],"batl":[[0,4.8,3],[1,4.9,66.65]],"ltp":4.8,"tv":5959.77,"id":21580749}],"tv":19720.38}]}
{"op":"mcm","clk":"993927724","pt":1580547777374,"mc":[{"id":"1.168096552","rc":[{"batl":[[0,3.1,39.89]],"ltp":3.05,"tv":4674.55,"id":18286408},{"batb":[[0,4.7,43.44]],"ltp":4.8,"tv":5959.77,"id":21580749}]}]}
{"op":"mcm","clk":"993928174","pt":1580547781484,"mc":[{"id":"1.168096552","rc":[{"batl":[[1,60,2.14],[2,65,5]],"ltp":40.0,"tv":161.53,"id":27706761}]}]}
{"op":"mcm","clk":"993928607","pt":1580547785476,"mc":[{"id":"1.168096552","rc":[{"trd":[[4.8,401.84]],"batb":[[0,4.8,31],[1,4.7,43.44],[2,4.6,24.22]],"batl":[[0,4.9,66.65],[1,5,17.39],[2,5.1,11.47]],"ltp":4.8,"tv":5965.77,"id":21580749}],"tv":19726.38}]}
{"op":"mcm","clk":"993928685","pt":1580547786204,"mc":[{"id":"1.168096552","rc":[{"batl":[[0,15,5.03]],"ltp":14.5,"tv":609.41,"id":26640937},{"trd":[[4.8,407.84]],"batb":[[0,4.8,28],[1,4.7,48.44],[2,4.6,26.22]],"batl":[[1,5,20.39]],"ltp":4.8,"tv":5971.77,"id":21580749},{"batb":[[0,3,214.39]],"ltp":3.05,"tv":8019.24,"id":52106},{"batb":[[0,25,8.81]],"batl":[[0,26,7]],"ltp":25.0,"tv":295.84,"id":24608298}],"tv":19732.38}]}
{"op":"mcm","clk":"993929338","pt":1580547792183,"mc":[{"id":"1.168096552","rc":[{"batl":[[0,3.05,89.18]],"ltp":3.05,"tv":8019.24,"id":52106}]}]}
{"op":"mcm","clk":"993929677","pt":1580547795520,"mc":[{"id":"1.168096552","rc":[{"trd":[[4.8,427.84]],"batb":[[0,4.8,18]],"ltp":4.8,"tv":5991.77,"id":21580749}],"tv":19752.38}]}
{"op":"mcm","clk":"993929971","pt":1580547798424,"mc":[{"id":"1.168096552","rc":[{"batb":[[0,4.8,28]],"ltp":4.8,"tv":5991.77,"id":21580749}]}]}
{"op":"mcm","clk":"993930186","pt":1580547800488,"mc":[{"id":"1.168096552","rc":[{"trd":[[3.05,1342.69]],"batb":[[0,3,121.63],[1,2.98,45],[2,2.96,36]],"batl":[[0,3.05,18.93],[1,3.1,39.89],[2,3.15,87.82]],"ltp":3.05,"tv":4711.7,"id":18286408},{"trd":[[4.8,465.73]],"batb":[[0,4.8,9.04]],"ltp":4.8,"tv":6029.67,"id":21580749}],"tv":19827.42}]}
{"op":"mcm","clk":"993930274","pt":1580547801418,"mc":[{"id":"1.168096552","rc":[{"batb":[[0,3,112.63]],"batl":[[0,3.05,22.93],[1,3.1,51.62]],"ltp":3.05,"tv":4711.7,"id":18286408},{"batl":[[0,65,5.41],[1,85,1],[2,110,2]],"ltp":40.0,"tv":161.53,"id":27706761},{"batb":[[0,3,219.39]],"ltp":3.05,"tv":8019.24,"id":52106},{"batb":[[0,25,10.81]],"batl":[[0,26,5],[2,34,12.22]],"ltp":25.0,"tv":295.84,"id":24608298}]}]}
{"op":"mcm","clk":"993930386","pt":1580547802515,"mc":[{"id":"1.168096552","rc":[{"trd":[[4.9,253.02]],"batb":[[0,4.8,94.54],[1,4.7,27.95]],"batl":[[0,4.9,51.53]],"ltp":4.9,"tv":6046.43,"id":21580749},{"batl":[[2,100,2.43]],"ltp":40.0,"tv":161.53,"id":27706761}],"tv":19844.18}]}
{"op":"mcm","clk":"993930471","pt":1580547803508,"mc":[{"id":"1.168096552","rc":[{"batl":[[0,60,2.53],[1,65,5],[2,85,1]],"ltp":40.0,"tv":161.53,"id":27706761}]}]}
{"op":"mcm","clk":"993930748","pt":1580547806444,"mc":[{"id":"1.168096552","rc":[{"trd":[[4.8,485.73]],"batb":[[0,4.8,84.54]],"ltp":4.8,"tv":6066.43,"id":21580749}],"tv":19864.18}]}
{"op":"mcm","clk":"993930926","pt":1580547808514,"mc":[{"id":"1.168096552","rc":[{"batl":[[1,5,27]],"ltp":4.8,"tv":6066.43,"id":21580749}]}]}
{"op":"mcm","clk":"993931575","pt":1580547815436,"mc":[{"id":"1.168096552","rc":[{"trd":[[3.05,500.5]],"batl":[[0,3.05,76.65]],"ltp":3.05,"tv":8044.3,"id":52106}],"tv":19889.24}]}
{"op":"mcm","clk":"993931986","pt":1580547819423,"mc":[{"id":"1.168096552","rc":[{"batl":[[0,3.05,4]],"ltp":3.05,"tv":4711.7,"id":18286408},{"trd":[[4.8,505.73]],"batb":[[0,4.8,74.54]],"ltp":4.8,"tv":6086.43,"id":21580749}],"tv":19909.24}]}
{"op":"mcm","clk":"993932038","pt":1580547819942,"mc":[{"id":"1.168096552","rc":[{"batl":[[2,34,8.15]],"ltp":25.0,"tv":295.84,"id":24608298}]}]}
{"op":"mcm","clk":"993932485","pt":1580547824322,"mc":[{"id":"1.168096552","rc":[{"batl":[[0,60,2.2]],"ltp":40.0,"tv":161.53,"id":27706761}]}]}
{"op":"mcm","clk":"993933073","pt":1580547830346,"mc":[{"id":"1.168096552","rc":[{"trd":[[3,769.88]],"batb":[[0,3,92.64]],"ltp":3.0,"tv":4751.69,"id":18286408},{"trd":[[4.8,525.73]],"batb":[[0,4.8,64.54]],"ltp":4.8,"tv":6106.43,"id":21580749}],"tv":19969.23}]}
{"op":"mcm","clk":"993933350","pt":1580547833260,"mc":[{"id":"1.168096552","rc":[{"trd":[[4.8,545.73]],"batb":[[0,4.8,54.54]],"ltp":4.8,"tv":6126.43,"id":21580749}],"tv":19989.23}]}
{"op":"mcm","clk":"993933586","pt":1580547835454,"mc":[{"id":"1.168096552","rc":[{"batb":[[0,4.8,74.54]],"ltp":4.8,"tv":6126.43,"id":21580749}]}]}
{"op":"mcm","clk":"993934281","pt":1580547842281,"mc":[{"id":"1.168096552","rc":[{"trd":[[4.8,565.73]],"batb":[[0,4.8,64.54]],"ltp":4.8,"tv":6146.43,"id":21580749}],"tv":20009.23}]}
{"op":"mcm","clk":"993934973","pt":1580547848462,"mc":[{"id":"1.168096552","rc":[{"trd":[[3,789.88]],"batb":[[0,3,82.64]],"ltp":3.0,"tv":4771.69,"id":18286408}],"tv":20029.23}]}
{"op":"mcm","clk":"993935673","pt":1580547854399,"mc":[{"id":"1.168096552","rc":[{"trd":[[4.8,585.73]],"batb":[[0,4.8,54.54]],"ltp":4.8,"tv":6166.43,"id":21580749}],"tv":20049.23}]}
{"op":"mcm","clk":"993935780","pt":1580547855482,"mc":[{"id":"1.168096552","rc":[{"trd":[[4.8,602.54]],"batb":[[0,4.8,46.14]],"ltp":4.8,"tv":6183.23,"id":21580749}],"tv":20066.03}]}
{"op":"mcm","clk":"993936441","pt":1580547861389,"mc":[{"id":"1.168096552","rc":[{"batl":[[0,4.9,71.53]],"ltp":4.8,"tv":6183.23,"id":21580749}]}]}
{"op":"mcm","clk":"993936838","pt":1580547865504,"mc":[{"id":"1.168096552","rc":[{"trd":[[4.8,639.76]],"batb":[[0,4.8,27.53]],"ltp":4.8,"tv":6220.45,"id":21580749}],"tv":20103.25}]}
{"op":"mcm","clk":"993936928","pt":1580547866487,"mc":[{"id":"1.168096552","rc":[{"trd":[[4.8,659.76]],"batb":[[0,4.8,17.53]],"ltp":4.8,"tv":6240.45,"id":21580749}],"tv":20123.25}]}
{"op":"mcm","clk":"993937531","pt":1580547872512,"mc":[{"id":"1.168096552","rc":[{"batl":[[0,3.05,14]],"ltp":3.0,"tv":4771.69,"id":18286408}]}]}
{"op":"mcm","clk":"993938210","pt":1580547879511,"mc":[{"id":"1.168096552","rc":[{"trd":[[4.8,679.76]],"batb":[[0,4.8,7.53]],"ltp":4.8,"tv":6260.45,"id":21580749}],"tv":20143.25}]}
{"op":"mcm","clk":"993938378","pt":1580547881221,"mc":[{"id":"1.168096552","rc":[{"batb":[[0,3,244.6]],"ltp":3.05,"tv":8044.3,"id":52106}]}]}
{"op":"mcm","clk":"993939081","pt":1580547888420,"mc":[{"id":"1.168096552","rc":[{"batl":[[0,15,3.03]],"ltp":14.5,"tv":609.41,"id":26640937},{"trd":[[4.8,699.76]],"batb":[[0,4.7,27.95],[1,4.6,26.22],[2,4.5,82.23]],"batl":[[0,4.8,3],[1,4.9,71.53],[2,5,27]],"ltp":4.8,"tv":6280.45,"id":21580749},{"batl":[[0,3.05,71.65]],"ltp":3.05,"tv":8044.3,"id":52106}],"tv":20163.25}]}
{"op":"mcm","clk":"993939192","pt":1580547889353,"mc":[{"id":"1.168096552","rc":[{"batb":[[2,13.5,14.35]],"ltp":14.5,"tv":609.41,"id":26640937},{"trd":[[4.8,705.76],[4.9,257.02]],"batl":[[0,4.9,69.53],[1,5,27],[2,5.1,11.47]],"ltp":4.9,"tv":6290.45,"id":21580749}],"tv":20173.25}]}
{"op":"mcm","clk":"993939785","pt":1580547895433,"mc":[{"id":"1.168096552","rc":[{"batb":[[1,2.98,41]],"ltp":3.0,"tv":4771.69,"id":18286408},{"trd":[[4.8,709.76]],"batl":[[0,4.8,1.3],[1,4.9,89.53],[2,5,27]],"ltp":4.8,"tv":6294.45,"id":21580749},{"batl":[[1,3.1,52],[2,3.15,18.96]],"ltp":3.05,"tv":8044.3,"id":52106}],"tv":20177.25}]}
{"op":"mcm","clk":"993939887","pt":1580547896479,"mc":[{"id":"1.168096552","rc":[{"trd":[[4.8,712.36]],"batl":[[0,4.9,89.53],[1,5,27],[2,5.1,11.47]],"ltp":4.8,"tv":6297.05,"id":21580749}],"tv":20179.85}]}
{"op":"mcm","clk":"993939973","pt":1580547897365,"mc":[{"id":"1.168096552","rc":[{"batb":[[2,4.5,85.23]],"batl":[[0,4.8,10.19],[1,4.9,89.53],[2,5,20.39]],"ltp":4.8,"tv":6297.05,"id":21580749}]}]}
{"op":"mcm","clk":"993940376","pt":1580547901455,"mc":[{"id":"1.168096552","rc":[{"batb":[[0,4.7,22.95]],"batl":[[0,4.8,20.19]],"ltp":4.8,"tv":6297.05,"id":21580749}]}]}
{"op":"mcm","clk":"993940900","pt":1580547906454,"mc":[{"id":"1.168096552","rc":[{"trd":[[4.7,1707.97]],"batb":[[0,4.7,12.95]],"ltp":4.7,"tv":6317.05,"id":21580749}],"tv":20199.85}]}
{"op":"mcm","clk":"993941303","pt":1580547910350,"mc":[{"id":"1.168096552","rc":[{"trd":[[4.8,732.36]],"batl":[[0,4.8,10.19]],"ltp":4.8,"tv":6337.06,"id":21580749}],"tv":20219.86}]}
{"op":"mcm","clk":"993941768","pt":1580547914484,"mc":[{"id":"1.168096552","rc":[{"batl":[[0,4.8,26.19]],"ltp":4.8,"tv":6337.06,"id":21580749},{"trd":[[25,27.52]],"batb":[[0,25,8.81]],"ltp":25.0,"tv":299.84,"id":24608298}],"tv":20223.86}]}
{"op":"mcm","clk":"993943467","pt":1580547931494,"mc":[{"id":"1.168096552","rc":[{"batb":[[0,3,87.54]],"ltp":3.0,"tv":4771.69,"id":18286408}]}]}
{"op":"mcm","clk":"993944210","pt":1580547939428,"mc":[{"id":"1.168096552","rc":[{"trd":[[3.05,1363.69]],"batl":[[0,3.05,7.5]],"ltp":3.05,"tv":4792.69,"id":18286408},{"trd":[[4.7,1727.97]],"batb":[[0,4.7,2.95]],"batl":[[0,4.8,28.19]],"ltp":4.7,"tv":6357.06,"id":21580749},{"trd":[[3,1177.81]],"batb":[[0,3,229.6]],"ltp":3.0,"tv":8074.3,"id":52106}],"tv":20294.86}]}
{"op":"mcm","clk":"993945444","pt":1580547950505,"mc":[{"id":"1.168096552","rc":[{"batb":[[1,14,4]],"ltp":14.5,"tv":609.41,"id":26640937}]}]}
{"op":"mcm","clk":"993945652","pt":1580547952510,"mc":[{"id":"1.168096552","rc":[{"trd":[[3,819.88]],"batb":[[0,3,72.55]],"ltp":3.0,"tv":4822.68,"id":18286408}],"tv":20324.85}]}
{"op":"mcm","clk":"993946270","pt":1580547959448,"mc":[{"id":"1.168096552","rc":[{"batl":[[0,3.05,9.5]],"ltp":3.0,"tv":4822.68,"id":18286408}]}]}
{"op":"mcm","clk":"993946525","pt":1580547962167,"mc":[{"id":"1.168096552","rc":[{"batl":[[0,4.8,38.19]],"ltp":4.7,"tv":6357.06,"id":21580749}]}]}
{"op":"mcm","clk":"993947538","pt":1580547972464,"mc":[{"id":"1.168096552","rc":[{"batl":[[0,4.8,51.19]],"ltp":4.7,"tv":6357.06,"id":21580749}]}]}
{"op":"mcm","clk":"993947628","pt":1580547973446,"mc":[{"id":"1.168096552","rc":[{"trd":[[3.05,1382.69]],"batb":[[0,3.05,9.4],[1,3,80.55],[2,2.98,41]],"batl":[[0,3.1,51.62],[1,3.15,87.82],[2,3.2,19]],"ltp":3.05,"tv":4841.68,"id":18286408},{"batl":[[0,3.05,79.65]],"ltp":3.0,"tv":8074.3,"id":52106}],"tv":20343.85}]}
{"op":"mcm","clk":"993947857","pt":1580547975490,"mc":[{"id":"1.168096552","rc":[{"batb":[[2,13.5,3.06]],"ltp":14.5,"tv":609.41,"id":26640937}]}]}
{"op":"mcm","clk":"993948065","pt":1580547977364,"mc":[{"id":"1.168096552","rc":[{"batb":[[2,2.98,43]],"ltp":3.05,"tv":4841.68,"id":18286408}]}]}
{"op":"mcm","clk":"993948734","pt":1580547984288,"mc":[{"id":"1.168096552","rc":[{"trd":[[4.7,1733.87]],"batb":[[0,4.6,26.22],[1,4.5,85.23],[2,4.4,31.03]],"batl":[[0,4.7,10.05],[1,4.8,51.19],[2,4.9,89.53]],"ltp":4.7,"tv":6362.96,"id":21580749},{"batl":[[0,3.05,71.65]],"ltp":3.0,"tv":8074.3,"id":52106}],"tv":20349.75}]}
{"op":"mcm","clk":"993949886","pt":1580547996491,"mc":[{"id":"1.168096552","rc":[{"trd":[[4.7,1753.97],[4.8,732.38]],"batl":[[0,4.8,51.18],[1,4.9,89.53],[2,5,20.39]],"ltp":4.8,"tv":6383.08,"id":21580749}],"tv":20369.87}]}
{"op":"mcm","clk":"993950388","pt":1580548002501,"mc":[{"id":"1.168096552","rc":[{"batb":[[0,3.05,11.4]],"ltp":3.05,"tv":4841.68,"id":18286408}]}]}
{"op":"mcm","clk":"993951871","pt":1580548019398,"mc":[{"id":"1.168096552","rc":[{"batl":[[1,4.9,69.53]],"ltp":4.8,"tv":6383.08,"id":21580749}]}]}
{"op":"mcm","clk":"993951934","pt":1580548020339,"mc":[{"id":"1.168096552","rc":[{"batl":[[1,4.9,49.53]],"ltp":4.8,"tv":6383.08,"id":21580749}]}]}
{"op":"mcm","clk":"993965191","pt":1580548059496,"mc":[{"id":"1.168096552","rc":[{"trd":[[3.1,1138.21]],"batl":[[0,3.1,51.13]],"ltp":3.1,"tv":4850.68,"id":18286408}],"tv":20378.86}]}
{"op":"mcm","clk":"993965602","pt":1580548064399,"mc":[{"id":"1.168096552","rc":[{"batb":[[0,3.05,20.4],[1,3,88.29]],"ltp":3.1,"tv":4850.68,"id":18286408},{"trd":[[36,50.34],[38,23.35],[40,45.14],[42,9.86]],"batb":[[0,34,2.9],[1,32,2.54],[2,30,2.35]],"batl":[[0,36,8.05],[1,65,5.08]],"ltp":36.0,"tv":185.44,"id":27706761}],"tv":20402.77}]}
{"op":"mcm","clk":"993965705","pt":1580548065459,"mc":[{"id":"1.168096552","rc":[{"trd":[[4.8,736.38]],"batl":[[0,4.8,49.18]],"ltp":4.8,"tv":6387.08,"id":21580749}],"tv":20406.77}]}
{"op":"mcm","clk":"993965802","pt":1580548066507,"mc":[{"id":"1.168096552","rc":[{"batb":[[0,3.05,61.42]],"batl":[[0,3.1,47.13]],"ltp":3.1,"tv":4850.68,"id":18286408},{"trd":[[15,72.26]],"batb":[[0,15,5.31],[1,14.5,17.63],[2,14,4]],"batl":[[0,15.5,7],[1,17,1.76],[2,18,1.87]],"ltp":15.0,"tv":615.47,"id":26640937},{"batb":[[0,4.6,53.42]],"batl":[[0,4.7,10],[1,4.8,49.18],[2,4.9,49.53]],"ltp":4.8,"tv":6387.08,"id":21580749},{"batb":[[0,32,3.29],[1,30,2],[2,23,11.74]],"ltp":36.0,"tv":185.44,"id":27706761},{"trd":[[3.05,582.52]],"batl":[[0,3.05,30.64]],"ltp":3.05,"tv":8156.33,"id":52106}],"tv":20494.86}]}
{"op":"mcm","clk":"993965864","pt":1580548067280,"mc":[{"id":"1.168096552","rc":[{"batb":[[0,3.05,52.42]],"batl":[[0,3.1,51.13]],"ltp":3.1,"tv":4850.68,"id":18286408},{"batb":[[0,15,7.31]],"batl":[[0,15.5,5],[1,16,2.25],[2,17,1.76]],"ltp":15.0,"tv":615.47,"id":26640937},{"trd":[[4.7,1773.97]],"batl":[[0,4.8,49.18],[1,4.9,49.53],[2,5,20.39]],"ltp":4.7,"tv":6407.08,"id":21580749},{"batb":[[0,32,7.2],[2,26,3.19]],"ltp":36.0,"tv":185.44,"id":27706761},{"trd":[[26,12.33]],"batb":[[0,25,6.81],[1,24,8.37]],"batl":[[0,32,4.5],[1,34,12.14],[2,36,6.07]],"ltp":26.0,"tv":310.79,"id":24608298}],"tv":20525.81}]}
{"op":"mcm","clk":"993965943","pt":1580548068369,"mc":[{"id":"1.168096552","rc":[{"trd":[[34,3.62]],"batb":[[0,32,6.99]],"batl":[[0,34,5.3],[1,55,2.26],[2,65,5.08]],"ltp":34.0,"tv":186.94,"id":27706761},{"batb":[[0,25,8.81]],"batl":[[0,32,2]],"ltp":26.0,"tv":310.79,"id":24608298}],"tv":20527.31}]}
{"op":"mcm","clk":"993965986","pt":1580548068990,"mc":[{"id":"1.168096552","rc":[{"batb":[[2,25,3.66]],"batl":[[0,34,7.3],[1,65,5.08],[2,85,1]],"ltp":34.0,"tv":186.94,"id":27706761},{"batb":[[0,26,2.58],[1,25,6.81],[2,24,8.37]],"batl":[[1,36,2],[2,48,1.13]],"ltp":26.0,"tv":310.79,"id":24608298}]}]}
{"op":"mcm","clk":"993966093","pt":1580548070489,"mc":[{"id":"1.168096552","rc":[{"batb":[[1,3,80.55]],"ltp":3.1,"tv":4850.68,"id":18286408},{"batb":[[2,23,7.99]],"ltp":34.0,"tv":186.94,"id":27706761},{"batl":[[2,42,4.25]],"ltp":26.0,"tv":310.79,"id":24608298}]}]}
{"op":"mcm","clk":"993966141","pt":1580548071012,"mc":[{"id":"1.168096552","rc":[{"trd":[[4.8,756.38]],"batl":[[0,4.8,39.18]],"ltp":4.8,"tv":6427.08,"id":21580749},{"trd":[[3.05,619.12]],"batl":[[0,3.05,12.34]],"ltp":3.05,"tv":8192.93,"id":52106}],"tv":20583.91}]}
{"op":"mcm","clk":"993966271","pt":1580548072518,"mc":[{"id":"1.168096552","rc":[{"batl":[[0,15.5,7]],"ltp":15.0,"tv":615.47,"id":26640937},{"batb":[[0,4.6,48.42]],"batl":[[0,4.7,2.28],[1,4.8,39.18],[2,4.9,49.53]],"ltp":4.8,"tv":6427.08,"id":21580749},{"trd":[[32,10.6]],"batb":[[0,32,1.69],[2,22,4.36]],"batl":[[0,55,2.28]],"ltp":32.0,"tv":197.54,"id":27706761},{"batb":[[0,26,4.58]],"ltp":26.0,"tv":310.79,"id":24608298}],"tv":20594.5}]}
{"op":"mcm","clk":"993966357","pt":1580548073508,"mc":[{"id":"1.168096552","rc":[{"trd":[[4.6,1908.02]],"batb":[[0,4.6,45.42]],"ltp":4.6,"tv":6447.08,"id":21580749},{"batb":[[0,32,1.15],[2,22,3.62]],"batl":[[0,60,2.57],[1,65,5]],"ltp":32.0,"tv":197.54,"id":27706761}],"tv":20614.5}]}
{"op":"mcm","clk":"993966404","pt":1580548074182,"mc":[{"id":"1.168096552","rc":[{"batb":[[0,4.6,38.42]],"ltp":4.6,"tv":6447.08,"id":21580749},{"batb":[[0,32,3.15],[2,21,5.62]],"batl":[[0,55,2.74],[1,60,4.91],[2,65,7.54]],"ltp":32.0,"tv":197.54,"id":27706761},{"batl":[[2,46,4.25]],"ltp":26.0,"tv":310.79,"id":24608298}]}]}
{"op":"mcm","clk":"993966514","pt":1580548075489,"mc":[{"id":"1.168096552","rc":[{"batl":[[0,4.7,12.28]],"ltp":4.6,"tv":6447.08,"id":21580749},{"batl":[[0,50,3.89],[1,60,2.57],[2,65,5]],"ltp":32.0,"tv":197.54,"id":27706761},{"batl":[[0,34,2.3]],"ltp":26.0,"tv":310.79,"id":24608298}]}]}
{"op":"mcm","clk":"993966583","pt":1580548076482,"mc":[{"id":"1.168096552","rc":[{"batb":[[0,15,5.31]],"ltp":15.0,"tv":615.47,"id":26640937},{"batl":[[0,50,1.59],[1,65,5.28],[2,85,1]],"ltp":32.0,"tv":197.54,"id":27706761}]}]}
{"op":"mcm","clk":"993966734","pt":1580548078302,"mc":[{"id":"1.168096552","rc":[{"batl":[[0,4.7,44.28]],"ltp":4.6,"tv":6447.08,"id":21580749}]}]}
{"op":"mcm","clk":"993967045","pt":1580548081430,"mc":[{"id":"1.168096552","rc":[{"trd":[[4.7,1789.97]],"batl":[[0,4.7,36.28]],"ltp":4.7,"tv":6463.08,"id":21580749}],"tv":20630.5}]}
{"op":"mcm","clk":"993967131","pt":1580548082422,"mc":[{"id":"1.168096552","rc":[{"batl":[[0,4.7,38.28]],"ltp":4.7,"tv":6463.08,"id":21580749},{"trd":[[3.05,643.81]],"batb":[[0,3.05,2.15],[1,3,229.6],[2,2.98,42.68]],"batl":[[0,3.1,52],[1,3.15,18.96],[2,3.2,83.9]],"ltp":3.05,"tv":8217.61,"id":52106}],"tv":20655.19}]}
{"op":"mcm","clk":"993967212","pt":1580548083519,"mc":[{"id":"1.168096552","rc":[{"trd":[[3.1,135.09]],"batl":[[0,3.1,16]],"ltp":3.1,"tv":8289.61,"id":52106}],"tv":20727.19}]}
{"op":"mcm","clk":"993967426","pt":1580548085427,"mc":[{"id":"1.168096552","rc":[{"batl":[[0,34,2.8]],"ltp":26.0,"tv":310.79,"id":24608298}]}]}
{"op":"mcm","clk":"993967772","pt":1580548089350,"mc":[{"id":"1.168096552","rc":[{"trd":[[4.7,1801.97]],"batl":[[0,4.7,32.28]],"ltp":4.7,"tv":6475.08,"id":21580749},{"batb":[[2,22,3.62]],"batl":[[0,60,2.32],[1,65,5]],"ltp":32.0,"tv":197.54,"id":27706761}],"tv":20739.19}]}
{"op":"mcm","clk":"993967841","pt":1580548090240,"mc":[{"id":"1.168096552","rc":[{"batb":[[2,22,7.24]],"ltp":32.0,"tv":197.54,"id":27706761}]}]}
{"op":"mcm","clk":"993968879","pt":1580548103325,"mc":[{"id":"1.168096552","rc":[{"trd":[[4.7,1821.97]],"batl":[[0,4.7,22.28]],"ltp":4.7,"tv":6495.08,"id":21580749}],"tv":20759.19}]}
{"op":"mcm","clk":"993969143","pt":1580548106450,"mc":[{"id":"1.168096552","rc":[{"batl":[[0,60,3.04]],"ltp":32.0,"tv":197.54,"id":27706761}]}]}
{"op":"mcm","clk":"993969289","pt":1580548108433,"mc":[{"id":"1.168096552","rc":[{"batl":[[0,46,2.15],[1,48,7],[2,60,1]],"ltp":32.0,"tv":197.54,"id":27706761}]}]}
{"op":"mcm","clk":"993969446","pt":1580548110452,"mc":[{"id":"1.168096552","rc":[{"trd":[[15,78.18]],"batb":[[0,15,2.35]],"ltp":15.0,"tv":621.39,"id":26640937}],"tv":20765.1}]}
{"op":"mcm","clk":"993969672","pt":1580548113472,"mc":[{"id":"1.168096552","rc":[{"batl":[[0,3.1,76.33]],"ltp":3.1,"tv":4850.68,"id":18286408}]}]}
{"op":"mcm","clk":"993969740","pt":1580548114366,"mc":[{"id":"1.168096552","rc":[{"batl":[[2,65,5.8]],"ltp":32.0,"tv":197.54,"id":27706761}]}]}
{"op":"mcm","clk":"993969901","pt":1580548116357,"mc":[{"id":"1.168096552","rc":[{"trd":[[4.6,1928.01]],"batb":[[0,4.6,28.42]],"ltp":4.6,"tv":6515.07,"id":21580749}],"tv":20785.1}]}
{"op":"mcm","clk":"993970210","pt":1580548120453,"mc":[{"id":"1.168096552","rc":[{"batb":[[2,22,10.86]],"ltp":32.0,"tv":197.54,"id":27706761}]}]}
{"op":"mcm","clk":"993970295","pt":1580548121484,"mc":[{"id":"1.168096552","rc":[{"batl":[[2,50,2]],"ltp":32.0,"tv":197.54,"id":27706761}]}]}
{"op":"mcm","clk":"993970727","pt":1580548126102,"mc":[{"id":"1.168096552","rc":[{"batl":[[0,4.7,32.28]],"ltp":4.6,"tv":6515.07,"id":21580749}]}]}
{"op":"mcm","clk":"993970830","pt":1580548127400,"mc":[{"id":"1.168096552","rc":[{"batl":[[0,3.1,51.13]],"ltp":3.1,"tv":4850.68,"id":18286408}]}]}
{"op":"mcm","clk":"993971064","pt":1580548130507,"mc":[{"id":"1.168096552","rc":[{"batl":[[0,4.7,52.28]],"ltp":4.6,"tv":6515.07,"id":21580749}]}]}
{"op":"mcm","clk":"993971286","pt":1580548132494,"mc":[{"id":"1.168096552","rc":[{"batb":[[0,3.05,77.62]],"ltp":3.1,"tv":4850.68,"id":18286408},{"batl":[[0,46,2.51]],"ltp":32.0,"tv":197.54,"id":27706761}]}]}
{"op":"mcm","clk":"993971943","pt":1580548139520,"mc":[{"id":"1.168096552","rc":[{"batl":[[0,30,8],[1,34,2.8],[2,36,2]],"ltp":26.0,"tv":310.79,"id":24608298}]}]}
{"op":"mcm","clk":"993972043","pt":1580548140504,"mc":[{"id":"1.168096552","rc":[{"batb":[[0,3.05,6.47]],"batl":[[0,3.1,9]],"ltp":3.1,"tv":8289.61,"id":52106},{"batl":[[0,29,2.32],[1,30,8],[2,36,2.5]],"ltp":26.0,"tv":310.79,"id":24608298}]}]}
{"op":"mcm","clk":"993972143","pt":1580548141496,"mc":[{"id":"1.168096552","rc":[{"trd":[[4.7,1842.37]],"batl":[[0,4.7,42.08]],"ltp":4.7,"tv":6535.47,"id":21580749}],"tv":20805.5}]}
{"op":"mcm","clk":"993973085","pt":1580548152435,"mc":[{"id":"1.168096552","rc":[{"batb":[[0,32,3.3]],"ltp":32.0,"tv":197.54,"id":27706761}]}]}
{"op":"mcm","clk":"993973316","pt":1580548155392,"mc":[{"id":"1.168096552","rc":[{"trd":[[4.6,1968.01]],"batb":[[0,4.6,8.42]],"ltp":4.6,"tv":6575.48,"id":21580749}],"tv":20845.5}]}
{"op":"mcm","clk":"993973408","pt":1580548156439,"mc":[{"id":"1.168096552","rc":[{"batl":[[2,32,2.5]],"ltp":26.0,"tv":310.79,"id":24608298}]}]}
{"op":"mcm","clk":"993973882","pt":1580548161519,"mc":[{"id":"1.168096552","rc":[{"batb":[[0,15,4.35]],"ltp":15.0,"tv":621.39,"id":26640937},{"batl":[[0,4.7,52.08]],"ltp":4.6,"tv":6575.48,"id":21580749}]}]}
{"op":"mcm","clk":"993974082","pt":1580548163431,"mc":[{"id":"1.168096552","rc":[{"trd":[[4.6,1988.02],[4.7,1847.21]],"batb":[[0,4.5,85.23],[1,4.4,31.03],[2,4.3,51.43]],"batl":[[0,4.7,49.66]],"ltp":4.7,"tv":6600.32,"id":21580749}],"tv":20870.34}]}
{"op":"mcm","clk":"993974217","pt":1580548164424,"mc":[{"id":"1.168096552","rc":[{"batb":[[1,4.4,40.14]],"ltp":4.7,"tv":6600.32,"id":21580749}]}]}
{"op":"mcm","clk":"993974328","pt":1580548165427,"mc":[{"id":"1.168096552","rc":[{"batb":[[1,4.4,31.03]],"ltp":4.7,"tv":6600.32,"id":21580749}]}]}
{"op":"mcm","clk":"993974548","pt":1580548167414,"mc":[{"id":"1.168096552","rc":[{"trd":[[4.6,2008.02]],"ltp":4.6,"tv":6620.32,"id":21580749}],"tv":20890.34}]}
{"op":"mcm","clk":"993975444","pt":1580548176453,"mc":[{"id":"1.168096552","rc":[{"batb":[[0,3.05,19.56]],"batl":[[1,3.15,28.34]],"ltp":3.1,"tv":8289.61,"id":52106}]}]}
{"op":"mcm","clk":"993975990","pt":1580548182432,"mc":[{"id":"1.168096552","rc":[{"batb":[[0,4.6,9.6],[1,4.5,85.23],[2,4.4,31.03]],"ltp":4.6,"tv":6620.32,"id":21580749}]}]}
{"op":"mcm","clk":"993976067","pt":1580548183394,"mc":[{"id":"1.168096552","rc":[{"batb":[[0,3.05,67.08]],"ltp":3.1,"tv":8289.61,"id":52106}]}]}
{"op":"mcm","clk":"993976146","pt":1580548184370,"mc":[{"id":"1.168096552","rc":[{"trd":[[4.6,2027.22]],"batb":[[0,4.5,85.23],[1,4.4,31.03],[2,4.3,51.43]],"batl":[[0,4.7,50.06]],"ltp":4.6,"tv":6639.52,"id":21580749}],"tv":20909.54}]}
{"op":"mcm","clk":"993976711","pt":1580548190473,"mc":[{"id":"1.168096552","rc":[{"batb":[[0,4.5,105.23]],"batl":[[1,4.8,40.69]],"ltp":4.6,"tv":6639.52,"id":21580749}]}]}
{"op":"mcm","clk":"993977279","pt":1580548196484,"mc":[{"id":"1.168096552","rc":[{"batl":[[0,4.6,10.4],[1,4.7,49.66],[2,4.8,40.69]],"ltp":4.6,"tv":6639.52,"id":21580749}]}]}
{"op":"mcm","clk":"993978001","pt":1580548203293,"mc":[{"id":"1.168096552","rc":[{"trd":[[4.6,2048.02]],"batl":[[0,4.7,49.66],[1,4.8,40.69],[2,4.9,49.53]],"ltp":4.6,"tv":6660.32,"id":21580749}],"tv":20930.34}]}
{"op":"mcm","clk":"993978135","pt":1580548204492,"mc":[{"id":"1.168096552","rc":[{"batl":[[0,4.7,58.62]],"ltp":4.6,"tv":6660.32,"id":21580749}]}]}
{"op":"mcm","clk":"993978503","pt":1580548207493,"mc":[{"id":"1.168096552","rc":[{"trd":[[4.5,891.86]],"batb":[[0,4.5,95.23]],"ltp":4.5,"tv":6680.32,"id":21580749}],"tv":20950.34}]}
{"op":"mcm","clk":"993979354","pt":1580548215508,"mc":[{"id":"1.168096552","rc":[{"trd":[[3.05,1494.69]],"batb":[[0,3.05,21.62]],"ltp":3.05,"tv":4962.68,"id":18286408}],"tv":21062.35}]}
{"op":"mcm","clk":"993980638","pt":1580548227337,"mc":[{"id":"1.168096552","rc":[{"trd":[[4.5,911.86]],"batb":[[0,4.5,85.23]],"ltp":4.5,"tv":6700.32,"id":21580749}],"tv":21082.35}]}
{"op":"mcm","clk":"993980747","pt":1580548228434,"mc":[{"id":"1.168096552","rc":[{"batl":[[0,15.5,5]],"ltp":15.0,"tv":621.39,"id":26640937}]}]}
{"op":"mcm","clk":"993981371","pt":1580548234140,"mc":[{"id":"1.168096552","rc":[{"trd":[[3.05,1533.78]],"batb":[[0,3.05,2.08]],"ltp":3.05,"tv":5001.77,"id":18286408},{"batl":[[1,4.8,27.69]],"ltp":4.5,"tv":6700.32,"id":21580749}],"tv":21121.43}]}
{"op":"mcm","clk":"993981520","pt":1580548235501,"mc":[{"id":"1.168096552","rc":[{"batl":[[1,3.15,18.96]],"ltp":3.1,"tv":8289.61,"id":52106}]}]}
{"op":"mcm","clk":"993981602","pt":1580548236332,"mc":[{"id":"1.168096552","rc":[{"batl":[[0,4.6,10],[1,4.7,49.66],[2,4.8,22.28]],"ltp":4.5,"tv":6700.32,"id":21580749}]}]}
{"op":"mcm","clk":"993981888","pt":1580548239349,"mc":[{"id":"1.168096552","rc":[{"trd":[[3.05,703.81]],"batb":[[0,3.05,41.08]],"batl":[[1,3.15,31.64]],"ltp":3.05,"tv":8349.61,"id":52106}],"tv":21181.44}]}
{"op":"mcm","clk":"993982280","pt":1580548243246,"mc":[{"id":"1.168096552","rc":[{"trd":[[3.05,723.81]],"batb":[[0,3.05,31.08]],"ltp":3.05,"tv":8369.61,"id":52106}],"tv":21201.44}]}
{"op":"mcm","clk":"993982829","pt":1580548248445,"mc":[{"id":"1.168096552","rc":[{"trd":[[3.1,1158.68]],"batl":[[0,3.1,40.89]],"ltp":3.1,"tv":5022.23,"id":18286408}],"tv":21221.9}]}
{"op":"mcm","clk":"993982920","pt":1580548249272,"mc":[{"id":"1.168096552","rc":[{"batb":[[1,3,82.85]],"ltp":3.1,"tv":5022.23,"id":18286408}]}]}
{"op":"mcm","clk":"993983560","pt":1580548255291,"mc":[{"id":"1.168096552","rc":[{"batl":[[0,4.6,35]],"ltp":4.5,"tv":6700.32,"id":21580749}]}]}
{"op":"mcm","clk":"993983691","pt":1580548256394,"mc":[{"id":"1.168096552","rc":[{"batl":[[2,4.8,13.51]],"ltp":4.5,"tv":6700.32,"id":21580749}]}]}
{"op":"mcm","clk":"993984013","pt":1580548259367,"mc":[{"id":"1.168096552","rc":[{"batb":[[2,4.3,62.43]],"ltp":4.5,"tv":6700.32,"id":21580749}]}]}
{"op":"mcm","clk":"993984560","pt":1580548264470,"mc":[{"id":"1.168096552","rc":[{"batl":[[0,4.6,44.15]],"ltp":4.5,"tv":6700.32,"id":21580749}]}]}
{"op":"mcm","clk":"993984640","pt":1580548265191,"mc":[{"id":"1.168096552","rc":[{"trd":[[3.1,137.29]],"batl":[[0,3.1,7.9],[2,3.2,65]],"ltp":3.1,"tv":8371.81,"id":52106}],"tv":21224.1}]}
{"op":"mcm","clk":"993986062","pt":1580548280510,"mc":[{"id":"1.168096552","rc":[{"trd":[[3.1,1240.46]],"batl":[[0,3.1,3.11]],"ltp":3.1,"tv":5104.01,"id":18286408}],"tv":21305.88}]}
{"op":"mcm","clk":"993986139","pt":1580548281394,"mc":[{"id":"1.168096552","rc":[{"batb":[[0,3.05,7.72]],"batl":[[0,3.1,9.04]],"ltp":3.1,"tv":5104.01,"id":18286408}]}]}
{"op":"mcm","clk":"993986446","pt":1580548284493,"mc":[{"id":"1.168096552","rc":[{"trd":[[4.5,931.86]],"batb":[[0,4.5,75.23]],"ltp":4.5,"tv":6720.32,"id":21580749}],"tv":21325.88}]}
{"op":"mcm","clk":"993987160","pt":1580548290420,"mc":[{"id":"1.168096552","rc":[{"batl":[[0,3.1,23.04]],"ltp":3.1,"tv":5104.01,"id":18286408}]}]}
{"op":"mcm","clk":"993988200","pt":1580548301518,"mc":[{"id":"1.168096552","rc":[{"batb":[[1,14.5,12.63]],"ltp":15.0,"tv":621.39,"id":26640937}]}]}
{"op":"mcm","clk":"993988298","pt":1580548302413,"mc":[{"id":"1.168096552","rc":[{"batb":[[0,15,9.35]],"ltp":15.0,"tv":621.39,"id":26640937}]}]}
{"op":"mcm","clk":"993989604","pt":1580548314459,"mc":[{"id":"1.168096552","rc":[{"batb":[[0,4.5,55.23]],"ltp":4.5,"tv":6720.32,"id":21580749}]}]}
{"op":"mcm","clk":"993990117","pt":1580548320472,"mc":[{"id":"1.168096552","rc":[{"batl":[[0,46,2.15]],"ltp":32.0,"tv":197.54,"id":27706761},{"batb":[[0,3.05,43.98]],"ltp":3.1,"tv":8371.81,"id":52106},{"batl":[[2,32,2]],"ltp":26.0,"tv":310.79,"id":24608298}]}]}
{"op":"mcm","clk":"993990700","pt":1580548324461,"mc":[{"id":"1.168096552","rc":[{"batb":[[0,15,9.05]],"ltp":15.0,"tv":621.39,"id":26640937}]}]}
{"op":"mcm","clk":"993992755","pt":1580548344488,"mc":[{"id":"1.168096552","rc":[{"trd":[[4.5,951.86]],"batb":[[0,4.5,45.23]],"ltp":4.5,"tv":6740.32,"id":21580749}],"tv":21345.88}]}
{"op":"mcm","clk":"993993232","pt":1580548348520,"mc":[{"id":"1.168096552","rc":[{"trd":[[3.1,1286.54]],"batb":[[0,3.1,56.96],[1,3.05,7.72],[2,3,82.85]],"batl":[[0,3.15,87.82],[1,3.2,19],[2,3.25,320]],"ltp":3.1,"tv":5150.1,"id":18286408}],"tv":21391.96}]}
{"op":"mcm","clk":"993993318","pt":1580548349308,"mc":[{"id":"1.168096552","rc":[{"trd":[[3.1,1292.54]],"batb":[[0,3.1,53.96],[1,3.05,30.95]],"ltp":3.1,"tv":5156.1,"id":18286408},{"batb":[[0,4.5,38.23]],"batl":[[0,4.6,46.15]],"ltp":4.5,"tv":6740.32,"id":21580749}],"tv":21397.96}]}
{"op":"mcm","clk":"993993409","pt":1580548350200,"mc":[{"id":"1.168096552","rc":[{"batb":[[0,3.1,56.19],[2,3,80.55]],"ltp":3.1,"tv":5156.1,"id":18286408}]}]}
{"op":"mcm","clk":"993993752","pt":1580548353388,"mc":[{"id":"1.168096552","rc":[{"trd":[[3.1,1342.96]],"batb":[[0,3.1,30.98]],"ltp":3.1,"tv":5206.51,"id":18286408}],"tv":21448.38}]}
{"op":"mcm","clk":"993993861","pt":1580548354487,"mc":[{"id":"1.168096552","rc":[{"batb":[[0,3.1,28.75],[1,3.05,33.21]],"ltp":3.1,"tv":5206.51,"id":18286408}]}]}
{"op":"mcm","clk":"993994510","pt":1580548360396,"mc":[{"id":"1.168096552","rc":[{"batb":[[0,3.1,53.96]],"ltp":3.1,"tv":5206.51,"id":18286408},{"trd":[[4.6,2072.62]],"batl":[[0,4.6,33.85]],"ltp":4.6,"tv":6764.92,"id":21580749}],"tv":21472.98}]}
{"op":"mcm","clk":"993995301","pt":1580548367497,"mc":[{"id":"1.168096552","rc":[{"batl":[[1,3.15,32.06]],"ltp":3.1,"tv":8371.81,"id":52106}]}]}
{"op":"mcm","clk":"993995709","pt":1580548371417,"mc":[{"id":"1.168096552","rc":[{"batl":[[0,4.6,53.85]],"ltp":4.6,"tv":6764.92,"id":21580749}]}]}
{"op":"mcm","clk":"993996064","pt":1580548374518,"mc":[{"id":"1.168096552","rc":[{"batb":[[0,3.1,59.12]],"ltp":3.1,"tv":5206.51,"id":18286408}]}]}
{"op":"mcm","clk":"993997027","pt":1580548383360,"mc":[{"id":"1.168096552","rc":[{"batb":[[0,3.1,53.96]],"ltp":3.1,"tv":5206.51,"id":18286408}]}]}
{"op":"mcm","clk":"993997246","pt":1580548385444,"mc":[{"id":"1.168096552","rc":[{"batl":[[0,4.6,63.85]],"ltp":4.6,"tv":6764.92,"id":21580749},{"batl":[[1,3.15,52.06]],"ltp":3.1,"tv":8371.81,"id":52106}]}]}
{"op":"mcm","clk":"993999205","pt":1580548402348,"mc":[{"id":"1.168096552","rc":[{"batl":[[0,4.6,65.85]],"ltp":4.6,"tv":6764.92,"id":21580749}]}]}
{"op":"mcm","clk":"994000050","pt":1580548409457,"mc":[{"id":"1.168096552","rc":[{"trd":[[4.5,971.86]],"batb":[[0,4.5,28.23]],"ltp":4.5,"tv":6784.92,"id":21580749}],"tv":21492.98}]}
{"op":"mcm","clk":"994001109","pt":1580548418482,"mc":[{"id":"1.168096552","rc":[{"batl":[[1,4.7,29.66]],"ltp":4.5,"tv":6784.92,"id":21580749}]}]}
{"op":"mcm","clk":"994001219","pt":1580548419506,"mc":[{"id":"1.168096552","rc":[{"trd":[[3.15,842.9]],"batl":[[0,3.15,82.76]],"ltp":3.15,"tv":5216.63,"id":18286408},{"batl":[[1,4.7,22]],"ltp":4.5,"tv":6784.92,"id":21580749}],"tv":21503.1}]}
{"op":"mcm","clk":"994001851","pt":1580548425478,"mc":[{"id":"1.168096552","rc":[{"batb":[[2,3,83.55]],"ltp":3.15,"tv":5216.63,"id":18286408}]}]}
{"op":"mcm","clk":"994001956","pt":1580548426463,"mc":[{"id":"1.168096552","rc":[{"trd":[[3.1,1382.96]],"batb":[[0,3.1,33.96]],"ltp":3.1,"tv":5256.63,"id":18286408}],"tv":21543.1}]}
{"op":"mcm","clk":"994002837","pt":1580548435419,"mc":[{"id":"1.168096552","rc":[{"batb":[[2,3,80.55]],"ltp":3.1,"tv":5256.63,"id":18286408}]}]}
{"op":"mcm","clk":"994003193","pt":1580548438484,"mc":[{"id":"1.168096552","rc":[{"trd":[[3.05,743.81]],"batb":[[0,3.05,33.98]],"ltp":3.05,"tv":8391.81,"id":52106}],"tv":21563.1}]}
{"op":"mcm","clk":"994003854","pt":1580548445487,"mc":[{"id":"1.168096552","rc":[{"trd":[[3.1,1394.96]],"batb":[[0,3.1,27.96]],"ltp":3.1,"tv":5268.63,"id":18286408}],"tv":21575.1}]}
{"op":"mcm","clk":"994005272","pt":1580548458520,"mc":[{"id":"1.168096552","rc":[{"trd":[[3.1,1444.96]],"batb":[[0,3.1,2.96]],"ltp":3.1,"tv":5318.63,"id":18286408},{"batl":[[0,3.1,16.9]],"ltp":3.05,"tv":8391.81,"id":52106}],"tv":21625.1}]}
{"op":"mcm","clk":"994005364","pt":1580548459248,"mc":[{"id":"1.168096552","rc":[{"batl":[[0,4.6,56.7],[1,4.7,30.96]],"ltp":4.5,"tv":6784.92,"id":21580749}]}]}
{"op":"mcm","clk":"994005832","pt":1580548463429,"mc":[{"id":"1.168096552","rc":[{"trd":[[4.6,2093.5]],"batl":[[0,4.6,46.26]],"ltp":4.6,"tv":6805.8,"id":21580749}],"tv":21645.98}]}
{"op":"mcm","clk":"994005925","pt":1580548464240,"mc":[{"id":"1.168096552","rc":[{"trd":[[4.5,991.85]],"batb":[[0,4.5,18.24]],"batl":[[1,4.7,22],[2,4.8,22.28]],"ltp":4.5,"tv":6825.79,"id":21580749}],"tv":21665.97}]}
{"op":"mcm","clk":"994006786","pt":1580548472340,"mc":[{"id":"1.168096552","rc":[{"batl":[[0,4.6,61.26]],"ltp":4.5,"tv":6825.79,"id":21580749}]}]}
{"op":"mcm","clk":"994006977","pt":1580548474322,"mc":[{"id":"1.168096552","rc":[{"batl":[[0,4.6,70.41],[2,4.8,13.51]],"ltp":4.5,"tv":6825.79,"id":21580749}]}]}
{"op":"mcm","clk":"994007714","pt":1580548481367,"mc":[{"id":"1.168096552","rc":[{"trd":[[3.1,1450.87]],"batb":[[0,3.05,33.21],[1,3,80.55],[2,2.98,43]],"batl":[[0,3.1,20.04],[1,3.15,82.76],[2,3.2,19]],"ltp":3.1,"tv":5324.55,"id":18286408},{"batl":[[0,3.1,7.9]],"ltp":3.05,"tv":8391.81,"id":52106}],"tv":21671.89}]}
{"op":"mcm","clk":"994007801","pt":1580548482090,"mc":[{"id":"1.168096552","rc":[{"batl":[[0,4.6,61.26]],"ltp":4.5,"tv":6825.79,"id":21580749}]}]}
{"op":"mcm","clk":"994007919","pt":1580548483181,"mc":[{"id":"1.168096552","rc":[{"batb":[[0,4.5,45.24]],"ltp":4.5,"tv":6825.79,"id":21580749}]}]}
{"op":"mcm","clk":"994008355","pt":1580548487374,"mc":[{"id":"1.168096552","rc":[{"trd":[[4.5,1008.64]],"batb":[[0,4.5,36.86]],"ltp":4.5,"tv":6842.58,"id":21580749}],"tv":21688.67}]}
{"op":"mcm","clk":"994008892","pt":1580548492361,"mc":[{"id":"1.168096552","rc":[{"trd":[[4.6,2117.98]],"batl":[[0,4.6,49.02]],"ltp":4.6,"tv":6867.06,"id":21580749}],"tv":21713.15}]}
{"op":"mcm","clk":"994009119","pt":1580548494493,"mc":[{"id":"1.168096552","rc":[{"batl":[[1,4.7,23.51]],"ltp":4.6,"tv":6867.06,"id":21580749}]}]}
{"op":"mcm","clk":"994009704","pt":1580548499490,"mc":[{"id":"1.168096552","rc":[{"trd":[[3.1,1471.49]],"batb":[[0,3.05,58.42]],"batl":[[0,3.1,9.73]],"ltp":3.1,"tv":5345.17,"id":18286408},{"batl":[[2,4.8,15.03]],"ltp":4.6,"tv":6867.06,"id":21580749}],"tv":21733.77}]}
{"op":"mcm","clk":"994009802","pt":1580548500374,"mc":[{"id":"1.168096552","rc":[{"batb":[[0,3.05,35.98]],"ltp":3.05,"tv":8391.81,"id":52106}]}]}
{"op":"mcm","clk":"994010267","pt":1580548504284,"mc":[{"id":"1.168096552","rc":[{"trd":[[4.5,1028.65]],"batb":[[0,4.5,26.85]],"ltp":4.5,"tv":6887.06,"id":21580749}],"tv":21753.78}]}
{"op":"mcm","clk":"994011742","pt":1580548516506,"mc":[{"id":"1.168096552","rc":[{"batl":[[0,42,2.09],[1,44,5],[2,46,2.15]],"ltp":32.0,"tv":197.54,"id":27706761}]}]}
{"op":"mcm","clk":"994012336","pt":1580548521505,"mc":[{"id":"1.168096552","rc":[{"batl":[[0,42,7.09],[1,46,2.15],[2,48,7]],"ltp":32.0,"tv":197.54,"id":27706761}]}]}
{"op":"mcm","clk":"994012428","pt":1580548522329,"mc":[{"id":"1.168096552","rc":[{"batl":[[0,42,5]],"ltp":32.0,"tv":197.54,"id":27706761}]}]}
{"op":"mcm","clk":"994013981","pt":1580548535513,"mc":[{"id":"1.168096552","rc":[{"trd":[[3.05,1537.78]],"batb":[[0,3.05,56.42]],"ltp":3.05,"tv":5349.17,"id":18286408},{"batl":[[0,40,2.19],[1,42,5]],"ltp":32.0,"tv":197.54,"id":27706761}],"tv":21757.78}]}
{"op":"mcm","clk":"994015863","pt":1580548550424,"mc":[{"id":"1.168096552","rc":[{"batb":[[0,4.5,36.85]],"ltp":4.5,"tv":6887.06,"id":21580749}]}]}
{"op":"mcm","clk":"994016386","pt":1580548555060,"mc":[{"id":"1.168096552","rc":[{"trd":[[3.05,1541.78]],"batb":[[0,3.05,54.42]],"ltp":3.05,"tv":5353.17,"id":18286408}],"tv":21761.78}]}
{"op":"mcm","clk":"994019155","pt":1580548580492,"mc":[{"id":"1.168096552","rc":[{"trd":[[4.5,1032.65]],"batb":[[0,4.5,34.85]],"ltp":4.5,"tv":6891.06,"id":21580749}],"tv":21765.78}]}
{"op":"mcm","clk":"994019585","pt":1580548584171,"mc":[{"id":"1.168096552","rc":[{"trd":[[3.05,1545.78]],"batb":[[0,3.05,52.42]],"ltp":3.05,"tv":5357.17,"id":18286408}],"tv":21769.78}]}
{"op":"mcm","clk":"994020477","pt":1580548591284,"mc":[{"id":"1.168096552","rc":[{"batl":[[0,3.1,57.9]],"ltp":3.05,"tv":8391.81,"id":52106}]}]}
{"op":"mcm","clk":"994020609","pt":1580548592405,"mc":[{"id":"1.168096552","rc":[{"trd":[[4.5,1052.65]],"batb":[[0,4.5,24.85]],"ltp":4.5,"tv":6911.06,"id":21580749}],"tv":21789.78}]}
{"op":"mcm","clk":"994020806","pt":1580548594187,"mc":[{"id":"1.168096552","rc":[{"trd":[[3.05,1549.78]],"batb":[[0,3.05,50.42]],"ltp":3.05,"tv":5361.17,"id":18286408}],"tv":21793.78}]}
{"op":"mcm","clk":"994020939","pt":1580548595490,"mc":[{"id":"1.168096552","rc":[{"batl":[[0,3.1,6.73]],"ltp":3.05,"tv":5361.17,"id":18286408},{"batl":[[0,4.6,47.02]],"ltp":4.5,"tv":6911.06,"id":21580749},{"trd":[[3,1198.85],[3.05,823.77]],"batb":[[0,3,219.08],[1,2.98,42.68],[2,2.96,5.06]],"batl":[[0,3.05,303.05],[1,3.1,66.9],[2,3.15,52.06]],"ltp":3.05,"tv":8492.81,"id":52106}],"tv":21894.78}]}
{"op":"mcm","clk":"994021024","pt":1580548596419,"mc":[{"id":"1.168096552","rc":[{"batb":[[0,3.05,59.42],[1,3,88.29]],"ltp":3.05,"tv":5361.17,"id":18286408},{"batb":[[1,4.4,34.46]],"ltp":4.5,"tv":6911.06,"id":21580749},{"batl":[[0,3.05,316.14],[2,3.15,39.38]],"ltp":3.05,"tv":8492.81,"id":52106}]}]}
{"op":"mcm","clk":"994021131","pt":1580548597519,"mc":[{"id":"1.168096552","rc":[{"batb":[[2,2.98,47]],"ltp":3.05,"tv":5361.17,"id":18286408},{"batb":[[0,3,217.08],[1,2.98,40.68],[2,2.96,3]],"batl":[[0,3.05,13.09]],"ltp":3.05,"tv":8492.81,"id":52106}]}]}
{"op":"mcm","clk":"994021270","pt":1580548598509,"mc":[{"id":"1.168096552","rc":[{"batl":[[0,3.1,66.9],[1,3.15,39.38],[2,3.2,65]],"ltp":3.05,"tv":8492.81,"id":52106},{"batb":[[0,26,5.22]],"ltp":26.0,"tv":310.79,"id":24608298}]}]}
{"op":"mcm","clk":"994021560","pt":1580548601396,"mc":[{"id":"1.168096552","rc":[{"batb":[[0,4.5,34.45]],"batl":[[1,4.7,32.47]],"ltp":4.5,"tv":6911.06,"id":21580749},{"batb":[[0,3.05,3.22],[1,3,217.08],[2,2.98,40.68]],"ltp":3.05,"tv":8492.81,"id":52106}]}]}
{"op":"mcm","clk":"994021770","pt":1580548603494,"mc":[{"id":"1.168096552","rc":[{"trd":[[3.05,1553.78]],"batb":[[0,3.05,57.42],[1,3,80.55]],"ltp":3.05,"tv":5365.17,"id":18286408},{"batb":[[1,4.4,31.03]],"ltp":4.5,"tv":6911.06,"id":21580749}],"tv":21898.78}]}
{"op":"mcm","clk":"994022515","pt":1580548608421,"mc":[{"id":"1.168096552","rc":[{"batb":[[0,3.05,60.7],[1,3,88.29]],"ltp":3.05,"tv":5365.17,"id":18286408},{"batb":[[1,4.4,34.46]],"ltp":4.5,"tv":6911.06,"id":21580749},{"trd":[[3,1580.51],[3.05,830.21]],"batb":[[0,3,28.25],[1,2.98,40.68],[2,2.96,3]],"batl":[[0,3.1,93.85]],"ltp":3.0,"tv":8880.91,"id":52106}],"tv":22286.88}]}
{"op":"mcm","clk":"994022849","pt":1580548611418,"mc":[{"id":"1.168096552","rc":[{"batl":[[0,4.6,67.02]],"ltp":4.5,"tv":6911.06,"id":21580749}]}]}
{"op":"mcm","clk":"994024495","pt":1580548624459,"mc":[{"id":"1.168096552","rc":[{"trd":[[3.05,1557.78]],"batb":[[0,3.05,58.7]],"ltp":3.05,"tv":5369.17,"id":18286408},{"trd":[[4.5,1082.65]],"batb":[[0,4.5,19.45]],"ltp":4.5,"tv":6941.06,"id":21580749}],"tv":22320.88}]}
{"op":"mcm","clk":"994024576","pt":1580548625347,"mc":[{"id":"1.168096552","rc":[{"batb":[[0,4.5,25.45]],"ltp":4.5,"tv":6941.06,"id":21580749}]}]}
{"op":"mcm","clk":"994025915","pt":1580548635451,"mc":[{"id":"1.168096552","rc":[{"trd":[[4.5,1102.65]],"batb":[[0,4.5,15.45]],"ltp":4.5,"tv":6961.06,"id":21580749}],"tv":22340.88}]}
{"op":"mcm","clk":"994026950","pt":1580548644476,"mc":[{"id":"1.168096552","rc":[{"trd":[[3.05,1561.78]],"batb":[[0,3.05,56.7]],"ltp":3.05,"tv":5373.17,"id":18286408}],"tv":22344.88}]}
{"op":"mcm","clk":"994027216","pt":1580548646478,"mc":[{"id":"1.168096552","rc":[{"trd":[[4.6,2127.98]],"batl":[[0,4.6,62.02]],"ltp":4.6,"tv":6971.06,"id":21580749}],"tv":22354.88}]}
{"op":"mcm","clk":"994027650","pt":1580548650297,"mc":[{"id":"1.168096552","rc":[{"trd":[[4.6,2148.38]],"batl":[[0,4.6,51.82]],"ltp":4.6,"tv":6991.46,"id":21580749}],"tv":22375.28}]}
{"op":"mcm","clk":"994027801","pt":1580548651467,"mc":[{"id":"1.168096552","rc":[{"batb":[[0,3.05,60.7]],"ltp":3.05,"tv":5373.17,"id":18286408},{"trd":[[4.5,1122.65]],"batb":[[0,4.5,5.45]],"batl":[[0,4.6,53.82]],"ltp":4.5,"tv":7011.46,"id":21580749}],"tv":22395.28}]}
{"op":"mcm","clk":"994028030","pt":1580548653496,"mc":[{"id":"1.168096552","rc":[{"trd":[[3.05,1565.78]],"batb":[[0,3.05,58.7]],"ltp":3.05,"tv":5377.17,"id":18286408}],"tv":22399.28}]}
{"op":"mcm","clk":"994028141","pt":1580548654497,"mc":[{"id":"1.168096552","rc":[{"trd":[[4.4,192.18],[4.5,1145.55]],"batb":[[0,4.4,25.44],[1,4.3,62.43],[2,4.2,15.79]],"batl":[[0,4.5,38.55],[1,4.6,53.82],[2,4.7,32.47]],"ltp":4.4,"tv":7052.41,"id":21580749},{"batl":[[0,30,10],[1,32,2],[2,36,2]],"ltp":26.0,"tv":310.79,"id":24608298}],"tv":22440.23}]}
{"op":"mcm","clk":"994028241","pt":1580548655393,"mc":[{"id":"1.168096552","rc":[{"batb":[[0,4.4,22.01],[1,4.3,74.18]],"batl":[[0,4.5,57.9],[2,4.7,23.51]],"ltp":4.4,"tv":7052.41,"id":21580749},{"batb":[[1,2.98,50.04]],"ltp":3.0,"tv":8880.91,"id":52106}]}]}
{"op":"mcm","clk":"994028468","pt":1580548657381,"mc":[{"id":"1.168096552","rc":[{"batb":[[0,3.05,75.31]],"ltp":3.05,"tv":5377.17,"id":18286408},{"batb":[[0,15,12.43]],"ltp":15.0,"tv":621.39,"id":26640937},{"batb":[[0,4.4,33.52]],"ltp":4.4,"tv":7052.41,"id":21580749},{"batb":[[0,32,4.88]],"ltp":32.0,"tv":197.54,"id":27706761},{"batb":[[0,3,45.13]],"ltp":3.0,"tv":8880.91,"id":52106},{"batb":[[0,26,7.17]],"ltp":26.0,"tv":310.79,"id":24608298}]}]}
{"op":"mcm","clk":"994028694","pt":1580548659471,"mc":[{"id":"1.168096552","rc":[{"batl":[[1,4.6,43.82]],"ltp":4.4,"tv":7052.41,"id":21580749}]}]}
{"op":"mcm","clk":"994029690","pt":1580548668496,"mc":[{"id":"1.168096552","rc":[{"batb":[[1,4.3,64.79]],"ltp":4.4,"tv":7052.41,"id":21580749},{"batb":[[2,26,3.62]],"ltp":32.0,"tv":197.54,"id":27706761},{"batb":[[1,2.98,54.46]],"ltp":3.0,"tv":8880.91,"id":52106}]}]}
{"op":"mcm","clk":"994030252","pt":1580548673504,"mc":[{"id":"1.168096552","rc":[{"trd":[[3.05,1569.78],[3.1,1484.69]],"batb":[[0,3.05,73.31]],"batl":[[0,3.15,82.89],[1,3.2,19],[2,3.25,320]],"ltp":3.1,"tv":5394.37,"id":18286408},{"batb":[[2,22,10.86]],"ltp":32.0,"tv":197.54,"id":27706761},{"trd":[[3.05,843.62]],"batl":[[0,3.05,2.29],[1,3.1,93.85],[2,3.15,39.38]],"ltp":3.05,"tv":8894.33,"id":52106}],"tv":22470.85}]}
{"op":"mcm","clk":"994030382","pt":1580548674504,"mc":[{"id":"1.168096552","rc":[{"trd":[[3.1,1484.95]],"batl":[[0,3.15,82.76]],"ltp":3.1,"tv":5394.63,"id":18286408},{"trd":[[15.5,4.86]],"batl":[[0,15.5,3.68]],"ltp":15.5,"tv":624.03,"id":26640937},{"batb":[[0,4.4,38.17]],"ltp":4.4,"tv":7052.41,"id":21580749},{"batb":[[0,27,1.4],[1,26,6.53],[2,25,6.81]],"ltp":26.0,"tv":310.79,"id":24608298}],"tv":22473.75}]}
{"op":"mcm","clk":"994030482","pt":1580548675336,"mc":[{"id":"1.168096552","rc":[{"batb":[[2,26,3.62]],"ltp":32.0,"tv":197.54,"id":27706761},{"batl":[[0,29,2],[1,30,10],[2,32,2]],"ltp":26.0,"tv":310.79,"id":24608298}]}]}
{"op":"mcm","clk":"994030611","pt":1580548676428,"mc":[{"id":"1.168096552","rc":[{"batb":[[0,3.05,77.03]],"ltp":3.1,"tv":5394.63,"id":18286408},{"batb":[[1,4.3,61.79]],"batl":[[0,4.5,67.9]],"ltp":4.4,"tv":7052.41,"id":21580749},{"batb":[[2,25,3.62]],"batl":[[0,42,7],[1,48,7],[2,50,2]],"ltp":32.0,"tv":197.54,"id":27706761}]}]}
{"op":"mcm","clk":"994031349","pt":1580548683131,"mc":[{"id":"1.168096552","rc":[{"batl":[[0,3.15,84.76]],"ltp":3.1,"tv":5394.63,"id":18286408}]}]}
{"op":"mcm","clk":"994031611","pt":1580548685519,"mc":[{"id":"1.168096552","rc":[{"batl":[[0,3.05,27.5]],"ltp":3.05,"tv":8894.33,"id":52106}]}]}
{"op":"mcm","clk":"994031736","pt":1580548686510,"mc":[{"id":"1.168096552","rc":[{"batb":[[2,22,10.86]],"ltp":32.0,"tv":197.54,"id":27706761}]}]}
{"op":"mcm","clk":"994033116","pt":1580548700464,"mc":[{"id":"1.168096552","rc":[{"trd":[[4.4,212.18]],"batb":[[0,4.4,28.18]],"ltp":4.4,"tv":7072.41,"id":21580749}],"tv":22493.74}]}
{"op":"mcm","clk":"994034904","pt":1580548716380,"mc":[{"id":"1.168096552","rc":[{"batl":[[0,3.1,1.93],[1,3.15,84.76],[2,3.2,19]],"ltp":3.1,"tv":5394.63,"id":18286408}]}]}
{"op":"mcm","clk":"994035027","pt":1580548717475,"mc":[{"id":"1.168096552","rc":[{"batl":[[0,3.15,84.76],[1,3.2,19],[2,3.25,320]],"ltp":3.1,"tv":5394.63,"id":18286408},{"trd":[[4.4,272.18]],"batb":[[0,4.4,1.17]],"ltp":4.4,"tv":7132.41,"id":21580749},{"batl":[[0,40,2],[1,42,7],[2,48,7]],"ltp":32.0,"tv":197.54,"id":27706761}],"tv":22553.75}]}
{"op":"mcm","clk":"994035122","pt":1580548718304,"mc":[{"id":"1.168096552","rc":[{"batb":[[0,4.4,5.17],[1,4.3,59.79]],"batl":[[0,4.5,70.9]],"ltp":4.4,"tv":7132.41,"id":21580749},{"batl":[[0,42,7],[1,48,7],[2,50,2]],"ltp":32.0,"tv":197.54,"id":27706761}]}]}
{"op":"mcm","clk":"994035541","pt":1580548722311,"mc":[{"id":"1.168096552","rc":[{"batl":[[2,4.7,13.51]],"ltp":4.4,"tv":7132.41,"id":21580749}]}]}
{"op":"mcm","clk":"994036418","pt":1580548730428,"mc":[{"id":"1.168096552","rc":[{"batb":[[0,3.1,6.6],[1,3.05,77.03],[2,3,88.29]],"ltp":3.1,"tv":5394.63,"id":18286408},{"trd":[[4.4,292.18]],"batb":[[0,4.4,2.82]],"ltp":4.4,"tv":7152.41,"id":21580749},{"batb":[[0,3,51.95]],"ltp":3.05,"tv":8894.33,"id":52106}],"tv":22573.75}]}
{"op":"mcm","clk":"994036529","pt":1580548731409,"mc":[{"id":"1.168096552","rc":[{"trd":[[15.5,7.5]],"batl":[[0,15.5,2.36]],"ltp":15.5,"tv":626.67,"id":26640937},{"batb":[[0,4.4,7.82],[2,4.2,21.33]],"batl":[[1,4.6,45.82],[2,4.7,15.51]],"ltp":4.4,"tv":7152.41,"id":21580749},{"batb":[[0,34,1.35],[1,32,4.73],[2,30,2]],"ltp":32.0,"tv":197.54,"id":27706761},{"batb":[[0,27,2.15]],"ltp":26.0,"tv":310.79,"id":24608298}],"tv":22576.39}]}
{"op":"mcm","clk":"994036643","pt":1580548732506,"mc":[{"id":"1.168096552","rc":[{"batb":[[1,4.3,57.43]],"ltp":4.4,"tv":7152.41,"id":21580749},{"batb":[[1,2.98,40.68]],"ltp":3.05,"tv":8894.33,"id":52106}]}]}
{"op":"mcm","clk":"994036753","pt":1580548733495,"mc":[{"id":"1.168096552","rc":[{"trd":[[3,1586.51]],"batb":[[0,3,48.95]],"ltp":3.0,"tv":8900.33,"id":52106}],"tv":22582.39}]}
{"op":"mcm","clk":"994036966","pt":1580548735520,"mc":[{"id":"1.168096552","rc":[{"batl":[[0,3.15,82.76],[1,3.2,17]],"ltp":3.1,"tv":5394.63,"id":18286408},{"trd":[[4.4,312.18]],"batb":[[0,4.4,3]],"batl":[[0,4.5,72.9]],"ltp":4.4,"tv":7172.41,"id":21580749},{"batb":[[0,3,50.95]],"ltp":3.0,"tv":8900.33,"id":52106}],"tv":22602.38}]}
{"op":"mcm","clk":"994037193","pt":1580548737520,"mc":[{"id":"1.168096552","rc":[{"batl":[[0,3.05,40.59]],"ltp":3.0,"tv":8900.33,"id":52106}]}]}
{"op":"mcm","clk":"994038145","pt":1580548747448,"mc":[{"id":"1.168096552","rc":[{"batl":[[1,4.6,25.82]],"ltp":4.4,"tv":7172.41,"id":21580749}]}]}
{"op":"mcm","clk":"994038386","pt":1580548749517,"mc":[{"id":"1.168096552","rc":[{"batl":[[1,4.6,10.82]],"ltp":4.4,"tv":7172.41,"id":21580749}]}]}
{"op":"mcm","clk":"994038504","pt":1580548750518,"mc":[{"id":"1.168096552","rc":[{"batl":[[0,4.5,63.55],[1,4.6,15.15]],"ltp":4.4,"tv":7172.41,"id":21580749}]}]}
{"op":"mcm","clk":"994038603","pt":1580548751455,"mc":[{"id":"1.168096552","rc":[{"batl":[[0,4.5,58.55]],"ltp":4.4,"tv":7172.41,"id":21580749}]}]}
{"op":"mcm","clk":"994038722","pt":1580548752441,"mc":[{"id":"1.168096552","rc":[{"batb":[[0,4.4,11.85]],"batl":[[1,4.6,6],[2,4.7,24.47]],"ltp":4.4,"tv":7172.41,"id":21580749},{"batb":[[0,27,8.96],[2,24,8.37]],"ltp":26.0,"tv":310.79,"id":24608298}]}]}
{"op":"mcm","clk":"994039829","pt":1580548763470,"mc":[{"id":"1.168096552","rc":[{"trd":[[4.4,335.88]],"batb":[[0,4.4,3],[2,4.2,19.33]],"ltp":4.4,"tv":7196.11,"id":21580749}],"tv":22626.08}]}
{"op":"mcm","clk":"994039938","pt":1580548764457,"mc":[{"id":"1.168096552","rc":[{"batb":[[2,4.2,21.33]],"ltp":4.4,"tv":7196.11,"id":21580749}]}]}
{"op":"mcm","clk":"994040244","pt":1580548767488,"mc":[{"id":"1.168096552","rc":[{"trd":[[4.5,1155.75]],"batl":[[0,4.5,53.45]],"ltp":4.5,"tv":7206.31,"id":21580749}],"tv":22636.28}]}
{"op":"mcm","clk":"994040444","pt":1580548769464,"mc":[{"id":"1.168096552","rc":[{"batl":[[1,3.1,96.85]],"ltp":3.0,"tv":8900.33,"id":52106}]}]}
{"op":"mcm","clk":"994041159","pt":1580548776386,"mc":[{"id":"1.168096552","rc":[{"batl":[[0,3.05,49.4]],"ltp":3.0,"tv":8900.33,"id":52106}]}]}
{"op":"mcm","clk":"994041733","pt":1580548782176,"mc":[{"id":"1.168096552","rc":[{"batl":[[0,30,10],[1,32,2],[2,36,2]],"ltp":26.0,"tv":310.79,"id":24608298}]}]}
{"op":"mcm","clk":"994041872","pt":1580548783479,"mc":[{"id":"1.168096552","rc":[{"batb":[[2,4.2,15.79]],"ltp":4.5,"tv":7206.31,"id":21580749}]}]}
{"op":"mcm","clk":"994042089","pt":1580548785474,"mc":[{"id":"1.168096552","rc":[{"batb":[[2,3,80.55]],"batl":[[0,3.15,96.26],[1,3.2,44]],"ltp":3.1,"tv":5394.63,"id":18286408}]}]}
{"op":"mcm","clk":"994042160","pt":1580548786290,"mc":[{"id":"1.168096552","rc":[{"batl":[[0,30,8],[1,32,4]],"ltp":26.0,"tv":310.79,"id":24608298}]}]}
{"op":"mcm","clk":"994042579","pt":1580548790506,"mc":[{"id":"1.168096552","rc":[{"trd":[[4.4,341.88]],"batb":[[0,4.3,57.43],[1,4.2,15.79],[2,4.1,19.34]],"batl":[[0,4.4,5.85],[1,4.5,103.45],[2,4.6,6]],"ltp":4.4,"tv":7212.31,"id":21580749}],"tv":22642.28}]}
{"op":"mcm","clk":"994042694","pt":1580548791489,"mc":[{"id":"1.168096552","rc":[{"batb":[[1,4.2,18.35]],"ltp":4.4,"tv":7212.31,"id":21580749}]}]}
{"op":"mcm","clk":"994042815","pt":1580548792477,"mc":[{"id":"1.168096552","rc":[{"batb":[[1,4.2,21.35]],"batl":[[0,4.4,15.41]],"ltp":4.4,"tv":7212.31,"id":21580749}]}]}
{"op":"mcm","clk":"994043514","pt":1580548799426,"mc":[{"id":"1.168096552","rc":[{"batb":[[1,4.2,18.79]],"batl":[[0,4.4,18.41]],"ltp":4.4,"tv":7212.31,"id":21580749}]}]}
{"op":"mcm","clk":"994044045","pt":1580548804429,"mc":[{"id":"1.168096552","rc":[{"trd":[[3.1,1498.15]],"batb":[[0,3.05,77.03],[1,3,80.55],[2,2.98,47]],"batl":[[0,3.1,3.4],[1,3.15,96.26],[2,3.2,44]],"ltp":3.1,"tv":5407.83,"id":18286408}],"tv":22655.48}]}
{"op":"mcm","clk":"994044152","pt":1580548805416,"mc":[{"id":"1.168096552","rc":[{"trd":[[3.1,1504.95]],"batb":[[0,3.1,38.02],[1,3.05,77.03],[2,3,88.29]],"batl":[[0,3.15,96.26],[1,3.2,44],[2,3.25,320]],"ltp":3.1,"tv":5414.63,"id":18286408},{"trd":[[15.5,12.22]],"batb":[[0,15.5,5.92],[1,15,12.43],[2,14.5,12.63]],"batl":[[0,16,2.25],[1,17,1.76],[2,18,1.87]],"ltp":15.5,"tv":631.39,"id":26640937},{"batb":[[0,4.3,87.29]],"ltp":4.4,"tv":7212.31,"id":21580749},{"batb":[[0,34,5.13]],"batl":[[0,40,2.02],[1,42,7],[2,48,7]],"ltp":32.0,"tv":197.54,"id":27706761},{"batb":[[0,3,93.75],[1,2.98,54.46]],"ltp":3.0,"tv":8900.33,"id":52106},{"batb":[[0,28,4.59],[1,27,8.96],[2,26,6.53]],"ltp":26.0,"tv":310.79,"id":24608298}],"tv":22667.01}]}
{"op":"mcm","clk":"994044265","pt":1580548806506,"mc":[{"id":"1.168096552","rc":[{"batb":[[0,15.5,7.92]],"batl":[[0,17,3.76],[1,18,1.87],[2,19.5,18.58]],"ltp":15.5,"tv":631.39,"id":26640937},{"batl":[[0,42,7],[1,48,7],[2,50,2]],"ltp":32.0,"tv":197.54,"id":27706761},{"batl":[[0,3.05,40.59]],"ltp":3.0,"tv":8900.33,"id":52106}]}]}
{"op":"mcm","clk":"994044349","pt":1580548807394,"mc":[{"id":"1.168096552","rc":[{"batl":[[2,19.5,13]],"ltp":15.5,"tv":631.39,"id":26640937},{"batb":[[1,2.98,40.68]],"ltp":3.0,"tv":8900.33,"id":52106}]}]}
{"op":"mcm","clk":"994044441","pt":1580548808432,"mc":[{"id":"1.168096552","rc":[{"trd":[[28,9.18]],"batb":[[0,28,2]],"batl":[[0,30,10]],"ltp":28.0,"tv":319.96,"id":24608298}],"tv":22676.18}]}
{"op":"mcm","clk":"994045079","pt":1580548815344,"mc":[{"id":"1.168096552","rc":[{"trd":[[4.3,215.15]],"batb":[[0,4.3,85.29]],"ltp":4.3,"tv":7216.31,"id":21580749}],"tv":22680.18}]}
{"op":"mcm","clk":"994045375","pt":1580548818423,"mc":[{"id":"1.168096552","rc":[{"batl":[[2,20,10]],"ltp":15.5,"tv":631.39,"id":26640937}]}]}
{"op":"mcm","clk":"994045480","pt":1580548819516,"mc":[{"id":"1.168096552","rc":[{"trd":[[28,15.08]],"batb":[[0,28,1.05]],"ltp":28.0,"tv":325.86,"id":24608298}],"tv":22686.08}]}
{"op":"mcm","clk":"994045744","pt":1580548822323,"mc":[{"id":"1.168096552","rc":[{"trd":[[4.4,362.42]],"batl":[[0,4.4,8.14]],"ltp":4.4,"tv":7236.85,"id":21580749}],"tv":22706.62}]}
{"op":"mcm","clk":"994046235","pt":1580548827430,"mc":[{"id":"1.168096552","rc":[{"trd":[[4.3,235.14]],"batb":[[0,4.3,75.3]],"ltp":4.3,"tv":7256.84,"id":21580749}],"tv":22726.62}]}
{"op":"mcm","clk":"994046289","pt":1580548827942,"mc":[{"id":"1.168096552","rc":[{"trd":[[4.3,249.33]],"batb":[[0,4.3,68.2]],"ltp":4.3,"tv":7271.04,"id":21580749}],"tv":22740.81}]}
{"op":"mcm","clk":"994046484","pt":1580548830072,"mc":[{"id":"1.168096552","rc":[{"batl":[[0,16,20],[1,16.5,2.16],[2,17,3.76]],"ltp":15.5,"tv":631.39,"id":26640937},{"batl":[[0,42,5],[1,44,2.16],[2,48,7]],"ltp":32.0,"tv":197.54,"id":27706761}]}]}
{"op":"mcm","clk":"994046919","pt":1580548834470,"mc":[{"id":"1.168096552","rc":[{"trd":[[4.3,269.33]],"batb":[[0,4.3,58.2]],"ltp":4.3,"tv":7291.03,"id":21580749}],"tv":22760.8}]}
{"op":"mcm","clk":"994047026","pt":1580548835475,"mc":[{"id":"1.168096552","rc":[{"batl":[[0,4.4,5.14]],"ltp":4.3,"tv":7291.03,"id":21580749}]}]}
{"op":"mcm","clk":"994047574","pt":1580548840478,"mc":[{"id":"1.168096552","rc":[{"trd":[[4.4,372.42]],"batl":[[0,4.5,103.59],[1,4.6,6],[2,4.7,15.51]],"ltp":4.4,"tv":7301.03,"id":21580749}],"tv":22770.8}]}
{"op":"mcm","clk":"994047681","pt":1580548841467,"mc":[{"id":"1.168096552","rc":[{"batb":[[1,4.2,16.79]],"ltp":4.4,"tv":7301.03,"id":21580749}]}]}
{"op":"mcm","clk":"994047796","pt":1580548842458,"mc":[{"id":"1.168096552","rc":[{"trd":[[15.5,26.41]],"batb":[[0,15,12.43],[1,14.5,12.63],[2,14,2]],"batl":[[0,16,22]],"ltp":15.5,"tv":645.58,"id":26640937},{"batb":[[1,4.2,18.79]],"batl":[[0,4.5,103.45]],"ltp":4.4,"tv":7301.03,"id":21580749}],"tv":22785.0}]}
{"op":"mcm","clk":"994047900","pt":1580548843389,"mc":[{"id":"1.168096552","rc":[{"batb":[[1,14.5,16.89]],"ltp":15.5,"tv":645.58,"id":26640937}]}]}
{"op":"mcm","clk":"994048847","pt":1580548852457,"mc":[{"id":"1.168096552","rc":[{"batb":[[0,3.1,48.35]],"ltp":3.1,"tv":5414.63,"id":18286408}]}]}
{"op":"mcm","clk":"994048969","pt":1580548853461,"mc":[{"id":"1.168096552","rc":[{"batb":[[0,4.3,108.2]],"ltp":4.4,"tv":7301.03,"id":21580749}]}]}
{"op":"mcm","clk":"994049062","pt":1580548854283,"mc":[{"id":"1.168096552","rc":[{"batb":[[0,4.4,8.85],[1,4.3,108.2],[2,4.2,20.79]],"ltp":4.4,"tv":7301.03,"id":21580749},{"batl":[[0,42,7]],"ltp":32.0,"tv":197.54,"id":27706761}]}]}
{"op":"mcm","clk":"994049189","pt":1580548855386,"mc":[{"id":"1.168096552","rc":[{"batb":[[2,3,80.55]],"ltp":3.1,"tv":5414.63,"id":18286408},{"batb":[[1,14.5,12.63]],"ltp":15.5,"tv":645.58,"id":26640937},{"batb":[[0,4.4,11.85]],"ltp":4.4,"tv":7301.03,"id":21580749}]}]}
{"op":"mcm","clk":"994049505","pt":1580548858494,"mc":[{"id":"1.168096552","rc":[{"batb":[[0,36,2.31],[1,34,5.13],[2,32,4.73]],"ltp":32.0,"tv":197.54,"id":27706761}]}]}
{"op":"mcm","clk":"994049713","pt":1580548860470,"mc":[{"id":"1.168096552","rc":[{"trd":[[4.4,402.12]],"batb":[[0,4.3,108.2],[1,4.2,20.79],[2,4.1,21.39]],"batl":[[0,4.4,5.15],[1,4.5,103.45],[2,4.6,6]],"ltp":4.4,"tv":7330.73,"id":21580749}],"tv":22814.7}]}
{"op":"mcm","clk":"994049813","pt":1580548861402,"mc":[{"id":"1.168096552","rc":[{"batb":[[1,4.2,27.78]],"ltp":4.4,"tv":7330.73,"id":21580749}]}]}
{"op":"mcm","clk":"994049902","pt":1580548862293,"mc":[{"id":"1.168096552","rc":[{"batb":[[1,4.2,20.79]],"ltp":4.4,"tv":7330.73,"id":21580749}]}]}
{"op":"mcm","clk":"994051011","pt":1580548873513,"mc":[{"id":"1.168096552","rc":[{"batl":[[1,3.1,46.85]],"ltp":3.0,"tv":8900.33,"id":52106}]}]}
{"op":"mcm","clk":"994051098","pt":1580548874302,"mc":[{"id":"1.168096552","rc":[{"batl":[[0,3.05,90.59]],"ltp":3.0,"tv":8900.33,"id":52106}]}]}
{"op":"mcm","clk":"994051786","pt":1580548880413,"mc":[{"id":"1.168096552","rc":[{"trd":[[4.3,314.77]],"batb":[[0,4.3,88.48]],"batl":[[2,4.6,9]],"ltp":4.3,"tv":7376.17,"id":21580749},{"batb":[[1,2.98,42.68],[2,2.96,5]],"ltp":3.0,"tv":8900.33,"id":52106}],"tv":22860.13}]}
{"op":"mcm","clk":"994051882","pt":1580548881412,"mc":[{"id":"1.168096552","rc":[{"trd":[[3.1,1550.39]],"batb":[[0,3.1,25.63]],"ltp":3.1,"tv":5460.07,"id":18286408},{"trd":[[4.3,334.77]],"batb":[[0,4.3,78.48]],"ltp":4.3,"tv":7396.17,"id":21580749},{"batb":[[0,36,4.31],[2,32,2.73]],"batl":[[0,42,5]],"ltp":32.0,"tv":197.54,"id":27706761}],"tv":22925.57}]}
{"op":"mcm","clk":"994051971","pt":1580548882445,"mc":[{"id":"1.168096552","rc":[{"trd":[[3.1,1601.64]],"batb":[[0,3.05,77.03],[1,3,80.55],[2,2.98,47]],"batl":[[0,3.1,324.38],[1,3.15,96.26],[2,3.2,44]],"ltp":3.1,"tv":5511.31,"id":18286408},{"trd":[[3,1631.94]],"batb":[[0,3,71.03]],"ltp":3.0,"tv":8945.77,"id":52106},{"batl":[[0,30,8]],"ltp":28.0,"tv":325.86,"id":24608298}],"tv":23022.26}]}
{"op":"mcm","clk":"994052058","pt":1580548883234,"mc":[{"id":"1.168096552","rc":[{"batb":[[1,3,91.17]],"ltp":3.1,"tv":5511.31,"id":18286408},{"batb":[[0,15.5,2],[1,15,12.43],[2,14.5,12.63]],"batl":[[0,16,20]],"ltp":15.5,"tv":645.58,"id":26640937}]}]}
{"op":"mcm","clk":"994052187","pt":1580548884430,"mc":[{"id":"1.168096552","rc":[{"batb":[[1,3,80.55]],"ltp":3.1,"tv":5511.31,"id":18286408}]}]}
{"op":"mcm","clk":"994052295","pt":1580548885425,"mc":[{"id":"1.168096552","rc":[{"batb":[[0,3.05,68.02]],"ltp":3.1,"tv":5511.31,"id":18286408}]}]}
{"op":"mcm","clk":"994052801","pt":1580548890457,"mc":[{"id":"1.168096552","rc":[{"trd":[[4.4,412.42]],"batb":[[0,4.4,52.41],[1,4.3,78.48],[2,4.2,20.79]],"batl":[[0,4.5,103.45],[1,4.6,9],[2,4.7,18.51]],"ltp":4.4,"tv":7406.46,"id":21580749}],"tv":23032.55}]}
{"op":"mcm","clk":"994052880","pt":1580548891128,"mc":[{"id":"1.168096552","rc":[{"batb":[[0,3.05,57.02]],"batl":[[0,3.1,327.38]],"ltp":3.1,"tv":5511.31,"id":18286408},{"batb":[[0,4.4,55.41]],"batl":[[0,4.5,98.45]],"ltp":4.4,"tv":7406.46,"id":21580749}]}]}
{"op":"mcm","clk":"994053582","pt":1580548897339,"mc":[{"id":"1.168096552","rc":[{"batb":[[0,4.4,61.31]],"ltp":4.4,"tv":7406.46,"id":21580749}]}]}
{"op":"mcm","clk":"994053745","pt":1580548898485,"mc":[{"id":"1.168096552","rc":[{"batb":[[0,3.05,68.02]],"batl":[[0,3.1,27.23]],"ltp":3.1,"tv":5511.31,"id":18286408},{"batl":[[0,16,22]],"ltp":15.5,"tv":645.58,"id":26640937},{"batl":[[0,42,7]],"ltp":32.0,"tv":197.54,"id":27706761}]}]}
{"op":"mcm","clk":"994053848","pt":1580548899421,"mc":[{"id":"1.168096552","rc":[{"batb":[[0,15,12.43],[1,14.5,12.63],[2,14,2]],"ltp":15.5,"tv":645.58,"id":26640937}]}]}
{"op":"mcm","clk":"994053983","pt":1580548900457,"mc":[{"id":"1.168096552","rc":[{"batb":[[0,4.4,8.9]],"ltp":4.4,"tv":7406.46,"id":21580749}]}]}
{"op":"mcm","clk":"994054080","pt":1580548901438,"mc":[{"id":"1.168096552","rc":[{"trd":[[3,1677.36]],"batb":[[0,3,48.33]],"ltp":3.0,"tv":8991.18,"id":52106}],"tv":23077.97}]}
{"op":"mcm","clk":"994054157","pt":1580548902332,"mc":[{"id":"1.168096552","rc":[{"trd":[[3.05,1615.22]],"batb":[[0,3.05,45.3]],"ltp":3.05,"tv":5556.75,"id":18286408}],"tv":23123.4}]}
{"op":"mcm","clk":"994054339","pt":1580548904461,"mc":[{"id":"1.168096552","rc":[{"batb":[[1,3,84.55]],"ltp":3.05,"tv":5556.75,"id":18286408},{"batb":[[0,15.5,2.24],[1,15,12.43],[2,14.5,12.63]],"ltp":15.5,"tv":645.58,"id":26640937},{"trd":[[4.4,430.21]],"batb":[[0,4.3,78.48],[1,4.2,20.79],[2,4.1,24.39]],"batl":[[0,4.4,13.82],[1,4.5,105.45],[2,4.6,9]],"ltp":4.4,"tv":7424.26,"id":21580749},{"batb":[[0,3,51.33]],"ltp":3.0,"tv":8991.18,"id":52106}],"tv":23141.2}]}
{"op":"mcm","clk":"994054411","pt":1580548905154,"mc":[{"id":"1.168096552","rc":[{"batb":[[1,4.2,27.31]],"ltp":4.4,"tv":7424.26,"id":21580749}]}]}
{"op":"mcm","clk":"994054520","pt":1580548906443,"mc":[{"id":"1.168096552","rc":[{"batb":[[1,4.2,20.79]],"ltp":4.4,"tv":7424.26,"id":21580749}]}]}
{"op":"mcm","clk":"994054680","pt":1580548908457,"mc":[{"id":"1.168096552","rc":[{"trd":[[4.4,457.84]],"batb":[[0,4.4,38.6],[1,4.3,78.48],[2,4.2,20.79]],"batl":[[0,4.5,105.45],[1,4.6,9],[2,4.7,18.51]],"ltp":4.4,"tv":7451.89,"id":21580749}],"tv":23168.83}]}
{"op":"mcm","clk":"994054822","pt":1580548909454,"mc":[{"id":"1.168096552","rc":[{"batb":[[0,4.4,41.6]],"batl":[[0,4.5,98.45]],"ltp":4.4,"tv":7451.89,"id":21580749}]}]}
{"op":"mcm","clk":"994055571","pt":1580548917476,"mc":[{"id":"1.168096552","rc":[{"trd":[[3.1,1676.72]],"batb":[[0,3.1,7.53],[1,3.05,45.3],[2,3,84.55]],"batl":[[0,3.15,96.26],[1,3.2,44],[2,3.25,320]],"ltp":3.1,"tv":5631.84,"id":18286408},{"batb":[[0,15,12.43],[1,14.5,12.63],[2,14,2]],"ltp":15.5,"tv":645.58,"id":26640937},{"trd":[[4.4,475.54],[4.5,1231.88]],"batb":[[0,4.4,3.31]],"batl":[[0,4.5,67.38]],"ltp":4.5,"tv":7545.73,"id":21580749},{"trd":[[3.05,933]],"batl":[[0,3.05,45.9]],"ltp":3.05,"tv":9080.56,"id":52106},{"batl":[[0,30,10]],"ltp":28.0,"tv":325.86,"id":24608298}],"tv":23427.13}]}
{"op":"mcm","clk":"994055666","pt":1580548918469,"mc":[{"id":"1.168096552","rc":[{"trd":[[3.1,1691.02]],"batb":[[0,3.05,45.68],[1,3,84.55],[2,2.98,47]],"batl":[[0,3.15,82.76],[1,3.2,17]],"ltp":3.1,"tv":5646.13,"id":18286408},{"batl":[[0,4.5,60.38]],"ltp":4.5,"tv":7545.73,"id":21580749}],"tv":23441.43}]}
{"op":"mcm","clk":"994055872","pt":1580548920387,"mc":[{"id":"1.168096552","rc":[{"batb":[[0,3.05,45.3]],"ltp":3.1,"tv":5646.13,"id":18286408}]}]}
{"op":"mcm","clk":"994055979","pt":1580548921495,"mc":[{"id":"1.168096552","rc":[{"trd":[[3.15,843.64]],"batb":[[0,3.05,56.48]],"batl":[[0,3.15,82.39]],"ltp":3.15,"tv":5646.88,"id":18286408},{"trd":[[4.5,1232.14]],"batl":[[0,4.5,60.25]],"ltp":4.5,"tv":7545.99,"id":21580749}],"tv":23442.43}]}
{"op":"mcm","clk":"994056470","pt":1580548926286,"mc":[{"id":"1.168096552","rc":[{"batb":[[1,3,87.55]],"ltp":3.15,"tv":5646.88,"id":18286408}]}]}
{"op":"mcm","clk":"994056583","pt":1580548927322,"mc":[{"id":"1.168096552","rc":[{"batl":[[0,3.15,80.39],[1,3.2,15]],"ltp":3.15,"tv":5646.88,"id":18286408},{"trd":[[4.4,482.16]],"batb":[[0,4.4,2.69]],"ltp":4.4,"tv":7552.61,"id":21580749},{"batl":[[1,3.1,43.85]],"ltp":3.05,"tv":9080.56,"id":52106}],"tv":23449.05}]}
{"op":"mcm","clk":"994056923","pt":1580548930470,"mc":[{"id":"1.168096552","rc":[{"batb":[[0,4.4,14.69]],"ltp":4.4,"tv":7552.61,"id":21580749}]}]}
{"op":"mcm","clk":"994057119","pt":1580548932503,"mc":[{"id":"1.168096552","rc":[{"batb":[[0,3.1,10],[1,3.05,56.48],[2,3,87.55]],"ltp":3.15,"tv":5646.88,"id":18286408}]}]}
{"op":"mcm","clk":"994057426","pt":1580548935516,"mc":[{"id":"1.168096552","rc":[{"trd":[[4.5,1269.8]],"batl":[[0,4.5,41.42]],"ltp":4.5,"tv":7590.27,"id":21580749}],"tv":23486.71}]}
{"op":"mcm","clk":"994057500","pt":1580548936302,"mc":[{"id":"1.168096552","rc":[{"trd":[[3.05,1752.18],[3.1,1711.02]],"batb":[[0,3,87.55],[1,2.98,47],[2,2.96,36]],"batl":[[0,3.05,245.89],[1,3.15,83.39],[2,3.2,18]],"ltp":3.05,"tv":5803.84,"id":18286408},{"batl":[[0,16,20]],"ltp":15.5,"tv":645.58,"id":26640937},{"batl":[[0,42,5]],"ltp":32.0,"tv":197.54,"id":27706761},{"batl":[[0,30,8]],"ltp":28.0,"tv":325.86,"id":24608298}],"tv":23643.68}]}
{"op":"mcm","clk":"994057621","pt":1580548937436,"mc":[{"id":"1.168096552","rc":[{"trd":[[3.05,1798.08]],"batb":[[1,2.98,52.12]],"batl":[[0,3.05,211.16],[1,3.1,3.09],[2,3.15,83.39]],"ltp":3.05,"tv":5849.74,"id":18286408},{"trd":[[16,8.75]],"batl":[[0,16,11.25]],"ltp":16.0,"tv":654.33,"id":26640937},{"trd":[[4.4,543.36]],"batb":[[0,4.3,78.48],[1,4.2,20.79],[2,4.1,24.39]],"batl":[[0,4.4,13.49],[1,4.5,48.42],[2,4.6,9]],"ltp":4.4,"tv":7651.47,"id":21580749},{"trd":[[42,16.53]],"batl":[[0,48,7],[1,50,2],[2,85,1.08]],"ltp":42.0,"tv":204.21,"id":27706761},{"trd":[[3.05,978.9]],"batb":[[0,3.05,5.09],[1,3,51.33],[2,2.98,56.46]],"batl":[[0,3.1,37.85],[1,3.15,36.38],[2,3.2,65]],"ltp":3.05,"tv":9126.46,"id":52106},{"trd":[[30,4.67]],"batl":[[0,30,3.33]],"ltp":30.0,"tv":330.53,"id":24608298}],"tv":23816.77}]}
{"op":"mcm","clk":"994057742","pt":1580548938427,"mc":[{"id":"1.168096552","rc":[{"batb":[[0,4.3,80.48]],"ltp":4.4,"tv":7651.47,"id":21580749},{"batb":[[0,3.05,10.74]],"ltp":3.05,"tv":9126.46,"id":52106}]}]}
{"op":"mcm","clk":"994057851","pt":1580548939427,"mc":[{"id":"1.168096552","rc":[{"batb":[[0,3,104.43],[1,2.98,47]],"ltp":3.05,"tv":5849.74,"id":18286408},{"batb":[[0,15.5,2.1],[1,15,15.81],[2,14.5,12.63]],"ltp":16.0,"tv":654.33,"id":26640937},{"batb":[[0,4.3,92.26],[1,4.2,31.06]],"ltp":4.4,"tv":7651.47,"id":21580749},{"batb":[[0,36,5.72]],"batl":[[0,46,2.1],[1,48,7],[2,50,2]],"ltp":42.0,"tv":204.21,"id":27706761},{"batb":[[0,3.05,27.34]],"batl":[[0,3.1,10.9],[1,3.15,62.9]],"ltp":3.05,"tv":9126.46,"id":52106},{"batb":[[0,29,2.1],[1,28,1.81],[2,27,8.96]],"ltp":30.0,"tv":330.53,"id":24608298}]}]}
{"op":"mcm","clk":"994057968","pt":1580548940480,"mc":[{"id":"1.168096552","rc":[{"batb":[[1,4.2,20.79]],"ltp":4.4,"tv":7651.47,"id":21580749}]}]}
{"op":"mcm","clk":"994058052","pt":1580548941418,"mc":[{"id":"1.168096552","rc":[{"trd":[[4.4,570.33]],"batb":[[0,4.4,25.12],[1,4.3,92.26],[2,4.2,20.79]],"batl":[[0,4.5,48.42],[1,4.6,9],[2,4.7,18.51]],"ltp":4.4,"tv":7678.44,"id":21580749}],"tv":23843.73}]}
{"op":"mcm","clk":"994058151","pt":1580548942509,"mc":[{"id":"1.168096552","rc":[{"batb":[[0,3,92.43]],"batl":[[0,3.05,214.16]],"ltp":3.05,"tv":5849.74,"id":18286408},{"batb":[[0,4.4,28.12],[1,4.3,90.26]],"batl":[[0,4.5,41.42]],"ltp":4.4,"tv":7678.44,"id":21580749}]}]}
{"op":"mcm","clk":"994058216","pt":1580548943241,"mc":[{"id":"1.168096552","rc":[{"batb":[[0,3,89.43]],"ltp":3.05,"tv":5849.74,"id":18286408}]}]}
{"op":"mcm","clk":"994058812","pt":1580548949451,"mc":[{"id":"1.168096552","rc":[{"batb":[[0,3,239.44]],"ltp":3.05,"tv":5849.74,"id":18286408},{"batb":[[0,4.4,3]],"ltp":4.4,"tv":7678.44,"id":21580749}]}]}
{"op":"mcm","clk":"994059026","pt":1580548951444,"mc":[{"id":"1.168096552","rc":[{"trd":[[3,839.88]],"batb":[[0,3,229.44]],"ltp":3.0,"tv":5869.74,"id":18286408}],"tv":23863.73}]}
{"op":"mcm","clk":"994069696","pt":1580548956443,"mc":[{"id":"1.168096552","rc":[{"batb":[[0,3,241.44]],"ltp":3.0,"tv":5869.74,"id":18286408},{"batb":[[0,3.05,37.52]],"ltp":3.05,"tv":9126.46,"id":52106},{"trd":[[28,18.69],[29,4.2]],"batb":[[0,27,8.96],[1,26,4.53],[2,24,8.37]],"batl":[[0,29,3.79],[1,30,5.33],[2,32,4]],"ltp":28.0,"tv":338.35,"id":24608298}],"tv":23871.55}]}
{"op":"mcm","clk":"994069991","pt":1580548959347,"mc":[{"id":"1.168096552","rc":[{"trd":[[3,959.88]],"batb":[[0,3,181.44]],"ltp":3.0,"tv":5989.74,"id":18286408},{"batb":[[0,27,10.96]],"ltp":28.0,"tv":338.35,"id":24608298}],"tv":23991.55}]}
{"op":"mcm","clk":"994070227","pt":1580548961472,"mc":[{"id":"1.168096552","rc":[{"trd":[[36,56.34]],"batb":[[0,36,2.72]],"ltp":36.0,"tv":210.21,"id":27706761}],"tv":23997.55}]}
{"op":"mcm","clk":"994070389","pt":1580548963361,"mc":[{"id":"1.168096552","rc":[{"batl":[[0,3.05,211.16]],"ltp":3.0,"tv":5989.74,"id":18286408},{"trd":[[4.4,576.33]],"batb":[[0,4.3,90.26],[1,4.2,20.79],[2,4.1,24.39]],"batl":[[0,4.4,7],[1,4.5,48.42],[2,4.6,9]],"ltp":4.4,"tv":7684.44,"id":21580749},{"batb":[[0,36,3.13]],"batl":[[0,46,2.45]],"ltp":36.0,"tv":210.21,"id":27706761}],"tv":24003.55}]}
{"op":"mcm","clk":"994070605","pt":1580548965492,"mc":[{"id":"1.168096552","rc":[{"trd":[[4.4,590.33]],"batb":[[0,4.4,21.13],[1,4.3,90.26],[2,4.2,20.79]],"batl":[[0,4.5,48.42],[1,4.6,9],[2,4.7,18.51]],"ltp":4.4,"tv":7698.43,"id":21580749}],"tv":24017.54}]}
{"op":"mcm","clk":"994070690","pt":1580548966370,"mc":[{"id":"1.168096552","rc":[{"trd":[[4.4,610.31]],"batb":[[0,4.4,11.14]],"batl":[[0,4.5,41.42]],"ltp":4.4,"tv":7718.42,"id":21580749}],"tv":24037.53}]}
{"op":"mcm","clk":"994070919","pt":1580548968399,"mc":[{"id":"1.168096552","rc":[{"batb":[[0,3,169.44]],"batl":[[0,3.05,214.16]],"ltp":3.0,"tv":5989.74,"id":18286408},{"trd":[[3.1,159.09]],"batb":[[0,3.1,19.1],[1,3.05,37.52],[2,3,51.33]],"batl":[[0,3.15,62.9],[1,3.2,69],[2,3.35,6]],"ltp":3.1,"tv":9148.26,"id":52106}],"tv":24059.33}]}
{"op":"mcm","clk":"994071004","pt":1580548969383,"mc":[{"id":"1.168096552","rc":[{"batl":[[2,3.4,3.63]],"ltp":3.1,"tv":9148.26,"id":52106}]}]}
{"op":"mcm","clk":"994071080","pt":1580548970370,"mc":[{"id":"1.168096552","rc":[{"trd":[[3.1,163.09]],"batb":[[0,3.1,17.1]],"ltp":3.1,"tv":9152.26,"id":52106}],"tv":24063.33}]}
{"op":"mcm","clk":"994071400","pt":1580548973498,"mc":[{"id":"1.168096552","rc":[{"batb":[[0,4.4,3]],"ltp":4.4,"tv":7718.42,"id":21580749}]}]}
{"op":"mcm","clk":"994071700","pt":1580548976512,"mc":[{"id":"1.168096552","rc":[{"batb":[[0,3.05,37.52],[1,3,51.33],[2,2.98,42.68]],"ltp":3.1,"tv":9152.26,"id":52106}]}]}
{"op":"mcm","clk":"994072104","pt":1580548980512,"mc":[{"id":"1.168096552","rc":[{"trd":[[3.05,1807.58]],"batl":[[0,3.05,209.41]],"ltp":3.05,"tv":5999.24,"id":18286408}],"tv":24072.83}]}
{"op":"mcm","clk":"994072354","pt":1580548982415,"mc":[{"id":"1.168096552","rc":[{"batb":[[0,3,181.44]],"batl":[[0,3.05,206.41]],"ltp":3.05,"tv":5999.24,"id":18286408},{"trd":[[4.4,622.31]],"batb":[[0,4.3,90.26],[1,4.2,20.79],[2,4.1,24.39]],"batl":[[0,4.4,4],[1,4.5,48.42],[2,4.6,9]],"ltp":4.4,"tv":7730.42,"id":21580749}],"tv":24084.83}]}
{"op":"mcm","clk":"994072918","pt":1580548987508,"mc":[{"id":"1.168096552","rc":[{"batl":[[0,3.05,209.41]],"ltp":3.05,"tv":5999.24,"id":18286408},{"batb":[[0,4.4,3.03],[1,4.3,90.26],[2,4.2,20.79]],"batl":[[0,4.5,41.42],[1,4.6,9],[2,4.7,18.51]],"ltp":4.4,"tv":7730.42,"id":21580749}]}]}
{"op":"mcm","clk":"994073154","pt":1580548990321,"mc":[{"id":"1.168096552","rc":[{"trd":[[3.05,1847.58]],"batl":[[0,3.05,189.41]],"ltp":3.05,"tv":6039.24,"id":18286408}],"tv":24124.83}]}
{"op":"mcm","clk":"994073367","pt":1580548992518,"mc":[{"id":"1.168096552","rc":[{"batl":[[0,3.05,186.41]],"ltp":3.05,"tv":6039.24,"id":18286408},{"trd":[[4.4,628.37]],"batb":[[0,4.3,90.26],[1,4.2,20.79],[2,4.1,24.39]],"batl":[[0,4.4,6.97],[1,4.5,48.42],[2,4.6,9]],"ltp":4.4,"tv":7736.48,"id":21580749},{"trd":[[3.15,120.48]],"batl":[[0,3.15,46.9]],"ltp":3.15,"tv":9192.26,"id":52106}],"tv":24170.89}]}
{"op":"mcm","clk":"994073536","pt":1580548994334,"mc":[{"id":"1.168096552","rc":[{"batl":[[0,4.4,16.97]],"ltp":4.4,"tv":7736.48,"id":21580749}]}]}
{"op":"mcm","clk":"994073724","pt":1580548996296,"mc":[{"id":"1.168096552","rc":[{"batl":[[0,4.4,26.97]],"ltp":4.4,"tv":7736.48,"id":21580749}]}]}
{"op":"mcm","clk":"994073843","pt":1580548997510,"mc":[{"id":"1.168096552","rc":[{"batl":[[0,4.4,36.97]],"ltp":4.4,"tv":7736.48,"id":21580749}]}]}
{"op":"mcm","clk":"994073932","pt":1580548998499,"mc":[{"id":"1.168096552","rc":[{"trd":[[4.4,686.37]],"batl":[[0,4.4,7.97]],"ltp":4.4,"tv":7794.48,"id":21580749}],"tv":24228.89}]}
{"op":"mcm","clk":"994074101","pt":1580549000425,"mc":[{"id":"1.168096552","rc":[{"trd":[[4.3,354.77]],"batb":[[0,4.3,80.26]],"ltp":4.3,"tv":7814.48,"id":21580749}],"tv":24248.89}]}
{"op":"mcm","clk":"994074778","pt":1580549007345,"mc":[{"id":"1.168096552","rc":[{"batl":[[1,3.2,89]],"ltp":3.15,"tv":9192.26,"id":52106}]}]}
{"op":"mcm","clk":"994074971","pt":1580549009335,"mc":[{"id":"1.168096552","rc":[{"batl":[[0,4.4,17.97]],"ltp":4.3,"tv":7814.48,"id":21580749}]}]}
{"op":"mcm","clk":"994075069","pt":1580549010330,"mc":[{"id":"1.168096552","rc":[{"batl":[[0,3.05,236.83]],"ltp":3.05,"tv":6039.24,"id":18286408}]}]}
{"op":"mcm","clk":"994075558","pt":1580549015449,"mc":[{"id":"1.168096552","rc":[{"batb":[[1,4.2,24.73]],"ltp":4.3,"tv":7814.48,"id":21580749}]}]}
{"op":"mcm","clk":"994076424","pt":1580549023471,"mc":[{"id":"1.168096552","rc":[{"batb":[[0,28,2.19],[1,27,10.96],[2,26,4.53]],"ltp":28.0,"tv":338.35,"id":24608298}]}]}
{"op":"mcm","clk":"994076543","pt":1580549024469,"mc":[{"id":"1.168096552","rc":[{"batb":[[0,3,169.44]],"batl":[[0,3.05,239.83]],"ltp":3.05,"tv":6039.24,"id":18286408},{"trd":[[4.4,722.32]],"batb":[[0,4.4,5.84],[1,4.3,80.26],[2,4.2,20.79]],"batl":[[0,4.5,48.42],[1,4.6,9],[2,4.7,18.51]],"ltp":4.4,"tv":7850.43,"id":21580749}],"tv":24284.84}]}
{"op":"mcm","clk":"994076710","pt":1580549025469,"mc":[{"id":"1.168096552","rc":[{"batb":[[0,3,194.19]],"ltp":3.05,"tv":6039.24,"id":18286408}]}]}
{"op":"mcm","clk":"994078405","pt":1580549041502,"mc":[{"id":"1.168096552","rc":[{"batl":[[0,3.15,55.49]],"ltp":3.15,"tv":9192.26,"id":52106}]}]}
{"op":"mcm","clk":"994078813","pt":1580549045196,"mc":[{"id":"1.168096552","rc":[{"trd":[[3.05,1857.9]],"batl":[[0,3.05,234.67]],"ltp":3.05,"tv":6049.56,"id":18286408}],"tv":24295.16}]}
{"op":"mcm","clk":"994079321","pt":1580549050512,"mc":[{"id":"1.168096552","rc":[{"trd":[[15.5,34.61]],"batb":[[0,15,15.81],[1,14.5,12.63],[2,14,2]],"batl":[[0,15.5,2.15],[1,16,13.25],[2,16.5,2.16]],"ltp":15.5,"tv":662.53,"id":26640937},{"batl":[[0,4.5,41.42]],"ltp":4.4,"tv":7850.43,"id":21580749},{"batl":[[0,3.15,28.98]],"ltp":3.15,"tv":9192.26,"id":52106}],"tv":24303.36}]}
{"op":"mcm","clk":"994079792","pt":1580549055519,"mc":[{"id":"1.168096552","rc":[{"batb":[[0,4.4,4.84]],"ltp":4.4,"tv":7850.43,"id":21580749},{"trd":[[3.15,275.89]],"batb":[[0,3.1,10.22],[1,3.05,40.43],[2,3,54.33]],"batl":[[0,3.15,3.08]],"ltp":3.15,"tv":9347.67,"id":52106},{"batb":[[0,27,10.96],[1,26,4.53],[2,24,8.37]],"ltp":28.0,"tv":338.35,"id":24608298}],"tv":24458.78}]}
{"op":"mcm","clk":"994080584","pt":1580549064144,"mc":[{"id":"1.168096552","rc":[{"batl":[[0,3.15,17.08]],"ltp":3.15,"tv":9347.67,"id":52106}]}]}
{"op":"mcm","clk":"994080816","pt":1580549066492,"mc":[{"id":"1.168096552","rc":[{"batb":[[0,3,19.43]],"batl":[[0,3.05,64.59]],"ltp":3.05,"tv":6049.56,"id":18286408},{"batb":[[0,3.1,18.22]],"ltp":3.15,"tv":9347.67,"id":52106}]}]}
{"op":"mcm","clk":"994080916","pt":1580549067434,"mc":[{"id":"1.168096552","rc":[{"batl":[[0,3.05,53.41]],"ltp":3.05,"tv":6049.56,"id":18286408}]}]}
{"op":"mcm","clk":"994081022","pt":1580549068424,"mc":[{"id":"1.168096552","rc":[{"batl":[[1,3.1,14.09]],"ltp":3.05,"tv":6049.56,"id":18286408}]}]}
{"op":"mcm","clk":"994081356","pt":1580549071460,"mc":[{"id":"1.168096552","rc":[{"trd":[[4.4,732.32]],"batb":[[0,4.4,1.84],[2,4.2,18.79]],"batl":[[0,4.5,51.42]],"ltp":4.4,"tv":7860.43,"id":21580749}],"tv":24468.78}]}
{"op":"mcm","clk":"994081409","pt":1580549071937,"mc":[{"id":"1.168096552","rc":[{"batb":[[2,4.2,20.79]],"ltp":4.4,"tv":7860.43,"id":21580749}]}]}
{"op":"mcm","clk":"994082381","pt":1580549081367,"mc":[{"id":"1.168096552","rc":[{"trd":[[4.4,736.32]],"batb":[[0,4.4,2.06],[2,4.2,18.79]],"ltp":4.4,"tv":7864.43,"id":21580749}],"tv":24472.78}]}
{"op":"mcm","clk":"994082468","pt":1580549082355,"mc":[{"id":"1.168096552","rc":[{"batb":[[2,4.2,20.79]],"ltp":4.4,"tv":7864.43,"id":21580749}]}]}
{"op":"mcm","clk":"994082711","pt":1580549084462,"mc":[{"id":"1.168096552","rc":[{"batl":[[0,3.15,35]],"ltp":3.15,"tv":9347.67,"id":52106}]}]}
{"op":"mcm","clk":"994083121","pt":1580549088274,"mc":[{"id":"1.168096552","rc":[{"trd":[[4.5,1289.8]],"batl":[[0,4.5,41.42]],"ltp":4.5,"tv":7884.43,"id":21580749}],"tv":24492.78}]}
{"op":"mcm","clk":"994083858","pt":1580549095395,"mc":[{"id":"1.168096552","rc":[{"batb":[[2,4.2,22.79]],"ltp":4.5,"tv":7884.43,"id":21580749}]}]}
{"op":"mcm","clk":"994083967","pt":1580549096505,"mc":[{"id":"1.168096552","rc":[{"batl":[[0,4.5,51.42]],"ltp":4.5,"tv":7884.43,"id":21580749}]}]}
{"op":"mcm","clk":"994084888","pt":1580549105496,"mc":[{"id":"1.168096552","rc":[{"trd":[[3.05,1894.5]],"batl":[[0,3.05,35.11]],"ltp":3.05,"tv":6086.16,"id":18286408}],"tv":24529.38}]}
{"op":"mcm","clk":"994086456","pt":1580549120504,"mc":[{"id":"1.168096552","rc":[{"trd":[[3,980.27]],"batb":[[0,3,9.24]],"ltp":3.0,"tv":6106.55,"id":18286408}],"tv":24549.77}]}
{"op":"mcm","clk":"994086855","pt":1580549124413,"mc":[{"id":"1.168096552","rc":[{"trd":[[3.1,169.09]],"batb":[[0,3.1,15.22]],"ltp":3.1,"tv":9353.67,"id":52106}],"tv":24555.77}]}
{"op":"mcm","clk":"994086966","pt":1580549125519,"mc":[{"id":"1.168096552","rc":[{"batl":[[1,3.2,69]],"ltp":3.1,"tv":9353.67,"id":52106}]}]}
{"op":"mcm","clk":"994087057","pt":1580549126348,"mc":[{"id":"1.168096552","rc":[{"trd":[[4.4,740.44]],"batb":[[0,4.3,77.26],[1,4.2,17.79],[2,4.1,21.39]],"batl":[[0,4.5,59.36]],"ltp":4.4,"tv":7888.55,"id":21580749}],"tv":24559.89}]}
{"op":"mcm","clk":"994087171","pt":1580549127445,"mc":[{"id":"1.168096552","rc":[{"batb":[[0,3,20.24]],"batl":[[0,3.05,32.11]],"ltp":3.0,"tv":6106.55,"id":18286408},{"batb":[[1,4.2,19.79]],"batl":[[0,4.4,10.94],[1,4.5,58.42],[2,4.6,9]],"ltp":4.4,"tv":7888.55,"id":21580749},{"batl":[[0,3.15,31.92]],"ltp":3.1,"tv":9353.67,"id":52106},{"batb":[[0,28,2.14],[1,27,10.96],[2,26,4.53]],"ltp":28.0,"tv":338.35,"id":24608298}]}]}
{"op":"mcm","clk":"994087337","pt":1580549129218,"mc":[{"id":"1.168096552","rc":[{"batl":[[0,3.15,14],[2,3.25,17.38]],"ltp":3.1,"tv":9353.67,"id":52106}]}]}
{"op":"mcm","clk":"994088136","pt":1580549136450,"mc":[{"id":"1.168096552","rc":[{"trd":[[4.3,374.77]],"batb":[[0,4.3,67.25]],"batl":[[0,4.4,20.94]],"ltp":4.3,"tv":7908.55,"id":21580749}],"tv":24579.89}]}
{"op":"mcm","clk":"994088621","pt":1580549140978,"mc":[{"id":"1.168096552","rc":[{"trd":[[3.05,1914.5]],"batl":[[0,3.05,22.11]],"ltp":3.05,"tv":6126.55,"id":18286408}],"tv":24599.89}]}
{"op":"mcm","clk":"994089620","pt":1580549151150,"mc":[{"id":"1.168096552","rc":[{"batl":[[0,3.05,24.11]],"ltp":3.05,"tv":6126.55,"id":18286408},{"trd":[[4.4,782.32]],"batb":[[0,4.4,9.06],[1,4.3,67.25],[2,4.2,19.79]],"batl":[[0,4.5,58.42],[1,4.6,9],[2,4.7,18.51]],"ltp":4.4,"tv":7950.43,"id":21580749}],"tv":24641.77}]}
{"op":"mcm","clk":"994089765","pt":1580549152461,"mc":[{"id":"1.168096552","rc":[{"batb":[[1,3.05,30.25]],"ltp":3.1,"tv":9353.67,"id":52106}]}]}
{"op":"mcm","clk":"994090058","pt":1580549155349,"mc":[{"id":"1.168096552","rc":[{"trd":[[4.3,376.65],[4.4,800.44]],"batb":[[0,4.3,66.31],[1,4.2,17.79],[2,4.1,21.39]],"ltp":4.3,"tv":7970.43,"id":21580749}],"tv":24661.77}]}
{"op":"mcm","clk":"994090988","pt":1580549164414,"mc":[{"id":"1.168096552","rc":[{"batl":[[0,3.05,22.11]],"ltp":3.05,"tv":6126.55,"id":18286408},{"batb":[[1,4.2,24.13]],"batl":[[0,4.4,2],[1,4.5,58.42],[2,4.6,9]],"ltp":4.3,"tv":7970.43,"id":21580749}]}]}
{"op":"mcm","clk":"994092600","pt":1580549179516,"mc":[{"id":"1.168096552","rc":[{"batb":[[0,36,2.72]],"ltp":36.0,"tv":210.21,"id":27706761}]}]}
{"op":"mcm","clk":"994092943","pt":1580549182391,"mc":[{"id":"1.168096552","rc":[{"batl":[[0,4.4,13.52]],"ltp":4.3,"tv":7970.43,"id":21580749}]}]}
{"op":"mcm","clk":"994093805","pt":1580549190436,"mc":[{"id":"1.168096552","rc":[{"batb":[[1,3.05,130.25]],"ltp":3.1,"tv":9353.67,"id":52106}]}]}
{"op":"mcm","clk":"994094366","pt":1580549196431,"mc":[{"id":"1.168096552","rc":[{"trd":[[4.3,396.66]],"batb":[[0,4.3,56.31]],"ltp":4.3,"tv":7990.43,"id":21580749}],"tv":24681.77}]}
{"op":"mcm","clk":"994094623","pt":1580549199447,"mc":[{"id":"1.168096552","rc":[{"trd":[[4.4,821.4]],"batl":[[0,4.4,3.04]],"ltp":4.4,"tv":8011.39,"id":21580749}],"tv":24702.73}]}
{"op":"mcm","clk":"994094824","pt":1580549201424,"mc":[{"id":"1.168096552","rc":[{"batl":[[0,3.05,24.11]],"ltp":3.05,"tv":6126.55,"id":18286408},{"trd":[[4.4,827.48]],"batb":[[0,4.4,7.17],[1,4.3,56.31],[2,4.2,24.13]],"batl":[[0,4.5,58.42],[1,4.6,9],[2,4.7,18.51]],"ltp":4.4,"tv":8017.47,"id":21580749},{"batl":[[1,3.2,67]],"ltp":3.1,"tv":9353.67,"id":52106},{"batb":[[0,27,10.96],[1,26,4.53],[2,24,8.37]],"ltp":28.0,"tv":338.35,"id":24608298}],"tv":24708.81}]}
{"op":"mcm","clk":"994095026","pt":1580549203360,"mc":[{"id":"1.168096552","rc":[{"batl":[[0,46,2.1]],"ltp":36.0,"tv":210.21,"id":27706761}]}]}
{"op":"mcm","clk":"994095220","pt":1580549205452,"mc":[{"id":"1.168096552","rc":[{"batb":[[2,4.2,26.13]],"ltp":4.4,"tv":8017.47,"id":21580749}]}]}
{"op":"mcm","clk":"994095537","pt":1580549208480,"mc":[{"id":"1.168096552","rc":[{"batl":[[0,4.5,27]],"ltp":4.4,"tv":8017.47,"id":21580749}]}]}
{"op":"mcm","clk":"994095629","pt":1580549209456,"mc":[{"id":"1.168096552","rc":[{"trd":[[3,1019.88]],"batb":[[0,2.98,47],[1,2.96,36],[2,2.94,4.75]],"batl":[[0,3.05,24.3]],"ltp":3.0,"tv":6166.16,"id":18286408},{"trd":[[4.5,1329.81]],"batb":[[0,4.5,2.32],[1,4.4,7.17],[2,4.3,56.31]],"batl":[[0,4.6,9],[1,4.7,26.5],[2,4.8,13.03]],"ltp":4.5,"tv":8057.48,"id":21580749},{"batl":[[0,29,5.79]],"ltp":28.0,"tv":338.35,"id":24608298}],"tv":24788.43}]}
{"op":"mcm","clk":"994095713","pt":1580549210338,"mc":[{"id":"1.168096552","rc":[{"trd":[[3,1020.26]],"batl":[[0,3.05,24.11]],"ltp":3.0,"tv":6166.54,"id":18286408}],"tv":24788.81}]}
{"op":"mcm","clk":"994095825","pt":1580549211430,"mc":[{"id":"1.168096552","rc":[{"batl":[[1,4.7,18.51]],"ltp":4.5,"tv":8057.48,"id":21580749}]}]}
{"op":"mcm","clk":"994096020","pt":1580549213361,"mc":[{"id":"1.168096552","rc":[{"trd":[[3.05,1935.5]],"batl":[[0,3.05,13.61]],"ltp":3.05,"tv":6187.54,"id":18286408}],"tv":24809.81}]}
{"op":"mcm","clk":"994096951","pt":1580549222521,"mc":[{"id":"1.168096552","rc":[{"trd":[[3.1,173.09]],"batb":[[0,3.1,13.22]],"ltp":3.1,"tv":9357.67,"id":52106}],"tv":24813.81}]}
{"op":"mcm","clk":"994097129","pt":1580549224509,"mc":[{"id":"1.168096552","rc":[{"trd":[[3.15,279.81]],"batl":[[0,3.15,12.04]],"ltp":3.15,"tv":9361.59,"id":52106}],"tv":24817.73}]}
{"op":"mcm","clk":"994098505","pt":1580549240451,"mc":[{"id":"1.168096552","rc":[{"batl":[[1,3.1,41.57]],"ltp":3.05,"tv":6187.54,"id":18286408},{"batl":[[0,4.6,2]],"ltp":4.5,"tv":8057.48,"id":21580749},{"trd":[[26,20.23],[27,21.93]],"batb":[[0,25,8.67],[1,24,14.45],[2,20,1.46]],"batl":[[0,27,9.03],[1,29,3.79],[2,30,3.33]],"ltp":26.0,"tv":368.18,"id":24608298}],"tv":24847.56}]}
{"op":"mcm","clk":"994098588","pt":1580549241512,"mc":[{"id":"1.168096552","rc":[{"batl":[[1,3.1,44.51]],"ltp":3.05,"tv":6187.54,"id":18286408},{"batb":[[0,24,10.95],[1,20,1.46],[2,19,4.31]],"ltp":26.0,"tv":368.18,"id":24608298}]}]}
{"op":"mcm","clk":"994098641","pt":1580549242130,"mc":[{"id":"1.168096552","rc":[{"batl":[[2,3.4,3.63]],"ltp":3.15,"tv":9361.59,"id":52106},{"trd":[[26,21.39]],"batb":[[0,24,10.37]],"batl":[[0,26,1.53],[1,27,9.03],[2,29,3.79]],"ltp":26.0,"tv":369.34,"id":24608298}],"tv":24848.72}]}
{"op":"mcm","clk":"994098728","pt":1580549243422,"mc":[{"id":"1.168096552","rc":[{"batb":[[2,19.5,8.54]],"ltp":26.0,"tv":369.34,"id":24608298}]}]}
{"op":"mcm","clk":"994098806","pt":1580549244351,"mc":[{"id":"1.168096552","rc":[{"trd":[[14.5,119.76],[15,113.79]],"batb":[[0,14.5,6.64],[1,14,2],[2,13.5,1.06]],"batl":[[0,15,14.19],[1,15.5,2.15],[2,16,13.25]],"ltp":15.0,"tv":708.11,"id":26640937}],"tv":24894.3}]}
{"op":"mcm","clk":"994098898","pt":1580549245450,"mc":[{"id":"1.168096552","rc":[{"batl":[[0,3.05,11.61],[1,3.1,41.42],[2,3.15,80.39]],"ltp":3.05,"tv":6187.54,"id":18286408},{"batb":[[0,14.5,4.64],[1,14,15.37]],"ltp":15.0,"tv":708.11,"id":26640937},{"batb":[[2,19.5,12.81]],"ltp":26.0,"tv":369.34,"id":24608298}]}]}
{"op":"mcm","clk":"994098994","pt":1580549246445,"mc":[{"id":"1.168096552","rc":[{"batb":[[1,14,4]],"ltp":15.0,"tv":708.11,"id":26640937}]}]}
{"op":"mcm","clk":"994099079","pt":1580549247442,"mc":[{"id":"1.168096552","rc":[{"batl":[[0,3.05,13.61],[2,3.15,78.39]],"ltp":3.05,"tv":6187.54,"id":18286408}]}]}
{"op":"mcm","clk":"994099435","pt":1580549251353,"mc":[{"id":"1.168096552","rc":[{"trd":[[4.6,2168.42]],"batl":[[0,4.7,19.13],[1,4.8,19.03],[2,4.9,46.53]],"ltp":4.6,"tv":8077.52,"id":21580749}],"tv":24914.34}]}
{"op":"mcm","clk":"994099620","pt":1580549253443,"mc":[{"id":"1.168096552","rc":[{"batb":[[0,4.5,12.52]],"ltp":4.6,"tv":8077.52,"id":21580749}]}]}
{"op":"mcm","clk":"994099711","pt":1580549254439,"mc":[{"id":"1.168096552","rc":[{"batl":[[0,4.6,2.62],[1,4.7,18.51],[2,4.8,19.03]],"ltp":4.6,"tv":8077.52,"id":21580749}]}]}
{"op":"mcm","clk":"994099785","pt":1580549255370,"mc":[{"id":"1.168096552","rc":[{"batb":[[1,21,4.27],[2,20,5.73]],"ltp":26.0,"tv":369.34,"id":24608298}]}]}
{"op":"mcm","clk":"994099897","pt":1580549256469,"mc":[{"id":"1.168096552","rc":[{"trd":[[4.6,2172.42]],"batb":[[0,4.6,5.46],[1,4.5,25.52],[2,4.4,7.17]],"batl":[[0,4.7,18.51],[1,4.8,19.03],[2,4.9,46.53]],"ltp":4.6,"tv":8081.52,"id":21580749},{"batb":[[0,3.1,25.18]],"ltp":3.15,"tv":9361.59,"id":52106}],"tv":24918.34}]}
{"op":"mcm","clk":"994100605","pt":1580549264465,"mc":[{"id":"1.168096552","rc":[{"batb":[[1,4.5,15.32]],"ltp":4.6,"tv":8081.52,"id":21580749}]}]}
{"op":"mcm","clk":"994100694","pt":1580549265353,"mc":[{"id":"1.168096552","rc":[{"batl":[[0,3.05,15.61]],"ltp":3.05,"tv":6187.54,"id":18286408},{"trd":[[4.7,1867.61]],"batl":[[0,4.7,8.31]],"ltp":4.7,"tv":8101.92,"id":21580749}],"tv":24938.74}]}
{"op":"mcm","clk":"994100876","pt":1580549267476,"mc":[{"id":"1.168096552","rc":[{"batb":[[1,22,7],[2,21,4.27]],"batl":[[0,27,11.03],[1,29,3.79],[2,30,3.33]],"ltp":26.0,"tv":369.34,"id":24608298}]}]}
{"op":"mcm","clk":"994101244","pt":1580549271462,"mc":[{"id":"1.168096552","rc":[{"batb":[[0,2.98,56.93]],"ltp":3.05,"tv":6187.54,"id":18286408},{"batb":[[0,14.5,6.68]],"ltp":15.0,"tv":708.11,"id":26640937},{"batb":[[0,4.6,11.89],[2,4.4,9.17]],"ltp":4.7,"tv":8101.92,"id":21580749},{"batb":[[0,3.1,34.72]],"ltp":3.15,"tv":9361.59,"id":52106},{"batb":[[0,25,2.28],[1,24,11.6],[2,22,11.27]],"ltp":26.0,"tv":369.34,"id":24608298}]}]}
{"op":"mcm","clk":"994101273","pt":1580549271768,"mc":[{"id":"1.168096552","rc":[{"batb":[[0,36,3.54]],"ltp":36.0,"tv":210.21,"id":27706761},{"batl":[[1,3.2,84.64]],"ltp":3.15,"tv":9361.59,"id":52106}]}]}
{"op":"mcm","clk":"994101400","pt":1580549273175,"mc":[{"id":"1.168096552","rc":[{"batb":[[2,22,7]],"ltp":26.0,"tv":369.34,"id":24608298}]}]}
{"op":"mcm","clk":"994101609","pt":1580549275473,"mc":[{"id":"1.168096552","rc":[{"trd":[[4.6,2196.2]],"batb":[[0,4.5,15.32],[1,4.4,9.17],[2,4.3,56.31]],"ltp":4.6,"tv":8125.7,"id":21580749}],"tv":24962.52}]}
{"op":"mcm","clk":"994101713","pt":1580549276508,"mc":[{"id":"1.168096552","rc":[{"batl":[[1,3.2,67]],"ltp":3.15,"tv":9361.59,"id":52106}]}]}
{"op":"mcm","clk":"994101801","pt":1580549277510,"mc":[{"id":"1.168096552","rc":[{"batl":[[2,3.25,17.38]],"ltp":3.15,"tv":9361.59,"id":52106}]}]}
{"op":"mcm","clk":"994102192","pt":1580549281521,"mc":[{"id":"1.168096552","rc":[{"batl":[[0,4.6,10],[1,4.7,8.31],[2,4.8,19.03]],"ltp":4.6,"tv":8125.7,"id":21580749}]}]}
{"op":"mcm","clk":"994102570","pt":1580549285427,"mc":[{"id":"1.168096552","rc":[{"batl":[[0,4.6,20]],"ltp":4.6,"tv":8125.7,"id":21580749}]}]}
{"op":"mcm","clk":"994102826","pt":1580549287513,"mc":[{"id":"1.168096552","rc":[{"batb":[[0,25,7],[2,20,1.46]],"ltp":26.0,"tv":369.34,"id":24608298}]}]}
{"op":"mcm","clk":"994104581","pt":1580549305433,"mc":[{"id":"1.168096552","rc":[{"batb":[[0,4.5,35.67]],"ltp":4.6,"tv":8125.7,"id":21580749},{"batb":[[0,25,9]],"ltp":26.0,"tv":369.34,"id":24608298}]}]}
{"op":"mcm","clk":"994104902","pt":1580549308463,"mc":[{"id":"1.168096552","rc":[{"batb":[[0,4.5,22.67],[2,4.3,11.78]],"ltp":4.6,"tv":8125.7,"id":21580749}]}]}
{"op":"mcm","clk":"994105510","pt":1580549314144,"mc":[{"id":"1.168096552","rc":[{"batb":[[0,4.5,25.67]],"ltp":4.6,"tv":8125.7,"id":21580749}]}]}
{"op":"mcm","clk":"994105764","pt":1580549316336,"mc":[{"id":"1.168096552","rc":[{"batb":[[0,36,3.99]],"ltp":36.0,"tv":210.21,"id":27706761}]}]}
{"op":"mcm","clk":"994105976","pt":1580549318464,"mc":[{"id":"1.168096552","rc":[{"trd":[[4.5,1353.8]],"batb":[[0,4.5,13.67]],"batl":[[0,4.6,26]],"ltp":4.5,"tv":8149.7,"id":21580749}],"tv":24986.52}]}
{"op":"mcm","clk":"994106752","pt":1580549326379,"mc":[{"id":"1.168096552","rc":[{"batl":[[2,3.15,88.39]],"ltp":3.05,"tv":6187.54,"id":18286408}]}]}
{"op":"mcm","clk":"994106828","pt":1580549327058,"mc":[{"id":"1.168096552","rc":[{"batl":[[1,3.1,51.42]],"ltp":3.05,"tv":6187.54,"id":18286408}]}]}
{"op":"mcm","clk":"994106964","pt":1580549328464,"mc":[{"id":"1.168096552","rc":[{"batb":[[0,3,10],[1,2.98,56.93],[2,2.96,36]],"batl":[[0,3.05,25.61]],"ltp":3.05,"tv":6187.54,"id":18286408}]}]}
{"op":"mcm","clk":"994107052","pt":1580549329350,"mc":[{"id":"1.168096552","rc":[{"batl":[[1,3.1,53.42]],"ltp":3.05,"tv":6187.54,"id":18286408}]}]}
{"op":"mcm","clk":"994107514","pt":1580549333975,"mc":[{"id":"1.168096552","rc":[{"batl":[[0,27,9.03],[1,28,4.58]],"ltp":26.0,"tv":369.34,"id":24608298}]}]}
{"op":"mcm","clk":"994108233","pt":1580549341366,"mc":[{"id":"1.168096552","rc":[{"trd":[[4.5,1373.8]],"batb":[[0,4.5,3.67]],"ltp":4.5,"tv":8169.7,"id":21580749}],"tv":25006.52}]}
{"op":"mcm","clk":"994108826","pt":1580549347467,"mc":[{"id":"1.168096552","rc":[{"trd":[[3.05,1986.73]],"batb":[[0,3.05,6.39],[1,3,10],[2,2.98,56.93]],"batl":[[0,3.1,53.42],[1,3.15,88.39],[2,3.2,15]],"ltp":3.05,"tv":6238.76,"id":18286408}],"tv":25057.74}]}
{"op":"mcm","clk":"994108928","pt":1580549348400,"mc":[{"id":"1.168096552","rc":[{"batb":[[1,4.4,11.17]],"ltp":4.5,"tv":8169.7,"id":21580749},{"batl":[[1,28,2]],"ltp":26.0,"tv":369.34,"id":24608298}]}]}
{"op":"mcm","clk":"994109049","pt":1580549349510,"mc":[{"id":"1.168096552","rc":[{"batb":[[1,3,21]],"batl":[[1,3.15,100.17]],"ltp":3.05,"tv":6238.76,"id":18286408},{"batl":[[0,3.15,29.96],[2,3.4,3.63]],"ltp":3.15,"tv":9361.59,"id":52106},{"batl":[[0,27,11.03]],"ltp":26.0,"tv":369.34,"id":24608298}]}]}
{"op":"mcm","clk":"994109155","pt":1580549350503,"mc":[{"id":"1.168096552","rc":[{"trd":[[3,1087.48],[3.05,1999.51]],"batb":[[0,2.98,56.93],[1,2.96,36],[2,2.94,14.8]],"batl":[[0,3.05,3.05],[1,3.1,53.42],[2,3.15,100.17]],"ltp":3.0,"tv":6318.76,"id":18286408},{"batb":[[0,38,2.5],[1,36,3.54],[2,34,5.13]],"ltp":36.0,"tv":210.21,"id":27706761},{"batb":[[0,26,2.05],[1,25,9],[2,24,11.6]],"batl":[[0,27,9.03]],"ltp":26.0,"tv":369.34,"id":24608298}],"tv":25137.74}]}
{"op":"mcm","clk":"994109258","pt":1580549351496,"mc":[{"id":"1.168096552","rc":[{"batb":[[0,36,5.99],[1,34,5.13],[2,32,2.73]],"ltp":36.0,"tv":210.21,"id":27706761},{"batl":[[0,3.15,12.04]],"ltp":3.15,"tv":9361.59,"id":52106}]}]}
{"op":"mcm","clk":"994109629","pt":1580549355295,"mc":[{"id":"1.168096552","rc":[{"batl":[[0,3.05,17.05]],"ltp":3.0,"tv":6318.76,"id":18286408}]}]}
{"op":"mcm","clk":"994110308","pt":1580549362236,"mc":[{"id":"1.168096552","rc":[{"trd":[[3.05,2017.51]],"batb":[[0,3,6.05],[1,2.98,56.93],[2,2.96,36]],"batl":[[0,3.05,11.05]],"ltp":3.05,"tv":6336.76,"id":18286408},{"batb":[[0,36,3.99]],"ltp":36.0,"tv":210.21,"id":27706761},{"trd":[[3.15,297.81]],"batb":[[0,3.1,45.86]],"batl":[[0,3.15,3.04]],"ltp":3.15,"tv":9379.59,"id":52106}],"tv":25173.74}]}
{"op":"mcm","clk":"994111445","pt":1580549373323,"mc":[{"id":"1.168096552","rc":[{"trd":[[3,1099.48]],"batb":[[0,3,10.23]],"ltp":3.0,"tv":6348.76,"id":18286408},{"trd":[[4.5,1375.14],[4.6,2202.2]],"batb":[[0,4.4,11.17],[1,4.3,13.78],[2,4.2,19.79]],"batl":[[0,4.6,23]],"ltp":4.5,"tv":8177.04,"id":21580749},{"batb":[[0,36,5.99]],"ltp":36.0,"tv":210.21,"id":27706761}],"tv":25193.08}]}
{"op":"mcm","clk":"994111869","pt":1580549377228,"mc":[{"id":"1.168096552","rc":[{"batl":[[0,3.05,13.05]],"ltp":3.0,"tv":6348.76,"id":18286408}]}]}
{"op":"mcm","clk":"994111978","pt":1580549378427,"mc":[{"id":"1.168096552","rc":[{"trd":[[3,1119.48]],"batb":[[0,2.98,57.16],[1,2.96,36],[2,2.94,14.8]],"ltp":3.0,"tv":6368.76,"id":18286408}],"tv":25213.08}]}
{"op":"mcm","clk":"994112069","pt":1580549379463,"mc":[{"id":"1.168096552","rc":[{"batl":[[2,3.3,17.11]],"ltp":3.15,"tv":9379.59,"id":52106}]}]}
{"op":"mcm","clk":"994112622","pt":1580549385454,"mc":[{"id":"1.168096552","rc":[{"batb":[[0,2.98,56.93]],"ltp":3.0,"tv":6368.76,"id":18286408},{"trd":[[3.15,303.89]],"batb":[[0,3.15,27.15],[1,3.1,48.95],[2,3.05,130.25]],"batl":[[0,3.2,65],[1,3.25,3.24],[2,3.3,20.11]],"ltp":3.15,"tv":9385.67,"id":52106}],"tv":25219.16}]}
{"op":"mcm","clk":"994112716","pt":1580549386444,"mc":[{"id":"1.168096552","rc":[{"batb":[[1,2.96,41]],"batl":[[0,3.05,18.05]],"ltp":3.0,"tv":6368.76,"id":18286408}]}]}
{"op":"mcm","clk":"994113013","pt":1580549389472,"mc":[{"id":"1.168096552","rc":[{"batb":[[0,2.98,66.84]],"ltp":3.0,"tv":6368.76,"id":18286408},{"batb":[[0,14.5,8.72]],"ltp":15.0,"tv":708.11,"id":26640937},{"batb":[[0,4.4,17.88]],"ltp":4.5,"tv":8177.04,"id":21580749},{"batb":[[0,36,6.81]],"ltp":36.0,"tv":210.21,"id":27706761},{"batb":[[0,3.15,36.53]],"ltp":3.15,"tv":9385.67,"id":52106},{"batb":[[0,26,3.19]],"ltp":26.0,"tv":369.34,"id":24608298}]}]}
{"op":"mcm","clk":"994113648","pt":1580549395462,"mc":[{"id":"1.168096552","rc":[{"batb":[[2,4.2,21.79]],"batl":[[0,4.5,10],[1,4.6,23],[2,4.7,8.31]],"ltp":4.5,"tv":8177.04,"id":21580749}]}]}
{"op":"mcm","clk":"994113767","pt":1580549396356,"mc":[{"id":"1.168096552","rc":[{"batb":[[2,4.2,24.79]],"ltp":4.5,"tv":8177.04,"id":21580749}]}]}
{"op":"mcm","clk":"994113906","pt":1580549397864,"mc":[{"id":"1.168096552","rc":[{"batl":[[0,4.5,15]],"ltp":4.5,"tv":8177.04,"id":21580749}]}]}
{"op":"mcm","clk":"994114155","pt":1580549400500,"mc":[{"id":"1.168096552","rc":[{"batl":[[0,3.05,28.39],[1,3.1,64.24],[2,3.15,150.17]],"ltp":3.0,"tv":6368.76,"id":18286408}]}]}
{"op":"mcm","clk":"994115475","pt":1580549412398,"mc":[{"id":"1.168096552","rc":[{"trd":[[4.4,847.48]],"batb":[[0,4.4,7.88]],"ltp":4.4,"tv":8197.04,"id":21580749}],"tv":25239.16}]}
{"op":"mcm","clk":"994115572","pt":1580549413288,"mc":[{"id":"1.168096552","rc":[{"batl":[[0,4.5,22]],"ltp":4.4,"tv":8197.04,"id":21580749}]}]}
{"op":"mcm","clk":"994115815","pt":1580549415421,"mc":[{"id":"1.168096552","rc":[{"trd":[[4.4,867.48],[4.5,1379.14]],"batb":[[0,4.3,13.78],[1,4.2,34.1],[2,4.1,21.39]],"batl":[[0,4.5,20]],"ltp":4.5,"tv":8221.04,"id":21580749},{"batl":[[2,3.3,3]],"ltp":3.15,"tv":9385.67,"id":52106}],"tv":25263.16}]}
{"op":"mcm","clk":"994116131","pt":1580549418490,"mc":[{"id":"1.168096552","rc":[{"batb":[[0,4.4,20.35],[1,4.3,13.78],[2,4.2,36.1]],"ltp":4.5,"tv":8221.04,"id":21580749}]}]}
{"op":"mcm","clk":"994116213","pt":1580549419216,"mc":[{"id":"1.168096552","rc":[{"batb":[[0,4.4,22.35],[2,4.2,24.79]],"batl":[[0,4.5,13]],"ltp":4.5,"tv":8221.04,"id":21580749}]}]}
{"op":"mcm","clk":"994116346","pt":1580549420416,"mc":[{"id":"1.168096552","rc":[{"trd":[[4.4,871.48]],"batb":[[0,4.4,20.35]],"ltp":4.4,"tv":8225.04,"id":21580749}],"tv":25267.16}]}
{"op":"mcm","clk":"994117184","pt":1580549428412,"mc":[{"id":"1.168096552","rc":[{"trd":[[4.5,1399.64]],"batl":[[0,4.5,2.75]],"ltp":4.5,"tv":8245.54,"id":21580749}],"tv":25287.66}]}
{"op":"mcm","clk":"994117458","pt":1580549431429,"mc":[{"id":"1.168096552","rc":[{"batl":[[0,3,4],[1,3.05,28.39],[2,3.1,64.24]],"ltp":3.0,"tv":6368.76,"id":18286408}]}]}
{"op":"mcm","clk":"994117853","pt":1580549435435,"mc":[{"id":"1.168096552","rc":[{"trd":[[2.98,72]],"batb":[[0,2.98,64.84]],"batl":[[1,3.05,26.39]],"ltp":2.98,"tv":6372.76,"id":18286408}],"tv":25291.66}]}
{"op":"mcm","clk":"994118059","pt":1580549437260,"mc":[{"id":"1.168096552","rc":[{"batb":[[2,4.2,26.79]],"ltp":4.5,"tv":8245.54,"id":21580749}]}]}
{"op":"mcm","clk":"994118321","pt":1580549439462,"mc":[{"id":"1.168096552","rc":[{"batl":[[2,3.1,66.24]],"ltp":2.98,"tv":6372.76,"id":18286408},{"batb":[[1,3.1,52.95],[2,3.05,134.25]],"ltp":3.15,"tv":9385.67,"id":52106},{"trd":[[26,27.77]],"batb":[[0,25,9],[1,24,11.6],[2,20,1.46]],"batl":[[0,27,11.84]],"ltp":26.0,"tv":375.72,"id":24608298}],"tv":25298.04}]}
{"op":"mcm","clk":"994118917","pt":1580549445351,"mc":[{"id":"1.168096552","rc":[{"trd":[[2.98,76]],"batb":[[0,2.98,51.84]],"ltp":2.98,"tv":6376.76,"id":18286408},{"trd":[[4.5,1405.14]],"batb":[[0,4.5,11.31],[1,4.4,20.35],[2,4.3,13.78]],"batl":[[0,4.6,23],[1,4.7,8.31],[2,4.8,19.03]],"ltp":4.5,"tv":8251.04,"id":21580749}],"tv":25307.54}]}
{"op":"mcm","clk":"994119023","pt":1580549446472,"mc":[{"id":"1.168096552","rc":[{"batl":[[1,3.25,20.62]],"ltp":3.15,"tv":9385.67,"id":52106}]}]}
{"op":"mcm","clk":"994119707","pt":1580549453472,"mc":[{"id":"1.168096552","rc":[{"trd":[[4.5,1427.75]],"batb":[[0,4.4,20.35],[1,4.3,24.49],[2,4.2,24.79]],"ltp":4.5,"tv":8273.64,"id":21580749},{"batl":[[1,3.25,3.24]],"ltp":3.15,"tv":9385.67,"id":52106}],"tv":25330.14}]}
